02/19/2018 00:00:00;0002;Server@node2;Svr;Log;Log opened
02/19/2018 00:00:00;0002;Server@node2;Svr;Server@node2;pbs_version=14.0.1
02/19/2018 00:00:00;0002;Server@node2;Svr;Server@node2;pbs_build=mach=N/A:security=N/A:configure_args=N/A
02/19/2018 00:00:00;0002;Server@node2;Svr;Server@node2;hostname=node2.supernodexp.hpc;pbs_leaf_name=N/A;pbs_mom_node_name=N/A
02/19/2018 00:00:00;0002;Server@node2;Svr;Server@node2;ipv4 interface lo: localhost localhost.localdomain localhost4 localhost4.localdomain4 
02/19/2018 00:00:00;0002;Server@node2;Svr;Server@node2;ipv4 interface br0: node2.supernodexp.hpc node2 supernodexp-cn02 
02/19/2018 00:00:00;0002;Server@node2;Svr;Server@node2;ipv4 interface ib0: node2.supernodexp.hpc 
02/19/2018 00:00:00;0002;Server@node2;Svr;Server@node2;ipv4 interface docker0: node2.supernodexp.hpc 
02/19/2018 00:00:00;0002;Server@node2;Svr;Server@node2;ipv4 interface virbr0: node2.supernodexp.hpc 
02/19/2018 00:00:00;0002;Server@node2;Svr;Server@node2;ipv6 interface lo: localhost localhost.localdomain localhost6 localhost6.localdomain6 
02/19/2018 00:00:00;0002;Server@node2;Svr;Server@node2;ipv6 interface eno49: node2.supernodexp.hpc 
02/19/2018 00:00:00;0002;Server@node2;Svr;Server@node2;ipv6 interface br0: node2.supernodexp.hpc 
02/19/2018 00:00:00;0002;Server@node2;Svr;Server@node2;ipv6 interface ib0: node2.supernodexp.hpc 
02/19/2018 00:00:00;0002;Server@node2;Svr;Server@node2;ipv6 interface veth1pl7177: node2.supernodexp.hpc 
02/19/2018 00:00:00;0002;Server@node2;Svr;Act;Account file /var/spool/pbs/server_priv/accounting/20180219 opened
02/19/2018 00:00:06;0040;Server@node2;Svr;node2.supernodexp.hpc;Scheduler sent command 3
02/19/2018 00:00:06;0040;Server@node2;Svr;node2.supernodexp.hpc;Scheduler sent command 0
02/19/2018 00:00:06;0100;Server@node2;Req;;Type 21 request received from Scheduler@node2.supernodexp.hpc, sock=16
02/19/2018 00:00:06;0100;Server@node2;Req;;Type 81 request received from Scheduler@node2.supernodexp.hpc, sock=16
02/19/2018 00:00:06;0100;Server@node2;Req;;Type 71 request received from Scheduler@node2.supernodexp.hpc, sock=16
02/19/2018 00:00:06;0100;Server@node2;Req;;Type 58 request received from Scheduler@node2.supernodexp.hpc, sock=16
02/19/2018 00:00:06;0100;Server@node2;Req;;Type 20 request received from Scheduler@node2.supernodexp.hpc, sock=16
02/19/2018 00:00:06;0100;Server@node2;Req;;Type 51 request received from Scheduler@node2.supernodexp.hpc, sock=16
02/19/2018 00:00:31;0080;Server@node2;Job;2701.node2.supernodexp.hpc;Obit received momhop:1 serverhop:1 state:4 substate:42
02/19/2018 00:00:33;0010;Server@node2;Job;2701.node2.supernodexp.hpc;Exit_status=0 resources_used.cpupercent=4740 resources_used.cput=08:18:20 resources_used.mem=7907640kb resources_used.ncpus=48 resources_used.vmem=47424220kb resources_used.walltime=00:10:37
02/19/2018 00:00:33;0100;Server@node2;Job;2701.node2.supernodexp.hpc;dequeuing from workq, state 5
02/19/2018 00:00:33;0040;Server@node2;Svr;node2.supernodexp.hpc;Scheduler sent command 2
02/19/2018 00:00:33;0040;Server@node2;Svr;node2.supernodexp.hpc;Scheduler sent command 0
02/19/2018 00:00:33;0100;Server@node2;Req;;Type 21 request received from Scheduler@node2.supernodexp.hpc, sock=16
02/19/2018 00:00:33;0100;Server@node2;Req;;Type 81 request received from Scheduler@node2.supernodexp.hpc, sock=16
02/19/2018 00:00:33;0100;Server@node2;Req;;Type 71 request received from Scheduler@node2.supernodexp.hpc, sock=16
02/19/2018 00:00:33;0100;Server@node2;Req;;Type 58 request received from Scheduler@node2.supernodexp.hpc, sock=16
02/19/2018 00:00:33;0100;Server@node2;Req;;Type 20 request received from Scheduler@node2.supernodexp.hpc, sock=16
02/19/2018 00:00:33;0100;Server@node2;Req;;Type 51 request received from Scheduler@node2.supernodexp.hpc, sock=16
02/19/2018 00:00:33;0100;Server@node2;Req;;Type 23 request received from Scheduler@node2.supernodexp.hpc, sock=16
02/19/2018 00:00:33;0008;Server@node2;Job;2747.node2.supernodexp.hpc;Job Run at request of Scheduler@node2.supernodexp.hpc on exec_vnode (node14:ncpus=48:mem=5242880kb)
02/19/2018 00:00:33;0001;Server@node2;Svr;Server@node2;Success (0) in req_runjob2, return value of svr_startjob is 0
02/19/2018 00:00:33;0100;Server@node2;Req;;Type 11 request received from Scheduler@node2.supernodexp.hpc, sock=16
02/19/2018 00:00:33;0008;Server@node2;Job;2749.node2.supernodexp.hpc;Job Modified at request of Scheduler@node2.supernodexp.hpc
02/19/2018 00:00:43;0080;Server@node2;Job;2704.node2.supernodexp.hpc;Obit received momhop:1 serverhop:1 state:4 substate:42
02/19/2018 00:00:44;0010;Server@node2;Job;2704.node2.supernodexp.hpc;Exit_status=0 resources_used.cpupercent=4747 resources_used.cput=08:18:48 resources_used.mem=7948592kb resources_used.ncpus=48 resources_used.vmem=47424916kb resources_used.walltime=00:10:38
02/19/2018 00:00:44;0100;Server@node2;Job;2704.node2.supernodexp.hpc;dequeuing from workq, state 5
02/19/2018 00:00:44;0040;Server@node2;Svr;node2.supernodexp.hpc;Scheduler sent command 2
02/19/2018 00:00:44;0040;Server@node2;Svr;node2.supernodexp.hpc;Scheduler sent command 0
02/19/2018 00:00:44;0100;Server@node2;Req;;Type 21 request received from Scheduler@node2.supernodexp.hpc, sock=16
02/19/2018 00:00:44;0100;Server@node2;Req;;Type 81 request received from Scheduler@node2.supernodexp.hpc, sock=16
02/19/2018 00:00:44;0100;Server@node2;Req;;Type 71 request received from Scheduler@node2.supernodexp.hpc, sock=16
02/19/2018 00:00:44;0100;Server@node2;Req;;Type 58 request received from Scheduler@node2.supernodexp.hpc, sock=16
02/19/2018 00:00:44;0100;Server@node2;Req;;Type 20 request received from Scheduler@node2.supernodexp.hpc, sock=16
02/19/2018 00:00:44;0100;Server@node2;Req;;Type 51 request received from Scheduler@node2.supernodexp.hpc, sock=16
02/19/2018 00:00:44;0100;Server@node2;Req;;Type 23 request received from Scheduler@node2.supernodexp.hpc, sock=16
02/19/2018 00:00:44;0008;Server@node2;Job;2749.node2.supernodexp.hpc;Job Run at request of Scheduler@node2.supernodexp.hpc on exec_vnode (node13:ncpus=48:mem=5242880kb)
02/19/2018 00:00:44;0001;Server@node2;Svr;Server@node2;Success (0) in req_runjob2, return value of svr_startjob is 0
02/19/2018 00:00:44;0100;Server@node2;Req;;Type 11 request received from Scheduler@node2.supernodexp.hpc, sock=16
02/19/2018 00:00:44;0008;Server@node2;Job;2761.node2.supernodexp.hpc;Job Modified at request of Scheduler@node2.supernodexp.hpc
02/19/2018 00:10:44;0040;Server@node2;Svr;node2.supernodexp.hpc;Scheduler sent command 3
02/19/2018 00:10:44;0040;Server@node2;Svr;node2.supernodexp.hpc;Scheduler sent command 0
02/19/2018 00:10:44;0100;Server@node2;Req;;Type 21 request received from Scheduler@node2.supernodexp.hpc, sock=16
02/19/2018 00:10:44;0100;Server@node2;Req;;Type 81 request received from Scheduler@node2.supernodexp.hpc, sock=16
02/19/2018 00:10:44;0100;Server@node2;Req;;Type 71 request received from Scheduler@node2.supernodexp.hpc, sock=16
02/19/2018 00:10:44;0100;Server@node2;Req;;Type 58 request received from Scheduler@node2.supernodexp.hpc, sock=16
02/19/2018 00:10:44;0100;Server@node2;Req;;Type 20 request received from Scheduler@node2.supernodexp.hpc, sock=16
02/19/2018 00:10:44;0100;Server@node2;Req;;Type 51 request received from Scheduler@node2.supernodexp.hpc, sock=16
02/19/2018 00:11:17;0080;Server@node2;Job;2747.node2.supernodexp.hpc;Obit received momhop:1 serverhop:1 state:4 substate:42
02/19/2018 00:11:18;0080;Server@node2;Job;2749.node2.supernodexp.hpc;Obit received momhop:1 serverhop:1 state:4 substate:42
02/19/2018 00:11:19;0010;Server@node2;Job;2747.node2.supernodexp.hpc;Exit_status=0 resources_used.cpupercent=4689 resources_used.cput=08:15:38 resources_used.mem=7895076kb resources_used.ncpus=48 resources_used.vmem=47424400kb resources_used.walltime=00:10:44
02/19/2018 00:11:19;0100;Server@node2;Job;2747.node2.supernodexp.hpc;dequeuing from workq, state 5
02/19/2018 00:11:19;0040;Server@node2;Svr;node2.supernodexp.hpc;Scheduler sent command 2
02/19/2018 00:11:19;0040;Server@node2;Svr;node2.supernodexp.hpc;Scheduler sent command 0
02/19/2018 00:11:19;0100;Server@node2;Req;;Type 21 request received from Scheduler@node2.supernodexp.hpc, sock=16
02/19/2018 00:11:19;0100;Server@node2;Req;;Type 81 request received from Scheduler@node2.supernodexp.hpc, sock=16
02/19/2018 00:11:19;0100;Server@node2;Req;;Type 71 request received from Scheduler@node2.supernodexp.hpc, sock=16
02/19/2018 00:11:19;0100;Server@node2;Req;;Type 58 request received from Scheduler@node2.supernodexp.hpc, sock=16
02/19/2018 00:11:19;0100;Server@node2;Req;;Type 20 request received from Scheduler@node2.supernodexp.hpc, sock=16
02/19/2018 00:11:19;0100;Server@node2;Req;;Type 51 request received from Scheduler@node2.supernodexp.hpc, sock=16
02/19/2018 00:11:19;0100;Server@node2;Req;;Type 23 request received from Scheduler@node2.supernodexp.hpc, sock=16
02/19/2018 00:11:19;0008;Server@node2;Job;2761.node2.supernodexp.hpc;Job Run at request of Scheduler@node2.supernodexp.hpc on exec_vnode (node14:ncpus=48:mem=5242880kb)
02/19/2018 00:11:19;0001;Server@node2;Svr;Server@node2;Success (0) in req_runjob2, return value of svr_startjob is 0
02/19/2018 00:11:19;0100;Server@node2;Req;;Type 11 request received from Scheduler@node2.supernodexp.hpc, sock=16
02/19/2018 00:11:19;0008;Server@node2;Job;2786.node2.supernodexp.hpc;Job Modified at request of Scheduler@node2.supernodexp.hpc
02/19/2018 00:11:19;0010;Server@node2;Job;2749.node2.supernodexp.hpc;Exit_status=0 resources_used.cpupercent=4741 resources_used.cput=08:09:10 resources_used.mem=7919472kb resources_used.ncpus=48 resources_used.vmem=47424328kb resources_used.walltime=00:10:34
02/19/2018 00:11:19;0100;Server@node2;Job;2749.node2.supernodexp.hpc;dequeuing from workq, state 5
02/19/2018 00:11:19;0040;Server@node2;Svr;node2.supernodexp.hpc;Scheduler sent command 2
02/19/2018 00:11:19;0040;Server@node2;Svr;node2.supernodexp.hpc;Scheduler sent command 0
02/19/2018 00:11:19;0100;Server@node2;Req;;Type 21 request received from Scheduler@node2.supernodexp.hpc, sock=16
02/19/2018 00:11:19;0100;Server@node2;Req;;Type 81 request received from Scheduler@node2.supernodexp.hpc, sock=16
02/19/2018 00:11:19;0100;Server@node2;Req;;Type 71 request received from Scheduler@node2.supernodexp.hpc, sock=16
02/19/2018 00:11:19;0100;Server@node2;Req;;Type 58 request received from Scheduler@node2.supernodexp.hpc, sock=16
02/19/2018 00:11:19;0100;Server@node2;Req;;Type 20 request received from Scheduler@node2.supernodexp.hpc, sock=16
02/19/2018 00:11:19;0100;Server@node2;Req;;Type 51 request received from Scheduler@node2.supernodexp.hpc, sock=16
02/19/2018 00:11:19;0100;Server@node2;Req;;Type 23 request received from Scheduler@node2.supernodexp.hpc, sock=16
02/19/2018 00:11:19;0008;Server@node2;Job;2786.node2.supernodexp.hpc;Job Run at request of Scheduler@node2.supernodexp.hpc on exec_vnode (node13:ncpus=48:mem=5242880kb)
02/19/2018 00:11:19;0001;Server@node2;Svr;Server@node2;Success (0) in req_runjob2, return value of svr_startjob is 0
02/19/2018 00:11:19;0100;Server@node2;Req;;Type 11 request received from Scheduler@node2.supernodexp.hpc, sock=16
02/19/2018 00:11:19;0008;Server@node2;Job;2801.node2.supernodexp.hpc;Job Modified at request of Scheduler@node2.supernodexp.hpc
02/19/2018 00:21:19;0040;Server@node2;Svr;node2.supernodexp.hpc;Scheduler sent command 3
02/19/2018 00:21:19;0040;Server@node2;Svr;node2.supernodexp.hpc;Scheduler sent command 0
02/19/2018 00:21:19;0100;Server@node2;Req;;Type 21 request received from Scheduler@node2.supernodexp.hpc, sock=16
02/19/2018 00:21:19;0100;Server@node2;Req;;Type 81 request received from Scheduler@node2.supernodexp.hpc, sock=16
02/19/2018 00:21:19;0100;Server@node2;Req;;Type 71 request received from Scheduler@node2.supernodexp.hpc, sock=16
02/19/2018 00:21:19;0100;Server@node2;Req;;Type 58 request received from Scheduler@node2.supernodexp.hpc, sock=16
02/19/2018 00:21:19;0100;Server@node2;Req;;Type 20 request received from Scheduler@node2.supernodexp.hpc, sock=16
02/19/2018 00:21:19;0100;Server@node2;Req;;Type 51 request received from Scheduler@node2.supernodexp.hpc, sock=16
02/19/2018 00:22:21;0080;Server@node2;Job;2761.node2.supernodexp.hpc;Obit received momhop:1 serverhop:1 state:4 substate:42
02/19/2018 00:22:22;0010;Server@node2;Job;2761.node2.supernodexp.hpc;Exit_status=0 resources_used.cpupercent=4744 resources_used.cput=08:44:48 resources_used.mem=7962936kb resources_used.ncpus=48 resources_used.vmem=47424180kb resources_used.walltime=00:11:02
02/19/2018 00:22:22;0100;Server@node2;Job;2761.node2.supernodexp.hpc;dequeuing from workq, state 5
02/19/2018 00:22:22;0040;Server@node2;Svr;node2.supernodexp.hpc;Scheduler sent command 2
02/19/2018 00:22:22;0040;Server@node2;Svr;node2.supernodexp.hpc;Scheduler sent command 0
02/19/2018 00:22:22;0100;Server@node2;Req;;Type 21 request received from Scheduler@node2.supernodexp.hpc, sock=16
02/19/2018 00:22:22;0100;Server@node2;Req;;Type 81 request received from Scheduler@node2.supernodexp.hpc, sock=16
02/19/2018 00:22:22;0100;Server@node2;Req;;Type 71 request received from Scheduler@node2.supernodexp.hpc, sock=16
02/19/2018 00:22:22;0100;Server@node2;Req;;Type 58 request received from Scheduler@node2.supernodexp.hpc, sock=16
02/19/2018 00:22:22;0100;Server@node2;Req;;Type 20 request received from Scheduler@node2.supernodexp.hpc, sock=16
02/19/2018 00:22:22;0100;Server@node2;Req;;Type 51 request received from Scheduler@node2.supernodexp.hpc, sock=16
02/19/2018 00:22:22;0100;Server@node2;Req;;Type 23 request received from Scheduler@node2.supernodexp.hpc, sock=16
02/19/2018 00:22:22;0008;Server@node2;Job;2801.node2.supernodexp.hpc;Job Run at request of Scheduler@node2.supernodexp.hpc on exec_vnode (node14:ncpus=48:mem=5242880kb)
02/19/2018 00:22:22;0001;Server@node2;Svr;Server@node2;Success (0) in req_runjob2, return value of svr_startjob is 0
02/19/2018 00:22:22;0100;Server@node2;Req;;Type 11 request received from Scheduler@node2.supernodexp.hpc, sock=16
02/19/2018 00:22:22;0008;Server@node2;Job;2832.node2.supernodexp.hpc;Job Modified at request of Scheduler@node2.supernodexp.hpc
02/19/2018 00:22:27;0080;Server@node2;Job;2786.node2.supernodexp.hpc;Obit received momhop:1 serverhop:1 state:4 substate:42
02/19/2018 00:22:29;0010;Server@node2;Job;2786.node2.supernodexp.hpc;Exit_status=0 resources_used.cpupercent=4732 resources_used.cput=08:20:25 resources_used.mem=7894016kb resources_used.ncpus=48 resources_used.vmem=47424600kb resources_used.walltime=00:11:08
02/19/2018 00:22:29;0100;Server@node2;Job;2786.node2.supernodexp.hpc;dequeuing from workq, state 5
02/19/2018 00:22:29;0040;Server@node2;Svr;node2.supernodexp.hpc;Scheduler sent command 2
02/19/2018 00:22:29;0040;Server@node2;Svr;node2.supernodexp.hpc;Scheduler sent command 0
02/19/2018 00:22:29;0100;Server@node2;Req;;Type 21 request received from Scheduler@node2.supernodexp.hpc, sock=16
02/19/2018 00:22:29;0100;Server@node2;Req;;Type 81 request received from Scheduler@node2.supernodexp.hpc, sock=16
02/19/2018 00:22:29;0100;Server@node2;Req;;Type 71 request received from Scheduler@node2.supernodexp.hpc, sock=16
02/19/2018 00:22:29;0100;Server@node2;Req;;Type 58 request received from Scheduler@node2.supernodexp.hpc, sock=16
02/19/2018 00:22:29;0100;Server@node2;Req;;Type 20 request received from Scheduler@node2.supernodexp.hpc, sock=16
02/19/2018 00:22:29;0100;Server@node2;Req;;Type 51 request received from Scheduler@node2.supernodexp.hpc, sock=16
02/19/2018 00:22:29;0100;Server@node2;Req;;Type 23 request received from Scheduler@node2.supernodexp.hpc, sock=16
02/19/2018 00:22:29;0008;Server@node2;Job;2832.node2.supernodexp.hpc;Job Run at request of Scheduler@node2.supernodexp.hpc on exec_vnode (node13:ncpus=48:mem=5242880kb)
02/19/2018 00:22:29;0001;Server@node2;Svr;Server@node2;Success (0) in req_runjob2, return value of svr_startjob is 0
02/19/2018 00:22:29;0100;Server@node2;Req;;Type 11 request received from Scheduler@node2.supernodexp.hpc, sock=16
02/19/2018 00:22:29;0008;Server@node2;Job;2855.node2.supernodexp.hpc;Job Modified at request of Scheduler@node2.supernodexp.hpc
02/19/2018 00:32:29;0040;Server@node2;Svr;node2.supernodexp.hpc;Scheduler sent command 3
02/19/2018 00:32:29;0040;Server@node2;Svr;node2.supernodexp.hpc;Scheduler sent command 0
02/19/2018 00:32:29;0100;Server@node2;Req;;Type 21 request received from Scheduler@node2.supernodexp.hpc, sock=16
02/19/2018 00:32:29;0100;Server@node2;Req;;Type 81 request received from Scheduler@node2.supernodexp.hpc, sock=16
02/19/2018 00:32:29;0100;Server@node2;Req;;Type 71 request received from Scheduler@node2.supernodexp.hpc, sock=16
02/19/2018 00:32:29;0100;Server@node2;Req;;Type 58 request received from Scheduler@node2.supernodexp.hpc, sock=16
02/19/2018 00:32:29;0100;Server@node2;Req;;Type 20 request received from Scheduler@node2.supernodexp.hpc, sock=16
02/19/2018 00:32:29;0100;Server@node2;Req;;Type 51 request received from Scheduler@node2.supernodexp.hpc, sock=16
02/19/2018 00:33:05;0080;Server@node2;Job;2801.node2.supernodexp.hpc;Obit received momhop:1 serverhop:1 state:4 substate:42
02/19/2018 00:33:07;0010;Server@node2;Job;2801.node2.supernodexp.hpc;Exit_status=0 resources_used.cpupercent=4745 resources_used.cput=08:13:53 resources_used.mem=7952556kb resources_used.ncpus=48 resources_used.vmem=47424524kb resources_used.walltime=00:10:43
02/19/2018 00:33:07;0100;Server@node2;Job;2801.node2.supernodexp.hpc;dequeuing from workq, state 5
02/19/2018 00:33:07;0040;Server@node2;Svr;node2.supernodexp.hpc;Scheduler sent command 2
02/19/2018 00:33:07;0040;Server@node2;Svr;node2.supernodexp.hpc;Scheduler sent command 0
02/19/2018 00:33:07;0100;Server@node2;Req;;Type 21 request received from Scheduler@node2.supernodexp.hpc, sock=16
02/19/2018 00:33:07;0100;Server@node2;Req;;Type 81 request received from Scheduler@node2.supernodexp.hpc, sock=16
02/19/2018 00:33:07;0100;Server@node2;Req;;Type 71 request received from Scheduler@node2.supernodexp.hpc, sock=16
02/19/2018 00:33:07;0100;Server@node2;Req;;Type 58 request received from Scheduler@node2.supernodexp.hpc, sock=16
02/19/2018 00:33:07;0100;Server@node2;Req;;Type 20 request received from Scheduler@node2.supernodexp.hpc, sock=16
02/19/2018 00:33:07;0100;Server@node2;Req;;Type 51 request received from Scheduler@node2.supernodexp.hpc, sock=16
02/19/2018 00:33:07;0100;Server@node2;Req;;Type 23 request received from Scheduler@node2.supernodexp.hpc, sock=16
02/19/2018 00:33:07;0008;Server@node2;Job;2855.node2.supernodexp.hpc;Job Run at request of Scheduler@node2.supernodexp.hpc on exec_vnode (node14:ncpus=48:mem=5242880kb)
02/19/2018 00:33:07;0001;Server@node2;Svr;Server@node2;Success (0) in req_runjob2, return value of svr_startjob is 0
02/19/2018 00:33:07;0100;Server@node2;Req;;Type 11 request received from Scheduler@node2.supernodexp.hpc, sock=16
02/19/2018 00:33:07;0008;Server@node2;Job;2883.node2.supernodexp.hpc;Job Modified at request of Scheduler@node2.supernodexp.hpc
02/19/2018 00:33:19;0080;Server@node2;Job;2832.node2.supernodexp.hpc;Obit received momhop:1 serverhop:1 state:4 substate:42
02/19/2018 00:33:20;0010;Server@node2;Job;2832.node2.supernodexp.hpc;Exit_status=0 resources_used.cpupercent=4737 resources_used.cput=08:15:29 resources_used.mem=7951160kb resources_used.ncpus=48 resources_used.vmem=47424648kb resources_used.walltime=00:10:51
02/19/2018 00:33:20;0100;Server@node2;Job;2832.node2.supernodexp.hpc;dequeuing from workq, state 5
02/19/2018 00:33:20;0040;Server@node2;Svr;node2.supernodexp.hpc;Scheduler sent command 2
02/19/2018 00:33:20;0040;Server@node2;Svr;node2.supernodexp.hpc;Scheduler sent command 0
02/19/2018 00:33:20;0100;Server@node2;Req;;Type 21 request received from Scheduler@node2.supernodexp.hpc, sock=16
02/19/2018 00:33:20;0100;Server@node2;Req;;Type 81 request received from Scheduler@node2.supernodexp.hpc, sock=16
02/19/2018 00:33:20;0100;Server@node2;Req;;Type 71 request received from Scheduler@node2.supernodexp.hpc, sock=16
02/19/2018 00:33:20;0100;Server@node2;Req;;Type 58 request received from Scheduler@node2.supernodexp.hpc, sock=16
02/19/2018 00:33:20;0100;Server@node2;Req;;Type 20 request received from Scheduler@node2.supernodexp.hpc, sock=16
02/19/2018 00:33:20;0100;Server@node2;Req;;Type 51 request received from Scheduler@node2.supernodexp.hpc, sock=16
02/19/2018 00:33:20;0100;Server@node2;Req;;Type 23 request received from Scheduler@node2.supernodexp.hpc, sock=16
02/19/2018 00:33:20;0008;Server@node2;Job;2883.node2.supernodexp.hpc;Job Run at request of Scheduler@node2.supernodexp.hpc on exec_vnode (node13:ncpus=48:mem=5242880kb)
02/19/2018 00:33:21;0001;Server@node2;Svr;Server@node2;Success (0) in req_runjob2, return value of svr_startjob is 0
02/19/2018 00:33:21;0100;Server@node2;Req;;Type 11 request received from Scheduler@node2.supernodexp.hpc, sock=16
02/19/2018 00:33:21;0008;Server@node2;Job;2896.node2.supernodexp.hpc;Job Modified at request of Scheduler@node2.supernodexp.hpc
02/19/2018 00:43:20;0040;Server@node2;Svr;node2.supernodexp.hpc;Scheduler sent command 3
02/19/2018 00:43:20;0040;Server@node2;Svr;node2.supernodexp.hpc;Scheduler sent command 0
02/19/2018 00:43:20;0100;Server@node2;Req;;Type 21 request received from Scheduler@node2.supernodexp.hpc, sock=16
02/19/2018 00:43:20;0100;Server@node2;Req;;Type 81 request received from Scheduler@node2.supernodexp.hpc, sock=16
02/19/2018 00:43:20;0100;Server@node2;Req;;Type 71 request received from Scheduler@node2.supernodexp.hpc, sock=16
02/19/2018 00:43:20;0100;Server@node2;Req;;Type 58 request received from Scheduler@node2.supernodexp.hpc, sock=16
02/19/2018 00:43:20;0100;Server@node2;Req;;Type 20 request received from Scheduler@node2.supernodexp.hpc, sock=16
02/19/2018 00:43:20;0100;Server@node2;Req;;Type 51 request received from Scheduler@node2.supernodexp.hpc, sock=16
02/19/2018 00:43:45;0080;Server@node2;Job;2855.node2.supernodexp.hpc;Obit received momhop:1 serverhop:1 state:4 substate:42
02/19/2018 00:43:46;0010;Server@node2;Job;2855.node2.supernodexp.hpc;Exit_status=0 resources_used.cpupercent=4743 resources_used.cput=08:15:42 resources_used.mem=7948080kb resources_used.ncpus=48 resources_used.vmem=47424396kb resources_used.walltime=00:10:38
02/19/2018 00:43:46;0100;Server@node2;Job;2855.node2.supernodexp.hpc;dequeuing from workq, state 5
02/19/2018 00:43:46;0040;Server@node2;Svr;node2.supernodexp.hpc;Scheduler sent command 2
02/19/2018 00:43:46;0040;Server@node2;Svr;node2.supernodexp.hpc;Scheduler sent command 0
02/19/2018 00:43:46;0100;Server@node2;Req;;Type 21 request received from Scheduler@node2.supernodexp.hpc, sock=16
02/19/2018 00:43:46;0100;Server@node2;Req;;Type 81 request received from Scheduler@node2.supernodexp.hpc, sock=16
02/19/2018 00:43:46;0100;Server@node2;Req;;Type 71 request received from Scheduler@node2.supernodexp.hpc, sock=16
02/19/2018 00:43:46;0100;Server@node2;Req;;Type 58 request received from Scheduler@node2.supernodexp.hpc, sock=16
02/19/2018 00:43:46;0100;Server@node2;Req;;Type 20 request received from Scheduler@node2.supernodexp.hpc, sock=16
02/19/2018 00:43:46;0100;Server@node2;Req;;Type 51 request received from Scheduler@node2.supernodexp.hpc, sock=16
02/19/2018 00:43:47;0100;Server@node2;Req;;Type 23 request received from Scheduler@node2.supernodexp.hpc, sock=16
02/19/2018 00:43:47;0008;Server@node2;Job;2896.node2.supernodexp.hpc;Job Run at request of Scheduler@node2.supernodexp.hpc on exec_vnode (node14:ncpus=48:mem=5242880kb)
02/19/2018 00:43:47;0001;Server@node2;Svr;Server@node2;Success (0) in req_runjob2, return value of svr_startjob is 0
02/19/2018 00:43:47;0100;Server@node2;Req;;Type 11 request received from Scheduler@node2.supernodexp.hpc, sock=16
02/19/2018 00:43:47;0008;Server@node2;Job;2929.node2.supernodexp.hpc;Job Modified at request of Scheduler@node2.supernodexp.hpc
02/19/2018 00:43:55;0080;Server@node2;Job;2883.node2.supernodexp.hpc;Obit received momhop:1 serverhop:1 state:4 substate:42
02/19/2018 00:43:56;0010;Server@node2;Job;2883.node2.supernodexp.hpc;Exit_status=0 resources_used.cpupercent=4747 resources_used.cput=08:11:44 resources_used.mem=7966576kb resources_used.ncpus=48 resources_used.vmem=47424176kb resources_used.walltime=00:10:34
02/19/2018 00:43:56;0100;Server@node2;Job;2883.node2.supernodexp.hpc;dequeuing from workq, state 5
02/19/2018 00:43:56;0040;Server@node2;Svr;node2.supernodexp.hpc;Scheduler sent command 2
02/19/2018 00:43:56;0040;Server@node2;Svr;node2.supernodexp.hpc;Scheduler sent command 0
02/19/2018 00:43:56;0100;Server@node2;Req;;Type 21 request received from Scheduler@node2.supernodexp.hpc, sock=16
02/19/2018 00:43:56;0100;Server@node2;Req;;Type 81 request received from Scheduler@node2.supernodexp.hpc, sock=16
02/19/2018 00:43:56;0100;Server@node2;Req;;Type 71 request received from Scheduler@node2.supernodexp.hpc, sock=16
02/19/2018 00:43:56;0100;Server@node2;Req;;Type 58 request received from Scheduler@node2.supernodexp.hpc, sock=16
02/19/2018 00:43:56;0100;Server@node2;Req;;Type 20 request received from Scheduler@node2.supernodexp.hpc, sock=16
02/19/2018 00:43:56;0100;Server@node2;Req;;Type 51 request received from Scheduler@node2.supernodexp.hpc, sock=16
02/19/2018 00:43:56;0100;Server@node2;Req;;Type 23 request received from Scheduler@node2.supernodexp.hpc, sock=16
02/19/2018 00:43:56;0008;Server@node2;Job;2929.node2.supernodexp.hpc;Job Run at request of Scheduler@node2.supernodexp.hpc on exec_vnode (node13:ncpus=48:mem=5242880kb)
02/19/2018 00:43:56;0001;Server@node2;Svr;Server@node2;Success (0) in req_runjob2, return value of svr_startjob is 0
02/19/2018 00:43:56;0100;Server@node2;Req;;Type 11 request received from Scheduler@node2.supernodexp.hpc, sock=16
02/19/2018 00:43:56;0008;Server@node2;Job;2937.node2.supernodexp.hpc;Job Modified at request of Scheduler@node2.supernodexp.hpc
02/19/2018 00:53:56;0040;Server@node2;Svr;node2.supernodexp.hpc;Scheduler sent command 3
02/19/2018 00:53:56;0040;Server@node2;Svr;node2.supernodexp.hpc;Scheduler sent command 0
02/19/2018 00:53:56;0100;Server@node2;Req;;Type 21 request received from Scheduler@node2.supernodexp.hpc, sock=16
02/19/2018 00:53:56;0100;Server@node2;Req;;Type 81 request received from Scheduler@node2.supernodexp.hpc, sock=16
02/19/2018 00:53:56;0100;Server@node2;Req;;Type 71 request received from Scheduler@node2.supernodexp.hpc, sock=16
02/19/2018 00:53:56;0100;Server@node2;Req;;Type 58 request received from Scheduler@node2.supernodexp.hpc, sock=16
02/19/2018 00:53:56;0100;Server@node2;Req;;Type 20 request received from Scheduler@node2.supernodexp.hpc, sock=16
02/19/2018 00:53:56;0100;Server@node2;Req;;Type 51 request received from Scheduler@node2.supernodexp.hpc, sock=16
02/19/2018 00:54:29;0080;Server@node2;Job;2896.node2.supernodexp.hpc;Obit received momhop:1 serverhop:1 state:4 substate:42
02/19/2018 00:54:32;0010;Server@node2;Job;2896.node2.supernodexp.hpc;Exit_status=0 resources_used.cpupercent=4739 resources_used.cput=08:18:35 resources_used.mem=7872840kb resources_used.ncpus=48 resources_used.vmem=47424200kb resources_used.walltime=00:10:42
02/19/2018 00:54:32;0100;Server@node2;Job;2896.node2.supernodexp.hpc;dequeuing from workq, state 5
02/19/2018 00:54:32;0040;Server@node2;Svr;node2.supernodexp.hpc;Scheduler sent command 2
02/19/2018 00:54:32;0040;Server@node2;Svr;node2.supernodexp.hpc;Scheduler sent command 0
02/19/2018 00:54:32;0100;Server@node2;Req;;Type 21 request received from Scheduler@node2.supernodexp.hpc, sock=16
02/19/2018 00:54:32;0100;Server@node2;Req;;Type 81 request received from Scheduler@node2.supernodexp.hpc, sock=16
02/19/2018 00:54:32;0100;Server@node2;Req;;Type 71 request received from Scheduler@node2.supernodexp.hpc, sock=16
02/19/2018 00:54:32;0100;Server@node2;Req;;Type 58 request received from Scheduler@node2.supernodexp.hpc, sock=16
02/19/2018 00:54:32;0100;Server@node2;Req;;Type 20 request received from Scheduler@node2.supernodexp.hpc, sock=16
02/19/2018 00:54:32;0100;Server@node2;Req;;Type 51 request received from Scheduler@node2.supernodexp.hpc, sock=16
02/19/2018 00:54:32;0100;Server@node2;Req;;Type 23 request received from Scheduler@node2.supernodexp.hpc, sock=16
02/19/2018 00:54:32;0008;Server@node2;Job;2937.node2.supernodexp.hpc;Job Run at request of Scheduler@node2.supernodexp.hpc on exec_vnode (node14:ncpus=48:mem=5242880kb)
02/19/2018 00:54:32;0001;Server@node2;Svr;Server@node2;Success (0) in req_runjob2, return value of svr_startjob is 0
02/19/2018 00:54:32;0100;Server@node2;Req;;Type 11 request received from Scheduler@node2.supernodexp.hpc, sock=16
02/19/2018 00:54:32;0008;Server@node2;Job;2950.node2.supernodexp.hpc;Job Modified at request of Scheduler@node2.supernodexp.hpc
02/19/2018 00:54:39;0080;Server@node2;Job;2929.node2.supernodexp.hpc;Obit received momhop:1 serverhop:1 state:4 substate:42
02/19/2018 00:54:41;0010;Server@node2;Job;2929.node2.supernodexp.hpc;Exit_status=0 resources_used.cpupercent=4740 resources_used.cput=08:16:13 resources_used.mem=7859156kb resources_used.ncpus=48 resources_used.vmem=47424628kb resources_used.walltime=00:10:44
02/19/2018 00:54:41;0100;Server@node2;Job;2929.node2.supernodexp.hpc;dequeuing from workq, state 5
02/19/2018 00:54:41;0040;Server@node2;Svr;node2.supernodexp.hpc;Scheduler sent command 2
02/19/2018 00:54:41;0040;Server@node2;Svr;node2.supernodexp.hpc;Scheduler sent command 0
02/19/2018 00:54:41;0100;Server@node2;Req;;Type 21 request received from Scheduler@node2.supernodexp.hpc, sock=16
02/19/2018 00:54:41;0100;Server@node2;Req;;Type 81 request received from Scheduler@node2.supernodexp.hpc, sock=16
02/19/2018 00:54:41;0100;Server@node2;Req;;Type 71 request received from Scheduler@node2.supernodexp.hpc, sock=16
02/19/2018 00:54:41;0100;Server@node2;Req;;Type 58 request received from Scheduler@node2.supernodexp.hpc, sock=16
02/19/2018 00:54:41;0100;Server@node2;Req;;Type 20 request received from Scheduler@node2.supernodexp.hpc, sock=16
02/19/2018 00:54:41;0100;Server@node2;Req;;Type 51 request received from Scheduler@node2.supernodexp.hpc, sock=16
02/19/2018 00:54:41;0100;Server@node2;Req;;Type 23 request received from Scheduler@node2.supernodexp.hpc, sock=16
02/19/2018 00:54:41;0008;Server@node2;Job;2950.node2.supernodexp.hpc;Job Run at request of Scheduler@node2.supernodexp.hpc on exec_vnode (node13:ncpus=48:mem=5242880kb)
02/19/2018 00:54:41;0001;Server@node2;Svr;Server@node2;Success (0) in req_runjob2, return value of svr_startjob is 0
02/19/2018 00:54:41;0100;Server@node2;Req;;Type 11 request received from Scheduler@node2.supernodexp.hpc, sock=16
02/19/2018 00:54:41;0008;Server@node2;Job;2954.node2.supernodexp.hpc;Job Modified at request of Scheduler@node2.supernodexp.hpc
02/19/2018 01:04:41;0040;Server@node2;Svr;node2.supernodexp.hpc;Scheduler sent command 3
02/19/2018 01:04:41;0040;Server@node2;Svr;node2.supernodexp.hpc;Scheduler sent command 0
02/19/2018 01:04:41;0100;Server@node2;Req;;Type 21 request received from Scheduler@node2.supernodexp.hpc, sock=16
02/19/2018 01:04:41;0100;Server@node2;Req;;Type 81 request received from Scheduler@node2.supernodexp.hpc, sock=16
02/19/2018 01:04:41;0100;Server@node2;Req;;Type 71 request received from Scheduler@node2.supernodexp.hpc, sock=16
02/19/2018 01:04:41;0100;Server@node2;Req;;Type 58 request received from Scheduler@node2.supernodexp.hpc, sock=16
02/19/2018 01:04:41;0100;Server@node2;Req;;Type 20 request received from Scheduler@node2.supernodexp.hpc, sock=16
02/19/2018 01:04:41;0100;Server@node2;Req;;Type 51 request received from Scheduler@node2.supernodexp.hpc, sock=16
02/19/2018 01:05:26;0080;Server@node2;Job;2937.node2.supernodexp.hpc;Obit received momhop:1 serverhop:1 state:4 substate:42
02/19/2018 01:05:27;0010;Server@node2;Job;2937.node2.supernodexp.hpc;Exit_status=0 resources_used.cpupercent=4737 resources_used.cput=08:11:02 resources_used.mem=7979016kb resources_used.ncpus=48 resources_used.vmem=47424808kb resources_used.walltime=00:10:54
02/19/2018 01:05:27;0100;Server@node2;Job;2937.node2.supernodexp.hpc;dequeuing from workq, state 5
02/19/2018 01:05:27;0040;Server@node2;Svr;node2.supernodexp.hpc;Scheduler sent command 2
02/19/2018 01:05:27;0040;Server@node2;Svr;node2.supernodexp.hpc;Scheduler sent command 0
02/19/2018 01:05:27;0100;Server@node2;Req;;Type 21 request received from Scheduler@node2.supernodexp.hpc, sock=16
02/19/2018 01:05:27;0100;Server@node2;Req;;Type 81 request received from Scheduler@node2.supernodexp.hpc, sock=16
02/19/2018 01:05:27;0100;Server@node2;Req;;Type 71 request received from Scheduler@node2.supernodexp.hpc, sock=16
02/19/2018 01:05:27;0100;Server@node2;Req;;Type 58 request received from Scheduler@node2.supernodexp.hpc, sock=16
02/19/2018 01:05:27;0100;Server@node2;Req;;Type 20 request received from Scheduler@node2.supernodexp.hpc, sock=16
02/19/2018 01:05:27;0100;Server@node2;Req;;Type 51 request received from Scheduler@node2.supernodexp.hpc, sock=16
02/19/2018 01:05:27;0100;Server@node2;Req;;Type 23 request received from Scheduler@node2.supernodexp.hpc, sock=16
02/19/2018 01:05:27;0008;Server@node2;Job;2954.node2.supernodexp.hpc;Job Run at request of Scheduler@node2.supernodexp.hpc on exec_vnode (node14:ncpus=48:mem=5242880kb)
02/19/2018 01:05:27;0001;Server@node2;Svr;Server@node2;Success (0) in req_runjob2, return value of svr_startjob is 0
02/19/2018 01:05:27;0100;Server@node2;Req;;Type 11 request received from Scheduler@node2.supernodexp.hpc, sock=16
02/19/2018 01:05:27;0008;Server@node2;Job;2963.node2.supernodexp.hpc;Job Modified at request of Scheduler@node2.supernodexp.hpc
02/19/2018 01:05:33;0080;Server@node2;Job;2950.node2.supernodexp.hpc;Obit received momhop:1 serverhop:1 state:4 substate:42
02/19/2018 01:05:34;0010;Server@node2;Job;2950.node2.supernodexp.hpc;Exit_status=0 resources_used.cpupercent=4700 resources_used.cput=08:14:37 resources_used.mem=7906828kb resources_used.ncpus=48 resources_used.vmem=47424644kb resources_used.walltime=00:10:53
02/19/2018 01:05:34;0100;Server@node2;Job;2950.node2.supernodexp.hpc;dequeuing from workq, state 5
02/19/2018 01:05:34;0040;Server@node2;Svr;node2.supernodexp.hpc;Scheduler sent command 2
02/19/2018 01:05:34;0040;Server@node2;Svr;node2.supernodexp.hpc;Scheduler sent command 0
02/19/2018 01:05:34;0100;Server@node2;Req;;Type 21 request received from Scheduler@node2.supernodexp.hpc, sock=16
02/19/2018 01:05:34;0100;Server@node2;Req;;Type 81 request received from Scheduler@node2.supernodexp.hpc, sock=16
02/19/2018 01:05:34;0100;Server@node2;Req;;Type 71 request received from Scheduler@node2.supernodexp.hpc, sock=16
02/19/2018 01:05:34;0100;Server@node2;Req;;Type 58 request received from Scheduler@node2.supernodexp.hpc, sock=16
02/19/2018 01:05:35;0100;Server@node2;Req;;Type 20 request received from Scheduler@node2.supernodexp.hpc, sock=16
02/19/2018 01:05:35;0100;Server@node2;Req;;Type 51 request received from Scheduler@node2.supernodexp.hpc, sock=16
02/19/2018 01:05:35;0100;Server@node2;Req;;Type 23 request received from Scheduler@node2.supernodexp.hpc, sock=16
02/19/2018 01:05:35;0008;Server@node2;Job;2963.node2.supernodexp.hpc;Job Run at request of Scheduler@node2.supernodexp.hpc on exec_vnode (node13:ncpus=48:mem=5242880kb)
02/19/2018 01:05:35;0001;Server@node2;Svr;Server@node2;Success (0) in req_runjob2, return value of svr_startjob is 0
02/19/2018 01:05:35;0100;Server@node2;Req;;Type 11 request received from Scheduler@node2.supernodexp.hpc, sock=16
02/19/2018 01:05:35;0008;Server@node2;Job;2970.node2.supernodexp.hpc;Job Modified at request of Scheduler@node2.supernodexp.hpc
02/19/2018 01:15:34;0040;Server@node2;Svr;node2.supernodexp.hpc;Scheduler sent command 3
02/19/2018 01:15:34;0040;Server@node2;Svr;node2.supernodexp.hpc;Scheduler sent command 0
02/19/2018 01:15:34;0100;Server@node2;Req;;Type 21 request received from Scheduler@node2.supernodexp.hpc, sock=16
02/19/2018 01:15:34;0100;Server@node2;Req;;Type 81 request received from Scheduler@node2.supernodexp.hpc, sock=16
02/19/2018 01:15:34;0100;Server@node2;Req;;Type 71 request received from Scheduler@node2.supernodexp.hpc, sock=16
02/19/2018 01:15:34;0100;Server@node2;Req;;Type 58 request received from Scheduler@node2.supernodexp.hpc, sock=16
02/19/2018 01:15:34;0100;Server@node2;Req;;Type 20 request received from Scheduler@node2.supernodexp.hpc, sock=16
02/19/2018 01:15:34;0100;Server@node2;Req;;Type 51 request received from Scheduler@node2.supernodexp.hpc, sock=16
02/19/2018 01:16:11;0080;Server@node2;Job;2954.node2.supernodexp.hpc;Obit received momhop:1 serverhop:1 state:4 substate:42
02/19/2018 01:16:12;0010;Server@node2;Job;2954.node2.supernodexp.hpc;Exit_status=0 resources_used.cpupercent=4733 resources_used.cput=08:12:28 resources_used.mem=7961380kb resources_used.ncpus=48 resources_used.vmem=47424512kb resources_used.walltime=00:10:44
02/19/2018 01:16:12;0100;Server@node2;Job;2954.node2.supernodexp.hpc;dequeuing from workq, state 5
02/19/2018 01:16:12;0040;Server@node2;Svr;node2.supernodexp.hpc;Scheduler sent command 2
02/19/2018 01:16:12;0040;Server@node2;Svr;node2.supernodexp.hpc;Scheduler sent command 0
02/19/2018 01:16:12;0100;Server@node2;Req;;Type 21 request received from Scheduler@node2.supernodexp.hpc, sock=16
02/19/2018 01:16:12;0100;Server@node2;Req;;Type 81 request received from Scheduler@node2.supernodexp.hpc, sock=16
02/19/2018 01:16:12;0100;Server@node2;Req;;Type 71 request received from Scheduler@node2.supernodexp.hpc, sock=16
02/19/2018 01:16:12;0100;Server@node2;Req;;Type 58 request received from Scheduler@node2.supernodexp.hpc, sock=16
02/19/2018 01:16:13;0100;Server@node2;Req;;Type 20 request received from Scheduler@node2.supernodexp.hpc, sock=16
02/19/2018 01:16:13;0100;Server@node2;Req;;Type 51 request received from Scheduler@node2.supernodexp.hpc, sock=16
02/19/2018 01:16:13;0100;Server@node2;Req;;Type 23 request received from Scheduler@node2.supernodexp.hpc, sock=16
02/19/2018 01:16:13;0008;Server@node2;Job;2970.node2.supernodexp.hpc;Job Run at request of Scheduler@node2.supernodexp.hpc on exec_vnode (node14:ncpus=48:mem=5242880kb)
02/19/2018 01:16:13;0001;Server@node2;Svr;Server@node2;Success (0) in req_runjob2, return value of svr_startjob is 0
02/19/2018 01:16:13;0100;Server@node2;Req;;Type 11 request received from Scheduler@node2.supernodexp.hpc, sock=16
02/19/2018 01:16:13;0008;Server@node2;Job;2977.node2.supernodexp.hpc;Job Modified at request of Scheduler@node2.supernodexp.hpc
02/19/2018 01:16:22;0080;Server@node2;Job;2963.node2.supernodexp.hpc;Obit received momhop:1 serverhop:1 state:4 substate:42
02/19/2018 01:16:23;0010;Server@node2;Job;2963.node2.supernodexp.hpc;Exit_status=0 resources_used.cpupercent=4686 resources_used.cput=08:32:36 resources_used.mem=7931728kb resources_used.ncpus=48 resources_used.vmem=47424620kb resources_used.walltime=00:10:48
02/19/2018 01:16:23;0100;Server@node2;Job;2963.node2.supernodexp.hpc;dequeuing from workq, state 5
02/19/2018 01:16:23;0040;Server@node2;Svr;node2.supernodexp.hpc;Scheduler sent command 2
02/19/2018 01:16:23;0040;Server@node2;Svr;node2.supernodexp.hpc;Scheduler sent command 0
02/19/2018 01:16:23;0100;Server@node2;Req;;Type 21 request received from Scheduler@node2.supernodexp.hpc, sock=16
02/19/2018 01:16:23;0100;Server@node2;Req;;Type 81 request received from Scheduler@node2.supernodexp.hpc, sock=16
02/19/2018 01:16:23;0100;Server@node2;Req;;Type 71 request received from Scheduler@node2.supernodexp.hpc, sock=16
02/19/2018 01:16:23;0100;Server@node2;Req;;Type 58 request received from Scheduler@node2.supernodexp.hpc, sock=16
02/19/2018 01:16:23;0100;Server@node2;Req;;Type 20 request received from Scheduler@node2.supernodexp.hpc, sock=16
02/19/2018 01:16:23;0100;Server@node2;Req;;Type 51 request received from Scheduler@node2.supernodexp.hpc, sock=16
02/19/2018 01:16:23;0100;Server@node2;Req;;Type 23 request received from Scheduler@node2.supernodexp.hpc, sock=16
02/19/2018 01:16:23;0008;Server@node2;Job;2977.node2.supernodexp.hpc;Job Run at request of Scheduler@node2.supernodexp.hpc on exec_vnode (node13:ncpus=48:mem=5242880kb)
02/19/2018 01:16:23;0001;Server@node2;Svr;Server@node2;Success (0) in req_runjob2, return value of svr_startjob is 0
02/19/2018 01:16:23;0100;Server@node2;Req;;Type 11 request received from Scheduler@node2.supernodexp.hpc, sock=16
02/19/2018 01:16:23;0008;Server@node2;Job;2988.node2.supernodexp.hpc;Job Modified at request of Scheduler@node2.supernodexp.hpc
02/19/2018 01:26:23;0040;Server@node2;Svr;node2.supernodexp.hpc;Scheduler sent command 3
02/19/2018 01:26:23;0040;Server@node2;Svr;node2.supernodexp.hpc;Scheduler sent command 0
02/19/2018 01:26:23;0100;Server@node2;Req;;Type 21 request received from Scheduler@node2.supernodexp.hpc, sock=16
02/19/2018 01:26:23;0100;Server@node2;Req;;Type 81 request received from Scheduler@node2.supernodexp.hpc, sock=16
02/19/2018 01:26:23;0100;Server@node2;Req;;Type 71 request received from Scheduler@node2.supernodexp.hpc, sock=16
02/19/2018 01:26:23;0100;Server@node2;Req;;Type 58 request received from Scheduler@node2.supernodexp.hpc, sock=16
02/19/2018 01:26:23;0100;Server@node2;Req;;Type 20 request received from Scheduler@node2.supernodexp.hpc, sock=16
02/19/2018 01:26:23;0100;Server@node2;Req;;Type 51 request received from Scheduler@node2.supernodexp.hpc, sock=16
02/19/2018 01:27:02;0080;Server@node2;Job;2970.node2.supernodexp.hpc;Obit received momhop:1 serverhop:1 state:4 substate:42
02/19/2018 01:27:03;0010;Server@node2;Job;2970.node2.supernodexp.hpc;Exit_status=0 resources_used.cpupercent=4743 resources_used.cput=08:28:24 resources_used.mem=7972076kb resources_used.ncpus=48 resources_used.vmem=47424096kb resources_used.walltime=00:10:49
02/19/2018 01:27:03;0100;Server@node2;Job;2970.node2.supernodexp.hpc;dequeuing from workq, state 5
02/19/2018 01:27:03;0040;Server@node2;Svr;node2.supernodexp.hpc;Scheduler sent command 2
02/19/2018 01:27:03;0040;Server@node2;Svr;node2.supernodexp.hpc;Scheduler sent command 0
02/19/2018 01:27:03;0100;Server@node2;Req;;Type 21 request received from Scheduler@node2.supernodexp.hpc, sock=16
02/19/2018 01:27:03;0100;Server@node2;Req;;Type 81 request received from Scheduler@node2.supernodexp.hpc, sock=16
02/19/2018 01:27:03;0100;Server@node2;Req;;Type 71 request received from Scheduler@node2.supernodexp.hpc, sock=16
02/19/2018 01:27:03;0100;Server@node2;Req;;Type 58 request received from Scheduler@node2.supernodexp.hpc, sock=16
02/19/2018 01:27:03;0100;Server@node2;Req;;Type 20 request received from Scheduler@node2.supernodexp.hpc, sock=16
02/19/2018 01:27:03;0100;Server@node2;Req;;Type 51 request received from Scheduler@node2.supernodexp.hpc, sock=16
02/19/2018 01:27:03;0100;Server@node2;Req;;Type 23 request received from Scheduler@node2.supernodexp.hpc, sock=16
02/19/2018 01:27:03;0008;Server@node2;Job;2988.node2.supernodexp.hpc;Job Run at request of Scheduler@node2.supernodexp.hpc on exec_vnode (node14:ncpus=48:mem=5242880kb)
02/19/2018 01:27:03;0001;Server@node2;Svr;Server@node2;Success (0) in req_runjob2, return value of svr_startjob is 0
02/19/2018 01:27:03;0100;Server@node2;Req;;Type 11 request received from Scheduler@node2.supernodexp.hpc, sock=16
02/19/2018 01:27:03;0008;Server@node2;Job;2991.node2.supernodexp.hpc;Job Modified at request of Scheduler@node2.supernodexp.hpc
02/19/2018 01:27:22;0080;Server@node2;Job;2977.node2.supernodexp.hpc;Obit received momhop:1 serverhop:1 state:4 substate:42
02/19/2018 01:27:23;0010;Server@node2;Job;2977.node2.supernodexp.hpc;Exit_status=0 resources_used.cpupercent=4732 resources_used.cput=08:25:12 resources_used.mem=7921760kb resources_used.ncpus=48 resources_used.vmem=47424624kb resources_used.walltime=00:10:59
02/19/2018 01:27:23;0100;Server@node2;Job;2977.node2.supernodexp.hpc;dequeuing from workq, state 5
02/19/2018 01:27:23;0040;Server@node2;Svr;node2.supernodexp.hpc;Scheduler sent command 2
02/19/2018 01:27:23;0040;Server@node2;Svr;node2.supernodexp.hpc;Scheduler sent command 0
02/19/2018 01:27:23;0100;Server@node2;Req;;Type 21 request received from Scheduler@node2.supernodexp.hpc, sock=16
02/19/2018 01:27:23;0100;Server@node2;Req;;Type 81 request received from Scheduler@node2.supernodexp.hpc, sock=16
02/19/2018 01:27:23;0100;Server@node2;Req;;Type 71 request received from Scheduler@node2.supernodexp.hpc, sock=16
02/19/2018 01:27:23;0100;Server@node2;Req;;Type 58 request received from Scheduler@node2.supernodexp.hpc, sock=16
02/19/2018 01:27:23;0100;Server@node2;Req;;Type 20 request received from Scheduler@node2.supernodexp.hpc, sock=16
02/19/2018 01:27:23;0100;Server@node2;Req;;Type 51 request received from Scheduler@node2.supernodexp.hpc, sock=16
02/19/2018 01:27:24;0100;Server@node2;Req;;Type 23 request received from Scheduler@node2.supernodexp.hpc, sock=16
02/19/2018 01:27:24;0008;Server@node2;Job;2991.node2.supernodexp.hpc;Job Run at request of Scheduler@node2.supernodexp.hpc on exec_vnode (node13:ncpus=48:mem=5242880kb)
02/19/2018 01:27:24;0001;Server@node2;Svr;Server@node2;Success (0) in req_runjob2, return value of svr_startjob is 0
02/19/2018 01:27:24;0100;Server@node2;Req;;Type 11 request received from Scheduler@node2.supernodexp.hpc, sock=16
02/19/2018 01:27:24;0008;Server@node2;Job;3012.node2.supernodexp.hpc;Job Modified at request of Scheduler@node2.supernodexp.hpc
02/19/2018 01:37:23;0040;Server@node2;Svr;node2.supernodexp.hpc;Scheduler sent command 3
02/19/2018 01:37:23;0040;Server@node2;Svr;node2.supernodexp.hpc;Scheduler sent command 0
02/19/2018 01:37:23;0100;Server@node2;Req;;Type 21 request received from Scheduler@node2.supernodexp.hpc, sock=16
02/19/2018 01:37:23;0100;Server@node2;Req;;Type 81 request received from Scheduler@node2.supernodexp.hpc, sock=16
02/19/2018 01:37:23;0100;Server@node2;Req;;Type 71 request received from Scheduler@node2.supernodexp.hpc, sock=16
02/19/2018 01:37:23;0100;Server@node2;Req;;Type 58 request received from Scheduler@node2.supernodexp.hpc, sock=16
02/19/2018 01:37:24;0100;Server@node2;Req;;Type 20 request received from Scheduler@node2.supernodexp.hpc, sock=16
02/19/2018 01:37:24;0100;Server@node2;Req;;Type 51 request received from Scheduler@node2.supernodexp.hpc, sock=16
02/19/2018 01:37:42;0080;Server@node2;Job;2988.node2.supernodexp.hpc;Obit received momhop:1 serverhop:1 state:4 substate:42
02/19/2018 01:37:43;0010;Server@node2;Job;2988.node2.supernodexp.hpc;Exit_status=0 resources_used.cpupercent=4730 resources_used.cput=08:15:50 resources_used.mem=7953516kb resources_used.ncpus=48 resources_used.vmem=47424212kb resources_used.walltime=00:10:39
02/19/2018 01:37:43;0100;Server@node2;Job;2988.node2.supernodexp.hpc;dequeuing from workq, state 5
02/19/2018 01:37:43;0040;Server@node2;Svr;node2.supernodexp.hpc;Scheduler sent command 2
02/19/2018 01:37:43;0040;Server@node2;Svr;node2.supernodexp.hpc;Scheduler sent command 0
02/19/2018 01:37:43;0100;Server@node2;Req;;Type 21 request received from Scheduler@node2.supernodexp.hpc, sock=16
02/19/2018 01:37:43;0100;Server@node2;Req;;Type 81 request received from Scheduler@node2.supernodexp.hpc, sock=16
02/19/2018 01:37:43;0100;Server@node2;Req;;Type 71 request received from Scheduler@node2.supernodexp.hpc, sock=16
02/19/2018 01:37:43;0100;Server@node2;Req;;Type 58 request received from Scheduler@node2.supernodexp.hpc, sock=16
02/19/2018 01:37:43;0100;Server@node2;Req;;Type 20 request received from Scheduler@node2.supernodexp.hpc, sock=16
02/19/2018 01:37:43;0100;Server@node2;Req;;Type 51 request received from Scheduler@node2.supernodexp.hpc, sock=16
02/19/2018 01:37:44;0100;Server@node2;Req;;Type 23 request received from Scheduler@node2.supernodexp.hpc, sock=16
02/19/2018 01:37:44;0008;Server@node2;Job;3012.node2.supernodexp.hpc;Job Run at request of Scheduler@node2.supernodexp.hpc on exec_vnode (node14:ncpus=48:mem=5242880kb)
02/19/2018 01:37:44;0001;Server@node2;Svr;Server@node2;Success (0) in req_runjob2, return value of svr_startjob is 0
02/19/2018 01:37:44;0100;Server@node2;Req;;Type 11 request received from Scheduler@node2.supernodexp.hpc, sock=16
02/19/2018 01:37:44;0008;Server@node2;Job;3017.node2.supernodexp.hpc;Job Modified at request of Scheduler@node2.supernodexp.hpc
02/19/2018 01:38:05;0080;Server@node2;Job;2991.node2.supernodexp.hpc;Obit received momhop:1 serverhop:1 state:4 substate:42
02/19/2018 01:38:06;0010;Server@node2;Job;2991.node2.supernodexp.hpc;Exit_status=0 resources_used.cpupercent=4740 resources_used.cput=08:22:19 resources_used.mem=7929212kb resources_used.ncpus=48 resources_used.vmem=47424648kb resources_used.walltime=00:10:42
02/19/2018 01:38:06;0100;Server@node2;Job;2991.node2.supernodexp.hpc;dequeuing from workq, state 5
02/19/2018 01:38:06;0040;Server@node2;Svr;node2.supernodexp.hpc;Scheduler sent command 2
02/19/2018 01:38:06;0040;Server@node2;Svr;node2.supernodexp.hpc;Scheduler sent command 0
02/19/2018 01:38:06;0100;Server@node2;Req;;Type 21 request received from Scheduler@node2.supernodexp.hpc, sock=16
02/19/2018 01:38:06;0100;Server@node2;Req;;Type 81 request received from Scheduler@node2.supernodexp.hpc, sock=16
02/19/2018 01:38:06;0100;Server@node2;Req;;Type 71 request received from Scheduler@node2.supernodexp.hpc, sock=16
02/19/2018 01:38:06;0100;Server@node2;Req;;Type 58 request received from Scheduler@node2.supernodexp.hpc, sock=16
02/19/2018 01:38:06;0100;Server@node2;Req;;Type 20 request received from Scheduler@node2.supernodexp.hpc, sock=16
02/19/2018 01:38:06;0100;Server@node2;Req;;Type 51 request received from Scheduler@node2.supernodexp.hpc, sock=16
02/19/2018 01:38:06;0100;Server@node2;Req;;Type 23 request received from Scheduler@node2.supernodexp.hpc, sock=16
02/19/2018 01:38:06;0008;Server@node2;Job;3017.node2.supernodexp.hpc;Job Run at request of Scheduler@node2.supernodexp.hpc on exec_vnode (node13:ncpus=48:mem=5242880kb)
02/19/2018 01:38:06;0001;Server@node2;Svr;Server@node2;Success (0) in req_runjob2, return value of svr_startjob is 0
02/19/2018 01:38:06;0100;Server@node2;Req;;Type 11 request received from Scheduler@node2.supernodexp.hpc, sock=16
02/19/2018 01:38:06;0008;Server@node2;Job;3031.node2.supernodexp.hpc;Job Modified at request of Scheduler@node2.supernodexp.hpc
02/19/2018 01:48:06;0040;Server@node2;Svr;node2.supernodexp.hpc;Scheduler sent command 3
02/19/2018 01:48:06;0040;Server@node2;Svr;node2.supernodexp.hpc;Scheduler sent command 0
02/19/2018 01:48:06;0100;Server@node2;Req;;Type 21 request received from Scheduler@node2.supernodexp.hpc, sock=16
02/19/2018 01:48:06;0100;Server@node2;Req;;Type 81 request received from Scheduler@node2.supernodexp.hpc, sock=16
02/19/2018 01:48:06;0100;Server@node2;Req;;Type 71 request received from Scheduler@node2.supernodexp.hpc, sock=16
02/19/2018 01:48:06;0100;Server@node2;Req;;Type 58 request received from Scheduler@node2.supernodexp.hpc, sock=16
02/19/2018 01:48:06;0100;Server@node2;Req;;Type 20 request received from Scheduler@node2.supernodexp.hpc, sock=16
02/19/2018 01:48:06;0100;Server@node2;Req;;Type 51 request received from Scheduler@node2.supernodexp.hpc, sock=16
02/19/2018 01:48:25;0080;Server@node2;Job;3012.node2.supernodexp.hpc;Obit received momhop:1 serverhop:1 state:4 substate:42
02/19/2018 01:48:26;0010;Server@node2;Job;3012.node2.supernodexp.hpc;Exit_status=0 resources_used.cpupercent=4747 resources_used.cput=08:16:59 resources_used.mem=7952812kb resources_used.ncpus=48 resources_used.vmem=47424192kb resources_used.walltime=00:10:41
02/19/2018 01:48:26;0100;Server@node2;Job;3012.node2.supernodexp.hpc;dequeuing from workq, state 5
02/19/2018 01:48:26;0040;Server@node2;Svr;node2.supernodexp.hpc;Scheduler sent command 2
02/19/2018 01:48:26;0040;Server@node2;Svr;node2.supernodexp.hpc;Scheduler sent command 0
02/19/2018 01:48:26;0100;Server@node2;Req;;Type 21 request received from Scheduler@node2.supernodexp.hpc, sock=16
02/19/2018 01:48:26;0100;Server@node2;Req;;Type 81 request received from Scheduler@node2.supernodexp.hpc, sock=16
02/19/2018 01:48:26;0100;Server@node2;Req;;Type 71 request received from Scheduler@node2.supernodexp.hpc, sock=16
02/19/2018 01:48:26;0100;Server@node2;Req;;Type 58 request received from Scheduler@node2.supernodexp.hpc, sock=16
02/19/2018 01:48:27;0100;Server@node2;Req;;Type 20 request received from Scheduler@node2.supernodexp.hpc, sock=16
02/19/2018 01:48:27;0100;Server@node2;Req;;Type 51 request received from Scheduler@node2.supernodexp.hpc, sock=16
02/19/2018 01:48:27;0100;Server@node2;Req;;Type 23 request received from Scheduler@node2.supernodexp.hpc, sock=16
02/19/2018 01:48:27;0008;Server@node2;Job;3031.node2.supernodexp.hpc;Job Run at request of Scheduler@node2.supernodexp.hpc on exec_vnode (node14:ncpus=48:mem=5242880kb)
02/19/2018 01:48:27;0001;Server@node2;Svr;Server@node2;Success (0) in req_runjob2, return value of svr_startjob is 0
02/19/2018 01:48:27;0100;Server@node2;Req;;Type 11 request received from Scheduler@node2.supernodexp.hpc, sock=16
02/19/2018 01:48:27;0008;Server@node2;Job;3040.node2.supernodexp.hpc;Job Modified at request of Scheduler@node2.supernodexp.hpc
02/19/2018 01:48:49;0080;Server@node2;Job;3017.node2.supernodexp.hpc;Obit received momhop:1 serverhop:1 state:4 substate:42
02/19/2018 01:48:50;0010;Server@node2;Job;3017.node2.supernodexp.hpc;Exit_status=0 resources_used.cpupercent=4739 resources_used.cput=08:19:42 resources_used.mem=7944472kb resources_used.ncpus=48 resources_used.vmem=47424940kb resources_used.walltime=00:10:43
02/19/2018 01:48:50;0100;Server@node2;Job;3017.node2.supernodexp.hpc;dequeuing from workq, state 5
02/19/2018 01:48:50;0040;Server@node2;Svr;node2.supernodexp.hpc;Scheduler sent command 2
02/19/2018 01:48:50;0040;Server@node2;Svr;node2.supernodexp.hpc;Scheduler sent command 0
02/19/2018 01:48:50;0100;Server@node2;Req;;Type 21 request received from Scheduler@node2.supernodexp.hpc, sock=16
02/19/2018 01:48:50;0100;Server@node2;Req;;Type 81 request received from Scheduler@node2.supernodexp.hpc, sock=16
02/19/2018 01:48:50;0100;Server@node2;Req;;Type 71 request received from Scheduler@node2.supernodexp.hpc, sock=16
02/19/2018 01:48:50;0100;Server@node2;Req;;Type 58 request received from Scheduler@node2.supernodexp.hpc, sock=16
02/19/2018 01:48:50;0100;Server@node2;Req;;Type 20 request received from Scheduler@node2.supernodexp.hpc, sock=16
02/19/2018 01:48:50;0100;Server@node2;Req;;Type 51 request received from Scheduler@node2.supernodexp.hpc, sock=16
02/19/2018 01:48:51;0100;Server@node2;Req;;Type 23 request received from Scheduler@node2.supernodexp.hpc, sock=16
02/19/2018 01:48:51;0008;Server@node2;Job;3040.node2.supernodexp.hpc;Job Run at request of Scheduler@node2.supernodexp.hpc on exec_vnode (node13:ncpus=48:mem=5242880kb)
02/19/2018 01:48:51;0001;Server@node2;Svr;Server@node2;Success (0) in req_runjob2, return value of svr_startjob is 0
02/19/2018 01:48:51;0100;Server@node2;Req;;Type 11 request received from Scheduler@node2.supernodexp.hpc, sock=16
02/19/2018 01:48:51;0008;Server@node2;Job;3042.node2.supernodexp.hpc;Job Modified at request of Scheduler@node2.supernodexp.hpc
02/19/2018 01:58:50;0040;Server@node2;Svr;node2.supernodexp.hpc;Scheduler sent command 3
02/19/2018 01:58:50;0040;Server@node2;Svr;node2.supernodexp.hpc;Scheduler sent command 0
02/19/2018 01:58:50;0100;Server@node2;Req;;Type 21 request received from Scheduler@node2.supernodexp.hpc, sock=16
02/19/2018 01:58:50;0100;Server@node2;Req;;Type 81 request received from Scheduler@node2.supernodexp.hpc, sock=16
02/19/2018 01:58:50;0100;Server@node2;Req;;Type 71 request received from Scheduler@node2.supernodexp.hpc, sock=16
02/19/2018 01:58:50;0100;Server@node2;Req;;Type 58 request received from Scheduler@node2.supernodexp.hpc, sock=16
02/19/2018 01:58:50;0100;Server@node2;Req;;Type 20 request received from Scheduler@node2.supernodexp.hpc, sock=16
02/19/2018 01:58:50;0100;Server@node2;Req;;Type 51 request received from Scheduler@node2.supernodexp.hpc, sock=16
02/19/2018 01:59:03;0080;Server@node2;Job;3031.node2.supernodexp.hpc;Obit received momhop:1 serverhop:1 state:4 substate:42
02/19/2018 01:59:04;0010;Server@node2;Job;3031.node2.supernodexp.hpc;Exit_status=0 resources_used.cpupercent=4729 resources_used.cput=08:17:08 resources_used.mem=7895496kb resources_used.ncpus=48 resources_used.vmem=47424828kb resources_used.walltime=00:10:36
02/19/2018 01:59:04;0100;Server@node2;Job;3031.node2.supernodexp.hpc;dequeuing from workq, state 5
02/19/2018 01:59:04;0040;Server@node2;Svr;node2.supernodexp.hpc;Scheduler sent command 2
02/19/2018 01:59:04;0040;Server@node2;Svr;node2.supernodexp.hpc;Scheduler sent command 0
02/19/2018 01:59:04;0100;Server@node2;Req;;Type 21 request received from Scheduler@node2.supernodexp.hpc, sock=16
02/19/2018 01:59:04;0100;Server@node2;Req;;Type 81 request received from Scheduler@node2.supernodexp.hpc, sock=16
02/19/2018 01:59:04;0100;Server@node2;Req;;Type 71 request received from Scheduler@node2.supernodexp.hpc, sock=16
02/19/2018 01:59:04;0100;Server@node2;Req;;Type 58 request received from Scheduler@node2.supernodexp.hpc, sock=16
02/19/2018 01:59:04;0100;Server@node2;Req;;Type 20 request received from Scheduler@node2.supernodexp.hpc, sock=16
02/19/2018 01:59:04;0100;Server@node2;Req;;Type 51 request received from Scheduler@node2.supernodexp.hpc, sock=16
02/19/2018 01:59:04;0100;Server@node2;Req;;Type 23 request received from Scheduler@node2.supernodexp.hpc, sock=16
02/19/2018 01:59:04;0008;Server@node2;Job;3042.node2.supernodexp.hpc;Job Run at request of Scheduler@node2.supernodexp.hpc on exec_vnode (node14:ncpus=48:mem=5242880kb)
02/19/2018 01:59:04;0001;Server@node2;Svr;Server@node2;Success (0) in req_runjob2, return value of svr_startjob is 0
02/19/2018 01:59:04;0100;Server@node2;Req;;Type 11 request received from Scheduler@node2.supernodexp.hpc, sock=16
02/19/2018 01:59:04;0008;Server@node2;Job;3059.node2.supernodexp.hpc;Job Modified at request of Scheduler@node2.supernodexp.hpc
02/19/2018 01:59:23;0080;Server@node2;Job;3040.node2.supernodexp.hpc;Obit received momhop:1 serverhop:1 state:4 substate:42
02/19/2018 01:59:25;0010;Server@node2;Job;3040.node2.supernodexp.hpc;Exit_status=0 resources_used.cpupercent=4739 resources_used.cput=08:16:46 resources_used.mem=7947652kb resources_used.ncpus=48 resources_used.vmem=47424924kb resources_used.walltime=00:10:33
02/19/2018 01:59:25;0100;Server@node2;Job;3040.node2.supernodexp.hpc;dequeuing from workq, state 5
02/19/2018 01:59:25;0040;Server@node2;Svr;node2.supernodexp.hpc;Scheduler sent command 2
02/19/2018 01:59:25;0040;Server@node2;Svr;node2.supernodexp.hpc;Scheduler sent command 0
02/19/2018 01:59:25;0100;Server@node2;Req;;Type 21 request received from Scheduler@node2.supernodexp.hpc, sock=16
02/19/2018 01:59:25;0100;Server@node2;Req;;Type 81 request received from Scheduler@node2.supernodexp.hpc, sock=16
02/19/2018 01:59:25;0100;Server@node2;Req;;Type 71 request received from Scheduler@node2.supernodexp.hpc, sock=16
02/19/2018 01:59:25;0100;Server@node2;Req;;Type 58 request received from Scheduler@node2.supernodexp.hpc, sock=16
02/19/2018 01:59:25;0100;Server@node2;Req;;Type 20 request received from Scheduler@node2.supernodexp.hpc, sock=16
02/19/2018 01:59:25;0100;Server@node2;Req;;Type 51 request received from Scheduler@node2.supernodexp.hpc, sock=16
02/19/2018 01:59:25;0100;Server@node2;Req;;Type 23 request received from Scheduler@node2.supernodexp.hpc, sock=16
02/19/2018 01:59:25;0008;Server@node2;Job;3059.node2.supernodexp.hpc;Job Run at request of Scheduler@node2.supernodexp.hpc on exec_vnode (node13:ncpus=48:mem=5242880kb)
02/19/2018 01:59:25;0001;Server@node2;Svr;Server@node2;Success (0) in req_runjob2, return value of svr_startjob is 0
02/19/2018 01:59:25;0100;Server@node2;Req;;Type 11 request received from Scheduler@node2.supernodexp.hpc, sock=16
02/19/2018 01:59:25;0008;Server@node2;Job;3062.node2.supernodexp.hpc;Job Modified at request of Scheduler@node2.supernodexp.hpc
02/19/2018 02:09:25;0040;Server@node2;Svr;node2.supernodexp.hpc;Scheduler sent command 3
02/19/2018 02:09:25;0040;Server@node2;Svr;node2.supernodexp.hpc;Scheduler sent command 0
02/19/2018 02:09:25;0100;Server@node2;Req;;Type 21 request received from Scheduler@node2.supernodexp.hpc, sock=16
02/19/2018 02:09:25;0100;Server@node2;Req;;Type 81 request received from Scheduler@node2.supernodexp.hpc, sock=16
02/19/2018 02:09:25;0100;Server@node2;Req;;Type 71 request received from Scheduler@node2.supernodexp.hpc, sock=16
02/19/2018 02:09:25;0100;Server@node2;Req;;Type 58 request received from Scheduler@node2.supernodexp.hpc, sock=16
02/19/2018 02:09:25;0100;Server@node2;Req;;Type 20 request received from Scheduler@node2.supernodexp.hpc, sock=16
02/19/2018 02:09:25;0100;Server@node2;Req;;Type 51 request received from Scheduler@node2.supernodexp.hpc, sock=16
02/19/2018 02:09:35;0080;Server@node2;Job;3042.node2.supernodexp.hpc;Obit received momhop:1 serverhop:1 state:4 substate:42
02/19/2018 02:09:37;0010;Server@node2;Job;3042.node2.supernodexp.hpc;Exit_status=0 resources_used.cpupercent=4736 resources_used.cput=08:13:37 resources_used.mem=7980568kb resources_used.ncpus=48 resources_used.vmem=47423892kb resources_used.walltime=00:10:31
02/19/2018 02:09:37;0100;Server@node2;Job;3042.node2.supernodexp.hpc;dequeuing from workq, state 5
02/19/2018 02:09:37;0040;Server@node2;Svr;node2.supernodexp.hpc;Scheduler sent command 2
02/19/2018 02:09:37;0040;Server@node2;Svr;node2.supernodexp.hpc;Scheduler sent command 0
02/19/2018 02:09:37;0100;Server@node2;Req;;Type 21 request received from Scheduler@node2.supernodexp.hpc, sock=16
02/19/2018 02:09:37;0100;Server@node2;Req;;Type 81 request received from Scheduler@node2.supernodexp.hpc, sock=16
02/19/2018 02:09:37;0100;Server@node2;Req;;Type 71 request received from Scheduler@node2.supernodexp.hpc, sock=16
02/19/2018 02:09:37;0100;Server@node2;Req;;Type 58 request received from Scheduler@node2.supernodexp.hpc, sock=16
02/19/2018 02:09:37;0100;Server@node2;Req;;Type 20 request received from Scheduler@node2.supernodexp.hpc, sock=16
02/19/2018 02:09:37;0100;Server@node2;Req;;Type 51 request received from Scheduler@node2.supernodexp.hpc, sock=16
02/19/2018 02:09:37;0100;Server@node2;Req;;Type 23 request received from Scheduler@node2.supernodexp.hpc, sock=16
02/19/2018 02:09:37;0008;Server@node2;Job;3062.node2.supernodexp.hpc;Job Run at request of Scheduler@node2.supernodexp.hpc on exec_vnode (node14:ncpus=48:mem=5242880kb)
02/19/2018 02:09:37;0001;Server@node2;Svr;Server@node2;Success (0) in req_runjob2, return value of svr_startjob is 0
02/19/2018 02:09:37;0100;Server@node2;Req;;Type 11 request received from Scheduler@node2.supernodexp.hpc, sock=16
02/19/2018 02:09:37;0008;Server@node2;Job;3077.node2.supernodexp.hpc;Job Modified at request of Scheduler@node2.supernodexp.hpc
02/19/2018 02:10:10;0080;Server@node2;Job;3059.node2.supernodexp.hpc;Obit received momhop:1 serverhop:1 state:4 substate:42
02/19/2018 02:10:11;0010;Server@node2;Job;3059.node2.supernodexp.hpc;Exit_status=0 resources_used.cpupercent=4742 resources_used.cput=08:19:09 resources_used.mem=7939504kb resources_used.ncpus=48 resources_used.vmem=47424928kb resources_used.walltime=00:10:46
02/19/2018 02:10:11;0100;Server@node2;Job;3059.node2.supernodexp.hpc;dequeuing from workq, state 5
02/19/2018 02:10:11;0040;Server@node2;Svr;node2.supernodexp.hpc;Scheduler sent command 2
02/19/2018 02:10:11;0040;Server@node2;Svr;node2.supernodexp.hpc;Scheduler sent command 0
02/19/2018 02:10:11;0100;Server@node2;Req;;Type 21 request received from Scheduler@node2.supernodexp.hpc, sock=16
02/19/2018 02:10:11;0100;Server@node2;Req;;Type 81 request received from Scheduler@node2.supernodexp.hpc, sock=16
02/19/2018 02:10:11;0100;Server@node2;Req;;Type 71 request received from Scheduler@node2.supernodexp.hpc, sock=16
02/19/2018 02:10:11;0100;Server@node2;Req;;Type 58 request received from Scheduler@node2.supernodexp.hpc, sock=16
02/19/2018 02:10:11;0100;Server@node2;Req;;Type 20 request received from Scheduler@node2.supernodexp.hpc, sock=16
02/19/2018 02:10:11;0100;Server@node2;Req;;Type 51 request received from Scheduler@node2.supernodexp.hpc, sock=16
02/19/2018 02:10:12;0100;Server@node2;Req;;Type 23 request received from Scheduler@node2.supernodexp.hpc, sock=16
02/19/2018 02:10:12;0008;Server@node2;Job;3077.node2.supernodexp.hpc;Job Run at request of Scheduler@node2.supernodexp.hpc on exec_vnode (node13:ncpus=48:mem=5242880kb)
02/19/2018 02:10:12;0001;Server@node2;Svr;Server@node2;Success (0) in req_runjob2, return value of svr_startjob is 0
02/19/2018 02:10:12;0100;Server@node2;Req;;Type 11 request received from Scheduler@node2.supernodexp.hpc, sock=16
02/19/2018 02:10:12;0008;Server@node2;Job;3097.node2.supernodexp.hpc;Job Modified at request of Scheduler@node2.supernodexp.hpc
02/19/2018 02:20:11;0040;Server@node2;Svr;node2.supernodexp.hpc;Scheduler sent command 3
02/19/2018 02:20:11;0040;Server@node2;Svr;node2.supernodexp.hpc;Scheduler sent command 0
02/19/2018 02:20:11;0100;Server@node2;Req;;Type 21 request received from Scheduler@node2.supernodexp.hpc, sock=16
02/19/2018 02:20:11;0100;Server@node2;Req;;Type 81 request received from Scheduler@node2.supernodexp.hpc, sock=16
02/19/2018 02:20:11;0100;Server@node2;Req;;Type 71 request received from Scheduler@node2.supernodexp.hpc, sock=16
02/19/2018 02:20:11;0100;Server@node2;Req;;Type 58 request received from Scheduler@node2.supernodexp.hpc, sock=16
02/19/2018 02:20:11;0100;Server@node2;Req;;Type 20 request received from Scheduler@node2.supernodexp.hpc, sock=16
02/19/2018 02:20:11;0100;Server@node2;Req;;Type 51 request received from Scheduler@node2.supernodexp.hpc, sock=16
02/19/2018 02:20:38;0080;Server@node2;Job;3062.node2.supernodexp.hpc;Obit received momhop:1 serverhop:1 state:4 substate:42
02/19/2018 02:20:40;0010;Server@node2;Job;3062.node2.supernodexp.hpc;Exit_status=0 resources_used.cpupercent=4747 resources_used.cput=08:24:07 resources_used.mem=7926340kb resources_used.ncpus=48 resources_used.vmem=47424180kb resources_used.walltime=00:11:01
02/19/2018 02:20:40;0100;Server@node2;Job;3062.node2.supernodexp.hpc;dequeuing from workq, state 5
02/19/2018 02:20:40;0040;Server@node2;Svr;node2.supernodexp.hpc;Scheduler sent command 2
02/19/2018 02:20:40;0040;Server@node2;Svr;node2.supernodexp.hpc;Scheduler sent command 0
02/19/2018 02:20:40;0100;Server@node2;Req;;Type 21 request received from Scheduler@node2.supernodexp.hpc, sock=16
02/19/2018 02:20:40;0100;Server@node2;Req;;Type 81 request received from Scheduler@node2.supernodexp.hpc, sock=16
02/19/2018 02:20:40;0100;Server@node2;Req;;Type 71 request received from Scheduler@node2.supernodexp.hpc, sock=16
02/19/2018 02:20:40;0100;Server@node2;Req;;Type 58 request received from Scheduler@node2.supernodexp.hpc, sock=16
02/19/2018 02:20:40;0100;Server@node2;Req;;Type 20 request received from Scheduler@node2.supernodexp.hpc, sock=16
02/19/2018 02:20:40;0100;Server@node2;Req;;Type 51 request received from Scheduler@node2.supernodexp.hpc, sock=16
02/19/2018 02:20:40;0100;Server@node2;Req;;Type 23 request received from Scheduler@node2.supernodexp.hpc, sock=16
02/19/2018 02:20:40;0008;Server@node2;Job;3097.node2.supernodexp.hpc;Job Run at request of Scheduler@node2.supernodexp.hpc on exec_vnode (node14:ncpus=48:mem=5242880kb)
02/19/2018 02:20:40;0001;Server@node2;Svr;Server@node2;Success (0) in req_runjob2, return value of svr_startjob is 0
02/19/2018 02:20:40;0100;Server@node2;Req;;Type 11 request received from Scheduler@node2.supernodexp.hpc, sock=16
02/19/2018 02:20:40;0008;Server@node2;Job;3114.node2.supernodexp.hpc;Job Modified at request of Scheduler@node2.supernodexp.hpc
02/19/2018 02:21:11;0080;Server@node2;Job;3077.node2.supernodexp.hpc;Obit received momhop:1 serverhop:1 state:4 substate:42
02/19/2018 02:21:13;0010;Server@node2;Job;3077.node2.supernodexp.hpc;Exit_status=0 resources_used.cpupercent=4736 resources_used.cput=08:40:27 resources_used.mem=7937800kb resources_used.ncpus=48 resources_used.vmem=47424956kb resources_used.walltime=00:11:00
02/19/2018 02:21:13;0100;Server@node2;Job;3077.node2.supernodexp.hpc;dequeuing from workq, state 5
02/19/2018 02:21:13;0040;Server@node2;Svr;node2.supernodexp.hpc;Scheduler sent command 2
02/19/2018 02:21:13;0040;Server@node2;Svr;node2.supernodexp.hpc;Scheduler sent command 0
02/19/2018 02:21:13;0100;Server@node2;Req;;Type 21 request received from Scheduler@node2.supernodexp.hpc, sock=16
02/19/2018 02:21:13;0100;Server@node2;Req;;Type 81 request received from Scheduler@node2.supernodexp.hpc, sock=16
02/19/2018 02:21:13;0100;Server@node2;Req;;Type 71 request received from Scheduler@node2.supernodexp.hpc, sock=16
02/19/2018 02:21:13;0100;Server@node2;Req;;Type 58 request received from Scheduler@node2.supernodexp.hpc, sock=16
02/19/2018 02:21:13;0100;Server@node2;Req;;Type 20 request received from Scheduler@node2.supernodexp.hpc, sock=16
02/19/2018 02:21:13;0100;Server@node2;Req;;Type 51 request received from Scheduler@node2.supernodexp.hpc, sock=16
02/19/2018 02:21:13;0100;Server@node2;Req;;Type 23 request received from Scheduler@node2.supernodexp.hpc, sock=16
02/19/2018 02:21:13;0008;Server@node2;Job;3114.node2.supernodexp.hpc;Job Run at request of Scheduler@node2.supernodexp.hpc on exec_vnode (node13:ncpus=48:mem=5242880kb)
02/19/2018 02:21:13;0001;Server@node2;Svr;Server@node2;Success (0) in req_runjob2, return value of svr_startjob is 0
02/19/2018 02:21:13;0100;Server@node2;Req;;Type 11 request received from Scheduler@node2.supernodexp.hpc, sock=16
02/19/2018 02:21:13;0008;Server@node2;Job;3120.node2.supernodexp.hpc;Job Modified at request of Scheduler@node2.supernodexp.hpc
02/19/2018 02:24:11;0100;Server@node2;Req;;Type 0 request received from ctminh@node2.supernodexp.hpc, sock=16
02/19/2018 02:24:11;0100;Server@node2;Req;;Type 49 request received from ctminh@node2.supernodexp.hpc, sock=20
02/19/2018 02:24:11;0100;Server@node2;Req;;Type 21 request received from ctminh@node2.supernodexp.hpc, sock=16
02/19/2018 02:24:11;0100;Server@node2;Req;;Type 19 request received from ctminh@node2.supernodexp.hpc, sock=16
02/19/2018 02:31:13;0040;Server@node2;Svr;node2.supernodexp.hpc;Scheduler sent command 3
02/19/2018 02:31:13;0040;Server@node2;Svr;node2.supernodexp.hpc;Scheduler sent command 0
02/19/2018 02:31:13;0100;Server@node2;Req;;Type 21 request received from Scheduler@node2.supernodexp.hpc, sock=16
02/19/2018 02:31:13;0100;Server@node2;Req;;Type 81 request received from Scheduler@node2.supernodexp.hpc, sock=16
02/19/2018 02:31:13;0100;Server@node2;Req;;Type 71 request received from Scheduler@node2.supernodexp.hpc, sock=16
02/19/2018 02:31:13;0100;Server@node2;Req;;Type 58 request received from Scheduler@node2.supernodexp.hpc, sock=16
02/19/2018 02:31:13;0100;Server@node2;Req;;Type 20 request received from Scheduler@node2.supernodexp.hpc, sock=16
02/19/2018 02:31:13;0100;Server@node2;Req;;Type 51 request received from Scheduler@node2.supernodexp.hpc, sock=16
02/19/2018 02:31:31;0080;Server@node2;Job;3097.node2.supernodexp.hpc;Obit received momhop:1 serverhop:1 state:4 substate:42
02/19/2018 02:31:33;0010;Server@node2;Job;3097.node2.supernodexp.hpc;Exit_status=0 resources_used.cpupercent=4739 resources_used.cput=08:22:15 resources_used.mem=7866400kb resources_used.ncpus=48 resources_used.vmem=47424240kb resources_used.walltime=00:10:51
02/19/2018 02:31:33;0100;Server@node2;Job;3097.node2.supernodexp.hpc;dequeuing from workq, state 5
02/19/2018 02:31:33;0040;Server@node2;Svr;node2.supernodexp.hpc;Scheduler sent command 2
02/19/2018 02:31:33;0040;Server@node2;Svr;node2.supernodexp.hpc;Scheduler sent command 0
02/19/2018 02:31:33;0100;Server@node2;Req;;Type 21 request received from Scheduler@node2.supernodexp.hpc, sock=16
02/19/2018 02:31:33;0100;Server@node2;Req;;Type 81 request received from Scheduler@node2.supernodexp.hpc, sock=16
02/19/2018 02:31:33;0100;Server@node2;Req;;Type 71 request received from Scheduler@node2.supernodexp.hpc, sock=16
02/19/2018 02:31:33;0100;Server@node2;Req;;Type 58 request received from Scheduler@node2.supernodexp.hpc, sock=16
02/19/2018 02:31:33;0100;Server@node2;Req;;Type 20 request received from Scheduler@node2.supernodexp.hpc, sock=16
02/19/2018 02:31:33;0100;Server@node2;Req;;Type 51 request received from Scheduler@node2.supernodexp.hpc, sock=16
02/19/2018 02:31:33;0100;Server@node2;Req;;Type 23 request received from Scheduler@node2.supernodexp.hpc, sock=16
02/19/2018 02:31:33;0008;Server@node2;Job;3120.node2.supernodexp.hpc;Job Run at request of Scheduler@node2.supernodexp.hpc on exec_vnode (node14:ncpus=48:mem=5242880kb)
02/19/2018 02:31:33;0001;Server@node2;Svr;Server@node2;Success (0) in req_runjob2, return value of svr_startjob is 0
02/19/2018 02:31:33;0100;Server@node2;Req;;Type 11 request received from Scheduler@node2.supernodexp.hpc, sock=16
02/19/2018 02:31:33;0008;Server@node2;Job;3129.node2.supernodexp.hpc;Job Modified at request of Scheduler@node2.supernodexp.hpc
02/19/2018 02:32:19;0080;Server@node2;Job;3114.node2.supernodexp.hpc;Obit received momhop:1 serverhop:1 state:4 substate:42
02/19/2018 02:32:21;0010;Server@node2;Job;3114.node2.supernodexp.hpc;Exit_status=0 resources_used.cpupercent=4704 resources_used.cput=08:23:47 resources_used.mem=7932428kb resources_used.ncpus=48 resources_used.vmem=47424036kb resources_used.walltime=00:11:07
02/19/2018 02:32:21;0100;Server@node2;Job;3114.node2.supernodexp.hpc;dequeuing from workq, state 5
02/19/2018 02:32:21;0040;Server@node2;Svr;node2.supernodexp.hpc;Scheduler sent command 2
02/19/2018 02:32:21;0040;Server@node2;Svr;node2.supernodexp.hpc;Scheduler sent command 0
02/19/2018 02:32:21;0100;Server@node2;Req;;Type 21 request received from Scheduler@node2.supernodexp.hpc, sock=16
02/19/2018 02:32:21;0100;Server@node2;Req;;Type 81 request received from Scheduler@node2.supernodexp.hpc, sock=16
02/19/2018 02:32:21;0100;Server@node2;Req;;Type 71 request received from Scheduler@node2.supernodexp.hpc, sock=16
02/19/2018 02:32:21;0100;Server@node2;Req;;Type 58 request received from Scheduler@node2.supernodexp.hpc, sock=16
02/19/2018 02:32:21;0100;Server@node2;Req;;Type 20 request received from Scheduler@node2.supernodexp.hpc, sock=16
02/19/2018 02:32:21;0100;Server@node2;Req;;Type 51 request received from Scheduler@node2.supernodexp.hpc, sock=16
02/19/2018 02:32:21;0100;Server@node2;Req;;Type 23 request received from Scheduler@node2.supernodexp.hpc, sock=16
02/19/2018 02:32:21;0008;Server@node2;Job;3129.node2.supernodexp.hpc;Job Run at request of Scheduler@node2.supernodexp.hpc on exec_vnode (node13:ncpus=48:mem=5242880kb)
02/19/2018 02:32:21;0001;Server@node2;Svr;Server@node2;Success (0) in req_runjob2, return value of svr_startjob is 0
02/19/2018 02:32:21;0100;Server@node2;Req;;Type 11 request received from Scheduler@node2.supernodexp.hpc, sock=16
02/19/2018 02:32:21;0008;Server@node2;Job;3131.node2.supernodexp.hpc;Job Modified at request of Scheduler@node2.supernodexp.hpc
02/19/2018 02:42:21;0040;Server@node2;Svr;node2.supernodexp.hpc;Scheduler sent command 3
02/19/2018 02:42:21;0040;Server@node2;Svr;node2.supernodexp.hpc;Scheduler sent command 0
02/19/2018 02:42:21;0100;Server@node2;Req;;Type 21 request received from Scheduler@node2.supernodexp.hpc, sock=16
02/19/2018 02:42:21;0100;Server@node2;Req;;Type 81 request received from Scheduler@node2.supernodexp.hpc, sock=16
02/19/2018 02:42:21;0100;Server@node2;Req;;Type 71 request received from Scheduler@node2.supernodexp.hpc, sock=16
02/19/2018 02:42:21;0100;Server@node2;Req;;Type 58 request received from Scheduler@node2.supernodexp.hpc, sock=16
02/19/2018 02:42:21;0100;Server@node2;Req;;Type 20 request received from Scheduler@node2.supernodexp.hpc, sock=16
02/19/2018 02:42:21;0100;Server@node2;Req;;Type 51 request received from Scheduler@node2.supernodexp.hpc, sock=16
02/19/2018 02:42:25;0080;Server@node2;Job;3120.node2.supernodexp.hpc;Obit received momhop:1 serverhop:1 state:4 substate:42
02/19/2018 02:42:27;0010;Server@node2;Job;3120.node2.supernodexp.hpc;Exit_status=0 resources_used.cpupercent=4741 resources_used.cput=08:28:40 resources_used.mem=7922728kb resources_used.ncpus=48 resources_used.vmem=47423792kb resources_used.walltime=00:10:53
02/19/2018 02:42:27;0100;Server@node2;Job;3120.node2.supernodexp.hpc;dequeuing from workq, state 5
02/19/2018 02:42:27;0040;Server@node2;Svr;node2.supernodexp.hpc;Scheduler sent command 2
02/19/2018 02:42:27;0040;Server@node2;Svr;node2.supernodexp.hpc;Scheduler sent command 0
02/19/2018 02:42:27;0100;Server@node2;Req;;Type 21 request received from Scheduler@node2.supernodexp.hpc, sock=16
02/19/2018 02:42:27;0100;Server@node2;Req;;Type 81 request received from Scheduler@node2.supernodexp.hpc, sock=16
02/19/2018 02:42:27;0100;Server@node2;Req;;Type 71 request received from Scheduler@node2.supernodexp.hpc, sock=16
02/19/2018 02:42:27;0100;Server@node2;Req;;Type 58 request received from Scheduler@node2.supernodexp.hpc, sock=16
02/19/2018 02:42:27;0100;Server@node2;Req;;Type 20 request received from Scheduler@node2.supernodexp.hpc, sock=16
02/19/2018 02:42:27;0100;Server@node2;Req;;Type 51 request received from Scheduler@node2.supernodexp.hpc, sock=16
02/19/2018 02:42:27;0100;Server@node2;Req;;Type 23 request received from Scheduler@node2.supernodexp.hpc, sock=16
02/19/2018 02:42:27;0008;Server@node2;Job;3131.node2.supernodexp.hpc;Job Run at request of Scheduler@node2.supernodexp.hpc on exec_vnode (node14:ncpus=48:mem=5242880kb)
02/19/2018 02:42:27;0001;Server@node2;Svr;Server@node2;Success (0) in req_runjob2, return value of svr_startjob is 0
02/19/2018 02:42:27;0100;Server@node2;Req;;Type 11 request received from Scheduler@node2.supernodexp.hpc, sock=16
02/19/2018 02:42:27;0008;Server@node2;Job;3139.node2.supernodexp.hpc;Job Modified at request of Scheduler@node2.supernodexp.hpc
02/19/2018 02:43:15;0080;Server@node2;Job;3129.node2.supernodexp.hpc;Obit received momhop:1 serverhop:1 state:4 substate:42
02/19/2018 02:43:16;0010;Server@node2;Job;3129.node2.supernodexp.hpc;Exit_status=0 resources_used.cpupercent=4727 resources_used.cput=08:19:08 resources_used.mem=7963864kb resources_used.ncpus=48 resources_used.vmem=47425236kb resources_used.walltime=00:10:55
02/19/2018 02:43:16;0100;Server@node2;Job;3129.node2.supernodexp.hpc;dequeuing from workq, state 5
02/19/2018 02:43:16;0040;Server@node2;Svr;node2.supernodexp.hpc;Scheduler sent command 2
02/19/2018 02:43:16;0040;Server@node2;Svr;node2.supernodexp.hpc;Scheduler sent command 0
02/19/2018 02:43:16;0100;Server@node2;Req;;Type 21 request received from Scheduler@node2.supernodexp.hpc, sock=16
02/19/2018 02:43:16;0100;Server@node2;Req;;Type 81 request received from Scheduler@node2.supernodexp.hpc, sock=16
02/19/2018 02:43:16;0100;Server@node2;Req;;Type 71 request received from Scheduler@node2.supernodexp.hpc, sock=16
02/19/2018 02:43:16;0100;Server@node2;Req;;Type 58 request received from Scheduler@node2.supernodexp.hpc, sock=16
02/19/2018 02:43:16;0100;Server@node2;Req;;Type 20 request received from Scheduler@node2.supernodexp.hpc, sock=16
02/19/2018 02:43:16;0100;Server@node2;Req;;Type 51 request received from Scheduler@node2.supernodexp.hpc, sock=16
02/19/2018 02:43:16;0100;Server@node2;Req;;Type 23 request received from Scheduler@node2.supernodexp.hpc, sock=16
02/19/2018 02:43:16;0008;Server@node2;Job;3139.node2.supernodexp.hpc;Job Run at request of Scheduler@node2.supernodexp.hpc on exec_vnode (node13:ncpus=48:mem=5242880kb)
02/19/2018 02:43:16;0001;Server@node2;Svr;Server@node2;Success (0) in req_runjob2, return value of svr_startjob is 0
02/19/2018 02:43:16;0100;Server@node2;Req;;Type 11 request received from Scheduler@node2.supernodexp.hpc, sock=16
02/19/2018 02:43:16;0008;Server@node2;Job;3150.node2.supernodexp.hpc;Job Modified at request of Scheduler@node2.supernodexp.hpc
02/19/2018 02:52:56;0080;Server@node2;Job;3131.node2.supernodexp.hpc;Obit received momhop:1 serverhop:1 state:4 substate:42
02/19/2018 02:52:57;0010;Server@node2;Job;3131.node2.supernodexp.hpc;Exit_status=0 resources_used.cpupercent=4746 resources_used.cput=08:12:45 resources_used.mem=7944472kb resources_used.ncpus=48 resources_used.vmem=47424484kb resources_used.walltime=00:10:29
02/19/2018 02:52:57;0100;Server@node2;Job;3131.node2.supernodexp.hpc;dequeuing from workq, state 5
02/19/2018 02:52:57;0040;Server@node2;Svr;node2.supernodexp.hpc;Scheduler sent command 2
02/19/2018 02:52:57;0040;Server@node2;Svr;node2.supernodexp.hpc;Scheduler sent command 0
02/19/2018 02:52:57;0100;Server@node2;Req;;Type 21 request received from Scheduler@node2.supernodexp.hpc, sock=16
02/19/2018 02:52:57;0100;Server@node2;Req;;Type 81 request received from Scheduler@node2.supernodexp.hpc, sock=16
02/19/2018 02:52:57;0100;Server@node2;Req;;Type 71 request received from Scheduler@node2.supernodexp.hpc, sock=16
02/19/2018 02:52:57;0100;Server@node2;Req;;Type 58 request received from Scheduler@node2.supernodexp.hpc, sock=16
02/19/2018 02:52:57;0100;Server@node2;Req;;Type 20 request received from Scheduler@node2.supernodexp.hpc, sock=16
02/19/2018 02:52:57;0100;Server@node2;Req;;Type 51 request received from Scheduler@node2.supernodexp.hpc, sock=16
02/19/2018 02:52:57;0100;Server@node2;Req;;Type 23 request received from Scheduler@node2.supernodexp.hpc, sock=16
02/19/2018 02:52:57;0008;Server@node2;Job;3150.node2.supernodexp.hpc;Job Run at request of Scheduler@node2.supernodexp.hpc on exec_vnode (node14:ncpus=48:mem=5242880kb)
02/19/2018 02:52:57;0001;Server@node2;Svr;Server@node2;Success (0) in req_runjob2, return value of svr_startjob is 0
02/19/2018 02:52:57;0100;Server@node2;Req;;Type 11 request received from Scheduler@node2.supernodexp.hpc, sock=16
02/19/2018 02:52:57;0008;Server@node2;Job;3158.node2.supernodexp.hpc;Job Modified at request of Scheduler@node2.supernodexp.hpc
02/19/2018 02:53:44;0080;Server@node2;Job;3139.node2.supernodexp.hpc;Obit received momhop:1 serverhop:1 state:4 substate:42
02/19/2018 02:53:45;0010;Server@node2;Job;3139.node2.supernodexp.hpc;Exit_status=0 resources_used.cpupercent=4739 resources_used.cput=08:10:54 resources_used.mem=7974228kb resources_used.ncpus=48 resources_used.vmem=47424324kb resources_used.walltime=00:10:27
02/19/2018 02:53:45;0100;Server@node2;Job;3139.node2.supernodexp.hpc;dequeuing from workq, state 5
02/19/2018 02:53:45;0040;Server@node2;Svr;node2.supernodexp.hpc;Scheduler sent command 2
02/19/2018 02:53:45;0040;Server@node2;Svr;node2.supernodexp.hpc;Scheduler sent command 0
02/19/2018 02:53:45;0100;Server@node2;Req;;Type 21 request received from Scheduler@node2.supernodexp.hpc, sock=16
02/19/2018 02:53:45;0100;Server@node2;Req;;Type 81 request received from Scheduler@node2.supernodexp.hpc, sock=16
02/19/2018 02:53:45;0100;Server@node2;Req;;Type 71 request received from Scheduler@node2.supernodexp.hpc, sock=16
02/19/2018 02:53:45;0100;Server@node2;Req;;Type 58 request received from Scheduler@node2.supernodexp.hpc, sock=16
02/19/2018 02:53:45;0100;Server@node2;Req;;Type 20 request received from Scheduler@node2.supernodexp.hpc, sock=16
02/19/2018 02:53:45;0100;Server@node2;Req;;Type 51 request received from Scheduler@node2.supernodexp.hpc, sock=16
02/19/2018 02:53:45;0100;Server@node2;Req;;Type 23 request received from Scheduler@node2.supernodexp.hpc, sock=16
02/19/2018 02:53:45;0008;Server@node2;Job;3158.node2.supernodexp.hpc;Job Run at request of Scheduler@node2.supernodexp.hpc on exec_vnode (node13:ncpus=48:mem=5242880kb)
02/19/2018 02:53:45;0001;Server@node2;Svr;Server@node2;Success (0) in req_runjob2, return value of svr_startjob is 0
02/19/2018 02:53:45;0100;Server@node2;Req;;Type 11 request received from Scheduler@node2.supernodexp.hpc, sock=16
02/19/2018 02:53:45;0008;Server@node2;Job;3161.node2.supernodexp.hpc;Job Modified at request of Scheduler@node2.supernodexp.hpc
02/19/2018 03:03:42;0080;Server@node2;Job;3150.node2.supernodexp.hpc;Obit received momhop:1 serverhop:1 state:4 substate:42
02/19/2018 03:03:43;0010;Server@node2;Job;3150.node2.supernodexp.hpc;Exit_status=0 resources_used.cpupercent=4762 resources_used.cput=08:16:33 resources_used.mem=7941448kb resources_used.ncpus=48 resources_used.vmem=47424120kb resources_used.walltime=00:10:44
02/19/2018 03:03:43;0100;Server@node2;Job;3150.node2.supernodexp.hpc;dequeuing from workq, state 5
02/19/2018 03:03:43;0040;Server@node2;Svr;node2.supernodexp.hpc;Scheduler sent command 2
02/19/2018 03:03:43;0040;Server@node2;Svr;node2.supernodexp.hpc;Scheduler sent command 0
02/19/2018 03:03:43;0100;Server@node2;Req;;Type 21 request received from Scheduler@node2.supernodexp.hpc, sock=16
02/19/2018 03:03:43;0100;Server@node2;Req;;Type 81 request received from Scheduler@node2.supernodexp.hpc, sock=16
02/19/2018 03:03:43;0100;Server@node2;Req;;Type 71 request received from Scheduler@node2.supernodexp.hpc, sock=16
02/19/2018 03:03:43;0100;Server@node2;Req;;Type 58 request received from Scheduler@node2.supernodexp.hpc, sock=16
02/19/2018 03:03:43;0100;Server@node2;Req;;Type 20 request received from Scheduler@node2.supernodexp.hpc, sock=16
02/19/2018 03:03:43;0100;Server@node2;Req;;Type 51 request received from Scheduler@node2.supernodexp.hpc, sock=16
02/19/2018 03:03:43;0100;Server@node2;Req;;Type 23 request received from Scheduler@node2.supernodexp.hpc, sock=16
02/19/2018 03:03:43;0008;Server@node2;Job;3161.node2.supernodexp.hpc;Job Run at request of Scheduler@node2.supernodexp.hpc on exec_vnode (node14:ncpus=48:mem=5242880kb)
02/19/2018 03:03:43;0001;Server@node2;Svr;Server@node2;Success (0) in req_runjob2, return value of svr_startjob is 0
02/19/2018 03:03:43;0100;Server@node2;Req;;Type 11 request received from Scheduler@node2.supernodexp.hpc, sock=16
02/19/2018 03:03:43;0008;Server@node2;Job;3164.node2.supernodexp.hpc;Job Modified at request of Scheduler@node2.supernodexp.hpc
02/19/2018 03:04:46;0080;Server@node2;Job;3158.node2.supernodexp.hpc;Obit received momhop:1 serverhop:1 state:4 substate:42
02/19/2018 03:04:47;0010;Server@node2;Job;3158.node2.supernodexp.hpc;Exit_status=0 resources_used.cpupercent=4785 resources_used.cput=08:46:16 resources_used.mem=7923696kb resources_used.ncpus=48 resources_used.vmem=47424328kb resources_used.walltime=00:11:01
02/19/2018 03:04:47;0100;Server@node2;Job;3158.node2.supernodexp.hpc;dequeuing from workq, state 5
02/19/2018 03:04:47;0040;Server@node2;Svr;node2.supernodexp.hpc;Scheduler sent command 2
02/19/2018 03:04:47;0040;Server@node2;Svr;node2.supernodexp.hpc;Scheduler sent command 0
02/19/2018 03:04:47;0100;Server@node2;Req;;Type 21 request received from Scheduler@node2.supernodexp.hpc, sock=16
02/19/2018 03:04:47;0100;Server@node2;Req;;Type 81 request received from Scheduler@node2.supernodexp.hpc, sock=16
02/19/2018 03:04:47;0100;Server@node2;Req;;Type 71 request received from Scheduler@node2.supernodexp.hpc, sock=16
02/19/2018 03:04:47;0100;Server@node2;Req;;Type 58 request received from Scheduler@node2.supernodexp.hpc, sock=16
02/19/2018 03:04:47;0100;Server@node2;Req;;Type 20 request received from Scheduler@node2.supernodexp.hpc, sock=16
02/19/2018 03:04:47;0100;Server@node2;Req;;Type 51 request received from Scheduler@node2.supernodexp.hpc, sock=16
02/19/2018 03:04:47;0100;Server@node2;Req;;Type 23 request received from Scheduler@node2.supernodexp.hpc, sock=16
02/19/2018 03:04:47;0008;Server@node2;Job;3164.node2.supernodexp.hpc;Job Run at request of Scheduler@node2.supernodexp.hpc on exec_vnode (node13:ncpus=48:mem=5242880kb)
02/19/2018 03:04:47;0001;Server@node2;Svr;Server@node2;Success (0) in req_runjob2, return value of svr_startjob is 0
02/19/2018 03:04:47;0100;Server@node2;Req;;Type 11 request received from Scheduler@node2.supernodexp.hpc, sock=16
02/19/2018 03:04:47;0008;Server@node2;Job;3190.node2.supernodexp.hpc;Job Modified at request of Scheduler@node2.supernodexp.hpc
02/19/2018 03:14:34;0080;Server@node2;Job;3161.node2.supernodexp.hpc;Obit received momhop:1 serverhop:1 state:4 substate:42
02/19/2018 03:14:36;0010;Server@node2;Job;3161.node2.supernodexp.hpc;Exit_status=0 resources_used.cpupercent=4745 resources_used.cput=08:12:51 resources_used.mem=7967884kb resources_used.ncpus=48 resources_used.vmem=47423776kb resources_used.walltime=00:10:51
02/19/2018 03:14:36;0100;Server@node2;Job;3161.node2.supernodexp.hpc;dequeuing from workq, state 5
02/19/2018 03:14:36;0040;Server@node2;Svr;node2.supernodexp.hpc;Scheduler sent command 2
02/19/2018 03:14:36;0040;Server@node2;Svr;node2.supernodexp.hpc;Scheduler sent command 0
02/19/2018 03:14:36;0100;Server@node2;Req;;Type 21 request received from Scheduler@node2.supernodexp.hpc, sock=16
02/19/2018 03:14:36;0100;Server@node2;Req;;Type 81 request received from Scheduler@node2.supernodexp.hpc, sock=16
02/19/2018 03:14:36;0100;Server@node2;Req;;Type 71 request received from Scheduler@node2.supernodexp.hpc, sock=16
02/19/2018 03:14:36;0100;Server@node2;Req;;Type 58 request received from Scheduler@node2.supernodexp.hpc, sock=16
02/19/2018 03:14:36;0100;Server@node2;Req;;Type 20 request received from Scheduler@node2.supernodexp.hpc, sock=16
02/19/2018 03:14:36;0100;Server@node2;Req;;Type 51 request received from Scheduler@node2.supernodexp.hpc, sock=16
02/19/2018 03:14:36;0100;Server@node2;Req;;Type 23 request received from Scheduler@node2.supernodexp.hpc, sock=16
02/19/2018 03:14:36;0008;Server@node2;Job;3190.node2.supernodexp.hpc;Job Run at request of Scheduler@node2.supernodexp.hpc on exec_vnode (node14:ncpus=48:mem=5242880kb)
02/19/2018 03:14:36;0001;Server@node2;Svr;Server@node2;Success (0) in req_runjob2, return value of svr_startjob is 0
02/19/2018 03:14:36;0100;Server@node2;Req;;Type 11 request received from Scheduler@node2.supernodexp.hpc, sock=16
02/19/2018 03:14:36;0008;Server@node2;Job;3198.node2.supernodexp.hpc;Job Modified at request of Scheduler@node2.supernodexp.hpc
02/19/2018 03:15:47;0080;Server@node2;Job;3164.node2.supernodexp.hpc;Obit received momhop:1 serverhop:1 state:4 substate:42
02/19/2018 03:15:48;0010;Server@node2;Job;3164.node2.supernodexp.hpc;Exit_status=0 resources_used.cpupercent=4732 resources_used.cput=08:25:55 resources_used.mem=7922932kb resources_used.ncpus=48 resources_used.vmem=47424620kb resources_used.walltime=00:10:59
02/19/2018 03:15:48;0100;Server@node2;Job;3164.node2.supernodexp.hpc;dequeuing from workq, state 5
02/19/2018 03:15:48;0040;Server@node2;Svr;node2.supernodexp.hpc;Scheduler sent command 2
02/19/2018 03:15:48;0040;Server@node2;Svr;node2.supernodexp.hpc;Scheduler sent command 0
02/19/2018 03:15:48;0100;Server@node2;Req;;Type 21 request received from Scheduler@node2.supernodexp.hpc, sock=16
02/19/2018 03:15:48;0100;Server@node2;Req;;Type 81 request received from Scheduler@node2.supernodexp.hpc, sock=16
02/19/2018 03:15:48;0100;Server@node2;Req;;Type 71 request received from Scheduler@node2.supernodexp.hpc, sock=16
02/19/2018 03:15:48;0100;Server@node2;Req;;Type 58 request received from Scheduler@node2.supernodexp.hpc, sock=16
02/19/2018 03:15:48;0100;Server@node2;Req;;Type 20 request received from Scheduler@node2.supernodexp.hpc, sock=16
02/19/2018 03:15:48;0100;Server@node2;Req;;Type 51 request received from Scheduler@node2.supernodexp.hpc, sock=16
02/19/2018 03:15:48;0100;Server@node2;Req;;Type 23 request received from Scheduler@node2.supernodexp.hpc, sock=16
02/19/2018 03:15:48;0008;Server@node2;Job;3198.node2.supernodexp.hpc;Job Run at request of Scheduler@node2.supernodexp.hpc on exec_vnode (node13:ncpus=48:mem=5242880kb)
02/19/2018 03:15:48;0001;Server@node2;Svr;Server@node2;Success (0) in req_runjob2, return value of svr_startjob is 0
02/19/2018 03:15:48;0100;Server@node2;Req;;Type 11 request received from Scheduler@node2.supernodexp.hpc, sock=16
02/19/2018 03:15:48;0008;Server@node2;Job;3200.node2.supernodexp.hpc;Job Modified at request of Scheduler@node2.supernodexp.hpc
02/19/2018 03:25:11;0080;Server@node2;Job;3190.node2.supernodexp.hpc;Obit received momhop:1 serverhop:1 state:4 substate:42
02/19/2018 03:25:12;0010;Server@node2;Job;3190.node2.supernodexp.hpc;Exit_status=0 resources_used.cpupercent=4737 resources_used.cput=08:25:20 resources_used.mem=7950844kb resources_used.ncpus=48 resources_used.vmem=47424528kb resources_used.walltime=00:10:35
02/19/2018 03:25:12;0100;Server@node2;Job;3190.node2.supernodexp.hpc;dequeuing from workq, state 5
02/19/2018 03:25:12;0040;Server@node2;Svr;node2.supernodexp.hpc;Scheduler sent command 2
02/19/2018 03:25:12;0040;Server@node2;Svr;node2.supernodexp.hpc;Scheduler sent command 0
02/19/2018 03:25:12;0100;Server@node2;Req;;Type 21 request received from Scheduler@node2.supernodexp.hpc, sock=16
02/19/2018 03:25:12;0100;Server@node2;Req;;Type 81 request received from Scheduler@node2.supernodexp.hpc, sock=16
02/19/2018 03:25:12;0100;Server@node2;Req;;Type 71 request received from Scheduler@node2.supernodexp.hpc, sock=16
02/19/2018 03:25:12;0100;Server@node2;Req;;Type 58 request received from Scheduler@node2.supernodexp.hpc, sock=16
02/19/2018 03:25:12;0100;Server@node2;Req;;Type 20 request received from Scheduler@node2.supernodexp.hpc, sock=16
02/19/2018 03:25:12;0100;Server@node2;Req;;Type 51 request received from Scheduler@node2.supernodexp.hpc, sock=16
02/19/2018 03:25:12;0100;Server@node2;Req;;Type 23 request received from Scheduler@node2.supernodexp.hpc, sock=16
02/19/2018 03:25:12;0008;Server@node2;Job;3200.node2.supernodexp.hpc;Job Run at request of Scheduler@node2.supernodexp.hpc on exec_vnode (node14:ncpus=48:mem=5242880kb)
02/19/2018 03:25:12;0001;Server@node2;Svr;Server@node2;Success (0) in req_runjob2, return value of svr_startjob is 0
02/19/2018 03:25:12;0100;Server@node2;Req;;Type 11 request received from Scheduler@node2.supernodexp.hpc, sock=16
02/19/2018 03:25:12;0008;Server@node2;Job;3218.node2.supernodexp.hpc;Job Modified at request of Scheduler@node2.supernodexp.hpc
02/19/2018 03:26:19;0080;Server@node2;Job;3198.node2.supernodexp.hpc;Obit received momhop:1 serverhop:1 state:4 substate:42
02/19/2018 03:26:21;0010;Server@node2;Job;3198.node2.supernodexp.hpc;Exit_status=0 resources_used.cpupercent=4749 resources_used.cput=08:14:39 resources_used.mem=7957628kb resources_used.ncpus=48 resources_used.vmem=47424352kb resources_used.walltime=00:10:31
02/19/2018 03:26:21;0100;Server@node2;Job;3198.node2.supernodexp.hpc;dequeuing from workq, state 5
02/19/2018 03:26:21;0040;Server@node2;Svr;node2.supernodexp.hpc;Scheduler sent command 2
02/19/2018 03:26:21;0040;Server@node2;Svr;node2.supernodexp.hpc;Scheduler sent command 0
02/19/2018 03:26:21;0100;Server@node2;Req;;Type 21 request received from Scheduler@node2.supernodexp.hpc, sock=16
02/19/2018 03:26:21;0100;Server@node2;Req;;Type 81 request received from Scheduler@node2.supernodexp.hpc, sock=16
02/19/2018 03:26:21;0100;Server@node2;Req;;Type 71 request received from Scheduler@node2.supernodexp.hpc, sock=16
02/19/2018 03:26:21;0100;Server@node2;Req;;Type 58 request received from Scheduler@node2.supernodexp.hpc, sock=16
02/19/2018 03:26:21;0100;Server@node2;Req;;Type 20 request received from Scheduler@node2.supernodexp.hpc, sock=16
02/19/2018 03:26:21;0100;Server@node2;Req;;Type 51 request received from Scheduler@node2.supernodexp.hpc, sock=16
02/19/2018 03:26:21;0100;Server@node2;Req;;Type 23 request received from Scheduler@node2.supernodexp.hpc, sock=16
02/19/2018 03:26:21;0008;Server@node2;Job;3218.node2.supernodexp.hpc;Job Run at request of Scheduler@node2.supernodexp.hpc on exec_vnode (node13:ncpus=48:mem=5242880kb)
02/19/2018 03:26:21;0001;Server@node2;Svr;Server@node2;Success (0) in req_runjob2, return value of svr_startjob is 0
02/19/2018 03:26:21;0100;Server@node2;Req;;Type 11 request received from Scheduler@node2.supernodexp.hpc, sock=16
02/19/2018 03:26:21;0008;Server@node2;Job;3237.node2.supernodexp.hpc;Job Modified at request of Scheduler@node2.supernodexp.hpc
02/19/2018 03:35:35;0080;Server@node2;Job;3200.node2.supernodexp.hpc;Obit received momhop:1 serverhop:1 state:4 substate:42
02/19/2018 03:35:37;0010;Server@node2;Job;3200.node2.supernodexp.hpc;Exit_status=0 resources_used.cpupercent=4668 resources_used.cput=08:05:15 resources_used.mem=7983764kb resources_used.ncpus=48 resources_used.vmem=47423816kb resources_used.walltime=00:10:23
02/19/2018 03:35:37;0100;Server@node2;Job;3200.node2.supernodexp.hpc;dequeuing from workq, state 5
02/19/2018 03:35:37;0040;Server@node2;Svr;node2.supernodexp.hpc;Scheduler sent command 2
02/19/2018 03:35:37;0040;Server@node2;Svr;node2.supernodexp.hpc;Scheduler sent command 0
02/19/2018 03:35:37;0100;Server@node2;Req;;Type 21 request received from Scheduler@node2.supernodexp.hpc, sock=16
02/19/2018 03:35:37;0100;Server@node2;Req;;Type 81 request received from Scheduler@node2.supernodexp.hpc, sock=16
02/19/2018 03:35:37;0100;Server@node2;Req;;Type 71 request received from Scheduler@node2.supernodexp.hpc, sock=16
02/19/2018 03:35:37;0100;Server@node2;Req;;Type 58 request received from Scheduler@node2.supernodexp.hpc, sock=16
02/19/2018 03:35:37;0100;Server@node2;Req;;Type 20 request received from Scheduler@node2.supernodexp.hpc, sock=16
02/19/2018 03:35:37;0100;Server@node2;Req;;Type 51 request received from Scheduler@node2.supernodexp.hpc, sock=16
02/19/2018 03:35:37;0100;Server@node2;Req;;Type 23 request received from Scheduler@node2.supernodexp.hpc, sock=16
02/19/2018 03:35:37;0008;Server@node2;Job;3237.node2.supernodexp.hpc;Job Run at request of Scheduler@node2.supernodexp.hpc on exec_vnode (node14:ncpus=48:mem=5242880kb)
02/19/2018 03:35:37;0001;Server@node2;Svr;Server@node2;Success (0) in req_runjob2, return value of svr_startjob is 0
02/19/2018 03:35:37;0100;Server@node2;Req;;Type 11 request received from Scheduler@node2.supernodexp.hpc, sock=16
02/19/2018 03:35:37;0008;Server@node2;Job;3246.node2.supernodexp.hpc;Job Modified at request of Scheduler@node2.supernodexp.hpc
02/19/2018 03:37:08;0080;Server@node2;Job;3218.node2.supernodexp.hpc;Obit received momhop:1 serverhop:1 state:4 substate:42
02/19/2018 03:37:09;0010;Server@node2;Job;3218.node2.supernodexp.hpc;Exit_status=0 resources_used.cpupercent=4784 resources_used.cput=08:19:02 resources_used.mem=7900680kb resources_used.ncpus=48 resources_used.vmem=47424616kb resources_used.walltime=00:10:47
02/19/2018 03:37:09;0100;Server@node2;Job;3218.node2.supernodexp.hpc;dequeuing from workq, state 5
02/19/2018 03:37:09;0040;Server@node2;Svr;node2.supernodexp.hpc;Scheduler sent command 2
02/19/2018 03:37:09;0040;Server@node2;Svr;node2.supernodexp.hpc;Scheduler sent command 0
02/19/2018 03:37:09;0100;Server@node2;Req;;Type 21 request received from Scheduler@node2.supernodexp.hpc, sock=16
02/19/2018 03:37:09;0100;Server@node2;Req;;Type 81 request received from Scheduler@node2.supernodexp.hpc, sock=16
02/19/2018 03:37:09;0100;Server@node2;Req;;Type 71 request received from Scheduler@node2.supernodexp.hpc, sock=16
02/19/2018 03:37:09;0100;Server@node2;Req;;Type 58 request received from Scheduler@node2.supernodexp.hpc, sock=16
02/19/2018 03:37:09;0100;Server@node2;Req;;Type 20 request received from Scheduler@node2.supernodexp.hpc, sock=16
02/19/2018 03:37:09;0100;Server@node2;Req;;Type 51 request received from Scheduler@node2.supernodexp.hpc, sock=16
02/19/2018 03:37:10;0100;Server@node2;Req;;Type 23 request received from Scheduler@node2.supernodexp.hpc, sock=16
02/19/2018 03:37:10;0008;Server@node2;Job;3246.node2.supernodexp.hpc;Job Run at request of Scheduler@node2.supernodexp.hpc on exec_vnode (node13:ncpus=48:mem=5242880kb)
02/19/2018 03:37:10;0001;Server@node2;Svr;Server@node2;Success (0) in req_runjob2, return value of svr_startjob is 0
02/19/2018 03:37:10;0100;Server@node2;Req;;Type 11 request received from Scheduler@node2.supernodexp.hpc, sock=16
02/19/2018 03:37:10;0008;Server@node2;Job;3250.node2.supernodexp.hpc;Job Modified at request of Scheduler@node2.supernodexp.hpc
02/19/2018 03:46:07;0080;Server@node2;Job;3237.node2.supernodexp.hpc;Obit received momhop:1 serverhop:1 state:4 substate:42
02/19/2018 03:46:08;0010;Server@node2;Job;3237.node2.supernodexp.hpc;Exit_status=0 resources_used.cpupercent=4746 resources_used.cput=08:07:12 resources_used.mem=7992544kb resources_used.ncpus=48 resources_used.vmem=47424400kb resources_used.walltime=00:10:30
02/19/2018 03:46:08;0100;Server@node2;Job;3237.node2.supernodexp.hpc;dequeuing from workq, state 5
02/19/2018 03:46:08;0040;Server@node2;Svr;node2.supernodexp.hpc;Scheduler sent command 2
02/19/2018 03:46:08;0040;Server@node2;Svr;node2.supernodexp.hpc;Scheduler sent command 0
02/19/2018 03:46:08;0100;Server@node2;Req;;Type 21 request received from Scheduler@node2.supernodexp.hpc, sock=16
02/19/2018 03:46:08;0100;Server@node2;Req;;Type 81 request received from Scheduler@node2.supernodexp.hpc, sock=16
02/19/2018 03:46:08;0100;Server@node2;Req;;Type 71 request received from Scheduler@node2.supernodexp.hpc, sock=16
02/19/2018 03:46:08;0100;Server@node2;Req;;Type 58 request received from Scheduler@node2.supernodexp.hpc, sock=16
02/19/2018 03:46:08;0100;Server@node2;Req;;Type 20 request received from Scheduler@node2.supernodexp.hpc, sock=16
02/19/2018 03:46:08;0100;Server@node2;Req;;Type 51 request received from Scheduler@node2.supernodexp.hpc, sock=16
02/19/2018 03:46:08;0100;Server@node2;Req;;Type 23 request received from Scheduler@node2.supernodexp.hpc, sock=16
02/19/2018 03:46:08;0008;Server@node2;Job;3250.node2.supernodexp.hpc;Job Run at request of Scheduler@node2.supernodexp.hpc on exec_vnode (node14:ncpus=48:mem=5242880kb)
02/19/2018 03:46:08;0001;Server@node2;Svr;Server@node2;Success (0) in req_runjob2, return value of svr_startjob is 0
02/19/2018 03:46:08;0100;Server@node2;Req;;Type 11 request received from Scheduler@node2.supernodexp.hpc, sock=16
02/19/2018 03:46:08;0008;Server@node2;Job;3258.node2.supernodexp.hpc;Job Modified at request of Scheduler@node2.supernodexp.hpc
02/19/2018 03:47:45;0080;Server@node2;Job;3246.node2.supernodexp.hpc;Obit received momhop:1 serverhop:1 state:4 substate:42
02/19/2018 03:47:46;0010;Server@node2;Job;3246.node2.supernodexp.hpc;Exit_status=0 resources_used.cpupercent=4739 resources_used.cput=08:09:36 resources_used.mem=7959216kb resources_used.ncpus=48 resources_used.vmem=47424628kb resources_used.walltime=00:10:35
02/19/2018 03:47:46;0100;Server@node2;Job;3246.node2.supernodexp.hpc;dequeuing from workq, state 5
02/19/2018 03:47:46;0040;Server@node2;Svr;node2.supernodexp.hpc;Scheduler sent command 2
02/19/2018 03:47:46;0040;Server@node2;Svr;node2.supernodexp.hpc;Scheduler sent command 0
02/19/2018 03:47:46;0100;Server@node2;Req;;Type 21 request received from Scheduler@node2.supernodexp.hpc, sock=16
02/19/2018 03:47:46;0100;Server@node2;Req;;Type 81 request received from Scheduler@node2.supernodexp.hpc, sock=16
02/19/2018 03:47:46;0100;Server@node2;Req;;Type 71 request received from Scheduler@node2.supernodexp.hpc, sock=16
02/19/2018 03:47:46;0100;Server@node2;Req;;Type 58 request received from Scheduler@node2.supernodexp.hpc, sock=16
02/19/2018 03:47:46;0100;Server@node2;Req;;Type 20 request received from Scheduler@node2.supernodexp.hpc, sock=16
02/19/2018 03:47:46;0100;Server@node2;Req;;Type 51 request received from Scheduler@node2.supernodexp.hpc, sock=16
02/19/2018 03:47:46;0100;Server@node2;Req;;Type 23 request received from Scheduler@node2.supernodexp.hpc, sock=16
02/19/2018 03:47:46;0008;Server@node2;Job;3258.node2.supernodexp.hpc;Job Run at request of Scheduler@node2.supernodexp.hpc on exec_vnode (node13:ncpus=48:mem=5242880kb)
02/19/2018 03:47:46;0001;Server@node2;Svr;Server@node2;Success (0) in req_runjob2, return value of svr_startjob is 0
02/19/2018 03:47:46;0100;Server@node2;Req;;Type 11 request received from Scheduler@node2.supernodexp.hpc, sock=16
02/19/2018 03:47:46;0008;Server@node2;Job;3341.node2.supernodexp.hpc;Job Modified at request of Scheduler@node2.supernodexp.hpc
02/19/2018 03:56:33;0080;Server@node2;Job;3250.node2.supernodexp.hpc;Obit received momhop:1 serverhop:1 state:4 substate:42
02/19/2018 03:56:34;0010;Server@node2;Job;3250.node2.supernodexp.hpc;Exit_status=0 resources_used.cpupercent=4744 resources_used.cput=08:08:18 resources_used.mem=7983148kb resources_used.ncpus=48 resources_used.vmem=47424520kb resources_used.walltime=00:10:25
02/19/2018 03:56:34;0100;Server@node2;Job;3250.node2.supernodexp.hpc;dequeuing from workq, state 5
02/19/2018 03:56:34;0040;Server@node2;Svr;node2.supernodexp.hpc;Scheduler sent command 2
02/19/2018 03:56:34;0040;Server@node2;Svr;node2.supernodexp.hpc;Scheduler sent command 0
02/19/2018 03:56:34;0100;Server@node2;Req;;Type 21 request received from Scheduler@node2.supernodexp.hpc, sock=16
02/19/2018 03:56:34;0100;Server@node2;Req;;Type 81 request received from Scheduler@node2.supernodexp.hpc, sock=16
02/19/2018 03:56:34;0100;Server@node2;Req;;Type 71 request received from Scheduler@node2.supernodexp.hpc, sock=16
02/19/2018 03:56:34;0100;Server@node2;Req;;Type 58 request received from Scheduler@node2.supernodexp.hpc, sock=16
02/19/2018 03:56:34;0100;Server@node2;Req;;Type 20 request received from Scheduler@node2.supernodexp.hpc, sock=16
02/19/2018 03:56:34;0100;Server@node2;Req;;Type 51 request received from Scheduler@node2.supernodexp.hpc, sock=16
02/19/2018 03:56:34;0100;Server@node2;Req;;Type 23 request received from Scheduler@node2.supernodexp.hpc, sock=16
02/19/2018 03:56:34;0008;Server@node2;Job;3341.node2.supernodexp.hpc;Job Run at request of Scheduler@node2.supernodexp.hpc on exec_vnode (node14:ncpus=48:mem=5242880kb)
02/19/2018 03:56:34;0001;Server@node2;Svr;Server@node2;Success (0) in req_runjob2, return value of svr_startjob is 0
02/19/2018 03:56:34;0100;Server@node2;Req;;Type 11 request received from Scheduler@node2.supernodexp.hpc, sock=16
02/19/2018 03:56:34;0008;Server@node2;Job;3342.node2.supernodexp.hpc;Job Modified at request of Scheduler@node2.supernodexp.hpc
02/19/2018 03:58:21;0080;Server@node2;Job;3258.node2.supernodexp.hpc;Obit received momhop:1 serverhop:1 state:4 substate:42
02/19/2018 03:58:22;0010;Server@node2;Job;3258.node2.supernodexp.hpc;Exit_status=0 resources_used.cpupercent=4785 resources_used.cput=08:13:06 resources_used.mem=7970424kb resources_used.ncpus=48 resources_used.vmem=47423900kb resources_used.walltime=00:10:34
02/19/2018 03:58:22;0100;Server@node2;Job;3258.node2.supernodexp.hpc;dequeuing from workq, state 5
02/19/2018 03:58:22;0040;Server@node2;Svr;node2.supernodexp.hpc;Scheduler sent command 2
02/19/2018 03:58:22;0040;Server@node2;Svr;node2.supernodexp.hpc;Scheduler sent command 0
02/19/2018 03:58:22;0100;Server@node2;Req;;Type 21 request received from Scheduler@node2.supernodexp.hpc, sock=16
02/19/2018 03:58:22;0100;Server@node2;Req;;Type 81 request received from Scheduler@node2.supernodexp.hpc, sock=16
02/19/2018 03:58:22;0100;Server@node2;Req;;Type 71 request received from Scheduler@node2.supernodexp.hpc, sock=16
02/19/2018 03:58:22;0100;Server@node2;Req;;Type 58 request received from Scheduler@node2.supernodexp.hpc, sock=16
02/19/2018 03:58:22;0100;Server@node2;Req;;Type 20 request received from Scheduler@node2.supernodexp.hpc, sock=16
02/19/2018 03:58:22;0100;Server@node2;Req;;Type 51 request received from Scheduler@node2.supernodexp.hpc, sock=16
02/19/2018 03:58:22;0100;Server@node2;Req;;Type 23 request received from Scheduler@node2.supernodexp.hpc, sock=16
02/19/2018 03:58:22;0008;Server@node2;Job;3342.node2.supernodexp.hpc;Job Run at request of Scheduler@node2.supernodexp.hpc on exec_vnode (node13:ncpus=48:mem=5242880kb)
02/19/2018 03:58:22;0001;Server@node2;Svr;Server@node2;Success (0) in req_runjob2, return value of svr_startjob is 0
02/19/2018 03:58:22;0100;Server@node2;Req;;Type 11 request received from Scheduler@node2.supernodexp.hpc, sock=16
02/19/2018 03:58:22;0008;Server@node2;Job;3345.node2.supernodexp.hpc;Job Modified at request of Scheduler@node2.supernodexp.hpc
02/19/2018 04:07:29;0080;Server@node2;Job;3341.node2.supernodexp.hpc;Obit received momhop:1 serverhop:1 state:4 substate:42
02/19/2018 04:07:30;0010;Server@node2;Job;3341.node2.supernodexp.hpc;Exit_status=0 resources_used.cpupercent=4741 resources_used.cput=08:13:50 resources_used.mem=7969568kb resources_used.ncpus=48 resources_used.vmem=47424060kb resources_used.walltime=00:10:55
02/19/2018 04:07:30;0100;Server@node2;Job;3341.node2.supernodexp.hpc;dequeuing from workq, state 5
02/19/2018 04:07:30;0040;Server@node2;Svr;node2.supernodexp.hpc;Scheduler sent command 2
02/19/2018 04:07:30;0040;Server@node2;Svr;node2.supernodexp.hpc;Scheduler sent command 0
02/19/2018 04:07:30;0100;Server@node2;Req;;Type 21 request received from Scheduler@node2.supernodexp.hpc, sock=16
02/19/2018 04:07:30;0100;Server@node2;Req;;Type 81 request received from Scheduler@node2.supernodexp.hpc, sock=16
02/19/2018 04:07:30;0100;Server@node2;Req;;Type 71 request received from Scheduler@node2.supernodexp.hpc, sock=16
02/19/2018 04:07:30;0100;Server@node2;Req;;Type 58 request received from Scheduler@node2.supernodexp.hpc, sock=16
02/19/2018 04:07:30;0100;Server@node2;Req;;Type 20 request received from Scheduler@node2.supernodexp.hpc, sock=16
02/19/2018 04:07:30;0100;Server@node2;Req;;Type 51 request received from Scheduler@node2.supernodexp.hpc, sock=16
02/19/2018 04:07:30;0100;Server@node2;Req;;Type 23 request received from Scheduler@node2.supernodexp.hpc, sock=16
02/19/2018 04:07:30;0008;Server@node2;Job;3345.node2.supernodexp.hpc;Job Run at request of Scheduler@node2.supernodexp.hpc on exec_vnode (node14:ncpus=48:mem=5242880kb)
02/19/2018 04:07:30;0001;Server@node2;Svr;Server@node2;Success (0) in req_runjob2, return value of svr_startjob is 0
02/19/2018 04:07:30;0100;Server@node2;Req;;Type 11 request received from Scheduler@node2.supernodexp.hpc, sock=16
02/19/2018 04:07:30;0008;Server@node2;Job;3358.node2.supernodexp.hpc;Job Modified at request of Scheduler@node2.supernodexp.hpc
02/19/2018 04:09:06;0080;Server@node2;Job;3342.node2.supernodexp.hpc;Obit received momhop:1 serverhop:1 state:4 substate:42
02/19/2018 04:09:07;0010;Server@node2;Job;3342.node2.supernodexp.hpc;Exit_status=0 resources_used.cpupercent=4750 resources_used.cput=08:14:42 resources_used.mem=7941668kb resources_used.ncpus=48 resources_used.vmem=47424940kb resources_used.walltime=00:10:43
02/19/2018 04:09:07;0100;Server@node2;Job;3342.node2.supernodexp.hpc;dequeuing from workq, state 5
02/19/2018 04:09:07;0040;Server@node2;Svr;node2.supernodexp.hpc;Scheduler sent command 2
02/19/2018 04:09:07;0040;Server@node2;Svr;node2.supernodexp.hpc;Scheduler sent command 0
02/19/2018 04:09:07;0100;Server@node2;Req;;Type 21 request received from Scheduler@node2.supernodexp.hpc, sock=16
02/19/2018 04:09:07;0100;Server@node2;Req;;Type 81 request received from Scheduler@node2.supernodexp.hpc, sock=16
02/19/2018 04:09:07;0100;Server@node2;Req;;Type 71 request received from Scheduler@node2.supernodexp.hpc, sock=16
02/19/2018 04:09:07;0100;Server@node2;Req;;Type 58 request received from Scheduler@node2.supernodexp.hpc, sock=16
02/19/2018 04:09:07;0100;Server@node2;Req;;Type 20 request received from Scheduler@node2.supernodexp.hpc, sock=16
02/19/2018 04:09:07;0100;Server@node2;Req;;Type 51 request received from Scheduler@node2.supernodexp.hpc, sock=16
02/19/2018 04:09:07;0100;Server@node2;Req;;Type 23 request received from Scheduler@node2.supernodexp.hpc, sock=16
02/19/2018 04:09:07;0008;Server@node2;Job;3358.node2.supernodexp.hpc;Job Run at request of Scheduler@node2.supernodexp.hpc on exec_vnode (node13:ncpus=48:mem=5242880kb)
02/19/2018 04:09:07;0001;Server@node2;Svr;Server@node2;Success (0) in req_runjob2, return value of svr_startjob is 0
02/19/2018 04:09:07;0100;Server@node2;Req;;Type 11 request received from Scheduler@node2.supernodexp.hpc, sock=16
02/19/2018 04:09:07;0008;Server@node2;Job;3370.node2.supernodexp.hpc;Job Modified at request of Scheduler@node2.supernodexp.hpc
02/19/2018 04:17:58;0080;Server@node2;Job;3345.node2.supernodexp.hpc;Obit received momhop:1 serverhop:1 state:4 substate:42
02/19/2018 04:18:00;0010;Server@node2;Job;3345.node2.supernodexp.hpc;Exit_status=0 resources_used.cpupercent=4742 resources_used.cput=08:12:36 resources_used.mem=7947096kb resources_used.ncpus=48 resources_used.vmem=47424224kb resources_used.walltime=00:10:28
02/19/2018 04:18:00;0100;Server@node2;Job;3345.node2.supernodexp.hpc;dequeuing from workq, state 5
02/19/2018 04:18:00;0040;Server@node2;Svr;node2.supernodexp.hpc;Scheduler sent command 2
02/19/2018 04:18:00;0040;Server@node2;Svr;node2.supernodexp.hpc;Scheduler sent command 0
02/19/2018 04:18:00;0100;Server@node2;Req;;Type 21 request received from Scheduler@node2.supernodexp.hpc, sock=16
02/19/2018 04:18:00;0100;Server@node2;Req;;Type 81 request received from Scheduler@node2.supernodexp.hpc, sock=16
02/19/2018 04:18:00;0100;Server@node2;Req;;Type 71 request received from Scheduler@node2.supernodexp.hpc, sock=16
02/19/2018 04:18:00;0100;Server@node2;Req;;Type 58 request received from Scheduler@node2.supernodexp.hpc, sock=16
02/19/2018 04:18:00;0100;Server@node2;Req;;Type 20 request received from Scheduler@node2.supernodexp.hpc, sock=16
02/19/2018 04:18:00;0100;Server@node2;Req;;Type 51 request received from Scheduler@node2.supernodexp.hpc, sock=16
02/19/2018 04:18:00;0100;Server@node2;Req;;Type 23 request received from Scheduler@node2.supernodexp.hpc, sock=16
02/19/2018 04:18:00;0008;Server@node2;Job;3370.node2.supernodexp.hpc;Job Run at request of Scheduler@node2.supernodexp.hpc on exec_vnode (node14:ncpus=48:mem=5242880kb)
02/19/2018 04:18:00;0001;Server@node2;Svr;Server@node2;Success (0) in req_runjob2, return value of svr_startjob is 0
02/19/2018 04:18:00;0100;Server@node2;Req;;Type 11 request received from Scheduler@node2.supernodexp.hpc, sock=16
02/19/2018 04:18:00;0008;Server@node2;Job;3389.node2.supernodexp.hpc;Job Modified at request of Scheduler@node2.supernodexp.hpc
02/19/2018 04:19:38;0080;Server@node2;Job;3358.node2.supernodexp.hpc;Obit received momhop:1 serverhop:1 state:4 substate:42
02/19/2018 04:19:39;0010;Server@node2;Job;3358.node2.supernodexp.hpc;Exit_status=0 resources_used.cpupercent=4734 resources_used.cput=08:13:35 resources_used.mem=7914660kb resources_used.ncpus=48 resources_used.vmem=47424912kb resources_used.walltime=00:10:30
02/19/2018 04:19:39;0100;Server@node2;Job;3358.node2.supernodexp.hpc;dequeuing from workq, state 5
02/19/2018 04:19:39;0040;Server@node2;Svr;node2.supernodexp.hpc;Scheduler sent command 2
02/19/2018 04:19:39;0040;Server@node2;Svr;node2.supernodexp.hpc;Scheduler sent command 0
02/19/2018 04:19:39;0100;Server@node2;Req;;Type 21 request received from Scheduler@node2.supernodexp.hpc, sock=16
02/19/2018 04:19:39;0100;Server@node2;Req;;Type 81 request received from Scheduler@node2.supernodexp.hpc, sock=16
02/19/2018 04:19:39;0100;Server@node2;Req;;Type 71 request received from Scheduler@node2.supernodexp.hpc, sock=16
02/19/2018 04:19:39;0100;Server@node2;Req;;Type 58 request received from Scheduler@node2.supernodexp.hpc, sock=16
02/19/2018 04:19:39;0100;Server@node2;Req;;Type 20 request received from Scheduler@node2.supernodexp.hpc, sock=16
02/19/2018 04:19:39;0100;Server@node2;Req;;Type 51 request received from Scheduler@node2.supernodexp.hpc, sock=16
02/19/2018 04:19:39;0100;Server@node2;Req;;Type 23 request received from Scheduler@node2.supernodexp.hpc, sock=16
02/19/2018 04:19:39;0008;Server@node2;Job;3389.node2.supernodexp.hpc;Job Run at request of Scheduler@node2.supernodexp.hpc on exec_vnode (node13:ncpus=48:mem=5242880kb)
02/19/2018 04:19:39;0001;Server@node2;Svr;Server@node2;Success (0) in req_runjob2, return value of svr_startjob is 0
02/19/2018 04:19:39;0100;Server@node2;Req;;Type 11 request received from Scheduler@node2.supernodexp.hpc, sock=16
02/19/2018 04:19:39;0008;Server@node2;Job;3393.node2.supernodexp.hpc;Job Modified at request of Scheduler@node2.supernodexp.hpc
02/19/2018 04:28:22;0080;Server@node2;Job;3370.node2.supernodexp.hpc;Obit received momhop:1 serverhop:1 state:4 substate:42
02/19/2018 04:28:24;0010;Server@node2;Job;3370.node2.supernodexp.hpc;Exit_status=0 resources_used.cpupercent=4738 resources_used.cput=08:07:10 resources_used.mem=7959108kb resources_used.ncpus=48 resources_used.vmem=47424176kb resources_used.walltime=00:10:22
02/19/2018 04:28:24;0100;Server@node2;Job;3370.node2.supernodexp.hpc;dequeuing from workq, state 5
02/19/2018 04:28:24;0040;Server@node2;Svr;node2.supernodexp.hpc;Scheduler sent command 2
02/19/2018 04:28:24;0040;Server@node2;Svr;node2.supernodexp.hpc;Scheduler sent command 0
02/19/2018 04:28:24;0100;Server@node2;Req;;Type 21 request received from Scheduler@node2.supernodexp.hpc, sock=16
02/19/2018 04:28:24;0100;Server@node2;Req;;Type 81 request received from Scheduler@node2.supernodexp.hpc, sock=16
02/19/2018 04:28:24;0100;Server@node2;Req;;Type 71 request received from Scheduler@node2.supernodexp.hpc, sock=16
02/19/2018 04:28:24;0100;Server@node2;Req;;Type 58 request received from Scheduler@node2.supernodexp.hpc, sock=16
02/19/2018 04:28:24;0100;Server@node2;Req;;Type 20 request received from Scheduler@node2.supernodexp.hpc, sock=16
02/19/2018 04:28:24;0100;Server@node2;Req;;Type 51 request received from Scheduler@node2.supernodexp.hpc, sock=16
02/19/2018 04:28:24;0100;Server@node2;Req;;Type 23 request received from Scheduler@node2.supernodexp.hpc, sock=16
02/19/2018 04:28:24;0008;Server@node2;Job;3393.node2.supernodexp.hpc;Job Run at request of Scheduler@node2.supernodexp.hpc on exec_vnode (node14:ncpus=48:mem=5242880kb)
02/19/2018 04:28:24;0001;Server@node2;Svr;Server@node2;Success (0) in req_runjob2, return value of svr_startjob is 0
02/19/2018 04:28:24;0100;Server@node2;Req;;Type 11 request received from Scheduler@node2.supernodexp.hpc, sock=16
02/19/2018 04:28:24;0008;Server@node2;Job;3397.node2.supernodexp.hpc;Job Modified at request of Scheduler@node2.supernodexp.hpc
02/19/2018 04:30:15;0080;Server@node2;Job;3389.node2.supernodexp.hpc;Obit received momhop:1 serverhop:1 state:4 substate:42
02/19/2018 04:30:16;0010;Server@node2;Job;3389.node2.supernodexp.hpc;Exit_status=0 resources_used.cpupercent=4747 resources_used.cput=08:17:04 resources_used.mem=7961704kb resources_used.ncpus=48 resources_used.vmem=47423988kb resources_used.walltime=00:10:35
02/19/2018 04:30:16;0100;Server@node2;Job;3389.node2.supernodexp.hpc;dequeuing from workq, state 5
02/19/2018 04:30:16;0040;Server@node2;Svr;node2.supernodexp.hpc;Scheduler sent command 2
02/19/2018 04:30:16;0040;Server@node2;Svr;node2.supernodexp.hpc;Scheduler sent command 0
02/19/2018 04:30:16;0100;Server@node2;Req;;Type 21 request received from Scheduler@node2.supernodexp.hpc, sock=16
02/19/2018 04:30:16;0100;Server@node2;Req;;Type 81 request received from Scheduler@node2.supernodexp.hpc, sock=16
02/19/2018 04:30:16;0100;Server@node2;Req;;Type 71 request received from Scheduler@node2.supernodexp.hpc, sock=16
02/19/2018 04:30:16;0100;Server@node2;Req;;Type 58 request received from Scheduler@node2.supernodexp.hpc, sock=16
02/19/2018 04:30:16;0100;Server@node2;Req;;Type 20 request received from Scheduler@node2.supernodexp.hpc, sock=16
02/19/2018 04:30:16;0100;Server@node2;Req;;Type 51 request received from Scheduler@node2.supernodexp.hpc, sock=16
02/19/2018 04:30:16;0100;Server@node2;Req;;Type 23 request received from Scheduler@node2.supernodexp.hpc, sock=16
02/19/2018 04:30:16;0008;Server@node2;Job;3397.node2.supernodexp.hpc;Job Run at request of Scheduler@node2.supernodexp.hpc on exec_vnode (node13:ncpus=48:mem=5242880kb)
02/19/2018 04:30:16;0001;Server@node2;Svr;Server@node2;Success (0) in req_runjob2, return value of svr_startjob is 0
02/19/2018 04:30:16;0100;Server@node2;Req;;Type 11 request received from Scheduler@node2.supernodexp.hpc, sock=16
02/19/2018 04:30:16;0008;Server@node2;Job;3403.node2.supernodexp.hpc;Job Modified at request of Scheduler@node2.supernodexp.hpc
02/19/2018 04:38:46;0080;Server@node2;Job;3393.node2.supernodexp.hpc;Obit received momhop:1 serverhop:1 state:4 substate:42
02/19/2018 04:38:47;0010;Server@node2;Job;3393.node2.supernodexp.hpc;Exit_status=0 resources_used.cpupercent=4742 resources_used.cput=08:07:41 resources_used.mem=7985500kb resources_used.ncpus=48 resources_used.vmem=47424832kb resources_used.walltime=00:10:22
02/19/2018 04:38:47;0100;Server@node2;Job;3393.node2.supernodexp.hpc;dequeuing from workq, state 5
02/19/2018 04:38:47;0040;Server@node2;Svr;node2.supernodexp.hpc;Scheduler sent command 2
02/19/2018 04:38:47;0040;Server@node2;Svr;node2.supernodexp.hpc;Scheduler sent command 0
02/19/2018 04:38:47;0100;Server@node2;Req;;Type 21 request received from Scheduler@node2.supernodexp.hpc, sock=16
02/19/2018 04:38:47;0100;Server@node2;Req;;Type 81 request received from Scheduler@node2.supernodexp.hpc, sock=16
02/19/2018 04:38:47;0100;Server@node2;Req;;Type 71 request received from Scheduler@node2.supernodexp.hpc, sock=16
02/19/2018 04:38:47;0100;Server@node2;Req;;Type 58 request received from Scheduler@node2.supernodexp.hpc, sock=16
02/19/2018 04:38:48;0100;Server@node2;Req;;Type 20 request received from Scheduler@node2.supernodexp.hpc, sock=16
02/19/2018 04:38:48;0100;Server@node2;Req;;Type 51 request received from Scheduler@node2.supernodexp.hpc, sock=16
02/19/2018 04:38:48;0100;Server@node2;Req;;Type 23 request received from Scheduler@node2.supernodexp.hpc, sock=16
02/19/2018 04:38:48;0008;Server@node2;Job;3403.node2.supernodexp.hpc;Job Run at request of Scheduler@node2.supernodexp.hpc on exec_vnode (node14:ncpus=48:mem=5242880kb)
02/19/2018 04:38:48;0001;Server@node2;Svr;Server@node2;Success (0) in req_runjob2, return value of svr_startjob is 0
02/19/2018 04:38:48;0100;Server@node2;Req;;Type 11 request received from Scheduler@node2.supernodexp.hpc, sock=16
02/19/2018 04:38:48;0008;Server@node2;Job;3489.node2.supernodexp.hpc;Job Modified at request of Scheduler@node2.supernodexp.hpc
02/19/2018 04:40:46;0080;Server@node2;Job;3397.node2.supernodexp.hpc;Obit received momhop:1 serverhop:1 state:4 substate:42
02/19/2018 04:40:48;0010;Server@node2;Job;3397.node2.supernodexp.hpc;Exit_status=0 resources_used.cpupercent=4731 resources_used.cput=08:13:25 resources_used.mem=7969820kb resources_used.ncpus=48 resources_used.vmem=47424652kb resources_used.walltime=00:10:30
02/19/2018 04:40:48;0100;Server@node2;Job;3397.node2.supernodexp.hpc;dequeuing from workq, state 5
02/19/2018 04:40:48;0040;Server@node2;Svr;node2.supernodexp.hpc;Scheduler sent command 2
02/19/2018 04:40:48;0040;Server@node2;Svr;node2.supernodexp.hpc;Scheduler sent command 0
02/19/2018 04:40:48;0100;Server@node2;Req;;Type 21 request received from Scheduler@node2.supernodexp.hpc, sock=16
02/19/2018 04:40:48;0100;Server@node2;Req;;Type 81 request received from Scheduler@node2.supernodexp.hpc, sock=16
02/19/2018 04:40:48;0100;Server@node2;Req;;Type 71 request received from Scheduler@node2.supernodexp.hpc, sock=16
02/19/2018 04:40:48;0100;Server@node2;Req;;Type 58 request received from Scheduler@node2.supernodexp.hpc, sock=16
02/19/2018 04:40:48;0100;Server@node2;Req;;Type 20 request received from Scheduler@node2.supernodexp.hpc, sock=16
02/19/2018 04:40:48;0100;Server@node2;Req;;Type 51 request received from Scheduler@node2.supernodexp.hpc, sock=16
02/19/2018 04:40:48;0100;Server@node2;Req;;Type 23 request received from Scheduler@node2.supernodexp.hpc, sock=16
02/19/2018 04:40:48;0008;Server@node2;Job;3489.node2.supernodexp.hpc;Job Run at request of Scheduler@node2.supernodexp.hpc on exec_vnode (node13:ncpus=48:mem=5242880kb)
02/19/2018 04:40:48;0001;Server@node2;Svr;Server@node2;Success (0) in req_runjob2, return value of svr_startjob is 0
02/19/2018 04:40:48;0100;Server@node2;Req;;Type 11 request received from Scheduler@node2.supernodexp.hpc, sock=16
02/19/2018 04:40:48;0008;Server@node2;Job;3498.node2.supernodexp.hpc;Job Modified at request of Scheduler@node2.supernodexp.hpc
02/19/2018 04:49:12;0080;Server@node2;Job;3403.node2.supernodexp.hpc;Obit received momhop:1 serverhop:1 state:4 substate:42
02/19/2018 04:49:13;0010;Server@node2;Job;3403.node2.supernodexp.hpc;Exit_status=0 resources_used.cpupercent=4748 resources_used.cput=08:09:08 resources_used.mem=7962260kb resources_used.ncpus=48 resources_used.vmem=47424492kb resources_used.walltime=00:10:24
02/19/2018 04:49:13;0100;Server@node2;Job;3403.node2.supernodexp.hpc;dequeuing from workq, state 5
02/19/2018 04:49:13;0040;Server@node2;Svr;node2.supernodexp.hpc;Scheduler sent command 2
02/19/2018 04:49:13;0040;Server@node2;Svr;node2.supernodexp.hpc;Scheduler sent command 0
02/19/2018 04:49:13;0100;Server@node2;Req;;Type 21 request received from Scheduler@node2.supernodexp.hpc, sock=16
02/19/2018 04:49:13;0100;Server@node2;Req;;Type 81 request received from Scheduler@node2.supernodexp.hpc, sock=16
02/19/2018 04:49:13;0100;Server@node2;Req;;Type 71 request received from Scheduler@node2.supernodexp.hpc, sock=16
02/19/2018 04:49:13;0100;Server@node2;Req;;Type 58 request received from Scheduler@node2.supernodexp.hpc, sock=16
02/19/2018 04:49:13;0100;Server@node2;Req;;Type 20 request received from Scheduler@node2.supernodexp.hpc, sock=16
02/19/2018 04:49:13;0100;Server@node2;Req;;Type 51 request received from Scheduler@node2.supernodexp.hpc, sock=16
02/19/2018 04:49:13;0100;Server@node2;Req;;Type 23 request received from Scheduler@node2.supernodexp.hpc, sock=16
02/19/2018 04:49:13;0008;Server@node2;Job;3498.node2.supernodexp.hpc;Job Run at request of Scheduler@node2.supernodexp.hpc on exec_vnode (node14:ncpus=48:mem=5242880kb)
02/19/2018 04:49:13;0001;Server@node2;Svr;Server@node2;Success (0) in req_runjob2, return value of svr_startjob is 0
02/19/2018 04:49:13;0100;Server@node2;Req;;Type 11 request received from Scheduler@node2.supernodexp.hpc, sock=16
02/19/2018 04:49:13;0008;Server@node2;Job;3507.node2.supernodexp.hpc;Job Modified at request of Scheduler@node2.supernodexp.hpc
02/19/2018 04:51:18;0080;Server@node2;Job;3489.node2.supernodexp.hpc;Obit received momhop:1 serverhop:1 state:4 substate:42
02/19/2018 04:51:20;0010;Server@node2;Job;3489.node2.supernodexp.hpc;Exit_status=0 resources_used.cpupercent=4699 resources_used.cput=08:13:52 resources_used.mem=7954224kb resources_used.ncpus=48 resources_used.vmem=47424620kb resources_used.walltime=00:10:31
02/19/2018 04:51:20;0100;Server@node2;Job;3489.node2.supernodexp.hpc;dequeuing from workq, state 5
02/19/2018 04:51:20;0040;Server@node2;Svr;node2.supernodexp.hpc;Scheduler sent command 2
02/19/2018 04:51:20;0040;Server@node2;Svr;node2.supernodexp.hpc;Scheduler sent command 0
02/19/2018 04:51:20;0100;Server@node2;Req;;Type 21 request received from Scheduler@node2.supernodexp.hpc, sock=16
02/19/2018 04:51:20;0100;Server@node2;Req;;Type 81 request received from Scheduler@node2.supernodexp.hpc, sock=16
02/19/2018 04:51:20;0100;Server@node2;Req;;Type 71 request received from Scheduler@node2.supernodexp.hpc, sock=16
02/19/2018 04:51:20;0100;Server@node2;Req;;Type 58 request received from Scheduler@node2.supernodexp.hpc, sock=16
02/19/2018 04:51:20;0100;Server@node2;Req;;Type 20 request received from Scheduler@node2.supernodexp.hpc, sock=16
02/19/2018 04:51:20;0100;Server@node2;Req;;Type 51 request received from Scheduler@node2.supernodexp.hpc, sock=16
02/19/2018 04:51:20;0100;Server@node2;Req;;Type 23 request received from Scheduler@node2.supernodexp.hpc, sock=16
02/19/2018 04:51:20;0008;Server@node2;Job;3507.node2.supernodexp.hpc;Job Run at request of Scheduler@node2.supernodexp.hpc on exec_vnode (node13:ncpus=48:mem=5242880kb)
02/19/2018 04:51:20;0001;Server@node2;Svr;Server@node2;Success (0) in req_runjob2, return value of svr_startjob is 0
02/19/2018 04:51:20;0100;Server@node2;Req;;Type 11 request received from Scheduler@node2.supernodexp.hpc, sock=16
02/19/2018 04:51:20;0008;Server@node2;Job;3527.node2.supernodexp.hpc;Job Modified at request of Scheduler@node2.supernodexp.hpc
02/19/2018 04:59:35;0080;Server@node2;Job;3498.node2.supernodexp.hpc;Obit received momhop:1 serverhop:1 state:4 substate:42
02/19/2018 04:59:37;0010;Server@node2;Job;3498.node2.supernodexp.hpc;Exit_status=0 resources_used.cpupercent=4748 resources_used.cput=08:07:02 resources_used.mem=7939496kb resources_used.ncpus=48 resources_used.vmem=47424216kb resources_used.walltime=00:10:22
02/19/2018 04:59:37;0100;Server@node2;Job;3498.node2.supernodexp.hpc;dequeuing from workq, state 5
02/19/2018 04:59:37;0040;Server@node2;Svr;node2.supernodexp.hpc;Scheduler sent command 2
02/19/2018 04:59:37;0040;Server@node2;Svr;node2.supernodexp.hpc;Scheduler sent command 0
02/19/2018 04:59:37;0100;Server@node2;Req;;Type 21 request received from Scheduler@node2.supernodexp.hpc, sock=16
02/19/2018 04:59:37;0100;Server@node2;Req;;Type 81 request received from Scheduler@node2.supernodexp.hpc, sock=16
02/19/2018 04:59:37;0100;Server@node2;Req;;Type 71 request received from Scheduler@node2.supernodexp.hpc, sock=16
02/19/2018 04:59:37;0100;Server@node2;Req;;Type 58 request received from Scheduler@node2.supernodexp.hpc, sock=16
02/19/2018 04:59:37;0100;Server@node2;Req;;Type 20 request received from Scheduler@node2.supernodexp.hpc, sock=16
02/19/2018 04:59:37;0100;Server@node2;Req;;Type 51 request received from Scheduler@node2.supernodexp.hpc, sock=16
02/19/2018 04:59:37;0100;Server@node2;Req;;Type 23 request received from Scheduler@node2.supernodexp.hpc, sock=16
02/19/2018 04:59:37;0008;Server@node2;Job;3527.node2.supernodexp.hpc;Job Run at request of Scheduler@node2.supernodexp.hpc on exec_vnode (node14:ncpus=48:mem=5242880kb)
02/19/2018 04:59:37;0001;Server@node2;Svr;Server@node2;Success (0) in req_runjob2, return value of svr_startjob is 0
02/19/2018 04:59:37;0100;Server@node2;Req;;Type 11 request received from Scheduler@node2.supernodexp.hpc, sock=16
02/19/2018 04:59:37;0008;Server@node2;Job;3547.node2.supernodexp.hpc;Job Modified at request of Scheduler@node2.supernodexp.hpc
02/19/2018 05:01:53;0080;Server@node2;Job;3507.node2.supernodexp.hpc;Obit received momhop:1 serverhop:1 state:4 substate:42
02/19/2018 05:01:54;0010;Server@node2;Job;3507.node2.supernodexp.hpc;Exit_status=0 resources_used.cpupercent=4744 resources_used.cput=08:15:26 resources_used.mem=7941536kb resources_used.ncpus=48 resources_used.vmem=47424916kb resources_used.walltime=00:10:33
02/19/2018 05:01:54;0100;Server@node2;Job;3507.node2.supernodexp.hpc;dequeuing from workq, state 5
02/19/2018 05:01:54;0040;Server@node2;Svr;node2.supernodexp.hpc;Scheduler sent command 2
02/19/2018 05:01:54;0040;Server@node2;Svr;node2.supernodexp.hpc;Scheduler sent command 0
02/19/2018 05:01:54;0100;Server@node2;Req;;Type 21 request received from Scheduler@node2.supernodexp.hpc, sock=16
02/19/2018 05:01:54;0100;Server@node2;Req;;Type 81 request received from Scheduler@node2.supernodexp.hpc, sock=16
02/19/2018 05:01:54;0100;Server@node2;Req;;Type 71 request received from Scheduler@node2.supernodexp.hpc, sock=16
02/19/2018 05:01:54;0100;Server@node2;Req;;Type 58 request received from Scheduler@node2.supernodexp.hpc, sock=16
02/19/2018 05:01:54;0100;Server@node2;Req;;Type 20 request received from Scheduler@node2.supernodexp.hpc, sock=16
02/19/2018 05:01:54;0100;Server@node2;Req;;Type 51 request received from Scheduler@node2.supernodexp.hpc, sock=16
02/19/2018 05:01:54;0100;Server@node2;Req;;Type 23 request received from Scheduler@node2.supernodexp.hpc, sock=16
02/19/2018 05:01:54;0008;Server@node2;Job;3547.node2.supernodexp.hpc;Job Run at request of Scheduler@node2.supernodexp.hpc on exec_vnode (node13:ncpus=48:mem=5242880kb)
02/19/2018 05:01:54;0001;Server@node2;Svr;Server@node2;Success (0) in req_runjob2, return value of svr_startjob is 0
02/19/2018 05:01:54;0100;Server@node2;Req;;Type 11 request received from Scheduler@node2.supernodexp.hpc, sock=16
02/19/2018 05:01:54;0008;Server@node2;Job;3548.node2.supernodexp.hpc;Job Modified at request of Scheduler@node2.supernodexp.hpc
02/19/2018 05:10:05;0080;Server@node2;Job;3527.node2.supernodexp.hpc;Obit received momhop:1 serverhop:1 state:4 substate:42
02/19/2018 05:10:07;0010;Server@node2;Job;3527.node2.supernodexp.hpc;Exit_status=0 resources_used.cpupercent=4738 resources_used.cput=08:11:52 resources_used.mem=7961656kb resources_used.ncpus=48 resources_used.vmem=47423936kb resources_used.walltime=00:10:28
02/19/2018 05:10:07;0100;Server@node2;Job;3527.node2.supernodexp.hpc;dequeuing from workq, state 5
02/19/2018 05:10:07;0040;Server@node2;Svr;node2.supernodexp.hpc;Scheduler sent command 2
02/19/2018 05:10:07;0040;Server@node2;Svr;node2.supernodexp.hpc;Scheduler sent command 0
02/19/2018 05:10:07;0100;Server@node2;Req;;Type 21 request received from Scheduler@node2.supernodexp.hpc, sock=16
02/19/2018 05:10:07;0100;Server@node2;Req;;Type 81 request received from Scheduler@node2.supernodexp.hpc, sock=16
02/19/2018 05:10:07;0100;Server@node2;Req;;Type 71 request received from Scheduler@node2.supernodexp.hpc, sock=16
02/19/2018 05:10:07;0100;Server@node2;Req;;Type 58 request received from Scheduler@node2.supernodexp.hpc, sock=16
02/19/2018 05:10:07;0100;Server@node2;Req;;Type 20 request received from Scheduler@node2.supernodexp.hpc, sock=16
02/19/2018 05:10:07;0100;Server@node2;Req;;Type 51 request received from Scheduler@node2.supernodexp.hpc, sock=16
02/19/2018 05:10:07;0100;Server@node2;Req;;Type 23 request received from Scheduler@node2.supernodexp.hpc, sock=16
02/19/2018 05:10:07;0008;Server@node2;Job;3548.node2.supernodexp.hpc;Job Run at request of Scheduler@node2.supernodexp.hpc on exec_vnode (node14:ncpus=48:mem=5242880kb)
02/19/2018 05:10:07;0001;Server@node2;Svr;Server@node2;Success (0) in req_runjob2, return value of svr_startjob is 0
02/19/2018 05:10:07;0100;Server@node2;Req;;Type 11 request received from Scheduler@node2.supernodexp.hpc, sock=16
02/19/2018 05:10:07;0008;Server@node2;Job;3550.node2.supernodexp.hpc;Job Modified at request of Scheduler@node2.supernodexp.hpc
02/19/2018 05:12:28;0080;Server@node2;Job;3547.node2.supernodexp.hpc;Obit received momhop:1 serverhop:1 state:4 substate:42
02/19/2018 05:12:30;0010;Server@node2;Job;3547.node2.supernodexp.hpc;Exit_status=0 resources_used.cpupercent=4746 resources_used.cput=08:15:54 resources_used.mem=7905052kb resources_used.ncpus=48 resources_used.vmem=47424304kb resources_used.walltime=00:10:34
02/19/2018 05:12:30;0100;Server@node2;Job;3547.node2.supernodexp.hpc;dequeuing from workq, state 5
02/19/2018 05:12:30;0040;Server@node2;Svr;node2.supernodexp.hpc;Scheduler sent command 2
02/19/2018 05:12:30;0040;Server@node2;Svr;node2.supernodexp.hpc;Scheduler sent command 0
02/19/2018 05:12:30;0100;Server@node2;Req;;Type 21 request received from Scheduler@node2.supernodexp.hpc, sock=16
02/19/2018 05:12:30;0100;Server@node2;Req;;Type 81 request received from Scheduler@node2.supernodexp.hpc, sock=16
02/19/2018 05:12:30;0100;Server@node2;Req;;Type 71 request received from Scheduler@node2.supernodexp.hpc, sock=16
02/19/2018 05:12:30;0100;Server@node2;Req;;Type 58 request received from Scheduler@node2.supernodexp.hpc, sock=16
02/19/2018 05:12:30;0100;Server@node2;Req;;Type 20 request received from Scheduler@node2.supernodexp.hpc, sock=16
02/19/2018 05:12:30;0100;Server@node2;Req;;Type 51 request received from Scheduler@node2.supernodexp.hpc, sock=16
02/19/2018 05:12:30;0100;Server@node2;Req;;Type 23 request received from Scheduler@node2.supernodexp.hpc, sock=16
02/19/2018 05:12:30;0008;Server@node2;Job;3550.node2.supernodexp.hpc;Job Run at request of Scheduler@node2.supernodexp.hpc on exec_vnode (node13:ncpus=48:mem=5242880kb)
02/19/2018 05:12:30;0001;Server@node2;Svr;Server@node2;Success (0) in req_runjob2, return value of svr_startjob is 0
02/19/2018 05:12:30;0100;Server@node2;Req;;Type 11 request received from Scheduler@node2.supernodexp.hpc, sock=16
02/19/2018 05:12:30;0008;Server@node2;Job;3566.node2.supernodexp.hpc;Job Modified at request of Scheduler@node2.supernodexp.hpc
02/19/2018 05:20:43;0080;Server@node2;Job;3548.node2.supernodexp.hpc;Obit received momhop:1 serverhop:1 state:4 substate:42
02/19/2018 05:20:44;0010;Server@node2;Job;3548.node2.supernodexp.hpc;Exit_status=0 resources_used.cpupercent=4735 resources_used.cput=08:09:03 resources_used.mem=8006780kb resources_used.ncpus=48 resources_used.vmem=47424208kb resources_used.walltime=00:10:36
02/19/2018 05:20:44;0100;Server@node2;Job;3548.node2.supernodexp.hpc;dequeuing from workq, state 5
02/19/2018 05:20:44;0040;Server@node2;Svr;node2.supernodexp.hpc;Scheduler sent command 2
02/19/2018 05:20:44;0040;Server@node2;Svr;node2.supernodexp.hpc;Scheduler sent command 0
02/19/2018 05:20:44;0100;Server@node2;Req;;Type 21 request received from Scheduler@node2.supernodexp.hpc, sock=16
02/19/2018 05:20:44;0100;Server@node2;Req;;Type 81 request received from Scheduler@node2.supernodexp.hpc, sock=16
02/19/2018 05:20:44;0100;Server@node2;Req;;Type 71 request received from Scheduler@node2.supernodexp.hpc, sock=16
02/19/2018 05:20:44;0100;Server@node2;Req;;Type 58 request received from Scheduler@node2.supernodexp.hpc, sock=16
02/19/2018 05:20:45;0100;Server@node2;Req;;Type 20 request received from Scheduler@node2.supernodexp.hpc, sock=16
02/19/2018 05:20:45;0100;Server@node2;Req;;Type 51 request received from Scheduler@node2.supernodexp.hpc, sock=16
02/19/2018 05:20:45;0100;Server@node2;Req;;Type 23 request received from Scheduler@node2.supernodexp.hpc, sock=16
02/19/2018 05:20:45;0008;Server@node2;Job;3566.node2.supernodexp.hpc;Job Run at request of Scheduler@node2.supernodexp.hpc on exec_vnode (node14:ncpus=48:mem=5242880kb)
02/19/2018 05:20:45;0001;Server@node2;Svr;Server@node2;Success (0) in req_runjob2, return value of svr_startjob is 0
02/19/2018 05:20:45;0100;Server@node2;Req;;Type 11 request received from Scheduler@node2.supernodexp.hpc, sock=16
02/19/2018 05:20:45;0008;Server@node2;Job;3620.node2.supernodexp.hpc;Job Modified at request of Scheduler@node2.supernodexp.hpc
02/19/2018 05:23:06;0080;Server@node2;Job;3550.node2.supernodexp.hpc;Obit received momhop:1 serverhop:1 state:4 substate:42
02/19/2018 05:23:07;0010;Server@node2;Job;3550.node2.supernodexp.hpc;Exit_status=0 resources_used.cpupercent=4742 resources_used.cput=08:12:34 resources_used.mem=7925608kb resources_used.ncpus=48 resources_used.vmem=47424940kb resources_used.walltime=00:10:36
02/19/2018 05:23:07;0100;Server@node2;Job;3550.node2.supernodexp.hpc;dequeuing from workq, state 5
02/19/2018 05:23:07;0040;Server@node2;Svr;node2.supernodexp.hpc;Scheduler sent command 2
02/19/2018 05:23:07;0040;Server@node2;Svr;node2.supernodexp.hpc;Scheduler sent command 0
02/19/2018 05:23:07;0100;Server@node2;Req;;Type 21 request received from Scheduler@node2.supernodexp.hpc, sock=16
02/19/2018 05:23:07;0100;Server@node2;Req;;Type 81 request received from Scheduler@node2.supernodexp.hpc, sock=16
02/19/2018 05:23:07;0100;Server@node2;Req;;Type 71 request received from Scheduler@node2.supernodexp.hpc, sock=16
02/19/2018 05:23:07;0100;Server@node2;Req;;Type 58 request received from Scheduler@node2.supernodexp.hpc, sock=16
02/19/2018 05:23:07;0100;Server@node2;Req;;Type 20 request received from Scheduler@node2.supernodexp.hpc, sock=16
02/19/2018 05:23:07;0100;Server@node2;Req;;Type 51 request received from Scheduler@node2.supernodexp.hpc, sock=16
02/19/2018 05:23:07;0100;Server@node2;Req;;Type 23 request received from Scheduler@node2.supernodexp.hpc, sock=16
02/19/2018 05:23:07;0008;Server@node2;Job;3620.node2.supernodexp.hpc;Job Run at request of Scheduler@node2.supernodexp.hpc on exec_vnode (node13:ncpus=48:mem=5242880kb)
02/19/2018 05:23:07;0001;Server@node2;Svr;Server@node2;Success (0) in req_runjob2, return value of svr_startjob is 0
02/19/2018 05:23:07;0100;Server@node2;Req;;Type 11 request received from Scheduler@node2.supernodexp.hpc, sock=16
02/19/2018 05:23:07;0008;Server@node2;Job;3621.node2.supernodexp.hpc;Job Modified at request of Scheduler@node2.supernodexp.hpc
02/19/2018 05:31:19;0080;Server@node2;Job;3566.node2.supernodexp.hpc;Obit received momhop:1 serverhop:1 state:4 substate:42
02/19/2018 05:31:20;0010;Server@node2;Job;3566.node2.supernodexp.hpc;Exit_status=0 resources_used.cpupercent=4742 resources_used.cput=08:07:32 resources_used.mem=7944412kb resources_used.ncpus=48 resources_used.vmem=47424192kb resources_used.walltime=00:10:34
02/19/2018 05:31:20;0100;Server@node2;Job;3566.node2.supernodexp.hpc;dequeuing from workq, state 5
02/19/2018 05:31:20;0040;Server@node2;Svr;node2.supernodexp.hpc;Scheduler sent command 2
02/19/2018 05:31:20;0040;Server@node2;Svr;node2.supernodexp.hpc;Scheduler sent command 0
02/19/2018 05:31:20;0100;Server@node2;Req;;Type 21 request received from Scheduler@node2.supernodexp.hpc, sock=16
02/19/2018 05:31:20;0100;Server@node2;Req;;Type 81 request received from Scheduler@node2.supernodexp.hpc, sock=16
02/19/2018 05:31:20;0100;Server@node2;Req;;Type 71 request received from Scheduler@node2.supernodexp.hpc, sock=16
02/19/2018 05:31:20;0100;Server@node2;Req;;Type 58 request received from Scheduler@node2.supernodexp.hpc, sock=16
02/19/2018 05:31:20;0100;Server@node2;Req;;Type 20 request received from Scheduler@node2.supernodexp.hpc, sock=16
02/19/2018 05:31:20;0100;Server@node2;Req;;Type 51 request received from Scheduler@node2.supernodexp.hpc, sock=16
02/19/2018 05:31:20;0100;Server@node2;Req;;Type 23 request received from Scheduler@node2.supernodexp.hpc, sock=16
02/19/2018 05:31:20;0008;Server@node2;Job;3621.node2.supernodexp.hpc;Job Run at request of Scheduler@node2.supernodexp.hpc on exec_vnode (node14:ncpus=48:mem=5242880kb)
02/19/2018 05:31:20;0001;Server@node2;Svr;Server@node2;Success (0) in req_runjob2, return value of svr_startjob is 0
02/19/2018 05:31:20;0100;Server@node2;Req;;Type 11 request received from Scheduler@node2.supernodexp.hpc, sock=16
02/19/2018 05:31:20;0008;Server@node2;Job;2665.node2.supernodexp.hpc;Job Modified at request of Scheduler@node2.supernodexp.hpc
02/19/2018 05:33:43;0080;Server@node2;Job;3620.node2.supernodexp.hpc;Obit received momhop:1 serverhop:1 state:4 substate:42
02/19/2018 05:33:45;0010;Server@node2;Job;3620.node2.supernodexp.hpc;Exit_status=0 resources_used.cpupercent=4738 resources_used.cput=08:17:59 resources_used.mem=7939540kb resources_used.ncpus=48 resources_used.vmem=47424608kb resources_used.walltime=00:10:36
02/19/2018 05:33:45;0100;Server@node2;Job;3620.node2.supernodexp.hpc;dequeuing from workq, state 5
02/19/2018 05:33:45;0040;Server@node2;Svr;node2.supernodexp.hpc;Scheduler sent command 2
02/19/2018 05:33:45;0040;Server@node2;Svr;node2.supernodexp.hpc;Scheduler sent command 0
02/19/2018 05:33:45;0100;Server@node2;Req;;Type 21 request received from Scheduler@node2.supernodexp.hpc, sock=16
02/19/2018 05:33:45;0100;Server@node2;Req;;Type 81 request received from Scheduler@node2.supernodexp.hpc, sock=16
02/19/2018 05:33:45;0100;Server@node2;Req;;Type 71 request received from Scheduler@node2.supernodexp.hpc, sock=16
02/19/2018 05:33:45;0100;Server@node2;Req;;Type 58 request received from Scheduler@node2.supernodexp.hpc, sock=16
02/19/2018 05:33:45;0100;Server@node2;Req;;Type 20 request received from Scheduler@node2.supernodexp.hpc, sock=16
02/19/2018 05:33:45;0100;Server@node2;Req;;Type 51 request received from Scheduler@node2.supernodexp.hpc, sock=16
02/19/2018 05:33:45;0100;Server@node2;Req;;Type 23 request received from Scheduler@node2.supernodexp.hpc, sock=16
02/19/2018 05:33:45;0008;Server@node2;Job;2665.node2.supernodexp.hpc;Job Run at request of Scheduler@node2.supernodexp.hpc on exec_vnode (node13:ncpus=32:nmics=1:mem=16777216kb)
02/19/2018 05:33:45;0001;Server@node2;Svr;Server@node2;Success (0) in req_runjob2, return value of svr_startjob is 0
02/19/2018 05:33:45;0100;Server@node2;Req;;Type 11 request received from Scheduler@node2.supernodexp.hpc, sock=16
02/19/2018 05:33:45;0008;Server@node2;Job;2668.node2.supernodexp.hpc;Job Modified at request of Scheduler@node2.supernodexp.hpc
02/19/2018 05:41:45;0080;Server@node2;Job;3621.node2.supernodexp.hpc;Obit received momhop:1 serverhop:1 state:4 substate:42
02/19/2018 05:41:47;0010;Server@node2;Job;3621.node2.supernodexp.hpc;Exit_status=0 resources_used.cpupercent=4730 resources_used.cput=08:08:59 resources_used.mem=7983900kb resources_used.ncpus=48 resources_used.vmem=47424524kb resources_used.walltime=00:10:24
02/19/2018 05:41:47;0100;Server@node2;Job;3621.node2.supernodexp.hpc;dequeuing from workq, state 5
02/19/2018 05:41:47;0040;Server@node2;Svr;node2.supernodexp.hpc;Scheduler sent command 2
02/19/2018 05:41:47;0040;Server@node2;Svr;node2.supernodexp.hpc;Scheduler sent command 0
02/19/2018 05:41:47;0100;Server@node2;Req;;Type 21 request received from Scheduler@node2.supernodexp.hpc, sock=16
02/19/2018 05:41:47;0100;Server@node2;Req;;Type 81 request received from Scheduler@node2.supernodexp.hpc, sock=16
02/19/2018 05:41:47;0100;Server@node2;Req;;Type 71 request received from Scheduler@node2.supernodexp.hpc, sock=16
02/19/2018 05:41:47;0100;Server@node2;Req;;Type 58 request received from Scheduler@node2.supernodexp.hpc, sock=16
02/19/2018 05:41:47;0100;Server@node2;Req;;Type 20 request received from Scheduler@node2.supernodexp.hpc, sock=16
02/19/2018 05:41:47;0100;Server@node2;Req;;Type 51 request received from Scheduler@node2.supernodexp.hpc, sock=16
02/19/2018 05:41:47;0100;Server@node2;Req;;Type 23 request received from Scheduler@node2.supernodexp.hpc, sock=16
02/19/2018 05:41:47;0008;Server@node2;Job;2668.node2.supernodexp.hpc;Job Run at request of Scheduler@node2.supernodexp.hpc on exec_vnode (node14:ncpus=32:nmics=1:mem=16777216kb)
02/19/2018 05:41:47;0001;Server@node2;Svr;Server@node2;Success (0) in req_runjob2, return value of svr_startjob is 0
02/19/2018 05:41:47;0100;Server@node2;Req;;Type 11 request received from Scheduler@node2.supernodexp.hpc, sock=16
02/19/2018 05:41:47;0008;Server@node2;Job;2672.node2.supernodexp.hpc;Job Modified at request of Scheduler@node2.supernodexp.hpc
02/19/2018 05:51:38;0080;Server@node2;Job;2665.node2.supernodexp.hpc;Obit received momhop:1 serverhop:1 state:4 substate:42
02/19/2018 05:51:39;0010;Server@node2;Job;2665.node2.supernodexp.hpc;Exit_status=2 resources_used.cpupercent=2186 resources_used.cput=06:20:58 resources_used.mem=21809356kb resources_used.ncpus=32 resources_used.vmem=24850164kb resources_used.walltime=00:17:52
02/19/2018 05:51:39;0100;Server@node2;Job;2665.node2.supernodexp.hpc;dequeuing from workq, state 5
02/19/2018 05:51:39;0040;Server@node2;Svr;node2.supernodexp.hpc;Scheduler sent command 2
02/19/2018 05:51:39;0040;Server@node2;Svr;node2.supernodexp.hpc;Scheduler sent command 0
02/19/2018 05:51:39;0100;Server@node2;Req;;Type 21 request received from Scheduler@node2.supernodexp.hpc, sock=16
02/19/2018 05:51:39;0100;Server@node2;Req;;Type 81 request received from Scheduler@node2.supernodexp.hpc, sock=16
02/19/2018 05:51:39;0100;Server@node2;Req;;Type 71 request received from Scheduler@node2.supernodexp.hpc, sock=16
02/19/2018 05:51:39;0100;Server@node2;Req;;Type 58 request received from Scheduler@node2.supernodexp.hpc, sock=16
02/19/2018 05:51:39;0100;Server@node2;Req;;Type 20 request received from Scheduler@node2.supernodexp.hpc, sock=16
02/19/2018 05:51:39;0100;Server@node2;Req;;Type 51 request received from Scheduler@node2.supernodexp.hpc, sock=16
02/19/2018 05:51:39;0100;Server@node2;Req;;Type 23 request received from Scheduler@node2.supernodexp.hpc, sock=16
02/19/2018 05:51:39;0008;Server@node2;Job;2672.node2.supernodexp.hpc;Job Run at request of Scheduler@node2.supernodexp.hpc on exec_vnode (node13:ncpus=32:nmics=1:mem=16777216kb)
02/19/2018 05:51:39;0001;Server@node2;Svr;Server@node2;Success (0) in req_runjob2, return value of svr_startjob is 0
02/19/2018 05:51:39;0100;Server@node2;Req;;Type 11 request received from Scheduler@node2.supernodexp.hpc, sock=16
02/19/2018 05:51:39;0008;Server@node2;Job;2676.node2.supernodexp.hpc;Job Modified at request of Scheduler@node2.supernodexp.hpc
02/19/2018 06:00:12;0080;Server@node2;Job;2668.node2.supernodexp.hpc;Obit received momhop:1 serverhop:1 state:4 substate:42
02/19/2018 06:00:13;0010;Server@node2;Job;2668.node2.supernodexp.hpc;Exit_status=2 resources_used.cpupercent=2088 resources_used.cput=06:11:24 resources_used.mem=22207824kb resources_used.ncpus=32 resources_used.vmem=24949956kb resources_used.walltime=00:18:25
02/19/2018 06:00:13;0100;Server@node2;Job;2668.node2.supernodexp.hpc;dequeuing from workq, state 5
02/19/2018 06:00:13;0040;Server@node2;Svr;node2.supernodexp.hpc;Scheduler sent command 2
02/19/2018 06:00:13;0040;Server@node2;Svr;node2.supernodexp.hpc;Scheduler sent command 0
02/19/2018 06:00:13;0100;Server@node2;Req;;Type 21 request received from Scheduler@node2.supernodexp.hpc, sock=16
02/19/2018 06:00:13;0100;Server@node2;Req;;Type 81 request received from Scheduler@node2.supernodexp.hpc, sock=16
02/19/2018 06:00:13;0100;Server@node2;Req;;Type 71 request received from Scheduler@node2.supernodexp.hpc, sock=16
02/19/2018 06:00:13;0100;Server@node2;Req;;Type 58 request received from Scheduler@node2.supernodexp.hpc, sock=16
02/19/2018 06:00:13;0100;Server@node2;Req;;Type 20 request received from Scheduler@node2.supernodexp.hpc, sock=16
02/19/2018 06:00:13;0100;Server@node2;Req;;Type 51 request received from Scheduler@node2.supernodexp.hpc, sock=16
02/19/2018 06:00:13;0100;Server@node2;Req;;Type 23 request received from Scheduler@node2.supernodexp.hpc, sock=16
02/19/2018 06:00:13;0008;Server@node2;Job;2676.node2.supernodexp.hpc;Job Run at request of Scheduler@node2.supernodexp.hpc on exec_vnode (node14:ncpus=32:nmics=1:mem=16777216kb)
02/19/2018 06:00:13;0001;Server@node2;Svr;Server@node2;Success (0) in req_runjob2, return value of svr_startjob is 0
02/19/2018 06:00:13;0100;Server@node2;Req;;Type 11 request received from Scheduler@node2.supernodexp.hpc, sock=16
02/19/2018 06:00:13;0008;Server@node2;Job;2679.node2.supernodexp.hpc;Job Modified at request of Scheduler@node2.supernodexp.hpc
02/19/2018 06:10:13;0040;Server@node2;Svr;node2.supernodexp.hpc;Scheduler sent command 3
02/19/2018 06:10:13;0040;Server@node2;Svr;node2.supernodexp.hpc;Scheduler sent command 0
02/19/2018 06:10:13;0100;Server@node2;Req;;Type 21 request received from Scheduler@node2.supernodexp.hpc, sock=16
02/19/2018 06:10:13;0100;Server@node2;Req;;Type 81 request received from Scheduler@node2.supernodexp.hpc, sock=16
02/19/2018 06:10:13;0100;Server@node2;Req;;Type 71 request received from Scheduler@node2.supernodexp.hpc, sock=16
02/19/2018 06:10:13;0100;Server@node2;Req;;Type 58 request received from Scheduler@node2.supernodexp.hpc, sock=16
02/19/2018 06:10:13;0100;Server@node2;Req;;Type 20 request received from Scheduler@node2.supernodexp.hpc, sock=16
02/19/2018 06:10:13;0100;Server@node2;Req;;Type 51 request received from Scheduler@node2.supernodexp.hpc, sock=16
02/19/2018 06:10:22;0080;Server@node2;Job;2672.node2.supernodexp.hpc;Obit received momhop:1 serverhop:1 state:4 substate:42
02/19/2018 06:10:23;0010;Server@node2;Job;2672.node2.supernodexp.hpc;Exit_status=2 resources_used.cpupercent=2199 resources_used.cput=06:36:38 resources_used.mem=21816380kb resources_used.ncpus=32 resources_used.vmem=25039348kb resources_used.walltime=00:18:43
02/19/2018 06:10:23;0100;Server@node2;Job;2672.node2.supernodexp.hpc;dequeuing from workq, state 5
02/19/2018 06:10:23;0040;Server@node2;Svr;node2.supernodexp.hpc;Scheduler sent command 2
02/19/2018 06:10:23;0040;Server@node2;Svr;node2.supernodexp.hpc;Scheduler sent command 0
02/19/2018 06:10:23;0100;Server@node2;Req;;Type 21 request received from Scheduler@node2.supernodexp.hpc, sock=16
02/19/2018 06:10:23;0100;Server@node2;Req;;Type 81 request received from Scheduler@node2.supernodexp.hpc, sock=16
02/19/2018 06:10:23;0100;Server@node2;Req;;Type 71 request received from Scheduler@node2.supernodexp.hpc, sock=16
02/19/2018 06:10:23;0100;Server@node2;Req;;Type 58 request received from Scheduler@node2.supernodexp.hpc, sock=16
02/19/2018 06:10:23;0100;Server@node2;Req;;Type 20 request received from Scheduler@node2.supernodexp.hpc, sock=16
02/19/2018 06:10:23;0100;Server@node2;Req;;Type 51 request received from Scheduler@node2.supernodexp.hpc, sock=16
02/19/2018 06:10:23;0100;Server@node2;Req;;Type 23 request received from Scheduler@node2.supernodexp.hpc, sock=16
02/19/2018 06:10:23;0008;Server@node2;Job;2679.node2.supernodexp.hpc;Job Run at request of Scheduler@node2.supernodexp.hpc on exec_vnode (node13:ncpus=32:nmics=1:mem=16777216kb)
02/19/2018 06:10:23;0001;Server@node2;Svr;Server@node2;Success (0) in req_runjob2, return value of svr_startjob is 0
02/19/2018 06:10:23;0100;Server@node2;Req;;Type 11 request received from Scheduler@node2.supernodexp.hpc, sock=16
02/19/2018 06:10:23;0008;Server@node2;Job;2686.node2.supernodexp.hpc;Job Modified at request of Scheduler@node2.supernodexp.hpc
02/19/2018 06:18:40;0080;Server@node2;Job;2676.node2.supernodexp.hpc;Obit received momhop:1 serverhop:1 state:4 substate:42
02/19/2018 06:18:41;0010;Server@node2;Job;2676.node2.supernodexp.hpc;Exit_status=2 resources_used.cpupercent=2133 resources_used.cput=06:17:57 resources_used.mem=22053128kb resources_used.ncpus=32 resources_used.vmem=24782676kb resources_used.walltime=00:18:27
02/19/2018 06:18:41;0100;Server@node2;Job;2676.node2.supernodexp.hpc;dequeuing from workq, state 5
02/19/2018 06:18:41;0040;Server@node2;Svr;node2.supernodexp.hpc;Scheduler sent command 2
02/19/2018 06:18:41;0040;Server@node2;Svr;node2.supernodexp.hpc;Scheduler sent command 0
02/19/2018 06:18:41;0100;Server@node2;Req;;Type 21 request received from Scheduler@node2.supernodexp.hpc, sock=16
02/19/2018 06:18:41;0100;Server@node2;Req;;Type 81 request received from Scheduler@node2.supernodexp.hpc, sock=16
02/19/2018 06:18:41;0100;Server@node2;Req;;Type 71 request received from Scheduler@node2.supernodexp.hpc, sock=16
02/19/2018 06:18:41;0100;Server@node2;Req;;Type 58 request received from Scheduler@node2.supernodexp.hpc, sock=16
02/19/2018 06:18:41;0100;Server@node2;Req;;Type 20 request received from Scheduler@node2.supernodexp.hpc, sock=16
02/19/2018 06:18:41;0100;Server@node2;Req;;Type 51 request received from Scheduler@node2.supernodexp.hpc, sock=16
02/19/2018 06:18:41;0100;Server@node2;Req;;Type 23 request received from Scheduler@node2.supernodexp.hpc, sock=16
02/19/2018 06:18:41;0008;Server@node2;Job;2686.node2.supernodexp.hpc;Job Run at request of Scheduler@node2.supernodexp.hpc on exec_vnode (node14:ncpus=32:nmics=1:mem=16777216kb)
02/19/2018 06:18:41;0001;Server@node2;Svr;Server@node2;Success (0) in req_runjob2, return value of svr_startjob is 0
02/19/2018 06:18:41;0100;Server@node2;Req;;Type 11 request received from Scheduler@node2.supernodexp.hpc, sock=16
02/19/2018 06:18:41;0008;Server@node2;Job;2711.node2.supernodexp.hpc;Job Modified at request of Scheduler@node2.supernodexp.hpc
02/19/2018 06:28:29;0080;Server@node2;Job;2679.node2.supernodexp.hpc;Obit received momhop:1 serverhop:1 state:4 substate:42
02/19/2018 06:28:30;0010;Server@node2;Job;2679.node2.supernodexp.hpc;Exit_status=2 resources_used.cpupercent=2172 resources_used.cput=06:28:07 resources_used.mem=22060704kb resources_used.ncpus=32 resources_used.vmem=25076708kb resources_used.walltime=00:18:06
02/19/2018 06:28:30;0100;Server@node2;Job;2679.node2.supernodexp.hpc;dequeuing from workq, state 5
02/19/2018 06:28:30;0040;Server@node2;Svr;node2.supernodexp.hpc;Scheduler sent command 2
02/19/2018 06:28:30;0040;Server@node2;Svr;node2.supernodexp.hpc;Scheduler sent command 0
02/19/2018 06:28:30;0100;Server@node2;Req;;Type 21 request received from Scheduler@node2.supernodexp.hpc, sock=16
02/19/2018 06:28:30;0100;Server@node2;Req;;Type 81 request received from Scheduler@node2.supernodexp.hpc, sock=16
02/19/2018 06:28:30;0100;Server@node2;Req;;Type 71 request received from Scheduler@node2.supernodexp.hpc, sock=16
02/19/2018 06:28:30;0100;Server@node2;Req;;Type 58 request received from Scheduler@node2.supernodexp.hpc, sock=16
02/19/2018 06:28:30;0100;Server@node2;Req;;Type 20 request received from Scheduler@node2.supernodexp.hpc, sock=16
02/19/2018 06:28:30;0100;Server@node2;Req;;Type 51 request received from Scheduler@node2.supernodexp.hpc, sock=16
02/19/2018 06:28:30;0100;Server@node2;Req;;Type 23 request received from Scheduler@node2.supernodexp.hpc, sock=16
02/19/2018 06:28:30;0008;Server@node2;Job;2711.node2.supernodexp.hpc;Job Run at request of Scheduler@node2.supernodexp.hpc on exec_vnode (node13:ncpus=32:nmics=1:mem=16777216kb)
02/19/2018 06:28:30;0001;Server@node2;Svr;Server@node2;Success (0) in req_runjob2, return value of svr_startjob is 0
02/19/2018 06:28:30;0100;Server@node2;Req;;Type 11 request received from Scheduler@node2.supernodexp.hpc, sock=16
02/19/2018 06:28:30;0008;Server@node2;Job;2727.node2.supernodexp.hpc;Job Modified at request of Scheduler@node2.supernodexp.hpc
02/19/2018 06:36:51;0080;Server@node2;Job;2686.node2.supernodexp.hpc;Obit received momhop:1 serverhop:1 state:4 substate:42
02/19/2018 06:36:53;0010;Server@node2;Job;2686.node2.supernodexp.hpc;Exit_status=2 resources_used.cpupercent=2091 resources_used.cput=06:10:25 resources_used.mem=22165468kb resources_used.ncpus=32 resources_used.vmem=24900628kb resources_used.walltime=00:18:10
02/19/2018 06:36:53;0100;Server@node2;Job;2686.node2.supernodexp.hpc;dequeuing from workq, state 5
02/19/2018 06:36:53;0040;Server@node2;Svr;node2.supernodexp.hpc;Scheduler sent command 2
02/19/2018 06:36:53;0040;Server@node2;Svr;node2.supernodexp.hpc;Scheduler sent command 0
02/19/2018 06:36:53;0100;Server@node2;Req;;Type 21 request received from Scheduler@node2.supernodexp.hpc, sock=16
02/19/2018 06:36:53;0100;Server@node2;Req;;Type 81 request received from Scheduler@node2.supernodexp.hpc, sock=16
02/19/2018 06:36:53;0100;Server@node2;Req;;Type 71 request received from Scheduler@node2.supernodexp.hpc, sock=16
02/19/2018 06:36:53;0100;Server@node2;Req;;Type 58 request received from Scheduler@node2.supernodexp.hpc, sock=16
02/19/2018 06:36:53;0100;Server@node2;Req;;Type 20 request received from Scheduler@node2.supernodexp.hpc, sock=16
02/19/2018 06:36:53;0100;Server@node2;Req;;Type 51 request received from Scheduler@node2.supernodexp.hpc, sock=16
02/19/2018 06:36:53;0100;Server@node2;Req;;Type 23 request received from Scheduler@node2.supernodexp.hpc, sock=16
02/19/2018 06:36:53;0008;Server@node2;Job;2727.node2.supernodexp.hpc;Job Run at request of Scheduler@node2.supernodexp.hpc on exec_vnode (node14:ncpus=32:nmics=1:mem=16777216kb)
02/19/2018 06:36:53;0001;Server@node2;Svr;Server@node2;Success (0) in req_runjob2, return value of svr_startjob is 0
02/19/2018 06:36:53;0100;Server@node2;Req;;Type 11 request received from Scheduler@node2.supernodexp.hpc, sock=16
02/19/2018 06:36:53;0008;Server@node2;Job;2733.node2.supernodexp.hpc;Job Modified at request of Scheduler@node2.supernodexp.hpc
02/19/2018 06:46:38;0080;Server@node2;Job;2711.node2.supernodexp.hpc;Obit received momhop:1 serverhop:1 state:4 substate:42
02/19/2018 06:46:39;0010;Server@node2;Job;2711.node2.supernodexp.hpc;Exit_status=2 resources_used.cpupercent=2146 resources_used.cput=06:29:11 resources_used.mem=21839316kb resources_used.ncpus=32 resources_used.vmem=24868600kb resources_used.walltime=00:18:08
02/19/2018 06:46:39;0100;Server@node2;Job;2711.node2.supernodexp.hpc;dequeuing from workq, state 5
02/19/2018 06:46:39;0040;Server@node2;Svr;node2.supernodexp.hpc;Scheduler sent command 2
02/19/2018 06:46:39;0040;Server@node2;Svr;node2.supernodexp.hpc;Scheduler sent command 0
02/19/2018 06:46:39;0100;Server@node2;Req;;Type 21 request received from Scheduler@node2.supernodexp.hpc, sock=16
02/19/2018 06:46:39;0100;Server@node2;Req;;Type 81 request received from Scheduler@node2.supernodexp.hpc, sock=16
02/19/2018 06:46:39;0100;Server@node2;Req;;Type 71 request received from Scheduler@node2.supernodexp.hpc, sock=16
02/19/2018 06:46:39;0100;Server@node2;Req;;Type 58 request received from Scheduler@node2.supernodexp.hpc, sock=16
02/19/2018 06:46:39;0100;Server@node2;Req;;Type 20 request received from Scheduler@node2.supernodexp.hpc, sock=16
02/19/2018 06:46:39;0100;Server@node2;Req;;Type 51 request received from Scheduler@node2.supernodexp.hpc, sock=16
02/19/2018 06:46:39;0100;Server@node2;Req;;Type 23 request received from Scheduler@node2.supernodexp.hpc, sock=16
02/19/2018 06:46:39;0008;Server@node2;Job;2733.node2.supernodexp.hpc;Job Run at request of Scheduler@node2.supernodexp.hpc on exec_vnode (node13:ncpus=32:nmics=1:mem=16777216kb)
02/19/2018 06:46:39;0001;Server@node2;Svr;Server@node2;Success (0) in req_runjob2, return value of svr_startjob is 0
02/19/2018 06:46:39;0100;Server@node2;Req;;Type 11 request received from Scheduler@node2.supernodexp.hpc, sock=16
02/19/2018 06:46:39;0008;Server@node2;Job;2767.node2.supernodexp.hpc;Job Modified at request of Scheduler@node2.supernodexp.hpc
02/19/2018 06:55:20;0080;Server@node2;Job;2727.node2.supernodexp.hpc;Obit received momhop:1 serverhop:1 state:4 substate:42
02/19/2018 06:55:22;0010;Server@node2;Job;2727.node2.supernodexp.hpc;Exit_status=2 resources_used.cpupercent=2123 resources_used.cput=06:15:52 resources_used.mem=22212500kb resources_used.ncpus=32 resources_used.vmem=24914456kb resources_used.walltime=00:18:27
02/19/2018 06:55:22;0100;Server@node2;Job;2727.node2.supernodexp.hpc;dequeuing from workq, state 5
02/19/2018 06:55:22;0040;Server@node2;Svr;node2.supernodexp.hpc;Scheduler sent command 2
02/19/2018 06:55:22;0040;Server@node2;Svr;node2.supernodexp.hpc;Scheduler sent command 0
02/19/2018 06:55:22;0100;Server@node2;Req;;Type 21 request received from Scheduler@node2.supernodexp.hpc, sock=16
02/19/2018 06:55:22;0100;Server@node2;Req;;Type 81 request received from Scheduler@node2.supernodexp.hpc, sock=16
02/19/2018 06:55:22;0100;Server@node2;Req;;Type 71 request received from Scheduler@node2.supernodexp.hpc, sock=16
02/19/2018 06:55:22;0100;Server@node2;Req;;Type 58 request received from Scheduler@node2.supernodexp.hpc, sock=16
02/19/2018 06:55:22;0100;Server@node2;Req;;Type 20 request received from Scheduler@node2.supernodexp.hpc, sock=16
02/19/2018 06:55:22;0100;Server@node2;Req;;Type 51 request received from Scheduler@node2.supernodexp.hpc, sock=16
02/19/2018 06:55:22;0100;Server@node2;Req;;Type 23 request received from Scheduler@node2.supernodexp.hpc, sock=16
02/19/2018 06:55:22;0008;Server@node2;Job;2767.node2.supernodexp.hpc;Job Run at request of Scheduler@node2.supernodexp.hpc on exec_vnode (node14:ncpus=32:nmics=1:mem=16777216kb)
02/19/2018 06:55:22;0001;Server@node2;Svr;Server@node2;Success (0) in req_runjob2, return value of svr_startjob is 0
02/19/2018 06:55:22;0100;Server@node2;Req;;Type 11 request received from Scheduler@node2.supernodexp.hpc, sock=16
02/19/2018 06:55:22;0008;Server@node2;Job;2776.node2.supernodexp.hpc;Job Modified at request of Scheduler@node2.supernodexp.hpc
02/19/2018 07:05:08;0080;Server@node2;Job;2733.node2.supernodexp.hpc;Obit received momhop:1 serverhop:1 state:4 substate:42
02/19/2018 07:05:09;0010;Server@node2;Job;2733.node2.supernodexp.hpc;Exit_status=2 resources_used.cpupercent=2158 resources_used.cput=06:28:32 resources_used.mem=21839076kb resources_used.ncpus=32 resources_used.vmem=24850172kb resources_used.walltime=00:18:28
02/19/2018 07:05:09;0100;Server@node2;Job;2733.node2.supernodexp.hpc;dequeuing from workq, state 5
02/19/2018 07:05:09;0040;Server@node2;Svr;node2.supernodexp.hpc;Scheduler sent command 2
02/19/2018 07:05:09;0040;Server@node2;Svr;node2.supernodexp.hpc;Scheduler sent command 0
02/19/2018 07:05:09;0100;Server@node2;Req;;Type 21 request received from Scheduler@node2.supernodexp.hpc, sock=16
02/19/2018 07:05:09;0100;Server@node2;Req;;Type 81 request received from Scheduler@node2.supernodexp.hpc, sock=16
02/19/2018 07:05:09;0100;Server@node2;Req;;Type 71 request received from Scheduler@node2.supernodexp.hpc, sock=16
02/19/2018 07:05:09;0100;Server@node2;Req;;Type 58 request received from Scheduler@node2.supernodexp.hpc, sock=16
02/19/2018 07:05:09;0100;Server@node2;Req;;Type 20 request received from Scheduler@node2.supernodexp.hpc, sock=16
02/19/2018 07:05:09;0100;Server@node2;Req;;Type 51 request received from Scheduler@node2.supernodexp.hpc, sock=16
02/19/2018 07:05:09;0100;Server@node2;Req;;Type 23 request received from Scheduler@node2.supernodexp.hpc, sock=16
02/19/2018 07:05:09;0008;Server@node2;Job;2776.node2.supernodexp.hpc;Job Run at request of Scheduler@node2.supernodexp.hpc on exec_vnode (node13:ncpus=32:nmics=1:mem=16777216kb)
02/19/2018 07:05:09;0001;Server@node2;Svr;Server@node2;Success (0) in req_runjob2, return value of svr_startjob is 0
02/19/2018 07:05:09;0100;Server@node2;Req;;Type 11 request received from Scheduler@node2.supernodexp.hpc, sock=16
02/19/2018 07:05:09;0008;Server@node2;Job;2781.node2.supernodexp.hpc;Job Modified at request of Scheduler@node2.supernodexp.hpc
02/19/2018 07:13:52;0080;Server@node2;Job;2767.node2.supernodexp.hpc;Obit received momhop:1 serverhop:1 state:4 substate:42
02/19/2018 07:13:54;0010;Server@node2;Job;2767.node2.supernodexp.hpc;Exit_status=2 resources_used.cpupercent=2087 resources_used.cput=06:13:43 resources_used.mem=22206788kb resources_used.ncpus=32 resources_used.vmem=24917168kb resources_used.walltime=00:18:30
02/19/2018 07:13:54;0100;Server@node2;Job;2767.node2.supernodexp.hpc;dequeuing from workq, state 5
02/19/2018 07:13:54;0040;Server@node2;Svr;node2.supernodexp.hpc;Scheduler sent command 2
02/19/2018 07:13:54;0040;Server@node2;Svr;node2.supernodexp.hpc;Scheduler sent command 0
02/19/2018 07:13:54;0100;Server@node2;Req;;Type 21 request received from Scheduler@node2.supernodexp.hpc, sock=16
02/19/2018 07:13:54;0100;Server@node2;Req;;Type 81 request received from Scheduler@node2.supernodexp.hpc, sock=16
02/19/2018 07:13:54;0100;Server@node2;Req;;Type 71 request received from Scheduler@node2.supernodexp.hpc, sock=16
02/19/2018 07:13:54;0100;Server@node2;Req;;Type 58 request received from Scheduler@node2.supernodexp.hpc, sock=16
02/19/2018 07:13:54;0100;Server@node2;Req;;Type 20 request received from Scheduler@node2.supernodexp.hpc, sock=16
02/19/2018 07:13:54;0100;Server@node2;Req;;Type 51 request received from Scheduler@node2.supernodexp.hpc, sock=16
02/19/2018 07:13:54;0100;Server@node2;Req;;Type 23 request received from Scheduler@node2.supernodexp.hpc, sock=16
02/19/2018 07:13:54;0008;Server@node2;Job;2781.node2.supernodexp.hpc;Job Run at request of Scheduler@node2.supernodexp.hpc on exec_vnode (node14:ncpus=32:nmics=1:mem=16777216kb)
02/19/2018 07:13:54;0001;Server@node2;Svr;Server@node2;Success (0) in req_runjob2, return value of svr_startjob is 0
02/19/2018 07:13:54;0100;Server@node2;Req;;Type 11 request received from Scheduler@node2.supernodexp.hpc, sock=16
02/19/2018 07:13:54;0008;Server@node2;Job;2815.node2.supernodexp.hpc;Job Modified at request of Scheduler@node2.supernodexp.hpc
02/19/2018 07:23:23;0080;Server@node2;Job;2776.node2.supernodexp.hpc;Obit received momhop:1 serverhop:1 state:4 substate:42
02/19/2018 07:23:25;0010;Server@node2;Job;2776.node2.supernodexp.hpc;Exit_status=2 resources_used.cpupercent=2162 resources_used.cput=06:31:48 resources_used.mem=21832600kb resources_used.ncpus=32 resources_used.vmem=24868596kb resources_used.walltime=00:18:15
02/19/2018 07:23:25;0100;Server@node2;Job;2776.node2.supernodexp.hpc;dequeuing from workq, state 5
02/19/2018 07:23:25;0040;Server@node2;Svr;node2.supernodexp.hpc;Scheduler sent command 2
02/19/2018 07:23:25;0040;Server@node2;Svr;node2.supernodexp.hpc;Scheduler sent command 0
02/19/2018 07:23:25;0100;Server@node2;Req;;Type 21 request received from Scheduler@node2.supernodexp.hpc, sock=16
02/19/2018 07:23:25;0100;Server@node2;Req;;Type 81 request received from Scheduler@node2.supernodexp.hpc, sock=16
02/19/2018 07:23:25;0100;Server@node2;Req;;Type 71 request received from Scheduler@node2.supernodexp.hpc, sock=16
02/19/2018 07:23:25;0100;Server@node2;Req;;Type 58 request received from Scheduler@node2.supernodexp.hpc, sock=16
02/19/2018 07:23:25;0100;Server@node2;Req;;Type 20 request received from Scheduler@node2.supernodexp.hpc, sock=16
02/19/2018 07:23:25;0100;Server@node2;Req;;Type 51 request received from Scheduler@node2.supernodexp.hpc, sock=16
02/19/2018 07:23:25;0100;Server@node2;Req;;Type 23 request received from Scheduler@node2.supernodexp.hpc, sock=16
02/19/2018 07:23:25;0008;Server@node2;Job;2815.node2.supernodexp.hpc;Job Run at request of Scheduler@node2.supernodexp.hpc on exec_vnode (node13:ncpus=32:nmics=1:mem=16777216kb)
02/19/2018 07:23:25;0001;Server@node2;Svr;Server@node2;Success (0) in req_runjob2, return value of svr_startjob is 0
02/19/2018 07:23:25;0100;Server@node2;Req;;Type 11 request received from Scheduler@node2.supernodexp.hpc, sock=16
02/19/2018 07:23:25;0008;Server@node2;Job;2829.node2.supernodexp.hpc;Job Modified at request of Scheduler@node2.supernodexp.hpc
02/19/2018 07:32:19;0080;Server@node2;Job;2781.node2.supernodexp.hpc;Obit received momhop:1 serverhop:1 state:4 substate:42
02/19/2018 07:32:20;0010;Server@node2;Job;2781.node2.supernodexp.hpc;Exit_status=2 resources_used.cpupercent=2147 resources_used.cput=06:16:14 resources_used.mem=22211368kb resources_used.ncpus=32 resources_used.vmem=24917508kb resources_used.walltime=00:18:25
02/19/2018 07:32:20;0100;Server@node2;Job;2781.node2.supernodexp.hpc;dequeuing from workq, state 5
02/19/2018 07:32:20;0040;Server@node2;Svr;node2.supernodexp.hpc;Scheduler sent command 2
02/19/2018 07:32:20;0040;Server@node2;Svr;node2.supernodexp.hpc;Scheduler sent command 0
02/19/2018 07:32:20;0100;Server@node2;Req;;Type 21 request received from Scheduler@node2.supernodexp.hpc, sock=16
02/19/2018 07:32:20;0100;Server@node2;Req;;Type 81 request received from Scheduler@node2.supernodexp.hpc, sock=16
02/19/2018 07:32:20;0100;Server@node2;Req;;Type 71 request received from Scheduler@node2.supernodexp.hpc, sock=16
02/19/2018 07:32:20;0100;Server@node2;Req;;Type 58 request received from Scheduler@node2.supernodexp.hpc, sock=16
02/19/2018 07:32:20;0100;Server@node2;Req;;Type 20 request received from Scheduler@node2.supernodexp.hpc, sock=16
02/19/2018 07:32:20;0100;Server@node2;Req;;Type 51 request received from Scheduler@node2.supernodexp.hpc, sock=16
02/19/2018 07:32:21;0100;Server@node2;Req;;Type 23 request received from Scheduler@node2.supernodexp.hpc, sock=16
02/19/2018 07:32:21;0008;Server@node2;Job;2829.node2.supernodexp.hpc;Job Run at request of Scheduler@node2.supernodexp.hpc on exec_vnode (node14:ncpus=32:nmics=1:mem=16777216kb)
02/19/2018 07:32:21;0001;Server@node2;Svr;Server@node2;Success (0) in req_runjob2, return value of svr_startjob is 0
02/19/2018 07:32:21;0100;Server@node2;Req;;Type 11 request received from Scheduler@node2.supernodexp.hpc, sock=16
02/19/2018 07:32:21;0008;Server@node2;Job;2831.node2.supernodexp.hpc;Job Modified at request of Scheduler@node2.supernodexp.hpc
02/19/2018 07:41:35;0080;Server@node2;Job;2815.node2.supernodexp.hpc;Obit received momhop:1 serverhop:1 state:4 substate:42
02/19/2018 07:41:37;0010;Server@node2;Job;2815.node2.supernodexp.hpc;Exit_status=2 resources_used.cpupercent=2187 resources_used.cput=06:29:54 resources_used.mem=21819884kb resources_used.ncpus=32 resources_used.vmem=24852740kb resources_used.walltime=00:18:11
02/19/2018 07:41:37;0100;Server@node2;Job;2815.node2.supernodexp.hpc;dequeuing from workq, state 5
02/19/2018 07:41:37;0040;Server@node2;Svr;node2.supernodexp.hpc;Scheduler sent command 2
02/19/2018 07:41:37;0040;Server@node2;Svr;node2.supernodexp.hpc;Scheduler sent command 0
02/19/2018 07:41:37;0100;Server@node2;Req;;Type 21 request received from Scheduler@node2.supernodexp.hpc, sock=16
02/19/2018 07:41:37;0100;Server@node2;Req;;Type 81 request received from Scheduler@node2.supernodexp.hpc, sock=16
02/19/2018 07:41:37;0100;Server@node2;Req;;Type 71 request received from Scheduler@node2.supernodexp.hpc, sock=16
02/19/2018 07:41:37;0100;Server@node2;Req;;Type 58 request received from Scheduler@node2.supernodexp.hpc, sock=16
02/19/2018 07:41:37;0100;Server@node2;Req;;Type 20 request received from Scheduler@node2.supernodexp.hpc, sock=16
02/19/2018 07:41:37;0100;Server@node2;Req;;Type 51 request received from Scheduler@node2.supernodexp.hpc, sock=16
02/19/2018 07:41:37;0100;Server@node2;Req;;Type 23 request received from Scheduler@node2.supernodexp.hpc, sock=16
02/19/2018 07:41:37;0008;Server@node2;Job;2831.node2.supernodexp.hpc;Job Run at request of Scheduler@node2.supernodexp.hpc on exec_vnode (node13:ncpus=32:nmics=1:mem=16777216kb)
02/19/2018 07:41:37;0001;Server@node2;Svr;Server@node2;Success (0) in req_runjob2, return value of svr_startjob is 0
02/19/2018 07:41:37;0100;Server@node2;Req;;Type 11 request received from Scheduler@node2.supernodexp.hpc, sock=16
02/19/2018 07:41:37;0008;Server@node2;Job;2834.node2.supernodexp.hpc;Job Modified at request of Scheduler@node2.supernodexp.hpc
02/19/2018 07:50:39;0080;Server@node2;Job;2829.node2.supernodexp.hpc;Obit received momhop:1 serverhop:1 state:4 substate:42
02/19/2018 07:50:40;0010;Server@node2;Job;2829.node2.supernodexp.hpc;Exit_status=2 resources_used.cpupercent=2085 resources_used.cput=06:12:17 resources_used.mem=22161556kb resources_used.ncpus=32 resources_used.vmem=24900624kb resources_used.walltime=00:18:18
02/19/2018 07:50:40;0100;Server@node2;Job;2829.node2.supernodexp.hpc;dequeuing from workq, state 5
02/19/2018 07:50:40;0040;Server@node2;Svr;node2.supernodexp.hpc;Scheduler sent command 2
02/19/2018 07:50:40;0040;Server@node2;Svr;node2.supernodexp.hpc;Scheduler sent command 0
02/19/2018 07:50:40;0100;Server@node2;Req;;Type 21 request received from Scheduler@node2.supernodexp.hpc, sock=16
02/19/2018 07:50:40;0100;Server@node2;Req;;Type 81 request received from Scheduler@node2.supernodexp.hpc, sock=16
02/19/2018 07:50:40;0100;Server@node2;Req;;Type 71 request received from Scheduler@node2.supernodexp.hpc, sock=16
02/19/2018 07:50:40;0100;Server@node2;Req;;Type 58 request received from Scheduler@node2.supernodexp.hpc, sock=16
02/19/2018 07:50:40;0100;Server@node2;Req;;Type 20 request received from Scheduler@node2.supernodexp.hpc, sock=16
02/19/2018 07:50:40;0100;Server@node2;Req;;Type 51 request received from Scheduler@node2.supernodexp.hpc, sock=16
02/19/2018 07:50:40;0100;Server@node2;Req;;Type 23 request received from Scheduler@node2.supernodexp.hpc, sock=16
02/19/2018 07:50:40;0008;Server@node2;Job;2834.node2.supernodexp.hpc;Job Run at request of Scheduler@node2.supernodexp.hpc on exec_vnode (node14:ncpus=32:nmics=1:mem=16777216kb)
02/19/2018 07:50:40;0001;Server@node2;Svr;Server@node2;Success (0) in req_runjob2, return value of svr_startjob is 0
02/19/2018 07:50:40;0100;Server@node2;Req;;Type 11 request received from Scheduler@node2.supernodexp.hpc, sock=16
02/19/2018 07:50:40;0008;Server@node2;Job;2847.node2.supernodexp.hpc;Job Modified at request of Scheduler@node2.supernodexp.hpc
02/19/2018 08:00:07;0080;Server@node2;Job;2831.node2.supernodexp.hpc;Obit received momhop:1 serverhop:1 state:4 substate:42
02/19/2018 08:00:08;0010;Server@node2;Job;2831.node2.supernodexp.hpc;Exit_status=2 resources_used.cpupercent=2173 resources_used.cput=06:31:06 resources_used.mem=22031576kb resources_used.ncpus=32 resources_used.vmem=25065764kb resources_used.walltime=00:18:30
02/19/2018 08:00:08;0100;Server@node2;Job;2831.node2.supernodexp.hpc;dequeuing from workq, state 5
02/19/2018 08:00:08;0040;Server@node2;Svr;node2.supernodexp.hpc;Scheduler sent command 2
02/19/2018 08:00:08;0040;Server@node2;Svr;node2.supernodexp.hpc;Scheduler sent command 0
02/19/2018 08:00:08;0100;Server@node2;Req;;Type 21 request received from Scheduler@node2.supernodexp.hpc, sock=16
02/19/2018 08:00:08;0100;Server@node2;Req;;Type 81 request received from Scheduler@node2.supernodexp.hpc, sock=16
02/19/2018 08:00:08;0100;Server@node2;Req;;Type 71 request received from Scheduler@node2.supernodexp.hpc, sock=16
02/19/2018 08:00:08;0100;Server@node2;Req;;Type 58 request received from Scheduler@node2.supernodexp.hpc, sock=16
02/19/2018 08:00:08;0100;Server@node2;Req;;Type 20 request received from Scheduler@node2.supernodexp.hpc, sock=16
02/19/2018 08:00:08;0100;Server@node2;Req;;Type 51 request received from Scheduler@node2.supernodexp.hpc, sock=16
02/19/2018 08:00:08;0100;Server@node2;Req;;Type 23 request received from Scheduler@node2.supernodexp.hpc, sock=16
02/19/2018 08:00:08;0008;Server@node2;Job;2847.node2.supernodexp.hpc;Job Run at request of Scheduler@node2.supernodexp.hpc on exec_vnode (node13:ncpus=32:nmics=1:mem=16777216kb)
02/19/2018 08:00:08;0001;Server@node2;Svr;Server@node2;Success (0) in req_runjob2, return value of svr_startjob is 0
02/19/2018 08:00:08;0100;Server@node2;Req;;Type 11 request received from Scheduler@node2.supernodexp.hpc, sock=16
02/19/2018 08:00:08;0008;Server@node2;Job;2877.node2.supernodexp.hpc;Job Modified at request of Scheduler@node2.supernodexp.hpc
02/19/2018 08:08:48;0080;Server@node2;Job;2834.node2.supernodexp.hpc;Obit received momhop:1 serverhop:1 state:4 substate:42
02/19/2018 08:08:50;0010;Server@node2;Job;2834.node2.supernodexp.hpc;Exit_status=2 resources_used.cpupercent=2074 resources_used.cput=06:09:01 resources_used.mem=22071272kb resources_used.ncpus=32 resources_used.vmem=24914960kb resources_used.walltime=00:18:08
02/19/2018 08:08:50;0100;Server@node2;Job;2834.node2.supernodexp.hpc;dequeuing from workq, state 5
02/19/2018 08:08:50;0040;Server@node2;Svr;node2.supernodexp.hpc;Scheduler sent command 2
02/19/2018 08:08:50;0040;Server@node2;Svr;node2.supernodexp.hpc;Scheduler sent command 0
02/19/2018 08:08:50;0100;Server@node2;Req;;Type 21 request received from Scheduler@node2.supernodexp.hpc, sock=16
02/19/2018 08:08:50;0100;Server@node2;Req;;Type 81 request received from Scheduler@node2.supernodexp.hpc, sock=16
02/19/2018 08:08:50;0100;Server@node2;Req;;Type 71 request received from Scheduler@node2.supernodexp.hpc, sock=16
02/19/2018 08:08:50;0100;Server@node2;Req;;Type 58 request received from Scheduler@node2.supernodexp.hpc, sock=16
02/19/2018 08:08:50;0100;Server@node2;Req;;Type 20 request received from Scheduler@node2.supernodexp.hpc, sock=16
02/19/2018 08:08:50;0100;Server@node2;Req;;Type 51 request received from Scheduler@node2.supernodexp.hpc, sock=16
02/19/2018 08:08:50;0100;Server@node2;Req;;Type 23 request received from Scheduler@node2.supernodexp.hpc, sock=16
02/19/2018 08:08:50;0008;Server@node2;Job;2877.node2.supernodexp.hpc;Job Run at request of Scheduler@node2.supernodexp.hpc on exec_vnode (node14:ncpus=32:nmics=1:mem=16777216kb)
02/19/2018 08:08:50;0001;Server@node2;Svr;Server@node2;Success (0) in req_runjob2, return value of svr_startjob is 0
02/19/2018 08:08:50;0100;Server@node2;Req;;Type 11 request received from Scheduler@node2.supernodexp.hpc, sock=16
02/19/2018 08:08:50;0008;Server@node2;Job;2898.node2.supernodexp.hpc;Job Modified at request of Scheduler@node2.supernodexp.hpc
02/19/2018 08:18:16;0080;Server@node2;Job;2847.node2.supernodexp.hpc;Obit received momhop:1 serverhop:1 state:4 substate:42
02/19/2018 08:18:17;0010;Server@node2;Job;2847.node2.supernodexp.hpc;Exit_status=2 resources_used.cpupercent=2170 resources_used.cput=06:28:55 resources_used.mem=21826300kb resources_used.ncpus=32 resources_used.vmem=24852740kb resources_used.walltime=00:18:07
02/19/2018 08:18:17;0100;Server@node2;Job;2847.node2.supernodexp.hpc;dequeuing from workq, state 5
02/19/2018 08:18:17;0040;Server@node2;Svr;node2.supernodexp.hpc;Scheduler sent command 2
02/19/2018 08:18:17;0040;Server@node2;Svr;node2.supernodexp.hpc;Scheduler sent command 0
02/19/2018 08:18:17;0100;Server@node2;Req;;Type 21 request received from Scheduler@node2.supernodexp.hpc, sock=16
02/19/2018 08:18:17;0100;Server@node2;Req;;Type 81 request received from Scheduler@node2.supernodexp.hpc, sock=16
02/19/2018 08:18:17;0100;Server@node2;Req;;Type 71 request received from Scheduler@node2.supernodexp.hpc, sock=16
02/19/2018 08:18:17;0100;Server@node2;Req;;Type 58 request received from Scheduler@node2.supernodexp.hpc, sock=16
02/19/2018 08:18:17;0100;Server@node2;Req;;Type 20 request received from Scheduler@node2.supernodexp.hpc, sock=16
02/19/2018 08:18:17;0100;Server@node2;Req;;Type 51 request received from Scheduler@node2.supernodexp.hpc, sock=16
02/19/2018 08:18:17;0100;Server@node2;Req;;Type 23 request received from Scheduler@node2.supernodexp.hpc, sock=16
02/19/2018 08:18:17;0008;Server@node2;Job;2898.node2.supernodexp.hpc;Job Run at request of Scheduler@node2.supernodexp.hpc on exec_vnode (node13:ncpus=32:nmics=1:mem=16777216kb)
02/19/2018 08:18:17;0001;Server@node2;Svr;Server@node2;Success (0) in req_runjob2, return value of svr_startjob is 0
02/19/2018 08:18:17;0100;Server@node2;Req;;Type 11 request received from Scheduler@node2.supernodexp.hpc, sock=16
02/19/2018 08:18:17;0008;Server@node2;Job;2907.node2.supernodexp.hpc;Job Modified at request of Scheduler@node2.supernodexp.hpc
02/19/2018 08:27:06;0080;Server@node2;Job;2877.node2.supernodexp.hpc;Obit received momhop:1 serverhop:1 state:4 substate:42
02/19/2018 08:27:07;0010;Server@node2;Job;2877.node2.supernodexp.hpc;Exit_status=2 resources_used.cpupercent=2110 resources_used.cput=06:12:23 resources_used.mem=21826824kb resources_used.ncpus=32 resources_used.vmem=24549720kb resources_used.walltime=00:18:16
02/19/2018 08:27:07;0100;Server@node2;Job;2877.node2.supernodexp.hpc;dequeuing from workq, state 5
02/19/2018 08:27:07;0040;Server@node2;Svr;node2.supernodexp.hpc;Scheduler sent command 2
02/19/2018 08:27:07;0040;Server@node2;Svr;node2.supernodexp.hpc;Scheduler sent command 0
02/19/2018 08:27:07;0100;Server@node2;Req;;Type 21 request received from Scheduler@node2.supernodexp.hpc, sock=16
02/19/2018 08:27:07;0100;Server@node2;Req;;Type 81 request received from Scheduler@node2.supernodexp.hpc, sock=16
02/19/2018 08:27:07;0100;Server@node2;Req;;Type 71 request received from Scheduler@node2.supernodexp.hpc, sock=16
02/19/2018 08:27:07;0100;Server@node2;Req;;Type 58 request received from Scheduler@node2.supernodexp.hpc, sock=16
02/19/2018 08:27:07;0100;Server@node2;Req;;Type 20 request received from Scheduler@node2.supernodexp.hpc, sock=16
02/19/2018 08:27:07;0100;Server@node2;Req;;Type 51 request received from Scheduler@node2.supernodexp.hpc, sock=16
02/19/2018 08:27:07;0100;Server@node2;Req;;Type 23 request received from Scheduler@node2.supernodexp.hpc, sock=16
02/19/2018 08:27:07;0008;Server@node2;Job;2907.node2.supernodexp.hpc;Job Run at request of Scheduler@node2.supernodexp.hpc on exec_vnode (node14:ncpus=32:nmics=1:mem=16777216kb)
02/19/2018 08:27:07;0001;Server@node2;Svr;Server@node2;Success (0) in req_runjob2, return value of svr_startjob is 0
02/19/2018 08:27:07;0100;Server@node2;Req;;Type 11 request received from Scheduler@node2.supernodexp.hpc, sock=16
02/19/2018 08:27:07;0008;Server@node2;Job;2912.node2.supernodexp.hpc;Job Modified at request of Scheduler@node2.supernodexp.hpc
02/19/2018 08:36:43;0080;Server@node2;Job;2898.node2.supernodexp.hpc;Obit received momhop:1 serverhop:1 state:4 substate:42
02/19/2018 08:36:44;0010;Server@node2;Job;2898.node2.supernodexp.hpc;Exit_status=2 resources_used.cpupercent=2205 resources_used.cput=06:35:04 resources_used.mem=21830576kb resources_used.ncpus=32 resources_used.vmem=25038136kb resources_used.walltime=00:18:25
02/19/2018 08:36:44;0100;Server@node2;Job;2898.node2.supernodexp.hpc;dequeuing from workq, state 5
02/19/2018 08:36:44;0040;Server@node2;Svr;node2.supernodexp.hpc;Scheduler sent command 2
02/19/2018 08:36:44;0040;Server@node2;Svr;node2.supernodexp.hpc;Scheduler sent command 0
02/19/2018 08:36:44;0100;Server@node2;Req;;Type 21 request received from Scheduler@node2.supernodexp.hpc, sock=16
02/19/2018 08:36:44;0100;Server@node2;Req;;Type 81 request received from Scheduler@node2.supernodexp.hpc, sock=16
02/19/2018 08:36:44;0100;Server@node2;Req;;Type 71 request received from Scheduler@node2.supernodexp.hpc, sock=16
02/19/2018 08:36:44;0100;Server@node2;Req;;Type 58 request received from Scheduler@node2.supernodexp.hpc, sock=16
02/19/2018 08:36:44;0100;Server@node2;Req;;Type 20 request received from Scheduler@node2.supernodexp.hpc, sock=16
02/19/2018 08:36:44;0100;Server@node2;Req;;Type 51 request received from Scheduler@node2.supernodexp.hpc, sock=16
02/19/2018 08:36:44;0100;Server@node2;Req;;Type 23 request received from Scheduler@node2.supernodexp.hpc, sock=16
02/19/2018 08:36:44;0008;Server@node2;Job;2912.node2.supernodexp.hpc;Job Run at request of Scheduler@node2.supernodexp.hpc on exec_vnode (node13:ncpus=32:nmics=1:mem=16777216kb)
02/19/2018 08:36:44;0001;Server@node2;Svr;Server@node2;Success (0) in req_runjob2, return value of svr_startjob is 0
02/19/2018 08:36:44;0100;Server@node2;Req;;Type 11 request received from Scheduler@node2.supernodexp.hpc, sock=16
02/19/2018 08:36:44;0008;Server@node2;Job;2920.node2.supernodexp.hpc;Job Modified at request of Scheduler@node2.supernodexp.hpc
02/19/2018 08:45:35;0080;Server@node2;Job;2907.node2.supernodexp.hpc;Obit received momhop:1 serverhop:1 state:4 substate:42
02/19/2018 08:45:37;0010;Server@node2;Job;2907.node2.supernodexp.hpc;Exit_status=2 resources_used.cpupercent=2064 resources_used.cput=06:11:37 resources_used.mem=22168756kb resources_used.ncpus=32 resources_used.vmem=24914960kb resources_used.walltime=00:18:29
02/19/2018 08:45:37;0100;Server@node2;Job;2907.node2.supernodexp.hpc;dequeuing from workq, state 5
02/19/2018 08:45:37;0040;Server@node2;Svr;node2.supernodexp.hpc;Scheduler sent command 2
02/19/2018 08:45:37;0040;Server@node2;Svr;node2.supernodexp.hpc;Scheduler sent command 0
02/19/2018 08:45:37;0100;Server@node2;Req;;Type 21 request received from Scheduler@node2.supernodexp.hpc, sock=16
02/19/2018 08:45:37;0100;Server@node2;Req;;Type 81 request received from Scheduler@node2.supernodexp.hpc, sock=16
02/19/2018 08:45:37;0100;Server@node2;Req;;Type 71 request received from Scheduler@node2.supernodexp.hpc, sock=16
02/19/2018 08:45:37;0100;Server@node2;Req;;Type 58 request received from Scheduler@node2.supernodexp.hpc, sock=16
02/19/2018 08:45:37;0100;Server@node2;Req;;Type 20 request received from Scheduler@node2.supernodexp.hpc, sock=16
02/19/2018 08:45:37;0100;Server@node2;Req;;Type 51 request received from Scheduler@node2.supernodexp.hpc, sock=16
02/19/2018 08:45:37;0100;Server@node2;Req;;Type 23 request received from Scheduler@node2.supernodexp.hpc, sock=16
02/19/2018 08:45:37;0008;Server@node2;Job;2920.node2.supernodexp.hpc;Job Run at request of Scheduler@node2.supernodexp.hpc on exec_vnode (node14:ncpus=32:nmics=1:mem=16777216kb)
02/19/2018 08:45:38;0001;Server@node2;Svr;Server@node2;Success (0) in req_runjob2, return value of svr_startjob is 0
02/19/2018 08:45:38;0100;Server@node2;Req;;Type 11 request received from Scheduler@node2.supernodexp.hpc, sock=16
02/19/2018 08:45:38;0008;Server@node2;Job;2935.node2.supernodexp.hpc;Job Modified at request of Scheduler@node2.supernodexp.hpc
02/19/2018 08:55:15;0080;Server@node2;Job;2912.node2.supernodexp.hpc;Obit received momhop:1 serverhop:1 state:4 substate:42
02/19/2018 08:55:16;0010;Server@node2;Job;2912.node2.supernodexp.hpc;Exit_status=2 resources_used.cpupercent=2243 resources_used.cput=06:36:49 resources_used.mem=22018532kb resources_used.ncpus=32 resources_used.vmem=25065436kb resources_used.walltime=00:18:32
02/19/2018 08:55:16;0100;Server@node2;Job;2912.node2.supernodexp.hpc;dequeuing from workq, state 5
02/19/2018 08:55:16;0040;Server@node2;Svr;node2.supernodexp.hpc;Scheduler sent command 2
02/19/2018 08:55:16;0040;Server@node2;Svr;node2.supernodexp.hpc;Scheduler sent command 0
02/19/2018 08:55:16;0100;Server@node2;Req;;Type 21 request received from Scheduler@node2.supernodexp.hpc, sock=16
02/19/2018 08:55:16;0100;Server@node2;Req;;Type 81 request received from Scheduler@node2.supernodexp.hpc, sock=16
02/19/2018 08:55:16;0100;Server@node2;Req;;Type 71 request received from Scheduler@node2.supernodexp.hpc, sock=16
02/19/2018 08:55:16;0100;Server@node2;Req;;Type 58 request received from Scheduler@node2.supernodexp.hpc, sock=16
02/19/2018 08:55:16;0100;Server@node2;Req;;Type 20 request received from Scheduler@node2.supernodexp.hpc, sock=16
02/19/2018 08:55:16;0100;Server@node2;Req;;Type 51 request received from Scheduler@node2.supernodexp.hpc, sock=16
02/19/2018 08:55:16;0100;Server@node2;Req;;Type 23 request received from Scheduler@node2.supernodexp.hpc, sock=16
02/19/2018 08:55:16;0008;Server@node2;Job;2935.node2.supernodexp.hpc;Job Run at request of Scheduler@node2.supernodexp.hpc on exec_vnode (node13:ncpus=32:nmics=1:mem=16777216kb)
02/19/2018 08:55:16;0001;Server@node2;Svr;Server@node2;Success (0) in req_runjob2, return value of svr_startjob is 0
02/19/2018 08:55:16;0100;Server@node2;Req;;Type 11 request received from Scheduler@node2.supernodexp.hpc, sock=16
02/19/2018 08:55:16;0008;Server@node2;Job;2971.node2.supernodexp.hpc;Job Modified at request of Scheduler@node2.supernodexp.hpc
02/19/2018 09:03:58;0080;Server@node2;Job;2920.node2.supernodexp.hpc;Obit received momhop:1 serverhop:1 state:4 substate:42
02/19/2018 09:04:00;0010;Server@node2;Job;2920.node2.supernodexp.hpc;Exit_status=2 resources_used.cpupercent=2075 resources_used.cput=06:12:22 resources_used.mem=22216292kb resources_used.ncpus=32 resources_used.vmem=24917160kb resources_used.walltime=00:18:21
02/19/2018 09:04:00;0100;Server@node2;Job;2920.node2.supernodexp.hpc;dequeuing from workq, state 5
02/19/2018 09:04:00;0040;Server@node2;Svr;node2.supernodexp.hpc;Scheduler sent command 2
02/19/2018 09:04:00;0040;Server@node2;Svr;node2.supernodexp.hpc;Scheduler sent command 0
02/19/2018 09:04:00;0100;Server@node2;Req;;Type 21 request received from Scheduler@node2.supernodexp.hpc, sock=16
02/19/2018 09:04:00;0100;Server@node2;Req;;Type 81 request received from Scheduler@node2.supernodexp.hpc, sock=16
02/19/2018 09:04:00;0100;Server@node2;Req;;Type 71 request received from Scheduler@node2.supernodexp.hpc, sock=16
02/19/2018 09:04:00;0100;Server@node2;Req;;Type 58 request received from Scheduler@node2.supernodexp.hpc, sock=16
02/19/2018 09:04:00;0100;Server@node2;Req;;Type 20 request received from Scheduler@node2.supernodexp.hpc, sock=16
02/19/2018 09:04:00;0100;Server@node2;Req;;Type 51 request received from Scheduler@node2.supernodexp.hpc, sock=16
02/19/2018 09:04:00;0100;Server@node2;Req;;Type 23 request received from Scheduler@node2.supernodexp.hpc, sock=16
02/19/2018 09:04:00;0008;Server@node2;Job;2971.node2.supernodexp.hpc;Job Run at request of Scheduler@node2.supernodexp.hpc on exec_vnode (node14:ncpus=32:nmics=1:mem=16777216kb)
02/19/2018 09:04:00;0001;Server@node2;Svr;Server@node2;Success (0) in req_runjob2, return value of svr_startjob is 0
02/19/2018 09:04:00;0100;Server@node2;Req;;Type 11 request received from Scheduler@node2.supernodexp.hpc, sock=16
02/19/2018 09:04:00;0008;Server@node2;Job;2978.node2.supernodexp.hpc;Job Modified at request of Scheduler@node2.supernodexp.hpc
02/19/2018 09:13:41;0080;Server@node2;Job;2935.node2.supernodexp.hpc;Obit received momhop:1 serverhop:1 state:4 substate:42
02/19/2018 09:13:42;0010;Server@node2;Job;2935.node2.supernodexp.hpc;Exit_status=2 resources_used.cpupercent=2163 resources_used.cput=06:31:59 resources_used.mem=21834044kb resources_used.ncpus=32 resources_used.vmem=25038144kb resources_used.walltime=00:18:24
02/19/2018 09:13:42;0100;Server@node2;Job;2935.node2.supernodexp.hpc;dequeuing from workq, state 5
02/19/2018 09:13:42;0040;Server@node2;Svr;node2.supernodexp.hpc;Scheduler sent command 2
02/19/2018 09:13:42;0040;Server@node2;Svr;node2.supernodexp.hpc;Scheduler sent command 0
02/19/2018 09:13:42;0100;Server@node2;Req;;Type 21 request received from Scheduler@node2.supernodexp.hpc, sock=16
02/19/2018 09:13:42;0100;Server@node2;Req;;Type 81 request received from Scheduler@node2.supernodexp.hpc, sock=16
02/19/2018 09:13:42;0100;Server@node2;Req;;Type 71 request received from Scheduler@node2.supernodexp.hpc, sock=16
02/19/2018 09:13:42;0100;Server@node2;Req;;Type 58 request received from Scheduler@node2.supernodexp.hpc, sock=16
02/19/2018 09:13:42;0100;Server@node2;Req;;Type 20 request received from Scheduler@node2.supernodexp.hpc, sock=16
02/19/2018 09:13:42;0100;Server@node2;Req;;Type 51 request received from Scheduler@node2.supernodexp.hpc, sock=16
02/19/2018 09:13:42;0100;Server@node2;Req;;Type 23 request received from Scheduler@node2.supernodexp.hpc, sock=16
02/19/2018 09:13:42;0008;Server@node2;Job;2978.node2.supernodexp.hpc;Job Run at request of Scheduler@node2.supernodexp.hpc on exec_vnode (node13:ncpus=32:nmics=1:mem=16777216kb)
02/19/2018 09:13:42;0001;Server@node2;Svr;Server@node2;Success (0) in req_runjob2, return value of svr_startjob is 0
02/19/2018 09:13:42;0100;Server@node2;Req;;Type 11 request received from Scheduler@node2.supernodexp.hpc, sock=16
02/19/2018 09:13:42;0008;Server@node2;Job;2993.node2.supernodexp.hpc;Job Modified at request of Scheduler@node2.supernodexp.hpc
02/19/2018 09:22:35;0080;Server@node2;Job;2971.node2.supernodexp.hpc;Obit received momhop:1 serverhop:1 state:4 substate:42
02/19/2018 09:22:38;0010;Server@node2;Job;2971.node2.supernodexp.hpc;Exit_status=2 resources_used.cpupercent=2117 resources_used.cput=06:14:26 resources_used.mem=22068068kb resources_used.ncpus=32 resources_used.vmem=24776076kb resources_used.walltime=00:18:35
02/19/2018 09:22:38;0100;Server@node2;Job;2971.node2.supernodexp.hpc;dequeuing from workq, state 5
02/19/2018 09:22:38;0040;Server@node2;Svr;node2.supernodexp.hpc;Scheduler sent command 2
02/19/2018 09:22:38;0040;Server@node2;Svr;node2.supernodexp.hpc;Scheduler sent command 0
02/19/2018 09:22:38;0100;Server@node2;Req;;Type 21 request received from Scheduler@node2.supernodexp.hpc, sock=16
02/19/2018 09:22:38;0100;Server@node2;Req;;Type 81 request received from Scheduler@node2.supernodexp.hpc, sock=16
02/19/2018 09:22:38;0100;Server@node2;Req;;Type 71 request received from Scheduler@node2.supernodexp.hpc, sock=16
02/19/2018 09:22:38;0100;Server@node2;Req;;Type 58 request received from Scheduler@node2.supernodexp.hpc, sock=16
02/19/2018 09:22:38;0100;Server@node2;Req;;Type 20 request received from Scheduler@node2.supernodexp.hpc, sock=16
02/19/2018 09:22:38;0100;Server@node2;Req;;Type 51 request received from Scheduler@node2.supernodexp.hpc, sock=16
02/19/2018 09:22:38;0100;Server@node2;Req;;Type 23 request received from Scheduler@node2.supernodexp.hpc, sock=16
02/19/2018 09:22:38;0008;Server@node2;Job;2993.node2.supernodexp.hpc;Job Run at request of Scheduler@node2.supernodexp.hpc on exec_vnode (node14:ncpus=32:nmics=1:mem=16777216kb)
02/19/2018 09:22:38;0001;Server@node2;Svr;Server@node2;Success (0) in req_runjob2, return value of svr_startjob is 0
02/19/2018 09:22:38;0100;Server@node2;Req;;Type 11 request received from Scheduler@node2.supernodexp.hpc, sock=16
02/19/2018 09:22:38;0008;Server@node2;Job;3007.node2.supernodexp.hpc;Job Modified at request of Scheduler@node2.supernodexp.hpc
02/19/2018 09:31:53;0080;Server@node2;Job;2978.node2.supernodexp.hpc;Obit received momhop:1 serverhop:1 state:4 substate:42
02/19/2018 09:31:54;0010;Server@node2;Job;2978.node2.supernodexp.hpc;Exit_status=2 resources_used.cpupercent=2170 resources_used.cput=06:27:44 resources_used.mem=21828600kb resources_used.ncpus=32 resources_used.vmem=24851192kb resources_used.walltime=00:18:10
02/19/2018 09:31:54;0100;Server@node2;Job;2978.node2.supernodexp.hpc;dequeuing from workq, state 5
02/19/2018 09:31:54;0040;Server@node2;Svr;node2.supernodexp.hpc;Scheduler sent command 2
02/19/2018 09:31:54;0040;Server@node2;Svr;node2.supernodexp.hpc;Scheduler sent command 0
02/19/2018 09:31:54;0100;Server@node2;Req;;Type 21 request received from Scheduler@node2.supernodexp.hpc, sock=16
02/19/2018 09:31:54;0100;Server@node2;Req;;Type 81 request received from Scheduler@node2.supernodexp.hpc, sock=16
02/19/2018 09:31:54;0100;Server@node2;Req;;Type 71 request received from Scheduler@node2.supernodexp.hpc, sock=16
02/19/2018 09:31:54;0100;Server@node2;Req;;Type 58 request received from Scheduler@node2.supernodexp.hpc, sock=16
02/19/2018 09:31:54;0100;Server@node2;Req;;Type 20 request received from Scheduler@node2.supernodexp.hpc, sock=16
02/19/2018 09:31:54;0100;Server@node2;Req;;Type 51 request received from Scheduler@node2.supernodexp.hpc, sock=16
02/19/2018 09:31:54;0100;Server@node2;Req;;Type 23 request received from Scheduler@node2.supernodexp.hpc, sock=16
02/19/2018 09:31:54;0008;Server@node2;Job;3007.node2.supernodexp.hpc;Job Run at request of Scheduler@node2.supernodexp.hpc on exec_vnode (node13:ncpus=32:nmics=1:mem=16777216kb)
02/19/2018 09:31:54;0001;Server@node2;Svr;Server@node2;Success (0) in req_runjob2, return value of svr_startjob is 0
02/19/2018 09:31:54;0100;Server@node2;Req;;Type 11 request received from Scheduler@node2.supernodexp.hpc, sock=16
02/19/2018 09:31:54;0008;Server@node2;Job;3048.node2.supernodexp.hpc;Job Modified at request of Scheduler@node2.supernodexp.hpc
02/19/2018 09:41:07;0080;Server@node2;Job;2993.node2.supernodexp.hpc;Obit received momhop:1 serverhop:1 state:4 substate:42
02/19/2018 09:41:08;0010;Server@node2;Job;2993.node2.supernodexp.hpc;Exit_status=2 resources_used.cpupercent=2139 resources_used.cput=06:16:56 resources_used.mem=22209764kb resources_used.ncpus=32 resources_used.vmem=24917164kb resources_used.walltime=00:18:28
02/19/2018 09:41:08;0100;Server@node2;Job;2993.node2.supernodexp.hpc;dequeuing from workq, state 5
02/19/2018 09:41:08;0040;Server@node2;Svr;node2.supernodexp.hpc;Scheduler sent command 2
02/19/2018 09:41:08;0040;Server@node2;Svr;node2.supernodexp.hpc;Scheduler sent command 0
02/19/2018 09:41:08;0100;Server@node2;Req;;Type 21 request received from Scheduler@node2.supernodexp.hpc, sock=16
02/19/2018 09:41:08;0100;Server@node2;Req;;Type 81 request received from Scheduler@node2.supernodexp.hpc, sock=16
02/19/2018 09:41:08;0100;Server@node2;Req;;Type 71 request received from Scheduler@node2.supernodexp.hpc, sock=16
02/19/2018 09:41:08;0100;Server@node2;Req;;Type 58 request received from Scheduler@node2.supernodexp.hpc, sock=16
02/19/2018 09:41:08;0100;Server@node2;Req;;Type 20 request received from Scheduler@node2.supernodexp.hpc, sock=16
02/19/2018 09:41:08;0100;Server@node2;Req;;Type 51 request received from Scheduler@node2.supernodexp.hpc, sock=16
02/19/2018 09:41:08;0100;Server@node2;Req;;Type 23 request received from Scheduler@node2.supernodexp.hpc, sock=16
02/19/2018 09:41:08;0008;Server@node2;Job;3048.node2.supernodexp.hpc;Job Run at request of Scheduler@node2.supernodexp.hpc on exec_vnode (node14:ncpus=32:nmics=1:mem=16777216kb)
02/19/2018 09:41:08;0001;Server@node2;Svr;Server@node2;Success (0) in req_runjob2, return value of svr_startjob is 0
02/19/2018 09:41:08;0100;Server@node2;Req;;Type 11 request received from Scheduler@node2.supernodexp.hpc, sock=16
02/19/2018 09:41:08;0008;Server@node2;Job;3074.node2.supernodexp.hpc;Job Modified at request of Scheduler@node2.supernodexp.hpc
02/19/2018 09:50:05;0080;Server@node2;Job;3007.node2.supernodexp.hpc;Obit received momhop:1 serverhop:1 state:4 substate:42
02/19/2018 09:50:06;0010;Server@node2;Job;3007.node2.supernodexp.hpc;Exit_status=2 resources_used.cpupercent=2177 resources_used.cput=06:30:46 resources_used.mem=22053860kb resources_used.ncpus=32 resources_used.vmem=25077744kb resources_used.walltime=00:18:11
02/19/2018 09:50:06;0100;Server@node2;Job;3007.node2.supernodexp.hpc;dequeuing from workq, state 5
02/19/2018 09:50:06;0040;Server@node2;Svr;node2.supernodexp.hpc;Scheduler sent command 2
02/19/2018 09:50:06;0040;Server@node2;Svr;node2.supernodexp.hpc;Scheduler sent command 0
02/19/2018 09:50:06;0100;Server@node2;Req;;Type 21 request received from Scheduler@node2.supernodexp.hpc, sock=16
02/19/2018 09:50:06;0100;Server@node2;Req;;Type 81 request received from Scheduler@node2.supernodexp.hpc, sock=16
02/19/2018 09:50:06;0100;Server@node2;Req;;Type 71 request received from Scheduler@node2.supernodexp.hpc, sock=16
02/19/2018 09:50:06;0100;Server@node2;Req;;Type 58 request received from Scheduler@node2.supernodexp.hpc, sock=16
02/19/2018 09:50:07;0100;Server@node2;Req;;Type 20 request received from Scheduler@node2.supernodexp.hpc, sock=16
02/19/2018 09:50:07;0100;Server@node2;Req;;Type 51 request received from Scheduler@node2.supernodexp.hpc, sock=16
02/19/2018 09:50:07;0100;Server@node2;Req;;Type 23 request received from Scheduler@node2.supernodexp.hpc, sock=16
02/19/2018 09:50:07;0008;Server@node2;Job;3074.node2.supernodexp.hpc;Job Run at request of Scheduler@node2.supernodexp.hpc on exec_vnode (node13:ncpus=32:nmics=1:mem=16777216kb)
02/19/2018 09:50:07;0001;Server@node2;Svr;Server@node2;Success (0) in req_runjob2, return value of svr_startjob is 0
02/19/2018 09:50:07;0100;Server@node2;Req;;Type 11 request received from Scheduler@node2.supernodexp.hpc, sock=16
02/19/2018 09:50:07;0008;Server@node2;Job;3091.node2.supernodexp.hpc;Job Modified at request of Scheduler@node2.supernodexp.hpc
02/19/2018 09:59:44;0080;Server@node2;Job;3048.node2.supernodexp.hpc;Obit received momhop:1 serverhop:1 state:4 substate:42
02/19/2018 09:59:46;0010;Server@node2;Job;3048.node2.supernodexp.hpc;Exit_status=2 resources_used.cpupercent=2137 resources_used.cput=06:16:34 resources_used.mem=21822464kb resources_used.ncpus=32 resources_used.vmem=24549520kb resources_used.walltime=00:18:36
02/19/2018 09:59:46;0100;Server@node2;Job;3048.node2.supernodexp.hpc;dequeuing from workq, state 5
02/19/2018 09:59:46;0040;Server@node2;Svr;node2.supernodexp.hpc;Scheduler sent command 2
02/19/2018 09:59:46;0040;Server@node2;Svr;node2.supernodexp.hpc;Scheduler sent command 0
02/19/2018 09:59:46;0100;Server@node2;Req;;Type 21 request received from Scheduler@node2.supernodexp.hpc, sock=16
02/19/2018 09:59:46;0100;Server@node2;Req;;Type 81 request received from Scheduler@node2.supernodexp.hpc, sock=16
02/19/2018 09:59:46;0100;Server@node2;Req;;Type 71 request received from Scheduler@node2.supernodexp.hpc, sock=16
02/19/2018 09:59:46;0100;Server@node2;Req;;Type 58 request received from Scheduler@node2.supernodexp.hpc, sock=16
02/19/2018 09:59:46;0100;Server@node2;Req;;Type 20 request received from Scheduler@node2.supernodexp.hpc, sock=16
02/19/2018 09:59:46;0100;Server@node2;Req;;Type 51 request received from Scheduler@node2.supernodexp.hpc, sock=16
02/19/2018 09:59:46;0100;Server@node2;Req;;Type 23 request received from Scheduler@node2.supernodexp.hpc, sock=16
02/19/2018 09:59:46;0008;Server@node2;Job;3091.node2.supernodexp.hpc;Job Run at request of Scheduler@node2.supernodexp.hpc on exec_vnode (node14:ncpus=32:nmics=1:mem=16777216kb)
02/19/2018 09:59:46;0001;Server@node2;Svr;Server@node2;Success (0) in req_runjob2, return value of svr_startjob is 0
02/19/2018 09:59:46;0100;Server@node2;Req;;Type 11 request received from Scheduler@node2.supernodexp.hpc, sock=16
02/19/2018 09:59:46;0008;Server@node2;Job;3101.node2.supernodexp.hpc;Job Modified at request of Scheduler@node2.supernodexp.hpc
02/19/2018 10:08:22;0080;Server@node2;Job;3074.node2.supernodexp.hpc;Obit received momhop:1 serverhop:1 state:4 substate:42
02/19/2018 10:08:23;0010;Server@node2;Job;3074.node2.supernodexp.hpc;Exit_status=2 resources_used.cpupercent=2176 resources_used.cput=06:31:32 resources_used.mem=21830900kb resources_used.ncpus=32 resources_used.vmem=24850152kb resources_used.walltime=00:18:15
02/19/2018 10:08:23;0100;Server@node2;Job;3074.node2.supernodexp.hpc;dequeuing from workq, state 5
02/19/2018 10:08:23;0040;Server@node2;Svr;node2.supernodexp.hpc;Scheduler sent command 2
02/19/2018 10:08:23;0040;Server@node2;Svr;node2.supernodexp.hpc;Scheduler sent command 0
02/19/2018 10:08:23;0100;Server@node2;Req;;Type 21 request received from Scheduler@node2.supernodexp.hpc, sock=16
02/19/2018 10:08:23;0100;Server@node2;Req;;Type 81 request received from Scheduler@node2.supernodexp.hpc, sock=16
02/19/2018 10:08:23;0100;Server@node2;Req;;Type 71 request received from Scheduler@node2.supernodexp.hpc, sock=16
02/19/2018 10:08:23;0100;Server@node2;Req;;Type 58 request received from Scheduler@node2.supernodexp.hpc, sock=16
02/19/2018 10:08:23;0100;Server@node2;Req;;Type 20 request received from Scheduler@node2.supernodexp.hpc, sock=16
02/19/2018 10:08:23;0100;Server@node2;Req;;Type 51 request received from Scheduler@node2.supernodexp.hpc, sock=16
02/19/2018 10:08:23;0100;Server@node2;Req;;Type 23 request received from Scheduler@node2.supernodexp.hpc, sock=16
02/19/2018 10:08:23;0008;Server@node2;Job;3101.node2.supernodexp.hpc;Job Run at request of Scheduler@node2.supernodexp.hpc on exec_vnode (node13:ncpus=32:nmics=1:mem=16777216kb)
02/19/2018 10:08:23;0001;Server@node2;Svr;Server@node2;Success (0) in req_runjob2, return value of svr_startjob is 0
02/19/2018 10:08:23;0100;Server@node2;Req;;Type 11 request received from Scheduler@node2.supernodexp.hpc, sock=16
02/19/2018 10:08:23;0008;Server@node2;Job;3106.node2.supernodexp.hpc;Job Modified at request of Scheduler@node2.supernodexp.hpc
02/19/2018 10:18:03;0080;Server@node2;Job;3091.node2.supernodexp.hpc;Obit received momhop:1 serverhop:1 state:4 substate:42
02/19/2018 10:18:04;0010;Server@node2;Job;3091.node2.supernodexp.hpc;Exit_status=2 resources_used.cpupercent=2088 resources_used.cput=06:12:49 resources_used.mem=22210692kb resources_used.ncpus=32 resources_used.vmem=24954376kb resources_used.walltime=00:18:17
02/19/2018 10:18:04;0100;Server@node2;Job;3091.node2.supernodexp.hpc;dequeuing from workq, state 5
02/19/2018 10:18:04;0040;Server@node2;Svr;node2.supernodexp.hpc;Scheduler sent command 2
02/19/2018 10:18:04;0040;Server@node2;Svr;node2.supernodexp.hpc;Scheduler sent command 0
02/19/2018 10:18:04;0100;Server@node2;Req;;Type 21 request received from Scheduler@node2.supernodexp.hpc, sock=16
02/19/2018 10:18:04;0100;Server@node2;Req;;Type 81 request received from Scheduler@node2.supernodexp.hpc, sock=16
02/19/2018 10:18:04;0100;Server@node2;Req;;Type 71 request received from Scheduler@node2.supernodexp.hpc, sock=16
02/19/2018 10:18:04;0100;Server@node2;Req;;Type 58 request received from Scheduler@node2.supernodexp.hpc, sock=16
02/19/2018 10:18:04;0100;Server@node2;Req;;Type 20 request received from Scheduler@node2.supernodexp.hpc, sock=16
02/19/2018 10:18:04;0100;Server@node2;Req;;Type 51 request received from Scheduler@node2.supernodexp.hpc, sock=16
02/19/2018 10:18:05;0100;Server@node2;Req;;Type 23 request received from Scheduler@node2.supernodexp.hpc, sock=16
02/19/2018 10:18:05;0008;Server@node2;Job;3106.node2.supernodexp.hpc;Job Run at request of Scheduler@node2.supernodexp.hpc on exec_vnode (node14:ncpus=32:nmics=1:mem=16777216kb)
02/19/2018 10:18:05;0001;Server@node2;Svr;Server@node2;Success (0) in req_runjob2, return value of svr_startjob is 0
02/19/2018 10:18:05;0100;Server@node2;Req;;Type 11 request received from Scheduler@node2.supernodexp.hpc, sock=16
02/19/2018 10:18:05;0008;Server@node2;Job;3108.node2.supernodexp.hpc;Job Modified at request of Scheduler@node2.supernodexp.hpc
02/19/2018 10:26:32;0080;Server@node2;Job;3101.node2.supernodexp.hpc;Obit received momhop:1 serverhop:1 state:4 substate:42
02/19/2018 10:26:34;0010;Server@node2;Job;3101.node2.supernodexp.hpc;Exit_status=2 resources_used.cpupercent=2165 resources_used.cput=06:28:03 resources_used.mem=22057972kb resources_used.ncpus=32 resources_used.vmem=25094944kb resources_used.walltime=00:18:09
02/19/2018 10:26:34;0100;Server@node2;Job;3101.node2.supernodexp.hpc;dequeuing from workq, state 5
02/19/2018 10:26:34;0040;Server@node2;Svr;node2.supernodexp.hpc;Scheduler sent command 2
02/19/2018 10:26:34;0040;Server@node2;Svr;node2.supernodexp.hpc;Scheduler sent command 0
02/19/2018 10:26:34;0100;Server@node2;Req;;Type 21 request received from Scheduler@node2.supernodexp.hpc, sock=16
02/19/2018 10:26:34;0100;Server@node2;Req;;Type 81 request received from Scheduler@node2.supernodexp.hpc, sock=16
02/19/2018 10:26:34;0100;Server@node2;Req;;Type 71 request received from Scheduler@node2.supernodexp.hpc, sock=16
02/19/2018 10:26:34;0100;Server@node2;Req;;Type 58 request received from Scheduler@node2.supernodexp.hpc, sock=16
02/19/2018 10:26:34;0100;Server@node2;Req;;Type 20 request received from Scheduler@node2.supernodexp.hpc, sock=16
02/19/2018 10:26:34;0100;Server@node2;Req;;Type 51 request received from Scheduler@node2.supernodexp.hpc, sock=16
02/19/2018 10:26:34;0100;Server@node2;Req;;Type 23 request received from Scheduler@node2.supernodexp.hpc, sock=16
02/19/2018 10:26:34;0008;Server@node2;Job;3108.node2.supernodexp.hpc;Job Run at request of Scheduler@node2.supernodexp.hpc on exec_vnode (node13:ncpus=32:nmics=1:mem=16777216kb)
02/19/2018 10:26:34;0001;Server@node2;Svr;Server@node2;Success (0) in req_runjob2, return value of svr_startjob is 0
02/19/2018 10:26:34;0100;Server@node2;Req;;Type 11 request received from Scheduler@node2.supernodexp.hpc, sock=16
02/19/2018 10:26:34;0008;Server@node2;Job;3116.node2.supernodexp.hpc;Job Modified at request of Scheduler@node2.supernodexp.hpc
02/19/2018 10:36:19;0080;Server@node2;Job;3106.node2.supernodexp.hpc;Obit received momhop:1 serverhop:1 state:4 substate:42
02/19/2018 10:36:20;0010;Server@node2;Job;3106.node2.supernodexp.hpc;Exit_status=2 resources_used.cpupercent=2079 resources_used.cput=06:12:10 resources_used.mem=22030772kb resources_used.ncpus=32 resources_used.vmem=24761032kb resources_used.walltime=00:18:14
02/19/2018 10:36:20;0100;Server@node2;Job;3106.node2.supernodexp.hpc;dequeuing from workq, state 5
02/19/2018 10:36:20;0040;Server@node2;Svr;node2.supernodexp.hpc;Scheduler sent command 2
02/19/2018 10:36:20;0040;Server@node2;Svr;node2.supernodexp.hpc;Scheduler sent command 0
02/19/2018 10:36:20;0100;Server@node2;Req;;Type 21 request received from Scheduler@node2.supernodexp.hpc, sock=16
02/19/2018 10:36:20;0100;Server@node2;Req;;Type 81 request received from Scheduler@node2.supernodexp.hpc, sock=16
02/19/2018 10:36:20;0100;Server@node2;Req;;Type 71 request received from Scheduler@node2.supernodexp.hpc, sock=16
02/19/2018 10:36:20;0100;Server@node2;Req;;Type 58 request received from Scheduler@node2.supernodexp.hpc, sock=16
02/19/2018 10:36:20;0100;Server@node2;Req;;Type 20 request received from Scheduler@node2.supernodexp.hpc, sock=16
02/19/2018 10:36:20;0100;Server@node2;Req;;Type 51 request received from Scheduler@node2.supernodexp.hpc, sock=16
02/19/2018 10:36:20;0100;Server@node2;Req;;Type 23 request received from Scheduler@node2.supernodexp.hpc, sock=16
02/19/2018 10:36:20;0008;Server@node2;Job;3116.node2.supernodexp.hpc;Job Run at request of Scheduler@node2.supernodexp.hpc on exec_vnode (node14:ncpus=32:nmics=1:mem=16777216kb)
02/19/2018 10:36:20;0001;Server@node2;Svr;Server@node2;Success (0) in req_runjob2, return value of svr_startjob is 0
02/19/2018 10:36:20;0100;Server@node2;Req;;Type 11 request received from Scheduler@node2.supernodexp.hpc, sock=16
02/19/2018 10:36:20;0008;Server@node2;Job;3122.node2.supernodexp.hpc;Job Modified at request of Scheduler@node2.supernodexp.hpc
02/19/2018 10:44:57;0080;Server@node2;Job;3108.node2.supernodexp.hpc;Obit received momhop:1 serverhop:1 state:4 substate:42
02/19/2018 10:44:59;0010;Server@node2;Job;3108.node2.supernodexp.hpc;Exit_status=2 resources_used.cpupercent=2226 resources_used.cput=06:33:24 resources_used.mem=22056920kb resources_used.ncpus=32 resources_used.vmem=25076728kb resources_used.walltime=00:18:24
02/19/2018 10:44:59;0100;Server@node2;Job;3108.node2.supernodexp.hpc;dequeuing from workq, state 5
02/19/2018 10:44:59;0040;Server@node2;Svr;node2.supernodexp.hpc;Scheduler sent command 2
02/19/2018 10:44:59;0040;Server@node2;Svr;node2.supernodexp.hpc;Scheduler sent command 0
02/19/2018 10:44:59;0100;Server@node2;Req;;Type 21 request received from Scheduler@node2.supernodexp.hpc, sock=16
02/19/2018 10:44:59;0100;Server@node2;Req;;Type 81 request received from Scheduler@node2.supernodexp.hpc, sock=16
02/19/2018 10:44:59;0100;Server@node2;Req;;Type 71 request received from Scheduler@node2.supernodexp.hpc, sock=16
02/19/2018 10:44:59;0100;Server@node2;Req;;Type 58 request received from Scheduler@node2.supernodexp.hpc, sock=16
02/19/2018 10:44:59;0100;Server@node2;Req;;Type 20 request received from Scheduler@node2.supernodexp.hpc, sock=16
02/19/2018 10:44:59;0100;Server@node2;Req;;Type 51 request received from Scheduler@node2.supernodexp.hpc, sock=16
02/19/2018 10:44:59;0100;Server@node2;Req;;Type 23 request received from Scheduler@node2.supernodexp.hpc, sock=16
02/19/2018 10:44:59;0008;Server@node2;Job;3122.node2.supernodexp.hpc;Job Run at request of Scheduler@node2.supernodexp.hpc on exec_vnode (node13:ncpus=32:nmics=1:mem=16777216kb)
02/19/2018 10:44:59;0001;Server@node2;Svr;Server@node2;Success (0) in req_runjob2, return value of svr_startjob is 0
02/19/2018 10:44:59;0100;Server@node2;Req;;Type 11 request received from Scheduler@node2.supernodexp.hpc, sock=16
02/19/2018 10:44:59;0008;Server@node2;Job;3125.node2.supernodexp.hpc;Job Modified at request of Scheduler@node2.supernodexp.hpc
02/19/2018 10:54:49;0080;Server@node2;Job;3116.node2.supernodexp.hpc;Obit received momhop:1 serverhop:1 state:4 substate:42
02/19/2018 10:54:50;0010;Server@node2;Job;3116.node2.supernodexp.hpc;Exit_status=2 resources_used.cpupercent=2136 resources_used.cput=06:16:11 resources_used.mem=22073148kb resources_used.ncpus=32 resources_used.vmem=24806588kb resources_used.walltime=00:18:29
02/19/2018 10:54:50;0100;Server@node2;Job;3116.node2.supernodexp.hpc;dequeuing from workq, state 5
02/19/2018 10:54:50;0040;Server@node2;Svr;node2.supernodexp.hpc;Scheduler sent command 2
02/19/2018 10:54:50;0040;Server@node2;Svr;node2.supernodexp.hpc;Scheduler sent command 0
02/19/2018 10:54:50;0100;Server@node2;Req;;Type 21 request received from Scheduler@node2.supernodexp.hpc, sock=16
02/19/2018 10:54:50;0100;Server@node2;Req;;Type 81 request received from Scheduler@node2.supernodexp.hpc, sock=16
02/19/2018 10:54:50;0100;Server@node2;Req;;Type 71 request received from Scheduler@node2.supernodexp.hpc, sock=16
02/19/2018 10:54:50;0100;Server@node2;Req;;Type 58 request received from Scheduler@node2.supernodexp.hpc, sock=16
02/19/2018 10:54:50;0100;Server@node2;Req;;Type 20 request received from Scheduler@node2.supernodexp.hpc, sock=16
02/19/2018 10:54:50;0100;Server@node2;Req;;Type 51 request received from Scheduler@node2.supernodexp.hpc, sock=16
02/19/2018 10:54:50;0100;Server@node2;Req;;Type 23 request received from Scheduler@node2.supernodexp.hpc, sock=16
02/19/2018 10:54:50;0008;Server@node2;Job;3125.node2.supernodexp.hpc;Job Run at request of Scheduler@node2.supernodexp.hpc on exec_vnode (node14:ncpus=32:nmics=1:mem=16777216kb)
02/19/2018 10:54:50;0001;Server@node2;Svr;Server@node2;Success (0) in req_runjob2, return value of svr_startjob is 0
02/19/2018 10:54:50;0100;Server@node2;Req;;Type 11 request received from Scheduler@node2.supernodexp.hpc, sock=16
02/19/2018 10:54:50;0008;Server@node2;Job;3137.node2.supernodexp.hpc;Job Modified at request of Scheduler@node2.supernodexp.hpc
02/19/2018 11:03:58;0080;Server@node2;Job;3122.node2.supernodexp.hpc;Obit received momhop:1 serverhop:1 state:4 substate:42
02/19/2018 11:04:00;0010;Server@node2;Job;3122.node2.supernodexp.hpc;Exit_status=2 resources_used.cpupercent=2245 resources_used.cput=06:35:44 resources_used.mem=21822372kb resources_used.ncpus=32 resources_used.vmem=24865552kb resources_used.walltime=00:18:59
02/19/2018 11:04:00;0100;Server@node2;Job;3122.node2.supernodexp.hpc;dequeuing from workq, state 5
02/19/2018 11:04:00;0040;Server@node2;Svr;node2.supernodexp.hpc;Scheduler sent command 2
02/19/2018 11:04:00;0040;Server@node2;Svr;node2.supernodexp.hpc;Scheduler sent command 0
02/19/2018 11:04:00;0100;Server@node2;Req;;Type 21 request received from Scheduler@node2.supernodexp.hpc, sock=16
02/19/2018 11:04:00;0100;Server@node2;Req;;Type 81 request received from Scheduler@node2.supernodexp.hpc, sock=16
02/19/2018 11:04:00;0100;Server@node2;Req;;Type 71 request received from Scheduler@node2.supernodexp.hpc, sock=16
02/19/2018 11:04:00;0100;Server@node2;Req;;Type 58 request received from Scheduler@node2.supernodexp.hpc, sock=16
02/19/2018 11:04:00;0100;Server@node2;Req;;Type 20 request received from Scheduler@node2.supernodexp.hpc, sock=16
02/19/2018 11:04:00;0100;Server@node2;Req;;Type 51 request received from Scheduler@node2.supernodexp.hpc, sock=16
02/19/2018 11:04:00;0100;Server@node2;Req;;Type 23 request received from Scheduler@node2.supernodexp.hpc, sock=16
02/19/2018 11:04:00;0008;Server@node2;Job;3137.node2.supernodexp.hpc;Job Run at request of Scheduler@node2.supernodexp.hpc on exec_vnode (node13:ncpus=32:nmics=1:mem=16777216kb)
02/19/2018 11:04:00;0001;Server@node2;Svr;Server@node2;Success (0) in req_runjob2, return value of svr_startjob is 0
02/19/2018 11:04:00;0100;Server@node2;Req;;Type 11 request received from Scheduler@node2.supernodexp.hpc, sock=16
02/19/2018 11:04:00;0008;Server@node2;Job;3157.node2.supernodexp.hpc;Job Modified at request of Scheduler@node2.supernodexp.hpc
02/19/2018 11:13:17;0080;Server@node2;Job;3125.node2.supernodexp.hpc;Obit received momhop:1 serverhop:1 state:4 substate:42
02/19/2018 11:13:19;0010;Server@node2;Job;3125.node2.supernodexp.hpc;Exit_status=2 resources_used.cpupercent=2081 resources_used.cput=06:10:40 resources_used.mem=22189456kb resources_used.ncpus=32 resources_used.vmem=24892928kb resources_used.walltime=00:18:27
02/19/2018 11:13:19;0100;Server@node2;Job;3125.node2.supernodexp.hpc;dequeuing from workq, state 5
02/19/2018 11:13:19;0040;Server@node2;Svr;node2.supernodexp.hpc;Scheduler sent command 2
02/19/2018 11:13:19;0040;Server@node2;Svr;node2.supernodexp.hpc;Scheduler sent command 0
02/19/2018 11:13:19;0100;Server@node2;Req;;Type 21 request received from Scheduler@node2.supernodexp.hpc, sock=16
02/19/2018 11:13:19;0100;Server@node2;Req;;Type 81 request received from Scheduler@node2.supernodexp.hpc, sock=16
02/19/2018 11:13:19;0100;Server@node2;Req;;Type 71 request received from Scheduler@node2.supernodexp.hpc, sock=16
02/19/2018 11:13:19;0100;Server@node2;Req;;Type 58 request received from Scheduler@node2.supernodexp.hpc, sock=16
02/19/2018 11:13:19;0100;Server@node2;Req;;Type 20 request received from Scheduler@node2.supernodexp.hpc, sock=16
02/19/2018 11:13:19;0100;Server@node2;Req;;Type 51 request received from Scheduler@node2.supernodexp.hpc, sock=16
02/19/2018 11:13:19;0100;Server@node2;Req;;Type 23 request received from Scheduler@node2.supernodexp.hpc, sock=16
02/19/2018 11:13:19;0008;Server@node2;Job;3157.node2.supernodexp.hpc;Job Run at request of Scheduler@node2.supernodexp.hpc on exec_vnode (node14:ncpus=32:nmics=1:mem=16777216kb)
02/19/2018 11:13:19;0001;Server@node2;Svr;Server@node2;Success (0) in req_runjob2, return value of svr_startjob is 0
02/19/2018 11:13:19;0100;Server@node2;Req;;Type 11 request received from Scheduler@node2.supernodexp.hpc, sock=16
02/19/2018 11:13:19;0008;Server@node2;Job;3160.node2.supernodexp.hpc;Job Modified at request of Scheduler@node2.supernodexp.hpc
02/19/2018 11:22:29;0080;Server@node2;Job;3137.node2.supernodexp.hpc;Obit received momhop:1 serverhop:1 state:4 substate:42
02/19/2018 11:22:31;0010;Server@node2;Job;3137.node2.supernodexp.hpc;Exit_status=2 resources_used.cpupercent=2169 resources_used.cput=06:31:38 resources_used.mem=22030964kb resources_used.ncpus=32 resources_used.vmem=25066800kb resources_used.walltime=00:18:29
02/19/2018 11:22:31;0100;Server@node2;Job;3137.node2.supernodexp.hpc;dequeuing from workq, state 5
02/19/2018 11:22:31;0040;Server@node2;Svr;node2.supernodexp.hpc;Scheduler sent command 2
02/19/2018 11:22:31;0040;Server@node2;Svr;node2.supernodexp.hpc;Scheduler sent command 0
02/19/2018 11:22:31;0100;Server@node2;Req;;Type 21 request received from Scheduler@node2.supernodexp.hpc, sock=16
02/19/2018 11:22:31;0100;Server@node2;Req;;Type 81 request received from Scheduler@node2.supernodexp.hpc, sock=16
02/19/2018 11:22:31;0100;Server@node2;Req;;Type 71 request received from Scheduler@node2.supernodexp.hpc, sock=16
02/19/2018 11:22:31;0100;Server@node2;Req;;Type 58 request received from Scheduler@node2.supernodexp.hpc, sock=16
02/19/2018 11:22:31;0100;Server@node2;Req;;Type 20 request received from Scheduler@node2.supernodexp.hpc, sock=16
02/19/2018 11:22:31;0100;Server@node2;Req;;Type 51 request received from Scheduler@node2.supernodexp.hpc, sock=16
02/19/2018 11:22:31;0100;Server@node2;Req;;Type 23 request received from Scheduler@node2.supernodexp.hpc, sock=16
02/19/2018 11:22:31;0008;Server@node2;Job;3160.node2.supernodexp.hpc;Job Run at request of Scheduler@node2.supernodexp.hpc on exec_vnode (node13:ncpus=32:nmics=1:mem=16777216kb)
02/19/2018 11:22:31;0001;Server@node2;Svr;Server@node2;Success (0) in req_runjob2, return value of svr_startjob is 0
02/19/2018 11:22:31;0100;Server@node2;Req;;Type 11 request received from Scheduler@node2.supernodexp.hpc, sock=16
02/19/2018 11:22:31;0008;Server@node2;Job;3192.node2.supernodexp.hpc;Job Modified at request of Scheduler@node2.supernodexp.hpc
02/19/2018 11:32:21;0080;Server@node2;Job;3157.node2.supernodexp.hpc;Obit received momhop:1 serverhop:1 state:4 substate:42
02/19/2018 11:32:24;0010;Server@node2;Job;3157.node2.supernodexp.hpc;Exit_status=2 resources_used.cpupercent=2118 resources_used.cput=06:16:21 resources_used.mem=21828424kb resources_used.ncpus=32 resources_used.vmem=24548684kb resources_used.walltime=00:19:03
02/19/2018 11:32:24;0100;Server@node2;Job;3157.node2.supernodexp.hpc;dequeuing from workq, state 5
02/19/2018 11:32:24;0040;Server@node2;Svr;node2.supernodexp.hpc;Scheduler sent command 2
02/19/2018 11:32:24;0040;Server@node2;Svr;node2.supernodexp.hpc;Scheduler sent command 0
02/19/2018 11:32:24;0100;Server@node2;Req;;Type 21 request received from Scheduler@node2.supernodexp.hpc, sock=16
02/19/2018 11:32:24;0100;Server@node2;Req;;Type 81 request received from Scheduler@node2.supernodexp.hpc, sock=16
02/19/2018 11:32:24;0100;Server@node2;Req;;Type 71 request received from Scheduler@node2.supernodexp.hpc, sock=16
02/19/2018 11:32:24;0100;Server@node2;Req;;Type 58 request received from Scheduler@node2.supernodexp.hpc, sock=16
02/19/2018 11:32:24;0100;Server@node2;Req;;Type 20 request received from Scheduler@node2.supernodexp.hpc, sock=16
02/19/2018 11:32:24;0100;Server@node2;Req;;Type 51 request received from Scheduler@node2.supernodexp.hpc, sock=16
02/19/2018 11:32:24;0100;Server@node2;Req;;Type 23 request received from Scheduler@node2.supernodexp.hpc, sock=16
02/19/2018 11:32:24;0008;Server@node2;Job;3192.node2.supernodexp.hpc;Job Run at request of Scheduler@node2.supernodexp.hpc on exec_vnode (node14:ncpus=32:nmics=1:mem=16777216kb)
02/19/2018 11:32:24;0001;Server@node2;Svr;Server@node2;Success (0) in req_runjob2, return value of svr_startjob is 0
02/19/2018 11:32:24;0100;Server@node2;Req;;Type 11 request received from Scheduler@node2.supernodexp.hpc, sock=16
02/19/2018 11:32:24;0008;Server@node2;Job;3220.node2.supernodexp.hpc;Job Modified at request of Scheduler@node2.supernodexp.hpc
02/19/2018 11:40:59;0080;Server@node2;Job;3160.node2.supernodexp.hpc;Obit received momhop:1 serverhop:1 state:4 substate:42
02/19/2018 11:41:00;0010;Server@node2;Job;3160.node2.supernodexp.hpc;Exit_status=2 resources_used.cpupercent=2187 resources_used.cput=06:34:05 resources_used.mem=21831808kb resources_used.ncpus=32 resources_used.vmem=25041196kb resources_used.walltime=00:18:28
02/19/2018 11:41:00;0100;Server@node2;Job;3160.node2.supernodexp.hpc;dequeuing from workq, state 5
02/19/2018 11:41:00;0040;Server@node2;Svr;node2.supernodexp.hpc;Scheduler sent command 2
02/19/2018 11:41:00;0040;Server@node2;Svr;node2.supernodexp.hpc;Scheduler sent command 0
02/19/2018 11:41:00;0100;Server@node2;Req;;Type 21 request received from Scheduler@node2.supernodexp.hpc, sock=16
02/19/2018 11:41:00;0100;Server@node2;Req;;Type 81 request received from Scheduler@node2.supernodexp.hpc, sock=16
02/19/2018 11:41:00;0100;Server@node2;Req;;Type 71 request received from Scheduler@node2.supernodexp.hpc, sock=16
02/19/2018 11:41:00;0100;Server@node2;Req;;Type 58 request received from Scheduler@node2.supernodexp.hpc, sock=16
02/19/2018 11:41:00;0100;Server@node2;Req;;Type 20 request received from Scheduler@node2.supernodexp.hpc, sock=16
02/19/2018 11:41:00;0100;Server@node2;Req;;Type 51 request received from Scheduler@node2.supernodexp.hpc, sock=16
02/19/2018 11:41:00;0100;Server@node2;Req;;Type 23 request received from Scheduler@node2.supernodexp.hpc, sock=16
02/19/2018 11:41:00;0008;Server@node2;Job;3220.node2.supernodexp.hpc;Job Run at request of Scheduler@node2.supernodexp.hpc on exec_vnode (node13:ncpus=32:nmics=1:mem=16777216kb)
02/19/2018 11:41:00;0001;Server@node2;Svr;Server@node2;Success (0) in req_runjob2, return value of svr_startjob is 0
02/19/2018 11:41:00;0100;Server@node2;Req;;Type 11 request received from Scheduler@node2.supernodexp.hpc, sock=16
02/19/2018 11:41:00;0008;Server@node2;Job;3231.node2.supernodexp.hpc;Job Modified at request of Scheduler@node2.supernodexp.hpc
02/19/2018 11:50:58;0080;Server@node2;Job;3192.node2.supernodexp.hpc;Obit received momhop:1 serverhop:1 state:4 substate:42
02/19/2018 11:50:59;0010;Server@node2;Job;3192.node2.supernodexp.hpc;Exit_status=2 resources_used.cpupercent=2117 resources_used.cput=06:14:42 resources_used.mem=22161972kb resources_used.ncpus=32 resources_used.vmem=24899580kb resources_used.walltime=00:18:34
02/19/2018 11:50:59;0100;Server@node2;Job;3192.node2.supernodexp.hpc;dequeuing from workq, state 5
02/19/2018 11:50:59;0040;Server@node2;Svr;node2.supernodexp.hpc;Scheduler sent command 2
02/19/2018 11:50:59;0040;Server@node2;Svr;node2.supernodexp.hpc;Scheduler sent command 0
02/19/2018 11:50:59;0100;Server@node2;Req;;Type 21 request received from Scheduler@node2.supernodexp.hpc, sock=16
02/19/2018 11:50:59;0100;Server@node2;Req;;Type 81 request received from Scheduler@node2.supernodexp.hpc, sock=16
02/19/2018 11:50:59;0100;Server@node2;Req;;Type 71 request received from Scheduler@node2.supernodexp.hpc, sock=16
02/19/2018 11:50:59;0100;Server@node2;Req;;Type 58 request received from Scheduler@node2.supernodexp.hpc, sock=16
02/19/2018 11:50:59;0100;Server@node2;Req;;Type 20 request received from Scheduler@node2.supernodexp.hpc, sock=16
02/19/2018 11:50:59;0100;Server@node2;Req;;Type 51 request received from Scheduler@node2.supernodexp.hpc, sock=16
02/19/2018 11:50:59;0100;Server@node2;Req;;Type 23 request received from Scheduler@node2.supernodexp.hpc, sock=16
02/19/2018 11:50:59;0008;Server@node2;Job;3231.node2.supernodexp.hpc;Job Run at request of Scheduler@node2.supernodexp.hpc on exec_vnode (node14:ncpus=32:nmics=1:mem=16777216kb)
02/19/2018 11:50:59;0001;Server@node2;Svr;Server@node2;Success (0) in req_runjob2, return value of svr_startjob is 0
02/19/2018 11:50:59;0100;Server@node2;Req;;Type 11 request received from Scheduler@node2.supernodexp.hpc, sock=16
02/19/2018 11:50:59;0008;Server@node2;Job;3271.node2.supernodexp.hpc;Job Modified at request of Scheduler@node2.supernodexp.hpc
02/19/2018 11:59:25;0080;Server@node2;Job;3220.node2.supernodexp.hpc;Obit received momhop:1 serverhop:1 state:4 substate:42
02/19/2018 11:59:27;0010;Server@node2;Job;3220.node2.supernodexp.hpc;Exit_status=2 resources_used.cpupercent=2150 resources_used.cput=06:31:57 resources_used.mem=21841900kb resources_used.ncpus=32 resources_used.vmem=24851196kb resources_used.walltime=00:18:25
02/19/2018 11:59:27;0100;Server@node2;Job;3220.node2.supernodexp.hpc;dequeuing from workq, state 5
02/19/2018 11:59:27;0040;Server@node2;Svr;node2.supernodexp.hpc;Scheduler sent command 2
02/19/2018 11:59:27;0040;Server@node2;Svr;node2.supernodexp.hpc;Scheduler sent command 0
02/19/2018 11:59:27;0100;Server@node2;Req;;Type 21 request received from Scheduler@node2.supernodexp.hpc, sock=16
02/19/2018 11:59:27;0100;Server@node2;Req;;Type 81 request received from Scheduler@node2.supernodexp.hpc, sock=16
02/19/2018 11:59:27;0100;Server@node2;Req;;Type 71 request received from Scheduler@node2.supernodexp.hpc, sock=16
02/19/2018 11:59:27;0100;Server@node2;Req;;Type 58 request received from Scheduler@node2.supernodexp.hpc, sock=16
02/19/2018 11:59:27;0100;Server@node2;Req;;Type 20 request received from Scheduler@node2.supernodexp.hpc, sock=16
02/19/2018 11:59:27;0100;Server@node2;Req;;Type 51 request received from Scheduler@node2.supernodexp.hpc, sock=16
02/19/2018 11:59:27;0100;Server@node2;Req;;Type 23 request received from Scheduler@node2.supernodexp.hpc, sock=16
02/19/2018 11:59:27;0008;Server@node2;Job;3271.node2.supernodexp.hpc;Job Run at request of Scheduler@node2.supernodexp.hpc on exec_vnode (node13:ncpus=32:nmics=1:mem=16777216kb)
02/19/2018 11:59:27;0001;Server@node2;Svr;Server@node2;Success (0) in req_runjob2, return value of svr_startjob is 0
02/19/2018 11:59:27;0100;Server@node2;Req;;Type 11 request received from Scheduler@node2.supernodexp.hpc, sock=16
02/19/2018 11:59:27;0008;Server@node2;Job;3297.node2.supernodexp.hpc;Job Modified at request of Scheduler@node2.supernodexp.hpc
02/19/2018 12:09:26;0080;Server@node2;Job;3231.node2.supernodexp.hpc;Obit received momhop:1 serverhop:1 state:4 substate:42
02/19/2018 12:09:27;0040;Server@node2;Svr;node2.supernodexp.hpc;Scheduler sent command 3
02/19/2018 12:09:27;0040;Server@node2;Svr;node2.supernodexp.hpc;Scheduler sent command 0
02/19/2018 12:09:27;0100;Server@node2;Req;;Type 21 request received from Scheduler@node2.supernodexp.hpc, sock=16
02/19/2018 12:09:27;0100;Server@node2;Req;;Type 81 request received from Scheduler@node2.supernodexp.hpc, sock=16
02/19/2018 12:09:27;0100;Server@node2;Req;;Type 71 request received from Scheduler@node2.supernodexp.hpc, sock=16
02/19/2018 12:09:27;0100;Server@node2;Req;;Type 58 request received from Scheduler@node2.supernodexp.hpc, sock=16
02/19/2018 12:09:27;0100;Server@node2;Req;;Type 20 request received from Scheduler@node2.supernodexp.hpc, sock=16
02/19/2018 12:09:27;0100;Server@node2;Req;;Type 51 request received from Scheduler@node2.supernodexp.hpc, sock=16
02/19/2018 12:09:28;0010;Server@node2;Job;3231.node2.supernodexp.hpc;Exit_status=2 resources_used.cpupercent=2091 resources_used.cput=06:12:15 resources_used.mem=22214184kb resources_used.ncpus=32 resources_used.vmem=24917168kb resources_used.walltime=00:18:27
02/19/2018 12:09:28;0100;Server@node2;Job;3231.node2.supernodexp.hpc;dequeuing from workq, state 5
02/19/2018 12:09:28;0040;Server@node2;Svr;node2.supernodexp.hpc;Scheduler sent command 2
02/19/2018 12:09:28;0040;Server@node2;Svr;node2.supernodexp.hpc;Scheduler sent command 0
02/19/2018 12:09:28;0100;Server@node2;Req;;Type 21 request received from Scheduler@node2.supernodexp.hpc, sock=16
02/19/2018 12:09:28;0100;Server@node2;Req;;Type 81 request received from Scheduler@node2.supernodexp.hpc, sock=16
02/19/2018 12:09:28;0100;Server@node2;Req;;Type 71 request received from Scheduler@node2.supernodexp.hpc, sock=16
02/19/2018 12:09:28;0100;Server@node2;Req;;Type 58 request received from Scheduler@node2.supernodexp.hpc, sock=16
02/19/2018 12:09:28;0100;Server@node2;Req;;Type 20 request received from Scheduler@node2.supernodexp.hpc, sock=16
02/19/2018 12:09:28;0100;Server@node2;Req;;Type 51 request received from Scheduler@node2.supernodexp.hpc, sock=16
02/19/2018 12:09:28;0100;Server@node2;Req;;Type 23 request received from Scheduler@node2.supernodexp.hpc, sock=16
02/19/2018 12:09:28;0008;Server@node2;Job;3297.node2.supernodexp.hpc;Job Run at request of Scheduler@node2.supernodexp.hpc on exec_vnode (node14:ncpus=32:nmics=1:mem=16777216kb)
02/19/2018 12:09:28;0001;Server@node2;Svr;Server@node2;Success (0) in req_runjob2, return value of svr_startjob is 0
02/19/2018 12:09:28;0100;Server@node2;Req;;Type 11 request received from Scheduler@node2.supernodexp.hpc, sock=16
02/19/2018 12:09:28;0008;Server@node2;Job;3307.node2.supernodexp.hpc;Job Modified at request of Scheduler@node2.supernodexp.hpc
02/19/2018 12:17:39;0080;Server@node2;Job;3271.node2.supernodexp.hpc;Obit received momhop:1 serverhop:1 state:4 substate:42
02/19/2018 12:17:40;0010;Server@node2;Job;3271.node2.supernodexp.hpc;Exit_status=2 resources_used.cpupercent=2175 resources_used.cput=06:25:12 resources_used.mem=21812304kb resources_used.ncpus=32 resources_used.vmem=24852008kb resources_used.walltime=00:18:12
02/19/2018 12:17:40;0100;Server@node2;Job;3271.node2.supernodexp.hpc;dequeuing from workq, state 5
02/19/2018 12:17:40;0040;Server@node2;Svr;node2.supernodexp.hpc;Scheduler sent command 2
02/19/2018 12:17:40;0040;Server@node2;Svr;node2.supernodexp.hpc;Scheduler sent command 0
02/19/2018 12:17:40;0100;Server@node2;Req;;Type 21 request received from Scheduler@node2.supernodexp.hpc, sock=16
02/19/2018 12:17:40;0100;Server@node2;Req;;Type 81 request received from Scheduler@node2.supernodexp.hpc, sock=16
02/19/2018 12:17:40;0100;Server@node2;Req;;Type 71 request received from Scheduler@node2.supernodexp.hpc, sock=16
02/19/2018 12:17:40;0100;Server@node2;Req;;Type 58 request received from Scheduler@node2.supernodexp.hpc, sock=16
02/19/2018 12:17:40;0100;Server@node2;Req;;Type 20 request received from Scheduler@node2.supernodexp.hpc, sock=16
02/19/2018 12:17:40;0100;Server@node2;Req;;Type 51 request received from Scheduler@node2.supernodexp.hpc, sock=16
02/19/2018 12:17:40;0100;Server@node2;Req;;Type 23 request received from Scheduler@node2.supernodexp.hpc, sock=16
02/19/2018 12:17:40;0008;Server@node2;Job;3307.node2.supernodexp.hpc;Job Run at request of Scheduler@node2.supernodexp.hpc on exec_vnode (node13:ncpus=32:nmics=1:mem=16777216kb)
02/19/2018 12:17:40;0001;Server@node2;Svr;Server@node2;Success (0) in req_runjob2, return value of svr_startjob is 0
02/19/2018 12:17:40;0100;Server@node2;Req;;Type 11 request received from Scheduler@node2.supernodexp.hpc, sock=16
02/19/2018 12:17:40;0008;Server@node2;Job;3315.node2.supernodexp.hpc;Job Modified at request of Scheduler@node2.supernodexp.hpc
02/19/2018 12:27:38;0080;Server@node2;Job;3297.node2.supernodexp.hpc;Obit received momhop:1 serverhop:1 state:4 substate:42
02/19/2018 12:27:40;0040;Server@node2;Svr;node2.supernodexp.hpc;Scheduler sent command 3
02/19/2018 12:27:40;0040;Server@node2;Svr;node2.supernodexp.hpc;Scheduler sent command 0
02/19/2018 12:27:40;0100;Server@node2;Req;;Type 21 request received from Scheduler@node2.supernodexp.hpc, sock=16
02/19/2018 12:27:40;0100;Server@node2;Req;;Type 81 request received from Scheduler@node2.supernodexp.hpc, sock=16
02/19/2018 12:27:40;0100;Server@node2;Req;;Type 71 request received from Scheduler@node2.supernodexp.hpc, sock=16
02/19/2018 12:27:40;0100;Server@node2;Req;;Type 58 request received from Scheduler@node2.supernodexp.hpc, sock=16
02/19/2018 12:27:40;0010;Server@node2;Job;3297.node2.supernodexp.hpc;Exit_status=2 resources_used.cpupercent=2062 resources_used.cput=06:09:15 resources_used.mem=22218308kb resources_used.ncpus=32 resources_used.vmem=24915660kb resources_used.walltime=00:18:10
02/19/2018 12:27:40;0100;Server@node2;Job;3297.node2.supernodexp.hpc;dequeuing from workq, state 5
02/19/2018 12:27:40;0100;Server@node2;Req;;Type 20 request received from Scheduler@node2.supernodexp.hpc, sock=16
02/19/2018 12:27:40;0100;Server@node2;Req;;Type 51 request received from Scheduler@node2.supernodexp.hpc, sock=16
02/19/2018 12:27:40;0100;Server@node2;Req;;Type 23 request received from Scheduler@node2.supernodexp.hpc, sock=16
02/19/2018 12:27:40;0008;Server@node2;Job;3315.node2.supernodexp.hpc;Job Run at request of Scheduler@node2.supernodexp.hpc on exec_vnode (node14:ncpus=32:nmics=1:mem=16777216kb)
02/19/2018 12:27:40;0001;Server@node2;Svr;Server@node2;Success (0) in req_runjob2, return value of svr_startjob is 0
02/19/2018 12:27:40;0100;Server@node2;Req;;Type 11 request received from Scheduler@node2.supernodexp.hpc, sock=16
02/19/2018 12:27:40;0008;Server@node2;Job;3324.node2.supernodexp.hpc;Job Modified at request of Scheduler@node2.supernodexp.hpc
02/19/2018 12:27:40;0040;Server@node2;Svr;node2.supernodexp.hpc;Scheduler sent command 2
02/19/2018 12:27:40;0040;Server@node2;Svr;node2.supernodexp.hpc;Scheduler sent command 0
02/19/2018 12:27:40;0100;Server@node2;Req;;Type 21 request received from Scheduler@node2.supernodexp.hpc, sock=16
02/19/2018 12:27:40;0100;Server@node2;Req;;Type 81 request received from Scheduler@node2.supernodexp.hpc, sock=16
02/19/2018 12:27:40;0100;Server@node2;Req;;Type 71 request received from Scheduler@node2.supernodexp.hpc, sock=16
02/19/2018 12:27:40;0100;Server@node2;Req;;Type 58 request received from Scheduler@node2.supernodexp.hpc, sock=16
02/19/2018 12:27:40;0100;Server@node2;Req;;Type 20 request received from Scheduler@node2.supernodexp.hpc, sock=16
02/19/2018 12:27:40;0100;Server@node2;Req;;Type 51 request received from Scheduler@node2.supernodexp.hpc, sock=16
02/19/2018 12:35:58;0080;Server@node2;Job;3307.node2.supernodexp.hpc;Obit received momhop:1 serverhop:1 state:4 substate:42
02/19/2018 12:36:00;0010;Server@node2;Job;3307.node2.supernodexp.hpc;Exit_status=2 resources_used.cpupercent=2169 resources_used.cput=06:30:29 resources_used.mem=21829700kb resources_used.ncpus=32 resources_used.vmem=24851192kb resources_used.walltime=00:18:17
02/19/2018 12:36:00;0100;Server@node2;Job;3307.node2.supernodexp.hpc;dequeuing from workq, state 5
02/19/2018 12:36:00;0040;Server@node2;Svr;node2.supernodexp.hpc;Scheduler sent command 2
02/19/2018 12:36:00;0040;Server@node2;Svr;node2.supernodexp.hpc;Scheduler sent command 0
02/19/2018 12:36:00;0100;Server@node2;Req;;Type 21 request received from Scheduler@node2.supernodexp.hpc, sock=16
02/19/2018 12:36:00;0100;Server@node2;Req;;Type 81 request received from Scheduler@node2.supernodexp.hpc, sock=16
02/19/2018 12:36:00;0100;Server@node2;Req;;Type 71 request received from Scheduler@node2.supernodexp.hpc, sock=16
02/19/2018 12:36:00;0100;Server@node2;Req;;Type 58 request received from Scheduler@node2.supernodexp.hpc, sock=16
02/19/2018 12:36:00;0100;Server@node2;Req;;Type 20 request received from Scheduler@node2.supernodexp.hpc, sock=16
02/19/2018 12:36:00;0100;Server@node2;Req;;Type 51 request received from Scheduler@node2.supernodexp.hpc, sock=16
02/19/2018 12:36:00;0100;Server@node2;Req;;Type 23 request received from Scheduler@node2.supernodexp.hpc, sock=16
02/19/2018 12:36:00;0008;Server@node2;Job;3324.node2.supernodexp.hpc;Job Run at request of Scheduler@node2.supernodexp.hpc on exec_vnode (node13:ncpus=32:nmics=1:mem=16777216kb)
02/19/2018 12:36:00;0001;Server@node2;Svr;Server@node2;Success (0) in req_runjob2, return value of svr_startjob is 0
02/19/2018 12:36:00;0100;Server@node2;Req;;Type 11 request received from Scheduler@node2.supernodexp.hpc, sock=16
02/19/2018 12:36:00;0008;Server@node2;Job;3330.node2.supernodexp.hpc;Job Modified at request of Scheduler@node2.supernodexp.hpc
02/19/2018 12:45:54;0080;Server@node2;Job;3315.node2.supernodexp.hpc;Obit received momhop:1 serverhop:1 state:4 substate:42
02/19/2018 12:45:55;0010;Server@node2;Job;3315.node2.supernodexp.hpc;Exit_status=2 resources_used.cpupercent=2092 resources_used.cput=06:12:04 resources_used.mem=21829760kb resources_used.ncpus=32 resources_used.vmem=24546452kb resources_used.walltime=00:18:14
02/19/2018 12:45:55;0100;Server@node2;Job;3315.node2.supernodexp.hpc;dequeuing from workq, state 5
02/19/2018 12:45:55;0040;Server@node2;Svr;node2.supernodexp.hpc;Scheduler sent command 2
02/19/2018 12:45:55;0040;Server@node2;Svr;node2.supernodexp.hpc;Scheduler sent command 0
02/19/2018 12:45:55;0100;Server@node2;Req;;Type 21 request received from Scheduler@node2.supernodexp.hpc, sock=16
02/19/2018 12:45:55;0100;Server@node2;Req;;Type 81 request received from Scheduler@node2.supernodexp.hpc, sock=16
02/19/2018 12:45:55;0100;Server@node2;Req;;Type 71 request received from Scheduler@node2.supernodexp.hpc, sock=16
02/19/2018 12:45:55;0100;Server@node2;Req;;Type 58 request received from Scheduler@node2.supernodexp.hpc, sock=16
02/19/2018 12:45:55;0100;Server@node2;Req;;Type 20 request received from Scheduler@node2.supernodexp.hpc, sock=16
02/19/2018 12:45:55;0100;Server@node2;Req;;Type 51 request received from Scheduler@node2.supernodexp.hpc, sock=16
02/19/2018 12:45:55;0100;Server@node2;Req;;Type 23 request received from Scheduler@node2.supernodexp.hpc, sock=16
02/19/2018 12:45:55;0008;Server@node2;Job;3330.node2.supernodexp.hpc;Job Run at request of Scheduler@node2.supernodexp.hpc on exec_vnode (node14:ncpus=32:nmics=1:mem=16777216kb)
02/19/2018 12:45:55;0001;Server@node2;Svr;Server@node2;Success (0) in req_runjob2, return value of svr_startjob is 0
02/19/2018 12:45:55;0100;Server@node2;Req;;Type 11 request received from Scheduler@node2.supernodexp.hpc, sock=16
02/19/2018 12:45:55;0008;Server@node2;Job;3332.node2.supernodexp.hpc;Job Modified at request of Scheduler@node2.supernodexp.hpc
02/19/2018 12:54:23;0080;Server@node2;Job;3324.node2.supernodexp.hpc;Obit received momhop:1 serverhop:1 state:4 substate:42
02/19/2018 12:54:24;0010;Server@node2;Job;3324.node2.supernodexp.hpc;Exit_status=2 resources_used.cpupercent=2171 resources_used.cput=06:33:46 resources_used.mem=21826316kb resources_used.ncpus=32 resources_used.vmem=25038144kb resources_used.walltime=00:18:23
02/19/2018 12:54:24;0100;Server@node2;Job;3324.node2.supernodexp.hpc;dequeuing from workq, state 5
02/19/2018 12:54:24;0040;Server@node2;Svr;node2.supernodexp.hpc;Scheduler sent command 2
02/19/2018 12:54:24;0040;Server@node2;Svr;node2.supernodexp.hpc;Scheduler sent command 0
02/19/2018 12:54:24;0100;Server@node2;Req;;Type 21 request received from Scheduler@node2.supernodexp.hpc, sock=16
02/19/2018 12:54:24;0100;Server@node2;Req;;Type 81 request received from Scheduler@node2.supernodexp.hpc, sock=16
02/19/2018 12:54:24;0100;Server@node2;Req;;Type 71 request received from Scheduler@node2.supernodexp.hpc, sock=16
02/19/2018 12:54:24;0100;Server@node2;Req;;Type 58 request received from Scheduler@node2.supernodexp.hpc, sock=16
02/19/2018 12:54:24;0100;Server@node2;Req;;Type 20 request received from Scheduler@node2.supernodexp.hpc, sock=16
02/19/2018 12:54:24;0100;Server@node2;Req;;Type 51 request received from Scheduler@node2.supernodexp.hpc, sock=16
02/19/2018 12:54:24;0100;Server@node2;Req;;Type 23 request received from Scheduler@node2.supernodexp.hpc, sock=16
02/19/2018 12:54:24;0008;Server@node2;Job;3332.node2.supernodexp.hpc;Job Run at request of Scheduler@node2.supernodexp.hpc on exec_vnode (node13:ncpus=32:nmics=1:mem=16777216kb)
02/19/2018 12:54:24;0001;Server@node2;Svr;Server@node2;Success (0) in req_runjob2, return value of svr_startjob is 0
02/19/2018 12:54:24;0100;Server@node2;Req;;Type 11 request received from Scheduler@node2.supernodexp.hpc, sock=16
02/19/2018 12:54:24;0008;Server@node2;Job;3398.node2.supernodexp.hpc;Job Modified at request of Scheduler@node2.supernodexp.hpc
02/19/2018 13:04:11;0080;Server@node2;Job;3330.node2.supernodexp.hpc;Obit received momhop:1 serverhop:1 state:4 substate:42
02/19/2018 13:04:13;0010;Server@node2;Job;3330.node2.supernodexp.hpc;Exit_status=2 resources_used.cpupercent=2090 resources_used.cput=06:13:31 resources_used.mem=22205476kb resources_used.ncpus=32 resources_used.vmem=24917508kb resources_used.walltime=00:18:16
02/19/2018 13:04:13;0100;Server@node2;Job;3330.node2.supernodexp.hpc;dequeuing from workq, state 5
02/19/2018 13:04:13;0040;Server@node2;Svr;node2.supernodexp.hpc;Scheduler sent command 2
02/19/2018 13:04:13;0040;Server@node2;Svr;node2.supernodexp.hpc;Scheduler sent command 0
02/19/2018 13:04:13;0100;Server@node2;Req;;Type 21 request received from Scheduler@node2.supernodexp.hpc, sock=16
02/19/2018 13:04:13;0100;Server@node2;Req;;Type 81 request received from Scheduler@node2.supernodexp.hpc, sock=16
02/19/2018 13:04:13;0100;Server@node2;Req;;Type 71 request received from Scheduler@node2.supernodexp.hpc, sock=16
02/19/2018 13:04:13;0100;Server@node2;Req;;Type 58 request received from Scheduler@node2.supernodexp.hpc, sock=16
02/19/2018 13:04:13;0100;Server@node2;Req;;Type 20 request received from Scheduler@node2.supernodexp.hpc, sock=16
02/19/2018 13:04:13;0100;Server@node2;Req;;Type 51 request received from Scheduler@node2.supernodexp.hpc, sock=16
02/19/2018 13:04:13;0100;Server@node2;Req;;Type 23 request received from Scheduler@node2.supernodexp.hpc, sock=16
02/19/2018 13:04:13;0008;Server@node2;Job;3398.node2.supernodexp.hpc;Job Run at request of Scheduler@node2.supernodexp.hpc on exec_vnode (node14:ncpus=32:nmics=1:mem=16777216kb)
02/19/2018 13:04:13;0001;Server@node2;Svr;Server@node2;Success (0) in req_runjob2, return value of svr_startjob is 0
02/19/2018 13:04:13;0100;Server@node2;Req;;Type 11 request received from Scheduler@node2.supernodexp.hpc, sock=16
02/19/2018 13:04:13;0008;Server@node2;Job;3409.node2.supernodexp.hpc;Job Modified at request of Scheduler@node2.supernodexp.hpc
02/19/2018 13:12:49;0080;Server@node2;Job;3332.node2.supernodexp.hpc;Obit received momhop:1 serverhop:1 state:4 substate:42
02/19/2018 13:12:51;0010;Server@node2;Job;3332.node2.supernodexp.hpc;Exit_status=2 resources_used.cpupercent=2179 resources_used.cput=06:29:24 resources_used.mem=21825688kb resources_used.ncpus=32 resources_used.vmem=24852008kb resources_used.walltime=00:18:25
02/19/2018 13:12:51;0100;Server@node2;Job;3332.node2.supernodexp.hpc;dequeuing from workq, state 5
02/19/2018 13:12:51;0040;Server@node2;Svr;node2.supernodexp.hpc;Scheduler sent command 2
02/19/2018 13:12:51;0040;Server@node2;Svr;node2.supernodexp.hpc;Scheduler sent command 0
02/19/2018 13:12:51;0100;Server@node2;Req;;Type 21 request received from Scheduler@node2.supernodexp.hpc, sock=16
02/19/2018 13:12:51;0100;Server@node2;Req;;Type 81 request received from Scheduler@node2.supernodexp.hpc, sock=16
02/19/2018 13:12:51;0100;Server@node2;Req;;Type 71 request received from Scheduler@node2.supernodexp.hpc, sock=16
02/19/2018 13:12:51;0100;Server@node2;Req;;Type 58 request received from Scheduler@node2.supernodexp.hpc, sock=16
02/19/2018 13:12:51;0100;Server@node2;Req;;Type 20 request received from Scheduler@node2.supernodexp.hpc, sock=16
02/19/2018 13:12:51;0100;Server@node2;Req;;Type 51 request received from Scheduler@node2.supernodexp.hpc, sock=16
02/19/2018 13:12:51;0100;Server@node2;Req;;Type 23 request received from Scheduler@node2.supernodexp.hpc, sock=16
02/19/2018 13:12:51;0008;Server@node2;Job;3409.node2.supernodexp.hpc;Job Run at request of Scheduler@node2.supernodexp.hpc on exec_vnode (node13:ncpus=32:nmics=1:mem=16777216kb)
02/19/2018 13:12:51;0001;Server@node2;Svr;Server@node2;Success (0) in req_runjob2, return value of svr_startjob is 0
02/19/2018 13:12:51;0100;Server@node2;Req;;Type 11 request received from Scheduler@node2.supernodexp.hpc, sock=16
02/19/2018 13:12:51;0008;Server@node2;Job;3422.node2.supernodexp.hpc;Job Modified at request of Scheduler@node2.supernodexp.hpc
02/19/2018 13:22:33;0080;Server@node2;Job;3398.node2.supernodexp.hpc;Obit received momhop:1 serverhop:1 state:4 substate:42
02/19/2018 13:22:34;0010;Server@node2;Job;3398.node2.supernodexp.hpc;Exit_status=2 resources_used.cpupercent=2126 resources_used.cput=06:13:59 resources_used.mem=22052544kb resources_used.ncpus=32 resources_used.vmem=24770764kb resources_used.walltime=00:18:20
02/19/2018 13:22:34;0100;Server@node2;Job;3398.node2.supernodexp.hpc;dequeuing from workq, state 5
02/19/2018 13:22:34;0040;Server@node2;Svr;node2.supernodexp.hpc;Scheduler sent command 2
02/19/2018 13:22:34;0040;Server@node2;Svr;node2.supernodexp.hpc;Scheduler sent command 0
02/19/2018 13:22:34;0100;Server@node2;Req;;Type 21 request received from Scheduler@node2.supernodexp.hpc, sock=16
02/19/2018 13:22:34;0100;Server@node2;Req;;Type 81 request received from Scheduler@node2.supernodexp.hpc, sock=16
02/19/2018 13:22:34;0100;Server@node2;Req;;Type 71 request received from Scheduler@node2.supernodexp.hpc, sock=16
02/19/2018 13:22:34;0100;Server@node2;Req;;Type 58 request received from Scheduler@node2.supernodexp.hpc, sock=16
02/19/2018 13:22:34;0100;Server@node2;Req;;Type 20 request received from Scheduler@node2.supernodexp.hpc, sock=16
02/19/2018 13:22:34;0100;Server@node2;Req;;Type 51 request received from Scheduler@node2.supernodexp.hpc, sock=16
02/19/2018 13:22:34;0100;Server@node2;Req;;Type 23 request received from Scheduler@node2.supernodexp.hpc, sock=16
02/19/2018 13:22:34;0008;Server@node2;Job;3422.node2.supernodexp.hpc;Job Run at request of Scheduler@node2.supernodexp.hpc on exec_vnode (node14:ncpus=32:nmics=1:mem=16777216kb)
02/19/2018 13:22:34;0001;Server@node2;Svr;Server@node2;Success (0) in req_runjob2, return value of svr_startjob is 0
02/19/2018 13:22:34;0100;Server@node2;Req;;Type 11 request received from Scheduler@node2.supernodexp.hpc, sock=16
02/19/2018 13:22:34;0008;Server@node2;Job;3439.node2.supernodexp.hpc;Job Modified at request of Scheduler@node2.supernodexp.hpc
02/19/2018 13:30:57;0080;Server@node2;Job;3409.node2.supernodexp.hpc;Obit received momhop:1 serverhop:1 state:4 substate:42
02/19/2018 13:30:59;0010;Server@node2;Job;3409.node2.supernodexp.hpc;Exit_status=2 resources_used.cpupercent=2156 resources_used.cput=06:28:52 resources_used.mem=21845740kb resources_used.ncpus=32 resources_used.vmem=24870436kb resources_used.walltime=00:18:06
02/19/2018 13:30:59;0100;Server@node2;Job;3409.node2.supernodexp.hpc;dequeuing from workq, state 5
02/19/2018 13:30:59;0040;Server@node2;Svr;node2.supernodexp.hpc;Scheduler sent command 2
02/19/2018 13:30:59;0040;Server@node2;Svr;node2.supernodexp.hpc;Scheduler sent command 0
02/19/2018 13:30:59;0100;Server@node2;Req;;Type 21 request received from Scheduler@node2.supernodexp.hpc, sock=16
02/19/2018 13:30:59;0100;Server@node2;Req;;Type 81 request received from Scheduler@node2.supernodexp.hpc, sock=16
02/19/2018 13:30:59;0100;Server@node2;Req;;Type 71 request received from Scheduler@node2.supernodexp.hpc, sock=16
02/19/2018 13:30:59;0100;Server@node2;Req;;Type 58 request received from Scheduler@node2.supernodexp.hpc, sock=16
02/19/2018 13:30:59;0100;Server@node2;Req;;Type 20 request received from Scheduler@node2.supernodexp.hpc, sock=16
02/19/2018 13:30:59;0100;Server@node2;Req;;Type 51 request received from Scheduler@node2.supernodexp.hpc, sock=16
02/19/2018 13:30:59;0100;Server@node2;Req;;Type 23 request received from Scheduler@node2.supernodexp.hpc, sock=16
02/19/2018 13:30:59;0008;Server@node2;Job;3439.node2.supernodexp.hpc;Job Run at request of Scheduler@node2.supernodexp.hpc on exec_vnode (node13:ncpus=32:nmics=1:mem=16777216kb)
02/19/2018 13:30:59;0001;Server@node2;Svr;Server@node2;Success (0) in req_runjob2, return value of svr_startjob is 0
02/19/2018 13:30:59;0100;Server@node2;Req;;Type 11 request received from Scheduler@node2.supernodexp.hpc, sock=16
02/19/2018 13:30:59;0008;Server@node2;Job;3479.node2.supernodexp.hpc;Job Modified at request of Scheduler@node2.supernodexp.hpc
02/19/2018 13:40:59;0040;Server@node2;Svr;node2.supernodexp.hpc;Scheduler sent command 3
02/19/2018 13:40:59;0040;Server@node2;Svr;node2.supernodexp.hpc;Scheduler sent command 0
02/19/2018 13:40:59;0100;Server@node2;Req;;Type 21 request received from Scheduler@node2.supernodexp.hpc, sock=16
02/19/2018 13:40:59;0100;Server@node2;Req;;Type 81 request received from Scheduler@node2.supernodexp.hpc, sock=16
02/19/2018 13:40:59;0100;Server@node2;Req;;Type 71 request received from Scheduler@node2.supernodexp.hpc, sock=16
02/19/2018 13:40:59;0100;Server@node2;Req;;Type 58 request received from Scheduler@node2.supernodexp.hpc, sock=16
02/19/2018 13:41:00;0100;Server@node2;Req;;Type 20 request received from Scheduler@node2.supernodexp.hpc, sock=16
02/19/2018 13:41:00;0100;Server@node2;Req;;Type 51 request received from Scheduler@node2.supernodexp.hpc, sock=16
02/19/2018 13:41:03;0080;Server@node2;Job;3422.node2.supernodexp.hpc;Obit received momhop:1 serverhop:1 state:4 substate:42
02/19/2018 13:41:05;0010;Server@node2;Job;3422.node2.supernodexp.hpc;Exit_status=2 resources_used.cpupercent=2086 resources_used.cput=06:08:40 resources_used.mem=22052784kb resources_used.ncpus=32 resources_used.vmem=24773012kb resources_used.walltime=00:18:29
02/19/2018 13:41:05;0100;Server@node2;Job;3422.node2.supernodexp.hpc;dequeuing from workq, state 5
02/19/2018 13:41:05;0040;Server@node2;Svr;node2.supernodexp.hpc;Scheduler sent command 2
02/19/2018 13:41:05;0040;Server@node2;Svr;node2.supernodexp.hpc;Scheduler sent command 0
02/19/2018 13:41:05;0100;Server@node2;Req;;Type 21 request received from Scheduler@node2.supernodexp.hpc, sock=16
02/19/2018 13:41:05;0100;Server@node2;Req;;Type 81 request received from Scheduler@node2.supernodexp.hpc, sock=16
02/19/2018 13:41:05;0100;Server@node2;Req;;Type 71 request received from Scheduler@node2.supernodexp.hpc, sock=16
02/19/2018 13:41:05;0100;Server@node2;Req;;Type 58 request received from Scheduler@node2.supernodexp.hpc, sock=16
02/19/2018 13:41:05;0100;Server@node2;Req;;Type 20 request received from Scheduler@node2.supernodexp.hpc, sock=16
02/19/2018 13:41:05;0100;Server@node2;Req;;Type 51 request received from Scheduler@node2.supernodexp.hpc, sock=16
02/19/2018 13:41:05;0100;Server@node2;Req;;Type 23 request received from Scheduler@node2.supernodexp.hpc, sock=16
02/19/2018 13:41:05;0008;Server@node2;Job;3479.node2.supernodexp.hpc;Job Run at request of Scheduler@node2.supernodexp.hpc on exec_vnode (node14:ncpus=32:nmics=1:mem=16777216kb)
02/19/2018 13:41:05;0001;Server@node2;Svr;Server@node2;Success (0) in req_runjob2, return value of svr_startjob is 0
02/19/2018 13:41:05;0100;Server@node2;Req;;Type 11 request received from Scheduler@node2.supernodexp.hpc, sock=16
02/19/2018 13:41:05;0008;Server@node2;Job;3482.node2.supernodexp.hpc;Job Modified at request of Scheduler@node2.supernodexp.hpc
02/19/2018 13:49:26;0080;Server@node2;Job;3439.node2.supernodexp.hpc;Obit received momhop:1 serverhop:1 state:4 substate:42
02/19/2018 13:49:27;0010;Server@node2;Job;3439.node2.supernodexp.hpc;Exit_status=2 resources_used.cpupercent=2150 resources_used.cput=06:31:24 resources_used.mem=21834832kb resources_used.ncpus=32 resources_used.vmem=24868584kb resources_used.walltime=00:18:27
02/19/2018 13:49:27;0100;Server@node2;Job;3439.node2.supernodexp.hpc;dequeuing from workq, state 5
02/19/2018 13:49:27;0040;Server@node2;Svr;node2.supernodexp.hpc;Scheduler sent command 2
02/19/2018 13:49:27;0040;Server@node2;Svr;node2.supernodexp.hpc;Scheduler sent command 0
02/19/2018 13:49:27;0100;Server@node2;Req;;Type 21 request received from Scheduler@node2.supernodexp.hpc, sock=16
02/19/2018 13:49:27;0100;Server@node2;Req;;Type 81 request received from Scheduler@node2.supernodexp.hpc, sock=16
02/19/2018 13:49:27;0100;Server@node2;Req;;Type 71 request received from Scheduler@node2.supernodexp.hpc, sock=16
02/19/2018 13:49:27;0100;Server@node2;Req;;Type 58 request received from Scheduler@node2.supernodexp.hpc, sock=16
02/19/2018 13:49:27;0100;Server@node2;Req;;Type 20 request received from Scheduler@node2.supernodexp.hpc, sock=16
02/19/2018 13:49:27;0100;Server@node2;Req;;Type 51 request received from Scheduler@node2.supernodexp.hpc, sock=16
02/19/2018 13:49:27;0100;Server@node2;Req;;Type 23 request received from Scheduler@node2.supernodexp.hpc, sock=16
02/19/2018 13:49:27;0008;Server@node2;Job;3482.node2.supernodexp.hpc;Job Run at request of Scheduler@node2.supernodexp.hpc on exec_vnode (node13:ncpus=32:nmics=1:mem=16777216kb)
02/19/2018 13:49:27;0001;Server@node2;Svr;Server@node2;Success (0) in req_runjob2, return value of svr_startjob is 0
02/19/2018 13:49:27;0100;Server@node2;Req;;Type 11 request received from Scheduler@node2.supernodexp.hpc, sock=16
02/19/2018 13:49:27;0008;Server@node2;Job;3518.node2.supernodexp.hpc;Job Modified at request of Scheduler@node2.supernodexp.hpc
02/19/2018 13:59:27;0040;Server@node2;Svr;node2.supernodexp.hpc;Scheduler sent command 3
02/19/2018 13:59:27;0040;Server@node2;Svr;node2.supernodexp.hpc;Scheduler sent command 0
02/19/2018 13:59:27;0100;Server@node2;Req;;Type 21 request received from Scheduler@node2.supernodexp.hpc, sock=16
02/19/2018 13:59:27;0100;Server@node2;Req;;Type 81 request received from Scheduler@node2.supernodexp.hpc, sock=16
02/19/2018 13:59:27;0100;Server@node2;Req;;Type 71 request received from Scheduler@node2.supernodexp.hpc, sock=16
02/19/2018 13:59:27;0100;Server@node2;Req;;Type 58 request received from Scheduler@node2.supernodexp.hpc, sock=16
02/19/2018 13:59:27;0100;Server@node2;Req;;Type 20 request received from Scheduler@node2.supernodexp.hpc, sock=16
02/19/2018 13:59:27;0100;Server@node2;Req;;Type 51 request received from Scheduler@node2.supernodexp.hpc, sock=16
02/19/2018 13:59:29;0080;Server@node2;Job;3479.node2.supernodexp.hpc;Obit received momhop:1 serverhop:1 state:4 substate:42
02/19/2018 13:59:32;0010;Server@node2;Job;3479.node2.supernodexp.hpc;Exit_status=2 resources_used.cpupercent=2093 resources_used.cput=06:12:49 resources_used.mem=21821580kb resources_used.ncpus=32 resources_used.vmem=24736448kb resources_used.walltime=00:18:24
02/19/2018 13:59:32;0100;Server@node2;Job;3479.node2.supernodexp.hpc;dequeuing from workq, state 5
02/19/2018 13:59:32;0040;Server@node2;Svr;node2.supernodexp.hpc;Scheduler sent command 2
02/19/2018 13:59:32;0040;Server@node2;Svr;node2.supernodexp.hpc;Scheduler sent command 0
02/19/2018 13:59:32;0100;Server@node2;Req;;Type 21 request received from Scheduler@node2.supernodexp.hpc, sock=16
02/19/2018 13:59:32;0100;Server@node2;Req;;Type 81 request received from Scheduler@node2.supernodexp.hpc, sock=16
02/19/2018 13:59:32;0100;Server@node2;Req;;Type 71 request received from Scheduler@node2.supernodexp.hpc, sock=16
02/19/2018 13:59:32;0100;Server@node2;Req;;Type 58 request received from Scheduler@node2.supernodexp.hpc, sock=16
02/19/2018 13:59:32;0100;Server@node2;Req;;Type 20 request received from Scheduler@node2.supernodexp.hpc, sock=16
02/19/2018 13:59:32;0100;Server@node2;Req;;Type 51 request received from Scheduler@node2.supernodexp.hpc, sock=16
02/19/2018 13:59:32;0100;Server@node2;Req;;Type 23 request received from Scheduler@node2.supernodexp.hpc, sock=16
02/19/2018 13:59:32;0008;Server@node2;Job;3518.node2.supernodexp.hpc;Job Run at request of Scheduler@node2.supernodexp.hpc on exec_vnode (node14:ncpus=32:nmics=1:mem=16777216kb)
02/19/2018 13:59:32;0001;Server@node2;Svr;Server@node2;Success (0) in req_runjob2, return value of svr_startjob is 0
02/19/2018 13:59:32;0100;Server@node2;Req;;Type 11 request received from Scheduler@node2.supernodexp.hpc, sock=16
02/19/2018 13:59:32;0008;Server@node2;Job;3521.node2.supernodexp.hpc;Job Modified at request of Scheduler@node2.supernodexp.hpc
02/19/2018 14:07:53;0080;Server@node2;Job;3482.node2.supernodexp.hpc;Obit received momhop:1 serverhop:1 state:4 substate:42
02/19/2018 14:07:55;0010;Server@node2;Job;3482.node2.supernodexp.hpc;Exit_status=2 resources_used.cpupercent=2180 resources_used.cput=06:28:10 resources_used.mem=21835348kb resources_used.ncpus=32 resources_used.vmem=24852740kb resources_used.walltime=00:18:25
02/19/2018 14:07:55;0100;Server@node2;Job;3482.node2.supernodexp.hpc;dequeuing from workq, state 5
02/19/2018 14:07:55;0040;Server@node2;Svr;node2.supernodexp.hpc;Scheduler sent command 2
02/19/2018 14:07:55;0040;Server@node2;Svr;node2.supernodexp.hpc;Scheduler sent command 0
02/19/2018 14:07:55;0100;Server@node2;Req;;Type 21 request received from Scheduler@node2.supernodexp.hpc, sock=16
02/19/2018 14:07:55;0100;Server@node2;Req;;Type 81 request received from Scheduler@node2.supernodexp.hpc, sock=16
02/19/2018 14:07:55;0100;Server@node2;Req;;Type 71 request received from Scheduler@node2.supernodexp.hpc, sock=16
02/19/2018 14:07:55;0100;Server@node2;Req;;Type 58 request received from Scheduler@node2.supernodexp.hpc, sock=16
02/19/2018 14:07:55;0100;Server@node2;Req;;Type 20 request received from Scheduler@node2.supernodexp.hpc, sock=16
02/19/2018 14:07:55;0100;Server@node2;Req;;Type 51 request received from Scheduler@node2.supernodexp.hpc, sock=16
02/19/2018 14:07:55;0100;Server@node2;Req;;Type 23 request received from Scheduler@node2.supernodexp.hpc, sock=16
02/19/2018 14:07:55;0008;Server@node2;Job;3521.node2.supernodexp.hpc;Job Run at request of Scheduler@node2.supernodexp.hpc on exec_vnode (node13:ncpus=32:nmics=1:mem=16777216kb)
02/19/2018 14:07:55;0001;Server@node2;Svr;Server@node2;Success (0) in req_runjob2, return value of svr_startjob is 0
02/19/2018 14:07:55;0100;Server@node2;Req;;Type 11 request received from Scheduler@node2.supernodexp.hpc, sock=16
02/19/2018 14:07:55;0008;Server@node2;Job;3529.node2.supernodexp.hpc;Job Modified at request of Scheduler@node2.supernodexp.hpc
02/19/2018 14:17:55;0040;Server@node2;Svr;node2.supernodexp.hpc;Scheduler sent command 3
02/19/2018 14:17:55;0040;Server@node2;Svr;node2.supernodexp.hpc;Scheduler sent command 0
02/19/2018 14:17:55;0100;Server@node2;Req;;Type 21 request received from Scheduler@node2.supernodexp.hpc, sock=16
02/19/2018 14:17:55;0100;Server@node2;Req;;Type 81 request received from Scheduler@node2.supernodexp.hpc, sock=16
02/19/2018 14:17:55;0100;Server@node2;Req;;Type 71 request received from Scheduler@node2.supernodexp.hpc, sock=16
02/19/2018 14:17:55;0100;Server@node2;Req;;Type 58 request received from Scheduler@node2.supernodexp.hpc, sock=16
02/19/2018 14:17:55;0100;Server@node2;Req;;Type 20 request received from Scheduler@node2.supernodexp.hpc, sock=16
02/19/2018 14:17:55;0100;Server@node2;Req;;Type 51 request received from Scheduler@node2.supernodexp.hpc, sock=16
02/19/2018 14:18:08;0080;Server@node2;Job;3518.node2.supernodexp.hpc;Obit received momhop:1 serverhop:1 state:4 substate:42
02/19/2018 14:18:09;0010;Server@node2;Job;3518.node2.supernodexp.hpc;Exit_status=2 resources_used.cpupercent=2096 resources_used.cput=06:14:56 resources_used.mem=22099920kb resources_used.ncpus=32 resources_used.vmem=24861860kb resources_used.walltime=00:18:36
02/19/2018 14:18:09;0100;Server@node2;Job;3518.node2.supernodexp.hpc;dequeuing from workq, state 5
02/19/2018 14:18:09;0040;Server@node2;Svr;node2.supernodexp.hpc;Scheduler sent command 2
02/19/2018 14:18:09;0040;Server@node2;Svr;node2.supernodexp.hpc;Scheduler sent command 0
02/19/2018 14:18:09;0100;Server@node2;Req;;Type 21 request received from Scheduler@node2.supernodexp.hpc, sock=16
02/19/2018 14:18:09;0100;Server@node2;Req;;Type 81 request received from Scheduler@node2.supernodexp.hpc, sock=16
02/19/2018 14:18:09;0100;Server@node2;Req;;Type 71 request received from Scheduler@node2.supernodexp.hpc, sock=16
02/19/2018 14:18:09;0100;Server@node2;Req;;Type 58 request received from Scheduler@node2.supernodexp.hpc, sock=16
02/19/2018 14:18:09;0100;Server@node2;Req;;Type 20 request received from Scheduler@node2.supernodexp.hpc, sock=16
02/19/2018 14:18:09;0100;Server@node2;Req;;Type 51 request received from Scheduler@node2.supernodexp.hpc, sock=16
02/19/2018 14:18:09;0100;Server@node2;Req;;Type 23 request received from Scheduler@node2.supernodexp.hpc, sock=16
02/19/2018 14:18:09;0008;Server@node2;Job;3529.node2.supernodexp.hpc;Job Run at request of Scheduler@node2.supernodexp.hpc on exec_vnode (node14:ncpus=32:nmics=1:mem=16777216kb)
02/19/2018 14:18:09;0001;Server@node2;Svr;Server@node2;Success (0) in req_runjob2, return value of svr_startjob is 0
02/19/2018 14:18:09;0100;Server@node2;Req;;Type 11 request received from Scheduler@node2.supernodexp.hpc, sock=16
02/19/2018 14:18:09;0008;Server@node2;Job;3557.node2.supernodexp.hpc;Job Modified at request of Scheduler@node2.supernodexp.hpc
02/19/2018 14:26:40;0080;Server@node2;Job;3521.node2.supernodexp.hpc;Obit received momhop:1 serverhop:1 state:4 substate:42
02/19/2018 14:26:41;0010;Server@node2;Job;3521.node2.supernodexp.hpc;Exit_status=2 resources_used.cpupercent=2192 resources_used.cput=06:37:31 resources_used.mem=21805452kb resources_used.ncpus=32 resources_used.vmem=24850764kb resources_used.walltime=00:18:45
02/19/2018 14:26:41;0100;Server@node2;Job;3521.node2.supernodexp.hpc;dequeuing from workq, state 5
02/19/2018 14:26:41;0040;Server@node2;Svr;node2.supernodexp.hpc;Scheduler sent command 2
02/19/2018 14:26:41;0040;Server@node2;Svr;node2.supernodexp.hpc;Scheduler sent command 0
02/19/2018 14:26:41;0100;Server@node2;Req;;Type 21 request received from Scheduler@node2.supernodexp.hpc, sock=16
02/19/2018 14:26:41;0100;Server@node2;Req;;Type 81 request received from Scheduler@node2.supernodexp.hpc, sock=16
02/19/2018 14:26:41;0100;Server@node2;Req;;Type 71 request received from Scheduler@node2.supernodexp.hpc, sock=16
02/19/2018 14:26:41;0100;Server@node2;Req;;Type 58 request received from Scheduler@node2.supernodexp.hpc, sock=16
02/19/2018 14:26:41;0100;Server@node2;Req;;Type 20 request received from Scheduler@node2.supernodexp.hpc, sock=16
02/19/2018 14:26:41;0100;Server@node2;Req;;Type 51 request received from Scheduler@node2.supernodexp.hpc, sock=16
02/19/2018 14:26:42;0100;Server@node2;Req;;Type 23 request received from Scheduler@node2.supernodexp.hpc, sock=16
02/19/2018 14:26:42;0008;Server@node2;Job;3557.node2.supernodexp.hpc;Job Run at request of Scheduler@node2.supernodexp.hpc on exec_vnode (node13:ncpus=32:nmics=1:mem=16777216kb)
02/19/2018 14:26:42;0001;Server@node2;Svr;Server@node2;Success (0) in req_runjob2, return value of svr_startjob is 0
02/19/2018 14:26:42;0100;Server@node2;Req;;Type 11 request received from Scheduler@node2.supernodexp.hpc, sock=16
02/19/2018 14:26:42;0008;Server@node2;Job;3565.node2.supernodexp.hpc;Job Modified at request of Scheduler@node2.supernodexp.hpc
02/19/2018 14:36:30;0080;Server@node2;Job;3529.node2.supernodexp.hpc;Obit received momhop:1 serverhop:1 state:4 substate:42
02/19/2018 14:36:31;0010;Server@node2;Job;3529.node2.supernodexp.hpc;Exit_status=2 resources_used.cpupercent=2117 resources_used.cput=06:14:41 resources_used.mem=21828264kb resources_used.ncpus=32 resources_used.vmem=24548684kb resources_used.walltime=00:18:22
02/19/2018 14:36:31;0100;Server@node2;Job;3529.node2.supernodexp.hpc;dequeuing from workq, state 5
02/19/2018 14:36:31;0040;Server@node2;Svr;node2.supernodexp.hpc;Scheduler sent command 2
02/19/2018 14:36:31;0040;Server@node2;Svr;node2.supernodexp.hpc;Scheduler sent command 0
02/19/2018 14:36:31;0100;Server@node2;Req;;Type 21 request received from Scheduler@node2.supernodexp.hpc, sock=16
02/19/2018 14:36:31;0100;Server@node2;Req;;Type 81 request received from Scheduler@node2.supernodexp.hpc, sock=16
02/19/2018 14:36:31;0100;Server@node2;Req;;Type 71 request received from Scheduler@node2.supernodexp.hpc, sock=16
02/19/2018 14:36:31;0100;Server@node2;Req;;Type 58 request received from Scheduler@node2.supernodexp.hpc, sock=16
02/19/2018 14:36:31;0100;Server@node2;Req;;Type 20 request received from Scheduler@node2.supernodexp.hpc, sock=16
02/19/2018 14:36:31;0100;Server@node2;Req;;Type 51 request received from Scheduler@node2.supernodexp.hpc, sock=16
02/19/2018 14:36:31;0100;Server@node2;Req;;Type 23 request received from Scheduler@node2.supernodexp.hpc, sock=16
02/19/2018 14:36:31;0008;Server@node2;Job;3565.node2.supernodexp.hpc;Job Run at request of Scheduler@node2.supernodexp.hpc on exec_vnode (node14:ncpus=32:nmics=1:mem=16777216kb)
02/19/2018 14:36:31;0001;Server@node2;Svr;Server@node2;Success (0) in req_runjob2, return value of svr_startjob is 0
02/19/2018 14:36:31;0100;Server@node2;Req;;Type 11 request received from Scheduler@node2.supernodexp.hpc, sock=16
02/19/2018 14:36:31;0008;Server@node2;Job;3580.node2.supernodexp.hpc;Job Modified at request of Scheduler@node2.supernodexp.hpc
02/19/2018 14:45:07;0080;Server@node2;Job;3557.node2.supernodexp.hpc;Obit received momhop:1 serverhop:1 state:4 substate:42
02/19/2018 14:45:09;0010;Server@node2;Job;3557.node2.supernodexp.hpc;Exit_status=2 resources_used.cpupercent=2184 resources_used.cput=06:33:44 resources_used.mem=21818360kb resources_used.ncpus=32 resources_used.vmem=24852004kb resources_used.walltime=00:18:25
02/19/2018 14:45:09;0100;Server@node2;Job;3557.node2.supernodexp.hpc;dequeuing from workq, state 5
02/19/2018 14:45:09;0040;Server@node2;Svr;node2.supernodexp.hpc;Scheduler sent command 2
02/19/2018 14:45:09;0040;Server@node2;Svr;node2.supernodexp.hpc;Scheduler sent command 0
02/19/2018 14:45:09;0100;Server@node2;Req;;Type 21 request received from Scheduler@node2.supernodexp.hpc, sock=16
02/19/2018 14:45:09;0100;Server@node2;Req;;Type 81 request received from Scheduler@node2.supernodexp.hpc, sock=16
02/19/2018 14:45:09;0100;Server@node2;Req;;Type 71 request received from Scheduler@node2.supernodexp.hpc, sock=16
02/19/2018 14:45:09;0100;Server@node2;Req;;Type 58 request received from Scheduler@node2.supernodexp.hpc, sock=16
02/19/2018 14:45:09;0100;Server@node2;Req;;Type 20 request received from Scheduler@node2.supernodexp.hpc, sock=16
02/19/2018 14:45:09;0100;Server@node2;Req;;Type 51 request received from Scheduler@node2.supernodexp.hpc, sock=16
02/19/2018 14:45:09;0100;Server@node2;Req;;Type 23 request received from Scheduler@node2.supernodexp.hpc, sock=16
02/19/2018 14:45:09;0008;Server@node2;Job;3580.node2.supernodexp.hpc;Job Run at request of Scheduler@node2.supernodexp.hpc on exec_vnode (node13:ncpus=32:nmics=1:mem=16777216kb)
02/19/2018 14:45:09;0001;Server@node2;Svr;Server@node2;Success (0) in req_runjob2, return value of svr_startjob is 0
02/19/2018 14:45:09;0100;Server@node2;Req;;Type 11 request received from Scheduler@node2.supernodexp.hpc, sock=16
02/19/2018 14:45:09;0008;Server@node2;Job;3581.node2.supernodexp.hpc;Job Modified at request of Scheduler@node2.supernodexp.hpc
02/19/2018 14:54:53;0080;Server@node2;Job;3565.node2.supernodexp.hpc;Obit received momhop:1 serverhop:1 state:4 substate:42
02/19/2018 14:54:54;0010;Server@node2;Job;3565.node2.supernodexp.hpc;Exit_status=2 resources_used.cpupercent=2113 resources_used.cput=06:12:43 resources_used.mem=22168852kb resources_used.ncpus=32 resources_used.vmem=24901840kb resources_used.walltime=00:18:21
02/19/2018 14:54:54;0100;Server@node2;Job;3565.node2.supernodexp.hpc;dequeuing from workq, state 5
02/19/2018 14:54:54;0040;Server@node2;Svr;node2.supernodexp.hpc;Scheduler sent command 2
02/19/2018 14:54:54;0040;Server@node2;Svr;node2.supernodexp.hpc;Scheduler sent command 0
02/19/2018 14:54:54;0100;Server@node2;Req;;Type 21 request received from Scheduler@node2.supernodexp.hpc, sock=16
02/19/2018 14:54:54;0100;Server@node2;Req;;Type 81 request received from Scheduler@node2.supernodexp.hpc, sock=16
02/19/2018 14:54:54;0100;Server@node2;Req;;Type 71 request received from Scheduler@node2.supernodexp.hpc, sock=16
02/19/2018 14:54:54;0100;Server@node2;Req;;Type 58 request received from Scheduler@node2.supernodexp.hpc, sock=16
02/19/2018 14:54:54;0100;Server@node2;Req;;Type 20 request received from Scheduler@node2.supernodexp.hpc, sock=16
02/19/2018 14:54:54;0100;Server@node2;Req;;Type 51 request received from Scheduler@node2.supernodexp.hpc, sock=16
02/19/2018 14:54:54;0100;Server@node2;Req;;Type 23 request received from Scheduler@node2.supernodexp.hpc, sock=16
02/19/2018 14:54:54;0008;Server@node2;Job;3581.node2.supernodexp.hpc;Job Run at request of Scheduler@node2.supernodexp.hpc on exec_vnode (node14:ncpus=32:nmics=1:mem=16777216kb)
02/19/2018 14:54:54;0001;Server@node2;Svr;Server@node2;Success (0) in req_runjob2, return value of svr_startjob is 0
02/19/2018 14:54:54;0100;Server@node2;Req;;Type 11 request received from Scheduler@node2.supernodexp.hpc, sock=16
02/19/2018 14:54:54;0008;Server@node2;Job;3589.node2.supernodexp.hpc;Job Modified at request of Scheduler@node2.supernodexp.hpc
02/19/2018 15:03:39;0080;Server@node2;Job;3580.node2.supernodexp.hpc;Obit received momhop:1 serverhop:1 state:4 substate:42
02/19/2018 15:03:40;0010;Server@node2;Job;3580.node2.supernodexp.hpc;Exit_status=2 resources_used.cpupercent=2244 resources_used.cput=06:39:20 resources_used.mem=21837044kb resources_used.ncpus=32 resources_used.vmem=24865552kb resources_used.walltime=00:18:31
02/19/2018 15:03:40;0100;Server@node2;Job;3580.node2.supernodexp.hpc;dequeuing from workq, state 5
02/19/2018 15:03:40;0040;Server@node2;Svr;node2.supernodexp.hpc;Scheduler sent command 2
02/19/2018 15:03:40;0040;Server@node2;Svr;node2.supernodexp.hpc;Scheduler sent command 0
02/19/2018 15:03:40;0100;Server@node2;Req;;Type 21 request received from Scheduler@node2.supernodexp.hpc, sock=16
02/19/2018 15:03:40;0100;Server@node2;Req;;Type 81 request received from Scheduler@node2.supernodexp.hpc, sock=16
02/19/2018 15:03:40;0100;Server@node2;Req;;Type 71 request received from Scheduler@node2.supernodexp.hpc, sock=16
02/19/2018 15:03:40;0100;Server@node2;Req;;Type 58 request received from Scheduler@node2.supernodexp.hpc, sock=16
02/19/2018 15:03:41;0100;Server@node2;Req;;Type 20 request received from Scheduler@node2.supernodexp.hpc, sock=16
02/19/2018 15:03:41;0100;Server@node2;Req;;Type 51 request received from Scheduler@node2.supernodexp.hpc, sock=16
02/19/2018 15:03:41;0100;Server@node2;Req;;Type 23 request received from Scheduler@node2.supernodexp.hpc, sock=16
02/19/2018 15:03:41;0008;Server@node2;Job;3589.node2.supernodexp.hpc;Job Run at request of Scheduler@node2.supernodexp.hpc on exec_vnode (node13:ncpus=32:nmics=1:mem=16777216kb)
02/19/2018 15:03:41;0001;Server@node2;Svr;Server@node2;Success (0) in req_runjob2, return value of svr_startjob is 0
02/19/2018 15:03:41;0100;Server@node2;Req;;Type 11 request received from Scheduler@node2.supernodexp.hpc, sock=16
02/19/2018 15:03:41;0008;Server@node2;Job;3619.node2.supernodexp.hpc;Job Modified at request of Scheduler@node2.supernodexp.hpc
02/19/2018 15:13:26;0080;Server@node2;Job;3581.node2.supernodexp.hpc;Obit received momhop:1 serverhop:1 state:4 substate:42
02/19/2018 15:13:27;0010;Server@node2;Job;3581.node2.supernodexp.hpc;Exit_status=2 resources_used.cpupercent=2101 resources_used.cput=06:13:27 resources_used.mem=22018980kb resources_used.ncpus=32 resources_used.vmem=24727220kb resources_used.walltime=00:18:32
02/19/2018 15:13:27;0100;Server@node2;Job;3581.node2.supernodexp.hpc;dequeuing from workq, state 5
02/19/2018 15:13:27;0040;Server@node2;Svr;node2.supernodexp.hpc;Scheduler sent command 2
02/19/2018 15:13:27;0040;Server@node2;Svr;node2.supernodexp.hpc;Scheduler sent command 0
02/19/2018 15:13:27;0100;Server@node2;Req;;Type 21 request received from Scheduler@node2.supernodexp.hpc, sock=16
02/19/2018 15:13:27;0100;Server@node2;Req;;Type 81 request received from Scheduler@node2.supernodexp.hpc, sock=16
02/19/2018 15:13:27;0100;Server@node2;Req;;Type 71 request received from Scheduler@node2.supernodexp.hpc, sock=16
02/19/2018 15:13:27;0100;Server@node2;Req;;Type 58 request received from Scheduler@node2.supernodexp.hpc, sock=16
02/19/2018 15:13:27;0100;Server@node2;Req;;Type 20 request received from Scheduler@node2.supernodexp.hpc, sock=16
02/19/2018 15:13:27;0100;Server@node2;Req;;Type 51 request received from Scheduler@node2.supernodexp.hpc, sock=16
02/19/2018 15:13:28;0100;Server@node2;Req;;Type 23 request received from Scheduler@node2.supernodexp.hpc, sock=16
02/19/2018 15:13:28;0008;Server@node2;Job;3619.node2.supernodexp.hpc;Job Run at request of Scheduler@node2.supernodexp.hpc on exec_vnode (node14:ncpus=32:nmics=1:mem=16777216kb)
02/19/2018 15:13:28;0001;Server@node2;Svr;Server@node2;Success (0) in req_runjob2, return value of svr_startjob is 0
02/19/2018 15:13:28;0100;Server@node2;Req;;Type 11 request received from Scheduler@node2.supernodexp.hpc, sock=16
02/19/2018 15:13:28;0008;Server@node2;Job;3622.node2.supernodexp.hpc;Job Modified at request of Scheduler@node2.supernodexp.hpc
02/19/2018 15:22:01;0080;Server@node2;Job;3589.node2.supernodexp.hpc;Obit received momhop:1 serverhop:1 state:4 substate:42
02/19/2018 15:22:03;0010;Server@node2;Job;3589.node2.supernodexp.hpc;Exit_status=2 resources_used.cpupercent=2156 resources_used.cput=06:27:01 resources_used.mem=21831408kb resources_used.ncpus=32 resources_used.vmem=24852744kb resources_used.walltime=00:18:20
02/19/2018 15:22:03;0100;Server@node2;Job;3589.node2.supernodexp.hpc;dequeuing from workq, state 5
02/19/2018 15:22:03;0040;Server@node2;Svr;node2.supernodexp.hpc;Scheduler sent command 2
02/19/2018 15:22:03;0040;Server@node2;Svr;node2.supernodexp.hpc;Scheduler sent command 0
02/19/2018 15:22:03;0100;Server@node2;Req;;Type 21 request received from Scheduler@node2.supernodexp.hpc, sock=16
02/19/2018 15:22:03;0100;Server@node2;Req;;Type 81 request received from Scheduler@node2.supernodexp.hpc, sock=16
02/19/2018 15:22:03;0100;Server@node2;Req;;Type 71 request received from Scheduler@node2.supernodexp.hpc, sock=16
02/19/2018 15:22:03;0100;Server@node2;Req;;Type 58 request received from Scheduler@node2.supernodexp.hpc, sock=16
02/19/2018 15:22:03;0100;Server@node2;Req;;Type 20 request received from Scheduler@node2.supernodexp.hpc, sock=16
02/19/2018 15:22:03;0100;Server@node2;Req;;Type 51 request received from Scheduler@node2.supernodexp.hpc, sock=16
02/19/2018 15:22:03;0100;Server@node2;Req;;Type 23 request received from Scheduler@node2.supernodexp.hpc, sock=16
02/19/2018 15:22:03;0008;Server@node2;Job;3622.node2.supernodexp.hpc;Job Run at request of Scheduler@node2.supernodexp.hpc on exec_vnode (node13:ncpus=32:nmics=1:mem=16777216kb)
02/19/2018 15:22:03;0001;Server@node2;Svr;Server@node2;Success (0) in req_runjob2, return value of svr_startjob is 0
02/19/2018 15:25:59;0100;Server@node2;Req;;Type 0 request received from ctminh@node2.supernodexp.hpc, sock=16
02/19/2018 15:25:59;0100;Server@node2;Req;;Type 49 request received from ctminh@node2.supernodexp.hpc, sock=20
02/19/2018 15:25:59;0100;Server@node2;Req;;Type 21 request received from ctminh@node2.supernodexp.hpc, sock=16
02/19/2018 15:25:59;0100;Server@node2;Req;;Type 19 request received from ctminh@node2.supernodexp.hpc, sock=16
02/19/2018 15:31:38;0080;Server@node2;Job;3619.node2.supernodexp.hpc;Obit received momhop:1 serverhop:1 state:4 substate:42
02/19/2018 15:31:41;0010;Server@node2;Job;3619.node2.supernodexp.hpc;Exit_status=2 resources_used.cpupercent=2083 resources_used.cput=06:11:41 resources_used.mem=22173392kb resources_used.ncpus=32 resources_used.vmem=24895180kb resources_used.walltime=00:18:11
02/19/2018 15:31:41;0100;Server@node2;Job;3619.node2.supernodexp.hpc;dequeuing from workq, state 5
02/19/2018 15:31:41;0040;Server@node2;Svr;node2.supernodexp.hpc;Scheduler sent command 2
02/19/2018 15:31:41;0040;Server@node2;Svr;node2.supernodexp.hpc;Scheduler sent command 0
02/19/2018 15:31:41;0100;Server@node2;Req;;Type 21 request received from Scheduler@node2.supernodexp.hpc, sock=16
02/19/2018 15:31:41;0100;Server@node2;Req;;Type 81 request received from Scheduler@node2.supernodexp.hpc, sock=16
02/19/2018 15:31:41;0100;Server@node2;Req;;Type 71 request received from Scheduler@node2.supernodexp.hpc, sock=16
02/19/2018 15:31:41;0100;Server@node2;Req;;Type 58 request received from Scheduler@node2.supernodexp.hpc, sock=16
02/19/2018 15:31:41;0100;Server@node2;Req;;Type 20 request received from Scheduler@node2.supernodexp.hpc, sock=16
02/19/2018 15:31:41;0100;Server@node2;Req;;Type 51 request received from Scheduler@node2.supernodexp.hpc, sock=16
02/19/2018 15:40:29;0080;Server@node2;Job;3622.node2.supernodexp.hpc;Obit received momhop:1 serverhop:1 state:4 substate:42
02/19/2018 15:40:31;0010;Server@node2;Job;3622.node2.supernodexp.hpc;Exit_status=2 resources_used.cpupercent=2212 resources_used.cput=06:35:42 resources_used.mem=21881140kb resources_used.ncpus=32 resources_used.vmem=24888864kb resources_used.walltime=00:18:27
02/19/2018 15:40:31;0100;Server@node2;Job;3622.node2.supernodexp.hpc;dequeuing from workq, state 5
02/19/2018 15:40:31;0040;Server@node2;Svr;node2.supernodexp.hpc;Scheduler sent command 2
02/19/2018 15:40:31;0040;Server@node2;Svr;node2.supernodexp.hpc;Scheduler sent command 0
02/19/2018 15:40:31;0100;Server@node2;Req;;Type 21 request received from Scheduler@node2.supernodexp.hpc, sock=16
02/19/2018 15:40:31;0100;Server@node2;Req;;Type 81 request received from Scheduler@node2.supernodexp.hpc, sock=16
02/19/2018 15:40:31;0100;Server@node2;Req;;Type 71 request received from Scheduler@node2.supernodexp.hpc, sock=16
02/19/2018 15:40:31;0100;Server@node2;Req;;Type 58 request received from Scheduler@node2.supernodexp.hpc, sock=16
02/19/2018 15:40:31;0100;Server@node2;Req;;Type 20 request received from Scheduler@node2.supernodexp.hpc, sock=16
02/19/2018 15:40:31;0100;Server@node2;Req;;Type 51 request received from Scheduler@node2.supernodexp.hpc, sock=16
02/19/2018 15:50:31;0040;Server@node2;Svr;node2.supernodexp.hpc;Scheduler sent command 3
02/19/2018 15:50:31;0040;Server@node2;Svr;node2.supernodexp.hpc;Scheduler sent command 0
02/19/2018 15:50:31;0100;Server@node2;Req;;Type 21 request received from Scheduler@node2.supernodexp.hpc, sock=16
02/19/2018 15:50:31;0100;Server@node2;Req;;Type 81 request received from Scheduler@node2.supernodexp.hpc, sock=16
02/19/2018 15:50:31;0100;Server@node2;Req;;Type 71 request received from Scheduler@node2.supernodexp.hpc, sock=16
02/19/2018 15:50:31;0100;Server@node2;Req;;Type 58 request received from Scheduler@node2.supernodexp.hpc, sock=16
02/19/2018 15:50:31;0100;Server@node2;Req;;Type 20 request received from Scheduler@node2.supernodexp.hpc, sock=16
02/19/2018 15:50:31;0100;Server@node2;Req;;Type 51 request received from Scheduler@node2.supernodexp.hpc, sock=16
02/19/2018 15:57:13;0100;Server@node2;Req;;Type 0 request received from ctminh@node2.supernodexp.hpc, sock=16
02/19/2018 15:57:13;0100;Server@node2;Req;;Type 49 request received from ctminh@node2.supernodexp.hpc, sock=20
02/19/2018 15:57:13;0100;Server@node2;Req;;Type 21 request received from ctminh@node2.supernodexp.hpc, sock=16
02/19/2018 15:57:13;0100;Server@node2;Req;;Type 19 request received from ctminh@node2.supernodexp.hpc, sock=16
02/19/2018 16:00:31;0040;Server@node2;Svr;node2.supernodexp.hpc;Scheduler sent command 3
02/19/2018 16:00:31;0040;Server@node2;Svr;node2.supernodexp.hpc;Scheduler sent command 0
02/19/2018 16:00:31;0100;Server@node2;Req;;Type 21 request received from Scheduler@node2.supernodexp.hpc, sock=16
02/19/2018 16:00:31;0100;Server@node2;Req;;Type 81 request received from Scheduler@node2.supernodexp.hpc, sock=16
02/19/2018 16:00:31;0100;Server@node2;Req;;Type 71 request received from Scheduler@node2.supernodexp.hpc, sock=16
02/19/2018 16:00:31;0100;Server@node2;Req;;Type 58 request received from Scheduler@node2.supernodexp.hpc, sock=16
02/19/2018 16:00:31;0100;Server@node2;Req;;Type 20 request received from Scheduler@node2.supernodexp.hpc, sock=16
02/19/2018 16:00:31;0100;Server@node2;Req;;Type 51 request received from Scheduler@node2.supernodexp.hpc, sock=16
02/19/2018 16:10:31;0040;Server@node2;Svr;node2.supernodexp.hpc;Scheduler sent command 3
02/19/2018 16:10:31;0040;Server@node2;Svr;node2.supernodexp.hpc;Scheduler sent command 0
02/19/2018 16:10:31;0100;Server@node2;Req;;Type 21 request received from Scheduler@node2.supernodexp.hpc, sock=16
02/19/2018 16:10:31;0100;Server@node2;Req;;Type 81 request received from Scheduler@node2.supernodexp.hpc, sock=16
02/19/2018 16:10:31;0100;Server@node2;Req;;Type 71 request received from Scheduler@node2.supernodexp.hpc, sock=16
02/19/2018 16:10:31;0100;Server@node2;Req;;Type 58 request received from Scheduler@node2.supernodexp.hpc, sock=16
02/19/2018 16:10:31;0100;Server@node2;Req;;Type 20 request received from Scheduler@node2.supernodexp.hpc, sock=16
02/19/2018 16:10:31;0100;Server@node2;Req;;Type 51 request received from Scheduler@node2.supernodexp.hpc, sock=16
02/19/2018 16:14:55;0100;Server@node2;Req;;Type 0 request received from root@node2.supernodexp.hpc, sock=16
02/19/2018 16:14:55;0100;Server@node2;Req;;Type 49 request received from root@node2.supernodexp.hpc, sock=20
02/19/2018 16:15:08;0100;Server@node2;Req;;Type 9 request received from root@node2.supernodexp.hpc, sock=16
02/19/2018 16:15:08;0004;Server@node2;Svr;Server@node2;attributes set:  at request of root@node2.supernodexp.hpc
02/19/2018 16:15:08;0004;Server@node2;Svr;Server@node2;attributes set: job_sort_formula = walltime
02/19/2018 16:15:17;0100;Server@node2;Req;;Type 0 request received from root@node2.supernodexp.hpc, sock=16
02/19/2018 16:15:17;0100;Server@node2;Req;;Type 49 request received from root@node2.supernodexp.hpc, sock=20
02/19/2018 16:15:17;0100;Server@node2;Req;;Type 21 request received from root@node2.supernodexp.hpc, sock=16
02/19/2018 16:15:17;0100;Server@node2;Req;;Type 0 request received from root@node2.supernodexp.hpc, sock=16
02/19/2018 16:15:17;0100;Server@node2;Req;;Type 49 request received from root@node2.supernodexp.hpc, sock=20
02/19/2018 16:15:17;0100;Server@node2;Req;;Type 17 request received from root@node2.supernodexp.hpc, sock=16
02/19/2018 16:15:17;0086;Server@node2;Svr;Server@node2;Shutdown request from root@node2.supernodexp.hpc 
02/19/2018 16:15:17;0086;Server@node2;Svr;Server@node2;Starting to shutdown the server, type is Quick
02/19/2018 16:15:17;0002;Server@node2;Svr;Server@node2;Stopping PBS dataservice
02/19/2018 16:15:21;0100;Server@node2;Svr;Server@node2;--> Stopping Python interpreter <--
02/19/2018 16:15:21;0d80;Server@node2;TPP;Server@node2(Main Thread);Shutting down TPP transport Layer
02/19/2018 16:15:21;0d80;Server@node2;TPP;Server@node2(Thread 0);Thrd exiting, had 1 connections
02/19/2018 16:15:21;0002;Server@node2;Svr;Server@node2;Server shutdown completed
02/19/2018 16:15:21;0002;Server@node2;Svr;Log;Log closed
02/19/2018 16:15:23;0002;Server@node2;Svr;Log;Log opened
02/19/2018 16:15:23;0002;Server@node2;Svr;Server@node2;pbs_version=14.0.1
02/19/2018 16:15:23;0002;Server@node2;Svr;Server@node2;pbs_build=mach=N/A:security=N/A:configure_args=N/A
02/19/2018 16:15:23;0002;Server@node2;Svr;Server@node2;hostname=node2.supernodexp.hpc;pbs_leaf_name=N/A;pbs_mom_node_name=N/A
02/19/2018 16:15:23;0002;Server@node2;Svr;Server@node2;ipv4 interface lo: localhost localhost.localdomain localhost4 localhost4.localdomain4 
02/19/2018 16:15:23;0002;Server@node2;Svr;Server@node2;ipv4 interface br0: node2.supernodexp.hpc node2 supernodexp-cn02 
02/19/2018 16:15:23;0002;Server@node2;Svr;Server@node2;ipv4 interface ib0: node2.supernodexp.hpc 
02/19/2018 16:15:23;0002;Server@node2;Svr;Server@node2;ipv4 interface docker0: node2.supernodexp.hpc 
02/19/2018 16:15:23;0002;Server@node2;Svr;Server@node2;ipv4 interface virbr0: node2.supernodexp.hpc 
02/19/2018 16:15:23;0002;Server@node2;Svr;Server@node2;ipv6 interface lo: localhost localhost.localdomain localhost6 localhost6.localdomain6 
02/19/2018 16:15:23;0002;Server@node2;Svr;Server@node2;ipv6 interface eno49: node2.supernodexp.hpc 
02/19/2018 16:15:23;0002;Server@node2;Svr;Server@node2;ipv6 interface br0: node2.supernodexp.hpc 
02/19/2018 16:15:23;0002;Server@node2;Svr;Server@node2;ipv6 interface ib0: node2.supernodexp.hpc 
02/19/2018 16:15:23;0002;Server@node2;Svr;Server@node2;ipv6 interface veth1pl7177: node2.supernodexp.hpc 
02/19/2018 16:15:23;0006;Server@node2;Fil;Server@node2;Version 14.0.1, started, initialization type = 1
02/19/2018 16:15:23;0002;Server@node2;Svr;Server@node2;Starting PBS dataservice
02/19/2018 16:15:29;0002;Server@node2;Svr;Server@node2;connected to PBS dataservice@node2.supernodexp.hpc
02/19/2018 16:15:29;0086;Server@node2;Svr;pbs_python_ext_quick_start_interpreter;--> Python Interpreter quick started, compiled with version:'2.7.5' <--
02/19/2018 16:15:29;0086;Server@node2;Svr;pbs_python_ext_quick_start_interpreter;--> Inserted Altair PBS Python modules dir '/opt/pbs/lib/python/altair' <--
02/19/2018 16:15:29;0002;Server@node2;Fil;Server@node2;PBS Server hostname is node2.supernodexp.hpc, Server-id is 1
02/19/2018 16:15:29;0002;Server@node2;n/a;setup_env;read environment from /var/spool/pbs/pbs_environment
02/19/2018 16:15:29;0004;Server@node2;Svr;Server@node2;node_fail_requeue value changed to 310
02/19/2018 16:15:29;0004;Server@node2;Svr;Server@node2;Licenses valid for 10000000 Floating hosts
02/19/2018 16:15:29;0002;Server@node2;Svr;Act;Account file /var/spool/pbs/server_priv/accounting/20180219 opened
02/19/2018 16:15:29;0086;Server@node2;Svr;Server@node2;Recovered queue workq
02/19/2018 16:15:29;0002;Server@node2;Svr;Server@node2;Expected 1, recovered 1 queues
02/19/2018 16:15:29;0080;Server@node2;Svr;Server@node2;No jobs to open
02/19/2018 16:15:29;0086;Server@node2;Svr;Server@node2;Found hook PBS_translate_mpp type=pbs
02/19/2018 16:15:29;0086;Server@node2;Svr;Server@node2;Found hook stop_docker type=site
02/19/2018 16:15:29;0086;Server@node2;Svr;Server@node2;Found hook launch_docker type=site
02/19/2018 16:15:29;0086;Server@node2;Svr;Server@node2;Found hook evaluation type=site
02/19/2018 16:15:29;0080;Server@node2;Hook;print_hook;ALLHOOKS hook[0] = {PBS_translate_mpp, order=1000, type=1, enabled=0 user=0, debug=(0) fail_action=(1), event=(queuejob,resvsub), alarm=90, freq=120}
02/19/2018 16:15:29;0080;Server@node2;Hook;print_hook;ALLHOOKS hook[1] = {stop_docker, order=1, type=0, enabled=1 user=0, debug=(0) fail_action=(1), event=(execjob_end), alarm=30, freq=120}
02/19/2018 16:15:29;0080;Server@node2;Hook;print_hook;ALLHOOKS hook[2] = {launch_docker, order=1, type=0, enabled=1 user=0, debug=(0) fail_action=(1), event=(execjob_launch), alarm=30, freq=120}
02/19/2018 16:15:29;0080;Server@node2;Hook;print_hook;ALLHOOKS hook[3] = {evaluation, order=1, type=0, enabled=1 user=0, debug=(0) fail_action=(1), event=(queuejob), alarm=30, freq=120}
02/19/2018 16:15:29;0080;Server@node2;Hook;print_hook;queuejob hook[0] = {evaluation, order=1, type=0, enabled=1 user=0, debug=(0) fail_action=(1), event=(queuejob), alarm=30, freq=120}
02/19/2018 16:15:29;0080;Server@node2;Hook;print_hook;queuejob hook[1] = {PBS_translate_mpp, order=1000, type=1, enabled=0 user=0, debug=(0) fail_action=(1), event=(queuejob,resvsub), alarm=90, freq=120}
02/19/2018 16:15:29;0080;Server@node2;Hook;print_hook;resvsub hook[0] = {PBS_translate_mpp, order=1000, type=1, enabled=0 user=0, debug=(0) fail_action=(1), event=(queuejob,resvsub), alarm=90, freq=120}
02/19/2018 16:15:29;0086;Server@node2;Svr;pbs_python_ext_quick_shutdown_interpreter;--> Stopping Python interpreter <--
02/19/2018 16:15:29;0d80;Server@node2;TPP;Server@node2(Main Thread);TPP set to use reserved port authentication
02/19/2018 16:15:29;0d80;Server@node2;TPP;Server@node2(Main Thread);Initializing TPP transport Layer
02/19/2018 16:15:29;0d80;Server@node2;TPP;Server@node2(Main Thread);Max files allowed = 1024
02/19/2018 16:15:29;0c06;Server@node2;TPP;Server@node2(Main Thread);Max files too low - you may want to increase it.
02/19/2018 16:15:29;0d80;Server@node2;TPP;Server@node2(Main Thread);TPP initialization done
02/19/2018 16:15:29;0c06;Server@node2;TPP;Server@node2(Main Thread);Single pbs_comm configured, TPP Fault tolerant mode disabled
02/19/2018 16:15:29;0d80;Server@node2;TPP;Server@node2(Main Thread);Connecting to pbs_comm node2.supernodexp.hpc
02/19/2018 16:15:29;0002;Server@node2;Svr;Server@node2;Server pid = 4807 ready;  using ports Server:15001 Scheduler:15004 MOM:15002 RM:15003
02/19/2018 16:15:29;0c06;Server@node2;TPP;Server@node2(Thread 0);Registering address 10.1.1.4:15001 to pbs_comm
02/19/2018 16:15:29;0c06;Server@node2;TPP;Server@node2(Thread 0);Connected to pbs_comm node2.supernodexp.hpc
02/19/2018 16:15:29;0100;Server@node2;Svr;Server@node2;--> Python Interpreter started, compiled with version:'2.7.5' <--
02/19/2018 16:15:29;0100;Server@node2;Svr;Server@node2;sys.modules= {'pbs.v1._svr_types': <module 'pbs.v1._svr_types' from '/opt/pbs/lib/python/altair/pbs/v1/_svr_types.pyo'>, 'copy_reg': <module 'copy_reg' from '/usr/lib64/python2.7/copy_reg.pyo'>, 'pbs.v1._pbs_v1': None, '__main__': <module '__main__' (built-in)>, '__builtin__': <module '__builtin__' (built-in)>, '_pbs_v1.svr_types': <module '_pbs_v1.svr_types' (built-in)>, 'encodings': <module 'encodings' from '/usr/lib64/python2.7/encodings/__init__.pyo'>, 'encodings.encodings': None, 'abc': <module 'abc' from '/usr/lib64/python2.7/abc.pyo'>, 'pbs._pbs_v1': None, 'posixpath': <module 'posixpath' from '/usr/lib64/python2.7/posixpath.pyo'>, '_weakrefset': <module '_weakrefset' from '/usr/lib64/python2.7/_weakrefset.pyo'>, 'pbs.v1': <module 'pbs.v1' from '/opt/pbs/lib/python/altair/pbs/v1/__init__.pyo'>, 'errno': <module 'errno' (built-in)>, 'encodings.codecs': None, 'pbs.v1._export_types': <module 'pbs.v1._export_types' from '/opt/pbs/lib/python/altair/pbs/v1/_export_types.pyo'>, 'pbs.v1.os': None, '_abcoll': <module '_abcoll' from '/usr/lib64/python2.7/_abcoll.pyo'>, 'os.path': <module 'posixpath' from '/usr/lib64/python2.7/posixpath.pyo'>, 'UserDict': <module 'UserDict' from '/usr/lib64/python2.7/UserDict.pyo'>, '_warnings': <module '_warnings' (built-in)>, 'genericpath': <module 'genericpath' from '/usr/lib64/python2.7/genericpath.pyo'>, 'stat': <module 'stat' from '/usr/lib64/python2.7/stat.pyo'>, 'zipimport': <module 'zipimport' (built-in)>, 'encodings.__builtin__': None, 'pbs.pbs': None, 'warnings': <module 'warnings' from '/usr/lib64/python2.7/warnings.pyo'>, '_codecs': <module '_codecs' (built-in)>, 'encodings.ascii': <module 'encodings.ascii' from '/usr/lib64/python2.7/encodings/ascii.pyo'>, 'sys': <module 'sys' (built-in)>, 'pbs.v1._base_types': <module 'pbs.v1._base_types' from '/opt/pbs/lib/python/altair/pbs/v1/_base_types.pyo'>, 'pbs.v1.sys': None, 'codecs': <module 'codecs' from '/usr/lib64/python2.7/codecs.pyo'>, 'types': <module 'types' from '/usr/lib64/python2.7/types.pyo'>, 'pbs': <module 'pbs' from '/opt/pbs/lib/python/altair/pbs/__init__.pyo'>, 'os': <module 'os' from '/usr/lib64/python2.7/os.pyo'>, 'signal': <module 'signal' (built-in)>, 'linecache': <module 'linecache' from '/usr/lib64/python2.7/linecache.pyo'>, '_pbs_v1': <module '_pbs_v1' (built-in)>, 'posix': <module 'posix' (built-in)>, 'encodings.aliases': <module 'encodings.aliases' from '/usr/lib64/python2.7/encodings/aliases.pyo'>, 'exceptions': <module 'exceptions' (built-in)>, 'pbs.v1._exc_types': <module 'pbs.v1._exc_types' from '/opt/pbs/lib/python/altair/pbs/v1/_exc_types.pyo'>, '_weakref': <module '_weakref' (built-in)>}
02/19/2018 16:15:29;0106;Server@node2;Svr;Server@node2;BEGIN setting up all resource attributes 
02/19/2018 16:15:29;0106;Server@node2;Svr;Server@node2;DONE setting up all resource attributes, number set <51>
02/19/2018 16:15:29;0106;Server@node2;Svr;Server@node2;BEGIN setting up all queue attributes 
02/19/2018 16:15:29;0106;Server@node2;Svr;Server@node2;DONE setting up all queue attributes, number set <55>
02/19/2018 16:15:29;0106;Server@node2;Svr;Server@node2;BEGIN setting up all job attributes 
02/19/2018 16:15:29;0106;Server@node2;Svr;Server@node2;DONE setting up all job attributes, number set <94>
02/19/2018 16:15:29;0106;Server@node2;Svr;Server@node2;BEGIN setting up all server attributes 
02/19/2018 16:15:29;0106;Server@node2;Svr;Server@node2;DONE setting up all server attributes, number set <88>
02/19/2018 16:15:29;0106;Server@node2;Svr;Server@node2;BEGIN setting up all reservation attributes 
02/19/2018 16:15:29;0106;Server@node2;Svr;Server@node2;DONE setting up all reservation attributes, number set <43>
02/19/2018 16:15:29;0106;Server@node2;Svr;Server@node2;BEGIN setting up all vnode attributes 
02/19/2018 16:15:29;0106;Server@node2;Svr;Server@node2;DONE setting up all vnode attributes, number set <28>
02/19/2018 16:15:29;0040;Server@node2;Svr;node2.supernodexp.hpc;Scheduler sent command 10
02/19/2018 16:15:29;0040;Server@node2;Svr;node2.supernodexp.hpc;Scheduler sent command 0
02/19/2018 16:15:29;0d80;Server@node2;TPP;Server@node2(Main Thread);net restore handler called
02/19/2018 16:15:29;0100;Server@node2;Req;;Type 9 request received from Scheduler@node2.supernodexp.hpc, sock=16
02/19/2018 16:15:29;0004;Server@node2;Sched;Server@node2;attributes set:  at request of Scheduler@node2.supernodexp.hpc
02/19/2018 16:15:29;0004;Server@node2;Sched;Server@node2;attributes set: sched_host = node2.supernodexp.hpc
02/19/2018 16:15:29;0004;Server@node2;Sched;Server@node2;attributes set: pbs_version = 14.0.1
02/19/2018 16:15:29;0100;Server@node2;Req;;Type 82 request received from Scheduler@node2.supernodexp.hpc, sock=16
02/19/2018 16:15:29;0100;Server@node2;Req;;Type 21 request received from Scheduler@node2.supernodexp.hpc, sock=16
02/19/2018 16:15:29;0100;Server@node2;Req;;Type 81 request received from Scheduler@node2.supernodexp.hpc, sock=16
02/19/2018 16:15:29;0100;Server@node2;Req;;Type 71 request received from Scheduler@node2.supernodexp.hpc, sock=16
02/19/2018 16:15:29;0100;Server@node2;Req;;Type 58 request received from Scheduler@node2.supernodexp.hpc, sock=16
02/19/2018 16:15:29;0100;Server@node2;Req;;Type 20 request received from Scheduler@node2.supernodexp.hpc, sock=16
02/19/2018 16:15:29;0100;Server@node2;Req;;Type 51 request received from Scheduler@node2.supernodexp.hpc, sock=16
02/19/2018 16:15:32;0d80;Server@node2;TPP;handle_incoming_data(Thread 0);Increased scratch size for tfd=15 to 16384
02/19/2018 16:15:32;0d80;Server@node2;TPP;handle_incoming_data(Thread 0);Increased scratch size for tfd=15 to 24576
02/19/2018 16:15:32;0d80;Server@node2;TPP;handle_incoming_data(Thread 0);Increased scratch size for tfd=15 to 32768
02/19/2018 16:15:32;0d80;Server@node2;TPP;handle_incoming_data(Thread 0);Increased scratch size for tfd=15 to 40960
02/19/2018 16:15:32;0d80;Server@node2;TPP;handle_incoming_data(Thread 0);Increased scratch size for tfd=15 to 49152
02/19/2018 16:15:32;0002;Server@node2;Node;node14.supernodexp.hpc;update2 state:0 ncpus:48
02/19/2018 16:15:32;0002;Server@node2;Node;node14.supernodexp.hpc;Mom reporting 1 vnodes as of Sun Feb 18 19:18:22 2018
02/19/2018 16:15:32;0002;Server@node2;Node;node14.supernodexp.hpc;node up
02/19/2018 16:15:32;0002;Server@node2;Node;10.1.1.15;update2 state:0 ncpus:48
02/19/2018 16:15:32;0002;Server@node2;Node;10.1.1.15;Mom reporting 1 vnodes as of Mon Feb 19 02:18:32 2018
02/19/2018 16:15:32;0002;Server@node2;Node;10.1.1.15;node up
02/19/2018 16:16:33;0002;Server@node2;Node;10.1.1.15;node down: communication closed
02/19/2018 16:16:34;0002;Server@node2;Node;10.1.1.15;Mom restarted on host
02/19/2018 16:16:34;0002;Server@node2;Node;10.1.1.15;update2 state:0 ncpus:48
02/19/2018 16:16:34;0002;Server@node2;Node;10.1.1.15;Mom reporting 1 vnodes as of Mon Feb 19 23:16:31 2018
02/19/2018 16:16:34;0002;Server@node2;Node;10.1.1.15;node up
02/19/2018 16:16:38;0d80;Server@node2;TPP;Server@node2(Thread 0);Received UPDATE from pbs_comm
02/19/2018 16:16:38;0d80;Server@node2;TPP;Server@node2(Main Thread);net restore handler called
02/19/2018 16:16:46;0002;Server@node2;Node;node14.supernodexp.hpc;node down: communication closed
02/19/2018 16:16:48;0002;Server@node2;Node;node14.supernodexp.hpc;Mom restarted on host
02/19/2018 16:16:48;0002;Server@node2;Node;node14.supernodexp.hpc;update2 state:0 ncpus:48
02/19/2018 16:16:48;0002;Server@node2;Node;node14.supernodexp.hpc;Mom reporting 1 vnodes as of Mon Feb 19 16:16:48 2018
02/19/2018 16:16:48;0002;Server@node2;Node;node14.supernodexp.hpc;node up
02/19/2018 16:16:52;0d80;Server@node2;TPP;Server@node2(Thread 0);Received UPDATE from pbs_comm
02/19/2018 16:16:52;0d80;Server@node2;TPP;Server@node2(Main Thread);net restore handler called
02/19/2018 16:17:01;0100;Server@node2;Req;;Type 0 request received from root@node2.supernodexp.hpc, sock=16
02/19/2018 16:17:01;0100;Server@node2;Req;;Type 49 request received from root@node2.supernodexp.hpc, sock=17
02/19/2018 16:17:06;0100;Server@node2;Req;;Type 82 request received from root@node2.supernodexp.hpc, sock=16
02/19/2018 16:17:06;0100;Server@node2;Req;;Type 20 request received from root@node2.supernodexp.hpc, sock=16
02/19/2018 16:17:06;0100;Server@node2;Req;;Type 71 request received from root@node2.supernodexp.hpc, sock=16
02/19/2018 16:17:06;0100;Server@node2;Req;;Type 21 request received from root@node2.supernodexp.hpc, sock=16
02/19/2018 16:17:48;0100;Server@node2;Req;;Type 0 request received from ctminh@node2.supernodexp.hpc, sock=16
02/19/2018 16:17:48;0100;Server@node2;Req;;Type 49 request received from ctminh@node2.supernodexp.hpc, sock=17
02/19/2018 16:17:48;0100;Server@node2;Req;;Type 21 request received from ctminh@node2.supernodexp.hpc, sock=16
02/19/2018 16:17:48;0100;Server@node2;Req;;Type 1 request received from ctminh@node2.supernodexp.hpc, sock=16
02/19/2018 16:17:48;0086;Server@node2;Svr;Server@node2;Compiling script file: </var/spool/pbs/server_priv/hooks/evaluation.PY>
02/19/2018 16:17:49;0100;Server@node2;Req;;Type 3 request received from ctminh@node2.supernodexp.hpc, sock=16
02/19/2018 16:17:49;0100;Server@node2;Req;;Type 5 request received from ctminh@node2.supernodexp.hpc, sock=16
