02/20/2018 00:00:00;0002;Server@node2;Svr;Log;Log opened
02/20/2018 00:00:00;0002;Server@node2;Svr;Server@node2;pbs_version=14.0.1
02/20/2018 00:00:00;0002;Server@node2;Svr;Server@node2;pbs_build=mach=N/A:security=N/A:configure_args=N/A
02/20/2018 00:00:00;0002;Server@node2;Svr;Server@node2;hostname=node2.supernodexp.hpc;pbs_leaf_name=N/A;pbs_mom_node_name=N/A
02/20/2018 00:00:00;0002;Server@node2;Svr;Server@node2;ipv4 interface lo: localhost localhost.localdomain localhost4 localhost4.localdomain4 
02/20/2018 00:00:00;0002;Server@node2;Svr;Server@node2;ipv4 interface br0: node2.supernodexp.hpc node2 supernodexp-cn02 
02/20/2018 00:00:00;0002;Server@node2;Svr;Server@node2;ipv4 interface ib0: node2.supernodexp.hpc 
02/20/2018 00:00:00;0002;Server@node2;Svr;Server@node2;ipv4 interface docker0: node2.supernodexp.hpc 
02/20/2018 00:00:00;0002;Server@node2;Svr;Server@node2;ipv4 interface virbr0: node2.supernodexp.hpc 
02/20/2018 00:00:00;0002;Server@node2;Svr;Server@node2;ipv6 interface lo: localhost localhost.localdomain localhost6 localhost6.localdomain6 
02/20/2018 00:00:00;0002;Server@node2;Svr;Server@node2;ipv6 interface eno49: node2.supernodexp.hpc 
02/20/2018 00:00:00;0002;Server@node2;Svr;Server@node2;ipv6 interface br0: node2.supernodexp.hpc 
02/20/2018 00:00:00;0002;Server@node2;Svr;Server@node2;ipv6 interface ib0: node2.supernodexp.hpc 
02/20/2018 00:00:00;0002;Server@node2;Svr;Server@node2;ipv6 interface veth1pl7177: node2.supernodexp.hpc 
02/20/2018 00:00:00;0002;Server@node2;Svr;Act;Account file /var/spool/pbs/server_priv/accounting/20180220 opened
02/20/2018 00:01:01;0100;Server@node2;Req;;Type 0 request received from ctminh@node2.supernodexp.hpc, sock=16
02/20/2018 00:01:01;0100;Server@node2;Req;;Type 49 request received from ctminh@node2.supernodexp.hpc, sock=20
02/20/2018 00:01:01;0100;Server@node2;Req;;Type 21 request received from ctminh@node2.supernodexp.hpc, sock=16
02/20/2018 00:01:09;0100;Server@node2;Req;;Type 0 request received from ctminh@node2.supernodexp.hpc, sock=16
02/20/2018 00:01:09;0100;Server@node2;Req;;Type 49 request received from ctminh@node2.supernodexp.hpc, sock=20
02/20/2018 00:01:09;0100;Server@node2;Req;;Type 21 request received from ctminh@node2.supernodexp.hpc, sock=16
02/20/2018 00:01:09;0100;Server@node2;Req;;Type 19 request received from ctminh@node2.supernodexp.hpc, sock=16
02/20/2018 00:06:18;0080;Server@node2;Job;4330.node2.supernodexp.hpc;Obit received momhop:1 serverhop:1 state:4 substate:42
02/20/2018 00:06:20;0010;Server@node2;Job;4330.node2.supernodexp.hpc;Exit_status=2 resources_used.cpupercent=2165 resources_used.cput=06:30:48 resources_used.mem=21815560kb resources_used.ncpus=32 resources_used.vmem=25041200kb resources_used.walltime=00:18:16
02/20/2018 00:06:20;0100;Server@node2;Job;4330.node2.supernodexp.hpc;dequeuing from workq, state 5
02/20/2018 00:06:20;0040;Server@node2;Svr;node2.supernodexp.hpc;Scheduler sent command 2
02/20/2018 00:06:20;0040;Server@node2;Svr;node2.supernodexp.hpc;Scheduler sent command 0
02/20/2018 00:06:20;0100;Server@node2;Req;;Type 21 request received from Scheduler@node2.supernodexp.hpc, sock=16
02/20/2018 00:06:20;0100;Server@node2;Req;;Type 81 request received from Scheduler@node2.supernodexp.hpc, sock=16
02/20/2018 00:06:20;0100;Server@node2;Req;;Type 71 request received from Scheduler@node2.supernodexp.hpc, sock=16
02/20/2018 00:06:20;0100;Server@node2;Req;;Type 58 request received from Scheduler@node2.supernodexp.hpc, sock=16
02/20/2018 00:06:20;0100;Server@node2;Req;;Type 20 request received from Scheduler@node2.supernodexp.hpc, sock=16
02/20/2018 00:06:20;0100;Server@node2;Req;;Type 51 request received from Scheduler@node2.supernodexp.hpc, sock=16
02/20/2018 00:06:20;0100;Server@node2;Req;;Type 23 request received from Scheduler@node2.supernodexp.hpc, sock=16
02/20/2018 00:06:20;0008;Server@node2;Job;4398.node2.supernodexp.hpc;Job Run at request of Scheduler@node2.supernodexp.hpc on exec_vnode (node13:ncpus=32:nmics=1:mem=16777216kb)
02/20/2018 00:06:20;0001;Server@node2;Svr;Server@node2;Success (0) in req_runjob2, return value of svr_startjob is 0
02/20/2018 00:06:20;0100;Server@node2;Req;;Type 11 request received from Scheduler@node2.supernodexp.hpc, sock=16
02/20/2018 00:06:20;0008;Server@node2;Job;4409.node2.supernodexp.hpc;Job Modified at request of Scheduler@node2.supernodexp.hpc
02/20/2018 00:07:58;0080;Server@node2;Job;4332.node2.supernodexp.hpc;Obit received momhop:1 serverhop:1 state:4 substate:42
02/20/2018 00:08:00;0010;Server@node2;Job;4332.node2.supernodexp.hpc;Exit_status=2 resources_used.cpupercent=2104 resources_used.cput=06:12:16 resources_used.mem=22064736kb resources_used.ncpus=32 resources_used.vmem=24773824kb resources_used.walltime=00:18:19
02/20/2018 00:08:00;0100;Server@node2;Job;4332.node2.supernodexp.hpc;dequeuing from workq, state 5
02/20/2018 00:08:00;0040;Server@node2;Svr;node2.supernodexp.hpc;Scheduler sent command 2
02/20/2018 00:08:00;0040;Server@node2;Svr;node2.supernodexp.hpc;Scheduler sent command 0
02/20/2018 00:08:00;0100;Server@node2;Req;;Type 21 request received from Scheduler@node2.supernodexp.hpc, sock=16
02/20/2018 00:08:00;0100;Server@node2;Req;;Type 81 request received from Scheduler@node2.supernodexp.hpc, sock=16
02/20/2018 00:08:00;0100;Server@node2;Req;;Type 71 request received from Scheduler@node2.supernodexp.hpc, sock=16
02/20/2018 00:08:00;0100;Server@node2;Req;;Type 58 request received from Scheduler@node2.supernodexp.hpc, sock=16
02/20/2018 00:08:00;0100;Server@node2;Req;;Type 20 request received from Scheduler@node2.supernodexp.hpc, sock=16
02/20/2018 00:08:00;0100;Server@node2;Req;;Type 51 request received from Scheduler@node2.supernodexp.hpc, sock=16
02/20/2018 00:08:00;0100;Server@node2;Req;;Type 23 request received from Scheduler@node2.supernodexp.hpc, sock=16
02/20/2018 00:08:00;0008;Server@node2;Job;4409.node2.supernodexp.hpc;Job Run at request of Scheduler@node2.supernodexp.hpc on exec_vnode (node14:ncpus=32:nmics=1:mem=16777216kb)
02/20/2018 00:08:00;0001;Server@node2;Svr;Server@node2;Success (0) in req_runjob2, return value of svr_startjob is 0
02/20/2018 00:08:00;0100;Server@node2;Req;;Type 11 request received from Scheduler@node2.supernodexp.hpc, sock=16
02/20/2018 00:08:00;0008;Server@node2;Job;4422.node2.supernodexp.hpc;Job Modified at request of Scheduler@node2.supernodexp.hpc
02/20/2018 00:18:00;0040;Server@node2;Svr;node2.supernodexp.hpc;Scheduler sent command 3
02/20/2018 00:18:00;0040;Server@node2;Svr;node2.supernodexp.hpc;Scheduler sent command 0
02/20/2018 00:18:00;0100;Server@node2;Req;;Type 21 request received from Scheduler@node2.supernodexp.hpc, sock=16
02/20/2018 00:18:00;0100;Server@node2;Req;;Type 81 request received from Scheduler@node2.supernodexp.hpc, sock=16
02/20/2018 00:18:00;0100;Server@node2;Req;;Type 71 request received from Scheduler@node2.supernodexp.hpc, sock=16
02/20/2018 00:18:00;0100;Server@node2;Req;;Type 58 request received from Scheduler@node2.supernodexp.hpc, sock=16
02/20/2018 00:18:00;0100;Server@node2;Req;;Type 20 request received from Scheduler@node2.supernodexp.hpc, sock=16
02/20/2018 00:18:00;0100;Server@node2;Req;;Type 51 request received from Scheduler@node2.supernodexp.hpc, sock=16
02/20/2018 00:24:17;0080;Server@node2;Job;4398.node2.supernodexp.hpc;Obit received momhop:1 serverhop:1 state:4 substate:42
02/20/2018 00:24:19;0010;Server@node2;Job;4398.node2.supernodexp.hpc;Exit_status=2 resources_used.cpupercent=2172 resources_used.cput=06:25:01 resources_used.mem=21803996kb resources_used.ncpus=32 resources_used.vmem=24850160kb resources_used.walltime=00:17:57
02/20/2018 00:24:19;0100;Server@node2;Job;4398.node2.supernodexp.hpc;dequeuing from workq, state 5
02/20/2018 00:24:19;0040;Server@node2;Svr;node2.supernodexp.hpc;Scheduler sent command 2
02/20/2018 00:24:19;0040;Server@node2;Svr;node2.supernodexp.hpc;Scheduler sent command 0
02/20/2018 00:24:19;0100;Server@node2;Req;;Type 21 request received from Scheduler@node2.supernodexp.hpc, sock=16
02/20/2018 00:24:19;0100;Server@node2;Req;;Type 81 request received from Scheduler@node2.supernodexp.hpc, sock=16
02/20/2018 00:24:19;0100;Server@node2;Req;;Type 71 request received from Scheduler@node2.supernodexp.hpc, sock=16
02/20/2018 00:24:19;0100;Server@node2;Req;;Type 58 request received from Scheduler@node2.supernodexp.hpc, sock=16
02/20/2018 00:24:19;0100;Server@node2;Req;;Type 20 request received from Scheduler@node2.supernodexp.hpc, sock=16
02/20/2018 00:24:19;0100;Server@node2;Req;;Type 51 request received from Scheduler@node2.supernodexp.hpc, sock=16
02/20/2018 00:24:19;0100;Server@node2;Req;;Type 23 request received from Scheduler@node2.supernodexp.hpc, sock=16
02/20/2018 00:24:19;0008;Server@node2;Job;4422.node2.supernodexp.hpc;Job Run at request of Scheduler@node2.supernodexp.hpc on exec_vnode (node13:ncpus=32:nmics=1:mem=16777216kb)
02/20/2018 00:24:19;0001;Server@node2;Svr;Server@node2;Success (0) in req_runjob2, return value of svr_startjob is 0
02/20/2018 00:24:19;0100;Server@node2;Req;;Type 11 request received from Scheduler@node2.supernodexp.hpc, sock=16
02/20/2018 00:24:19;0008;Server@node2;Job;4439.node2.supernodexp.hpc;Job Modified at request of Scheduler@node2.supernodexp.hpc
02/20/2018 00:26:19;0080;Server@node2;Job;4409.node2.supernodexp.hpc;Obit received momhop:1 serverhop:1 state:4 substate:42
02/20/2018 00:26:20;0010;Server@node2;Job;4409.node2.supernodexp.hpc;Exit_status=2 resources_used.cpupercent=2072 resources_used.cput=06:13:42 resources_used.mem=22212496kb resources_used.ncpus=32 resources_used.vmem=24917160kb resources_used.walltime=00:18:19
02/20/2018 00:26:20;0100;Server@node2;Job;4409.node2.supernodexp.hpc;dequeuing from workq, state 5
02/20/2018 00:26:20;0040;Server@node2;Svr;node2.supernodexp.hpc;Scheduler sent command 2
02/20/2018 00:26:20;0040;Server@node2;Svr;node2.supernodexp.hpc;Scheduler sent command 0
02/20/2018 00:26:20;0100;Server@node2;Req;;Type 21 request received from Scheduler@node2.supernodexp.hpc, sock=16
02/20/2018 00:26:20;0100;Server@node2;Req;;Type 81 request received from Scheduler@node2.supernodexp.hpc, sock=16
02/20/2018 00:26:20;0100;Server@node2;Req;;Type 71 request received from Scheduler@node2.supernodexp.hpc, sock=16
02/20/2018 00:26:20;0100;Server@node2;Req;;Type 58 request received from Scheduler@node2.supernodexp.hpc, sock=16
02/20/2018 00:26:20;0100;Server@node2;Req;;Type 20 request received from Scheduler@node2.supernodexp.hpc, sock=16
02/20/2018 00:26:20;0100;Server@node2;Req;;Type 51 request received from Scheduler@node2.supernodexp.hpc, sock=16
02/20/2018 00:26:21;0100;Server@node2;Req;;Type 23 request received from Scheduler@node2.supernodexp.hpc, sock=16
02/20/2018 00:26:21;0008;Server@node2;Job;4439.node2.supernodexp.hpc;Job Run at request of Scheduler@node2.supernodexp.hpc on exec_vnode (node14:ncpus=32:nmics=1:mem=16777216kb)
02/20/2018 00:26:21;0001;Server@node2;Svr;Server@node2;Success (0) in req_runjob2, return value of svr_startjob is 0
02/20/2018 00:26:21;0100;Server@node2;Req;;Type 11 request received from Scheduler@node2.supernodexp.hpc, sock=16
02/20/2018 00:26:21;0008;Server@node2;Job;4479.node2.supernodexp.hpc;Job Modified at request of Scheduler@node2.supernodexp.hpc
02/20/2018 00:36:20;0040;Server@node2;Svr;node2.supernodexp.hpc;Scheduler sent command 3
02/20/2018 00:36:20;0040;Server@node2;Svr;node2.supernodexp.hpc;Scheduler sent command 0
02/20/2018 00:36:20;0100;Server@node2;Req;;Type 21 request received from Scheduler@node2.supernodexp.hpc, sock=16
02/20/2018 00:36:20;0100;Server@node2;Req;;Type 81 request received from Scheduler@node2.supernodexp.hpc, sock=16
02/20/2018 00:36:20;0100;Server@node2;Req;;Type 71 request received from Scheduler@node2.supernodexp.hpc, sock=16
02/20/2018 00:36:20;0100;Server@node2;Req;;Type 58 request received from Scheduler@node2.supernodexp.hpc, sock=16
02/20/2018 00:36:20;0100;Server@node2;Req;;Type 20 request received from Scheduler@node2.supernodexp.hpc, sock=16
02/20/2018 00:36:20;0100;Server@node2;Req;;Type 51 request received from Scheduler@node2.supernodexp.hpc, sock=16
02/20/2018 00:42:36;0080;Server@node2;Job;4422.node2.supernodexp.hpc;Obit received momhop:1 serverhop:1 state:4 substate:42
02/20/2018 00:42:38;0010;Server@node2;Job;4422.node2.supernodexp.hpc;Exit_status=2 resources_used.cpupercent=2175 resources_used.cput=06:31:30 resources_used.mem=21832388kb resources_used.ncpus=32 resources_used.vmem=25041196kb resources_used.walltime=00:18:18
02/20/2018 00:42:38;0100;Server@node2;Job;4422.node2.supernodexp.hpc;dequeuing from workq, state 5
02/20/2018 00:42:38;0040;Server@node2;Svr;node2.supernodexp.hpc;Scheduler sent command 2
02/20/2018 00:42:38;0040;Server@node2;Svr;node2.supernodexp.hpc;Scheduler sent command 0
02/20/2018 00:42:38;0100;Server@node2;Req;;Type 21 request received from Scheduler@node2.supernodexp.hpc, sock=16
02/20/2018 00:42:38;0100;Server@node2;Req;;Type 81 request received from Scheduler@node2.supernodexp.hpc, sock=16
02/20/2018 00:42:38;0100;Server@node2;Req;;Type 71 request received from Scheduler@node2.supernodexp.hpc, sock=16
02/20/2018 00:42:38;0100;Server@node2;Req;;Type 58 request received from Scheduler@node2.supernodexp.hpc, sock=16
02/20/2018 00:42:38;0100;Server@node2;Req;;Type 20 request received from Scheduler@node2.supernodexp.hpc, sock=16
02/20/2018 00:42:38;0100;Server@node2;Req;;Type 51 request received from Scheduler@node2.supernodexp.hpc, sock=16
02/20/2018 00:42:38;0100;Server@node2;Req;;Type 23 request received from Scheduler@node2.supernodexp.hpc, sock=16
02/20/2018 00:42:38;0008;Server@node2;Job;4479.node2.supernodexp.hpc;Job Run at request of Scheduler@node2.supernodexp.hpc on exec_vnode (node13:ncpus=32:nmics=1:mem=16777216kb)
02/20/2018 00:42:38;0001;Server@node2;Svr;Server@node2;Success (0) in req_runjob2, return value of svr_startjob is 0
02/20/2018 00:42:38;0100;Server@node2;Req;;Type 11 request received from Scheduler@node2.supernodexp.hpc, sock=16
02/20/2018 00:42:38;0008;Server@node2;Job;4482.node2.supernodexp.hpc;Job Modified at request of Scheduler@node2.supernodexp.hpc
02/20/2018 00:44:42;0080;Server@node2;Job;4439.node2.supernodexp.hpc;Obit received momhop:1 serverhop:1 state:4 substate:42
02/20/2018 00:44:43;0010;Server@node2;Job;4439.node2.supernodexp.hpc;Exit_status=2 resources_used.cpupercent=2077 resources_used.cput=06:13:05 resources_used.mem=21863160kb resources_used.ncpus=32 resources_used.vmem=24552896kb resources_used.walltime=00:18:21
02/20/2018 00:44:43;0100;Server@node2;Job;4439.node2.supernodexp.hpc;dequeuing from workq, state 5
02/20/2018 00:44:43;0040;Server@node2;Svr;node2.supernodexp.hpc;Scheduler sent command 2
02/20/2018 00:44:43;0040;Server@node2;Svr;node2.supernodexp.hpc;Scheduler sent command 0
02/20/2018 00:44:43;0100;Server@node2;Req;;Type 21 request received from Scheduler@node2.supernodexp.hpc, sock=16
02/20/2018 00:44:43;0100;Server@node2;Req;;Type 81 request received from Scheduler@node2.supernodexp.hpc, sock=16
02/20/2018 00:44:43;0100;Server@node2;Req;;Type 71 request received from Scheduler@node2.supernodexp.hpc, sock=16
02/20/2018 00:44:43;0100;Server@node2;Req;;Type 58 request received from Scheduler@node2.supernodexp.hpc, sock=16
02/20/2018 00:44:43;0100;Server@node2;Req;;Type 20 request received from Scheduler@node2.supernodexp.hpc, sock=16
02/20/2018 00:44:43;0100;Server@node2;Req;;Type 51 request received from Scheduler@node2.supernodexp.hpc, sock=16
02/20/2018 00:44:44;0100;Server@node2;Req;;Type 23 request received from Scheduler@node2.supernodexp.hpc, sock=16
02/20/2018 00:44:44;0008;Server@node2;Job;4482.node2.supernodexp.hpc;Job Run at request of Scheduler@node2.supernodexp.hpc on exec_vnode (node14:ncpus=32:nmics=1:mem=16777216kb)
02/20/2018 00:44:44;0001;Server@node2;Svr;Server@node2;Success (0) in req_runjob2, return value of svr_startjob is 0
02/20/2018 00:44:44;0100;Server@node2;Req;;Type 11 request received from Scheduler@node2.supernodexp.hpc, sock=16
02/20/2018 00:44:44;0008;Server@node2;Job;4518.node2.supernodexp.hpc;Job Modified at request of Scheduler@node2.supernodexp.hpc
02/20/2018 00:54:43;0040;Server@node2;Svr;node2.supernodexp.hpc;Scheduler sent command 3
02/20/2018 00:54:43;0040;Server@node2;Svr;node2.supernodexp.hpc;Scheduler sent command 0
02/20/2018 00:54:43;0100;Server@node2;Req;;Type 21 request received from Scheduler@node2.supernodexp.hpc, sock=16
02/20/2018 00:54:43;0100;Server@node2;Req;;Type 81 request received from Scheduler@node2.supernodexp.hpc, sock=16
02/20/2018 00:54:43;0100;Server@node2;Req;;Type 71 request received from Scheduler@node2.supernodexp.hpc, sock=16
02/20/2018 00:54:43;0100;Server@node2;Req;;Type 58 request received from Scheduler@node2.supernodexp.hpc, sock=16
02/20/2018 00:54:43;0100;Server@node2;Req;;Type 20 request received from Scheduler@node2.supernodexp.hpc, sock=16
02/20/2018 00:54:43;0100;Server@node2;Req;;Type 51 request received from Scheduler@node2.supernodexp.hpc, sock=16
02/20/2018 01:01:03;0080;Server@node2;Job;4479.node2.supernodexp.hpc;Obit received momhop:1 serverhop:1 state:4 substate:42
02/20/2018 01:01:05;0010;Server@node2;Job;4479.node2.supernodexp.hpc;Exit_status=2 resources_used.cpupercent=2237 resources_used.cput=06:36:37 resources_used.mem=22062324kb resources_used.ncpus=32 resources_used.vmem=25076380kb resources_used.walltime=00:18:25
02/20/2018 01:01:05;0100;Server@node2;Job;4479.node2.supernodexp.hpc;dequeuing from workq, state 5
02/20/2018 01:01:05;0040;Server@node2;Svr;node2.supernodexp.hpc;Scheduler sent command 2
02/20/2018 01:01:05;0040;Server@node2;Svr;node2.supernodexp.hpc;Scheduler sent command 0
02/20/2018 01:01:05;0100;Server@node2;Req;;Type 21 request received from Scheduler@node2.supernodexp.hpc, sock=16
02/20/2018 01:01:05;0100;Server@node2;Req;;Type 81 request received from Scheduler@node2.supernodexp.hpc, sock=16
02/20/2018 01:01:05;0100;Server@node2;Req;;Type 71 request received from Scheduler@node2.supernodexp.hpc, sock=16
02/20/2018 01:01:05;0100;Server@node2;Req;;Type 58 request received from Scheduler@node2.supernodexp.hpc, sock=16
02/20/2018 01:01:05;0100;Server@node2;Req;;Type 20 request received from Scheduler@node2.supernodexp.hpc, sock=16
02/20/2018 01:01:05;0100;Server@node2;Req;;Type 51 request received from Scheduler@node2.supernodexp.hpc, sock=16
02/20/2018 01:01:05;0100;Server@node2;Req;;Type 23 request received from Scheduler@node2.supernodexp.hpc, sock=16
02/20/2018 01:01:05;0008;Server@node2;Job;4518.node2.supernodexp.hpc;Job Run at request of Scheduler@node2.supernodexp.hpc on exec_vnode (node13:ncpus=32:nmics=1:mem=16777216kb)
02/20/2018 01:01:05;0001;Server@node2;Svr;Server@node2;Success (0) in req_runjob2, return value of svr_startjob is 0
02/20/2018 01:01:05;0100;Server@node2;Req;;Type 11 request received from Scheduler@node2.supernodexp.hpc, sock=16
02/20/2018 01:01:05;0008;Server@node2;Job;4521.node2.supernodexp.hpc;Job Modified at request of Scheduler@node2.supernodexp.hpc
02/20/2018 01:03:05;0080;Server@node2;Job;4482.node2.supernodexp.hpc;Obit received momhop:1 serverhop:1 state:4 substate:42
02/20/2018 01:03:07;0010;Server@node2;Job;4482.node2.supernodexp.hpc;Exit_status=2 resources_used.cpupercent=2077 resources_used.cput=06:08:38 resources_used.mem=22066456kb resources_used.ncpus=32 resources_used.vmem=24771980kb resources_used.walltime=00:18:22
02/20/2018 01:03:07;0100;Server@node2;Job;4482.node2.supernodexp.hpc;dequeuing from workq, state 5
02/20/2018 01:03:08;0040;Server@node2;Svr;node2.supernodexp.hpc;Scheduler sent command 2
02/20/2018 01:03:08;0040;Server@node2;Svr;node2.supernodexp.hpc;Scheduler sent command 0
02/20/2018 01:03:08;0100;Server@node2;Req;;Type 21 request received from Scheduler@node2.supernodexp.hpc, sock=16
02/20/2018 01:03:08;0100;Server@node2;Req;;Type 81 request received from Scheduler@node2.supernodexp.hpc, sock=16
02/20/2018 01:03:08;0100;Server@node2;Req;;Type 71 request received from Scheduler@node2.supernodexp.hpc, sock=16
02/20/2018 01:03:08;0100;Server@node2;Req;;Type 58 request received from Scheduler@node2.supernodexp.hpc, sock=16
02/20/2018 01:03:08;0100;Server@node2;Req;;Type 20 request received from Scheduler@node2.supernodexp.hpc, sock=16
02/20/2018 01:03:08;0100;Server@node2;Req;;Type 51 request received from Scheduler@node2.supernodexp.hpc, sock=16
02/20/2018 01:03:08;0100;Server@node2;Req;;Type 23 request received from Scheduler@node2.supernodexp.hpc, sock=16
02/20/2018 01:03:08;0008;Server@node2;Job;4521.node2.supernodexp.hpc;Job Run at request of Scheduler@node2.supernodexp.hpc on exec_vnode (node14:ncpus=32:nmics=1:mem=16777216kb)
02/20/2018 01:03:08;0001;Server@node2;Svr;Server@node2;Success (0) in req_runjob2, return value of svr_startjob is 0
02/20/2018 01:03:08;0100;Server@node2;Req;;Type 11 request received from Scheduler@node2.supernodexp.hpc, sock=16
02/20/2018 01:03:08;0008;Server@node2;Job;4529.node2.supernodexp.hpc;Job Modified at request of Scheduler@node2.supernodexp.hpc
02/20/2018 01:13:08;0040;Server@node2;Svr;node2.supernodexp.hpc;Scheduler sent command 3
02/20/2018 01:13:08;0040;Server@node2;Svr;node2.supernodexp.hpc;Scheduler sent command 0
02/20/2018 01:13:08;0100;Server@node2;Req;;Type 21 request received from Scheduler@node2.supernodexp.hpc, sock=16
02/20/2018 01:13:08;0100;Server@node2;Req;;Type 81 request received from Scheduler@node2.supernodexp.hpc, sock=16
02/20/2018 01:13:08;0100;Server@node2;Req;;Type 71 request received from Scheduler@node2.supernodexp.hpc, sock=16
02/20/2018 01:13:08;0100;Server@node2;Req;;Type 58 request received from Scheduler@node2.supernodexp.hpc, sock=16
02/20/2018 01:13:08;0100;Server@node2;Req;;Type 20 request received from Scheduler@node2.supernodexp.hpc, sock=16
02/20/2018 01:13:08;0100;Server@node2;Req;;Type 51 request received from Scheduler@node2.supernodexp.hpc, sock=16
02/20/2018 01:19:46;0080;Server@node2;Job;4518.node2.supernodexp.hpc;Obit received momhop:1 serverhop:1 state:4 substate:42
02/20/2018 01:19:47;0010;Server@node2;Job;4518.node2.supernodexp.hpc;Exit_status=2 resources_used.cpupercent=2231 resources_used.cput=06:35:41 resources_used.mem=21815560kb resources_used.ncpus=32 resources_used.vmem=24854452kb resources_used.walltime=00:18:41
02/20/2018 01:19:47;0100;Server@node2;Job;4518.node2.supernodexp.hpc;dequeuing from workq, state 5
02/20/2018 01:19:47;0040;Server@node2;Svr;node2.supernodexp.hpc;Scheduler sent command 2
02/20/2018 01:19:47;0040;Server@node2;Svr;node2.supernodexp.hpc;Scheduler sent command 0
02/20/2018 01:19:47;0100;Server@node2;Req;;Type 21 request received from Scheduler@node2.supernodexp.hpc, sock=16
02/20/2018 01:19:47;0100;Server@node2;Req;;Type 81 request received from Scheduler@node2.supernodexp.hpc, sock=16
02/20/2018 01:19:47;0100;Server@node2;Req;;Type 71 request received from Scheduler@node2.supernodexp.hpc, sock=16
02/20/2018 01:19:47;0100;Server@node2;Req;;Type 58 request received from Scheduler@node2.supernodexp.hpc, sock=16
02/20/2018 01:19:47;0100;Server@node2;Req;;Type 20 request received from Scheduler@node2.supernodexp.hpc, sock=16
02/20/2018 01:19:47;0100;Server@node2;Req;;Type 51 request received from Scheduler@node2.supernodexp.hpc, sock=16
02/20/2018 01:19:48;0100;Server@node2;Req;;Type 23 request received from Scheduler@node2.supernodexp.hpc, sock=16
02/20/2018 01:19:48;0008;Server@node2;Job;4529.node2.supernodexp.hpc;Job Run at request of Scheduler@node2.supernodexp.hpc on exec_vnode (node13:ncpus=32:nmics=1:mem=16777216kb)
02/20/2018 01:19:48;0001;Server@node2;Svr;Server@node2;Success (0) in req_runjob2, return value of svr_startjob is 0
02/20/2018 01:19:48;0100;Server@node2;Req;;Type 11 request received from Scheduler@node2.supernodexp.hpc, sock=16
02/20/2018 01:19:48;0008;Server@node2;Job;4557.node2.supernodexp.hpc;Job Modified at request of Scheduler@node2.supernodexp.hpc
02/20/2018 01:21:28;0080;Server@node2;Job;4521.node2.supernodexp.hpc;Obit received momhop:1 serverhop:1 state:4 substate:42
02/20/2018 01:21:30;0010;Server@node2;Job;4521.node2.supernodexp.hpc;Exit_status=2 resources_used.cpupercent=2101 resources_used.cput=06:13:54 resources_used.mem=22201508kb resources_used.ncpus=32 resources_used.vmem=24917160kb resources_used.walltime=00:18:20
02/20/2018 01:21:30;0100;Server@node2;Job;4521.node2.supernodexp.hpc;dequeuing from workq, state 5
02/20/2018 01:21:30;0040;Server@node2;Svr;node2.supernodexp.hpc;Scheduler sent command 2
02/20/2018 01:21:30;0040;Server@node2;Svr;node2.supernodexp.hpc;Scheduler sent command 0
02/20/2018 01:21:30;0100;Server@node2;Req;;Type 21 request received from Scheduler@node2.supernodexp.hpc, sock=16
02/20/2018 01:21:30;0100;Server@node2;Req;;Type 81 request received from Scheduler@node2.supernodexp.hpc, sock=16
02/20/2018 01:21:30;0100;Server@node2;Req;;Type 71 request received from Scheduler@node2.supernodexp.hpc, sock=16
02/20/2018 01:21:30;0100;Server@node2;Req;;Type 58 request received from Scheduler@node2.supernodexp.hpc, sock=16
02/20/2018 01:21:30;0100;Server@node2;Req;;Type 20 request received from Scheduler@node2.supernodexp.hpc, sock=16
02/20/2018 01:21:30;0100;Server@node2;Req;;Type 51 request received from Scheduler@node2.supernodexp.hpc, sock=16
02/20/2018 01:21:30;0100;Server@node2;Req;;Type 23 request received from Scheduler@node2.supernodexp.hpc, sock=16
02/20/2018 01:21:30;0008;Server@node2;Job;4557.node2.supernodexp.hpc;Job Run at request of Scheduler@node2.supernodexp.hpc on exec_vnode (node14:ncpus=32:nmics=1:mem=16777216kb)
02/20/2018 01:21:30;0001;Server@node2;Svr;Server@node2;Success (0) in req_runjob2, return value of svr_startjob is 0
02/20/2018 01:21:30;0100;Server@node2;Req;;Type 11 request received from Scheduler@node2.supernodexp.hpc, sock=16
02/20/2018 01:21:30;0008;Server@node2;Job;4565.node2.supernodexp.hpc;Job Modified at request of Scheduler@node2.supernodexp.hpc
02/20/2018 01:31:30;0040;Server@node2;Svr;node2.supernodexp.hpc;Scheduler sent command 3
02/20/2018 01:31:30;0040;Server@node2;Svr;node2.supernodexp.hpc;Scheduler sent command 0
02/20/2018 01:31:30;0100;Server@node2;Req;;Type 21 request received from Scheduler@node2.supernodexp.hpc, sock=16
02/20/2018 01:31:30;0100;Server@node2;Req;;Type 81 request received from Scheduler@node2.supernodexp.hpc, sock=16
02/20/2018 01:31:30;0100;Server@node2;Req;;Type 71 request received from Scheduler@node2.supernodexp.hpc, sock=16
02/20/2018 01:31:30;0100;Server@node2;Req;;Type 58 request received from Scheduler@node2.supernodexp.hpc, sock=16
02/20/2018 01:31:30;0100;Server@node2;Req;;Type 20 request received from Scheduler@node2.supernodexp.hpc, sock=16
02/20/2018 01:31:30;0100;Server@node2;Req;;Type 51 request received from Scheduler@node2.supernodexp.hpc, sock=16
02/20/2018 01:38:09;0080;Server@node2;Job;4529.node2.supernodexp.hpc;Obit received momhop:1 serverhop:1 state:4 substate:42
02/20/2018 01:38:10;0010;Server@node2;Job;4529.node2.supernodexp.hpc;Exit_status=2 resources_used.cpupercent=2168 resources_used.cput=06:29:39 resources_used.mem=21840064kb resources_used.ncpus=32 resources_used.vmem=24850172kb resources_used.walltime=00:18:21
02/20/2018 01:38:10;0100;Server@node2;Job;4529.node2.supernodexp.hpc;dequeuing from workq, state 5
02/20/2018 01:38:10;0040;Server@node2;Svr;node2.supernodexp.hpc;Scheduler sent command 2
02/20/2018 01:38:10;0040;Server@node2;Svr;node2.supernodexp.hpc;Scheduler sent command 0
02/20/2018 01:38:10;0100;Server@node2;Req;;Type 21 request received from Scheduler@node2.supernodexp.hpc, sock=16
02/20/2018 01:38:10;0100;Server@node2;Req;;Type 81 request received from Scheduler@node2.supernodexp.hpc, sock=16
02/20/2018 01:38:10;0100;Server@node2;Req;;Type 71 request received from Scheduler@node2.supernodexp.hpc, sock=16
02/20/2018 01:38:10;0100;Server@node2;Req;;Type 58 request received from Scheduler@node2.supernodexp.hpc, sock=16
02/20/2018 01:38:10;0100;Server@node2;Req;;Type 20 request received from Scheduler@node2.supernodexp.hpc, sock=16
02/20/2018 01:38:10;0100;Server@node2;Req;;Type 51 request received from Scheduler@node2.supernodexp.hpc, sock=16
02/20/2018 01:38:11;0100;Server@node2;Req;;Type 23 request received from Scheduler@node2.supernodexp.hpc, sock=16
02/20/2018 01:38:11;0008;Server@node2;Job;4565.node2.supernodexp.hpc;Job Run at request of Scheduler@node2.supernodexp.hpc on exec_vnode (node13:ncpus=32:nmics=1:mem=16777216kb)
02/20/2018 01:38:11;0001;Server@node2;Svr;Server@node2;Success (0) in req_runjob2, return value of svr_startjob is 0
02/20/2018 01:38:11;0100;Server@node2;Req;;Type 11 request received from Scheduler@node2.supernodexp.hpc, sock=16
02/20/2018 01:38:11;0008;Server@node2;Job;4580.node2.supernodexp.hpc;Job Modified at request of Scheduler@node2.supernodexp.hpc
02/20/2018 01:40:07;0080;Server@node2;Job;4557.node2.supernodexp.hpc;Obit received momhop:1 serverhop:1 state:4 substate:42
02/20/2018 01:40:08;0010;Server@node2;Job;4557.node2.supernodexp.hpc;Exit_status=2 resources_used.cpupercent=2123 resources_used.cput=06:14:24 resources_used.mem=22063048kb resources_used.ncpus=32 resources_used.vmem=24770768kb resources_used.walltime=00:18:38
02/20/2018 01:40:08;0100;Server@node2;Job;4557.node2.supernodexp.hpc;dequeuing from workq, state 5
02/20/2018 01:40:08;0040;Server@node2;Svr;node2.supernodexp.hpc;Scheduler sent command 2
02/20/2018 01:40:08;0040;Server@node2;Svr;node2.supernodexp.hpc;Scheduler sent command 0
02/20/2018 01:40:08;0100;Server@node2;Req;;Type 21 request received from Scheduler@node2.supernodexp.hpc, sock=16
02/20/2018 01:40:08;0100;Server@node2;Req;;Type 81 request received from Scheduler@node2.supernodexp.hpc, sock=16
02/20/2018 01:40:08;0100;Server@node2;Req;;Type 71 request received from Scheduler@node2.supernodexp.hpc, sock=16
02/20/2018 01:40:08;0100;Server@node2;Req;;Type 58 request received from Scheduler@node2.supernodexp.hpc, sock=16
02/20/2018 01:40:08;0100;Server@node2;Req;;Type 20 request received from Scheduler@node2.supernodexp.hpc, sock=16
02/20/2018 01:40:08;0100;Server@node2;Req;;Type 51 request received from Scheduler@node2.supernodexp.hpc, sock=16
02/20/2018 01:40:09;0100;Server@node2;Req;;Type 23 request received from Scheduler@node2.supernodexp.hpc, sock=16
02/20/2018 01:40:09;0008;Server@node2;Job;4580.node2.supernodexp.hpc;Job Run at request of Scheduler@node2.supernodexp.hpc on exec_vnode (node14:ncpus=32:nmics=1:mem=16777216kb)
02/20/2018 01:40:09;0001;Server@node2;Svr;Server@node2;Success (0) in req_runjob2, return value of svr_startjob is 0
02/20/2018 01:40:09;0100;Server@node2;Req;;Type 11 request received from Scheduler@node2.supernodexp.hpc, sock=16
02/20/2018 01:40:09;0008;Server@node2;Job;4581.node2.supernodexp.hpc;Job Modified at request of Scheduler@node2.supernodexp.hpc
02/20/2018 01:50:08;0040;Server@node2;Svr;node2.supernodexp.hpc;Scheduler sent command 3
02/20/2018 01:50:08;0040;Server@node2;Svr;node2.supernodexp.hpc;Scheduler sent command 0
02/20/2018 01:50:08;0100;Server@node2;Req;;Type 21 request received from Scheduler@node2.supernodexp.hpc, sock=16
02/20/2018 01:50:08;0100;Server@node2;Req;;Type 81 request received from Scheduler@node2.supernodexp.hpc, sock=16
02/20/2018 01:50:08;0100;Server@node2;Req;;Type 71 request received from Scheduler@node2.supernodexp.hpc, sock=16
02/20/2018 01:50:08;0100;Server@node2;Req;;Type 58 request received from Scheduler@node2.supernodexp.hpc, sock=16
02/20/2018 01:50:08;0100;Server@node2;Req;;Type 20 request received from Scheduler@node2.supernodexp.hpc, sock=16
02/20/2018 01:50:08;0100;Server@node2;Req;;Type 51 request received from Scheduler@node2.supernodexp.hpc, sock=16
02/20/2018 01:56:21;0080;Server@node2;Job;4565.node2.supernodexp.hpc;Obit received momhop:1 serverhop:1 state:4 substate:42
02/20/2018 01:56:23;0010;Server@node2;Job;4565.node2.supernodexp.hpc;Exit_status=2 resources_used.cpupercent=2167 resources_used.cput=06:26:48 resources_used.mem=21832168kb resources_used.ncpus=32 resources_used.vmem=24850164kb resources_used.walltime=00:18:11
02/20/2018 01:56:23;0100;Server@node2;Job;4565.node2.supernodexp.hpc;dequeuing from workq, state 5
02/20/2018 01:56:23;0040;Server@node2;Svr;node2.supernodexp.hpc;Scheduler sent command 2
02/20/2018 01:56:23;0040;Server@node2;Svr;node2.supernodexp.hpc;Scheduler sent command 0
02/20/2018 01:56:23;0100;Server@node2;Req;;Type 21 request received from Scheduler@node2.supernodexp.hpc, sock=16
02/20/2018 01:56:23;0100;Server@node2;Req;;Type 81 request received from Scheduler@node2.supernodexp.hpc, sock=16
02/20/2018 01:56:23;0100;Server@node2;Req;;Type 71 request received from Scheduler@node2.supernodexp.hpc, sock=16
02/20/2018 01:56:23;0100;Server@node2;Req;;Type 58 request received from Scheduler@node2.supernodexp.hpc, sock=16
02/20/2018 01:56:23;0100;Server@node2;Req;;Type 20 request received from Scheduler@node2.supernodexp.hpc, sock=16
02/20/2018 01:56:23;0100;Server@node2;Req;;Type 51 request received from Scheduler@node2.supernodexp.hpc, sock=16
02/20/2018 01:56:23;0100;Server@node2;Req;;Type 23 request received from Scheduler@node2.supernodexp.hpc, sock=16
02/20/2018 01:56:23;0008;Server@node2;Job;4581.node2.supernodexp.hpc;Job Run at request of Scheduler@node2.supernodexp.hpc on exec_vnode (node13:ncpus=32:nmics=1:mem=16777216kb)
02/20/2018 01:56:23;0001;Server@node2;Svr;Server@node2;Success (0) in req_runjob2, return value of svr_startjob is 0
02/20/2018 01:56:23;0100;Server@node2;Req;;Type 11 request received from Scheduler@node2.supernodexp.hpc, sock=16
02/20/2018 01:56:23;0008;Server@node2;Job;4589.node2.supernodexp.hpc;Job Modified at request of Scheduler@node2.supernodexp.hpc
02/20/2018 01:58:49;0080;Server@node2;Job;4580.node2.supernodexp.hpc;Obit received momhop:1 serverhop:1 state:4 substate:42
02/20/2018 01:58:51;0010;Server@node2;Job;4580.node2.supernodexp.hpc;Exit_status=2 resources_used.cpupercent=2087 resources_used.cput=06:12:17 resources_used.mem=22200008kb resources_used.ncpus=32 resources_used.vmem=24923656kb resources_used.walltime=00:18:40
02/20/2018 01:58:51;0100;Server@node2;Job;4580.node2.supernodexp.hpc;dequeuing from workq, state 5
02/20/2018 01:58:51;0040;Server@node2;Svr;node2.supernodexp.hpc;Scheduler sent command 2
02/20/2018 01:58:51;0040;Server@node2;Svr;node2.supernodexp.hpc;Scheduler sent command 0
02/20/2018 01:58:51;0100;Server@node2;Req;;Type 21 request received from Scheduler@node2.supernodexp.hpc, sock=16
02/20/2018 01:58:51;0100;Server@node2;Req;;Type 81 request received from Scheduler@node2.supernodexp.hpc, sock=16
02/20/2018 01:58:51;0100;Server@node2;Req;;Type 71 request received from Scheduler@node2.supernodexp.hpc, sock=16
02/20/2018 01:58:51;0100;Server@node2;Req;;Type 58 request received from Scheduler@node2.supernodexp.hpc, sock=16
02/20/2018 01:58:51;0100;Server@node2;Req;;Type 20 request received from Scheduler@node2.supernodexp.hpc, sock=16
02/20/2018 01:58:51;0100;Server@node2;Req;;Type 51 request received from Scheduler@node2.supernodexp.hpc, sock=16
02/20/2018 01:58:51;0100;Server@node2;Req;;Type 23 request received from Scheduler@node2.supernodexp.hpc, sock=16
02/20/2018 01:58:51;0008;Server@node2;Job;4589.node2.supernodexp.hpc;Job Run at request of Scheduler@node2.supernodexp.hpc on exec_vnode (node14:ncpus=32:nmics=1:mem=16777216kb)
02/20/2018 01:58:51;0001;Server@node2;Svr;Server@node2;Success (0) in req_runjob2, return value of svr_startjob is 0
02/20/2018 01:58:51;0100;Server@node2;Req;;Type 11 request received from Scheduler@node2.supernodexp.hpc, sock=16
02/20/2018 01:58:51;0008;Server@node2;Job;4619.node2.supernodexp.hpc;Job Modified at request of Scheduler@node2.supernodexp.hpc
02/20/2018 02:08:51;0040;Server@node2;Svr;node2.supernodexp.hpc;Scheduler sent command 3
02/20/2018 02:08:51;0040;Server@node2;Svr;node2.supernodexp.hpc;Scheduler sent command 0
02/20/2018 02:08:51;0100;Server@node2;Req;;Type 21 request received from Scheduler@node2.supernodexp.hpc, sock=16
02/20/2018 02:08:51;0100;Server@node2;Req;;Type 81 request received from Scheduler@node2.supernodexp.hpc, sock=16
02/20/2018 02:08:51;0100;Server@node2;Req;;Type 71 request received from Scheduler@node2.supernodexp.hpc, sock=16
02/20/2018 02:08:51;0100;Server@node2;Req;;Type 58 request received from Scheduler@node2.supernodexp.hpc, sock=16
02/20/2018 02:08:51;0100;Server@node2;Req;;Type 20 request received from Scheduler@node2.supernodexp.hpc, sock=16
02/20/2018 02:08:51;0100;Server@node2;Req;;Type 51 request received from Scheduler@node2.supernodexp.hpc, sock=16
02/20/2018 02:14:27;0080;Server@node2;Job;4581.node2.supernodexp.hpc;Obit received momhop:1 serverhop:1 state:4 substate:42
02/20/2018 02:14:28;0010;Server@node2;Job;4581.node2.supernodexp.hpc;Exit_status=2 resources_used.cpupercent=2179 resources_used.cput=06:27:13 resources_used.mem=21859724kb resources_used.ncpus=32 resources_used.vmem=24888868kb resources_used.walltime=00:18:04
02/20/2018 02:14:28;0100;Server@node2;Job;4581.node2.supernodexp.hpc;dequeuing from workq, state 5
02/20/2018 02:14:28;0040;Server@node2;Svr;node2.supernodexp.hpc;Scheduler sent command 2
02/20/2018 02:14:28;0040;Server@node2;Svr;node2.supernodexp.hpc;Scheduler sent command 0
02/20/2018 02:14:28;0100;Server@node2;Req;;Type 21 request received from Scheduler@node2.supernodexp.hpc, sock=16
02/20/2018 02:14:28;0100;Server@node2;Req;;Type 81 request received from Scheduler@node2.supernodexp.hpc, sock=16
02/20/2018 02:14:28;0100;Server@node2;Req;;Type 71 request received from Scheduler@node2.supernodexp.hpc, sock=16
02/20/2018 02:14:28;0100;Server@node2;Req;;Type 58 request received from Scheduler@node2.supernodexp.hpc, sock=16
02/20/2018 02:14:28;0100;Server@node2;Req;;Type 20 request received from Scheduler@node2.supernodexp.hpc, sock=16
02/20/2018 02:14:28;0100;Server@node2;Req;;Type 51 request received from Scheduler@node2.supernodexp.hpc, sock=16
02/20/2018 02:14:29;0100;Server@node2;Req;;Type 23 request received from Scheduler@node2.supernodexp.hpc, sock=16
02/20/2018 02:14:29;0008;Server@node2;Job;4619.node2.supernodexp.hpc;Job Run at request of Scheduler@node2.supernodexp.hpc on exec_vnode (node13:ncpus=32:nmics=1:mem=16777216kb)
02/20/2018 02:14:29;0001;Server@node2;Svr;Server@node2;Success (0) in req_runjob2, return value of svr_startjob is 0
02/20/2018 02:14:29;0100;Server@node2;Req;;Type 11 request received from Scheduler@node2.supernodexp.hpc, sock=16
02/20/2018 02:14:29;0008;Server@node2;Job;4622.node2.supernodexp.hpc;Job Modified at request of Scheduler@node2.supernodexp.hpc
02/20/2018 02:17:16;0080;Server@node2;Job;4589.node2.supernodexp.hpc;Obit received momhop:1 serverhop:1 state:4 substate:42
02/20/2018 02:17:18;0010;Server@node2;Job;4589.node2.supernodexp.hpc;Exit_status=2 resources_used.cpupercent=2118 resources_used.cput=06:13:55 resources_used.mem=22058888kb resources_used.ncpus=32 resources_used.vmem=24770764kb resources_used.walltime=00:18:26
02/20/2018 02:17:18;0100;Server@node2;Job;4589.node2.supernodexp.hpc;dequeuing from workq, state 5
02/20/2018 02:17:18;0040;Server@node2;Svr;node2.supernodexp.hpc;Scheduler sent command 2
02/20/2018 02:17:18;0040;Server@node2;Svr;node2.supernodexp.hpc;Scheduler sent command 0
02/20/2018 02:17:18;0100;Server@node2;Req;;Type 21 request received from Scheduler@node2.supernodexp.hpc, sock=16
02/20/2018 02:17:18;0100;Server@node2;Req;;Type 81 request received from Scheduler@node2.supernodexp.hpc, sock=16
02/20/2018 02:17:18;0100;Server@node2;Req;;Type 71 request received from Scheduler@node2.supernodexp.hpc, sock=16
02/20/2018 02:17:18;0100;Server@node2;Req;;Type 58 request received from Scheduler@node2.supernodexp.hpc, sock=16
02/20/2018 02:17:18;0100;Server@node2;Req;;Type 20 request received from Scheduler@node2.supernodexp.hpc, sock=16
02/20/2018 02:17:18;0100;Server@node2;Req;;Type 51 request received from Scheduler@node2.supernodexp.hpc, sock=16
02/20/2018 02:17:18;0100;Server@node2;Req;;Type 23 request received from Scheduler@node2.supernodexp.hpc, sock=16
02/20/2018 02:17:18;0008;Server@node2;Job;4622.node2.supernodexp.hpc;Job Run at request of Scheduler@node2.supernodexp.hpc on exec_vnode (node14:ncpus=32:nmics=1:mem=16777216kb)
02/20/2018 02:17:18;0001;Server@node2;Svr;Server@node2;Success (0) in req_runjob2, return value of svr_startjob is 0
02/20/2018 02:17:18;0100;Server@node2;Req;;Type 11 request received from Scheduler@node2.supernodexp.hpc, sock=16
02/20/2018 02:17:18;0008;Server@node2;Job;3655.node2.supernodexp.hpc;Job Modified at request of Scheduler@node2.supernodexp.hpc
02/20/2018 02:27:18;0040;Server@node2;Svr;node2.supernodexp.hpc;Scheduler sent command 3
02/20/2018 02:27:18;0040;Server@node2;Svr;node2.supernodexp.hpc;Scheduler sent command 0
02/20/2018 02:27:18;0100;Server@node2;Req;;Type 21 request received from Scheduler@node2.supernodexp.hpc, sock=16
02/20/2018 02:27:18;0100;Server@node2;Req;;Type 81 request received from Scheduler@node2.supernodexp.hpc, sock=16
02/20/2018 02:27:18;0100;Server@node2;Req;;Type 71 request received from Scheduler@node2.supernodexp.hpc, sock=16
02/20/2018 02:27:18;0100;Server@node2;Req;;Type 58 request received from Scheduler@node2.supernodexp.hpc, sock=16
02/20/2018 02:27:18;0100;Server@node2;Req;;Type 20 request received from Scheduler@node2.supernodexp.hpc, sock=16
02/20/2018 02:27:18;0100;Server@node2;Req;;Type 51 request received from Scheduler@node2.supernodexp.hpc, sock=16
02/20/2018 02:32:54;0080;Server@node2;Job;4619.node2.supernodexp.hpc;Obit received momhop:1 serverhop:1 state:4 substate:42
02/20/2018 02:32:56;0010;Server@node2;Job;4619.node2.supernodexp.hpc;Exit_status=2 resources_used.cpupercent=2159 resources_used.cput=06:25:47 resources_used.mem=21836124kb resources_used.ncpus=32 resources_used.vmem=24852740kb resources_used.walltime=00:18:27
02/20/2018 02:32:56;0100;Server@node2;Job;4619.node2.supernodexp.hpc;dequeuing from workq, state 5
02/20/2018 02:32:56;0040;Server@node2;Svr;node2.supernodexp.hpc;Scheduler sent command 2
02/20/2018 02:32:56;0040;Server@node2;Svr;node2.supernodexp.hpc;Scheduler sent command 0
02/20/2018 02:32:56;0100;Server@node2;Req;;Type 21 request received from Scheduler@node2.supernodexp.hpc, sock=16
02/20/2018 02:32:56;0100;Server@node2;Req;;Type 81 request received from Scheduler@node2.supernodexp.hpc, sock=16
02/20/2018 02:32:56;0100;Server@node2;Req;;Type 71 request received from Scheduler@node2.supernodexp.hpc, sock=16
02/20/2018 02:32:56;0100;Server@node2;Req;;Type 58 request received from Scheduler@node2.supernodexp.hpc, sock=16
02/20/2018 02:32:56;0100;Server@node2;Req;;Type 20 request received from Scheduler@node2.supernodexp.hpc, sock=16
02/20/2018 02:32:56;0100;Server@node2;Req;;Type 51 request received from Scheduler@node2.supernodexp.hpc, sock=16
02/20/2018 02:32:57;0100;Server@node2;Req;;Type 23 request received from Scheduler@node2.supernodexp.hpc, sock=16
02/20/2018 02:32:57;0008;Server@node2;Job;3655.node2.supernodexp.hpc;Job Run at request of Scheduler@node2.supernodexp.hpc on exec_vnode (node13:ncpus=48:mem=5242880kb)
02/20/2018 02:32:57;0001;Server@node2;Svr;Server@node2;Success (0) in req_runjob2, return value of svr_startjob is 0
02/20/2018 02:32:57;0100;Server@node2;Req;;Type 11 request received from Scheduler@node2.supernodexp.hpc, sock=16
02/20/2018 02:32:57;0008;Server@node2;Job;3685.node2.supernodexp.hpc;Job Modified at request of Scheduler@node2.supernodexp.hpc
02/20/2018 02:35:17;0080;Server@node2;Job;4622.node2.supernodexp.hpc;Obit received momhop:1 serverhop:1 state:4 substate:42
02/20/2018 02:35:19;0010;Server@node2;Job;4622.node2.supernodexp.hpc;Exit_status=2 resources_used.cpupercent=2079 resources_used.cput=06:04:50 resources_used.mem=21835048kb resources_used.ncpus=32 resources_used.vmem=24891080kb resources_used.walltime=00:17:59
02/20/2018 02:35:19;0100;Server@node2;Job;4622.node2.supernodexp.hpc;dequeuing from workq, state 5
02/20/2018 02:35:19;0040;Server@node2;Svr;node2.supernodexp.hpc;Scheduler sent command 2
02/20/2018 02:35:19;0040;Server@node2;Svr;node2.supernodexp.hpc;Scheduler sent command 0
02/20/2018 02:35:19;0100;Server@node2;Req;;Type 21 request received from Scheduler@node2.supernodexp.hpc, sock=16
02/20/2018 02:35:19;0100;Server@node2;Req;;Type 81 request received from Scheduler@node2.supernodexp.hpc, sock=16
02/20/2018 02:35:19;0100;Server@node2;Req;;Type 71 request received from Scheduler@node2.supernodexp.hpc, sock=16
02/20/2018 02:35:19;0100;Server@node2;Req;;Type 58 request received from Scheduler@node2.supernodexp.hpc, sock=16
02/20/2018 02:35:19;0100;Server@node2;Req;;Type 20 request received from Scheduler@node2.supernodexp.hpc, sock=16
02/20/2018 02:35:19;0100;Server@node2;Req;;Type 51 request received from Scheduler@node2.supernodexp.hpc, sock=16
02/20/2018 02:35:19;0100;Server@node2;Req;;Type 23 request received from Scheduler@node2.supernodexp.hpc, sock=16
02/20/2018 02:35:19;0008;Server@node2;Job;3685.node2.supernodexp.hpc;Job Run at request of Scheduler@node2.supernodexp.hpc on exec_vnode (node14:ncpus=48:mem=5242880kb)
02/20/2018 02:35:19;0001;Server@node2;Svr;Server@node2;Success (0) in req_runjob2, return value of svr_startjob is 0
02/20/2018 02:35:19;0100;Server@node2;Req;;Type 11 request received from Scheduler@node2.supernodexp.hpc, sock=16
02/20/2018 02:35:19;0008;Server@node2;Job;3689.node2.supernodexp.hpc;Job Modified at request of Scheduler@node2.supernodexp.hpc
02/20/2018 02:43:34;0080;Server@node2;Job;3655.node2.supernodexp.hpc;Obit received momhop:1 serverhop:1 state:4 substate:42
02/20/2018 02:43:36;0010;Server@node2;Job;3655.node2.supernodexp.hpc;Exit_status=0 resources_used.cpupercent=4637 resources_used.cput=08:17:45 resources_used.mem=7926060kb resources_used.ncpus=48 resources_used.vmem=47424936kb resources_used.walltime=00:10:38
02/20/2018 02:43:36;0100;Server@node2;Job;3655.node2.supernodexp.hpc;dequeuing from workq, state 5
02/20/2018 02:43:36;0040;Server@node2;Svr;node2.supernodexp.hpc;Scheduler sent command 2
02/20/2018 02:43:36;0040;Server@node2;Svr;node2.supernodexp.hpc;Scheduler sent command 0
02/20/2018 02:43:36;0100;Server@node2;Req;;Type 21 request received from Scheduler@node2.supernodexp.hpc, sock=16
02/20/2018 02:43:36;0100;Server@node2;Req;;Type 81 request received from Scheduler@node2.supernodexp.hpc, sock=16
02/20/2018 02:43:36;0100;Server@node2;Req;;Type 71 request received from Scheduler@node2.supernodexp.hpc, sock=16
02/20/2018 02:43:36;0100;Server@node2;Req;;Type 58 request received from Scheduler@node2.supernodexp.hpc, sock=16
02/20/2018 02:43:36;0100;Server@node2;Req;;Type 20 request received from Scheduler@node2.supernodexp.hpc, sock=16
02/20/2018 02:43:36;0100;Server@node2;Req;;Type 51 request received from Scheduler@node2.supernodexp.hpc, sock=16
02/20/2018 02:43:36;0100;Server@node2;Req;;Type 23 request received from Scheduler@node2.supernodexp.hpc, sock=16
02/20/2018 02:43:36;0008;Server@node2;Job;3689.node2.supernodexp.hpc;Job Run at request of Scheduler@node2.supernodexp.hpc on exec_vnode (node13:ncpus=48:mem=5242880kb)
02/20/2018 02:43:36;0001;Server@node2;Svr;Server@node2;Success (0) in req_runjob2, return value of svr_startjob is 0
02/20/2018 02:43:36;0100;Server@node2;Req;;Type 11 request received from Scheduler@node2.supernodexp.hpc, sock=16
02/20/2018 02:43:36;0008;Server@node2;Job;3695.node2.supernodexp.hpc;Job Modified at request of Scheduler@node2.supernodexp.hpc
02/20/2018 02:45:40;0080;Server@node2;Job;3685.node2.supernodexp.hpc;Obit received momhop:1 serverhop:1 state:4 substate:42
02/20/2018 02:45:41;0010;Server@node2;Job;3685.node2.supernodexp.hpc;Exit_status=0 resources_used.cpupercent=4740 resources_used.cput=08:06:11 resources_used.mem=7929116kb resources_used.ncpus=48 resources_used.vmem=47424528kb resources_used.walltime=00:10:21
02/20/2018 02:45:41;0100;Server@node2;Job;3685.node2.supernodexp.hpc;dequeuing from workq, state 5
02/20/2018 02:45:41;0040;Server@node2;Svr;node2.supernodexp.hpc;Scheduler sent command 2
02/20/2018 02:45:41;0040;Server@node2;Svr;node2.supernodexp.hpc;Scheduler sent command 0
02/20/2018 02:45:41;0100;Server@node2;Req;;Type 21 request received from Scheduler@node2.supernodexp.hpc, sock=16
02/20/2018 02:45:41;0100;Server@node2;Req;;Type 81 request received from Scheduler@node2.supernodexp.hpc, sock=16
02/20/2018 02:45:41;0100;Server@node2;Req;;Type 71 request received from Scheduler@node2.supernodexp.hpc, sock=16
02/20/2018 02:45:41;0100;Server@node2;Req;;Type 58 request received from Scheduler@node2.supernodexp.hpc, sock=16
02/20/2018 02:45:42;0100;Server@node2;Req;;Type 20 request received from Scheduler@node2.supernodexp.hpc, sock=16
02/20/2018 02:45:42;0100;Server@node2;Req;;Type 51 request received from Scheduler@node2.supernodexp.hpc, sock=16
02/20/2018 02:45:42;0100;Server@node2;Req;;Type 23 request received from Scheduler@node2.supernodexp.hpc, sock=16
02/20/2018 02:45:42;0008;Server@node2;Job;3695.node2.supernodexp.hpc;Job Run at request of Scheduler@node2.supernodexp.hpc on exec_vnode (node14:ncpus=48:mem=5242880kb)
02/20/2018 02:45:42;0001;Server@node2;Svr;Server@node2;Success (0) in req_runjob2, return value of svr_startjob is 0
02/20/2018 02:45:42;0100;Server@node2;Req;;Type 11 request received from Scheduler@node2.supernodexp.hpc, sock=16
02/20/2018 02:45:42;0008;Server@node2;Job;3700.node2.supernodexp.hpc;Job Modified at request of Scheduler@node2.supernodexp.hpc
02/20/2018 02:54:10;0080;Server@node2;Job;3689.node2.supernodexp.hpc;Obit received momhop:1 serverhop:1 state:4 substate:42
02/20/2018 02:54:11;0010;Server@node2;Job;3689.node2.supernodexp.hpc;Exit_status=0 resources_used.cpupercent=4740 resources_used.cput=08:16:08 resources_used.mem=7898676kb resources_used.ncpus=48 resources_used.vmem=47423988kb resources_used.walltime=00:10:34
02/20/2018 02:54:11;0100;Server@node2;Job;3689.node2.supernodexp.hpc;dequeuing from workq, state 5
02/20/2018 02:54:11;0040;Server@node2;Svr;node2.supernodexp.hpc;Scheduler sent command 2
02/20/2018 02:54:11;0040;Server@node2;Svr;node2.supernodexp.hpc;Scheduler sent command 0
02/20/2018 02:54:11;0100;Server@node2;Req;;Type 21 request received from Scheduler@node2.supernodexp.hpc, sock=16
02/20/2018 02:54:11;0100;Server@node2;Req;;Type 81 request received from Scheduler@node2.supernodexp.hpc, sock=16
02/20/2018 02:54:11;0100;Server@node2;Req;;Type 71 request received from Scheduler@node2.supernodexp.hpc, sock=16
02/20/2018 02:54:11;0100;Server@node2;Req;;Type 58 request received from Scheduler@node2.supernodexp.hpc, sock=16
02/20/2018 02:54:11;0100;Server@node2;Req;;Type 20 request received from Scheduler@node2.supernodexp.hpc, sock=16
02/20/2018 02:54:11;0100;Server@node2;Req;;Type 51 request received from Scheduler@node2.supernodexp.hpc, sock=16
02/20/2018 02:54:11;0100;Server@node2;Req;;Type 23 request received from Scheduler@node2.supernodexp.hpc, sock=16
02/20/2018 02:54:11;0008;Server@node2;Job;3700.node2.supernodexp.hpc;Job Run at request of Scheduler@node2.supernodexp.hpc on exec_vnode (node13:ncpus=48:mem=5242880kb)
02/20/2018 02:54:11;0001;Server@node2;Svr;Server@node2;Success (0) in req_runjob2, return value of svr_startjob is 0
02/20/2018 02:54:11;0100;Server@node2;Req;;Type 11 request received from Scheduler@node2.supernodexp.hpc, sock=16
02/20/2018 02:54:11;0008;Server@node2;Job;3701.node2.supernodexp.hpc;Job Modified at request of Scheduler@node2.supernodexp.hpc
02/20/2018 02:56:26;0080;Server@node2;Job;3695.node2.supernodexp.hpc;Obit received momhop:1 serverhop:1 state:4 substate:42
02/20/2018 02:56:27;0010;Server@node2;Job;3695.node2.supernodexp.hpc;Exit_status=0 resources_used.cpupercent=4742 resources_used.cput=08:13:21 resources_used.mem=7966888kb resources_used.ncpus=48 resources_used.vmem=47424056kb resources_used.walltime=00:10:44
02/20/2018 02:56:27;0100;Server@node2;Job;3695.node2.supernodexp.hpc;dequeuing from workq, state 5
02/20/2018 02:56:27;0040;Server@node2;Svr;node2.supernodexp.hpc;Scheduler sent command 2
02/20/2018 02:56:27;0040;Server@node2;Svr;node2.supernodexp.hpc;Scheduler sent command 0
02/20/2018 02:56:27;0100;Server@node2;Req;;Type 21 request received from Scheduler@node2.supernodexp.hpc, sock=16
02/20/2018 02:56:27;0100;Server@node2;Req;;Type 81 request received from Scheduler@node2.supernodexp.hpc, sock=16
02/20/2018 02:56:27;0100;Server@node2;Req;;Type 71 request received from Scheduler@node2.supernodexp.hpc, sock=16
02/20/2018 02:56:27;0100;Server@node2;Req;;Type 58 request received from Scheduler@node2.supernodexp.hpc, sock=16
02/20/2018 02:56:27;0100;Server@node2;Req;;Type 20 request received from Scheduler@node2.supernodexp.hpc, sock=16
02/20/2018 02:56:27;0100;Server@node2;Req;;Type 51 request received from Scheduler@node2.supernodexp.hpc, sock=16
02/20/2018 02:56:28;0100;Server@node2;Req;;Type 23 request received from Scheduler@node2.supernodexp.hpc, sock=16
02/20/2018 02:56:28;0008;Server@node2;Job;3701.node2.supernodexp.hpc;Job Run at request of Scheduler@node2.supernodexp.hpc on exec_vnode (node14:ncpus=48:mem=5242880kb)
02/20/2018 02:56:28;0001;Server@node2;Svr;Server@node2;Success (0) in req_runjob2, return value of svr_startjob is 0
02/20/2018 02:56:28;0100;Server@node2;Req;;Type 11 request received from Scheduler@node2.supernodexp.hpc, sock=16
02/20/2018 02:56:28;0008;Server@node2;Job;3704.node2.supernodexp.hpc;Job Modified at request of Scheduler@node2.supernodexp.hpc
02/20/2018 03:04:56;0080;Server@node2;Job;3700.node2.supernodexp.hpc;Obit received momhop:1 serverhop:1 state:4 substate:42
02/20/2018 03:04:58;0010;Server@node2;Job;3700.node2.supernodexp.hpc;Exit_status=0 resources_used.cpupercent=4745 resources_used.cput=08:17:21 resources_used.mem=7937140kb resources_used.ncpus=48 resources_used.vmem=47424600kb resources_used.walltime=00:10:45
02/20/2018 03:04:58;0100;Server@node2;Job;3700.node2.supernodexp.hpc;dequeuing from workq, state 5
02/20/2018 03:04:58;0040;Server@node2;Svr;node2.supernodexp.hpc;Scheduler sent command 2
02/20/2018 03:04:58;0040;Server@node2;Svr;node2.supernodexp.hpc;Scheduler sent command 0
02/20/2018 03:04:58;0100;Server@node2;Req;;Type 21 request received from Scheduler@node2.supernodexp.hpc, sock=16
02/20/2018 03:04:58;0100;Server@node2;Req;;Type 81 request received from Scheduler@node2.supernodexp.hpc, sock=16
02/20/2018 03:04:58;0100;Server@node2;Req;;Type 71 request received from Scheduler@node2.supernodexp.hpc, sock=16
02/20/2018 03:04:58;0100;Server@node2;Req;;Type 58 request received from Scheduler@node2.supernodexp.hpc, sock=16
02/20/2018 03:04:59;0100;Server@node2;Req;;Type 20 request received from Scheduler@node2.supernodexp.hpc, sock=16
02/20/2018 03:04:59;0100;Server@node2;Req;;Type 51 request received from Scheduler@node2.supernodexp.hpc, sock=16
02/20/2018 03:04:59;0100;Server@node2;Req;;Type 23 request received from Scheduler@node2.supernodexp.hpc, sock=16
02/20/2018 03:04:59;0008;Server@node2;Job;3704.node2.supernodexp.hpc;Job Run at request of Scheduler@node2.supernodexp.hpc on exec_vnode (node13:ncpus=48:mem=5242880kb)
02/20/2018 03:04:59;0001;Server@node2;Svr;Server@node2;Success (0) in req_runjob2, return value of svr_startjob is 0
02/20/2018 03:04:59;0100;Server@node2;Req;;Type 11 request received from Scheduler@node2.supernodexp.hpc, sock=16
02/20/2018 03:04:59;0008;Server@node2;Job;3747.node2.supernodexp.hpc;Job Modified at request of Scheduler@node2.supernodexp.hpc
02/20/2018 03:07:04;0080;Server@node2;Job;3701.node2.supernodexp.hpc;Obit received momhop:1 serverhop:1 state:4 substate:42
02/20/2018 03:07:06;0010;Server@node2;Job;3701.node2.supernodexp.hpc;Exit_status=0 resources_used.cpupercent=4739 resources_used.cput=08:17:00 resources_used.mem=7905524kb resources_used.ncpus=48 resources_used.vmem=47424532kb resources_used.walltime=00:10:36
02/20/2018 03:07:06;0100;Server@node2;Job;3701.node2.supernodexp.hpc;dequeuing from workq, state 5
02/20/2018 03:07:06;0040;Server@node2;Svr;node2.supernodexp.hpc;Scheduler sent command 2
02/20/2018 03:07:06;0040;Server@node2;Svr;node2.supernodexp.hpc;Scheduler sent command 0
02/20/2018 03:07:06;0100;Server@node2;Req;;Type 21 request received from Scheduler@node2.supernodexp.hpc, sock=16
02/20/2018 03:07:06;0100;Server@node2;Req;;Type 81 request received from Scheduler@node2.supernodexp.hpc, sock=16
02/20/2018 03:07:06;0100;Server@node2;Req;;Type 71 request received from Scheduler@node2.supernodexp.hpc, sock=16
02/20/2018 03:07:06;0100;Server@node2;Req;;Type 58 request received from Scheduler@node2.supernodexp.hpc, sock=16
02/20/2018 03:07:06;0100;Server@node2;Req;;Type 20 request received from Scheduler@node2.supernodexp.hpc, sock=16
02/20/2018 03:07:06;0100;Server@node2;Req;;Type 51 request received from Scheduler@node2.supernodexp.hpc, sock=16
02/20/2018 03:07:06;0100;Server@node2;Req;;Type 23 request received from Scheduler@node2.supernodexp.hpc, sock=16
02/20/2018 03:07:06;0008;Server@node2;Job;3747.node2.supernodexp.hpc;Job Run at request of Scheduler@node2.supernodexp.hpc on exec_vnode (node14:ncpus=48:mem=5242880kb)
02/20/2018 03:07:06;0001;Server@node2;Svr;Server@node2;Success (0) in req_runjob2, return value of svr_startjob is 0
02/20/2018 03:07:06;0100;Server@node2;Req;;Type 11 request received from Scheduler@node2.supernodexp.hpc, sock=16
02/20/2018 03:07:06;0008;Server@node2;Job;3749.node2.supernodexp.hpc;Job Modified at request of Scheduler@node2.supernodexp.hpc
02/20/2018 03:15:40;0080;Server@node2;Job;3704.node2.supernodexp.hpc;Obit received momhop:1 serverhop:1 state:4 substate:42
02/20/2018 03:15:41;0010;Server@node2;Job;3704.node2.supernodexp.hpc;Exit_status=0 resources_used.cpupercent=4733 resources_used.cput=08:16:50 resources_used.mem=7920492kb resources_used.ncpus=48 resources_used.vmem=47424644kb resources_used.walltime=00:10:41
02/20/2018 03:15:41;0100;Server@node2;Job;3704.node2.supernodexp.hpc;dequeuing from workq, state 5
02/20/2018 03:15:41;0040;Server@node2;Svr;node2.supernodexp.hpc;Scheduler sent command 2
02/20/2018 03:15:41;0040;Server@node2;Svr;node2.supernodexp.hpc;Scheduler sent command 0
02/20/2018 03:15:41;0100;Server@node2;Req;;Type 21 request received from Scheduler@node2.supernodexp.hpc, sock=16
02/20/2018 03:15:41;0100;Server@node2;Req;;Type 81 request received from Scheduler@node2.supernodexp.hpc, sock=16
02/20/2018 03:15:41;0100;Server@node2;Req;;Type 71 request received from Scheduler@node2.supernodexp.hpc, sock=16
02/20/2018 03:15:41;0100;Server@node2;Req;;Type 58 request received from Scheduler@node2.supernodexp.hpc, sock=16
02/20/2018 03:15:41;0100;Server@node2;Req;;Type 20 request received from Scheduler@node2.supernodexp.hpc, sock=16
02/20/2018 03:15:41;0100;Server@node2;Req;;Type 51 request received from Scheduler@node2.supernodexp.hpc, sock=16
02/20/2018 03:15:42;0100;Server@node2;Req;;Type 23 request received from Scheduler@node2.supernodexp.hpc, sock=16
02/20/2018 03:15:42;0008;Server@node2;Job;3749.node2.supernodexp.hpc;Job Run at request of Scheduler@node2.supernodexp.hpc on exec_vnode (node13:ncpus=48:mem=5242880kb)
02/20/2018 03:15:42;0001;Server@node2;Svr;Server@node2;Success (0) in req_runjob2, return value of svr_startjob is 0
02/20/2018 03:15:42;0100;Server@node2;Req;;Type 11 request received from Scheduler@node2.supernodexp.hpc, sock=16
02/20/2018 03:15:42;0008;Server@node2;Job;3761.node2.supernodexp.hpc;Job Modified at request of Scheduler@node2.supernodexp.hpc
02/20/2018 03:17:46;0080;Server@node2;Job;3747.node2.supernodexp.hpc;Obit received momhop:1 serverhop:1 state:4 substate:42
02/20/2018 03:17:48;0010;Server@node2;Job;3747.node2.supernodexp.hpc;Exit_status=0 resources_used.cpupercent=4749 resources_used.cput=08:21:31 resources_used.mem=7914280kb resources_used.ncpus=48 resources_used.vmem=47424436kb resources_used.walltime=00:10:41
02/20/2018 03:17:48;0100;Server@node2;Job;3747.node2.supernodexp.hpc;dequeuing from workq, state 5
02/20/2018 03:17:48;0040;Server@node2;Svr;node2.supernodexp.hpc;Scheduler sent command 2
02/20/2018 03:17:48;0040;Server@node2;Svr;node2.supernodexp.hpc;Scheduler sent command 0
02/20/2018 03:17:48;0100;Server@node2;Req;;Type 21 request received from Scheduler@node2.supernodexp.hpc, sock=16
02/20/2018 03:17:48;0100;Server@node2;Req;;Type 81 request received from Scheduler@node2.supernodexp.hpc, sock=16
02/20/2018 03:17:48;0100;Server@node2;Req;;Type 71 request received from Scheduler@node2.supernodexp.hpc, sock=16
02/20/2018 03:17:48;0100;Server@node2;Req;;Type 58 request received from Scheduler@node2.supernodexp.hpc, sock=16
02/20/2018 03:17:48;0100;Server@node2;Req;;Type 20 request received from Scheduler@node2.supernodexp.hpc, sock=16
02/20/2018 03:17:48;0100;Server@node2;Req;;Type 51 request received from Scheduler@node2.supernodexp.hpc, sock=16
02/20/2018 03:17:49;0100;Server@node2;Req;;Type 23 request received from Scheduler@node2.supernodexp.hpc, sock=16
02/20/2018 03:17:49;0008;Server@node2;Job;3761.node2.supernodexp.hpc;Job Run at request of Scheduler@node2.supernodexp.hpc on exec_vnode (node14:ncpus=48:mem=5242880kb)
02/20/2018 03:17:49;0001;Server@node2;Svr;Server@node2;Success (0) in req_runjob2, return value of svr_startjob is 0
02/20/2018 03:17:49;0100;Server@node2;Req;;Type 11 request received from Scheduler@node2.supernodexp.hpc, sock=16
02/20/2018 03:17:49;0008;Server@node2;Job;3786.node2.supernodexp.hpc;Job Modified at request of Scheduler@node2.supernodexp.hpc
02/20/2018 03:26:25;0080;Server@node2;Job;3749.node2.supernodexp.hpc;Obit received momhop:1 serverhop:1 state:4 substate:42
02/20/2018 03:26:27;0010;Server@node2;Job;3749.node2.supernodexp.hpc;Exit_status=0 resources_used.cpupercent=4735 resources_used.cput=08:23:24 resources_used.mem=7900748kb resources_used.ncpus=48 resources_used.vmem=47424640kb resources_used.walltime=00:10:43
02/20/2018 03:26:27;0100;Server@node2;Job;3749.node2.supernodexp.hpc;dequeuing from workq, state 5
02/20/2018 03:26:27;0040;Server@node2;Svr;node2.supernodexp.hpc;Scheduler sent command 2
02/20/2018 03:26:27;0040;Server@node2;Svr;node2.supernodexp.hpc;Scheduler sent command 0
02/20/2018 03:26:27;0100;Server@node2;Req;;Type 21 request received from Scheduler@node2.supernodexp.hpc, sock=16
02/20/2018 03:26:27;0100;Server@node2;Req;;Type 81 request received from Scheduler@node2.supernodexp.hpc, sock=16
02/20/2018 03:26:27;0100;Server@node2;Req;;Type 71 request received from Scheduler@node2.supernodexp.hpc, sock=16
02/20/2018 03:26:27;0100;Server@node2;Req;;Type 58 request received from Scheduler@node2.supernodexp.hpc, sock=16
02/20/2018 03:26:27;0100;Server@node2;Req;;Type 20 request received from Scheduler@node2.supernodexp.hpc, sock=16
02/20/2018 03:26:27;0100;Server@node2;Req;;Type 51 request received from Scheduler@node2.supernodexp.hpc, sock=16
02/20/2018 03:26:27;0100;Server@node2;Req;;Type 23 request received from Scheduler@node2.supernodexp.hpc, sock=16
02/20/2018 03:26:27;0008;Server@node2;Job;3786.node2.supernodexp.hpc;Job Run at request of Scheduler@node2.supernodexp.hpc on exec_vnode (node13:ncpus=48:mem=5242880kb)
02/20/2018 03:26:27;0001;Server@node2;Svr;Server@node2;Success (0) in req_runjob2, return value of svr_startjob is 0
02/20/2018 03:26:27;0100;Server@node2;Req;;Type 11 request received from Scheduler@node2.supernodexp.hpc, sock=16
02/20/2018 03:26:27;0008;Server@node2;Job;3801.node2.supernodexp.hpc;Job Modified at request of Scheduler@node2.supernodexp.hpc
02/20/2018 03:27:55;0100;Server@node2;Req;;Type 0 request received from ctminh@node2.supernodexp.hpc, sock=16
02/20/2018 03:27:55;0100;Server@node2;Req;;Type 49 request received from ctminh@node2.supernodexp.hpc, sock=20
02/20/2018 03:27:55;0100;Server@node2;Req;;Type 21 request received from ctminh@node2.supernodexp.hpc, sock=16
02/20/2018 03:27:55;0100;Server@node2;Req;;Type 19 request received from ctminh@node2.supernodexp.hpc, sock=16
02/20/2018 03:28:26;0080;Server@node2;Job;3761.node2.supernodexp.hpc;Obit received momhop:1 serverhop:1 state:4 substate:42
02/20/2018 03:28:28;0010;Server@node2;Job;3761.node2.supernodexp.hpc;Exit_status=0 resources_used.cpupercent=4738 resources_used.cput=08:17:34 resources_used.mem=7878708kb resources_used.ncpus=48 resources_used.vmem=47424076kb resources_used.walltime=00:10:38
02/20/2018 03:28:28;0100;Server@node2;Job;3761.node2.supernodexp.hpc;dequeuing from workq, state 5
02/20/2018 03:28:28;0040;Server@node2;Svr;node2.supernodexp.hpc;Scheduler sent command 2
02/20/2018 03:28:28;0040;Server@node2;Svr;node2.supernodexp.hpc;Scheduler sent command 0
02/20/2018 03:28:28;0100;Server@node2;Req;;Type 21 request received from Scheduler@node2.supernodexp.hpc, sock=16
02/20/2018 03:28:28;0100;Server@node2;Req;;Type 81 request received from Scheduler@node2.supernodexp.hpc, sock=16
02/20/2018 03:28:28;0100;Server@node2;Req;;Type 71 request received from Scheduler@node2.supernodexp.hpc, sock=16
02/20/2018 03:28:28;0100;Server@node2;Req;;Type 58 request received from Scheduler@node2.supernodexp.hpc, sock=16
02/20/2018 03:28:28;0100;Server@node2;Req;;Type 20 request received from Scheduler@node2.supernodexp.hpc, sock=16
02/20/2018 03:28:28;0100;Server@node2;Req;;Type 51 request received from Scheduler@node2.supernodexp.hpc, sock=16
02/20/2018 03:28:28;0100;Server@node2;Req;;Type 23 request received from Scheduler@node2.supernodexp.hpc, sock=16
02/20/2018 03:28:28;0008;Server@node2;Job;3801.node2.supernodexp.hpc;Job Run at request of Scheduler@node2.supernodexp.hpc on exec_vnode (node14:ncpus=48:mem=5242880kb)
02/20/2018 03:28:28;0001;Server@node2;Svr;Server@node2;Success (0) in req_runjob2, return value of svr_startjob is 0
02/20/2018 03:28:28;0100;Server@node2;Req;;Type 11 request received from Scheduler@node2.supernodexp.hpc, sock=16
02/20/2018 03:28:28;0008;Server@node2;Job;3832.node2.supernodexp.hpc;Job Modified at request of Scheduler@node2.supernodexp.hpc
02/20/2018 03:37:15;0080;Server@node2;Job;3786.node2.supernodexp.hpc;Obit received momhop:1 serverhop:1 state:4 substate:42
02/20/2018 03:37:17;0010;Server@node2;Job;3786.node2.supernodexp.hpc;Exit_status=0 resources_used.cpupercent=4744 resources_used.cput=08:20:35 resources_used.mem=7863224kb resources_used.ncpus=48 resources_used.vmem=47424928kb resources_used.walltime=00:10:48
02/20/2018 03:37:17;0100;Server@node2;Job;3786.node2.supernodexp.hpc;dequeuing from workq, state 5
02/20/2018 03:37:17;0040;Server@node2;Svr;node2.supernodexp.hpc;Scheduler sent command 2
02/20/2018 03:37:17;0040;Server@node2;Svr;node2.supernodexp.hpc;Scheduler sent command 0
02/20/2018 03:37:17;0100;Server@node2;Req;;Type 21 request received from Scheduler@node2.supernodexp.hpc, sock=16
02/20/2018 03:37:17;0100;Server@node2;Req;;Type 81 request received from Scheduler@node2.supernodexp.hpc, sock=16
02/20/2018 03:37:17;0100;Server@node2;Req;;Type 71 request received from Scheduler@node2.supernodexp.hpc, sock=16
02/20/2018 03:37:17;0100;Server@node2;Req;;Type 58 request received from Scheduler@node2.supernodexp.hpc, sock=16
02/20/2018 03:37:17;0100;Server@node2;Req;;Type 20 request received from Scheduler@node2.supernodexp.hpc, sock=16
02/20/2018 03:37:17;0100;Server@node2;Req;;Type 51 request received from Scheduler@node2.supernodexp.hpc, sock=16
02/20/2018 03:37:17;0100;Server@node2;Req;;Type 23 request received from Scheduler@node2.supernodexp.hpc, sock=16
02/20/2018 03:37:17;0008;Server@node2;Job;3832.node2.supernodexp.hpc;Job Run at request of Scheduler@node2.supernodexp.hpc on exec_vnode (node13:ncpus=48:mem=5242880kb)
02/20/2018 03:37:17;0001;Server@node2;Svr;Server@node2;Success (0) in req_runjob2, return value of svr_startjob is 0
02/20/2018 03:37:17;0100;Server@node2;Req;;Type 11 request received from Scheduler@node2.supernodexp.hpc, sock=16
02/20/2018 03:37:17;0008;Server@node2;Job;3855.node2.supernodexp.hpc;Job Modified at request of Scheduler@node2.supernodexp.hpc
02/20/2018 03:39:16;0080;Server@node2;Job;3801.node2.supernodexp.hpc;Obit received momhop:1 serverhop:1 state:4 substate:42
02/20/2018 03:39:18;0010;Server@node2;Job;3801.node2.supernodexp.hpc;Exit_status=0 resources_used.cpupercent=4742 resources_used.cput=08:19:43 resources_used.mem=7913112kb resources_used.ncpus=48 resources_used.vmem=47423888kb resources_used.walltime=00:10:49
02/20/2018 03:39:18;0100;Server@node2;Job;3801.node2.supernodexp.hpc;dequeuing from workq, state 5
02/20/2018 03:39:18;0040;Server@node2;Svr;node2.supernodexp.hpc;Scheduler sent command 2
02/20/2018 03:39:18;0040;Server@node2;Svr;node2.supernodexp.hpc;Scheduler sent command 0
02/20/2018 03:39:18;0100;Server@node2;Req;;Type 21 request received from Scheduler@node2.supernodexp.hpc, sock=16
02/20/2018 03:39:18;0100;Server@node2;Req;;Type 81 request received from Scheduler@node2.supernodexp.hpc, sock=16
02/20/2018 03:39:18;0100;Server@node2;Req;;Type 71 request received from Scheduler@node2.supernodexp.hpc, sock=16
02/20/2018 03:39:18;0100;Server@node2;Req;;Type 58 request received from Scheduler@node2.supernodexp.hpc, sock=16
02/20/2018 03:39:18;0100;Server@node2;Req;;Type 20 request received from Scheduler@node2.supernodexp.hpc, sock=16
02/20/2018 03:39:18;0100;Server@node2;Req;;Type 51 request received from Scheduler@node2.supernodexp.hpc, sock=16
02/20/2018 03:39:18;0100;Server@node2;Req;;Type 23 request received from Scheduler@node2.supernodexp.hpc, sock=16
02/20/2018 03:39:18;0008;Server@node2;Job;3855.node2.supernodexp.hpc;Job Run at request of Scheduler@node2.supernodexp.hpc on exec_vnode (node14:ncpus=48:mem=5242880kb)
02/20/2018 03:39:18;0001;Server@node2;Svr;Server@node2;Success (0) in req_runjob2, return value of svr_startjob is 0
02/20/2018 03:39:18;0100;Server@node2;Req;;Type 11 request received from Scheduler@node2.supernodexp.hpc, sock=16
02/20/2018 03:39:18;0008;Server@node2;Job;3883.node2.supernodexp.hpc;Job Modified at request of Scheduler@node2.supernodexp.hpc
02/20/2018 03:47:59;0080;Server@node2;Job;3832.node2.supernodexp.hpc;Obit received momhop:1 serverhop:1 state:4 substate:42
02/20/2018 03:48:01;0010;Server@node2;Job;3832.node2.supernodexp.hpc;Exit_status=0 resources_used.cpupercent=4745 resources_used.cput=08:22:51 resources_used.mem=7874696kb resources_used.ncpus=48 resources_used.vmem=47424284kb resources_used.walltime=00:10:42
02/20/2018 03:48:01;0100;Server@node2;Job;3832.node2.supernodexp.hpc;dequeuing from workq, state 5
02/20/2018 03:48:01;0040;Server@node2;Svr;node2.supernodexp.hpc;Scheduler sent command 2
02/20/2018 03:48:01;0040;Server@node2;Svr;node2.supernodexp.hpc;Scheduler sent command 0
02/20/2018 03:48:01;0100;Server@node2;Req;;Type 21 request received from Scheduler@node2.supernodexp.hpc, sock=16
02/20/2018 03:48:01;0100;Server@node2;Req;;Type 81 request received from Scheduler@node2.supernodexp.hpc, sock=16
02/20/2018 03:48:01;0100;Server@node2;Req;;Type 71 request received from Scheduler@node2.supernodexp.hpc, sock=16
02/20/2018 03:48:01;0100;Server@node2;Req;;Type 58 request received from Scheduler@node2.supernodexp.hpc, sock=16
02/20/2018 03:48:01;0100;Server@node2;Req;;Type 20 request received from Scheduler@node2.supernodexp.hpc, sock=16
02/20/2018 03:48:01;0100;Server@node2;Req;;Type 51 request received from Scheduler@node2.supernodexp.hpc, sock=16
02/20/2018 03:48:01;0100;Server@node2;Req;;Type 23 request received from Scheduler@node2.supernodexp.hpc, sock=16
02/20/2018 03:48:01;0008;Server@node2;Job;3883.node2.supernodexp.hpc;Job Run at request of Scheduler@node2.supernodexp.hpc on exec_vnode (node13:ncpus=48:mem=5242880kb)
02/20/2018 03:48:01;0001;Server@node2;Svr;Server@node2;Success (0) in req_runjob2, return value of svr_startjob is 0
02/20/2018 03:48:01;0100;Server@node2;Req;;Type 11 request received from Scheduler@node2.supernodexp.hpc, sock=16
02/20/2018 03:48:01;0008;Server@node2;Job;3896.node2.supernodexp.hpc;Job Modified at request of Scheduler@node2.supernodexp.hpc
02/20/2018 03:49:53;0080;Server@node2;Job;3855.node2.supernodexp.hpc;Obit received momhop:1 serverhop:1 state:4 substate:42
02/20/2018 03:49:54;0010;Server@node2;Job;3855.node2.supernodexp.hpc;Exit_status=0 resources_used.cpupercent=4734 resources_used.cput=08:16:21 resources_used.mem=7961092kb resources_used.ncpus=48 resources_used.vmem=47424528kb resources_used.walltime=00:10:35
02/20/2018 03:49:54;0100;Server@node2;Job;3855.node2.supernodexp.hpc;dequeuing from workq, state 5
02/20/2018 03:49:54;0040;Server@node2;Svr;node2.supernodexp.hpc;Scheduler sent command 2
02/20/2018 03:49:54;0040;Server@node2;Svr;node2.supernodexp.hpc;Scheduler sent command 0
02/20/2018 03:49:54;0100;Server@node2;Req;;Type 21 request received from Scheduler@node2.supernodexp.hpc, sock=16
02/20/2018 03:49:54;0100;Server@node2;Req;;Type 81 request received from Scheduler@node2.supernodexp.hpc, sock=16
02/20/2018 03:49:54;0100;Server@node2;Req;;Type 71 request received from Scheduler@node2.supernodexp.hpc, sock=16
02/20/2018 03:49:54;0100;Server@node2;Req;;Type 58 request received from Scheduler@node2.supernodexp.hpc, sock=16
02/20/2018 03:49:54;0100;Server@node2;Req;;Type 20 request received from Scheduler@node2.supernodexp.hpc, sock=16
02/20/2018 03:49:54;0100;Server@node2;Req;;Type 51 request received from Scheduler@node2.supernodexp.hpc, sock=16
02/20/2018 03:49:55;0100;Server@node2;Req;;Type 23 request received from Scheduler@node2.supernodexp.hpc, sock=16
02/20/2018 03:49:55;0008;Server@node2;Job;3896.node2.supernodexp.hpc;Job Run at request of Scheduler@node2.supernodexp.hpc on exec_vnode (node14:ncpus=48:mem=5242880kb)
02/20/2018 03:49:55;0001;Server@node2;Svr;Server@node2;Success (0) in req_runjob2, return value of svr_startjob is 0
02/20/2018 03:49:55;0100;Server@node2;Req;;Type 11 request received from Scheduler@node2.supernodexp.hpc, sock=16
02/20/2018 03:49:55;0008;Server@node2;Job;3929.node2.supernodexp.hpc;Job Modified at request of Scheduler@node2.supernodexp.hpc
02/20/2018 03:58:46;0080;Server@node2;Job;3883.node2.supernodexp.hpc;Obit received momhop:1 serverhop:1 state:4 substate:42
02/20/2018 03:58:47;0010;Server@node2;Job;3883.node2.supernodexp.hpc;Exit_status=0 resources_used.cpupercent=4745 resources_used.cput=08:18:55 resources_used.mem=7935828kb resources_used.ncpus=48 resources_used.vmem=47424640kb resources_used.walltime=00:10:45
02/20/2018 03:58:47;0100;Server@node2;Job;3883.node2.supernodexp.hpc;dequeuing from workq, state 5
02/20/2018 03:58:47;0040;Server@node2;Svr;node2.supernodexp.hpc;Scheduler sent command 2
02/20/2018 03:58:47;0040;Server@node2;Svr;node2.supernodexp.hpc;Scheduler sent command 0
02/20/2018 03:58:47;0100;Server@node2;Req;;Type 21 request received from Scheduler@node2.supernodexp.hpc, sock=16
02/20/2018 03:58:47;0100;Server@node2;Req;;Type 81 request received from Scheduler@node2.supernodexp.hpc, sock=16
02/20/2018 03:58:47;0100;Server@node2;Req;;Type 71 request received from Scheduler@node2.supernodexp.hpc, sock=16
02/20/2018 03:58:47;0100;Server@node2;Req;;Type 58 request received from Scheduler@node2.supernodexp.hpc, sock=16
02/20/2018 03:58:47;0100;Server@node2;Req;;Type 20 request received from Scheduler@node2.supernodexp.hpc, sock=16
02/20/2018 03:58:47;0100;Server@node2;Req;;Type 51 request received from Scheduler@node2.supernodexp.hpc, sock=16
02/20/2018 03:58:48;0100;Server@node2;Req;;Type 23 request received from Scheduler@node2.supernodexp.hpc, sock=16
02/20/2018 03:58:48;0008;Server@node2;Job;3929.node2.supernodexp.hpc;Job Run at request of Scheduler@node2.supernodexp.hpc on exec_vnode (node13:ncpus=48:mem=5242880kb)
02/20/2018 03:58:48;0001;Server@node2;Svr;Server@node2;Success (0) in req_runjob2, return value of svr_startjob is 0
02/20/2018 03:58:48;0100;Server@node2;Req;;Type 11 request received from Scheduler@node2.supernodexp.hpc, sock=16
02/20/2018 03:58:48;0008;Server@node2;Job;3937.node2.supernodexp.hpc;Job Modified at request of Scheduler@node2.supernodexp.hpc
02/20/2018 04:00:35;0080;Server@node2;Job;3896.node2.supernodexp.hpc;Obit received momhop:1 serverhop:1 state:4 substate:42
02/20/2018 04:00:37;0010;Server@node2;Job;3896.node2.supernodexp.hpc;Exit_status=0 resources_used.cpupercent=4739 resources_used.cput=08:21:06 resources_used.mem=7927368kb resources_used.ncpus=48 resources_used.vmem=47423800kb resources_used.walltime=00:10:40
02/20/2018 04:00:37;0100;Server@node2;Job;3896.node2.supernodexp.hpc;dequeuing from workq, state 5
02/20/2018 04:00:37;0040;Server@node2;Svr;node2.supernodexp.hpc;Scheduler sent command 2
02/20/2018 04:00:37;0040;Server@node2;Svr;node2.supernodexp.hpc;Scheduler sent command 0
02/20/2018 04:00:37;0100;Server@node2;Req;;Type 21 request received from Scheduler@node2.supernodexp.hpc, sock=16
02/20/2018 04:00:37;0100;Server@node2;Req;;Type 81 request received from Scheduler@node2.supernodexp.hpc, sock=16
02/20/2018 04:00:37;0100;Server@node2;Req;;Type 71 request received from Scheduler@node2.supernodexp.hpc, sock=16
02/20/2018 04:00:37;0100;Server@node2;Req;;Type 58 request received from Scheduler@node2.supernodexp.hpc, sock=16
02/20/2018 04:00:37;0100;Server@node2;Req;;Type 20 request received from Scheduler@node2.supernodexp.hpc, sock=16
02/20/2018 04:00:37;0100;Server@node2;Req;;Type 51 request received from Scheduler@node2.supernodexp.hpc, sock=16
02/20/2018 04:00:37;0100;Server@node2;Req;;Type 23 request received from Scheduler@node2.supernodexp.hpc, sock=16
02/20/2018 04:00:37;0008;Server@node2;Job;3937.node2.supernodexp.hpc;Job Run at request of Scheduler@node2.supernodexp.hpc on exec_vnode (node14:ncpus=48:mem=5242880kb)
02/20/2018 04:00:37;0001;Server@node2;Svr;Server@node2;Success (0) in req_runjob2, return value of svr_startjob is 0
02/20/2018 04:00:37;0100;Server@node2;Req;;Type 11 request received from Scheduler@node2.supernodexp.hpc, sock=16
02/20/2018 04:00:37;0008;Server@node2;Job;3950.node2.supernodexp.hpc;Job Modified at request of Scheduler@node2.supernodexp.hpc
02/20/2018 04:09:25;0080;Server@node2;Job;3929.node2.supernodexp.hpc;Obit received momhop:1 serverhop:1 state:4 substate:42
02/20/2018 04:09:27;0010;Server@node2;Job;3929.node2.supernodexp.hpc;Exit_status=0 resources_used.cpupercent=4746 resources_used.cput=08:19:15 resources_used.mem=7873404kb resources_used.ncpus=48 resources_used.vmem=47424624kb resources_used.walltime=00:10:38
02/20/2018 04:09:27;0100;Server@node2;Job;3929.node2.supernodexp.hpc;dequeuing from workq, state 5
02/20/2018 04:09:27;0040;Server@node2;Svr;node2.supernodexp.hpc;Scheduler sent command 2
02/20/2018 04:09:27;0040;Server@node2;Svr;node2.supernodexp.hpc;Scheduler sent command 0
02/20/2018 04:09:27;0100;Server@node2;Req;;Type 21 request received from Scheduler@node2.supernodexp.hpc, sock=16
02/20/2018 04:09:27;0100;Server@node2;Req;;Type 81 request received from Scheduler@node2.supernodexp.hpc, sock=16
02/20/2018 04:09:27;0100;Server@node2;Req;;Type 71 request received from Scheduler@node2.supernodexp.hpc, sock=16
02/20/2018 04:09:27;0100;Server@node2;Req;;Type 58 request received from Scheduler@node2.supernodexp.hpc, sock=16
02/20/2018 04:09:27;0100;Server@node2;Req;;Type 20 request received from Scheduler@node2.supernodexp.hpc, sock=16
02/20/2018 04:09:27;0100;Server@node2;Req;;Type 51 request received from Scheduler@node2.supernodexp.hpc, sock=16
02/20/2018 04:09:27;0100;Server@node2;Req;;Type 23 request received from Scheduler@node2.supernodexp.hpc, sock=16
02/20/2018 04:09:27;0008;Server@node2;Job;3950.node2.supernodexp.hpc;Job Run at request of Scheduler@node2.supernodexp.hpc on exec_vnode (node13:ncpus=48:mem=5242880kb)
02/20/2018 04:09:27;0001;Server@node2;Svr;Server@node2;Success (0) in req_runjob2, return value of svr_startjob is 0
02/20/2018 04:09:27;0100;Server@node2;Req;;Type 11 request received from Scheduler@node2.supernodexp.hpc, sock=16
02/20/2018 04:09:27;0008;Server@node2;Job;3954.node2.supernodexp.hpc;Job Modified at request of Scheduler@node2.supernodexp.hpc
02/20/2018 04:11:07;0080;Server@node2;Job;3937.node2.supernodexp.hpc;Obit received momhop:1 serverhop:1 state:4 substate:42
02/20/2018 04:11:08;0010;Server@node2;Job;3937.node2.supernodexp.hpc;Exit_status=0 resources_used.cpupercent=4744 resources_used.cput=08:13:47 resources_used.mem=7953556kb resources_used.ncpus=48 resources_used.vmem=47424188kb resources_used.walltime=00:10:30
02/20/2018 04:11:08;0100;Server@node2;Job;3937.node2.supernodexp.hpc;dequeuing from workq, state 5
02/20/2018 04:11:08;0040;Server@node2;Svr;node2.supernodexp.hpc;Scheduler sent command 2
02/20/2018 04:11:08;0040;Server@node2;Svr;node2.supernodexp.hpc;Scheduler sent command 0
02/20/2018 04:11:08;0100;Server@node2;Req;;Type 21 request received from Scheduler@node2.supernodexp.hpc, sock=16
02/20/2018 04:11:08;0100;Server@node2;Req;;Type 81 request received from Scheduler@node2.supernodexp.hpc, sock=16
02/20/2018 04:11:08;0100;Server@node2;Req;;Type 71 request received from Scheduler@node2.supernodexp.hpc, sock=16
02/20/2018 04:11:08;0100;Server@node2;Req;;Type 58 request received from Scheduler@node2.supernodexp.hpc, sock=16
02/20/2018 04:11:09;0100;Server@node2;Req;;Type 20 request received from Scheduler@node2.supernodexp.hpc, sock=16
02/20/2018 04:11:09;0100;Server@node2;Req;;Type 51 request received from Scheduler@node2.supernodexp.hpc, sock=16
02/20/2018 04:11:09;0100;Server@node2;Req;;Type 23 request received from Scheduler@node2.supernodexp.hpc, sock=16
02/20/2018 04:11:09;0008;Server@node2;Job;3954.node2.supernodexp.hpc;Job Run at request of Scheduler@node2.supernodexp.hpc on exec_vnode (node14:ncpus=48:mem=5242880kb)
02/20/2018 04:11:09;0001;Server@node2;Svr;Server@node2;Success (0) in req_runjob2, return value of svr_startjob is 0
02/20/2018 04:11:09;0100;Server@node2;Req;;Type 11 request received from Scheduler@node2.supernodexp.hpc, sock=16
02/20/2018 04:11:09;0008;Server@node2;Job;3963.node2.supernodexp.hpc;Job Modified at request of Scheduler@node2.supernodexp.hpc
02/20/2018 04:20:20;0080;Server@node2;Job;3950.node2.supernodexp.hpc;Obit received momhop:1 serverhop:1 state:4 substate:42
02/20/2018 04:20:22;0010;Server@node2;Job;3950.node2.supernodexp.hpc;Exit_status=0 resources_used.cpupercent=4746 resources_used.cput=08:23:15 resources_used.mem=7899872kb resources_used.ncpus=48 resources_used.vmem=47424628kb resources_used.walltime=00:10:53
02/20/2018 04:20:22;0100;Server@node2;Job;3950.node2.supernodexp.hpc;dequeuing from workq, state 5
02/20/2018 04:20:22;0040;Server@node2;Svr;node2.supernodexp.hpc;Scheduler sent command 2
02/20/2018 04:20:22;0040;Server@node2;Svr;node2.supernodexp.hpc;Scheduler sent command 0
02/20/2018 04:20:22;0100;Server@node2;Req;;Type 21 request received from Scheduler@node2.supernodexp.hpc, sock=16
02/20/2018 04:20:22;0100;Server@node2;Req;;Type 81 request received from Scheduler@node2.supernodexp.hpc, sock=16
02/20/2018 04:20:22;0100;Server@node2;Req;;Type 71 request received from Scheduler@node2.supernodexp.hpc, sock=16
02/20/2018 04:20:22;0100;Server@node2;Req;;Type 58 request received from Scheduler@node2.supernodexp.hpc, sock=16
02/20/2018 04:20:22;0100;Server@node2;Req;;Type 20 request received from Scheduler@node2.supernodexp.hpc, sock=16
02/20/2018 04:20:22;0100;Server@node2;Req;;Type 51 request received from Scheduler@node2.supernodexp.hpc, sock=16
02/20/2018 04:20:22;0100;Server@node2;Req;;Type 23 request received from Scheduler@node2.supernodexp.hpc, sock=16
02/20/2018 04:20:22;0008;Server@node2;Job;3963.node2.supernodexp.hpc;Job Run at request of Scheduler@node2.supernodexp.hpc on exec_vnode (node13:ncpus=48:mem=5242880kb)
02/20/2018 04:20:22;0001;Server@node2;Svr;Server@node2;Success (0) in req_runjob2, return value of svr_startjob is 0
02/20/2018 04:20:22;0100;Server@node2;Req;;Type 11 request received from Scheduler@node2.supernodexp.hpc, sock=16
02/20/2018 04:20:22;0008;Server@node2;Job;3970.node2.supernodexp.hpc;Job Modified at request of Scheduler@node2.supernodexp.hpc
02/20/2018 04:21:51;0080;Server@node2;Job;3954.node2.supernodexp.hpc;Obit received momhop:1 serverhop:1 state:4 substate:42
02/20/2018 04:21:52;0010;Server@node2;Job;3954.node2.supernodexp.hpc;Exit_status=0 resources_used.cpupercent=4738 resources_used.cput=08:13:20 resources_used.mem=7959160kb resources_used.ncpus=48 resources_used.vmem=47424200kb resources_used.walltime=00:10:42
02/20/2018 04:21:52;0100;Server@node2;Job;3954.node2.supernodexp.hpc;dequeuing from workq, state 5
02/20/2018 04:21:52;0040;Server@node2;Svr;node2.supernodexp.hpc;Scheduler sent command 2
02/20/2018 04:21:52;0040;Server@node2;Svr;node2.supernodexp.hpc;Scheduler sent command 0
02/20/2018 04:21:52;0100;Server@node2;Req;;Type 21 request received from Scheduler@node2.supernodexp.hpc, sock=16
02/20/2018 04:21:52;0100;Server@node2;Req;;Type 81 request received from Scheduler@node2.supernodexp.hpc, sock=16
02/20/2018 04:21:52;0100;Server@node2;Req;;Type 71 request received from Scheduler@node2.supernodexp.hpc, sock=16
02/20/2018 04:21:52;0100;Server@node2;Req;;Type 58 request received from Scheduler@node2.supernodexp.hpc, sock=16
02/20/2018 04:21:52;0100;Server@node2;Req;;Type 20 request received from Scheduler@node2.supernodexp.hpc, sock=16
02/20/2018 04:21:52;0100;Server@node2;Req;;Type 51 request received from Scheduler@node2.supernodexp.hpc, sock=16
02/20/2018 04:21:53;0100;Server@node2;Req;;Type 23 request received from Scheduler@node2.supernodexp.hpc, sock=16
02/20/2018 04:21:53;0008;Server@node2;Job;3970.node2.supernodexp.hpc;Job Run at request of Scheduler@node2.supernodexp.hpc on exec_vnode (node14:ncpus=48:mem=5242880kb)
02/20/2018 04:21:53;0001;Server@node2;Svr;Server@node2;Success (0) in req_runjob2, return value of svr_startjob is 0
02/20/2018 04:21:53;0100;Server@node2;Req;;Type 11 request received from Scheduler@node2.supernodexp.hpc, sock=16
02/20/2018 04:21:53;0008;Server@node2;Job;3977.node2.supernodexp.hpc;Job Modified at request of Scheduler@node2.supernodexp.hpc
02/20/2018 04:31:07;0080;Server@node2;Job;3963.node2.supernodexp.hpc;Obit received momhop:1 serverhop:1 state:4 substate:42
02/20/2018 04:31:08;0010;Server@node2;Job;3963.node2.supernodexp.hpc;Exit_status=0 resources_used.cpupercent=4744 resources_used.cput=08:20:59 resources_used.mem=7917180kb resources_used.ncpus=48 resources_used.vmem=47424336kb resources_used.walltime=00:10:45
02/20/2018 04:31:08;0100;Server@node2;Job;3963.node2.supernodexp.hpc;dequeuing from workq, state 5
02/20/2018 04:31:08;0040;Server@node2;Svr;node2.supernodexp.hpc;Scheduler sent command 2
02/20/2018 04:31:08;0040;Server@node2;Svr;node2.supernodexp.hpc;Scheduler sent command 0
02/20/2018 04:31:08;0100;Server@node2;Req;;Type 21 request received from Scheduler@node2.supernodexp.hpc, sock=16
02/20/2018 04:31:08;0100;Server@node2;Req;;Type 81 request received from Scheduler@node2.supernodexp.hpc, sock=16
02/20/2018 04:31:08;0100;Server@node2;Req;;Type 71 request received from Scheduler@node2.supernodexp.hpc, sock=16
02/20/2018 04:31:08;0100;Server@node2;Req;;Type 58 request received from Scheduler@node2.supernodexp.hpc, sock=16
02/20/2018 04:31:08;0100;Server@node2;Req;;Type 20 request received from Scheduler@node2.supernodexp.hpc, sock=16
02/20/2018 04:31:08;0100;Server@node2;Req;;Type 51 request received from Scheduler@node2.supernodexp.hpc, sock=16
02/20/2018 04:31:08;0100;Server@node2;Req;;Type 23 request received from Scheduler@node2.supernodexp.hpc, sock=16
02/20/2018 04:31:08;0008;Server@node2;Job;3977.node2.supernodexp.hpc;Job Run at request of Scheduler@node2.supernodexp.hpc on exec_vnode (node13:ncpus=48:mem=5242880kb)
02/20/2018 04:31:08;0001;Server@node2;Svr;Server@node2;Success (0) in req_runjob2, return value of svr_startjob is 0
02/20/2018 04:31:08;0100;Server@node2;Req;;Type 11 request received from Scheduler@node2.supernodexp.hpc, sock=16
02/20/2018 04:31:08;0008;Server@node2;Job;3988.node2.supernodexp.hpc;Job Modified at request of Scheduler@node2.supernodexp.hpc
02/20/2018 04:32:32;0080;Server@node2;Job;3970.node2.supernodexp.hpc;Obit received momhop:1 serverhop:1 state:4 substate:42
02/20/2018 04:32:33;0010;Server@node2;Job;3970.node2.supernodexp.hpc;Exit_status=0 resources_used.cpupercent=4738 resources_used.cput=08:21:26 resources_used.mem=7869740kb resources_used.ncpus=48 resources_used.vmem=47424512kb resources_used.walltime=00:10:40
02/20/2018 04:32:33;0100;Server@node2;Job;3970.node2.supernodexp.hpc;dequeuing from workq, state 5
02/20/2018 04:32:34;0040;Server@node2;Svr;node2.supernodexp.hpc;Scheduler sent command 2
02/20/2018 04:32:34;0040;Server@node2;Svr;node2.supernodexp.hpc;Scheduler sent command 0
02/20/2018 04:32:34;0100;Server@node2;Req;;Type 21 request received from Scheduler@node2.supernodexp.hpc, sock=16
02/20/2018 04:32:34;0100;Server@node2;Req;;Type 81 request received from Scheduler@node2.supernodexp.hpc, sock=16
02/20/2018 04:32:34;0100;Server@node2;Req;;Type 71 request received from Scheduler@node2.supernodexp.hpc, sock=16
02/20/2018 04:32:34;0100;Server@node2;Req;;Type 58 request received from Scheduler@node2.supernodexp.hpc, sock=16
02/20/2018 04:32:34;0100;Server@node2;Req;;Type 20 request received from Scheduler@node2.supernodexp.hpc, sock=16
02/20/2018 04:32:34;0100;Server@node2;Req;;Type 51 request received from Scheduler@node2.supernodexp.hpc, sock=16
02/20/2018 04:32:34;0100;Server@node2;Req;;Type 23 request received from Scheduler@node2.supernodexp.hpc, sock=16
02/20/2018 04:32:34;0008;Server@node2;Job;3988.node2.supernodexp.hpc;Job Run at request of Scheduler@node2.supernodexp.hpc on exec_vnode (node14:ncpus=48:mem=5242880kb)
02/20/2018 04:32:34;0001;Server@node2;Svr;Server@node2;Success (0) in req_runjob2, return value of svr_startjob is 0
02/20/2018 04:32:34;0100;Server@node2;Req;;Type 11 request received from Scheduler@node2.supernodexp.hpc, sock=16
02/20/2018 04:32:34;0008;Server@node2;Job;3991.node2.supernodexp.hpc;Job Modified at request of Scheduler@node2.supernodexp.hpc
02/20/2018 04:41:44;0080;Server@node2;Job;3977.node2.supernodexp.hpc;Obit received momhop:1 serverhop:1 state:4 substate:42
02/20/2018 04:41:45;0010;Server@node2;Job;3977.node2.supernodexp.hpc;Exit_status=0 resources_used.cpupercent=4788 resources_used.cput=08:18:04 resources_used.mem=7935336kb resources_used.ncpus=48 resources_used.vmem=47424332kb resources_used.walltime=00:10:36
02/20/2018 04:41:45;0100;Server@node2;Job;3977.node2.supernodexp.hpc;dequeuing from workq, state 5
02/20/2018 04:41:45;0040;Server@node2;Svr;node2.supernodexp.hpc;Scheduler sent command 2
02/20/2018 04:41:45;0040;Server@node2;Svr;node2.supernodexp.hpc;Scheduler sent command 0
02/20/2018 04:41:45;0100;Server@node2;Req;;Type 21 request received from Scheduler@node2.supernodexp.hpc, sock=16
02/20/2018 04:41:45;0100;Server@node2;Req;;Type 81 request received from Scheduler@node2.supernodexp.hpc, sock=16
02/20/2018 04:41:45;0100;Server@node2;Req;;Type 71 request received from Scheduler@node2.supernodexp.hpc, sock=16
02/20/2018 04:41:45;0100;Server@node2;Req;;Type 58 request received from Scheduler@node2.supernodexp.hpc, sock=16
02/20/2018 04:41:45;0100;Server@node2;Req;;Type 20 request received from Scheduler@node2.supernodexp.hpc, sock=16
02/20/2018 04:41:45;0100;Server@node2;Req;;Type 51 request received from Scheduler@node2.supernodexp.hpc, sock=16
02/20/2018 04:41:45;0100;Server@node2;Req;;Type 23 request received from Scheduler@node2.supernodexp.hpc, sock=16
02/20/2018 04:41:45;0008;Server@node2;Job;3991.node2.supernodexp.hpc;Job Run at request of Scheduler@node2.supernodexp.hpc on exec_vnode (node13:ncpus=48:mem=5242880kb)
02/20/2018 04:41:45;0001;Server@node2;Svr;Server@node2;Success (0) in req_runjob2, return value of svr_startjob is 0
02/20/2018 04:41:45;0100;Server@node2;Req;;Type 11 request received from Scheduler@node2.supernodexp.hpc, sock=16
02/20/2018 04:41:45;0008;Server@node2;Job;4012.node2.supernodexp.hpc;Job Modified at request of Scheduler@node2.supernodexp.hpc
02/20/2018 04:43:20;0080;Server@node2;Job;3988.node2.supernodexp.hpc;Obit received momhop:1 serverhop:1 state:4 substate:42
02/20/2018 04:43:21;0010;Server@node2;Job;3988.node2.supernodexp.hpc;Exit_status=0 resources_used.cpupercent=4744 resources_used.cput=08:18:45 resources_used.mem=7939428kb resources_used.ncpus=48 resources_used.vmem=47424244kb resources_used.walltime=00:10:46
02/20/2018 04:43:21;0100;Server@node2;Job;3988.node2.supernodexp.hpc;dequeuing from workq, state 5
02/20/2018 04:43:21;0040;Server@node2;Svr;node2.supernodexp.hpc;Scheduler sent command 2
02/20/2018 04:43:21;0040;Server@node2;Svr;node2.supernodexp.hpc;Scheduler sent command 0
02/20/2018 04:43:21;0100;Server@node2;Req;;Type 21 request received from Scheduler@node2.supernodexp.hpc, sock=16
02/20/2018 04:43:21;0100;Server@node2;Req;;Type 81 request received from Scheduler@node2.supernodexp.hpc, sock=16
02/20/2018 04:43:21;0100;Server@node2;Req;;Type 71 request received from Scheduler@node2.supernodexp.hpc, sock=16
02/20/2018 04:43:21;0100;Server@node2;Req;;Type 58 request received from Scheduler@node2.supernodexp.hpc, sock=16
02/20/2018 04:43:21;0100;Server@node2;Req;;Type 20 request received from Scheduler@node2.supernodexp.hpc, sock=16
02/20/2018 04:43:21;0100;Server@node2;Req;;Type 51 request received from Scheduler@node2.supernodexp.hpc, sock=16
02/20/2018 04:43:22;0100;Server@node2;Req;;Type 23 request received from Scheduler@node2.supernodexp.hpc, sock=16
02/20/2018 04:43:22;0008;Server@node2;Job;4012.node2.supernodexp.hpc;Job Run at request of Scheduler@node2.supernodexp.hpc on exec_vnode (node14:ncpus=48:mem=5242880kb)
02/20/2018 04:43:22;0001;Server@node2;Svr;Server@node2;Success (0) in req_runjob2, return value of svr_startjob is 0
02/20/2018 04:43:22;0100;Server@node2;Req;;Type 11 request received from Scheduler@node2.supernodexp.hpc, sock=16
02/20/2018 04:43:22;0008;Server@node2;Job;4017.node2.supernodexp.hpc;Job Modified at request of Scheduler@node2.supernodexp.hpc
02/20/2018 04:52:36;0080;Server@node2;Job;3991.node2.supernodexp.hpc;Obit received momhop:1 serverhop:1 state:4 substate:42
02/20/2018 04:52:38;0010;Server@node2;Job;3991.node2.supernodexp.hpc;Exit_status=0 resources_used.cpupercent=4733 resources_used.cput=08:25:31 resources_used.mem=7923844kb resources_used.ncpus=48 resources_used.vmem=47424308kb resources_used.walltime=00:10:50
02/20/2018 04:52:38;0100;Server@node2;Job;3991.node2.supernodexp.hpc;dequeuing from workq, state 5
02/20/2018 04:52:38;0040;Server@node2;Svr;node2.supernodexp.hpc;Scheduler sent command 2
02/20/2018 04:52:38;0040;Server@node2;Svr;node2.supernodexp.hpc;Scheduler sent command 0
02/20/2018 04:52:38;0100;Server@node2;Req;;Type 21 request received from Scheduler@node2.supernodexp.hpc, sock=16
02/20/2018 04:52:38;0100;Server@node2;Req;;Type 81 request received from Scheduler@node2.supernodexp.hpc, sock=16
02/20/2018 04:52:38;0100;Server@node2;Req;;Type 71 request received from Scheduler@node2.supernodexp.hpc, sock=16
02/20/2018 04:52:38;0100;Server@node2;Req;;Type 58 request received from Scheduler@node2.supernodexp.hpc, sock=16
02/20/2018 04:52:38;0100;Server@node2;Req;;Type 20 request received from Scheduler@node2.supernodexp.hpc, sock=16
02/20/2018 04:52:38;0100;Server@node2;Req;;Type 51 request received from Scheduler@node2.supernodexp.hpc, sock=16
02/20/2018 04:52:38;0100;Server@node2;Req;;Type 23 request received from Scheduler@node2.supernodexp.hpc, sock=16
02/20/2018 04:52:38;0008;Server@node2;Job;4017.node2.supernodexp.hpc;Job Run at request of Scheduler@node2.supernodexp.hpc on exec_vnode (node13:ncpus=48:mem=5242880kb)
02/20/2018 04:52:38;0001;Server@node2;Svr;Server@node2;Success (0) in req_runjob2, return value of svr_startjob is 0
02/20/2018 04:52:38;0100;Server@node2;Req;;Type 11 request received from Scheduler@node2.supernodexp.hpc, sock=16
02/20/2018 04:52:38;0008;Server@node2;Job;4031.node2.supernodexp.hpc;Job Modified at request of Scheduler@node2.supernodexp.hpc
02/20/2018 04:53:56;0080;Server@node2;Job;4012.node2.supernodexp.hpc;Obit received momhop:1 serverhop:1 state:4 substate:42
02/20/2018 04:53:58;0010;Server@node2;Job;4012.node2.supernodexp.hpc;Exit_status=0 resources_used.cpupercent=4741 resources_used.cput=08:17:19 resources_used.mem=7879296kb resources_used.ncpus=48 resources_used.vmem=47424220kb resources_used.walltime=00:10:35
02/20/2018 04:53:58;0100;Server@node2;Job;4012.node2.supernodexp.hpc;dequeuing from workq, state 5
02/20/2018 04:53:58;0040;Server@node2;Svr;node2.supernodexp.hpc;Scheduler sent command 2
02/20/2018 04:53:58;0040;Server@node2;Svr;node2.supernodexp.hpc;Scheduler sent command 0
02/20/2018 04:53:58;0100;Server@node2;Req;;Type 21 request received from Scheduler@node2.supernodexp.hpc, sock=16
02/20/2018 04:53:58;0100;Server@node2;Req;;Type 81 request received from Scheduler@node2.supernodexp.hpc, sock=16
02/20/2018 04:53:58;0100;Server@node2;Req;;Type 71 request received from Scheduler@node2.supernodexp.hpc, sock=16
02/20/2018 04:53:58;0100;Server@node2;Req;;Type 58 request received from Scheduler@node2.supernodexp.hpc, sock=16
02/20/2018 04:53:58;0100;Server@node2;Req;;Type 20 request received from Scheduler@node2.supernodexp.hpc, sock=16
02/20/2018 04:53:58;0100;Server@node2;Req;;Type 51 request received from Scheduler@node2.supernodexp.hpc, sock=16
02/20/2018 04:53:58;0100;Server@node2;Req;;Type 23 request received from Scheduler@node2.supernodexp.hpc, sock=16
02/20/2018 04:53:58;0008;Server@node2;Job;4031.node2.supernodexp.hpc;Job Run at request of Scheduler@node2.supernodexp.hpc on exec_vnode (node14:ncpus=48:mem=5242880kb)
02/20/2018 04:53:58;0001;Server@node2;Svr;Server@node2;Success (0) in req_runjob2, return value of svr_startjob is 0
02/20/2018 04:53:58;0100;Server@node2;Req;;Type 11 request received from Scheduler@node2.supernodexp.hpc, sock=16
02/20/2018 04:53:58;0008;Server@node2;Job;4040.node2.supernodexp.hpc;Job Modified at request of Scheduler@node2.supernodexp.hpc
02/20/2018 05:03:17;0080;Server@node2;Job;4017.node2.supernodexp.hpc;Obit received momhop:1 serverhop:1 state:4 substate:42
02/20/2018 05:03:18;0010;Server@node2;Job;4017.node2.supernodexp.hpc;Exit_status=0 resources_used.cpupercent=4738 resources_used.cput=08:20:48 resources_used.mem=7937608kb resources_used.ncpus=48 resources_used.vmem=47424016kb resources_used.walltime=00:10:39
02/20/2018 05:03:18;0100;Server@node2;Job;4017.node2.supernodexp.hpc;dequeuing from workq, state 5
02/20/2018 05:03:18;0040;Server@node2;Svr;node2.supernodexp.hpc;Scheduler sent command 2
02/20/2018 05:03:18;0040;Server@node2;Svr;node2.supernodexp.hpc;Scheduler sent command 0
02/20/2018 05:03:18;0100;Server@node2;Req;;Type 21 request received from Scheduler@node2.supernodexp.hpc, sock=16
02/20/2018 05:03:18;0100;Server@node2;Req;;Type 81 request received from Scheduler@node2.supernodexp.hpc, sock=16
02/20/2018 05:03:18;0100;Server@node2;Req;;Type 71 request received from Scheduler@node2.supernodexp.hpc, sock=16
02/20/2018 05:03:18;0100;Server@node2;Req;;Type 58 request received from Scheduler@node2.supernodexp.hpc, sock=16
02/20/2018 05:03:18;0100;Server@node2;Req;;Type 20 request received from Scheduler@node2.supernodexp.hpc, sock=16
02/20/2018 05:03:18;0100;Server@node2;Req;;Type 51 request received from Scheduler@node2.supernodexp.hpc, sock=16
02/20/2018 05:03:19;0100;Server@node2;Req;;Type 23 request received from Scheduler@node2.supernodexp.hpc, sock=16
02/20/2018 05:03:19;0008;Server@node2;Job;4040.node2.supernodexp.hpc;Job Run at request of Scheduler@node2.supernodexp.hpc on exec_vnode (node13:ncpus=48:mem=5242880kb)
02/20/2018 05:03:19;0001;Server@node2;Svr;Server@node2;Success (0) in req_runjob2, return value of svr_startjob is 0
02/20/2018 05:03:19;0100;Server@node2;Req;;Type 11 request received from Scheduler@node2.supernodexp.hpc, sock=16
02/20/2018 05:03:19;0008;Server@node2;Job;4042.node2.supernodexp.hpc;Job Modified at request of Scheduler@node2.supernodexp.hpc
02/20/2018 05:04:40;0080;Server@node2;Job;4031.node2.supernodexp.hpc;Obit received momhop:1 serverhop:1 state:4 substate:42
02/20/2018 05:04:42;0010;Server@node2;Job;4031.node2.supernodexp.hpc;Exit_status=0 resources_used.cpupercent=4745 resources_used.cput=08:16:16 resources_used.mem=7958764kb resources_used.ncpus=48 resources_used.vmem=47424512kb resources_used.walltime=00:10:42
02/20/2018 05:04:42;0100;Server@node2;Job;4031.node2.supernodexp.hpc;dequeuing from workq, state 5
02/20/2018 05:04:42;0040;Server@node2;Svr;node2.supernodexp.hpc;Scheduler sent command 2
02/20/2018 05:04:42;0040;Server@node2;Svr;node2.supernodexp.hpc;Scheduler sent command 0
02/20/2018 05:04:42;0100;Server@node2;Req;;Type 21 request received from Scheduler@node2.supernodexp.hpc, sock=16
02/20/2018 05:04:42;0100;Server@node2;Req;;Type 81 request received from Scheduler@node2.supernodexp.hpc, sock=16
02/20/2018 05:04:42;0100;Server@node2;Req;;Type 71 request received from Scheduler@node2.supernodexp.hpc, sock=16
02/20/2018 05:04:42;0100;Server@node2;Req;;Type 58 request received from Scheduler@node2.supernodexp.hpc, sock=16
02/20/2018 05:04:42;0100;Server@node2;Req;;Type 20 request received from Scheduler@node2.supernodexp.hpc, sock=16
02/20/2018 05:04:42;0100;Server@node2;Req;;Type 51 request received from Scheduler@node2.supernodexp.hpc, sock=16
02/20/2018 05:04:42;0100;Server@node2;Req;;Type 23 request received from Scheduler@node2.supernodexp.hpc, sock=16
02/20/2018 05:04:42;0008;Server@node2;Job;4042.node2.supernodexp.hpc;Job Run at request of Scheduler@node2.supernodexp.hpc on exec_vnode (node14:ncpus=48:mem=5242880kb)
02/20/2018 05:04:42;0001;Server@node2;Svr;Server@node2;Success (0) in req_runjob2, return value of svr_startjob is 0
02/20/2018 05:04:42;0100;Server@node2;Req;;Type 11 request received from Scheduler@node2.supernodexp.hpc, sock=16
02/20/2018 05:04:42;0008;Server@node2;Job;4059.node2.supernodexp.hpc;Job Modified at request of Scheduler@node2.supernodexp.hpc
02/20/2018 05:13:58;0080;Server@node2;Job;4040.node2.supernodexp.hpc;Obit received momhop:1 serverhop:1 state:4 substate:42
02/20/2018 05:13:59;0010;Server@node2;Job;4040.node2.supernodexp.hpc;Exit_status=0 resources_used.cpupercent=4732 resources_used.cput=08:19:54 resources_used.mem=7909028kb resources_used.ncpus=48 resources_used.vmem=47424948kb resources_used.walltime=00:10:40
02/20/2018 05:13:59;0100;Server@node2;Job;4040.node2.supernodexp.hpc;dequeuing from workq, state 5
02/20/2018 05:13:59;0040;Server@node2;Svr;node2.supernodexp.hpc;Scheduler sent command 2
02/20/2018 05:13:59;0040;Server@node2;Svr;node2.supernodexp.hpc;Scheduler sent command 0
02/20/2018 05:13:59;0100;Server@node2;Req;;Type 21 request received from Scheduler@node2.supernodexp.hpc, sock=16
02/20/2018 05:13:59;0100;Server@node2;Req;;Type 81 request received from Scheduler@node2.supernodexp.hpc, sock=16
02/20/2018 05:13:59;0100;Server@node2;Req;;Type 71 request received from Scheduler@node2.supernodexp.hpc, sock=16
02/20/2018 05:13:59;0100;Server@node2;Req;;Type 58 request received from Scheduler@node2.supernodexp.hpc, sock=16
02/20/2018 05:13:59;0100;Server@node2;Req;;Type 20 request received from Scheduler@node2.supernodexp.hpc, sock=16
02/20/2018 05:13:59;0100;Server@node2;Req;;Type 51 request received from Scheduler@node2.supernodexp.hpc, sock=16
02/20/2018 05:13:59;0100;Server@node2;Req;;Type 23 request received from Scheduler@node2.supernodexp.hpc, sock=16
02/20/2018 05:13:59;0008;Server@node2;Job;4059.node2.supernodexp.hpc;Job Run at request of Scheduler@node2.supernodexp.hpc on exec_vnode (node13:ncpus=48:mem=5242880kb)
02/20/2018 05:13:59;0001;Server@node2;Svr;Server@node2;Success (0) in req_runjob2, return value of svr_startjob is 0
02/20/2018 05:13:59;0100;Server@node2;Req;;Type 11 request received from Scheduler@node2.supernodexp.hpc, sock=16
02/20/2018 05:13:59;0008;Server@node2;Job;4062.node2.supernodexp.hpc;Job Modified at request of Scheduler@node2.supernodexp.hpc
02/20/2018 05:15:24;0080;Server@node2;Job;4042.node2.supernodexp.hpc;Obit received momhop:1 serverhop:1 state:4 substate:42
02/20/2018 05:15:26;0010;Server@node2;Job;4042.node2.supernodexp.hpc;Exit_status=0 resources_used.cpupercent=4745 resources_used.cput=08:13:10 resources_used.mem=7889536kb resources_used.ncpus=48 resources_used.vmem=47424184kb resources_used.walltime=00:10:43
02/20/2018 05:15:26;0100;Server@node2;Job;4042.node2.supernodexp.hpc;dequeuing from workq, state 5
02/20/2018 05:15:26;0040;Server@node2;Svr;node2.supernodexp.hpc;Scheduler sent command 2
02/20/2018 05:15:26;0040;Server@node2;Svr;node2.supernodexp.hpc;Scheduler sent command 0
02/20/2018 05:15:26;0100;Server@node2;Req;;Type 21 request received from Scheduler@node2.supernodexp.hpc, sock=16
02/20/2018 05:15:26;0100;Server@node2;Req;;Type 81 request received from Scheduler@node2.supernodexp.hpc, sock=16
02/20/2018 05:15:26;0100;Server@node2;Req;;Type 71 request received from Scheduler@node2.supernodexp.hpc, sock=16
02/20/2018 05:15:26;0100;Server@node2;Req;;Type 58 request received from Scheduler@node2.supernodexp.hpc, sock=16
02/20/2018 05:15:26;0100;Server@node2;Req;;Type 20 request received from Scheduler@node2.supernodexp.hpc, sock=16
02/20/2018 05:15:26;0100;Server@node2;Req;;Type 51 request received from Scheduler@node2.supernodexp.hpc, sock=16
02/20/2018 05:15:26;0100;Server@node2;Req;;Type 23 request received from Scheduler@node2.supernodexp.hpc, sock=16
02/20/2018 05:15:26;0008;Server@node2;Job;4062.node2.supernodexp.hpc;Job Run at request of Scheduler@node2.supernodexp.hpc on exec_vnode (node14:ncpus=48:mem=5242880kb)
02/20/2018 05:15:26;0001;Server@node2;Svr;Server@node2;Success (0) in req_runjob2, return value of svr_startjob is 0
02/20/2018 05:15:26;0100;Server@node2;Req;;Type 11 request received from Scheduler@node2.supernodexp.hpc, sock=16
02/20/2018 05:15:26;0008;Server@node2;Job;4077.node2.supernodexp.hpc;Job Modified at request of Scheduler@node2.supernodexp.hpc
02/20/2018 05:24:39;0080;Server@node2;Job;4059.node2.supernodexp.hpc;Obit received momhop:1 serverhop:1 state:4 substate:42
02/20/2018 05:24:40;0010;Server@node2;Job;4059.node2.supernodexp.hpc;Exit_status=0 resources_used.cpupercent=4737 resources_used.cput=08:21:33 resources_used.mem=7910120kb resources_used.ncpus=48 resources_used.vmem=47424328kb resources_used.walltime=00:10:40
02/20/2018 05:24:40;0100;Server@node2;Job;4059.node2.supernodexp.hpc;dequeuing from workq, state 5
02/20/2018 05:24:40;0040;Server@node2;Svr;node2.supernodexp.hpc;Scheduler sent command 2
02/20/2018 05:24:40;0040;Server@node2;Svr;node2.supernodexp.hpc;Scheduler sent command 0
02/20/2018 05:24:40;0100;Server@node2;Req;;Type 21 request received from Scheduler@node2.supernodexp.hpc, sock=16
02/20/2018 05:24:40;0100;Server@node2;Req;;Type 81 request received from Scheduler@node2.supernodexp.hpc, sock=16
02/20/2018 05:24:40;0100;Server@node2;Req;;Type 71 request received from Scheduler@node2.supernodexp.hpc, sock=16
02/20/2018 05:24:40;0100;Server@node2;Req;;Type 58 request received from Scheduler@node2.supernodexp.hpc, sock=16
02/20/2018 05:24:41;0100;Server@node2;Req;;Type 20 request received from Scheduler@node2.supernodexp.hpc, sock=16
02/20/2018 05:24:41;0100;Server@node2;Req;;Type 51 request received from Scheduler@node2.supernodexp.hpc, sock=16
02/20/2018 05:24:41;0100;Server@node2;Req;;Type 23 request received from Scheduler@node2.supernodexp.hpc, sock=16
02/20/2018 05:24:41;0008;Server@node2;Job;4077.node2.supernodexp.hpc;Job Run at request of Scheduler@node2.supernodexp.hpc on exec_vnode (node13:ncpus=48:mem=5242880kb)
02/20/2018 05:24:41;0001;Server@node2;Svr;Server@node2;Success (0) in req_runjob2, return value of svr_startjob is 0
02/20/2018 05:24:41;0100;Server@node2;Req;;Type 11 request received from Scheduler@node2.supernodexp.hpc, sock=16
02/20/2018 05:24:41;0008;Server@node2;Job;4097.node2.supernodexp.hpc;Job Modified at request of Scheduler@node2.supernodexp.hpc
02/20/2018 05:26:00;0080;Server@node2;Job;4062.node2.supernodexp.hpc;Obit received momhop:1 serverhop:1 state:4 substate:42
02/20/2018 05:26:01;0010;Server@node2;Job;4062.node2.supernodexp.hpc;Exit_status=0 resources_used.cpupercent=4700 resources_used.cput=08:16:10 resources_used.mem=7953224kb resources_used.ncpus=48 resources_used.vmem=47424380kb resources_used.walltime=00:10:34
02/20/2018 05:26:01;0100;Server@node2;Job;4062.node2.supernodexp.hpc;dequeuing from workq, state 5
02/20/2018 05:26:01;0040;Server@node2;Svr;node2.supernodexp.hpc;Scheduler sent command 2
02/20/2018 05:26:01;0040;Server@node2;Svr;node2.supernodexp.hpc;Scheduler sent command 0
02/20/2018 05:26:01;0100;Server@node2;Req;;Type 21 request received from Scheduler@node2.supernodexp.hpc, sock=16
02/20/2018 05:26:01;0100;Server@node2;Req;;Type 81 request received from Scheduler@node2.supernodexp.hpc, sock=16
02/20/2018 05:26:01;0100;Server@node2;Req;;Type 71 request received from Scheduler@node2.supernodexp.hpc, sock=16
02/20/2018 05:26:01;0100;Server@node2;Req;;Type 58 request received from Scheduler@node2.supernodexp.hpc, sock=16
02/20/2018 05:26:01;0100;Server@node2;Req;;Type 20 request received from Scheduler@node2.supernodexp.hpc, sock=16
02/20/2018 05:26:01;0100;Server@node2;Req;;Type 51 request received from Scheduler@node2.supernodexp.hpc, sock=16
02/20/2018 05:26:02;0100;Server@node2;Req;;Type 23 request received from Scheduler@node2.supernodexp.hpc, sock=16
02/20/2018 05:26:02;0008;Server@node2;Job;4097.node2.supernodexp.hpc;Job Run at request of Scheduler@node2.supernodexp.hpc on exec_vnode (node14:ncpus=48:mem=5242880kb)
02/20/2018 05:26:02;0001;Server@node2;Svr;Server@node2;Success (0) in req_runjob2, return value of svr_startjob is 0
02/20/2018 05:26:02;0100;Server@node2;Req;;Type 11 request received from Scheduler@node2.supernodexp.hpc, sock=16
02/20/2018 05:26:02;0008;Server@node2;Job;4114.node2.supernodexp.hpc;Job Modified at request of Scheduler@node2.supernodexp.hpc
02/20/2018 05:35:19;0080;Server@node2;Job;4077.node2.supernodexp.hpc;Obit received momhop:1 serverhop:1 state:4 substate:42
02/20/2018 05:35:20;0010;Server@node2;Job;4077.node2.supernodexp.hpc;Exit_status=0 resources_used.cpupercent=4749 resources_used.cput=08:20:25 resources_used.mem=7875624kb resources_used.ncpus=48 resources_used.vmem=47424332kb resources_used.walltime=00:10:38
02/20/2018 05:35:20;0100;Server@node2;Job;4077.node2.supernodexp.hpc;dequeuing from workq, state 5
02/20/2018 05:35:20;0040;Server@node2;Svr;node2.supernodexp.hpc;Scheduler sent command 2
02/20/2018 05:35:20;0040;Server@node2;Svr;node2.supernodexp.hpc;Scheduler sent command 0
02/20/2018 05:35:20;0100;Server@node2;Req;;Type 21 request received from Scheduler@node2.supernodexp.hpc, sock=16
02/20/2018 05:35:20;0100;Server@node2;Req;;Type 81 request received from Scheduler@node2.supernodexp.hpc, sock=16
02/20/2018 05:35:20;0100;Server@node2;Req;;Type 71 request received from Scheduler@node2.supernodexp.hpc, sock=16
02/20/2018 05:35:20;0100;Server@node2;Req;;Type 58 request received from Scheduler@node2.supernodexp.hpc, sock=16
02/20/2018 05:35:20;0100;Server@node2;Req;;Type 20 request received from Scheduler@node2.supernodexp.hpc, sock=16
02/20/2018 05:35:20;0100;Server@node2;Req;;Type 51 request received from Scheduler@node2.supernodexp.hpc, sock=16
02/20/2018 05:35:21;0100;Server@node2;Req;;Type 23 request received from Scheduler@node2.supernodexp.hpc, sock=16
02/20/2018 05:35:21;0008;Server@node2;Job;4114.node2.supernodexp.hpc;Job Run at request of Scheduler@node2.supernodexp.hpc on exec_vnode (node13:ncpus=48:mem=5242880kb)
02/20/2018 05:35:21;0001;Server@node2;Svr;Server@node2;Success (0) in req_runjob2, return value of svr_startjob is 0
02/20/2018 05:35:21;0100;Server@node2;Req;;Type 11 request received from Scheduler@node2.supernodexp.hpc, sock=16
02/20/2018 05:35:21;0008;Server@node2;Job;4120.node2.supernodexp.hpc;Job Modified at request of Scheduler@node2.supernodexp.hpc
02/20/2018 05:36:35;0080;Server@node2;Job;4097.node2.supernodexp.hpc;Obit received momhop:1 serverhop:1 state:4 substate:42
02/20/2018 05:36:36;0010;Server@node2;Job;4097.node2.supernodexp.hpc;Exit_status=0 resources_used.cpupercent=4733 resources_used.cput=08:15:50 resources_used.mem=7947020kb resources_used.ncpus=48 resources_used.vmem=47423884kb resources_used.walltime=00:10:33
02/20/2018 05:36:36;0100;Server@node2;Job;4097.node2.supernodexp.hpc;dequeuing from workq, state 5
02/20/2018 05:36:36;0040;Server@node2;Svr;node2.supernodexp.hpc;Scheduler sent command 2
02/20/2018 05:36:36;0040;Server@node2;Svr;node2.supernodexp.hpc;Scheduler sent command 0
02/20/2018 05:36:36;0100;Server@node2;Req;;Type 21 request received from Scheduler@node2.supernodexp.hpc, sock=16
02/20/2018 05:36:36;0100;Server@node2;Req;;Type 81 request received from Scheduler@node2.supernodexp.hpc, sock=16
02/20/2018 05:36:36;0100;Server@node2;Req;;Type 71 request received from Scheduler@node2.supernodexp.hpc, sock=16
02/20/2018 05:36:36;0100;Server@node2;Req;;Type 58 request received from Scheduler@node2.supernodexp.hpc, sock=16
02/20/2018 05:36:36;0100;Server@node2;Req;;Type 20 request received from Scheduler@node2.supernodexp.hpc, sock=16
02/20/2018 05:36:36;0100;Server@node2;Req;;Type 51 request received from Scheduler@node2.supernodexp.hpc, sock=16
02/20/2018 05:36:36;0100;Server@node2;Req;;Type 23 request received from Scheduler@node2.supernodexp.hpc, sock=16
02/20/2018 05:36:36;0008;Server@node2;Job;4120.node2.supernodexp.hpc;Job Run at request of Scheduler@node2.supernodexp.hpc on exec_vnode (node14:ncpus=48:mem=5242880kb)
02/20/2018 05:36:36;0001;Server@node2;Svr;Server@node2;Success (0) in req_runjob2, return value of svr_startjob is 0
02/20/2018 05:36:36;0100;Server@node2;Req;;Type 11 request received from Scheduler@node2.supernodexp.hpc, sock=16
02/20/2018 05:36:36;0008;Server@node2;Job;4129.node2.supernodexp.hpc;Job Modified at request of Scheduler@node2.supernodexp.hpc
02/20/2018 05:46:08;0080;Server@node2;Job;4114.node2.supernodexp.hpc;Obit received momhop:1 serverhop:1 state:4 substate:42
02/20/2018 05:46:09;0010;Server@node2;Job;4114.node2.supernodexp.hpc;Exit_status=0 resources_used.cpupercent=4742 resources_used.cput=08:18:08 resources_used.mem=7894104kb resources_used.ncpus=48 resources_used.vmem=47425240kb resources_used.walltime=00:10:48
02/20/2018 05:46:09;0100;Server@node2;Job;4114.node2.supernodexp.hpc;dequeuing from workq, state 5
02/20/2018 05:46:09;0040;Server@node2;Svr;node2.supernodexp.hpc;Scheduler sent command 2
02/20/2018 05:46:09;0040;Server@node2;Svr;node2.supernodexp.hpc;Scheduler sent command 0
02/20/2018 05:46:09;0100;Server@node2;Req;;Type 21 request received from Scheduler@node2.supernodexp.hpc, sock=16
02/20/2018 05:46:09;0100;Server@node2;Req;;Type 81 request received from Scheduler@node2.supernodexp.hpc, sock=16
02/20/2018 05:46:09;0100;Server@node2;Req;;Type 71 request received from Scheduler@node2.supernodexp.hpc, sock=16
02/20/2018 05:46:09;0100;Server@node2;Req;;Type 58 request received from Scheduler@node2.supernodexp.hpc, sock=16
02/20/2018 05:46:09;0100;Server@node2;Req;;Type 20 request received from Scheduler@node2.supernodexp.hpc, sock=16
02/20/2018 05:46:09;0100;Server@node2;Req;;Type 51 request received from Scheduler@node2.supernodexp.hpc, sock=16
02/20/2018 05:46:10;0100;Server@node2;Req;;Type 23 request received from Scheduler@node2.supernodexp.hpc, sock=16
02/20/2018 05:46:10;0008;Server@node2;Job;4129.node2.supernodexp.hpc;Job Run at request of Scheduler@node2.supernodexp.hpc on exec_vnode (node13:ncpus=48:mem=5242880kb)
02/20/2018 05:46:10;0001;Server@node2;Svr;Server@node2;Success (0) in req_runjob2, return value of svr_startjob is 0
02/20/2018 05:46:10;0100;Server@node2;Req;;Type 11 request received from Scheduler@node2.supernodexp.hpc, sock=16
02/20/2018 05:46:10;0008;Server@node2;Job;4131.node2.supernodexp.hpc;Job Modified at request of Scheduler@node2.supernodexp.hpc
02/20/2018 05:47:09;0080;Server@node2;Job;4120.node2.supernodexp.hpc;Obit received momhop:1 serverhop:1 state:4 substate:42
02/20/2018 05:47:10;0010;Server@node2;Job;4120.node2.supernodexp.hpc;Exit_status=0 resources_used.cpupercent=4734 resources_used.cput=08:15:30 resources_used.mem=7935184kb resources_used.ncpus=48 resources_used.vmem=47424220kb resources_used.walltime=00:10:32
02/20/2018 05:47:10;0100;Server@node2;Job;4120.node2.supernodexp.hpc;dequeuing from workq, state 5
02/20/2018 05:47:10;0040;Server@node2;Svr;node2.supernodexp.hpc;Scheduler sent command 2
02/20/2018 05:47:10;0040;Server@node2;Svr;node2.supernodexp.hpc;Scheduler sent command 0
02/20/2018 05:47:10;0100;Server@node2;Req;;Type 21 request received from Scheduler@node2.supernodexp.hpc, sock=16
02/20/2018 05:47:10;0100;Server@node2;Req;;Type 81 request received from Scheduler@node2.supernodexp.hpc, sock=16
02/20/2018 05:47:10;0100;Server@node2;Req;;Type 71 request received from Scheduler@node2.supernodexp.hpc, sock=16
02/20/2018 05:47:10;0100;Server@node2;Req;;Type 58 request received from Scheduler@node2.supernodexp.hpc, sock=16
02/20/2018 05:47:10;0100;Server@node2;Req;;Type 20 request received from Scheduler@node2.supernodexp.hpc, sock=16
02/20/2018 05:47:10;0100;Server@node2;Req;;Type 51 request received from Scheduler@node2.supernodexp.hpc, sock=16
02/20/2018 05:47:10;0100;Server@node2;Req;;Type 23 request received from Scheduler@node2.supernodexp.hpc, sock=16
02/20/2018 05:47:10;0008;Server@node2;Job;4131.node2.supernodexp.hpc;Job Run at request of Scheduler@node2.supernodexp.hpc on exec_vnode (node14:ncpus=48:mem=5242880kb)
02/20/2018 05:47:10;0001;Server@node2;Svr;Server@node2;Success (0) in req_runjob2, return value of svr_startjob is 0
02/20/2018 05:47:10;0100;Server@node2;Req;;Type 11 request received from Scheduler@node2.supernodexp.hpc, sock=16
02/20/2018 05:47:10;0008;Server@node2;Job;4139.node2.supernodexp.hpc;Job Modified at request of Scheduler@node2.supernodexp.hpc
02/20/2018 05:56:50;0080;Server@node2;Job;4129.node2.supernodexp.hpc;Obit received momhop:1 serverhop:1 state:4 substate:42
02/20/2018 05:56:51;0010;Server@node2;Job;4129.node2.supernodexp.hpc;Exit_status=0 resources_used.cpupercent=4744 resources_used.cput=08:21:00 resources_used.mem=7918664kb resources_used.ncpus=48 resources_used.vmem=47424012kb resources_used.walltime=00:10:41
02/20/2018 05:56:51;0100;Server@node2;Job;4129.node2.supernodexp.hpc;dequeuing from workq, state 5
02/20/2018 05:56:51;0040;Server@node2;Svr;node2.supernodexp.hpc;Scheduler sent command 2
02/20/2018 05:56:51;0040;Server@node2;Svr;node2.supernodexp.hpc;Scheduler sent command 0
02/20/2018 05:56:51;0100;Server@node2;Req;;Type 21 request received from Scheduler@node2.supernodexp.hpc, sock=16
02/20/2018 05:56:51;0100;Server@node2;Req;;Type 81 request received from Scheduler@node2.supernodexp.hpc, sock=16
02/20/2018 05:56:51;0100;Server@node2;Req;;Type 71 request received from Scheduler@node2.supernodexp.hpc, sock=16
02/20/2018 05:56:51;0100;Server@node2;Req;;Type 58 request received from Scheduler@node2.supernodexp.hpc, sock=16
02/20/2018 05:56:51;0100;Server@node2;Req;;Type 20 request received from Scheduler@node2.supernodexp.hpc, sock=16
02/20/2018 05:56:51;0100;Server@node2;Req;;Type 51 request received from Scheduler@node2.supernodexp.hpc, sock=16
02/20/2018 05:56:51;0100;Server@node2;Req;;Type 23 request received from Scheduler@node2.supernodexp.hpc, sock=16
02/20/2018 05:56:51;0008;Server@node2;Job;4139.node2.supernodexp.hpc;Job Run at request of Scheduler@node2.supernodexp.hpc on exec_vnode (node13:ncpus=48:mem=5242880kb)
02/20/2018 05:56:51;0001;Server@node2;Svr;Server@node2;Success (0) in req_runjob2, return value of svr_startjob is 0
02/20/2018 05:56:51;0100;Server@node2;Req;;Type 11 request received from Scheduler@node2.supernodexp.hpc, sock=16
02/20/2018 05:56:51;0008;Server@node2;Job;4150.node2.supernodexp.hpc;Job Modified at request of Scheduler@node2.supernodexp.hpc
02/20/2018 05:57:41;0080;Server@node2;Job;4131.node2.supernodexp.hpc;Obit received momhop:1 serverhop:1 state:4 substate:42
02/20/2018 05:57:42;0010;Server@node2;Job;4131.node2.supernodexp.hpc;Exit_status=0 resources_used.cpupercent=4739 resources_used.cput=08:13:35 resources_used.mem=7957180kb resources_used.ncpus=48 resources_used.vmem=47424200kb resources_used.walltime=00:10:31
02/20/2018 05:57:42;0100;Server@node2;Job;4131.node2.supernodexp.hpc;dequeuing from workq, state 5
02/20/2018 05:57:42;0040;Server@node2;Svr;node2.supernodexp.hpc;Scheduler sent command 2
02/20/2018 05:57:42;0040;Server@node2;Svr;node2.supernodexp.hpc;Scheduler sent command 0
02/20/2018 05:57:42;0100;Server@node2;Req;;Type 21 request received from Scheduler@node2.supernodexp.hpc, sock=16
02/20/2018 05:57:42;0100;Server@node2;Req;;Type 81 request received from Scheduler@node2.supernodexp.hpc, sock=16
02/20/2018 05:57:42;0100;Server@node2;Req;;Type 71 request received from Scheduler@node2.supernodexp.hpc, sock=16
02/20/2018 05:57:42;0100;Server@node2;Req;;Type 58 request received from Scheduler@node2.supernodexp.hpc, sock=16
02/20/2018 05:57:42;0100;Server@node2;Req;;Type 20 request received from Scheduler@node2.supernodexp.hpc, sock=16
02/20/2018 05:57:42;0100;Server@node2;Req;;Type 51 request received from Scheduler@node2.supernodexp.hpc, sock=16
02/20/2018 05:57:42;0100;Server@node2;Req;;Type 23 request received from Scheduler@node2.supernodexp.hpc, sock=16
02/20/2018 05:57:42;0008;Server@node2;Job;4150.node2.supernodexp.hpc;Job Run at request of Scheduler@node2.supernodexp.hpc on exec_vnode (node14:ncpus=48:mem=5242880kb)
02/20/2018 05:57:42;0001;Server@node2;Svr;Server@node2;Success (0) in req_runjob2, return value of svr_startjob is 0
02/20/2018 05:57:42;0100;Server@node2;Req;;Type 11 request received from Scheduler@node2.supernodexp.hpc, sock=16
02/20/2018 05:57:42;0008;Server@node2;Job;4158.node2.supernodexp.hpc;Job Modified at request of Scheduler@node2.supernodexp.hpc
02/20/2018 06:07:32;0080;Server@node2;Job;4139.node2.supernodexp.hpc;Obit received momhop:1 serverhop:1 state:4 substate:42
02/20/2018 06:07:34;0010;Server@node2;Job;4139.node2.supernodexp.hpc;Exit_status=0 resources_used.cpupercent=4745 resources_used.cput=08:18:29 resources_used.mem=7879600kb resources_used.ncpus=48 resources_used.vmem=47424332kb resources_used.walltime=00:10:41
02/20/2018 06:07:34;0100;Server@node2;Job;4139.node2.supernodexp.hpc;dequeuing from workq, state 5
02/20/2018 06:07:34;0040;Server@node2;Svr;node2.supernodexp.hpc;Scheduler sent command 2
02/20/2018 06:07:34;0040;Server@node2;Svr;node2.supernodexp.hpc;Scheduler sent command 0
02/20/2018 06:07:34;0100;Server@node2;Req;;Type 21 request received from Scheduler@node2.supernodexp.hpc, sock=16
02/20/2018 06:07:34;0100;Server@node2;Req;;Type 81 request received from Scheduler@node2.supernodexp.hpc, sock=16
02/20/2018 06:07:34;0100;Server@node2;Req;;Type 71 request received from Scheduler@node2.supernodexp.hpc, sock=16
02/20/2018 06:07:34;0100;Server@node2;Req;;Type 58 request received from Scheduler@node2.supernodexp.hpc, sock=16
02/20/2018 06:07:34;0100;Server@node2;Req;;Type 20 request received from Scheduler@node2.supernodexp.hpc, sock=16
02/20/2018 06:07:34;0100;Server@node2;Req;;Type 51 request received from Scheduler@node2.supernodexp.hpc, sock=16
02/20/2018 06:07:34;0100;Server@node2;Req;;Type 23 request received from Scheduler@node2.supernodexp.hpc, sock=16
02/20/2018 06:07:34;0008;Server@node2;Job;4158.node2.supernodexp.hpc;Job Run at request of Scheduler@node2.supernodexp.hpc on exec_vnode (node13:ncpus=48:mem=5242880kb)
02/20/2018 06:07:34;0001;Server@node2;Svr;Server@node2;Success (0) in req_runjob2, return value of svr_startjob is 0
02/20/2018 06:07:34;0100;Server@node2;Req;;Type 11 request received from Scheduler@node2.supernodexp.hpc, sock=16
02/20/2018 06:07:34;0008;Server@node2;Job;4161.node2.supernodexp.hpc;Job Modified at request of Scheduler@node2.supernodexp.hpc
02/20/2018 06:08:15;0080;Server@node2;Job;4150.node2.supernodexp.hpc;Obit received momhop:1 serverhop:1 state:4 substate:42
02/20/2018 06:08:16;0010;Server@node2;Job;4150.node2.supernodexp.hpc;Exit_status=0 resources_used.cpupercent=4732 resources_used.cput=08:15:47 resources_used.mem=7930072kb resources_used.ncpus=48 resources_used.vmem=47423936kb resources_used.walltime=00:10:33
02/20/2018 06:08:16;0100;Server@node2;Job;4150.node2.supernodexp.hpc;dequeuing from workq, state 5
02/20/2018 06:08:16;0040;Server@node2;Svr;node2.supernodexp.hpc;Scheduler sent command 2
02/20/2018 06:08:16;0040;Server@node2;Svr;node2.supernodexp.hpc;Scheduler sent command 0
02/20/2018 06:08:16;0100;Server@node2;Req;;Type 21 request received from Scheduler@node2.supernodexp.hpc, sock=16
02/20/2018 06:08:16;0100;Server@node2;Req;;Type 81 request received from Scheduler@node2.supernodexp.hpc, sock=16
02/20/2018 06:08:16;0100;Server@node2;Req;;Type 71 request received from Scheduler@node2.supernodexp.hpc, sock=16
02/20/2018 06:08:16;0100;Server@node2;Req;;Type 58 request received from Scheduler@node2.supernodexp.hpc, sock=16
02/20/2018 06:08:16;0100;Server@node2;Req;;Type 20 request received from Scheduler@node2.supernodexp.hpc, sock=16
02/20/2018 06:08:16;0100;Server@node2;Req;;Type 51 request received from Scheduler@node2.supernodexp.hpc, sock=16
02/20/2018 06:08:16;0100;Server@node2;Req;;Type 23 request received from Scheduler@node2.supernodexp.hpc, sock=16
02/20/2018 06:08:16;0008;Server@node2;Job;4161.node2.supernodexp.hpc;Job Run at request of Scheduler@node2.supernodexp.hpc on exec_vnode (node14:ncpus=48:mem=5242880kb)
02/20/2018 06:08:16;0001;Server@node2;Svr;Server@node2;Success (0) in req_runjob2, return value of svr_startjob is 0
02/20/2018 06:08:16;0100;Server@node2;Req;;Type 11 request received from Scheduler@node2.supernodexp.hpc, sock=16
02/20/2018 06:08:16;0008;Server@node2;Job;4164.node2.supernodexp.hpc;Job Modified at request of Scheduler@node2.supernodexp.hpc
02/20/2018 06:18:09;0080;Server@node2;Job;4158.node2.supernodexp.hpc;Obit received momhop:1 serverhop:1 state:4 substate:42
02/20/2018 06:18:10;0010;Server@node2;Job;4158.node2.supernodexp.hpc;Exit_status=0 resources_used.cpupercent=4740 resources_used.cput=08:17:07 resources_used.mem=7901772kb resources_used.ncpus=48 resources_used.vmem=47425228kb resources_used.walltime=00:10:35
02/20/2018 06:18:10;0100;Server@node2;Job;4158.node2.supernodexp.hpc;dequeuing from workq, state 5
02/20/2018 06:18:10;0040;Server@node2;Svr;node2.supernodexp.hpc;Scheduler sent command 2
02/20/2018 06:18:10;0040;Server@node2;Svr;node2.supernodexp.hpc;Scheduler sent command 0
02/20/2018 06:18:10;0100;Server@node2;Req;;Type 21 request received from Scheduler@node2.supernodexp.hpc, sock=16
02/20/2018 06:18:10;0100;Server@node2;Req;;Type 81 request received from Scheduler@node2.supernodexp.hpc, sock=16
02/20/2018 06:18:10;0100;Server@node2;Req;;Type 71 request received from Scheduler@node2.supernodexp.hpc, sock=16
02/20/2018 06:18:10;0100;Server@node2;Req;;Type 58 request received from Scheduler@node2.supernodexp.hpc, sock=16
02/20/2018 06:18:10;0100;Server@node2;Req;;Type 20 request received from Scheduler@node2.supernodexp.hpc, sock=16
02/20/2018 06:18:10;0100;Server@node2;Req;;Type 51 request received from Scheduler@node2.supernodexp.hpc, sock=16
02/20/2018 06:18:10;0100;Server@node2;Req;;Type 23 request received from Scheduler@node2.supernodexp.hpc, sock=16
02/20/2018 06:18:10;0008;Server@node2;Job;4164.node2.supernodexp.hpc;Job Run at request of Scheduler@node2.supernodexp.hpc on exec_vnode (node13:ncpus=48:mem=5242880kb)
02/20/2018 06:18:10;0001;Server@node2;Svr;Server@node2;Success (0) in req_runjob2, return value of svr_startjob is 0
02/20/2018 06:18:10;0100;Server@node2;Req;;Type 11 request received from Scheduler@node2.supernodexp.hpc, sock=16
02/20/2018 06:18:10;0008;Server@node2;Job;4190.node2.supernodexp.hpc;Job Modified at request of Scheduler@node2.supernodexp.hpc
02/20/2018 06:18:59;0080;Server@node2;Job;4161.node2.supernodexp.hpc;Obit received momhop:1 serverhop:1 state:4 substate:42
02/20/2018 06:19:01;0010;Server@node2;Job;4161.node2.supernodexp.hpc;Exit_status=0 resources_used.cpupercent=4754 resources_used.cput=08:19:15 resources_used.mem=7919620kb resources_used.ncpus=48 resources_used.vmem=47424824kb resources_used.walltime=00:10:43
02/20/2018 06:19:01;0100;Server@node2;Job;4161.node2.supernodexp.hpc;dequeuing from workq, state 5
02/20/2018 06:19:01;0040;Server@node2;Svr;node2.supernodexp.hpc;Scheduler sent command 2
02/20/2018 06:19:01;0040;Server@node2;Svr;node2.supernodexp.hpc;Scheduler sent command 0
02/20/2018 06:19:01;0100;Server@node2;Req;;Type 21 request received from Scheduler@node2.supernodexp.hpc, sock=16
02/20/2018 06:19:01;0100;Server@node2;Req;;Type 81 request received from Scheduler@node2.supernodexp.hpc, sock=16
02/20/2018 06:19:01;0100;Server@node2;Req;;Type 71 request received from Scheduler@node2.supernodexp.hpc, sock=16
02/20/2018 06:19:01;0100;Server@node2;Req;;Type 58 request received from Scheduler@node2.supernodexp.hpc, sock=16
02/20/2018 06:19:01;0100;Server@node2;Req;;Type 20 request received from Scheduler@node2.supernodexp.hpc, sock=16
02/20/2018 06:19:01;0100;Server@node2;Req;;Type 51 request received from Scheduler@node2.supernodexp.hpc, sock=16
02/20/2018 06:19:01;0100;Server@node2;Req;;Type 23 request received from Scheduler@node2.supernodexp.hpc, sock=16
02/20/2018 06:19:01;0008;Server@node2;Job;4190.node2.supernodexp.hpc;Job Run at request of Scheduler@node2.supernodexp.hpc on exec_vnode (node14:ncpus=48:mem=5242880kb)
02/20/2018 06:19:01;0001;Server@node2;Svr;Server@node2;Success (0) in req_runjob2, return value of svr_startjob is 0
02/20/2018 06:19:01;0100;Server@node2;Req;;Type 11 request received from Scheduler@node2.supernodexp.hpc, sock=16
02/20/2018 06:19:01;0008;Server@node2;Job;4198.node2.supernodexp.hpc;Job Modified at request of Scheduler@node2.supernodexp.hpc
02/20/2018 06:28:52;0080;Server@node2;Job;4164.node2.supernodexp.hpc;Obit received momhop:1 serverhop:1 state:4 substate:42
02/20/2018 06:28:53;0010;Server@node2;Job;4164.node2.supernodexp.hpc;Exit_status=0 resources_used.cpupercent=4697 resources_used.cput=08:22:24 resources_used.mem=7907428kb resources_used.ncpus=48 resources_used.vmem=47424624kb resources_used.walltime=00:10:42
02/20/2018 06:28:53;0100;Server@node2;Job;4164.node2.supernodexp.hpc;dequeuing from workq, state 5
02/20/2018 06:28:53;0040;Server@node2;Svr;node2.supernodexp.hpc;Scheduler sent command 2
02/20/2018 06:28:53;0040;Server@node2;Svr;node2.supernodexp.hpc;Scheduler sent command 0
02/20/2018 06:28:53;0100;Server@node2;Req;;Type 21 request received from Scheduler@node2.supernodexp.hpc, sock=16
02/20/2018 06:28:53;0100;Server@node2;Req;;Type 81 request received from Scheduler@node2.supernodexp.hpc, sock=16
02/20/2018 06:28:53;0100;Server@node2;Req;;Type 71 request received from Scheduler@node2.supernodexp.hpc, sock=16
02/20/2018 06:28:53;0100;Server@node2;Req;;Type 58 request received from Scheduler@node2.supernodexp.hpc, sock=16
02/20/2018 06:28:53;0100;Server@node2;Req;;Type 20 request received from Scheduler@node2.supernodexp.hpc, sock=16
02/20/2018 06:28:53;0100;Server@node2;Req;;Type 51 request received from Scheduler@node2.supernodexp.hpc, sock=16
02/20/2018 06:28:53;0100;Server@node2;Req;;Type 23 request received from Scheduler@node2.supernodexp.hpc, sock=16
02/20/2018 06:28:53;0008;Server@node2;Job;4198.node2.supernodexp.hpc;Job Run at request of Scheduler@node2.supernodexp.hpc on exec_vnode (node13:ncpus=48:mem=5242880kb)
02/20/2018 06:28:53;0001;Server@node2;Svr;Server@node2;Success (0) in req_runjob2, return value of svr_startjob is 0
02/20/2018 06:28:53;0100;Server@node2;Req;;Type 11 request received from Scheduler@node2.supernodexp.hpc, sock=16
02/20/2018 06:28:53;0008;Server@node2;Job;4200.node2.supernodexp.hpc;Job Modified at request of Scheduler@node2.supernodexp.hpc
02/20/2018 06:29:46;0080;Server@node2;Job;4190.node2.supernodexp.hpc;Obit received momhop:1 serverhop:1 state:4 substate:42
02/20/2018 06:29:48;0010;Server@node2;Job;4190.node2.supernodexp.hpc;Exit_status=0 resources_used.cpupercent=4745 resources_used.cput=08:15:33 resources_used.mem=7938340kb resources_used.ncpus=48 resources_used.vmem=47424500kb resources_used.walltime=00:10:46
02/20/2018 06:29:48;0100;Server@node2;Job;4190.node2.supernodexp.hpc;dequeuing from workq, state 5
02/20/2018 06:29:48;0040;Server@node2;Svr;node2.supernodexp.hpc;Scheduler sent command 2
02/20/2018 06:29:48;0040;Server@node2;Svr;node2.supernodexp.hpc;Scheduler sent command 0
02/20/2018 06:29:48;0100;Server@node2;Req;;Type 21 request received from Scheduler@node2.supernodexp.hpc, sock=16
02/20/2018 06:29:48;0100;Server@node2;Req;;Type 81 request received from Scheduler@node2.supernodexp.hpc, sock=16
02/20/2018 06:29:48;0100;Server@node2;Req;;Type 71 request received from Scheduler@node2.supernodexp.hpc, sock=16
02/20/2018 06:29:48;0100;Server@node2;Req;;Type 58 request received from Scheduler@node2.supernodexp.hpc, sock=16
02/20/2018 06:29:48;0100;Server@node2;Req;;Type 20 request received from Scheduler@node2.supernodexp.hpc, sock=16
02/20/2018 06:29:48;0100;Server@node2;Req;;Type 51 request received from Scheduler@node2.supernodexp.hpc, sock=16
02/20/2018 06:29:48;0100;Server@node2;Req;;Type 23 request received from Scheduler@node2.supernodexp.hpc, sock=16
02/20/2018 06:29:48;0008;Server@node2;Job;4200.node2.supernodexp.hpc;Job Run at request of Scheduler@node2.supernodexp.hpc on exec_vnode (node14:ncpus=48:mem=5242880kb)
02/20/2018 06:29:48;0001;Server@node2;Svr;Server@node2;Success (0) in req_runjob2, return value of svr_startjob is 0
02/20/2018 06:29:48;0100;Server@node2;Req;;Type 11 request received from Scheduler@node2.supernodexp.hpc, sock=16
02/20/2018 06:29:48;0008;Server@node2;Job;4218.node2.supernodexp.hpc;Job Modified at request of Scheduler@node2.supernodexp.hpc
02/20/2018 06:39:38;0080;Server@node2;Job;4198.node2.supernodexp.hpc;Obit received momhop:1 serverhop:1 state:4 substate:42
02/20/2018 06:39:39;0010;Server@node2;Job;4198.node2.supernodexp.hpc;Exit_status=0 resources_used.cpupercent=4741 resources_used.cput=08:23:36 resources_used.mem=7863800kb resources_used.ncpus=48 resources_used.vmem=47424648kb resources_used.walltime=00:10:45
02/20/2018 06:39:39;0100;Server@node2;Job;4198.node2.supernodexp.hpc;dequeuing from workq, state 5
02/20/2018 06:39:39;0040;Server@node2;Svr;node2.supernodexp.hpc;Scheduler sent command 2
02/20/2018 06:39:39;0040;Server@node2;Svr;node2.supernodexp.hpc;Scheduler sent command 0
02/20/2018 06:39:39;0100;Server@node2;Req;;Type 21 request received from Scheduler@node2.supernodexp.hpc, sock=16
02/20/2018 06:39:39;0100;Server@node2;Req;;Type 81 request received from Scheduler@node2.supernodexp.hpc, sock=16
02/20/2018 06:39:39;0100;Server@node2;Req;;Type 71 request received from Scheduler@node2.supernodexp.hpc, sock=16
02/20/2018 06:39:39;0100;Server@node2;Req;;Type 58 request received from Scheduler@node2.supernodexp.hpc, sock=16
02/20/2018 06:39:39;0100;Server@node2;Req;;Type 20 request received from Scheduler@node2.supernodexp.hpc, sock=16
02/20/2018 06:39:39;0100;Server@node2;Req;;Type 51 request received from Scheduler@node2.supernodexp.hpc, sock=16
02/20/2018 06:39:40;0100;Server@node2;Req;;Type 23 request received from Scheduler@node2.supernodexp.hpc, sock=16
02/20/2018 06:39:40;0008;Server@node2;Job;4218.node2.supernodexp.hpc;Job Run at request of Scheduler@node2.supernodexp.hpc on exec_vnode (node13:ncpus=48:mem=5242880kb)
02/20/2018 06:39:40;0001;Server@node2;Svr;Server@node2;Success (0) in req_runjob2, return value of svr_startjob is 0
02/20/2018 06:39:40;0100;Server@node2;Req;;Type 11 request received from Scheduler@node2.supernodexp.hpc, sock=16
02/20/2018 06:39:40;0008;Server@node2;Job;4237.node2.supernodexp.hpc;Job Modified at request of Scheduler@node2.supernodexp.hpc
02/20/2018 06:40:31;0080;Server@node2;Job;4200.node2.supernodexp.hpc;Obit received momhop:1 serverhop:1 state:4 substate:42
02/20/2018 06:40:33;0010;Server@node2;Job;4200.node2.supernodexp.hpc;Exit_status=0 resources_used.cpupercent=4731 resources_used.cput=08:20:09 resources_used.mem=7924152kb resources_used.ncpus=48 resources_used.vmem=47424524kb resources_used.walltime=00:10:44
02/20/2018 06:40:33;0100;Server@node2;Job;4200.node2.supernodexp.hpc;dequeuing from workq, state 5
02/20/2018 06:40:33;0040;Server@node2;Svr;node2.supernodexp.hpc;Scheduler sent command 2
02/20/2018 06:40:33;0040;Server@node2;Svr;node2.supernodexp.hpc;Scheduler sent command 0
02/20/2018 06:40:33;0100;Server@node2;Req;;Type 21 request received from Scheduler@node2.supernodexp.hpc, sock=16
02/20/2018 06:40:33;0100;Server@node2;Req;;Type 81 request received from Scheduler@node2.supernodexp.hpc, sock=16
02/20/2018 06:40:33;0100;Server@node2;Req;;Type 71 request received from Scheduler@node2.supernodexp.hpc, sock=16
02/20/2018 06:40:33;0100;Server@node2;Req;;Type 58 request received from Scheduler@node2.supernodexp.hpc, sock=16
02/20/2018 06:40:33;0100;Server@node2;Req;;Type 20 request received from Scheduler@node2.supernodexp.hpc, sock=16
02/20/2018 06:40:33;0100;Server@node2;Req;;Type 51 request received from Scheduler@node2.supernodexp.hpc, sock=16
02/20/2018 06:40:33;0100;Server@node2;Req;;Type 23 request received from Scheduler@node2.supernodexp.hpc, sock=16
02/20/2018 06:40:33;0008;Server@node2;Job;4237.node2.supernodexp.hpc;Job Run at request of Scheduler@node2.supernodexp.hpc on exec_vnode (node14:ncpus=48:mem=5242880kb)
02/20/2018 06:40:33;0001;Server@node2;Svr;Server@node2;Success (0) in req_runjob2, return value of svr_startjob is 0
02/20/2018 06:40:33;0100;Server@node2;Req;;Type 11 request received from Scheduler@node2.supernodexp.hpc, sock=16
02/20/2018 06:40:33;0008;Server@node2;Job;4246.node2.supernodexp.hpc;Job Modified at request of Scheduler@node2.supernodexp.hpc
02/20/2018 06:50:27;0080;Server@node2;Job;4218.node2.supernodexp.hpc;Obit received momhop:1 serverhop:1 state:4 substate:42
02/20/2018 06:50:29;0010;Server@node2;Job;4218.node2.supernodexp.hpc;Exit_status=0 resources_used.cpupercent=4740 resources_used.cput=08:22:22 resources_used.mem=7893328kb resources_used.ncpus=48 resources_used.vmem=47424032kb resources_used.walltime=00:10:48
02/20/2018 06:50:29;0100;Server@node2;Job;4218.node2.supernodexp.hpc;dequeuing from workq, state 5
02/20/2018 06:50:29;0040;Server@node2;Svr;node2.supernodexp.hpc;Scheduler sent command 2
02/20/2018 06:50:29;0040;Server@node2;Svr;node2.supernodexp.hpc;Scheduler sent command 0
02/20/2018 06:50:29;0100;Server@node2;Req;;Type 21 request received from Scheduler@node2.supernodexp.hpc, sock=16
02/20/2018 06:50:29;0100;Server@node2;Req;;Type 81 request received from Scheduler@node2.supernodexp.hpc, sock=16
02/20/2018 06:50:29;0100;Server@node2;Req;;Type 71 request received from Scheduler@node2.supernodexp.hpc, sock=16
02/20/2018 06:50:29;0100;Server@node2;Req;;Type 58 request received from Scheduler@node2.supernodexp.hpc, sock=16
02/20/2018 06:50:29;0100;Server@node2;Req;;Type 20 request received from Scheduler@node2.supernodexp.hpc, sock=16
02/20/2018 06:50:29;0100;Server@node2;Req;;Type 51 request received from Scheduler@node2.supernodexp.hpc, sock=16
02/20/2018 06:50:29;0100;Server@node2;Req;;Type 23 request received from Scheduler@node2.supernodexp.hpc, sock=16
02/20/2018 06:50:29;0008;Server@node2;Job;4246.node2.supernodexp.hpc;Job Run at request of Scheduler@node2.supernodexp.hpc on exec_vnode (node13:ncpus=48:mem=5242880kb)
02/20/2018 06:50:29;0001;Server@node2;Svr;Server@node2;Success (0) in req_runjob2, return value of svr_startjob is 0
02/20/2018 06:50:29;0100;Server@node2;Req;;Type 11 request received from Scheduler@node2.supernodexp.hpc, sock=16
02/20/2018 06:50:29;0008;Server@node2;Job;4250.node2.supernodexp.hpc;Job Modified at request of Scheduler@node2.supernodexp.hpc
02/20/2018 06:51:07;0080;Server@node2;Job;4237.node2.supernodexp.hpc;Obit received momhop:1 serverhop:1 state:4 substate:42
02/20/2018 06:51:08;0010;Server@node2;Job;4237.node2.supernodexp.hpc;Exit_status=0 resources_used.cpupercent=4745 resources_used.cput=08:15:25 resources_used.mem=7963740kb resources_used.ncpus=48 resources_used.vmem=47424428kb resources_used.walltime=00:10:34
02/20/2018 06:51:08;0100;Server@node2;Job;4237.node2.supernodexp.hpc;dequeuing from workq, state 5
02/20/2018 06:51:08;0040;Server@node2;Svr;node2.supernodexp.hpc;Scheduler sent command 2
02/20/2018 06:51:08;0040;Server@node2;Svr;node2.supernodexp.hpc;Scheduler sent command 0
02/20/2018 06:51:08;0100;Server@node2;Req;;Type 21 request received from Scheduler@node2.supernodexp.hpc, sock=16
02/20/2018 06:51:08;0100;Server@node2;Req;;Type 81 request received from Scheduler@node2.supernodexp.hpc, sock=16
02/20/2018 06:51:08;0100;Server@node2;Req;;Type 71 request received from Scheduler@node2.supernodexp.hpc, sock=16
02/20/2018 06:51:08;0100;Server@node2;Req;;Type 58 request received from Scheduler@node2.supernodexp.hpc, sock=16
02/20/2018 06:51:08;0100;Server@node2;Req;;Type 20 request received from Scheduler@node2.supernodexp.hpc, sock=16
02/20/2018 06:51:08;0100;Server@node2;Req;;Type 51 request received from Scheduler@node2.supernodexp.hpc, sock=16
02/20/2018 06:51:08;0100;Server@node2;Req;;Type 23 request received from Scheduler@node2.supernodexp.hpc, sock=16
02/20/2018 06:51:08;0008;Server@node2;Job;4250.node2.supernodexp.hpc;Job Run at request of Scheduler@node2.supernodexp.hpc on exec_vnode (node14:ncpus=48:mem=5242880kb)
02/20/2018 06:51:08;0001;Server@node2;Svr;Server@node2;Success (0) in req_runjob2, return value of svr_startjob is 0
02/20/2018 06:51:08;0100;Server@node2;Req;;Type 11 request received from Scheduler@node2.supernodexp.hpc, sock=16
02/20/2018 06:51:08;0008;Server@node2;Job;4258.node2.supernodexp.hpc;Job Modified at request of Scheduler@node2.supernodexp.hpc
02/20/2018 07:01:08;0040;Server@node2;Svr;node2.supernodexp.hpc;Scheduler sent command 3
02/20/2018 07:01:08;0040;Server@node2;Svr;node2.supernodexp.hpc;Scheduler sent command 0
02/20/2018 07:01:08;0100;Server@node2;Req;;Type 21 request received from Scheduler@node2.supernodexp.hpc, sock=16
02/20/2018 07:01:08;0100;Server@node2;Req;;Type 81 request received from Scheduler@node2.supernodexp.hpc, sock=16
02/20/2018 07:01:08;0100;Server@node2;Req;;Type 71 request received from Scheduler@node2.supernodexp.hpc, sock=16
02/20/2018 07:01:08;0100;Server@node2;Req;;Type 58 request received from Scheduler@node2.supernodexp.hpc, sock=16
02/20/2018 07:01:08;0100;Server@node2;Req;;Type 20 request received from Scheduler@node2.supernodexp.hpc, sock=16
02/20/2018 07:01:08;0100;Server@node2;Req;;Type 51 request received from Scheduler@node2.supernodexp.hpc, sock=16
02/20/2018 07:01:24;0080;Server@node2;Job;4246.node2.supernodexp.hpc;Obit received momhop:1 serverhop:1 state:4 substate:42
02/20/2018 07:01:26;0010;Server@node2;Job;4246.node2.supernodexp.hpc;Exit_status=0 resources_used.cpupercent=4738 resources_used.cput=08:24:55 resources_used.mem=7896536kb resources_used.ncpus=48 resources_used.vmem=47424024kb resources_used.walltime=00:10:55
02/20/2018 07:01:26;0100;Server@node2;Job;4246.node2.supernodexp.hpc;dequeuing from workq, state 5
02/20/2018 07:01:26;0040;Server@node2;Svr;node2.supernodexp.hpc;Scheduler sent command 2
02/20/2018 07:01:26;0040;Server@node2;Svr;node2.supernodexp.hpc;Scheduler sent command 0
02/20/2018 07:01:26;0100;Server@node2;Req;;Type 21 request received from Scheduler@node2.supernodexp.hpc, sock=16
02/20/2018 07:01:26;0100;Server@node2;Req;;Type 81 request received from Scheduler@node2.supernodexp.hpc, sock=16
02/20/2018 07:01:26;0100;Server@node2;Req;;Type 71 request received from Scheduler@node2.supernodexp.hpc, sock=16
02/20/2018 07:01:26;0100;Server@node2;Req;;Type 58 request received from Scheduler@node2.supernodexp.hpc, sock=16
02/20/2018 07:01:26;0100;Server@node2;Req;;Type 20 request received from Scheduler@node2.supernodexp.hpc, sock=16
02/20/2018 07:01:26;0100;Server@node2;Req;;Type 51 request received from Scheduler@node2.supernodexp.hpc, sock=16
02/20/2018 07:01:26;0100;Server@node2;Req;;Type 23 request received from Scheduler@node2.supernodexp.hpc, sock=16
02/20/2018 07:01:26;0008;Server@node2;Job;4258.node2.supernodexp.hpc;Job Run at request of Scheduler@node2.supernodexp.hpc on exec_vnode (node13:ncpus=48:mem=5242880kb)
02/20/2018 07:01:26;0001;Server@node2;Svr;Server@node2;Success (0) in req_runjob2, return value of svr_startjob is 0
02/20/2018 07:01:26;0100;Server@node2;Req;;Type 11 request received from Scheduler@node2.supernodexp.hpc, sock=16
02/20/2018 07:01:26;0008;Server@node2;Job;4341.node2.supernodexp.hpc;Job Modified at request of Scheduler@node2.supernodexp.hpc
02/20/2018 07:01:50;0080;Server@node2;Job;4250.node2.supernodexp.hpc;Obit received momhop:1 serverhop:1 state:4 substate:42
02/20/2018 07:01:51;0010;Server@node2;Job;4250.node2.supernodexp.hpc;Exit_status=0 resources_used.cpupercent=4750 resources_used.cput=08:17:52 resources_used.mem=7921280kb resources_used.ncpus=48 resources_used.vmem=47424200kb resources_used.walltime=00:10:43
02/20/2018 07:01:51;0100;Server@node2;Job;4250.node2.supernodexp.hpc;dequeuing from workq, state 5
02/20/2018 07:01:51;0040;Server@node2;Svr;node2.supernodexp.hpc;Scheduler sent command 2
02/20/2018 07:01:51;0040;Server@node2;Svr;node2.supernodexp.hpc;Scheduler sent command 0
02/20/2018 07:01:51;0100;Server@node2;Req;;Type 21 request received from Scheduler@node2.supernodexp.hpc, sock=16
02/20/2018 07:01:51;0100;Server@node2;Req;;Type 81 request received from Scheduler@node2.supernodexp.hpc, sock=16
02/20/2018 07:01:51;0100;Server@node2;Req;;Type 71 request received from Scheduler@node2.supernodexp.hpc, sock=16
02/20/2018 07:01:51;0100;Server@node2;Req;;Type 58 request received from Scheduler@node2.supernodexp.hpc, sock=16
02/20/2018 07:01:51;0100;Server@node2;Req;;Type 20 request received from Scheduler@node2.supernodexp.hpc, sock=16
02/20/2018 07:01:51;0100;Server@node2;Req;;Type 51 request received from Scheduler@node2.supernodexp.hpc, sock=16
02/20/2018 07:01:52;0100;Server@node2;Req;;Type 23 request received from Scheduler@node2.supernodexp.hpc, sock=16
02/20/2018 07:01:52;0008;Server@node2;Job;4341.node2.supernodexp.hpc;Job Run at request of Scheduler@node2.supernodexp.hpc on exec_vnode (node14:ncpus=48:mem=5242880kb)
02/20/2018 07:01:52;0001;Server@node2;Svr;Server@node2;Success (0) in req_runjob2, return value of svr_startjob is 0
02/20/2018 07:01:52;0100;Server@node2;Req;;Type 11 request received from Scheduler@node2.supernodexp.hpc, sock=16
02/20/2018 07:01:52;0008;Server@node2;Job;4342.node2.supernodexp.hpc;Job Modified at request of Scheduler@node2.supernodexp.hpc
02/20/2018 07:11:51;0040;Server@node2;Svr;node2.supernodexp.hpc;Scheduler sent command 3
02/20/2018 07:11:51;0040;Server@node2;Svr;node2.supernodexp.hpc;Scheduler sent command 0
02/20/2018 07:11:51;0100;Server@node2;Req;;Type 21 request received from Scheduler@node2.supernodexp.hpc, sock=16
02/20/2018 07:11:51;0100;Server@node2;Req;;Type 81 request received from Scheduler@node2.supernodexp.hpc, sock=16
02/20/2018 07:11:51;0100;Server@node2;Req;;Type 71 request received from Scheduler@node2.supernodexp.hpc, sock=16
02/20/2018 07:11:51;0100;Server@node2;Req;;Type 58 request received from Scheduler@node2.supernodexp.hpc, sock=16
02/20/2018 07:11:51;0100;Server@node2;Req;;Type 20 request received from Scheduler@node2.supernodexp.hpc, sock=16
02/20/2018 07:11:51;0100;Server@node2;Req;;Type 51 request received from Scheduler@node2.supernodexp.hpc, sock=16
02/20/2018 07:12:07;0080;Server@node2;Job;4258.node2.supernodexp.hpc;Obit received momhop:1 serverhop:1 state:4 substate:42
02/20/2018 07:12:08;0010;Server@node2;Job;4258.node2.supernodexp.hpc;Exit_status=0 resources_used.cpupercent=4748 resources_used.cput=08:20:16 resources_used.mem=7904304kb resources_used.ncpus=48 resources_used.vmem=47424328kb resources_used.walltime=00:10:41
02/20/2018 07:12:08;0100;Server@node2;Job;4258.node2.supernodexp.hpc;dequeuing from workq, state 5
02/20/2018 07:12:08;0040;Server@node2;Svr;node2.supernodexp.hpc;Scheduler sent command 2
02/20/2018 07:12:08;0040;Server@node2;Svr;node2.supernodexp.hpc;Scheduler sent command 0
02/20/2018 07:12:08;0100;Server@node2;Req;;Type 21 request received from Scheduler@node2.supernodexp.hpc, sock=16
02/20/2018 07:12:08;0100;Server@node2;Req;;Type 81 request received from Scheduler@node2.supernodexp.hpc, sock=16
02/20/2018 07:12:08;0100;Server@node2;Req;;Type 71 request received from Scheduler@node2.supernodexp.hpc, sock=16
02/20/2018 07:12:08;0100;Server@node2;Req;;Type 58 request received from Scheduler@node2.supernodexp.hpc, sock=16
02/20/2018 07:12:08;0100;Server@node2;Req;;Type 20 request received from Scheduler@node2.supernodexp.hpc, sock=16
02/20/2018 07:12:08;0100;Server@node2;Req;;Type 51 request received from Scheduler@node2.supernodexp.hpc, sock=16
02/20/2018 07:12:08;0100;Server@node2;Req;;Type 23 request received from Scheduler@node2.supernodexp.hpc, sock=16
02/20/2018 07:12:08;0008;Server@node2;Job;4342.node2.supernodexp.hpc;Job Run at request of Scheduler@node2.supernodexp.hpc on exec_vnode (node13:ncpus=48:mem=5242880kb)
02/20/2018 07:12:08;0001;Server@node2;Svr;Server@node2;Success (0) in req_runjob2, return value of svr_startjob is 0
02/20/2018 07:12:08;0100;Server@node2;Req;;Type 11 request received from Scheduler@node2.supernodexp.hpc, sock=16
02/20/2018 07:12:08;0008;Server@node2;Job;4345.node2.supernodexp.hpc;Job Modified at request of Scheduler@node2.supernodexp.hpc
02/20/2018 07:12:28;0080;Server@node2;Job;4341.node2.supernodexp.hpc;Obit received momhop:1 serverhop:1 state:4 substate:42
02/20/2018 07:12:29;0010;Server@node2;Job;4341.node2.supernodexp.hpc;Exit_status=0 resources_used.cpupercent=4735 resources_used.cput=08:17:57 resources_used.mem=7938212kb resources_used.ncpus=48 resources_used.vmem=47424380kb resources_used.walltime=00:10:36
02/20/2018 07:12:29;0100;Server@node2;Job;4341.node2.supernodexp.hpc;dequeuing from workq, state 5
02/20/2018 07:12:29;0040;Server@node2;Svr;node2.supernodexp.hpc;Scheduler sent command 2
02/20/2018 07:12:29;0040;Server@node2;Svr;node2.supernodexp.hpc;Scheduler sent command 0
02/20/2018 07:12:29;0100;Server@node2;Req;;Type 21 request received from Scheduler@node2.supernodexp.hpc, sock=16
02/20/2018 07:12:29;0100;Server@node2;Req;;Type 81 request received from Scheduler@node2.supernodexp.hpc, sock=16
02/20/2018 07:12:29;0100;Server@node2;Req;;Type 71 request received from Scheduler@node2.supernodexp.hpc, sock=16
02/20/2018 07:12:29;0100;Server@node2;Req;;Type 58 request received from Scheduler@node2.supernodexp.hpc, sock=16
02/20/2018 07:12:29;0100;Server@node2;Req;;Type 20 request received from Scheduler@node2.supernodexp.hpc, sock=16
02/20/2018 07:12:29;0100;Server@node2;Req;;Type 51 request received from Scheduler@node2.supernodexp.hpc, sock=16
02/20/2018 07:12:29;0100;Server@node2;Req;;Type 23 request received from Scheduler@node2.supernodexp.hpc, sock=16
02/20/2018 07:12:29;0008;Server@node2;Job;4345.node2.supernodexp.hpc;Job Run at request of Scheduler@node2.supernodexp.hpc on exec_vnode (node14:ncpus=48:mem=5242880kb)
02/20/2018 07:12:29;0001;Server@node2;Svr;Server@node2;Success (0) in req_runjob2, return value of svr_startjob is 0
02/20/2018 07:12:29;0100;Server@node2;Req;;Type 11 request received from Scheduler@node2.supernodexp.hpc, sock=16
02/20/2018 07:12:29;0008;Server@node2;Job;4358.node2.supernodexp.hpc;Job Modified at request of Scheduler@node2.supernodexp.hpc
02/20/2018 07:22:29;0040;Server@node2;Svr;node2.supernodexp.hpc;Scheduler sent command 3
02/20/2018 07:22:29;0040;Server@node2;Svr;node2.supernodexp.hpc;Scheduler sent command 0
02/20/2018 07:22:29;0100;Server@node2;Req;;Type 21 request received from Scheduler@node2.supernodexp.hpc, sock=16
02/20/2018 07:22:29;0100;Server@node2;Req;;Type 81 request received from Scheduler@node2.supernodexp.hpc, sock=16
02/20/2018 07:22:29;0100;Server@node2;Req;;Type 71 request received from Scheduler@node2.supernodexp.hpc, sock=16
02/20/2018 07:22:29;0100;Server@node2;Req;;Type 58 request received from Scheduler@node2.supernodexp.hpc, sock=16
02/20/2018 07:22:29;0100;Server@node2;Req;;Type 20 request received from Scheduler@node2.supernodexp.hpc, sock=16
02/20/2018 07:22:29;0100;Server@node2;Req;;Type 51 request received from Scheduler@node2.supernodexp.hpc, sock=16
02/20/2018 07:22:47;0080;Server@node2;Job;4342.node2.supernodexp.hpc;Obit received momhop:1 serverhop:1 state:4 substate:42
02/20/2018 07:22:48;0010;Server@node2;Job;4342.node2.supernodexp.hpc;Exit_status=0 resources_used.cpupercent=4745 resources_used.cput=08:19:02 resources_used.mem=7896636kb resources_used.ncpus=48 resources_used.vmem=47424324kb resources_used.walltime=00:10:39
02/20/2018 07:22:48;0100;Server@node2;Job;4342.node2.supernodexp.hpc;dequeuing from workq, state 5
02/20/2018 07:22:48;0040;Server@node2;Svr;node2.supernodexp.hpc;Scheduler sent command 2
02/20/2018 07:22:48;0040;Server@node2;Svr;node2.supernodexp.hpc;Scheduler sent command 0
02/20/2018 07:22:48;0100;Server@node2;Req;;Type 21 request received from Scheduler@node2.supernodexp.hpc, sock=16
02/20/2018 07:22:48;0100;Server@node2;Req;;Type 81 request received from Scheduler@node2.supernodexp.hpc, sock=16
02/20/2018 07:22:48;0100;Server@node2;Req;;Type 71 request received from Scheduler@node2.supernodexp.hpc, sock=16
02/20/2018 07:22:48;0100;Server@node2;Req;;Type 58 request received from Scheduler@node2.supernodexp.hpc, sock=16
02/20/2018 07:22:48;0100;Server@node2;Req;;Type 20 request received from Scheduler@node2.supernodexp.hpc, sock=16
02/20/2018 07:22:48;0100;Server@node2;Req;;Type 51 request received from Scheduler@node2.supernodexp.hpc, sock=16
02/20/2018 07:22:49;0100;Server@node2;Req;;Type 23 request received from Scheduler@node2.supernodexp.hpc, sock=16
02/20/2018 07:22:49;0008;Server@node2;Job;4358.node2.supernodexp.hpc;Job Run at request of Scheduler@node2.supernodexp.hpc on exec_vnode (node13:ncpus=48:mem=5242880kb)
02/20/2018 07:22:49;0001;Server@node2;Svr;Server@node2;Success (0) in req_runjob2, return value of svr_startjob is 0
02/20/2018 07:22:49;0100;Server@node2;Req;;Type 11 request received from Scheduler@node2.supernodexp.hpc, sock=16
02/20/2018 07:22:49;0008;Server@node2;Job;4370.node2.supernodexp.hpc;Job Modified at request of Scheduler@node2.supernodexp.hpc
02/20/2018 07:23:06;0080;Server@node2;Job;4345.node2.supernodexp.hpc;Obit received momhop:1 serverhop:1 state:4 substate:42
02/20/2018 07:23:07;0010;Server@node2;Job;4345.node2.supernodexp.hpc;Exit_status=0 resources_used.cpupercent=4732 resources_used.cput=08:17:14 resources_used.mem=7933548kb resources_used.ncpus=48 resources_used.vmem=47424212kb resources_used.walltime=00:10:37
02/20/2018 07:23:07;0100;Server@node2;Job;4345.node2.supernodexp.hpc;dequeuing from workq, state 5
02/20/2018 07:23:07;0040;Server@node2;Svr;node2.supernodexp.hpc;Scheduler sent command 2
02/20/2018 07:23:07;0040;Server@node2;Svr;node2.supernodexp.hpc;Scheduler sent command 0
02/20/2018 07:23:07;0100;Server@node2;Req;;Type 21 request received from Scheduler@node2.supernodexp.hpc, sock=16
02/20/2018 07:23:07;0100;Server@node2;Req;;Type 81 request received from Scheduler@node2.supernodexp.hpc, sock=16
02/20/2018 07:23:07;0100;Server@node2;Req;;Type 71 request received from Scheduler@node2.supernodexp.hpc, sock=16
02/20/2018 07:23:07;0100;Server@node2;Req;;Type 58 request received from Scheduler@node2.supernodexp.hpc, sock=16
02/20/2018 07:23:07;0100;Server@node2;Req;;Type 20 request received from Scheduler@node2.supernodexp.hpc, sock=16
02/20/2018 07:23:07;0100;Server@node2;Req;;Type 51 request received from Scheduler@node2.supernodexp.hpc, sock=16
02/20/2018 07:23:07;0100;Server@node2;Req;;Type 23 request received from Scheduler@node2.supernodexp.hpc, sock=16
02/20/2018 07:23:07;0008;Server@node2;Job;4370.node2.supernodexp.hpc;Job Run at request of Scheduler@node2.supernodexp.hpc on exec_vnode (node14:ncpus=48:mem=5242880kb)
02/20/2018 07:23:07;0001;Server@node2;Svr;Server@node2;Success (0) in req_runjob2, return value of svr_startjob is 0
02/20/2018 07:23:07;0100;Server@node2;Req;;Type 11 request received from Scheduler@node2.supernodexp.hpc, sock=16
02/20/2018 07:23:07;0008;Server@node2;Job;4389.node2.supernodexp.hpc;Job Modified at request of Scheduler@node2.supernodexp.hpc
02/20/2018 07:33:07;0040;Server@node2;Svr;node2.supernodexp.hpc;Scheduler sent command 3
02/20/2018 07:33:07;0040;Server@node2;Svr;node2.supernodexp.hpc;Scheduler sent command 0
02/20/2018 07:33:07;0100;Server@node2;Req;;Type 21 request received from Scheduler@node2.supernodexp.hpc, sock=16
02/20/2018 07:33:07;0100;Server@node2;Req;;Type 81 request received from Scheduler@node2.supernodexp.hpc, sock=16
02/20/2018 07:33:07;0100;Server@node2;Req;;Type 71 request received from Scheduler@node2.supernodexp.hpc, sock=16
02/20/2018 07:33:07;0100;Server@node2;Req;;Type 58 request received from Scheduler@node2.supernodexp.hpc, sock=16
02/20/2018 07:33:07;0100;Server@node2;Req;;Type 20 request received from Scheduler@node2.supernodexp.hpc, sock=16
02/20/2018 07:33:07;0100;Server@node2;Req;;Type 51 request received from Scheduler@node2.supernodexp.hpc, sock=16
02/20/2018 07:33:32;0080;Server@node2;Job;4358.node2.supernodexp.hpc;Obit received momhop:1 serverhop:1 state:4 substate:42
02/20/2018 07:33:34;0010;Server@node2;Job;4358.node2.supernodexp.hpc;Exit_status=0 resources_used.cpupercent=4747 resources_used.cput=08:19:50 resources_used.mem=7935940kb resources_used.ncpus=48 resources_used.vmem=47425244kb resources_used.walltime=00:10:44
02/20/2018 07:33:34;0100;Server@node2;Job;4358.node2.supernodexp.hpc;dequeuing from workq, state 5
02/20/2018 07:33:34;0040;Server@node2;Svr;node2.supernodexp.hpc;Scheduler sent command 2
02/20/2018 07:33:34;0040;Server@node2;Svr;node2.supernodexp.hpc;Scheduler sent command 0
02/20/2018 07:33:34;0100;Server@node2;Req;;Type 21 request received from Scheduler@node2.supernodexp.hpc, sock=16
02/20/2018 07:33:34;0100;Server@node2;Req;;Type 81 request received from Scheduler@node2.supernodexp.hpc, sock=16
02/20/2018 07:33:34;0100;Server@node2;Req;;Type 71 request received from Scheduler@node2.supernodexp.hpc, sock=16
02/20/2018 07:33:34;0100;Server@node2;Req;;Type 58 request received from Scheduler@node2.supernodexp.hpc, sock=16
02/20/2018 07:33:34;0100;Server@node2;Req;;Type 20 request received from Scheduler@node2.supernodexp.hpc, sock=16
02/20/2018 07:33:34;0100;Server@node2;Req;;Type 51 request received from Scheduler@node2.supernodexp.hpc, sock=16
02/20/2018 07:33:34;0100;Server@node2;Req;;Type 23 request received from Scheduler@node2.supernodexp.hpc, sock=16
02/20/2018 07:33:34;0008;Server@node2;Job;4389.node2.supernodexp.hpc;Job Run at request of Scheduler@node2.supernodexp.hpc on exec_vnode (node13:ncpus=48:mem=5242880kb)
02/20/2018 07:33:34;0001;Server@node2;Svr;Server@node2;Success (0) in req_runjob2, return value of svr_startjob is 0
02/20/2018 07:33:34;0100;Server@node2;Req;;Type 11 request received from Scheduler@node2.supernodexp.hpc, sock=16
02/20/2018 07:33:34;0008;Server@node2;Job;4393.node2.supernodexp.hpc;Job Modified at request of Scheduler@node2.supernodexp.hpc
02/20/2018 07:33:47;0080;Server@node2;Job;4370.node2.supernodexp.hpc;Obit received momhop:1 serverhop:1 state:4 substate:42
02/20/2018 07:33:48;0010;Server@node2;Job;4370.node2.supernodexp.hpc;Exit_status=0 resources_used.cpupercent=4745 resources_used.cput=08:18:55 resources_used.mem=7871656kb resources_used.ncpus=48 resources_used.vmem=47423904kb resources_used.walltime=00:10:41
02/20/2018 07:33:48;0100;Server@node2;Job;4370.node2.supernodexp.hpc;dequeuing from workq, state 5
02/20/2018 07:33:48;0040;Server@node2;Svr;node2.supernodexp.hpc;Scheduler sent command 2
02/20/2018 07:33:48;0040;Server@node2;Svr;node2.supernodexp.hpc;Scheduler sent command 0
02/20/2018 07:33:48;0100;Server@node2;Req;;Type 21 request received from Scheduler@node2.supernodexp.hpc, sock=16
02/20/2018 07:33:48;0100;Server@node2;Req;;Type 81 request received from Scheduler@node2.supernodexp.hpc, sock=16
02/20/2018 07:33:48;0100;Server@node2;Req;;Type 71 request received from Scheduler@node2.supernodexp.hpc, sock=16
02/20/2018 07:33:48;0100;Server@node2;Req;;Type 58 request received from Scheduler@node2.supernodexp.hpc, sock=16
02/20/2018 07:33:48;0100;Server@node2;Req;;Type 20 request received from Scheduler@node2.supernodexp.hpc, sock=16
02/20/2018 07:33:48;0100;Server@node2;Req;;Type 51 request received from Scheduler@node2.supernodexp.hpc, sock=16
02/20/2018 07:33:49;0100;Server@node2;Req;;Type 23 request received from Scheduler@node2.supernodexp.hpc, sock=16
02/20/2018 07:33:49;0008;Server@node2;Job;4393.node2.supernodexp.hpc;Job Run at request of Scheduler@node2.supernodexp.hpc on exec_vnode (node14:ncpus=48:mem=5242880kb)
02/20/2018 07:33:49;0001;Server@node2;Svr;Server@node2;Success (0) in req_runjob2, return value of svr_startjob is 0
02/20/2018 07:33:49;0100;Server@node2;Req;;Type 11 request received from Scheduler@node2.supernodexp.hpc, sock=16
02/20/2018 07:33:49;0008;Server@node2;Job;4397.node2.supernodexp.hpc;Job Modified at request of Scheduler@node2.supernodexp.hpc
02/20/2018 07:43:48;0040;Server@node2;Svr;node2.supernodexp.hpc;Scheduler sent command 3
02/20/2018 07:43:48;0040;Server@node2;Svr;node2.supernodexp.hpc;Scheduler sent command 0
02/20/2018 07:43:48;0100;Server@node2;Req;;Type 21 request received from Scheduler@node2.supernodexp.hpc, sock=16
02/20/2018 07:43:48;0100;Server@node2;Req;;Type 81 request received from Scheduler@node2.supernodexp.hpc, sock=16
02/20/2018 07:43:48;0100;Server@node2;Req;;Type 71 request received from Scheduler@node2.supernodexp.hpc, sock=16
02/20/2018 07:43:48;0100;Server@node2;Req;;Type 58 request received from Scheduler@node2.supernodexp.hpc, sock=16
02/20/2018 07:43:48;0100;Server@node2;Req;;Type 20 request received from Scheduler@node2.supernodexp.hpc, sock=16
02/20/2018 07:43:48;0100;Server@node2;Req;;Type 51 request received from Scheduler@node2.supernodexp.hpc, sock=16
02/20/2018 07:44:40;0080;Server@node2;Job;4389.node2.supernodexp.hpc;Obit received momhop:1 serverhop:1 state:4 substate:42
02/20/2018 07:44:40;0080;Server@node2;Job;4393.node2.supernodexp.hpc;Obit received momhop:1 serverhop:1 state:4 substate:42
02/20/2018 07:44:41;0010;Server@node2;Job;4393.node2.supernodexp.hpc;Exit_status=0 resources_used.cpupercent=4775 resources_used.cput=08:13:31 resources_used.mem=7972008kb resources_used.ncpus=48 resources_used.vmem=47424096kb resources_used.walltime=00:10:52
02/20/2018 07:44:41;0100;Server@node2;Job;4393.node2.supernodexp.hpc;dequeuing from workq, state 5
02/20/2018 07:44:41;0040;Server@node2;Svr;node2.supernodexp.hpc;Scheduler sent command 2
02/20/2018 07:44:41;0040;Server@node2;Svr;node2.supernodexp.hpc;Scheduler sent command 0
02/20/2018 07:44:41;0100;Server@node2;Req;;Type 21 request received from Scheduler@node2.supernodexp.hpc, sock=16
02/20/2018 07:44:41;0100;Server@node2;Req;;Type 81 request received from Scheduler@node2.supernodexp.hpc, sock=16
02/20/2018 07:44:41;0100;Server@node2;Req;;Type 71 request received from Scheduler@node2.supernodexp.hpc, sock=16
02/20/2018 07:44:41;0100;Server@node2;Req;;Type 58 request received from Scheduler@node2.supernodexp.hpc, sock=16
02/20/2018 07:44:41;0100;Server@node2;Req;;Type 20 request received from Scheduler@node2.supernodexp.hpc, sock=16
02/20/2018 07:44:41;0100;Server@node2;Req;;Type 51 request received from Scheduler@node2.supernodexp.hpc, sock=16
02/20/2018 07:44:41;0010;Server@node2;Job;4389.node2.supernodexp.hpc;Exit_status=0 resources_used.cpupercent=4744 resources_used.cput=08:24:13 resources_used.mem=7898620kb resources_used.ncpus=48 resources_used.vmem=47424648kb resources_used.walltime=00:11:06
02/20/2018 07:44:41;0100;Server@node2;Job;4389.node2.supernodexp.hpc;dequeuing from workq, state 5
02/20/2018 07:44:42;0100;Server@node2;Req;;Type 23 request received from Scheduler@node2.supernodexp.hpc, sock=16
02/20/2018 07:44:42;0008;Server@node2;Job;4397.node2.supernodexp.hpc;Job Run at request of Scheduler@node2.supernodexp.hpc on exec_vnode (node14:ncpus=48:mem=5242880kb)
02/20/2018 07:44:42;0001;Server@node2;Svr;Server@node2;Success (0) in req_runjob2, return value of svr_startjob is 0
02/20/2018 07:44:42;0100;Server@node2;Req;;Type 11 request received from Scheduler@node2.supernodexp.hpc, sock=16
02/20/2018 07:44:42;0008;Server@node2;Job;4403.node2.supernodexp.hpc;Job Modified at request of Scheduler@node2.supernodexp.hpc
02/20/2018 07:44:42;0040;Server@node2;Svr;node2.supernodexp.hpc;Scheduler sent command 2
02/20/2018 07:44:42;0040;Server@node2;Svr;node2.supernodexp.hpc;Scheduler sent command 0
02/20/2018 07:44:42;0100;Server@node2;Req;;Type 21 request received from Scheduler@node2.supernodexp.hpc, sock=16
02/20/2018 07:44:42;0100;Server@node2;Req;;Type 81 request received from Scheduler@node2.supernodexp.hpc, sock=16
02/20/2018 07:44:42;0100;Server@node2;Req;;Type 71 request received from Scheduler@node2.supernodexp.hpc, sock=16
02/20/2018 07:44:42;0100;Server@node2;Req;;Type 58 request received from Scheduler@node2.supernodexp.hpc, sock=16
02/20/2018 07:44:42;0100;Server@node2;Req;;Type 20 request received from Scheduler@node2.supernodexp.hpc, sock=16
02/20/2018 07:44:42;0100;Server@node2;Req;;Type 51 request received from Scheduler@node2.supernodexp.hpc, sock=16
02/20/2018 07:44:42;0100;Server@node2;Req;;Type 23 request received from Scheduler@node2.supernodexp.hpc, sock=16
02/20/2018 07:44:42;0008;Server@node2;Job;4403.node2.supernodexp.hpc;Job Run at request of Scheduler@node2.supernodexp.hpc on exec_vnode (node13:ncpus=48:mem=5242880kb)
02/20/2018 07:44:42;0001;Server@node2;Svr;Server@node2;Success (0) in req_runjob2, return value of svr_startjob is 0
02/20/2018 07:44:42;0100;Server@node2;Req;;Type 11 request received from Scheduler@node2.supernodexp.hpc, sock=16
02/20/2018 07:44:42;0008;Server@node2;Job;4489.node2.supernodexp.hpc;Job Modified at request of Scheduler@node2.supernodexp.hpc
02/20/2018 07:54:42;0040;Server@node2;Svr;node2.supernodexp.hpc;Scheduler sent command 3
02/20/2018 07:54:42;0040;Server@node2;Svr;node2.supernodexp.hpc;Scheduler sent command 0
02/20/2018 07:54:42;0100;Server@node2;Req;;Type 21 request received from Scheduler@node2.supernodexp.hpc, sock=16
02/20/2018 07:54:42;0100;Server@node2;Req;;Type 81 request received from Scheduler@node2.supernodexp.hpc, sock=16
02/20/2018 07:54:42;0100;Server@node2;Req;;Type 71 request received from Scheduler@node2.supernodexp.hpc, sock=16
02/20/2018 07:54:42;0100;Server@node2;Req;;Type 58 request received from Scheduler@node2.supernodexp.hpc, sock=16
02/20/2018 07:54:42;0100;Server@node2;Req;;Type 20 request received from Scheduler@node2.supernodexp.hpc, sock=16
02/20/2018 07:54:42;0100;Server@node2;Req;;Type 51 request received from Scheduler@node2.supernodexp.hpc, sock=16
02/20/2018 07:55:15;0080;Server@node2;Job;4397.node2.supernodexp.hpc;Obit received momhop:1 serverhop:1 state:4 substate:42
02/20/2018 07:55:17;0010;Server@node2;Job;4397.node2.supernodexp.hpc;Exit_status=0 resources_used.cpupercent=4806 resources_used.cput=08:10:24 resources_used.mem=7949940kb resources_used.ncpus=48 resources_used.vmem=47423920kb resources_used.walltime=00:10:33
02/20/2018 07:55:17;0100;Server@node2;Job;4397.node2.supernodexp.hpc;dequeuing from workq, state 5
02/20/2018 07:55:17;0040;Server@node2;Svr;node2.supernodexp.hpc;Scheduler sent command 2
02/20/2018 07:55:17;0040;Server@node2;Svr;node2.supernodexp.hpc;Scheduler sent command 0
02/20/2018 07:55:17;0100;Server@node2;Req;;Type 21 request received from Scheduler@node2.supernodexp.hpc, sock=16
02/20/2018 07:55:17;0100;Server@node2;Req;;Type 81 request received from Scheduler@node2.supernodexp.hpc, sock=16
02/20/2018 07:55:17;0100;Server@node2;Req;;Type 71 request received from Scheduler@node2.supernodexp.hpc, sock=16
02/20/2018 07:55:17;0100;Server@node2;Req;;Type 58 request received from Scheduler@node2.supernodexp.hpc, sock=16
02/20/2018 07:55:17;0100;Server@node2;Req;;Type 20 request received from Scheduler@node2.supernodexp.hpc, sock=16
02/20/2018 07:55:17;0100;Server@node2;Req;;Type 51 request received from Scheduler@node2.supernodexp.hpc, sock=16
02/20/2018 07:55:17;0100;Server@node2;Req;;Type 23 request received from Scheduler@node2.supernodexp.hpc, sock=16
02/20/2018 07:55:17;0008;Server@node2;Job;4489.node2.supernodexp.hpc;Job Run at request of Scheduler@node2.supernodexp.hpc on exec_vnode (node14:ncpus=48:mem=5242880kb)
02/20/2018 07:55:17;0001;Server@node2;Svr;Server@node2;Success (0) in req_runjob2, return value of svr_startjob is 0
02/20/2018 07:55:17;0100;Server@node2;Req;;Type 11 request received from Scheduler@node2.supernodexp.hpc, sock=16
02/20/2018 07:55:17;0008;Server@node2;Job;4498.node2.supernodexp.hpc;Job Modified at request of Scheduler@node2.supernodexp.hpc
02/20/2018 07:55:29;0080;Server@node2;Job;4403.node2.supernodexp.hpc;Obit received momhop:1 serverhop:1 state:4 substate:42
02/20/2018 07:55:30;0010;Server@node2;Job;4403.node2.supernodexp.hpc;Exit_status=0 resources_used.cpupercent=4802 resources_used.cput=08:24:12 resources_used.mem=7906540kb resources_used.ncpus=48 resources_used.vmem=47424324kb resources_used.walltime=00:10:48
02/20/2018 07:55:30;0100;Server@node2;Job;4403.node2.supernodexp.hpc;dequeuing from workq, state 5
02/20/2018 07:55:30;0040;Server@node2;Svr;node2.supernodexp.hpc;Scheduler sent command 2
02/20/2018 07:55:30;0040;Server@node2;Svr;node2.supernodexp.hpc;Scheduler sent command 0
02/20/2018 07:55:30;0100;Server@node2;Req;;Type 21 request received from Scheduler@node2.supernodexp.hpc, sock=16
02/20/2018 07:55:30;0100;Server@node2;Req;;Type 81 request received from Scheduler@node2.supernodexp.hpc, sock=16
02/20/2018 07:55:30;0100;Server@node2;Req;;Type 71 request received from Scheduler@node2.supernodexp.hpc, sock=16
02/20/2018 07:55:30;0100;Server@node2;Req;;Type 58 request received from Scheduler@node2.supernodexp.hpc, sock=16
02/20/2018 07:55:30;0100;Server@node2;Req;;Type 20 request received from Scheduler@node2.supernodexp.hpc, sock=16
02/20/2018 07:55:30;0100;Server@node2;Req;;Type 51 request received from Scheduler@node2.supernodexp.hpc, sock=16
02/20/2018 07:55:31;0100;Server@node2;Req;;Type 23 request received from Scheduler@node2.supernodexp.hpc, sock=16
02/20/2018 07:55:31;0008;Server@node2;Job;4498.node2.supernodexp.hpc;Job Run at request of Scheduler@node2.supernodexp.hpc on exec_vnode (node13:ncpus=48:mem=5242880kb)
02/20/2018 07:55:31;0001;Server@node2;Svr;Server@node2;Success (0) in req_runjob2, return value of svr_startjob is 0
02/20/2018 07:55:31;0100;Server@node2;Req;;Type 11 request received from Scheduler@node2.supernodexp.hpc, sock=16
02/20/2018 07:55:31;0008;Server@node2;Job;4507.node2.supernodexp.hpc;Job Modified at request of Scheduler@node2.supernodexp.hpc
02/20/2018 08:05:30;0040;Server@node2;Svr;node2.supernodexp.hpc;Scheduler sent command 3
02/20/2018 08:05:30;0040;Server@node2;Svr;node2.supernodexp.hpc;Scheduler sent command 0
02/20/2018 08:05:30;0100;Server@node2;Req;;Type 21 request received from Scheduler@node2.supernodexp.hpc, sock=16
02/20/2018 08:05:30;0100;Server@node2;Req;;Type 81 request received from Scheduler@node2.supernodexp.hpc, sock=16
02/20/2018 08:05:30;0100;Server@node2;Req;;Type 71 request received from Scheduler@node2.supernodexp.hpc, sock=16
02/20/2018 08:05:30;0100;Server@node2;Req;;Type 58 request received from Scheduler@node2.supernodexp.hpc, sock=16
02/20/2018 08:05:30;0100;Server@node2;Req;;Type 20 request received from Scheduler@node2.supernodexp.hpc, sock=16
02/20/2018 08:05:30;0100;Server@node2;Req;;Type 51 request received from Scheduler@node2.supernodexp.hpc, sock=16
02/20/2018 08:05:50;0080;Server@node2;Job;4489.node2.supernodexp.hpc;Obit received momhop:1 serverhop:1 state:4 substate:42
02/20/2018 08:05:51;0010;Server@node2;Job;4489.node2.supernodexp.hpc;Exit_status=0 resources_used.cpupercent=4735 resources_used.cput=08:15:08 resources_used.mem=7897396kb resources_used.ncpus=48 resources_used.vmem=47423752kb resources_used.walltime=00:10:33
02/20/2018 08:05:51;0100;Server@node2;Job;4489.node2.supernodexp.hpc;dequeuing from workq, state 5
02/20/2018 08:05:51;0040;Server@node2;Svr;node2.supernodexp.hpc;Scheduler sent command 2
02/20/2018 08:05:51;0040;Server@node2;Svr;node2.supernodexp.hpc;Scheduler sent command 0
02/20/2018 08:05:51;0100;Server@node2;Req;;Type 21 request received from Scheduler@node2.supernodexp.hpc, sock=16
02/20/2018 08:05:51;0100;Server@node2;Req;;Type 81 request received from Scheduler@node2.supernodexp.hpc, sock=16
02/20/2018 08:05:51;0100;Server@node2;Req;;Type 71 request received from Scheduler@node2.supernodexp.hpc, sock=16
02/20/2018 08:05:51;0100;Server@node2;Req;;Type 58 request received from Scheduler@node2.supernodexp.hpc, sock=16
02/20/2018 08:05:51;0100;Server@node2;Req;;Type 20 request received from Scheduler@node2.supernodexp.hpc, sock=16
02/20/2018 08:05:51;0100;Server@node2;Req;;Type 51 request received from Scheduler@node2.supernodexp.hpc, sock=16
02/20/2018 08:05:51;0100;Server@node2;Req;;Type 23 request received from Scheduler@node2.supernodexp.hpc, sock=16
02/20/2018 08:05:51;0008;Server@node2;Job;4507.node2.supernodexp.hpc;Job Run at request of Scheduler@node2.supernodexp.hpc on exec_vnode (node14:ncpus=48:mem=5242880kb)
02/20/2018 08:05:51;0001;Server@node2;Svr;Server@node2;Success (0) in req_runjob2, return value of svr_startjob is 0
02/20/2018 08:05:51;0100;Server@node2;Req;;Type 11 request received from Scheduler@node2.supernodexp.hpc, sock=16
02/20/2018 08:05:51;0008;Server@node2;Job;4527.node2.supernodexp.hpc;Job Modified at request of Scheduler@node2.supernodexp.hpc
02/20/2018 08:06:06;0080;Server@node2;Job;4498.node2.supernodexp.hpc;Obit received momhop:1 serverhop:1 state:4 substate:42
02/20/2018 08:06:07;0010;Server@node2;Job;4498.node2.supernodexp.hpc;Exit_status=0 resources_used.cpupercent=4747 resources_used.cput=08:17:06 resources_used.mem=7906832kb resources_used.ncpus=48 resources_used.vmem=47424032kb resources_used.walltime=00:10:36
02/20/2018 08:06:07;0100;Server@node2;Job;4498.node2.supernodexp.hpc;dequeuing from workq, state 5
02/20/2018 08:06:07;0040;Server@node2;Svr;node2.supernodexp.hpc;Scheduler sent command 2
02/20/2018 08:06:07;0040;Server@node2;Svr;node2.supernodexp.hpc;Scheduler sent command 0
02/20/2018 08:06:07;0100;Server@node2;Req;;Type 21 request received from Scheduler@node2.supernodexp.hpc, sock=16
02/20/2018 08:06:07;0100;Server@node2;Req;;Type 81 request received from Scheduler@node2.supernodexp.hpc, sock=16
02/20/2018 08:06:07;0100;Server@node2;Req;;Type 71 request received from Scheduler@node2.supernodexp.hpc, sock=16
02/20/2018 08:06:07;0100;Server@node2;Req;;Type 58 request received from Scheduler@node2.supernodexp.hpc, sock=16
02/20/2018 08:06:08;0100;Server@node2;Req;;Type 20 request received from Scheduler@node2.supernodexp.hpc, sock=16
02/20/2018 08:06:08;0100;Server@node2;Req;;Type 51 request received from Scheduler@node2.supernodexp.hpc, sock=16
02/20/2018 08:06:08;0100;Server@node2;Req;;Type 23 request received from Scheduler@node2.supernodexp.hpc, sock=16
02/20/2018 08:06:08;0008;Server@node2;Job;4527.node2.supernodexp.hpc;Job Run at request of Scheduler@node2.supernodexp.hpc on exec_vnode (node13:ncpus=48:mem=5242880kb)
02/20/2018 08:06:08;0001;Server@node2;Svr;Server@node2;Success (0) in req_runjob2, return value of svr_startjob is 0
02/20/2018 08:06:08;0100;Server@node2;Req;;Type 11 request received from Scheduler@node2.supernodexp.hpc, sock=16
02/20/2018 08:06:08;0008;Server@node2;Job;4547.node2.supernodexp.hpc;Job Modified at request of Scheduler@node2.supernodexp.hpc
02/20/2018 08:16:07;0040;Server@node2;Svr;node2.supernodexp.hpc;Scheduler sent command 3
02/20/2018 08:16:07;0040;Server@node2;Svr;node2.supernodexp.hpc;Scheduler sent command 0
02/20/2018 08:16:07;0100;Server@node2;Req;;Type 21 request received from Scheduler@node2.supernodexp.hpc, sock=16
02/20/2018 08:16:07;0100;Server@node2;Req;;Type 81 request received from Scheduler@node2.supernodexp.hpc, sock=16
02/20/2018 08:16:07;0100;Server@node2;Req;;Type 71 request received from Scheduler@node2.supernodexp.hpc, sock=16
02/20/2018 08:16:07;0100;Server@node2;Req;;Type 58 request received from Scheduler@node2.supernodexp.hpc, sock=16
02/20/2018 08:16:07;0100;Server@node2;Req;;Type 20 request received from Scheduler@node2.supernodexp.hpc, sock=16
02/20/2018 08:16:07;0100;Server@node2;Req;;Type 51 request received from Scheduler@node2.supernodexp.hpc, sock=16
02/20/2018 08:16:31;0080;Server@node2;Job;4507.node2.supernodexp.hpc;Obit received momhop:1 serverhop:1 state:4 substate:42
02/20/2018 08:16:32;0010;Server@node2;Job;4507.node2.supernodexp.hpc;Exit_status=0 resources_used.cpupercent=4733 resources_used.cput=08:16:06 resources_used.mem=7943176kb resources_used.ncpus=48 resources_used.vmem=47424512kb resources_used.walltime=00:10:40
02/20/2018 08:16:32;0100;Server@node2;Job;4507.node2.supernodexp.hpc;dequeuing from workq, state 5
02/20/2018 08:16:32;0040;Server@node2;Svr;node2.supernodexp.hpc;Scheduler sent command 2
02/20/2018 08:16:32;0040;Server@node2;Svr;node2.supernodexp.hpc;Scheduler sent command 0
02/20/2018 08:16:32;0100;Server@node2;Req;;Type 21 request received from Scheduler@node2.supernodexp.hpc, sock=16
02/20/2018 08:16:32;0100;Server@node2;Req;;Type 81 request received from Scheduler@node2.supernodexp.hpc, sock=16
02/20/2018 08:16:32;0100;Server@node2;Req;;Type 71 request received from Scheduler@node2.supernodexp.hpc, sock=16
02/20/2018 08:16:32;0100;Server@node2;Req;;Type 58 request received from Scheduler@node2.supernodexp.hpc, sock=16
02/20/2018 08:16:32;0100;Server@node2;Req;;Type 20 request received from Scheduler@node2.supernodexp.hpc, sock=16
02/20/2018 08:16:32;0100;Server@node2;Req;;Type 51 request received from Scheduler@node2.supernodexp.hpc, sock=16
02/20/2018 08:16:33;0100;Server@node2;Req;;Type 23 request received from Scheduler@node2.supernodexp.hpc, sock=16
02/20/2018 08:16:33;0008;Server@node2;Job;4547.node2.supernodexp.hpc;Job Run at request of Scheduler@node2.supernodexp.hpc on exec_vnode (node14:ncpus=48:mem=5242880kb)
02/20/2018 08:16:33;0001;Server@node2;Svr;Server@node2;Success (0) in req_runjob2, return value of svr_startjob is 0
02/20/2018 08:16:33;0100;Server@node2;Req;;Type 11 request received from Scheduler@node2.supernodexp.hpc, sock=16
02/20/2018 08:16:33;0008;Server@node2;Job;4548.node2.supernodexp.hpc;Job Modified at request of Scheduler@node2.supernodexp.hpc
02/20/2018 08:16:47;0080;Server@node2;Job;4527.node2.supernodexp.hpc;Obit received momhop:1 serverhop:1 state:4 substate:42
02/20/2018 08:16:48;0010;Server@node2;Job;4527.node2.supernodexp.hpc;Exit_status=0 resources_used.cpupercent=4746 resources_used.cput=08:20:17 resources_used.mem=7946096kb resources_used.ncpus=48 resources_used.vmem=47424636kb resources_used.walltime=00:10:39
02/20/2018 08:16:48;0100;Server@node2;Job;4527.node2.supernodexp.hpc;dequeuing from workq, state 5
02/20/2018 08:16:48;0040;Server@node2;Svr;node2.supernodexp.hpc;Scheduler sent command 2
02/20/2018 08:16:48;0040;Server@node2;Svr;node2.supernodexp.hpc;Scheduler sent command 0
02/20/2018 08:16:48;0100;Server@node2;Req;;Type 21 request received from Scheduler@node2.supernodexp.hpc, sock=16
02/20/2018 08:16:48;0100;Server@node2;Req;;Type 81 request received from Scheduler@node2.supernodexp.hpc, sock=16
02/20/2018 08:16:48;0100;Server@node2;Req;;Type 71 request received from Scheduler@node2.supernodexp.hpc, sock=16
02/20/2018 08:16:48;0100;Server@node2;Req;;Type 58 request received from Scheduler@node2.supernodexp.hpc, sock=16
02/20/2018 08:16:48;0100;Server@node2;Req;;Type 20 request received from Scheduler@node2.supernodexp.hpc, sock=16
02/20/2018 08:16:48;0100;Server@node2;Req;;Type 51 request received from Scheduler@node2.supernodexp.hpc, sock=16
02/20/2018 08:16:48;0100;Server@node2;Req;;Type 23 request received from Scheduler@node2.supernodexp.hpc, sock=16
02/20/2018 08:16:48;0008;Server@node2;Job;4548.node2.supernodexp.hpc;Job Run at request of Scheduler@node2.supernodexp.hpc on exec_vnode (node13:ncpus=48:mem=5242880kb)
02/20/2018 08:16:48;0001;Server@node2;Svr;Server@node2;Success (0) in req_runjob2, return value of svr_startjob is 0
02/20/2018 08:16:48;0100;Server@node2;Req;;Type 11 request received from Scheduler@node2.supernodexp.hpc, sock=16
02/20/2018 08:16:48;0008;Server@node2;Job;4550.node2.supernodexp.hpc;Job Modified at request of Scheduler@node2.supernodexp.hpc
02/20/2018 08:26:48;0040;Server@node2;Svr;node2.supernodexp.hpc;Scheduler sent command 3
02/20/2018 08:26:48;0040;Server@node2;Svr;node2.supernodexp.hpc;Scheduler sent command 0
02/20/2018 08:26:48;0100;Server@node2;Req;;Type 21 request received from Scheduler@node2.supernodexp.hpc, sock=16
02/20/2018 08:26:48;0100;Server@node2;Req;;Type 81 request received from Scheduler@node2.supernodexp.hpc, sock=16
02/20/2018 08:26:48;0100;Server@node2;Req;;Type 71 request received from Scheduler@node2.supernodexp.hpc, sock=16
02/20/2018 08:26:48;0100;Server@node2;Req;;Type 58 request received from Scheduler@node2.supernodexp.hpc, sock=16
02/20/2018 08:26:48;0100;Server@node2;Req;;Type 20 request received from Scheduler@node2.supernodexp.hpc, sock=16
02/20/2018 08:26:48;0100;Server@node2;Req;;Type 51 request received from Scheduler@node2.supernodexp.hpc, sock=16
02/20/2018 08:27:08;0080;Server@node2;Job;4547.node2.supernodexp.hpc;Obit received momhop:1 serverhop:1 state:4 substate:42
02/20/2018 08:27:09;0010;Server@node2;Job;4547.node2.supernodexp.hpc;Exit_status=0 resources_used.cpupercent=4747 resources_used.cput=08:15:35 resources_used.mem=7956744kb resources_used.ncpus=48 resources_used.vmem=47423900kb resources_used.walltime=00:10:35
02/20/2018 08:27:09;0100;Server@node2;Job;4547.node2.supernodexp.hpc;dequeuing from workq, state 5
02/20/2018 08:27:09;0040;Server@node2;Svr;node2.supernodexp.hpc;Scheduler sent command 2
02/20/2018 08:27:09;0040;Server@node2;Svr;node2.supernodexp.hpc;Scheduler sent command 0
02/20/2018 08:27:09;0100;Server@node2;Req;;Type 21 request received from Scheduler@node2.supernodexp.hpc, sock=16
02/20/2018 08:27:09;0100;Server@node2;Req;;Type 81 request received from Scheduler@node2.supernodexp.hpc, sock=16
02/20/2018 08:27:09;0100;Server@node2;Req;;Type 71 request received from Scheduler@node2.supernodexp.hpc, sock=16
02/20/2018 08:27:09;0100;Server@node2;Req;;Type 58 request received from Scheduler@node2.supernodexp.hpc, sock=16
02/20/2018 08:27:09;0100;Server@node2;Req;;Type 20 request received from Scheduler@node2.supernodexp.hpc, sock=16
02/20/2018 08:27:09;0100;Server@node2;Req;;Type 51 request received from Scheduler@node2.supernodexp.hpc, sock=16
02/20/2018 08:27:09;0100;Server@node2;Req;;Type 23 request received from Scheduler@node2.supernodexp.hpc, sock=16
02/20/2018 08:27:09;0008;Server@node2;Job;4550.node2.supernodexp.hpc;Job Run at request of Scheduler@node2.supernodexp.hpc on exec_vnode (node14:ncpus=48:mem=5242880kb)
02/20/2018 08:27:09;0001;Server@node2;Svr;Server@node2;Success (0) in req_runjob2, return value of svr_startjob is 0
02/20/2018 08:27:09;0100;Server@node2;Req;;Type 11 request received from Scheduler@node2.supernodexp.hpc, sock=16
02/20/2018 08:27:09;0008;Server@node2;Job;4566.node2.supernodexp.hpc;Job Modified at request of Scheduler@node2.supernodexp.hpc
02/20/2018 08:27:41;0080;Server@node2;Job;4548.node2.supernodexp.hpc;Obit received momhop:1 serverhop:1 state:4 substate:42
02/20/2018 08:27:42;0010;Server@node2;Job;4548.node2.supernodexp.hpc;Exit_status=0 resources_used.cpupercent=4722 resources_used.cput=08:22:54 resources_used.mem=7931172kb resources_used.ncpus=48 resources_used.vmem=47424920kb resources_used.walltime=00:10:53
02/20/2018 08:27:42;0100;Server@node2;Job;4548.node2.supernodexp.hpc;dequeuing from workq, state 5
02/20/2018 08:27:42;0040;Server@node2;Svr;node2.supernodexp.hpc;Scheduler sent command 2
02/20/2018 08:27:42;0040;Server@node2;Svr;node2.supernodexp.hpc;Scheduler sent command 0
02/20/2018 08:27:42;0100;Server@node2;Req;;Type 21 request received from Scheduler@node2.supernodexp.hpc, sock=16
02/20/2018 08:27:42;0100;Server@node2;Req;;Type 81 request received from Scheduler@node2.supernodexp.hpc, sock=16
02/20/2018 08:27:42;0100;Server@node2;Req;;Type 71 request received from Scheduler@node2.supernodexp.hpc, sock=16
02/20/2018 08:27:42;0100;Server@node2;Req;;Type 58 request received from Scheduler@node2.supernodexp.hpc, sock=16
02/20/2018 08:27:42;0100;Server@node2;Req;;Type 20 request received from Scheduler@node2.supernodexp.hpc, sock=16
02/20/2018 08:27:42;0100;Server@node2;Req;;Type 51 request received from Scheduler@node2.supernodexp.hpc, sock=16
02/20/2018 08:27:43;0100;Server@node2;Req;;Type 23 request received from Scheduler@node2.supernodexp.hpc, sock=16
02/20/2018 08:27:43;0008;Server@node2;Job;4566.node2.supernodexp.hpc;Job Run at request of Scheduler@node2.supernodexp.hpc on exec_vnode (node13:ncpus=48:mem=5242880kb)
02/20/2018 08:27:43;0001;Server@node2;Svr;Server@node2;Success (0) in req_runjob2, return value of svr_startjob is 0
02/20/2018 08:27:43;0100;Server@node2;Req;;Type 11 request received from Scheduler@node2.supernodexp.hpc, sock=16
02/20/2018 08:27:43;0008;Server@node2;Job;4620.node2.supernodexp.hpc;Job Modified at request of Scheduler@node2.supernodexp.hpc
02/20/2018 08:37:42;0040;Server@node2;Svr;node2.supernodexp.hpc;Scheduler sent command 3
02/20/2018 08:37:42;0040;Server@node2;Svr;node2.supernodexp.hpc;Scheduler sent command 0
02/20/2018 08:37:42;0100;Server@node2;Req;;Type 21 request received from Scheduler@node2.supernodexp.hpc, sock=16
02/20/2018 08:37:42;0100;Server@node2;Req;;Type 81 request received from Scheduler@node2.supernodexp.hpc, sock=16
02/20/2018 08:37:42;0100;Server@node2;Req;;Type 71 request received from Scheduler@node2.supernodexp.hpc, sock=16
02/20/2018 08:37:42;0100;Server@node2;Req;;Type 58 request received from Scheduler@node2.supernodexp.hpc, sock=16
02/20/2018 08:37:42;0100;Server@node2;Req;;Type 20 request received from Scheduler@node2.supernodexp.hpc, sock=16
02/20/2018 08:37:42;0100;Server@node2;Req;;Type 51 request received from Scheduler@node2.supernodexp.hpc, sock=16
02/20/2018 08:37:44;0080;Server@node2;Job;4550.node2.supernodexp.hpc;Obit received momhop:1 serverhop:1 state:4 substate:42
02/20/2018 08:37:45;0010;Server@node2;Job;4550.node2.supernodexp.hpc;Exit_status=0 resources_used.cpupercent=4732 resources_used.cput=08:16:36 resources_used.mem=7893260kb resources_used.ncpus=48 resources_used.vmem=47423908kb resources_used.walltime=00:10:35
02/20/2018 08:37:45;0100;Server@node2;Job;4550.node2.supernodexp.hpc;dequeuing from workq, state 5
02/20/2018 08:37:45;0040;Server@node2;Svr;node2.supernodexp.hpc;Scheduler sent command 2
02/20/2018 08:37:45;0040;Server@node2;Svr;node2.supernodexp.hpc;Scheduler sent command 0
02/20/2018 08:37:45;0100;Server@node2;Req;;Type 21 request received from Scheduler@node2.supernodexp.hpc, sock=16
02/20/2018 08:37:45;0100;Server@node2;Req;;Type 81 request received from Scheduler@node2.supernodexp.hpc, sock=16
02/20/2018 08:37:45;0100;Server@node2;Req;;Type 71 request received from Scheduler@node2.supernodexp.hpc, sock=16
02/20/2018 08:37:45;0100;Server@node2;Req;;Type 58 request received from Scheduler@node2.supernodexp.hpc, sock=16
02/20/2018 08:37:45;0100;Server@node2;Req;;Type 20 request received from Scheduler@node2.supernodexp.hpc, sock=16
02/20/2018 08:37:45;0100;Server@node2;Req;;Type 51 request received from Scheduler@node2.supernodexp.hpc, sock=16
02/20/2018 08:37:46;0100;Server@node2;Req;;Type 23 request received from Scheduler@node2.supernodexp.hpc, sock=16
02/20/2018 08:37:46;0008;Server@node2;Job;4620.node2.supernodexp.hpc;Job Run at request of Scheduler@node2.supernodexp.hpc on exec_vnode (node14:ncpus=48:mem=5242880kb)
02/20/2018 08:37:46;0001;Server@node2;Svr;Server@node2;Success (0) in req_runjob2, return value of svr_startjob is 0
02/20/2018 08:37:46;0100;Server@node2;Req;;Type 11 request received from Scheduler@node2.supernodexp.hpc, sock=16
02/20/2018 08:37:46;0008;Server@node2;Job;4621.node2.supernodexp.hpc;Job Modified at request of Scheduler@node2.supernodexp.hpc
02/20/2018 08:38:22;0080;Server@node2;Job;4566.node2.supernodexp.hpc;Obit received momhop:1 serverhop:1 state:4 substate:42
02/20/2018 08:38:24;0010;Server@node2;Job;4566.node2.supernodexp.hpc;Exit_status=0 resources_used.cpupercent=4748 resources_used.cput=08:20:55 resources_used.mem=7929848kb resources_used.ncpus=48 resources_used.vmem=47424296kb resources_used.walltime=00:10:39
02/20/2018 08:38:24;0100;Server@node2;Job;4566.node2.supernodexp.hpc;dequeuing from workq, state 5
02/20/2018 08:38:24;0040;Server@node2;Svr;node2.supernodexp.hpc;Scheduler sent command 2
02/20/2018 08:38:24;0040;Server@node2;Svr;node2.supernodexp.hpc;Scheduler sent command 0
02/20/2018 08:38:24;0100;Server@node2;Req;;Type 21 request received from Scheduler@node2.supernodexp.hpc, sock=16
02/20/2018 08:38:24;0100;Server@node2;Req;;Type 81 request received from Scheduler@node2.supernodexp.hpc, sock=16
02/20/2018 08:38:24;0100;Server@node2;Req;;Type 71 request received from Scheduler@node2.supernodexp.hpc, sock=16
02/20/2018 08:38:24;0100;Server@node2;Req;;Type 58 request received from Scheduler@node2.supernodexp.hpc, sock=16
02/20/2018 08:38:24;0100;Server@node2;Req;;Type 20 request received from Scheduler@node2.supernodexp.hpc, sock=16
02/20/2018 08:38:24;0100;Server@node2;Req;;Type 51 request received from Scheduler@node2.supernodexp.hpc, sock=16
02/20/2018 08:38:24;0100;Server@node2;Req;;Type 23 request received from Scheduler@node2.supernodexp.hpc, sock=16
02/20/2018 08:38:24;0008;Server@node2;Job;4621.node2.supernodexp.hpc;Job Run at request of Scheduler@node2.supernodexp.hpc on exec_vnode (node13:ncpus=48:mem=5242880kb)
02/20/2018 08:38:24;0001;Server@node2;Svr;Server@node2;Success (0) in req_runjob2, return value of svr_startjob is 0
02/20/2018 08:38:24;0100;Server@node2;Req;;Type 11 request received from Scheduler@node2.supernodexp.hpc, sock=16
02/20/2018 08:38:24;0008;Server@node2;Job;3669.node2.supernodexp.hpc;Job Modified at request of Scheduler@node2.supernodexp.hpc
02/20/2018 08:48:24;0040;Server@node2;Svr;node2.supernodexp.hpc;Scheduler sent command 3
02/20/2018 08:48:24;0040;Server@node2;Svr;node2.supernodexp.hpc;Scheduler sent command 0
02/20/2018 08:48:24;0100;Server@node2;Req;;Type 21 request received from Scheduler@node2.supernodexp.hpc, sock=16
02/20/2018 08:48:24;0100;Server@node2;Req;;Type 81 request received from Scheduler@node2.supernodexp.hpc, sock=16
02/20/2018 08:48:24;0100;Server@node2;Req;;Type 71 request received from Scheduler@node2.supernodexp.hpc, sock=16
02/20/2018 08:48:24;0100;Server@node2;Req;;Type 58 request received from Scheduler@node2.supernodexp.hpc, sock=16
02/20/2018 08:48:24;0100;Server@node2;Req;;Type 20 request received from Scheduler@node2.supernodexp.hpc, sock=16
02/20/2018 08:48:24;0100;Server@node2;Req;;Type 51 request received from Scheduler@node2.supernodexp.hpc, sock=16
02/20/2018 08:48:29;0080;Server@node2;Job;4620.node2.supernodexp.hpc;Obit received momhop:1 serverhop:1 state:4 substate:42
02/20/2018 08:48:31;0010;Server@node2;Job;4620.node2.supernodexp.hpc;Exit_status=0 resources_used.cpupercent=4742 resources_used.cput=08:18:32 resources_used.mem=7939200kb resources_used.ncpus=48 resources_used.vmem=47424168kb resources_used.walltime=00:10:44
02/20/2018 08:48:31;0100;Server@node2;Job;4620.node2.supernodexp.hpc;dequeuing from workq, state 5
02/20/2018 08:48:31;0040;Server@node2;Svr;node2.supernodexp.hpc;Scheduler sent command 2
02/20/2018 08:48:31;0040;Server@node2;Svr;node2.supernodexp.hpc;Scheduler sent command 0
02/20/2018 08:48:31;0100;Server@node2;Req;;Type 21 request received from Scheduler@node2.supernodexp.hpc, sock=16
02/20/2018 08:48:31;0100;Server@node2;Req;;Type 81 request received from Scheduler@node2.supernodexp.hpc, sock=16
02/20/2018 08:48:31;0100;Server@node2;Req;;Type 71 request received from Scheduler@node2.supernodexp.hpc, sock=16
02/20/2018 08:48:31;0100;Server@node2;Req;;Type 58 request received from Scheduler@node2.supernodexp.hpc, sock=16
02/20/2018 08:48:31;0100;Server@node2;Req;;Type 20 request received from Scheduler@node2.supernodexp.hpc, sock=16
02/20/2018 08:48:31;0100;Server@node2;Req;;Type 51 request received from Scheduler@node2.supernodexp.hpc, sock=16
02/20/2018 08:48:31;0100;Server@node2;Req;;Type 23 request received from Scheduler@node2.supernodexp.hpc, sock=16
02/20/2018 08:48:31;0008;Server@node2;Job;3669.node2.supernodexp.hpc;Job Run at request of Scheduler@node2.supernodexp.hpc on exec_vnode (node14:ncpus=16:mem=8388608kb)
02/20/2018 08:48:31;0001;Server@node2;Svr;Server@node2;Success (0) in req_runjob2, return value of svr_startjob is 0
02/20/2018 08:48:31;0100;Server@node2;Req;;Type 23 request received from Scheduler@node2.supernodexp.hpc, sock=16
02/20/2018 08:48:31;0008;Server@node2;Job;3675.node2.supernodexp.hpc;Job Run at request of Scheduler@node2.supernodexp.hpc on exec_vnode (node14:ncpus=16:mem=8388608kb)
02/20/2018 08:48:31;0001;Server@node2;Svr;Server@node2;Success (0) in req_runjob2, return value of svr_startjob is 0
02/20/2018 08:48:31;0100;Server@node2;Req;;Type 23 request received from Scheduler@node2.supernodexp.hpc, sock=16
02/20/2018 08:48:31;0008;Server@node2;Job;3693.node2.supernodexp.hpc;Job Run at request of Scheduler@node2.supernodexp.hpc on exec_vnode (node14:ncpus=16:mem=8388608kb)
02/20/2018 08:48:31;0001;Server@node2;Svr;Server@node2;Success (0) in req_runjob2, return value of svr_startjob is 0
02/20/2018 08:48:31;0100;Server@node2;Req;;Type 11 request received from Scheduler@node2.supernodexp.hpc, sock=16
02/20/2018 08:48:31;0008;Server@node2;Job;3703.node2.supernodexp.hpc;Job Modified at request of Scheduler@node2.supernodexp.hpc
02/20/2018 08:48:36;0080;Server@node2;Job;3669.node2.supernodexp.hpc;Obit received momhop:1 serverhop:1 state:4 substate:42
02/20/2018 08:48:36;0080;Server@node2;Job;3693.node2.supernodexp.hpc;Obit received momhop:1 serverhop:1 state:4 substate:42
02/20/2018 08:48:38;0010;Server@node2;Job;3669.node2.supernodexp.hpc;Exit_status=1 resources_used.cpupercent=50 resources_used.cput=00:00:02 resources_used.mem=0kb resources_used.ncpus=16 resources_used.vmem=0kb resources_used.walltime=00:00:05
02/20/2018 08:48:38;0100;Server@node2;Job;3669.node2.supernodexp.hpc;dequeuing from workq, state 5
02/20/2018 08:48:38;0010;Server@node2;Job;3693.node2.supernodexp.hpc;Exit_status=1 resources_used.cpupercent=50 resources_used.cput=00:00:02 resources_used.mem=0kb resources_used.ncpus=16 resources_used.vmem=0kb resources_used.walltime=00:00:04
02/20/2018 08:48:38;0100;Server@node2;Job;3693.node2.supernodexp.hpc;dequeuing from workq, state 5
02/20/2018 08:48:38;0040;Server@node2;Svr;node2.supernodexp.hpc;Scheduler sent command 2
02/20/2018 08:48:38;0040;Server@node2;Svr;node2.supernodexp.hpc;Scheduler sent command 0
02/20/2018 08:48:38;0100;Server@node2;Req;;Type 21 request received from Scheduler@node2.supernodexp.hpc, sock=16
02/20/2018 08:48:38;0100;Server@node2;Req;;Type 81 request received from Scheduler@node2.supernodexp.hpc, sock=16
02/20/2018 08:48:38;0100;Server@node2;Req;;Type 71 request received from Scheduler@node2.supernodexp.hpc, sock=16
02/20/2018 08:48:38;0100;Server@node2;Req;;Type 58 request received from Scheduler@node2.supernodexp.hpc, sock=16
02/20/2018 08:48:38;0100;Server@node2;Req;;Type 20 request received from Scheduler@node2.supernodexp.hpc, sock=16
02/20/2018 08:48:38;0100;Server@node2;Req;;Type 51 request received from Scheduler@node2.supernodexp.hpc, sock=16
02/20/2018 08:48:38;0100;Server@node2;Req;;Type 23 request received from Scheduler@node2.supernodexp.hpc, sock=16
02/20/2018 08:48:38;0008;Server@node2;Job;3703.node2.supernodexp.hpc;Job Run at request of Scheduler@node2.supernodexp.hpc on exec_vnode (node14:ncpus=16:mem=8388608kb)
02/20/2018 08:48:38;0001;Server@node2;Svr;Server@node2;Success (0) in req_runjob2, return value of svr_startjob is 0
02/20/2018 08:48:38;0100;Server@node2;Req;;Type 23 request received from Scheduler@node2.supernodexp.hpc, sock=16
02/20/2018 08:48:38;0008;Server@node2;Job;3716.node2.supernodexp.hpc;Job Run at request of Scheduler@node2.supernodexp.hpc on exec_vnode (node14:ncpus=16:mem=8388608kb)
02/20/2018 08:48:38;0001;Server@node2;Svr;Server@node2;Success (0) in req_runjob2, return value of svr_startjob is 0
02/20/2018 08:48:38;0100;Server@node2;Req;;Type 11 request received from Scheduler@node2.supernodexp.hpc, sock=16
02/20/2018 08:48:38;0008;Server@node2;Job;3742.node2.supernodexp.hpc;Job Modified at request of Scheduler@node2.supernodexp.hpc
02/20/2018 08:48:40;0080;Server@node2;Job;3703.node2.supernodexp.hpc;Obit received momhop:1 serverhop:1 state:4 substate:42
02/20/2018 08:48:42;0010;Server@node2;Job;3703.node2.supernodexp.hpc;Exit_status=1 resources_used.cpupercent=100 resources_used.cput=00:00:02 resources_used.mem=4536kb resources_used.ncpus=16 resources_used.vmem=531996kb resources_used.walltime=00:00:02
02/20/2018 08:48:42;0100;Server@node2;Job;3703.node2.supernodexp.hpc;dequeuing from workq, state 5
02/20/2018 08:48:42;0040;Server@node2;Svr;node2.supernodexp.hpc;Scheduler sent command 2
02/20/2018 08:48:42;0040;Server@node2;Svr;node2.supernodexp.hpc;Scheduler sent command 0
02/20/2018 08:48:42;0100;Server@node2;Req;;Type 21 request received from Scheduler@node2.supernodexp.hpc, sock=16
02/20/2018 08:48:42;0100;Server@node2;Req;;Type 81 request received from Scheduler@node2.supernodexp.hpc, sock=16
02/20/2018 08:48:42;0100;Server@node2;Req;;Type 71 request received from Scheduler@node2.supernodexp.hpc, sock=16
02/20/2018 08:48:42;0100;Server@node2;Req;;Type 58 request received from Scheduler@node2.supernodexp.hpc, sock=16
02/20/2018 08:48:42;0100;Server@node2;Req;;Type 20 request received from Scheduler@node2.supernodexp.hpc, sock=16
02/20/2018 08:48:42;0100;Server@node2;Req;;Type 51 request received from Scheduler@node2.supernodexp.hpc, sock=16
02/20/2018 08:48:42;0100;Server@node2;Req;;Type 23 request received from Scheduler@node2.supernodexp.hpc, sock=16
02/20/2018 08:48:42;0008;Server@node2;Job;3742.node2.supernodexp.hpc;Job Run at request of Scheduler@node2.supernodexp.hpc on exec_vnode (node14:ncpus=16:mem=8388608kb)
02/20/2018 08:48:42;0001;Server@node2;Svr;Server@node2;Success (0) in req_runjob2, return value of svr_startjob is 0
02/20/2018 08:48:42;0100;Server@node2;Req;;Type 11 request received from Scheduler@node2.supernodexp.hpc, sock=16
02/20/2018 08:48:42;0008;Server@node2;Job;3743.node2.supernodexp.hpc;Job Modified at request of Scheduler@node2.supernodexp.hpc
02/20/2018 08:49:16;0080;Server@node2;Job;4621.node2.supernodexp.hpc;Obit received momhop:1 serverhop:1 state:4 substate:42
02/20/2018 08:49:17;0010;Server@node2;Job;4621.node2.supernodexp.hpc;Exit_status=0 resources_used.cpupercent=4800 resources_used.cput=08:23:18 resources_used.mem=7920872kb resources_used.ncpus=48 resources_used.vmem=47424360kb resources_used.walltime=00:10:53
02/20/2018 08:49:17;0100;Server@node2;Job;4621.node2.supernodexp.hpc;dequeuing from workq, state 5
02/20/2018 08:49:17;0040;Server@node2;Svr;node2.supernodexp.hpc;Scheduler sent command 2
02/20/2018 08:49:17;0040;Server@node2;Svr;node2.supernodexp.hpc;Scheduler sent command 0
02/20/2018 08:49:17;0100;Server@node2;Req;;Type 21 request received from Scheduler@node2.supernodexp.hpc, sock=16
02/20/2018 08:49:17;0100;Server@node2;Req;;Type 81 request received from Scheduler@node2.supernodexp.hpc, sock=16
02/20/2018 08:49:17;0100;Server@node2;Req;;Type 71 request received from Scheduler@node2.supernodexp.hpc, sock=16
02/20/2018 08:49:17;0100;Server@node2;Req;;Type 58 request received from Scheduler@node2.supernodexp.hpc, sock=16
02/20/2018 08:49:17;0100;Server@node2;Req;;Type 20 request received from Scheduler@node2.supernodexp.hpc, sock=16
02/20/2018 08:49:17;0100;Server@node2;Req;;Type 51 request received from Scheduler@node2.supernodexp.hpc, sock=16
02/20/2018 08:49:18;0100;Server@node2;Req;;Type 23 request received from Scheduler@node2.supernodexp.hpc, sock=16
02/20/2018 08:49:18;0008;Server@node2;Job;3743.node2.supernodexp.hpc;Job Run at request of Scheduler@node2.supernodexp.hpc on exec_vnode (node13:ncpus=16:mem=8388608kb)
02/20/2018 08:49:18;0001;Server@node2;Svr;Server@node2;Success (0) in req_runjob2, return value of svr_startjob is 0
02/20/2018 08:49:18;0100;Server@node2;Req;;Type 23 request received from Scheduler@node2.supernodexp.hpc, sock=16
02/20/2018 08:49:18;0008;Server@node2;Job;3750.node2.supernodexp.hpc;Job Run at request of Scheduler@node2.supernodexp.hpc on exec_vnode (node13:ncpus=16:mem=8388608kb)
02/20/2018 08:49:18;0001;Server@node2;Svr;Server@node2;Success (0) in req_runjob2, return value of svr_startjob is 0
02/20/2018 08:49:18;0100;Server@node2;Req;;Type 23 request received from Scheduler@node2.supernodexp.hpc, sock=16
02/20/2018 08:49:18;0008;Server@node2;Job;3774.node2.supernodexp.hpc;Job Run at request of Scheduler@node2.supernodexp.hpc on exec_vnode (node13:ncpus=16:mem=8388608kb)
02/20/2018 08:49:18;0001;Server@node2;Svr;Server@node2;Success (0) in req_runjob2, return value of svr_startjob is 0
02/20/2018 08:49:18;0100;Server@node2;Req;;Type 11 request received from Scheduler@node2.supernodexp.hpc, sock=16
02/20/2018 08:49:18;0008;Server@node2;Job;3778.node2.supernodexp.hpc;Job Modified at request of Scheduler@node2.supernodexp.hpc
02/20/2018 08:49:20;0080;Server@node2;Job;3743.node2.supernodexp.hpc;Obit received momhop:1 serverhop:1 state:4 substate:42
02/20/2018 08:49:22;0010;Server@node2;Job;3743.node2.supernodexp.hpc;Exit_status=1 resources_used.cpupercent=100 resources_used.cput=00:00:02 resources_used.mem=0kb resources_used.ncpus=16 resources_used.vmem=0kb resources_used.walltime=00:00:02
02/20/2018 08:49:22;0100;Server@node2;Job;3743.node2.supernodexp.hpc;dequeuing from workq, state 5
02/20/2018 08:49:22;0040;Server@node2;Svr;node2.supernodexp.hpc;Scheduler sent command 2
02/20/2018 08:49:22;0040;Server@node2;Svr;node2.supernodexp.hpc;Scheduler sent command 0
02/20/2018 08:49:22;0100;Server@node2;Req;;Type 21 request received from Scheduler@node2.supernodexp.hpc, sock=16
02/20/2018 08:49:22;0100;Server@node2;Req;;Type 81 request received from Scheduler@node2.supernodexp.hpc, sock=16
02/20/2018 08:49:22;0100;Server@node2;Req;;Type 71 request received from Scheduler@node2.supernodexp.hpc, sock=16
02/20/2018 08:49:22;0100;Server@node2;Req;;Type 58 request received from Scheduler@node2.supernodexp.hpc, sock=16
02/20/2018 08:49:22;0100;Server@node2;Req;;Type 20 request received from Scheduler@node2.supernodexp.hpc, sock=16
02/20/2018 08:49:22;0100;Server@node2;Req;;Type 51 request received from Scheduler@node2.supernodexp.hpc, sock=16
02/20/2018 08:49:22;0100;Server@node2;Req;;Type 23 request received from Scheduler@node2.supernodexp.hpc, sock=16
02/20/2018 08:49:22;0008;Server@node2;Job;3778.node2.supernodexp.hpc;Job Run at request of Scheduler@node2.supernodexp.hpc on exec_vnode (node13:ncpus=16:mem=8388608kb)
02/20/2018 08:49:22;0001;Server@node2;Svr;Server@node2;Success (0) in req_runjob2, return value of svr_startjob is 0
02/20/2018 08:49:22;0100;Server@node2;Req;;Type 11 request received from Scheduler@node2.supernodexp.hpc, sock=16
02/20/2018 08:49:22;0008;Server@node2;Job;3812.node2.supernodexp.hpc;Job Modified at request of Scheduler@node2.supernodexp.hpc
02/20/2018 08:49:27;0080;Server@node2;Job;3774.node2.supernodexp.hpc;Obit received momhop:1 serverhop:1 state:4 substate:42
02/20/2018 08:49:29;0010;Server@node2;Job;3774.node2.supernodexp.hpc;Exit_status=1 resources_used.cpupercent=100 resources_used.cput=00:00:03 resources_used.mem=76676kb resources_used.ncpus=16 resources_used.vmem=1067292kb resources_used.walltime=00:00:09
02/20/2018 08:49:29;0100;Server@node2;Job;3774.node2.supernodexp.hpc;dequeuing from workq, state 5
02/20/2018 08:49:29;0040;Server@node2;Svr;node2.supernodexp.hpc;Scheduler sent command 2
02/20/2018 08:49:29;0040;Server@node2;Svr;node2.supernodexp.hpc;Scheduler sent command 0
02/20/2018 08:49:29;0100;Server@node2;Req;;Type 21 request received from Scheduler@node2.supernodexp.hpc, sock=16
02/20/2018 08:49:29;0100;Server@node2;Req;;Type 81 request received from Scheduler@node2.supernodexp.hpc, sock=16
02/20/2018 08:49:29;0100;Server@node2;Req;;Type 71 request received from Scheduler@node2.supernodexp.hpc, sock=16
02/20/2018 08:49:29;0100;Server@node2;Req;;Type 58 request received from Scheduler@node2.supernodexp.hpc, sock=16
02/20/2018 08:49:29;0100;Server@node2;Req;;Type 20 request received from Scheduler@node2.supernodexp.hpc, sock=16
02/20/2018 08:49:29;0100;Server@node2;Req;;Type 51 request received from Scheduler@node2.supernodexp.hpc, sock=16
02/20/2018 08:49:29;0100;Server@node2;Req;;Type 23 request received from Scheduler@node2.supernodexp.hpc, sock=16
02/20/2018 08:49:29;0008;Server@node2;Job;3812.node2.supernodexp.hpc;Job Run at request of Scheduler@node2.supernodexp.hpc on exec_vnode (node13:ncpus=16:mem=8388608kb)
02/20/2018 08:49:29;0001;Server@node2;Svr;Server@node2;Success (0) in req_runjob2, return value of svr_startjob is 0
02/20/2018 08:49:29;0100;Server@node2;Req;;Type 11 request received from Scheduler@node2.supernodexp.hpc, sock=16
02/20/2018 08:49:29;0008;Server@node2;Job;3844.node2.supernodexp.hpc;Job Modified at request of Scheduler@node2.supernodexp.hpc
02/20/2018 08:52:07;0080;Server@node2;Job;3675.node2.supernodexp.hpc;Obit received momhop:1 serverhop:1 state:4 substate:42
02/20/2018 08:52:09;0010;Server@node2;Job;3675.node2.supernodexp.hpc;Exit_status=0 resources_used.cpupercent=833 resources_used.cput=00:54:05 resources_used.mem=1116528kb resources_used.ncpus=16 resources_used.vmem=9813020kb resources_used.walltime=00:03:35
02/20/2018 08:52:09;0100;Server@node2;Job;3675.node2.supernodexp.hpc;dequeuing from workq, state 5
02/20/2018 08:52:09;0040;Server@node2;Svr;node2.supernodexp.hpc;Scheduler sent command 2
02/20/2018 08:52:09;0040;Server@node2;Svr;node2.supernodexp.hpc;Scheduler sent command 0
02/20/2018 08:52:09;0100;Server@node2;Req;;Type 21 request received from Scheduler@node2.supernodexp.hpc, sock=16
02/20/2018 08:52:09;0100;Server@node2;Req;;Type 81 request received from Scheduler@node2.supernodexp.hpc, sock=16
02/20/2018 08:52:09;0100;Server@node2;Req;;Type 71 request received from Scheduler@node2.supernodexp.hpc, sock=16
02/20/2018 08:52:09;0100;Server@node2;Req;;Type 58 request received from Scheduler@node2.supernodexp.hpc, sock=16
02/20/2018 08:52:09;0100;Server@node2;Req;;Type 20 request received from Scheduler@node2.supernodexp.hpc, sock=16
02/20/2018 08:52:09;0100;Server@node2;Req;;Type 51 request received from Scheduler@node2.supernodexp.hpc, sock=16
02/20/2018 08:52:10;0100;Server@node2;Req;;Type 23 request received from Scheduler@node2.supernodexp.hpc, sock=16
02/20/2018 08:52:10;0008;Server@node2;Job;3844.node2.supernodexp.hpc;Job Run at request of Scheduler@node2.supernodexp.hpc on exec_vnode (node14:ncpus=16:mem=8388608kb)
02/20/2018 08:52:10;0001;Server@node2;Svr;Server@node2;Success (0) in req_runjob2, return value of svr_startjob is 0
02/20/2018 08:52:10;0100;Server@node2;Req;;Type 11 request received from Scheduler@node2.supernodexp.hpc, sock=16
02/20/2018 08:52:10;0008;Server@node2;Job;3890.node2.supernodexp.hpc;Job Modified at request of Scheduler@node2.supernodexp.hpc
02/20/2018 08:52:18;0080;Server@node2;Job;3716.node2.supernodexp.hpc;Obit received momhop:1 serverhop:1 state:4 substate:42
02/20/2018 08:52:20;0010;Server@node2;Job;3716.node2.supernodexp.hpc;Exit_status=0 resources_used.cpupercent=874 resources_used.cput=00:55:50 resources_used.mem=1115048kb resources_used.ncpus=16 resources_used.vmem=9812052kb resources_used.walltime=00:03:40
02/20/2018 08:52:20;0100;Server@node2;Job;3716.node2.supernodexp.hpc;dequeuing from workq, state 5
02/20/2018 08:52:20;0040;Server@node2;Svr;node2.supernodexp.hpc;Scheduler sent command 2
02/20/2018 08:52:20;0040;Server@node2;Svr;node2.supernodexp.hpc;Scheduler sent command 0
02/20/2018 08:52:20;0100;Server@node2;Req;;Type 21 request received from Scheduler@node2.supernodexp.hpc, sock=16
02/20/2018 08:52:20;0100;Server@node2;Req;;Type 81 request received from Scheduler@node2.supernodexp.hpc, sock=16
02/20/2018 08:52:20;0100;Server@node2;Req;;Type 71 request received from Scheduler@node2.supernodexp.hpc, sock=16
02/20/2018 08:52:20;0100;Server@node2;Req;;Type 58 request received from Scheduler@node2.supernodexp.hpc, sock=16
02/20/2018 08:52:20;0100;Server@node2;Req;;Type 20 request received from Scheduler@node2.supernodexp.hpc, sock=16
02/20/2018 08:52:20;0100;Server@node2;Req;;Type 51 request received from Scheduler@node2.supernodexp.hpc, sock=16
02/20/2018 08:52:20;0080;Server@node2;Job;3742.node2.supernodexp.hpc;Obit received momhop:1 serverhop:1 state:4 substate:42
02/20/2018 08:52:20;0100;Server@node2;Req;;Type 23 request received from Scheduler@node2.supernodexp.hpc, sock=16
02/20/2018 08:52:20;0008;Server@node2;Job;3890.node2.supernodexp.hpc;Job Run at request of Scheduler@node2.supernodexp.hpc on exec_vnode (node14:ncpus=16:mem=8388608kb)
02/20/2018 08:52:20;0001;Server@node2;Svr;Server@node2;Success (0) in req_runjob2, return value of svr_startjob is 0
02/20/2018 08:52:20;0100;Server@node2;Req;;Type 11 request received from Scheduler@node2.supernodexp.hpc, sock=16
02/20/2018 08:52:20;0008;Server@node2;Job;3901.node2.supernodexp.hpc;Job Modified at request of Scheduler@node2.supernodexp.hpc
02/20/2018 08:52:21;0010;Server@node2;Job;3742.node2.supernodexp.hpc;Exit_status=0 resources_used.cpupercent=847 resources_used.cput=00:54:54 resources_used.mem=1115080kb resources_used.ncpus=16 resources_used.vmem=9812008kb resources_used.walltime=00:03:38
02/20/2018 08:52:21;0100;Server@node2;Job;3742.node2.supernodexp.hpc;dequeuing from workq, state 5
02/20/2018 08:52:21;0040;Server@node2;Svr;node2.supernodexp.hpc;Scheduler sent command 2
02/20/2018 08:52:21;0040;Server@node2;Svr;node2.supernodexp.hpc;Scheduler sent command 0
02/20/2018 08:52:21;0100;Server@node2;Req;;Type 21 request received from Scheduler@node2.supernodexp.hpc, sock=16
02/20/2018 08:52:21;0100;Server@node2;Req;;Type 81 request received from Scheduler@node2.supernodexp.hpc, sock=16
02/20/2018 08:52:21;0100;Server@node2;Req;;Type 71 request received from Scheduler@node2.supernodexp.hpc, sock=16
02/20/2018 08:52:21;0100;Server@node2;Req;;Type 58 request received from Scheduler@node2.supernodexp.hpc, sock=16
02/20/2018 08:52:21;0100;Server@node2;Req;;Type 20 request received from Scheduler@node2.supernodexp.hpc, sock=16
02/20/2018 08:52:21;0100;Server@node2;Req;;Type 51 request received from Scheduler@node2.supernodexp.hpc, sock=16
02/20/2018 08:52:21;0100;Server@node2;Req;;Type 23 request received from Scheduler@node2.supernodexp.hpc, sock=16
02/20/2018 08:52:21;0008;Server@node2;Job;3901.node2.supernodexp.hpc;Job Run at request of Scheduler@node2.supernodexp.hpc on exec_vnode (node14:ncpus=16:mem=8388608kb)
02/20/2018 08:52:21;0001;Server@node2;Svr;Server@node2;Success (0) in req_runjob2, return value of svr_startjob is 0
02/20/2018 08:52:21;0100;Server@node2;Req;;Type 11 request received from Scheduler@node2.supernodexp.hpc, sock=16
02/20/2018 08:52:21;0008;Server@node2;Job;3902.node2.supernodexp.hpc;Job Modified at request of Scheduler@node2.supernodexp.hpc
02/20/2018 08:52:58;0080;Server@node2;Job;3778.node2.supernodexp.hpc;Obit received momhop:1 serverhop:1 state:4 substate:42
02/20/2018 08:52:59;0010;Server@node2;Job;3778.node2.supernodexp.hpc;Exit_status=0 resources_used.cpupercent=838 resources_used.cput=00:54:58 resources_used.mem=1116692kb resources_used.ncpus=16 resources_used.vmem=9777620kb resources_used.walltime=00:03:35
02/20/2018 08:52:59;0100;Server@node2;Job;3778.node2.supernodexp.hpc;dequeuing from workq, state 5
02/20/2018 08:52:59;0040;Server@node2;Svr;node2.supernodexp.hpc;Scheduler sent command 2
02/20/2018 08:52:59;0040;Server@node2;Svr;node2.supernodexp.hpc;Scheduler sent command 0
02/20/2018 08:52:59;0100;Server@node2;Req;;Type 21 request received from Scheduler@node2.supernodexp.hpc, sock=16
02/20/2018 08:52:59;0100;Server@node2;Req;;Type 81 request received from Scheduler@node2.supernodexp.hpc, sock=16
02/20/2018 08:52:59;0100;Server@node2;Req;;Type 71 request received from Scheduler@node2.supernodexp.hpc, sock=16
02/20/2018 08:52:59;0100;Server@node2;Req;;Type 58 request received from Scheduler@node2.supernodexp.hpc, sock=16
02/20/2018 08:52:59;0100;Server@node2;Req;;Type 20 request received from Scheduler@node2.supernodexp.hpc, sock=16
02/20/2018 08:52:59;0100;Server@node2;Req;;Type 51 request received from Scheduler@node2.supernodexp.hpc, sock=16
02/20/2018 08:52:59;0100;Server@node2;Req;;Type 23 request received from Scheduler@node2.supernodexp.hpc, sock=16
02/20/2018 08:52:59;0008;Server@node2;Job;3902.node2.supernodexp.hpc;Job Run at request of Scheduler@node2.supernodexp.hpc on exec_vnode (node13:ncpus=16:mem=8388608kb)
02/20/2018 08:52:59;0001;Server@node2;Svr;Server@node2;Success (0) in req_runjob2, return value of svr_startjob is 0
02/20/2018 08:52:59;0100;Server@node2;Req;;Type 11 request received from Scheduler@node2.supernodexp.hpc, sock=16
02/20/2018 08:52:59;0008;Server@node2;Job;3911.node2.supernodexp.hpc;Job Modified at request of Scheduler@node2.supernodexp.hpc
02/20/2018 08:53:05;0080;Server@node2;Job;3750.node2.supernodexp.hpc;Obit received momhop:1 serverhop:1 state:4 substate:42
02/20/2018 08:53:06;0010;Server@node2;Job;3750.node2.supernodexp.hpc;Exit_status=0 resources_used.cpupercent=880 resources_used.cput=00:56:37 resources_used.mem=1115120kb resources_used.ncpus=16 resources_used.vmem=9776680kb resources_used.walltime=00:03:47
02/20/2018 08:53:06;0100;Server@node2;Job;3750.node2.supernodexp.hpc;dequeuing from workq, state 5
02/20/2018 08:53:06;0040;Server@node2;Svr;node2.supernodexp.hpc;Scheduler sent command 2
02/20/2018 08:53:06;0040;Server@node2;Svr;node2.supernodexp.hpc;Scheduler sent command 0
02/20/2018 08:53:06;0100;Server@node2;Req;;Type 21 request received from Scheduler@node2.supernodexp.hpc, sock=16
02/20/2018 08:53:06;0100;Server@node2;Req;;Type 81 request received from Scheduler@node2.supernodexp.hpc, sock=16
02/20/2018 08:53:06;0100;Server@node2;Req;;Type 71 request received from Scheduler@node2.supernodexp.hpc, sock=16
02/20/2018 08:53:06;0100;Server@node2;Req;;Type 58 request received from Scheduler@node2.supernodexp.hpc, sock=16
02/20/2018 08:53:06;0100;Server@node2;Req;;Type 20 request received from Scheduler@node2.supernodexp.hpc, sock=16
02/20/2018 08:53:06;0100;Server@node2;Req;;Type 51 request received from Scheduler@node2.supernodexp.hpc, sock=16
02/20/2018 08:53:07;0100;Server@node2;Req;;Type 23 request received from Scheduler@node2.supernodexp.hpc, sock=16
02/20/2018 08:53:07;0008;Server@node2;Job;3911.node2.supernodexp.hpc;Job Run at request of Scheduler@node2.supernodexp.hpc on exec_vnode (node13:ncpus=16:mem=8388608kb)
02/20/2018 08:53:07;0001;Server@node2;Svr;Server@node2;Success (0) in req_runjob2, return value of svr_startjob is 0
02/20/2018 08:53:07;0100;Server@node2;Req;;Type 11 request received from Scheduler@node2.supernodexp.hpc, sock=16
02/20/2018 08:53:07;0008;Server@node2;Job;3918.node2.supernodexp.hpc;Job Modified at request of Scheduler@node2.supernodexp.hpc
02/20/2018 08:53:08;0080;Server@node2;Job;3812.node2.supernodexp.hpc;Obit received momhop:1 serverhop:1 state:4 substate:42
02/20/2018 08:53:09;0010;Server@node2;Job;3812.node2.supernodexp.hpc;Exit_status=0 resources_used.cpupercent=851 resources_used.cput=00:54:53 resources_used.mem=1116888kb resources_used.ncpus=16 resources_used.vmem=9776740kb resources_used.walltime=00:03:39
02/20/2018 08:53:09;0100;Server@node2;Job;3812.node2.supernodexp.hpc;dequeuing from workq, state 5
02/20/2018 08:53:09;0040;Server@node2;Svr;node2.supernodexp.hpc;Scheduler sent command 2
02/20/2018 08:53:09;0040;Server@node2;Svr;node2.supernodexp.hpc;Scheduler sent command 0
02/20/2018 08:53:09;0100;Server@node2;Req;;Type 21 request received from Scheduler@node2.supernodexp.hpc, sock=16
02/20/2018 08:53:09;0100;Server@node2;Req;;Type 81 request received from Scheduler@node2.supernodexp.hpc, sock=16
02/20/2018 08:53:09;0100;Server@node2;Req;;Type 71 request received from Scheduler@node2.supernodexp.hpc, sock=16
02/20/2018 08:53:09;0100;Server@node2;Req;;Type 58 request received from Scheduler@node2.supernodexp.hpc, sock=16
02/20/2018 08:53:09;0100;Server@node2;Req;;Type 20 request received from Scheduler@node2.supernodexp.hpc, sock=16
02/20/2018 08:53:09;0100;Server@node2;Req;;Type 51 request received from Scheduler@node2.supernodexp.hpc, sock=16
02/20/2018 08:53:09;0100;Server@node2;Req;;Type 23 request received from Scheduler@node2.supernodexp.hpc, sock=16
02/20/2018 08:53:09;0008;Server@node2;Job;3918.node2.supernodexp.hpc;Job Run at request of Scheduler@node2.supernodexp.hpc on exec_vnode (node13:ncpus=16:mem=8388608kb)
02/20/2018 08:53:09;0001;Server@node2;Svr;Server@node2;Success (0) in req_runjob2, return value of svr_startjob is 0
02/20/2018 08:53:09;0100;Server@node2;Req;;Type 11 request received from Scheduler@node2.supernodexp.hpc, sock=16
02/20/2018 08:53:09;0008;Server@node2;Job;3922.node2.supernodexp.hpc;Job Modified at request of Scheduler@node2.supernodexp.hpc
02/20/2018 08:55:45;0080;Server@node2;Job;3844.node2.supernodexp.hpc;Obit received momhop:1 serverhop:1 state:4 substate:42
02/20/2018 08:55:47;0010;Server@node2;Job;3844.node2.supernodexp.hpc;Exit_status=0 resources_used.cpupercent=818 resources_used.cput=00:53:42 resources_used.mem=1115260kb resources_used.ncpus=16 resources_used.vmem=9812132kb resources_used.walltime=00:03:36
02/20/2018 08:55:47;0100;Server@node2;Job;3844.node2.supernodexp.hpc;dequeuing from workq, state 5
02/20/2018 08:55:47;0040;Server@node2;Svr;node2.supernodexp.hpc;Scheduler sent command 2
02/20/2018 08:55:47;0040;Server@node2;Svr;node2.supernodexp.hpc;Scheduler sent command 0
02/20/2018 08:55:47;0100;Server@node2;Req;;Type 21 request received from Scheduler@node2.supernodexp.hpc, sock=16
02/20/2018 08:55:47;0100;Server@node2;Req;;Type 81 request received from Scheduler@node2.supernodexp.hpc, sock=16
02/20/2018 08:55:47;0100;Server@node2;Req;;Type 71 request received from Scheduler@node2.supernodexp.hpc, sock=16
02/20/2018 08:55:47;0100;Server@node2;Req;;Type 58 request received from Scheduler@node2.supernodexp.hpc, sock=16
02/20/2018 08:55:47;0100;Server@node2;Req;;Type 20 request received from Scheduler@node2.supernodexp.hpc, sock=16
02/20/2018 08:55:47;0100;Server@node2;Req;;Type 51 request received from Scheduler@node2.supernodexp.hpc, sock=16
02/20/2018 08:55:47;0100;Server@node2;Req;;Type 23 request received from Scheduler@node2.supernodexp.hpc, sock=16
02/20/2018 08:55:47;0008;Server@node2;Job;3922.node2.supernodexp.hpc;Job Run at request of Scheduler@node2.supernodexp.hpc on exec_vnode (node14:ncpus=16:mem=8388608kb)
02/20/2018 08:55:47;0001;Server@node2;Svr;Server@node2;Success (0) in req_runjob2, return value of svr_startjob is 0
02/20/2018 08:55:47;0100;Server@node2;Req;;Type 11 request received from Scheduler@node2.supernodexp.hpc, sock=16
02/20/2018 08:55:47;0008;Server@node2;Job;3927.node2.supernodexp.hpc;Job Modified at request of Scheduler@node2.supernodexp.hpc
02/20/2018 08:55:59;0080;Server@node2;Job;3901.node2.supernodexp.hpc;Obit received momhop:1 serverhop:1 state:4 substate:42
02/20/2018 08:55:59;0080;Server@node2;Job;3890.node2.supernodexp.hpc;Obit received momhop:1 serverhop:1 state:4 substate:42
02/20/2018 08:56:00;0010;Server@node2;Job;3901.node2.supernodexp.hpc;Exit_status=0 resources_used.cpupercent=1072 resources_used.cput=00:55:48 resources_used.mem=1115092kb resources_used.ncpus=16 resources_used.vmem=9812196kb resources_used.walltime=00:03:37
02/20/2018 08:56:00;0100;Server@node2;Job;3901.node2.supernodexp.hpc;dequeuing from workq, state 5
02/20/2018 08:56:00;0010;Server@node2;Job;3890.node2.supernodexp.hpc;Exit_status=0 resources_used.cpupercent=876 resources_used.cput=00:56:11 resources_used.mem=1114996kb resources_used.ncpus=16 resources_used.vmem=9812036kb resources_used.walltime=00:03:39
02/20/2018 08:56:00;0100;Server@node2;Job;3890.node2.supernodexp.hpc;dequeuing from workq, state 5
02/20/2018 08:56:00;0040;Server@node2;Svr;node2.supernodexp.hpc;Scheduler sent command 2
02/20/2018 08:56:00;0040;Server@node2;Svr;node2.supernodexp.hpc;Scheduler sent command 0
02/20/2018 08:56:00;0100;Server@node2;Req;;Type 21 request received from Scheduler@node2.supernodexp.hpc, sock=16
02/20/2018 08:56:00;0100;Server@node2;Req;;Type 81 request received from Scheduler@node2.supernodexp.hpc, sock=16
02/20/2018 08:56:00;0100;Server@node2;Req;;Type 71 request received from Scheduler@node2.supernodexp.hpc, sock=16
02/20/2018 08:56:00;0100;Server@node2;Req;;Type 58 request received from Scheduler@node2.supernodexp.hpc, sock=16
02/20/2018 08:56:00;0100;Server@node2;Req;;Type 20 request received from Scheduler@node2.supernodexp.hpc, sock=16
02/20/2018 08:56:00;0100;Server@node2;Req;;Type 51 request received from Scheduler@node2.supernodexp.hpc, sock=16
02/20/2018 08:56:00;0100;Server@node2;Req;;Type 23 request received from Scheduler@node2.supernodexp.hpc, sock=16
02/20/2018 08:56:00;0008;Server@node2;Job;3927.node2.supernodexp.hpc;Job Run at request of Scheduler@node2.supernodexp.hpc on exec_vnode (node14:ncpus=16:mem=8388608kb)
02/20/2018 08:56:00;0001;Server@node2;Svr;Server@node2;Success (0) in req_runjob2, return value of svr_startjob is 0
02/20/2018 08:56:00;0100;Server@node2;Req;;Type 23 request received from Scheduler@node2.supernodexp.hpc, sock=16
02/20/2018 08:56:00;0008;Server@node2;Job;3939.node2.supernodexp.hpc;Job Run at request of Scheduler@node2.supernodexp.hpc on exec_vnode (node14:ncpus=16:mem=8388608kb)
02/20/2018 08:56:00;0001;Server@node2;Svr;Server@node2;Success (0) in req_runjob2, return value of svr_startjob is 0
02/20/2018 08:56:00;0100;Server@node2;Req;;Type 11 request received from Scheduler@node2.supernodexp.hpc, sock=16
02/20/2018 08:56:00;0008;Server@node2;Job;3985.node2.supernodexp.hpc;Job Modified at request of Scheduler@node2.supernodexp.hpc
02/20/2018 08:56:07;0080;Server@node2;Job;3939.node2.supernodexp.hpc;Obit received momhop:1 serverhop:1 state:4 substate:42
02/20/2018 08:56:08;0010;Server@node2;Job;3939.node2.supernodexp.hpc;Exit_status=1 resources_used.cpupercent=49 resources_used.cput=00:00:03 resources_used.mem=0kb resources_used.ncpus=16 resources_used.vmem=0kb resources_used.walltime=00:00:07
02/20/2018 08:56:08;0100;Server@node2;Job;3939.node2.supernodexp.hpc;dequeuing from workq, state 5
02/20/2018 08:56:08;0040;Server@node2;Svr;node2.supernodexp.hpc;Scheduler sent command 2
02/20/2018 08:56:08;0040;Server@node2;Svr;node2.supernodexp.hpc;Scheduler sent command 0
02/20/2018 08:56:08;0100;Server@node2;Req;;Type 21 request received from Scheduler@node2.supernodexp.hpc, sock=16
02/20/2018 08:56:08;0100;Server@node2;Req;;Type 81 request received from Scheduler@node2.supernodexp.hpc, sock=16
02/20/2018 08:56:08;0100;Server@node2;Req;;Type 71 request received from Scheduler@node2.supernodexp.hpc, sock=16
02/20/2018 08:56:08;0100;Server@node2;Req;;Type 58 request received from Scheduler@node2.supernodexp.hpc, sock=16
02/20/2018 08:56:08;0100;Server@node2;Req;;Type 20 request received from Scheduler@node2.supernodexp.hpc, sock=16
02/20/2018 08:56:08;0100;Server@node2;Req;;Type 51 request received from Scheduler@node2.supernodexp.hpc, sock=16
02/20/2018 08:56:09;0100;Server@node2;Req;;Type 23 request received from Scheduler@node2.supernodexp.hpc, sock=16
02/20/2018 08:56:09;0008;Server@node2;Job;3985.node2.supernodexp.hpc;Job Run at request of Scheduler@node2.supernodexp.hpc on exec_vnode (node14:ncpus=16:mem=8388608kb)
02/20/2018 08:56:09;0001;Server@node2;Svr;Server@node2;Success (0) in req_runjob2, return value of svr_startjob is 0
02/20/2018 08:56:09;0100;Server@node2;Req;;Type 11 request received from Scheduler@node2.supernodexp.hpc, sock=16
02/20/2018 08:56:09;0008;Server@node2;Job;3989.node2.supernodexp.hpc;Job Modified at request of Scheduler@node2.supernodexp.hpc
02/20/2018 08:56:41;0080;Server@node2;Job;3902.node2.supernodexp.hpc;Obit received momhop:1 serverhop:1 state:4 substate:42
02/20/2018 08:56:43;0010;Server@node2;Job;3902.node2.supernodexp.hpc;Exit_status=0 resources_used.cpupercent=837 resources_used.cput=00:55:31 resources_used.mem=1115104kb resources_used.ncpus=16 resources_used.vmem=9776744kb resources_used.walltime=00:03:42
02/20/2018 08:56:43;0100;Server@node2;Job;3902.node2.supernodexp.hpc;dequeuing from workq, state 5
02/20/2018 08:56:43;0040;Server@node2;Svr;node2.supernodexp.hpc;Scheduler sent command 2
02/20/2018 08:56:43;0040;Server@node2;Svr;node2.supernodexp.hpc;Scheduler sent command 0
02/20/2018 08:56:43;0100;Server@node2;Req;;Type 21 request received from Scheduler@node2.supernodexp.hpc, sock=16
02/20/2018 08:56:43;0100;Server@node2;Req;;Type 81 request received from Scheduler@node2.supernodexp.hpc, sock=16
02/20/2018 08:56:43;0100;Server@node2;Req;;Type 71 request received from Scheduler@node2.supernodexp.hpc, sock=16
02/20/2018 08:56:43;0100;Server@node2;Req;;Type 58 request received from Scheduler@node2.supernodexp.hpc, sock=16
02/20/2018 08:56:43;0100;Server@node2;Req;;Type 20 request received from Scheduler@node2.supernodexp.hpc, sock=16
02/20/2018 08:56:43;0100;Server@node2;Req;;Type 51 request received from Scheduler@node2.supernodexp.hpc, sock=16
02/20/2018 08:56:43;0100;Server@node2;Req;;Type 23 request received from Scheduler@node2.supernodexp.hpc, sock=16
02/20/2018 08:56:43;0008;Server@node2;Job;3989.node2.supernodexp.hpc;Job Run at request of Scheduler@node2.supernodexp.hpc on exec_vnode (node13:ncpus=16:mem=8388608kb)
02/20/2018 08:56:43;0001;Server@node2;Svr;Server@node2;Success (0) in req_runjob2, return value of svr_startjob is 0
02/20/2018 08:56:43;0100;Server@node2;Req;;Type 11 request received from Scheduler@node2.supernodexp.hpc, sock=16
02/20/2018 08:56:43;0008;Server@node2;Job;3997.node2.supernodexp.hpc;Job Modified at request of Scheduler@node2.supernodexp.hpc
02/20/2018 08:56:46;0080;Server@node2;Job;3911.node2.supernodexp.hpc;Obit received momhop:1 serverhop:1 state:4 substate:42
02/20/2018 08:56:48;0010;Server@node2;Job;3911.node2.supernodexp.hpc;Exit_status=0 resources_used.cpupercent=877 resources_used.cput=00:56:18 resources_used.mem=1114960kb resources_used.ncpus=16 resources_used.vmem=9776460kb resources_used.walltime=00:03:40
02/20/2018 08:56:48;0100;Server@node2;Job;3911.node2.supernodexp.hpc;dequeuing from workq, state 5
02/20/2018 08:56:48;0040;Server@node2;Svr;node2.supernodexp.hpc;Scheduler sent command 2
02/20/2018 08:56:48;0040;Server@node2;Svr;node2.supernodexp.hpc;Scheduler sent command 0
02/20/2018 08:56:48;0100;Server@node2;Req;;Type 21 request received from Scheduler@node2.supernodexp.hpc, sock=16
02/20/2018 08:56:48;0100;Server@node2;Req;;Type 81 request received from Scheduler@node2.supernodexp.hpc, sock=16
02/20/2018 08:56:48;0100;Server@node2;Req;;Type 71 request received from Scheduler@node2.supernodexp.hpc, sock=16
02/20/2018 08:56:48;0100;Server@node2;Req;;Type 58 request received from Scheduler@node2.supernodexp.hpc, sock=16
02/20/2018 08:56:48;0100;Server@node2;Req;;Type 20 request received from Scheduler@node2.supernodexp.hpc, sock=16
02/20/2018 08:56:48;0100;Server@node2;Req;;Type 51 request received from Scheduler@node2.supernodexp.hpc, sock=16
02/20/2018 08:56:48;0100;Server@node2;Req;;Type 23 request received from Scheduler@node2.supernodexp.hpc, sock=16
02/20/2018 08:56:48;0008;Server@node2;Job;3997.node2.supernodexp.hpc;Job Run at request of Scheduler@node2.supernodexp.hpc on exec_vnode (node13:ncpus=16:mem=8388608kb)
02/20/2018 08:56:48;0001;Server@node2;Svr;Server@node2;Success (0) in req_runjob2, return value of svr_startjob is 0
02/20/2018 08:56:48;0100;Server@node2;Req;;Type 11 request received from Scheduler@node2.supernodexp.hpc, sock=16
02/20/2018 08:56:48;0008;Server@node2;Job;3999.node2.supernodexp.hpc;Job Modified at request of Scheduler@node2.supernodexp.hpc
02/20/2018 08:56:49;0080;Server@node2;Job;3918.node2.supernodexp.hpc;Obit received momhop:1 serverhop:1 state:4 substate:42
02/20/2018 08:56:50;0010;Server@node2;Job;3918.node2.supernodexp.hpc;Exit_status=0 resources_used.cpupercent=995 resources_used.cput=00:55:57 resources_used.mem=1115204kb resources_used.ncpus=16 resources_used.vmem=9776904kb resources_used.walltime=00:03:40
02/20/2018 08:56:50;0100;Server@node2;Job;3918.node2.supernodexp.hpc;dequeuing from workq, state 5
02/20/2018 08:56:50;0040;Server@node2;Svr;node2.supernodexp.hpc;Scheduler sent command 2
02/20/2018 08:56:50;0040;Server@node2;Svr;node2.supernodexp.hpc;Scheduler sent command 0
02/20/2018 08:56:50;0100;Server@node2;Req;;Type 21 request received from Scheduler@node2.supernodexp.hpc, sock=16
02/20/2018 08:56:50;0100;Server@node2;Req;;Type 81 request received from Scheduler@node2.supernodexp.hpc, sock=16
02/20/2018 08:56:50;0100;Server@node2;Req;;Type 71 request received from Scheduler@node2.supernodexp.hpc, sock=16
02/20/2018 08:56:50;0100;Server@node2;Req;;Type 58 request received from Scheduler@node2.supernodexp.hpc, sock=16
02/20/2018 08:56:50;0100;Server@node2;Req;;Type 20 request received from Scheduler@node2.supernodexp.hpc, sock=16
02/20/2018 08:56:50;0100;Server@node2;Req;;Type 51 request received from Scheduler@node2.supernodexp.hpc, sock=16
02/20/2018 08:56:50;0100;Server@node2;Req;;Type 23 request received from Scheduler@node2.supernodexp.hpc, sock=16
02/20/2018 08:56:50;0008;Server@node2;Job;3999.node2.supernodexp.hpc;Job Run at request of Scheduler@node2.supernodexp.hpc on exec_vnode (node13:ncpus=16:mem=8388608kb)
02/20/2018 08:56:50;0001;Server@node2;Svr;Server@node2;Success (0) in req_runjob2, return value of svr_startjob is 0
02/20/2018 08:56:50;0100;Server@node2;Req;;Type 11 request received from Scheduler@node2.supernodexp.hpc, sock=16
02/20/2018 08:56:50;0008;Server@node2;Job;4000.node2.supernodexp.hpc;Job Modified at request of Scheduler@node2.supernodexp.hpc
02/20/2018 08:59:23;0080;Server@node2;Job;3922.node2.supernodexp.hpc;Obit received momhop:1 serverhop:1 state:4 substate:42
02/20/2018 08:59:25;0010;Server@node2;Job;3922.node2.supernodexp.hpc;Exit_status=0 resources_used.cpupercent=831 resources_used.cput=00:53:34 resources_used.mem=1115056kb resources_used.ncpus=16 resources_used.vmem=9812068kb resources_used.walltime=00:03:36
02/20/2018 08:59:25;0100;Server@node2;Job;3922.node2.supernodexp.hpc;dequeuing from workq, state 5
02/20/2018 08:59:25;0040;Server@node2;Svr;node2.supernodexp.hpc;Scheduler sent command 2
02/20/2018 08:59:25;0040;Server@node2;Svr;node2.supernodexp.hpc;Scheduler sent command 0
02/20/2018 08:59:25;0100;Server@node2;Req;;Type 21 request received from Scheduler@node2.supernodexp.hpc, sock=16
02/20/2018 08:59:25;0100;Server@node2;Req;;Type 81 request received from Scheduler@node2.supernodexp.hpc, sock=16
02/20/2018 08:59:25;0100;Server@node2;Req;;Type 71 request received from Scheduler@node2.supernodexp.hpc, sock=16
02/20/2018 08:59:25;0100;Server@node2;Req;;Type 58 request received from Scheduler@node2.supernodexp.hpc, sock=16
02/20/2018 08:59:25;0100;Server@node2;Req;;Type 20 request received from Scheduler@node2.supernodexp.hpc, sock=16
02/20/2018 08:59:25;0100;Server@node2;Req;;Type 51 request received from Scheduler@node2.supernodexp.hpc, sock=16
02/20/2018 08:59:26;0100;Server@node2;Req;;Type 23 request received from Scheduler@node2.supernodexp.hpc, sock=16
02/20/2018 08:59:26;0008;Server@node2;Job;4000.node2.supernodexp.hpc;Job Run at request of Scheduler@node2.supernodexp.hpc on exec_vnode (node14:ncpus=16:mem=8388608kb)
02/20/2018 08:59:26;0001;Server@node2;Svr;Server@node2;Success (0) in req_runjob2, return value of svr_startjob is 0
02/20/2018 08:59:26;0100;Server@node2;Req;;Type 11 request received from Scheduler@node2.supernodexp.hpc, sock=16
02/20/2018 08:59:26;0008;Server@node2;Job;4002.node2.supernodexp.hpc;Job Modified at request of Scheduler@node2.supernodexp.hpc
02/20/2018 08:59:42;0080;Server@node2;Job;3927.node2.supernodexp.hpc;Obit received momhop:1 serverhop:1 state:4 substate:42
02/20/2018 08:59:43;0010;Server@node2;Job;3927.node2.supernodexp.hpc;Exit_status=0 resources_used.cpupercent=836 resources_used.cput=00:55:41 resources_used.mem=1115128kb resources_used.ncpus=16 resources_used.vmem=9812040kb resources_used.walltime=00:03:42
02/20/2018 08:59:43;0100;Server@node2;Job;3927.node2.supernodexp.hpc;dequeuing from workq, state 5
02/20/2018 08:59:43;0040;Server@node2;Svr;node2.supernodexp.hpc;Scheduler sent command 2
02/20/2018 08:59:43;0040;Server@node2;Svr;node2.supernodexp.hpc;Scheduler sent command 0
02/20/2018 08:59:43;0100;Server@node2;Req;;Type 21 request received from Scheduler@node2.supernodexp.hpc, sock=16
02/20/2018 08:59:43;0100;Server@node2;Req;;Type 81 request received from Scheduler@node2.supernodexp.hpc, sock=16
02/20/2018 08:59:43;0100;Server@node2;Req;;Type 71 request received from Scheduler@node2.supernodexp.hpc, sock=16
02/20/2018 08:59:43;0100;Server@node2;Req;;Type 58 request received from Scheduler@node2.supernodexp.hpc, sock=16
02/20/2018 08:59:43;0100;Server@node2;Req;;Type 20 request received from Scheduler@node2.supernodexp.hpc, sock=16
02/20/2018 08:59:43;0100;Server@node2;Req;;Type 51 request received from Scheduler@node2.supernodexp.hpc, sock=16
02/20/2018 08:59:43;0100;Server@node2;Req;;Type 23 request received from Scheduler@node2.supernodexp.hpc, sock=16
02/20/2018 08:59:43;0008;Server@node2;Job;4002.node2.supernodexp.hpc;Job Run at request of Scheduler@node2.supernodexp.hpc on exec_vnode (node14:ncpus=16:mem=8388608kb)
02/20/2018 08:59:43;0001;Server@node2;Svr;Server@node2;Success (0) in req_runjob2, return value of svr_startjob is 0
02/20/2018 08:59:43;0100;Server@node2;Req;;Type 11 request received from Scheduler@node2.supernodexp.hpc, sock=16
02/20/2018 08:59:43;0008;Server@node2;Job;4076.node2.supernodexp.hpc;Job Modified at request of Scheduler@node2.supernodexp.hpc
02/20/2018 08:59:44;0080;Server@node2;Job;3985.node2.supernodexp.hpc;Obit received momhop:1 serverhop:1 state:4 substate:42
02/20/2018 08:59:45;0010;Server@node2;Job;3985.node2.supernodexp.hpc;Exit_status=0 resources_used.cpupercent=986 resources_used.cput=00:54:36 resources_used.mem=1115240kb resources_used.ncpus=16 resources_used.vmem=9812012kb resources_used.walltime=00:03:35
02/20/2018 08:59:45;0100;Server@node2;Job;3985.node2.supernodexp.hpc;dequeuing from workq, state 5
02/20/2018 08:59:45;0040;Server@node2;Svr;node2.supernodexp.hpc;Scheduler sent command 2
02/20/2018 08:59:45;0040;Server@node2;Svr;node2.supernodexp.hpc;Scheduler sent command 0
02/20/2018 08:59:45;0100;Server@node2;Req;;Type 21 request received from Scheduler@node2.supernodexp.hpc, sock=16
02/20/2018 08:59:45;0100;Server@node2;Req;;Type 81 request received from Scheduler@node2.supernodexp.hpc, sock=16
02/20/2018 08:59:45;0100;Server@node2;Req;;Type 71 request received from Scheduler@node2.supernodexp.hpc, sock=16
02/20/2018 08:59:45;0100;Server@node2;Req;;Type 58 request received from Scheduler@node2.supernodexp.hpc, sock=16
02/20/2018 08:59:45;0100;Server@node2;Req;;Type 20 request received from Scheduler@node2.supernodexp.hpc, sock=16
02/20/2018 08:59:45;0100;Server@node2;Req;;Type 51 request received from Scheduler@node2.supernodexp.hpc, sock=16
02/20/2018 08:59:45;0100;Server@node2;Req;;Type 23 request received from Scheduler@node2.supernodexp.hpc, sock=16
02/20/2018 08:59:45;0008;Server@node2;Job;4076.node2.supernodexp.hpc;Job Run at request of Scheduler@node2.supernodexp.hpc on exec_vnode (node14:ncpus=16:mem=8388608kb)
02/20/2018 08:59:45;0001;Server@node2;Svr;Server@node2;Success (0) in req_runjob2, return value of svr_startjob is 0
02/20/2018 08:59:45;0100;Server@node2;Req;;Type 11 request received from Scheduler@node2.supernodexp.hpc, sock=16
02/20/2018 08:59:45;0008;Server@node2;Job;4079.node2.supernodexp.hpc;Job Modified at request of Scheduler@node2.supernodexp.hpc
02/20/2018 09:00:26;0080;Server@node2;Job;3989.node2.supernodexp.hpc;Obit received momhop:1 serverhop:1 state:4 substate:42
02/20/2018 09:00:28;0010;Server@node2;Job;3989.node2.supernodexp.hpc;Exit_status=0 resources_used.cpupercent=880 resources_used.cput=00:56:07 resources_used.mem=1115044kb resources_used.ncpus=16 resources_used.vmem=9776796kb resources_used.walltime=00:03:43
02/20/2018 09:00:28;0100;Server@node2;Job;3989.node2.supernodexp.hpc;dequeuing from workq, state 5
02/20/2018 09:00:28;0040;Server@node2;Svr;node2.supernodexp.hpc;Scheduler sent command 2
02/20/2018 09:00:28;0040;Server@node2;Svr;node2.supernodexp.hpc;Scheduler sent command 0
02/20/2018 09:00:28;0100;Server@node2;Req;;Type 21 request received from Scheduler@node2.supernodexp.hpc, sock=16
02/20/2018 09:00:28;0100;Server@node2;Req;;Type 81 request received from Scheduler@node2.supernodexp.hpc, sock=16
02/20/2018 09:00:28;0100;Server@node2;Req;;Type 71 request received from Scheduler@node2.supernodexp.hpc, sock=16
02/20/2018 09:00:28;0100;Server@node2;Req;;Type 58 request received from Scheduler@node2.supernodexp.hpc, sock=16
02/20/2018 09:00:28;0100;Server@node2;Req;;Type 20 request received from Scheduler@node2.supernodexp.hpc, sock=16
02/20/2018 09:00:28;0100;Server@node2;Req;;Type 51 request received from Scheduler@node2.supernodexp.hpc, sock=16
02/20/2018 09:00:28;0100;Server@node2;Req;;Type 23 request received from Scheduler@node2.supernodexp.hpc, sock=16
02/20/2018 09:00:28;0008;Server@node2;Job;4079.node2.supernodexp.hpc;Job Run at request of Scheduler@node2.supernodexp.hpc on exec_vnode (node13:ncpus=16:mem=8388608kb)
02/20/2018 09:00:28;0001;Server@node2;Svr;Server@node2;Success (0) in req_runjob2, return value of svr_startjob is 0
02/20/2018 09:00:28;0100;Server@node2;Req;;Type 11 request received from Scheduler@node2.supernodexp.hpc, sock=16
02/20/2018 09:00:28;0008;Server@node2;Job;4089.node2.supernodexp.hpc;Job Modified at request of Scheduler@node2.supernodexp.hpc
02/20/2018 09:00:29;0080;Server@node2;Job;3997.node2.supernodexp.hpc;Obit received momhop:1 serverhop:1 state:4 substate:42
02/20/2018 09:00:30;0010;Server@node2;Job;3997.node2.supernodexp.hpc;Exit_status=0 resources_used.cpupercent=884 resources_used.cput=00:56:38 resources_used.mem=1115016kb resources_used.ncpus=16 resources_used.vmem=9776700kb resources_used.walltime=00:03:42
02/20/2018 09:00:30;0100;Server@node2;Job;3997.node2.supernodexp.hpc;dequeuing from workq, state 5
02/20/2018 09:00:30;0040;Server@node2;Svr;node2.supernodexp.hpc;Scheduler sent command 2
02/20/2018 09:00:30;0040;Server@node2;Svr;node2.supernodexp.hpc;Scheduler sent command 0
02/20/2018 09:00:30;0100;Server@node2;Req;;Type 21 request received from Scheduler@node2.supernodexp.hpc, sock=16
02/20/2018 09:00:30;0100;Server@node2;Req;;Type 81 request received from Scheduler@node2.supernodexp.hpc, sock=16
02/20/2018 09:00:30;0100;Server@node2;Req;;Type 71 request received from Scheduler@node2.supernodexp.hpc, sock=16
02/20/2018 09:00:30;0100;Server@node2;Req;;Type 58 request received from Scheduler@node2.supernodexp.hpc, sock=16
02/20/2018 09:00:30;0100;Server@node2;Req;;Type 20 request received from Scheduler@node2.supernodexp.hpc, sock=16
02/20/2018 09:00:30;0100;Server@node2;Req;;Type 51 request received from Scheduler@node2.supernodexp.hpc, sock=16
02/20/2018 09:00:30;0080;Server@node2;Job;3999.node2.supernodexp.hpc;Obit received momhop:1 serverhop:1 state:4 substate:42
02/20/2018 09:00:30;0100;Server@node2;Req;;Type 23 request received from Scheduler@node2.supernodexp.hpc, sock=16
02/20/2018 09:00:30;0008;Server@node2;Job;4089.node2.supernodexp.hpc;Job Run at request of Scheduler@node2.supernodexp.hpc on exec_vnode (node13:ncpus=16:mem=8388608kb)
02/20/2018 09:00:30;0001;Server@node2;Svr;Server@node2;Success (0) in req_runjob2, return value of svr_startjob is 0
02/20/2018 09:00:30;0100;Server@node2;Req;;Type 11 request received from Scheduler@node2.supernodexp.hpc, sock=16
02/20/2018 09:00:30;0008;Server@node2;Job;4113.node2.supernodexp.hpc;Job Modified at request of Scheduler@node2.supernodexp.hpc
02/20/2018 09:00:31;0010;Server@node2;Job;3999.node2.supernodexp.hpc;Exit_status=0 resources_used.cpupercent=1003 resources_used.cput=00:56:13 resources_used.mem=1115008kb resources_used.ncpus=16 resources_used.vmem=9776564kb resources_used.walltime=00:03:40
02/20/2018 09:00:31;0100;Server@node2;Job;3999.node2.supernodexp.hpc;dequeuing from workq, state 5
02/20/2018 09:00:31;0040;Server@node2;Svr;node2.supernodexp.hpc;Scheduler sent command 2
02/20/2018 09:00:31;0040;Server@node2;Svr;node2.supernodexp.hpc;Scheduler sent command 0
02/20/2018 09:00:31;0100;Server@node2;Req;;Type 21 request received from Scheduler@node2.supernodexp.hpc, sock=16
02/20/2018 09:00:31;0100;Server@node2;Req;;Type 81 request received from Scheduler@node2.supernodexp.hpc, sock=16
02/20/2018 09:00:31;0100;Server@node2;Req;;Type 71 request received from Scheduler@node2.supernodexp.hpc, sock=16
02/20/2018 09:00:31;0100;Server@node2;Req;;Type 58 request received from Scheduler@node2.supernodexp.hpc, sock=16
02/20/2018 09:00:31;0100;Server@node2;Req;;Type 20 request received from Scheduler@node2.supernodexp.hpc, sock=16
02/20/2018 09:00:31;0100;Server@node2;Req;;Type 51 request received from Scheduler@node2.supernodexp.hpc, sock=16
02/20/2018 09:00:32;0100;Server@node2;Req;;Type 23 request received from Scheduler@node2.supernodexp.hpc, sock=16
02/20/2018 09:00:32;0008;Server@node2;Job;4113.node2.supernodexp.hpc;Job Run at request of Scheduler@node2.supernodexp.hpc on exec_vnode (node13:ncpus=16:mem=8388608kb)
02/20/2018 09:00:32;0001;Server@node2;Svr;Server@node2;Success (0) in req_runjob2, return value of svr_startjob is 0
02/20/2018 09:00:32;0100;Server@node2;Req;;Type 11 request received from Scheduler@node2.supernodexp.hpc, sock=16
02/20/2018 09:00:32;0008;Server@node2;Job;4127.node2.supernodexp.hpc;Job Modified at request of Scheduler@node2.supernodexp.hpc
02/20/2018 09:00:34;0080;Server@node2;Job;4079.node2.supernodexp.hpc;Obit received momhop:1 serverhop:1 state:4 substate:42
02/20/2018 09:00:34;0080;Server@node2;Job;4089.node2.supernodexp.hpc;Obit received momhop:1 serverhop:1 state:4 substate:42
02/20/2018 09:00:36;0010;Server@node2;Job;4079.node2.supernodexp.hpc;Exit_status=1 resources_used.cpupercent=66 resources_used.cput=00:00:02 resources_used.mem=34088kb resources_used.ncpus=16 resources_used.vmem=647100kb resources_used.walltime=00:00:06
02/20/2018 09:00:36;0100;Server@node2;Job;4079.node2.supernodexp.hpc;dequeuing from workq, state 5
02/20/2018 09:00:36;0010;Server@node2;Job;4089.node2.supernodexp.hpc;Exit_status=1 resources_used.cpupercent=66 resources_used.cput=00:00:02 resources_used.mem=34088kb resources_used.ncpus=16 resources_used.vmem=647100kb resources_used.walltime=00:00:04
02/20/2018 09:00:36;0100;Server@node2;Job;4089.node2.supernodexp.hpc;dequeuing from workq, state 5
02/20/2018 09:00:36;0040;Server@node2;Svr;node2.supernodexp.hpc;Scheduler sent command 2
02/20/2018 09:00:36;0040;Server@node2;Svr;node2.supernodexp.hpc;Scheduler sent command 0
02/20/2018 09:00:36;0100;Server@node2;Req;;Type 21 request received from Scheduler@node2.supernodexp.hpc, sock=16
02/20/2018 09:00:36;0100;Server@node2;Req;;Type 81 request received from Scheduler@node2.supernodexp.hpc, sock=16
02/20/2018 09:00:36;0100;Server@node2;Req;;Type 71 request received from Scheduler@node2.supernodexp.hpc, sock=16
02/20/2018 09:00:36;0100;Server@node2;Req;;Type 58 request received from Scheduler@node2.supernodexp.hpc, sock=16
02/20/2018 09:00:36;0100;Server@node2;Req;;Type 20 request received from Scheduler@node2.supernodexp.hpc, sock=16
02/20/2018 09:00:36;0100;Server@node2;Req;;Type 51 request received from Scheduler@node2.supernodexp.hpc, sock=16
02/20/2018 09:00:36;0100;Server@node2;Req;;Type 23 request received from Scheduler@node2.supernodexp.hpc, sock=16
02/20/2018 09:00:36;0008;Server@node2;Job;4127.node2.supernodexp.hpc;Job Run at request of Scheduler@node2.supernodexp.hpc on exec_vnode (node13:ncpus=16:mem=8388608kb)
02/20/2018 09:00:36;0001;Server@node2;Svr;Server@node2;Success (0) in req_runjob2, return value of svr_startjob is 0
02/20/2018 09:00:36;0100;Server@node2;Req;;Type 23 request received from Scheduler@node2.supernodexp.hpc, sock=16
02/20/2018 09:00:36;0008;Server@node2;Job;4128.node2.supernodexp.hpc;Job Run at request of Scheduler@node2.supernodexp.hpc on exec_vnode (node13:ncpus=16:mem=8388608kb)
02/20/2018 09:00:36;0001;Server@node2;Svr;Server@node2;Success (0) in req_runjob2, return value of svr_startjob is 0
02/20/2018 09:00:36;0100;Server@node2;Req;;Type 11 request received from Scheduler@node2.supernodexp.hpc, sock=16
02/20/2018 09:00:36;0008;Server@node2;Job;4130.node2.supernodexp.hpc;Job Modified at request of Scheduler@node2.supernodexp.hpc
02/20/2018 09:00:38;0080;Server@node2;Job;4127.node2.supernodexp.hpc;Obit received momhop:1 serverhop:1 state:4 substate:42
02/20/2018 09:00:40;0010;Server@node2;Job;4127.node2.supernodexp.hpc;Exit_status=1 resources_used.cpupercent=100 resources_used.cput=00:00:02 resources_used.mem=0kb resources_used.ncpus=16 resources_used.vmem=0kb resources_used.walltime=00:00:02
02/20/2018 09:00:40;0100;Server@node2;Job;4127.node2.supernodexp.hpc;dequeuing from workq, state 5
02/20/2018 09:00:40;0040;Server@node2;Svr;node2.supernodexp.hpc;Scheduler sent command 2
02/20/2018 09:00:40;0040;Server@node2;Svr;node2.supernodexp.hpc;Scheduler sent command 0
02/20/2018 09:00:40;0100;Server@node2;Req;;Type 21 request received from Scheduler@node2.supernodexp.hpc, sock=16
02/20/2018 09:00:40;0100;Server@node2;Req;;Type 81 request received from Scheduler@node2.supernodexp.hpc, sock=16
02/20/2018 09:00:40;0100;Server@node2;Req;;Type 71 request received from Scheduler@node2.supernodexp.hpc, sock=16
02/20/2018 09:00:40;0100;Server@node2;Req;;Type 58 request received from Scheduler@node2.supernodexp.hpc, sock=16
02/20/2018 09:00:40;0100;Server@node2;Req;;Type 20 request received from Scheduler@node2.supernodexp.hpc, sock=16
02/20/2018 09:00:40;0100;Server@node2;Req;;Type 51 request received from Scheduler@node2.supernodexp.hpc, sock=16
02/20/2018 09:00:40;0100;Server@node2;Req;;Type 23 request received from Scheduler@node2.supernodexp.hpc, sock=16
02/20/2018 09:00:40;0008;Server@node2;Job;4130.node2.supernodexp.hpc;Job Run at request of Scheduler@node2.supernodexp.hpc on exec_vnode (node13:ncpus=16:mem=8388608kb)
02/20/2018 09:00:40;0001;Server@node2;Svr;Server@node2;Success (0) in req_runjob2, return value of svr_startjob is 0
02/20/2018 09:00:40;0100;Server@node2;Req;;Type 11 request received from Scheduler@node2.supernodexp.hpc, sock=16
02/20/2018 09:00:40;0008;Server@node2;Job;4182.node2.supernodexp.hpc;Job Modified at request of Scheduler@node2.supernodexp.hpc
02/20/2018 09:03:06;0080;Server@node2;Job;4000.node2.supernodexp.hpc;Obit received momhop:1 serverhop:1 state:4 substate:42
02/20/2018 09:03:07;0010;Server@node2;Job;4000.node2.supernodexp.hpc;Exit_status=0 resources_used.cpupercent=823 resources_used.cput=00:53:29 resources_used.mem=1115308kb resources_used.ncpus=16 resources_used.vmem=9812360kb resources_used.walltime=00:03:40
02/20/2018 09:03:07;0100;Server@node2;Job;4000.node2.supernodexp.hpc;dequeuing from workq, state 5
02/20/2018 09:03:07;0040;Server@node2;Svr;node2.supernodexp.hpc;Scheduler sent command 2
02/20/2018 09:03:07;0040;Server@node2;Svr;node2.supernodexp.hpc;Scheduler sent command 0
02/20/2018 09:03:07;0100;Server@node2;Req;;Type 21 request received from Scheduler@node2.supernodexp.hpc, sock=16
02/20/2018 09:03:07;0100;Server@node2;Req;;Type 81 request received from Scheduler@node2.supernodexp.hpc, sock=16
02/20/2018 09:03:07;0100;Server@node2;Req;;Type 71 request received from Scheduler@node2.supernodexp.hpc, sock=16
02/20/2018 09:03:07;0100;Server@node2;Req;;Type 58 request received from Scheduler@node2.supernodexp.hpc, sock=16
02/20/2018 09:03:07;0100;Server@node2;Req;;Type 20 request received from Scheduler@node2.supernodexp.hpc, sock=16
02/20/2018 09:03:07;0100;Server@node2;Req;;Type 51 request received from Scheduler@node2.supernodexp.hpc, sock=16
02/20/2018 09:03:08;0100;Server@node2;Req;;Type 23 request received from Scheduler@node2.supernodexp.hpc, sock=16
02/20/2018 09:03:08;0008;Server@node2;Job;4182.node2.supernodexp.hpc;Job Run at request of Scheduler@node2.supernodexp.hpc on exec_vnode (node14:ncpus=16:mem=8388608kb)
02/20/2018 09:03:08;0001;Server@node2;Svr;Server@node2;Success (0) in req_runjob2, return value of svr_startjob is 0
02/20/2018 09:03:08;0100;Server@node2;Req;;Type 11 request received from Scheduler@node2.supernodexp.hpc, sock=16
02/20/2018 09:03:08;0008;Server@node2;Job;4193.node2.supernodexp.hpc;Job Modified at request of Scheduler@node2.supernodexp.hpc
02/20/2018 09:03:22;0080;Server@node2;Job;4002.node2.supernodexp.hpc;Obit received momhop:1 serverhop:1 state:4 substate:42
02/20/2018 09:03:23;0010;Server@node2;Job;4002.node2.supernodexp.hpc;Exit_status=0 resources_used.cpupercent=917 resources_used.cput=00:55:51 resources_used.mem=1115220kb resources_used.ncpus=16 resources_used.vmem=9812100kb resources_used.walltime=00:03:38
02/20/2018 09:03:23;0100;Server@node2;Job;4002.node2.supernodexp.hpc;dequeuing from workq, state 5
02/20/2018 09:03:23;0040;Server@node2;Svr;node2.supernodexp.hpc;Scheduler sent command 2
02/20/2018 09:03:23;0040;Server@node2;Svr;node2.supernodexp.hpc;Scheduler sent command 0
02/20/2018 09:03:23;0100;Server@node2;Req;;Type 21 request received from Scheduler@node2.supernodexp.hpc, sock=16
02/20/2018 09:03:23;0100;Server@node2;Req;;Type 81 request received from Scheduler@node2.supernodexp.hpc, sock=16
02/20/2018 09:03:23;0100;Server@node2;Req;;Type 71 request received from Scheduler@node2.supernodexp.hpc, sock=16
02/20/2018 09:03:23;0100;Server@node2;Req;;Type 58 request received from Scheduler@node2.supernodexp.hpc, sock=16
02/20/2018 09:03:23;0100;Server@node2;Req;;Type 20 request received from Scheduler@node2.supernodexp.hpc, sock=16
02/20/2018 09:03:23;0100;Server@node2;Req;;Type 51 request received from Scheduler@node2.supernodexp.hpc, sock=16
02/20/2018 09:03:24;0100;Server@node2;Req;;Type 23 request received from Scheduler@node2.supernodexp.hpc, sock=16
02/20/2018 09:03:24;0008;Server@node2;Job;4193.node2.supernodexp.hpc;Job Run at request of Scheduler@node2.supernodexp.hpc on exec_vnode (node14:ncpus=16:mem=8388608kb)
02/20/2018 09:03:24;0001;Server@node2;Svr;Server@node2;Success (0) in req_runjob2, return value of svr_startjob is 0
02/20/2018 09:03:24;0100;Server@node2;Req;;Type 11 request received from Scheduler@node2.supernodexp.hpc, sock=16
02/20/2018 09:03:24;0008;Server@node2;Job;4208.node2.supernodexp.hpc;Job Modified at request of Scheduler@node2.supernodexp.hpc
02/20/2018 09:03:25;0080;Server@node2;Job;4076.node2.supernodexp.hpc;Obit received momhop:1 serverhop:1 state:4 substate:42
02/20/2018 09:03:26;0010;Server@node2;Job;4076.node2.supernodexp.hpc;Exit_status=0 resources_used.cpupercent=999 resources_used.cput=00:55:46 resources_used.mem=1115792kb resources_used.ncpus=16 resources_used.vmem=9812648kb resources_used.walltime=00:03:39
02/20/2018 09:03:26;0100;Server@node2;Job;4076.node2.supernodexp.hpc;dequeuing from workq, state 5
02/20/2018 09:03:26;0040;Server@node2;Svr;node2.supernodexp.hpc;Scheduler sent command 2
02/20/2018 09:03:26;0040;Server@node2;Svr;node2.supernodexp.hpc;Scheduler sent command 0
02/20/2018 09:03:26;0100;Server@node2;Req;;Type 21 request received from Scheduler@node2.supernodexp.hpc, sock=16
02/20/2018 09:03:26;0100;Server@node2;Req;;Type 81 request received from Scheduler@node2.supernodexp.hpc, sock=16
02/20/2018 09:03:26;0100;Server@node2;Req;;Type 71 request received from Scheduler@node2.supernodexp.hpc, sock=16
02/20/2018 09:03:26;0100;Server@node2;Req;;Type 58 request received from Scheduler@node2.supernodexp.hpc, sock=16
02/20/2018 09:03:26;0100;Server@node2;Req;;Type 20 request received from Scheduler@node2.supernodexp.hpc, sock=16
02/20/2018 09:03:26;0100;Server@node2;Req;;Type 51 request received from Scheduler@node2.supernodexp.hpc, sock=16
02/20/2018 09:03:26;0100;Server@node2;Req;;Type 23 request received from Scheduler@node2.supernodexp.hpc, sock=16
02/20/2018 09:03:26;0008;Server@node2;Job;4208.node2.supernodexp.hpc;Job Run at request of Scheduler@node2.supernodexp.hpc on exec_vnode (node14:ncpus=16:mem=8388608kb)
02/20/2018 09:03:26;0001;Server@node2;Svr;Server@node2;Success (0) in req_runjob2, return value of svr_startjob is 0
02/20/2018 09:03:26;0100;Server@node2;Req;;Type 11 request received from Scheduler@node2.supernodexp.hpc, sock=16
02/20/2018 09:03:26;0008;Server@node2;Job;4210.node2.supernodexp.hpc;Job Modified at request of Scheduler@node2.supernodexp.hpc
02/20/2018 09:04:06;0080;Server@node2;Job;4113.node2.supernodexp.hpc;Obit received momhop:1 serverhop:1 state:4 substate:42
02/20/2018 09:04:07;0010;Server@node2;Job;4113.node2.supernodexp.hpc;Exit_status=0 resources_used.cpupercent=866 resources_used.cput=00:54:49 resources_used.mem=1116928kb resources_used.ncpus=16 resources_used.vmem=9776744kb resources_used.walltime=00:03:34
02/20/2018 09:04:07;0100;Server@node2;Job;4113.node2.supernodexp.hpc;dequeuing from workq, state 5
02/20/2018 09:04:07;0040;Server@node2;Svr;node2.supernodexp.hpc;Scheduler sent command 2
02/20/2018 09:04:07;0040;Server@node2;Svr;node2.supernodexp.hpc;Scheduler sent command 0
02/20/2018 09:04:07;0100;Server@node2;Req;;Type 21 request received from Scheduler@node2.supernodexp.hpc, sock=16
02/20/2018 09:04:07;0100;Server@node2;Req;;Type 81 request received from Scheduler@node2.supernodexp.hpc, sock=16
02/20/2018 09:04:07;0100;Server@node2;Req;;Type 71 request received from Scheduler@node2.supernodexp.hpc, sock=16
02/20/2018 09:04:07;0100;Server@node2;Req;;Type 58 request received from Scheduler@node2.supernodexp.hpc, sock=16
02/20/2018 09:04:07;0100;Server@node2;Req;;Type 20 request received from Scheduler@node2.supernodexp.hpc, sock=16
02/20/2018 09:04:07;0100;Server@node2;Req;;Type 51 request received from Scheduler@node2.supernodexp.hpc, sock=16
02/20/2018 09:04:08;0100;Server@node2;Req;;Type 23 request received from Scheduler@node2.supernodexp.hpc, sock=16
02/20/2018 09:04:08;0008;Server@node2;Job;4210.node2.supernodexp.hpc;Job Run at request of Scheduler@node2.supernodexp.hpc on exec_vnode (node13:ncpus=16:mem=8388608kb)
02/20/2018 09:04:08;0001;Server@node2;Svr;Server@node2;Success (0) in req_runjob2, return value of svr_startjob is 0
02/20/2018 09:04:08;0100;Server@node2;Req;;Type 11 request received from Scheduler@node2.supernodexp.hpc, sock=16
02/20/2018 09:04:08;0008;Server@node2;Job;4225.node2.supernodexp.hpc;Job Modified at request of Scheduler@node2.supernodexp.hpc
02/20/2018 09:04:16;0080;Server@node2;Job;4128.node2.supernodexp.hpc;Obit received momhop:1 serverhop:1 state:4 substate:42
02/20/2018 09:04:18;0010;Server@node2;Job;4128.node2.supernodexp.hpc;Exit_status=0 resources_used.cpupercent=882 resources_used.cput=00:56:32 resources_used.mem=1114880kb resources_used.ncpus=16 resources_used.vmem=9776672kb resources_used.walltime=00:03:40
02/20/2018 09:04:18;0100;Server@node2;Job;4128.node2.supernodexp.hpc;dequeuing from workq, state 5
02/20/2018 09:04:18;0040;Server@node2;Svr;node2.supernodexp.hpc;Scheduler sent command 2
02/20/2018 09:04:18;0040;Server@node2;Svr;node2.supernodexp.hpc;Scheduler sent command 0
02/20/2018 09:04:18;0100;Server@node2;Req;;Type 21 request received from Scheduler@node2.supernodexp.hpc, sock=16
02/20/2018 09:04:18;0100;Server@node2;Req;;Type 81 request received from Scheduler@node2.supernodexp.hpc, sock=16
02/20/2018 09:04:18;0100;Server@node2;Req;;Type 71 request received from Scheduler@node2.supernodexp.hpc, sock=16
02/20/2018 09:04:18;0100;Server@node2;Req;;Type 58 request received from Scheduler@node2.supernodexp.hpc, sock=16
02/20/2018 09:04:18;0100;Server@node2;Req;;Type 20 request received from Scheduler@node2.supernodexp.hpc, sock=16
02/20/2018 09:04:18;0100;Server@node2;Req;;Type 51 request received from Scheduler@node2.supernodexp.hpc, sock=16
02/20/2018 09:04:18;0100;Server@node2;Req;;Type 23 request received from Scheduler@node2.supernodexp.hpc, sock=16
02/20/2018 09:04:18;0008;Server@node2;Job;4225.node2.supernodexp.hpc;Job Run at request of Scheduler@node2.supernodexp.hpc on exec_vnode (node13:ncpus=16:mem=8388608kb)
02/20/2018 09:04:18;0001;Server@node2;Svr;Server@node2;Success (0) in req_runjob2, return value of svr_startjob is 0
02/20/2018 09:04:18;0100;Server@node2;Req;;Type 11 request received from Scheduler@node2.supernodexp.hpc, sock=16
02/20/2018 09:04:18;0008;Server@node2;Job;4241.node2.supernodexp.hpc;Job Modified at request of Scheduler@node2.supernodexp.hpc
02/20/2018 09:04:18;0080;Server@node2;Job;4130.node2.supernodexp.hpc;Obit received momhop:1 serverhop:1 state:4 substate:42
02/20/2018 09:04:19;0010;Server@node2;Job;4130.node2.supernodexp.hpc;Exit_status=0 resources_used.cpupercent=1001 resources_used.cput=00:55:32 resources_used.mem=1114844kb resources_used.ncpus=16 resources_used.vmem=9776708kb resources_used.walltime=00:03:38
02/20/2018 09:04:19;0100;Server@node2;Job;4130.node2.supernodexp.hpc;dequeuing from workq, state 5
02/20/2018 09:04:19;0040;Server@node2;Svr;node2.supernodexp.hpc;Scheduler sent command 2
02/20/2018 09:04:19;0040;Server@node2;Svr;node2.supernodexp.hpc;Scheduler sent command 0
02/20/2018 09:04:19;0100;Server@node2;Req;;Type 21 request received from Scheduler@node2.supernodexp.hpc, sock=16
02/20/2018 09:04:19;0100;Server@node2;Req;;Type 81 request received from Scheduler@node2.supernodexp.hpc, sock=16
02/20/2018 09:04:19;0100;Server@node2;Req;;Type 71 request received from Scheduler@node2.supernodexp.hpc, sock=16
02/20/2018 09:04:19;0100;Server@node2;Req;;Type 58 request received from Scheduler@node2.supernodexp.hpc, sock=16
02/20/2018 09:04:19;0100;Server@node2;Req;;Type 20 request received from Scheduler@node2.supernodexp.hpc, sock=16
02/20/2018 09:04:19;0100;Server@node2;Req;;Type 51 request received from Scheduler@node2.supernodexp.hpc, sock=16
02/20/2018 09:04:19;0100;Server@node2;Req;;Type 23 request received from Scheduler@node2.supernodexp.hpc, sock=16
02/20/2018 09:04:19;0008;Server@node2;Job;4241.node2.supernodexp.hpc;Job Run at request of Scheduler@node2.supernodexp.hpc on exec_vnode (node13:ncpus=16:mem=8388608kb)
02/20/2018 09:04:19;0001;Server@node2;Svr;Server@node2;Success (0) in req_runjob2, return value of svr_startjob is 0
02/20/2018 09:04:19;0100;Server@node2;Req;;Type 11 request received from Scheduler@node2.supernodexp.hpc, sock=16
02/20/2018 09:04:19;0008;Server@node2;Job;4260.node2.supernodexp.hpc;Job Modified at request of Scheduler@node2.supernodexp.hpc
02/20/2018 09:06:41;0080;Server@node2;Job;4182.node2.supernodexp.hpc;Obit received momhop:1 serverhop:1 state:4 substate:42
02/20/2018 09:06:44;0010;Server@node2;Job;4182.node2.supernodexp.hpc;Exit_status=0 resources_used.cpupercent=803 resources_used.cput=00:52:18 resources_used.mem=1115024kb resources_used.ncpus=16 resources_used.vmem=9812036kb resources_used.walltime=00:03:34
02/20/2018 09:06:44;0100;Server@node2;Job;4182.node2.supernodexp.hpc;dequeuing from workq, state 5
02/20/2018 09:06:44;0040;Server@node2;Svr;node2.supernodexp.hpc;Scheduler sent command 2
02/20/2018 09:06:44;0040;Server@node2;Svr;node2.supernodexp.hpc;Scheduler sent command 0
02/20/2018 09:06:44;0100;Server@node2;Req;;Type 21 request received from Scheduler@node2.supernodexp.hpc, sock=16
02/20/2018 09:06:44;0100;Server@node2;Req;;Type 81 request received from Scheduler@node2.supernodexp.hpc, sock=16
02/20/2018 09:06:44;0100;Server@node2;Req;;Type 71 request received from Scheduler@node2.supernodexp.hpc, sock=16
02/20/2018 09:06:44;0100;Server@node2;Req;;Type 58 request received from Scheduler@node2.supernodexp.hpc, sock=16
02/20/2018 09:06:44;0100;Server@node2;Req;;Type 20 request received from Scheduler@node2.supernodexp.hpc, sock=16
02/20/2018 09:06:44;0100;Server@node2;Req;;Type 51 request received from Scheduler@node2.supernodexp.hpc, sock=16
02/20/2018 09:06:45;0100;Server@node2;Req;;Type 23 request received from Scheduler@node2.supernodexp.hpc, sock=16
02/20/2018 09:06:45;0008;Server@node2;Job;4260.node2.supernodexp.hpc;Job Run at request of Scheduler@node2.supernodexp.hpc on exec_vnode (node14:ncpus=16:mem=8388608kb)
02/20/2018 09:06:45;0001;Server@node2;Svr;Server@node2;Success (0) in req_runjob2, return value of svr_startjob is 0
02/20/2018 09:06:45;0100;Server@node2;Req;;Type 11 request received from Scheduler@node2.supernodexp.hpc, sock=16
02/20/2018 09:06:45;0008;Server@node2;Job;4270.node2.supernodexp.hpc;Job Modified at request of Scheduler@node2.supernodexp.hpc
02/20/2018 09:07:03;0080;Server@node2;Job;4208.node2.supernodexp.hpc;Obit received momhop:1 serverhop:1 state:4 substate:42
02/20/2018 09:07:04;0010;Server@node2;Job;4208.node2.supernodexp.hpc;Exit_status=0 resources_used.cpupercent=834 resources_used.cput=00:54:41 resources_used.mem=1115028kb resources_used.ncpus=16 resources_used.vmem=9811860kb resources_used.walltime=00:03:36
02/20/2018 09:07:04;0100;Server@node2;Job;4208.node2.supernodexp.hpc;dequeuing from workq, state 5
02/20/2018 09:07:04;0040;Server@node2;Svr;node2.supernodexp.hpc;Scheduler sent command 2
02/20/2018 09:07:04;0040;Server@node2;Svr;node2.supernodexp.hpc;Scheduler sent command 0
02/20/2018 09:07:04;0100;Server@node2;Req;;Type 21 request received from Scheduler@node2.supernodexp.hpc, sock=16
02/20/2018 09:07:04;0100;Server@node2;Req;;Type 81 request received from Scheduler@node2.supernodexp.hpc, sock=16
02/20/2018 09:07:04;0100;Server@node2;Req;;Type 71 request received from Scheduler@node2.supernodexp.hpc, sock=16
02/20/2018 09:07:04;0100;Server@node2;Req;;Type 58 request received from Scheduler@node2.supernodexp.hpc, sock=16
02/20/2018 09:07:04;0100;Server@node2;Req;;Type 20 request received from Scheduler@node2.supernodexp.hpc, sock=16
02/20/2018 09:07:04;0100;Server@node2;Req;;Type 51 request received from Scheduler@node2.supernodexp.hpc, sock=16
02/20/2018 09:07:04;0100;Server@node2;Req;;Type 23 request received from Scheduler@node2.supernodexp.hpc, sock=16
02/20/2018 09:07:04;0008;Server@node2;Job;4270.node2.supernodexp.hpc;Job Run at request of Scheduler@node2.supernodexp.hpc on exec_vnode (node14:ncpus=16:mem=8388608kb)
02/20/2018 09:07:04;0001;Server@node2;Svr;Server@node2;Success (0) in req_runjob2, return value of svr_startjob is 0
02/20/2018 09:07:04;0100;Server@node2;Req;;Type 11 request received from Scheduler@node2.supernodexp.hpc, sock=16
02/20/2018 09:07:04;0008;Server@node2;Job;4289.node2.supernodexp.hpc;Job Modified at request of Scheduler@node2.supernodexp.hpc
02/20/2018 09:07:07;0080;Server@node2;Job;4193.node2.supernodexp.hpc;Obit received momhop:1 serverhop:1 state:4 substate:42
02/20/2018 09:07:08;0010;Server@node2;Job;4193.node2.supernodexp.hpc;Exit_status=0 resources_used.cpupercent=874 resources_used.cput=00:56:06 resources_used.mem=1114892kb resources_used.ncpus=16 resources_used.vmem=9811896kb resources_used.walltime=00:03:43
02/20/2018 09:07:08;0100;Server@node2;Job;4193.node2.supernodexp.hpc;dequeuing from workq, state 5
02/20/2018 09:07:08;0040;Server@node2;Svr;node2.supernodexp.hpc;Scheduler sent command 2
02/20/2018 09:07:08;0040;Server@node2;Svr;node2.supernodexp.hpc;Scheduler sent command 0
02/20/2018 09:07:08;0100;Server@node2;Req;;Type 21 request received from Scheduler@node2.supernodexp.hpc, sock=16
02/20/2018 09:07:08;0100;Server@node2;Req;;Type 81 request received from Scheduler@node2.supernodexp.hpc, sock=16
02/20/2018 09:07:08;0100;Server@node2;Req;;Type 71 request received from Scheduler@node2.supernodexp.hpc, sock=16
02/20/2018 09:07:08;0100;Server@node2;Req;;Type 58 request received from Scheduler@node2.supernodexp.hpc, sock=16
02/20/2018 09:07:08;0100;Server@node2;Req;;Type 20 request received from Scheduler@node2.supernodexp.hpc, sock=16
02/20/2018 09:07:08;0100;Server@node2;Req;;Type 51 request received from Scheduler@node2.supernodexp.hpc, sock=16
02/20/2018 09:07:08;0100;Server@node2;Req;;Type 23 request received from Scheduler@node2.supernodexp.hpc, sock=16
02/20/2018 09:07:08;0008;Server@node2;Job;4289.node2.supernodexp.hpc;Job Run at request of Scheduler@node2.supernodexp.hpc on exec_vnode (node14:ncpus=16:mem=8388608kb)
02/20/2018 09:07:08;0001;Server@node2;Svr;Server@node2;Success (0) in req_runjob2, return value of svr_startjob is 0
02/20/2018 09:07:08;0100;Server@node2;Req;;Type 11 request received from Scheduler@node2.supernodexp.hpc, sock=16
02/20/2018 09:07:08;0008;Server@node2;Job;4301.node2.supernodexp.hpc;Job Modified at request of Scheduler@node2.supernodexp.hpc
02/20/2018 09:07:46;0080;Server@node2;Job;4210.node2.supernodexp.hpc;Obit received momhop:1 serverhop:1 state:4 substate:42
02/20/2018 09:07:47;0010;Server@node2;Job;4210.node2.supernodexp.hpc;Exit_status=0 resources_used.cpupercent=833 resources_used.cput=00:54:35 resources_used.mem=1116272kb resources_used.ncpus=16 resources_used.vmem=9777488kb resources_used.walltime=00:03:39
02/20/2018 09:07:47;0100;Server@node2;Job;4210.node2.supernodexp.hpc;dequeuing from workq, state 5
02/20/2018 09:07:48;0040;Server@node2;Svr;node2.supernodexp.hpc;Scheduler sent command 2
02/20/2018 09:07:48;0040;Server@node2;Svr;node2.supernodexp.hpc;Scheduler sent command 0
02/20/2018 09:07:48;0100;Server@node2;Req;;Type 21 request received from Scheduler@node2.supernodexp.hpc, sock=16
02/20/2018 09:07:48;0100;Server@node2;Req;;Type 81 request received from Scheduler@node2.supernodexp.hpc, sock=16
02/20/2018 09:07:48;0100;Server@node2;Req;;Type 71 request received from Scheduler@node2.supernodexp.hpc, sock=16
02/20/2018 09:07:48;0100;Server@node2;Req;;Type 58 request received from Scheduler@node2.supernodexp.hpc, sock=16
02/20/2018 09:07:48;0100;Server@node2;Req;;Type 20 request received from Scheduler@node2.supernodexp.hpc, sock=16
02/20/2018 09:07:48;0100;Server@node2;Req;;Type 51 request received from Scheduler@node2.supernodexp.hpc, sock=16
02/20/2018 09:07:48;0100;Server@node2;Req;;Type 23 request received from Scheduler@node2.supernodexp.hpc, sock=16
02/20/2018 09:07:48;0008;Server@node2;Job;4301.node2.supernodexp.hpc;Job Run at request of Scheduler@node2.supernodexp.hpc on exec_vnode (node13:ncpus=16:mem=8388608kb)
02/20/2018 09:07:48;0001;Server@node2;Svr;Server@node2;Success (0) in req_runjob2, return value of svr_startjob is 0
02/20/2018 09:07:48;0100;Server@node2;Req;;Type 11 request received from Scheduler@node2.supernodexp.hpc, sock=16
02/20/2018 09:07:48;0008;Server@node2;Job;4326.node2.supernodexp.hpc;Job Modified at request of Scheduler@node2.supernodexp.hpc
02/20/2018 09:07:55;0080;Server@node2;Job;4241.node2.supernodexp.hpc;Obit received momhop:1 serverhop:1 state:4 substate:42
02/20/2018 09:07:57;0010;Server@node2;Job;4241.node2.supernodexp.hpc;Exit_status=0 resources_used.cpupercent=1060 resources_used.cput=00:55:11 resources_used.mem=1114992kb resources_used.ncpus=16 resources_used.vmem=9776696kb resources_used.walltime=00:03:35
02/20/2018 09:07:57;0100;Server@node2;Job;4241.node2.supernodexp.hpc;dequeuing from workq, state 5
02/20/2018 09:07:57;0040;Server@node2;Svr;node2.supernodexp.hpc;Scheduler sent command 2
02/20/2018 09:07:57;0040;Server@node2;Svr;node2.supernodexp.hpc;Scheduler sent command 0
02/20/2018 09:07:57;0100;Server@node2;Req;;Type 21 request received from Scheduler@node2.supernodexp.hpc, sock=16
02/20/2018 09:07:57;0100;Server@node2;Req;;Type 81 request received from Scheduler@node2.supernodexp.hpc, sock=16
02/20/2018 09:07:57;0100;Server@node2;Req;;Type 71 request received from Scheduler@node2.supernodexp.hpc, sock=16
02/20/2018 09:07:57;0100;Server@node2;Req;;Type 58 request received from Scheduler@node2.supernodexp.hpc, sock=16
02/20/2018 09:07:57;0100;Server@node2;Req;;Type 20 request received from Scheduler@node2.supernodexp.hpc, sock=16
02/20/2018 09:07:57;0100;Server@node2;Req;;Type 51 request received from Scheduler@node2.supernodexp.hpc, sock=16
02/20/2018 09:07:57;0100;Server@node2;Req;;Type 23 request received from Scheduler@node2.supernodexp.hpc, sock=16
02/20/2018 09:07:57;0008;Server@node2;Job;4326.node2.supernodexp.hpc;Job Run at request of Scheduler@node2.supernodexp.hpc on exec_vnode (node13:ncpus=16:mem=8388608kb)
02/20/2018 09:07:57;0001;Server@node2;Svr;Server@node2;Success (0) in req_runjob2, return value of svr_startjob is 0
02/20/2018 09:07:57;0100;Server@node2;Req;;Type 11 request received from Scheduler@node2.supernodexp.hpc, sock=16
02/20/2018 09:07:57;0008;Server@node2;Job;4369.node2.supernodexp.hpc;Job Modified at request of Scheduler@node2.supernodexp.hpc
02/20/2018 09:07:59;0080;Server@node2;Job;4225.node2.supernodexp.hpc;Obit received momhop:1 serverhop:1 state:4 substate:42
02/20/2018 09:08:00;0010;Server@node2;Job;4225.node2.supernodexp.hpc;Exit_status=0 resources_used.cpupercent=882 resources_used.cput=00:56:41 resources_used.mem=1115116kb resources_used.ncpus=16 resources_used.vmem=9776928kb resources_used.walltime=00:03:41
02/20/2018 09:08:00;0100;Server@node2;Job;4225.node2.supernodexp.hpc;dequeuing from workq, state 5
02/20/2018 09:08:00;0040;Server@node2;Svr;node2.supernodexp.hpc;Scheduler sent command 2
02/20/2018 09:08:00;0040;Server@node2;Svr;node2.supernodexp.hpc;Scheduler sent command 0
02/20/2018 09:08:00;0100;Server@node2;Req;;Type 21 request received from Scheduler@node2.supernodexp.hpc, sock=16
02/20/2018 09:08:00;0100;Server@node2;Req;;Type 81 request received from Scheduler@node2.supernodexp.hpc, sock=16
02/20/2018 09:08:00;0100;Server@node2;Req;;Type 71 request received from Scheduler@node2.supernodexp.hpc, sock=16
02/20/2018 09:08:00;0100;Server@node2;Req;;Type 58 request received from Scheduler@node2.supernodexp.hpc, sock=16
02/20/2018 09:08:00;0100;Server@node2;Req;;Type 20 request received from Scheduler@node2.supernodexp.hpc, sock=16
02/20/2018 09:08:00;0100;Server@node2;Req;;Type 51 request received from Scheduler@node2.supernodexp.hpc, sock=16
02/20/2018 09:08:00;0100;Server@node2;Req;;Type 23 request received from Scheduler@node2.supernodexp.hpc, sock=16
02/20/2018 09:08:00;0008;Server@node2;Job;4369.node2.supernodexp.hpc;Job Run at request of Scheduler@node2.supernodexp.hpc on exec_vnode (node13:ncpus=16:mem=8388608kb)
02/20/2018 09:08:00;0001;Server@node2;Svr;Server@node2;Success (0) in req_runjob2, return value of svr_startjob is 0
02/20/2018 09:08:00;0100;Server@node2;Req;;Type 11 request received from Scheduler@node2.supernodexp.hpc, sock=16
02/20/2018 09:08:00;0008;Server@node2;Job;4399.node2.supernodexp.hpc;Job Modified at request of Scheduler@node2.supernodexp.hpc
02/20/2018 09:10:27;0080;Server@node2;Job;4260.node2.supernodexp.hpc;Obit received momhop:1 serverhop:1 state:4 substate:42
02/20/2018 09:10:28;0010;Server@node2;Job;4260.node2.supernodexp.hpc;Exit_status=0 resources_used.cpupercent=850 resources_used.cput=00:55:09 resources_used.mem=1115088kb resources_used.ncpus=16 resources_used.vmem=9812024kb resources_used.walltime=00:03:42
02/20/2018 09:10:28;0100;Server@node2;Job;4260.node2.supernodexp.hpc;dequeuing from workq, state 5
02/20/2018 09:10:28;0040;Server@node2;Svr;node2.supernodexp.hpc;Scheduler sent command 2
02/20/2018 09:10:28;0040;Server@node2;Svr;node2.supernodexp.hpc;Scheduler sent command 0
02/20/2018 09:10:28;0100;Server@node2;Req;;Type 21 request received from Scheduler@node2.supernodexp.hpc, sock=16
02/20/2018 09:10:28;0100;Server@node2;Req;;Type 81 request received from Scheduler@node2.supernodexp.hpc, sock=16
02/20/2018 09:10:28;0100;Server@node2;Req;;Type 71 request received from Scheduler@node2.supernodexp.hpc, sock=16
02/20/2018 09:10:28;0100;Server@node2;Req;;Type 58 request received from Scheduler@node2.supernodexp.hpc, sock=16
02/20/2018 09:10:28;0100;Server@node2;Req;;Type 20 request received from Scheduler@node2.supernodexp.hpc, sock=16
02/20/2018 09:10:28;0100;Server@node2;Req;;Type 51 request received from Scheduler@node2.supernodexp.hpc, sock=16
02/20/2018 09:10:29;0100;Server@node2;Req;;Type 23 request received from Scheduler@node2.supernodexp.hpc, sock=16
02/20/2018 09:10:29;0008;Server@node2;Job;4399.node2.supernodexp.hpc;Job Run at request of Scheduler@node2.supernodexp.hpc on exec_vnode (node14:ncpus=16:mem=8388608kb)
02/20/2018 09:10:29;0001;Server@node2;Svr;Server@node2;Success (0) in req_runjob2, return value of svr_startjob is 0
02/20/2018 09:10:29;0100;Server@node2;Req;;Type 11 request received from Scheduler@node2.supernodexp.hpc, sock=16
02/20/2018 09:10:29;0008;Server@node2;Job;4400.node2.supernodexp.hpc;Job Modified at request of Scheduler@node2.supernodexp.hpc
02/20/2018 09:10:40;0080;Server@node2;Job;4270.node2.supernodexp.hpc;Obit received momhop:1 serverhop:1 state:4 substate:42
02/20/2018 09:10:41;0010;Server@node2;Job;4270.node2.supernodexp.hpc;Exit_status=0 resources_used.cpupercent=873 resources_used.cput=00:55:30 resources_used.mem=1115056kb resources_used.ncpus=16 resources_used.vmem=9812128kb resources_used.walltime=00:03:36
02/20/2018 09:10:41;0100;Server@node2;Job;4270.node2.supernodexp.hpc;dequeuing from workq, state 5
02/20/2018 09:10:41;0040;Server@node2;Svr;node2.supernodexp.hpc;Scheduler sent command 2
02/20/2018 09:10:41;0040;Server@node2;Svr;node2.supernodexp.hpc;Scheduler sent command 0
02/20/2018 09:10:41;0100;Server@node2;Req;;Type 21 request received from Scheduler@node2.supernodexp.hpc, sock=16
02/20/2018 09:10:41;0100;Server@node2;Req;;Type 81 request received from Scheduler@node2.supernodexp.hpc, sock=16
02/20/2018 09:10:41;0100;Server@node2;Req;;Type 71 request received from Scheduler@node2.supernodexp.hpc, sock=16
02/20/2018 09:10:41;0100;Server@node2;Req;;Type 58 request received from Scheduler@node2.supernodexp.hpc, sock=16
02/20/2018 09:10:41;0100;Server@node2;Req;;Type 20 request received from Scheduler@node2.supernodexp.hpc, sock=16
02/20/2018 09:10:41;0100;Server@node2;Req;;Type 51 request received from Scheduler@node2.supernodexp.hpc, sock=16
02/20/2018 09:10:41;0080;Server@node2;Job;4289.node2.supernodexp.hpc;Obit received momhop:1 serverhop:1 state:4 substate:42
02/20/2018 09:10:41;0100;Server@node2;Req;;Type 23 request received from Scheduler@node2.supernodexp.hpc, sock=16
02/20/2018 09:10:41;0008;Server@node2;Job;4400.node2.supernodexp.hpc;Job Run at request of Scheduler@node2.supernodexp.hpc on exec_vnode (node14:ncpus=16:mem=8388608kb)
02/20/2018 09:10:41;0001;Server@node2;Svr;Server@node2;Success (0) in req_runjob2, return value of svr_startjob is 0
02/20/2018 09:10:41;0100;Server@node2;Req;;Type 11 request received from Scheduler@node2.supernodexp.hpc, sock=16
02/20/2018 09:10:41;0008;Server@node2;Job;4407.node2.supernodexp.hpc;Job Modified at request of Scheduler@node2.supernodexp.hpc
02/20/2018 09:10:42;0010;Server@node2;Job;4289.node2.supernodexp.hpc;Exit_status=0 resources_used.cpupercent=959 resources_used.cput=00:54:29 resources_used.mem=1115096kb resources_used.ncpus=16 resources_used.vmem=9812056kb resources_used.walltime=00:03:34
02/20/2018 09:10:42;0100;Server@node2;Job;4289.node2.supernodexp.hpc;dequeuing from workq, state 5
02/20/2018 09:10:42;0040;Server@node2;Svr;node2.supernodexp.hpc;Scheduler sent command 2
02/20/2018 09:10:42;0040;Server@node2;Svr;node2.supernodexp.hpc;Scheduler sent command 0
02/20/2018 09:10:42;0100;Server@node2;Req;;Type 21 request received from Scheduler@node2.supernodexp.hpc, sock=16
02/20/2018 09:10:42;0100;Server@node2;Req;;Type 81 request received from Scheduler@node2.supernodexp.hpc, sock=16
02/20/2018 09:10:42;0100;Server@node2;Req;;Type 71 request received from Scheduler@node2.supernodexp.hpc, sock=16
02/20/2018 09:10:42;0100;Server@node2;Req;;Type 58 request received from Scheduler@node2.supernodexp.hpc, sock=16
02/20/2018 09:10:42;0100;Server@node2;Req;;Type 20 request received from Scheduler@node2.supernodexp.hpc, sock=16
02/20/2018 09:10:42;0100;Server@node2;Req;;Type 51 request received from Scheduler@node2.supernodexp.hpc, sock=16
02/20/2018 09:10:43;0100;Server@node2;Req;;Type 23 request received from Scheduler@node2.supernodexp.hpc, sock=16
02/20/2018 09:10:43;0008;Server@node2;Job;4407.node2.supernodexp.hpc;Job Run at request of Scheduler@node2.supernodexp.hpc on exec_vnode (node14:ncpus=16:mem=8388608kb)
02/20/2018 09:10:43;0001;Server@node2;Svr;Server@node2;Success (0) in req_runjob2, return value of svr_startjob is 0
02/20/2018 09:10:43;0100;Server@node2;Req;;Type 11 request received from Scheduler@node2.supernodexp.hpc, sock=16
02/20/2018 09:10:43;0008;Server@node2;Job;4428.node2.supernodexp.hpc;Job Modified at request of Scheduler@node2.supernodexp.hpc
02/20/2018 09:11:23;0080;Server@node2;Job;4301.node2.supernodexp.hpc;Obit received momhop:1 serverhop:1 state:4 substate:42
02/20/2018 09:11:25;0010;Server@node2;Job;4301.node2.supernodexp.hpc;Exit_status=0 resources_used.cpupercent=828 resources_used.cput=00:53:54 resources_used.mem=1114708kb resources_used.ncpus=16 resources_used.vmem=9776652kb resources_used.walltime=00:03:35
02/20/2018 09:11:25;0100;Server@node2;Job;4301.node2.supernodexp.hpc;dequeuing from workq, state 5
02/20/2018 09:11:25;0040;Server@node2;Svr;node2.supernodexp.hpc;Scheduler sent command 2
02/20/2018 09:11:25;0040;Server@node2;Svr;node2.supernodexp.hpc;Scheduler sent command 0
02/20/2018 09:11:25;0100;Server@node2;Req;;Type 21 request received from Scheduler@node2.supernodexp.hpc, sock=16
02/20/2018 09:11:25;0100;Server@node2;Req;;Type 81 request received from Scheduler@node2.supernodexp.hpc, sock=16
02/20/2018 09:11:25;0100;Server@node2;Req;;Type 71 request received from Scheduler@node2.supernodexp.hpc, sock=16
02/20/2018 09:11:25;0100;Server@node2;Req;;Type 58 request received from Scheduler@node2.supernodexp.hpc, sock=16
02/20/2018 09:11:25;0100;Server@node2;Req;;Type 20 request received from Scheduler@node2.supernodexp.hpc, sock=16
02/20/2018 09:11:25;0100;Server@node2;Req;;Type 51 request received from Scheduler@node2.supernodexp.hpc, sock=16
02/20/2018 09:11:25;0100;Server@node2;Req;;Type 23 request received from Scheduler@node2.supernodexp.hpc, sock=16
02/20/2018 09:11:25;0008;Server@node2;Job;4428.node2.supernodexp.hpc;Job Run at request of Scheduler@node2.supernodexp.hpc on exec_vnode (node13:ncpus=16:mem=8388608kb)
02/20/2018 09:11:25;0001;Server@node2;Svr;Server@node2;Success (0) in req_runjob2, return value of svr_startjob is 0
02/20/2018 09:11:25;0100;Server@node2;Req;;Type 11 request received from Scheduler@node2.supernodexp.hpc, sock=16
02/20/2018 09:11:25;0008;Server@node2;Job;4447.node2.supernodexp.hpc;Job Modified at request of Scheduler@node2.supernodexp.hpc
02/20/2018 09:11:37;0080;Server@node2;Job;4326.node2.supernodexp.hpc;Obit received momhop:1 serverhop:1 state:4 substate:42
02/20/2018 09:11:38;0010;Server@node2;Job;4326.node2.supernodexp.hpc;Exit_status=0 resources_used.cpupercent=862 resources_used.cput=00:56:44 resources_used.mem=1115008kb resources_used.ncpus=16 resources_used.vmem=9776808kb resources_used.walltime=00:03:40
02/20/2018 09:11:38;0100;Server@node2;Job;4326.node2.supernodexp.hpc;dequeuing from workq, state 5
02/20/2018 09:11:38;0040;Server@node2;Svr;node2.supernodexp.hpc;Scheduler sent command 2
02/20/2018 09:11:38;0040;Server@node2;Svr;node2.supernodexp.hpc;Scheduler sent command 0
02/20/2018 09:11:38;0100;Server@node2;Req;;Type 21 request received from Scheduler@node2.supernodexp.hpc, sock=16
02/20/2018 09:11:38;0100;Server@node2;Req;;Type 81 request received from Scheduler@node2.supernodexp.hpc, sock=16
02/20/2018 09:11:38;0100;Server@node2;Req;;Type 71 request received from Scheduler@node2.supernodexp.hpc, sock=16
02/20/2018 09:11:38;0100;Server@node2;Req;;Type 58 request received from Scheduler@node2.supernodexp.hpc, sock=16
02/20/2018 09:11:38;0100;Server@node2;Req;;Type 20 request received from Scheduler@node2.supernodexp.hpc, sock=16
02/20/2018 09:11:38;0100;Server@node2;Req;;Type 51 request received from Scheduler@node2.supernodexp.hpc, sock=16
02/20/2018 09:11:39;0080;Server@node2;Job;4369.node2.supernodexp.hpc;Obit received momhop:1 serverhop:1 state:4 substate:42
02/20/2018 09:11:39;0100;Server@node2;Req;;Type 23 request received from Scheduler@node2.supernodexp.hpc, sock=16
02/20/2018 09:11:39;0008;Server@node2;Job;4447.node2.supernodexp.hpc;Job Run at request of Scheduler@node2.supernodexp.hpc on exec_vnode (node13:ncpus=16:mem=8388608kb)
02/20/2018 09:11:39;0001;Server@node2;Svr;Server@node2;Success (0) in req_runjob2, return value of svr_startjob is 0
02/20/2018 09:11:39;0100;Server@node2;Req;;Type 11 request received from Scheduler@node2.supernodexp.hpc, sock=16
02/20/2018 09:11:39;0008;Server@node2;Job;4476.node2.supernodexp.hpc;Job Modified at request of Scheduler@node2.supernodexp.hpc
02/20/2018 09:11:40;0010;Server@node2;Job;4369.node2.supernodexp.hpc;Exit_status=0 resources_used.cpupercent=926 resources_used.cput=00:55:51 resources_used.mem=1114904kb resources_used.ncpus=16 resources_used.vmem=9776512kb resources_used.walltime=00:03:39
02/20/2018 09:11:40;0100;Server@node2;Job;4369.node2.supernodexp.hpc;dequeuing from workq, state 5
02/20/2018 09:11:40;0040;Server@node2;Svr;node2.supernodexp.hpc;Scheduler sent command 2
02/20/2018 09:11:40;0040;Server@node2;Svr;node2.supernodexp.hpc;Scheduler sent command 0
02/20/2018 09:11:40;0100;Server@node2;Req;;Type 21 request received from Scheduler@node2.supernodexp.hpc, sock=16
02/20/2018 09:11:40;0100;Server@node2;Req;;Type 81 request received from Scheduler@node2.supernodexp.hpc, sock=16
02/20/2018 09:11:40;0100;Server@node2;Req;;Type 71 request received from Scheduler@node2.supernodexp.hpc, sock=16
02/20/2018 09:11:40;0100;Server@node2;Req;;Type 58 request received from Scheduler@node2.supernodexp.hpc, sock=16
02/20/2018 09:11:40;0100;Server@node2;Req;;Type 20 request received from Scheduler@node2.supernodexp.hpc, sock=16
02/20/2018 09:11:40;0100;Server@node2;Req;;Type 51 request received from Scheduler@node2.supernodexp.hpc, sock=16
02/20/2018 09:11:40;0100;Server@node2;Req;;Type 23 request received from Scheduler@node2.supernodexp.hpc, sock=16
02/20/2018 09:11:40;0008;Server@node2;Job;4476.node2.supernodexp.hpc;Job Run at request of Scheduler@node2.supernodexp.hpc on exec_vnode (node13:ncpus=16:mem=8388608kb)
02/20/2018 09:11:40;0001;Server@node2;Svr;Server@node2;Success (0) in req_runjob2, return value of svr_startjob is 0
02/20/2018 09:11:40;0100;Server@node2;Req;;Type 11 request received from Scheduler@node2.supernodexp.hpc, sock=16
02/20/2018 09:11:40;0008;Server@node2;Job;4477.node2.supernodexp.hpc;Job Modified at request of Scheduler@node2.supernodexp.hpc
02/20/2018 09:14:04;0080;Server@node2;Job;4399.node2.supernodexp.hpc;Obit received momhop:1 serverhop:1 state:4 substate:42
02/20/2018 09:14:06;0010;Server@node2;Job;4399.node2.supernodexp.hpc;Exit_status=0 resources_used.cpupercent=844 resources_used.cput=00:54:02 resources_used.mem=1116944kb resources_used.ncpus=16 resources_used.vmem=9811924kb resources_used.walltime=00:03:36
02/20/2018 09:14:06;0100;Server@node2;Job;4399.node2.supernodexp.hpc;dequeuing from workq, state 5
02/20/2018 09:14:06;0040;Server@node2;Svr;node2.supernodexp.hpc;Scheduler sent command 2
02/20/2018 09:14:06;0040;Server@node2;Svr;node2.supernodexp.hpc;Scheduler sent command 0
02/20/2018 09:14:06;0100;Server@node2;Req;;Type 21 request received from Scheduler@node2.supernodexp.hpc, sock=16
02/20/2018 09:14:06;0100;Server@node2;Req;;Type 81 request received from Scheduler@node2.supernodexp.hpc, sock=16
02/20/2018 09:14:06;0100;Server@node2;Req;;Type 71 request received from Scheduler@node2.supernodexp.hpc, sock=16
02/20/2018 09:14:06;0100;Server@node2;Req;;Type 58 request received from Scheduler@node2.supernodexp.hpc, sock=16
02/20/2018 09:14:06;0100;Server@node2;Req;;Type 20 request received from Scheduler@node2.supernodexp.hpc, sock=16
02/20/2018 09:14:06;0100;Server@node2;Req;;Type 51 request received from Scheduler@node2.supernodexp.hpc, sock=16
02/20/2018 09:14:06;0100;Server@node2;Req;;Type 23 request received from Scheduler@node2.supernodexp.hpc, sock=16
02/20/2018 09:14:06;0008;Server@node2;Job;4477.node2.supernodexp.hpc;Job Run at request of Scheduler@node2.supernodexp.hpc on exec_vnode (node14:ncpus=16:mem=8388608kb)
02/20/2018 09:14:06;0001;Server@node2;Svr;Server@node2;Success (0) in req_runjob2, return value of svr_startjob is 0
02/20/2018 09:14:06;0100;Server@node2;Req;;Type 11 request received from Scheduler@node2.supernodexp.hpc, sock=16
02/20/2018 09:14:06;0008;Server@node2;Job;4480.node2.supernodexp.hpc;Job Modified at request of Scheduler@node2.supernodexp.hpc
02/20/2018 09:14:18;0080;Server@node2;Job;4407.node2.supernodexp.hpc;Obit received momhop:1 serverhop:1 state:4 substate:42
02/20/2018 09:14:20;0010;Server@node2;Job;4407.node2.supernodexp.hpc;Exit_status=0 resources_used.cpupercent=987 resources_used.cput=00:54:47 resources_used.mem=1115172kb resources_used.ncpus=16 resources_used.vmem=9811912kb resources_used.walltime=00:03:36
02/20/2018 09:14:20;0100;Server@node2;Job;4407.node2.supernodexp.hpc;dequeuing from workq, state 5
02/20/2018 09:14:20;0040;Server@node2;Svr;node2.supernodexp.hpc;Scheduler sent command 2
02/20/2018 09:14:20;0040;Server@node2;Svr;node2.supernodexp.hpc;Scheduler sent command 0
02/20/2018 09:14:20;0100;Server@node2;Req;;Type 21 request received from Scheduler@node2.supernodexp.hpc, sock=16
02/20/2018 09:14:20;0100;Server@node2;Req;;Type 81 request received from Scheduler@node2.supernodexp.hpc, sock=16
02/20/2018 09:14:20;0100;Server@node2;Req;;Type 71 request received from Scheduler@node2.supernodexp.hpc, sock=16
02/20/2018 09:14:20;0100;Server@node2;Req;;Type 58 request received from Scheduler@node2.supernodexp.hpc, sock=16
02/20/2018 09:14:20;0100;Server@node2;Req;;Type 20 request received from Scheduler@node2.supernodexp.hpc, sock=16
02/20/2018 09:14:20;0100;Server@node2;Req;;Type 51 request received from Scheduler@node2.supernodexp.hpc, sock=16
02/20/2018 09:14:20;0100;Server@node2;Req;;Type 23 request received from Scheduler@node2.supernodexp.hpc, sock=16
02/20/2018 09:14:20;0008;Server@node2;Job;4480.node2.supernodexp.hpc;Job Run at request of Scheduler@node2.supernodexp.hpc on exec_vnode (node14:ncpus=16:mem=8388608kb)
02/20/2018 09:14:20;0001;Server@node2;Svr;Server@node2;Success (0) in req_runjob2, return value of svr_startjob is 0
02/20/2018 09:14:20;0100;Server@node2;Req;;Type 11 request received from Scheduler@node2.supernodexp.hpc, sock=16
02/20/2018 09:14:20;0008;Server@node2;Job;4493.node2.supernodexp.hpc;Job Modified at request of Scheduler@node2.supernodexp.hpc
02/20/2018 09:14:20;0080;Server@node2;Job;4400.node2.supernodexp.hpc;Obit received momhop:1 serverhop:1 state:4 substate:42
02/20/2018 09:14:22;0010;Server@node2;Job;4400.node2.supernodexp.hpc;Exit_status=0 resources_used.cpupercent=872 resources_used.cput=00:55:42 resources_used.mem=1115128kb resources_used.ncpus=16 resources_used.vmem=9812072kb resources_used.walltime=00:03:39
02/20/2018 09:14:22;0100;Server@node2;Job;4400.node2.supernodexp.hpc;dequeuing from workq, state 5
02/20/2018 09:14:22;0040;Server@node2;Svr;node2.supernodexp.hpc;Scheduler sent command 2
02/20/2018 09:14:22;0040;Server@node2;Svr;node2.supernodexp.hpc;Scheduler sent command 0
02/20/2018 09:14:22;0100;Server@node2;Req;;Type 21 request received from Scheduler@node2.supernodexp.hpc, sock=16
02/20/2018 09:14:22;0100;Server@node2;Req;;Type 81 request received from Scheduler@node2.supernodexp.hpc, sock=16
02/20/2018 09:14:22;0100;Server@node2;Req;;Type 71 request received from Scheduler@node2.supernodexp.hpc, sock=16
02/20/2018 09:14:22;0100;Server@node2;Req;;Type 58 request received from Scheduler@node2.supernodexp.hpc, sock=16
02/20/2018 09:14:22;0100;Server@node2;Req;;Type 20 request received from Scheduler@node2.supernodexp.hpc, sock=16
02/20/2018 09:14:22;0100;Server@node2;Req;;Type 51 request received from Scheduler@node2.supernodexp.hpc, sock=16
02/20/2018 09:14:22;0100;Server@node2;Req;;Type 23 request received from Scheduler@node2.supernodexp.hpc, sock=16
02/20/2018 09:14:22;0008;Server@node2;Job;4493.node2.supernodexp.hpc;Job Run at request of Scheduler@node2.supernodexp.hpc on exec_vnode (node14:ncpus=16:mem=8388608kb)
02/20/2018 09:14:22;0001;Server@node2;Svr;Server@node2;Success (0) in req_runjob2, return value of svr_startjob is 0
02/20/2018 09:14:22;0100;Server@node2;Req;;Type 11 request received from Scheduler@node2.supernodexp.hpc, sock=16
02/20/2018 09:14:22;0008;Server@node2;Job;4554.node2.supernodexp.hpc;Job Modified at request of Scheduler@node2.supernodexp.hpc
02/20/2018 09:15:02;0080;Server@node2;Job;4428.node2.supernodexp.hpc;Obit received momhop:1 serverhop:1 state:4 substate:42
02/20/2018 09:15:04;0010;Server@node2;Job;4428.node2.supernodexp.hpc;Exit_status=0 resources_used.cpupercent=829 resources_used.cput=00:53:59 resources_used.mem=1115016kb resources_used.ncpus=16 resources_used.vmem=9776676kb resources_used.walltime=00:03:37
02/20/2018 09:15:04;0100;Server@node2;Job;4428.node2.supernodexp.hpc;dequeuing from workq, state 5
02/20/2018 09:15:04;0040;Server@node2;Svr;node2.supernodexp.hpc;Scheduler sent command 2
02/20/2018 09:15:04;0040;Server@node2;Svr;node2.supernodexp.hpc;Scheduler sent command 0
02/20/2018 09:15:04;0100;Server@node2;Req;;Type 21 request received from Scheduler@node2.supernodexp.hpc, sock=16
02/20/2018 09:15:04;0100;Server@node2;Req;;Type 81 request received from Scheduler@node2.supernodexp.hpc, sock=16
02/20/2018 09:15:04;0100;Server@node2;Req;;Type 71 request received from Scheduler@node2.supernodexp.hpc, sock=16
02/20/2018 09:15:04;0100;Server@node2;Req;;Type 58 request received from Scheduler@node2.supernodexp.hpc, sock=16
02/20/2018 09:15:04;0100;Server@node2;Req;;Type 20 request received from Scheduler@node2.supernodexp.hpc, sock=16
02/20/2018 09:15:04;0100;Server@node2;Req;;Type 51 request received from Scheduler@node2.supernodexp.hpc, sock=16
02/20/2018 09:15:04;0100;Server@node2;Req;;Type 23 request received from Scheduler@node2.supernodexp.hpc, sock=16
02/20/2018 09:15:04;0008;Server@node2;Job;4554.node2.supernodexp.hpc;Job Run at request of Scheduler@node2.supernodexp.hpc on exec_vnode (node13:ncpus=16:mem=8388608kb)
02/20/2018 09:15:04;0001;Server@node2;Svr;Server@node2;Success (0) in req_runjob2, return value of svr_startjob is 0
02/20/2018 09:15:04;0100;Server@node2;Req;;Type 11 request received from Scheduler@node2.supernodexp.hpc, sock=16
02/20/2018 09:15:04;0008;Server@node2;Job;4564.node2.supernodexp.hpc;Job Modified at request of Scheduler@node2.supernodexp.hpc
02/20/2018 09:15:17;0080;Server@node2;Job;4476.node2.supernodexp.hpc;Obit received momhop:1 serverhop:1 state:4 substate:42
02/20/2018 09:15:17;0080;Server@node2;Job;4447.node2.supernodexp.hpc;Obit received momhop:1 serverhop:1 state:4 substate:42
02/20/2018 09:15:18;0010;Server@node2;Job;4476.node2.supernodexp.hpc;Exit_status=0 resources_used.cpupercent=1150 resources_used.cput=00:55:38 resources_used.mem=1114840kb resources_used.ncpus=16 resources_used.vmem=9776584kb resources_used.walltime=00:03:37
02/20/2018 09:15:18;0100;Server@node2;Job;4476.node2.supernodexp.hpc;dequeuing from workq, state 5
02/20/2018 09:15:18;0040;Server@node2;Svr;node2.supernodexp.hpc;Scheduler sent command 2
02/20/2018 09:15:18;0040;Server@node2;Svr;node2.supernodexp.hpc;Scheduler sent command 0
02/20/2018 09:15:18;0100;Server@node2;Req;;Type 21 request received from Scheduler@node2.supernodexp.hpc, sock=16
02/20/2018 09:15:18;0100;Server@node2;Req;;Type 81 request received from Scheduler@node2.supernodexp.hpc, sock=16
02/20/2018 09:15:18;0100;Server@node2;Req;;Type 71 request received from Scheduler@node2.supernodexp.hpc, sock=16
02/20/2018 09:15:18;0100;Server@node2;Req;;Type 58 request received from Scheduler@node2.supernodexp.hpc, sock=16
02/20/2018 09:15:18;0100;Server@node2;Req;;Type 20 request received from Scheduler@node2.supernodexp.hpc, sock=16
02/20/2018 09:15:18;0100;Server@node2;Req;;Type 51 request received from Scheduler@node2.supernodexp.hpc, sock=16
02/20/2018 09:15:18;0100;Server@node2;Req;;Type 23 request received from Scheduler@node2.supernodexp.hpc, sock=16
02/20/2018 09:15:18;0008;Server@node2;Job;4564.node2.supernodexp.hpc;Job Run at request of Scheduler@node2.supernodexp.hpc on exec_vnode (node13:ncpus=16:mem=8388608kb)
02/20/2018 09:15:18;0001;Server@node2;Svr;Server@node2;Success (0) in req_runjob2, return value of svr_startjob is 0
02/20/2018 09:15:18;0100;Server@node2;Req;;Type 11 request received from Scheduler@node2.supernodexp.hpc, sock=16
02/20/2018 09:15:18;0008;Server@node2;Job;4576.node2.supernodexp.hpc;Job Modified at request of Scheduler@node2.supernodexp.hpc
02/20/2018 09:15:19;0010;Server@node2;Job;4447.node2.supernodexp.hpc;Exit_status=0 resources_used.cpupercent=878 resources_used.cput=00:56:07 resources_used.mem=1114904kb resources_used.ncpus=16 resources_used.vmem=9776780kb resources_used.walltime=00:03:38
02/20/2018 09:15:19;0100;Server@node2;Job;4447.node2.supernodexp.hpc;dequeuing from workq, state 5
02/20/2018 09:15:19;0040;Server@node2;Svr;node2.supernodexp.hpc;Scheduler sent command 2
02/20/2018 09:15:19;0040;Server@node2;Svr;node2.supernodexp.hpc;Scheduler sent command 0
02/20/2018 09:15:19;0100;Server@node2;Req;;Type 21 request received from Scheduler@node2.supernodexp.hpc, sock=16
02/20/2018 09:15:19;0100;Server@node2;Req;;Type 81 request received from Scheduler@node2.supernodexp.hpc, sock=16
02/20/2018 09:15:19;0100;Server@node2;Req;;Type 71 request received from Scheduler@node2.supernodexp.hpc, sock=16
02/20/2018 09:15:19;0100;Server@node2;Req;;Type 58 request received from Scheduler@node2.supernodexp.hpc, sock=16
02/20/2018 09:15:19;0100;Server@node2;Req;;Type 20 request received from Scheduler@node2.supernodexp.hpc, sock=16
02/20/2018 09:15:19;0100;Server@node2;Req;;Type 51 request received from Scheduler@node2.supernodexp.hpc, sock=16
02/20/2018 09:15:19;0100;Server@node2;Req;;Type 23 request received from Scheduler@node2.supernodexp.hpc, sock=16
02/20/2018 09:15:19;0008;Server@node2;Job;4576.node2.supernodexp.hpc;Job Run at request of Scheduler@node2.supernodexp.hpc on exec_vnode (node13:ncpus=16:mem=8388608kb)
02/20/2018 09:15:19;0001;Server@node2;Svr;Server@node2;Success (0) in req_runjob2, return value of svr_startjob is 0
02/20/2018 09:15:19;0100;Server@node2;Req;;Type 11 request received from Scheduler@node2.supernodexp.hpc, sock=16
02/20/2018 09:15:19;0008;Server@node2;Job;4604.node2.supernodexp.hpc;Job Modified at request of Scheduler@node2.supernodexp.hpc
02/20/2018 09:15:23;0080;Server@node2;Job;4576.node2.supernodexp.hpc;Obit received momhop:1 serverhop:1 state:4 substate:42
02/20/2018 09:15:24;0010;Server@node2;Job;4576.node2.supernodexp.hpc;Exit_status=1 resources_used.cpupercent=50 resources_used.cput=00:00:02 resources_used.mem=0kb resources_used.ncpus=16 resources_used.vmem=0kb resources_used.walltime=00:00:04
02/20/2018 09:15:24;0100;Server@node2;Job;4576.node2.supernodexp.hpc;dequeuing from workq, state 5
02/20/2018 09:15:24;0040;Server@node2;Svr;node2.supernodexp.hpc;Scheduler sent command 2
02/20/2018 09:15:24;0040;Server@node2;Svr;node2.supernodexp.hpc;Scheduler sent command 0
02/20/2018 09:15:24;0100;Server@node2;Req;;Type 21 request received from Scheduler@node2.supernodexp.hpc, sock=16
02/20/2018 09:15:24;0100;Server@node2;Req;;Type 81 request received from Scheduler@node2.supernodexp.hpc, sock=16
02/20/2018 09:15:24;0100;Server@node2;Req;;Type 71 request received from Scheduler@node2.supernodexp.hpc, sock=16
02/20/2018 09:15:24;0100;Server@node2;Req;;Type 58 request received from Scheduler@node2.supernodexp.hpc, sock=16
02/20/2018 09:15:24;0100;Server@node2;Req;;Type 20 request received from Scheduler@node2.supernodexp.hpc, sock=16
02/20/2018 09:15:24;0100;Server@node2;Req;;Type 51 request received from Scheduler@node2.supernodexp.hpc, sock=16
02/20/2018 09:15:24;0100;Server@node2;Req;;Type 23 request received from Scheduler@node2.supernodexp.hpc, sock=16
02/20/2018 09:15:24;0008;Server@node2;Job;4604.node2.supernodexp.hpc;Job Run at request of Scheduler@node2.supernodexp.hpc on exec_vnode (node13:ncpus=16:mem=8388608kb)
02/20/2018 09:15:24;0001;Server@node2;Svr;Server@node2;Success (0) in req_runjob2, return value of svr_startjob is 0
02/20/2018 09:15:24;0100;Server@node2;Req;;Type 11 request received from Scheduler@node2.supernodexp.hpc, sock=16
02/20/2018 09:15:24;0008;Server@node2;Job;4606.node2.supernodexp.hpc;Job Modified at request of Scheduler@node2.supernodexp.hpc
02/20/2018 09:17:45;0080;Server@node2;Job;4477.node2.supernodexp.hpc;Obit received momhop:1 serverhop:1 state:4 substate:42
02/20/2018 09:17:47;0010;Server@node2;Job;4477.node2.supernodexp.hpc;Exit_status=0 resources_used.cpupercent=837 resources_used.cput=00:54:03 resources_used.mem=1115272kb resources_used.ncpus=16 resources_used.vmem=9812176kb resources_used.walltime=00:03:39
02/20/2018 09:17:47;0100;Server@node2;Job;4477.node2.supernodexp.hpc;dequeuing from workq, state 5
02/20/2018 09:17:47;0040;Server@node2;Svr;node2.supernodexp.hpc;Scheduler sent command 2
02/20/2018 09:17:47;0040;Server@node2;Svr;node2.supernodexp.hpc;Scheduler sent command 0
02/20/2018 09:17:47;0100;Server@node2;Req;;Type 21 request received from Scheduler@node2.supernodexp.hpc, sock=16
02/20/2018 09:17:47;0100;Server@node2;Req;;Type 81 request received from Scheduler@node2.supernodexp.hpc, sock=16
02/20/2018 09:17:47;0100;Server@node2;Req;;Type 71 request received from Scheduler@node2.supernodexp.hpc, sock=16
02/20/2018 09:17:47;0100;Server@node2;Req;;Type 58 request received from Scheduler@node2.supernodexp.hpc, sock=16
02/20/2018 09:17:47;0100;Server@node2;Req;;Type 20 request received from Scheduler@node2.supernodexp.hpc, sock=16
02/20/2018 09:17:47;0100;Server@node2;Req;;Type 51 request received from Scheduler@node2.supernodexp.hpc, sock=16
02/20/2018 09:17:47;0100;Server@node2;Req;;Type 23 request received from Scheduler@node2.supernodexp.hpc, sock=16
02/20/2018 09:17:47;0008;Server@node2;Job;4606.node2.supernodexp.hpc;Job Run at request of Scheduler@node2.supernodexp.hpc on exec_vnode (node14:ncpus=16:mem=8388608kb)
02/20/2018 09:17:47;0001;Server@node2;Svr;Server@node2;Success (0) in req_runjob2, return value of svr_startjob is 0
02/20/2018 09:17:47;0100;Server@node2;Req;;Type 11 request received from Scheduler@node2.supernodexp.hpc, sock=16
02/20/2018 09:17:47;0008;Server@node2;Job;4615.node2.supernodexp.hpc;Job Modified at request of Scheduler@node2.supernodexp.hpc
02/20/2018 09:17:59;0080;Server@node2;Job;4493.node2.supernodexp.hpc;Obit received momhop:1 serverhop:1 state:4 substate:42
02/20/2018 09:18:00;0010;Server@node2;Job;4493.node2.supernodexp.hpc;Exit_status=0 resources_used.cpupercent=1069 resources_used.cput=00:55:08 resources_used.mem=1116676kb resources_used.ncpus=16 resources_used.vmem=9813164kb resources_used.walltime=00:03:37
02/20/2018 09:18:00;0100;Server@node2;Job;4493.node2.supernodexp.hpc;dequeuing from workq, state 5
02/20/2018 09:18:00;0040;Server@node2;Svr;node2.supernodexp.hpc;Scheduler sent command 2
02/20/2018 09:18:00;0040;Server@node2;Svr;node2.supernodexp.hpc;Scheduler sent command 0
02/20/2018 09:18:00;0100;Server@node2;Req;;Type 21 request received from Scheduler@node2.supernodexp.hpc, sock=16
02/20/2018 09:18:00;0100;Server@node2;Req;;Type 81 request received from Scheduler@node2.supernodexp.hpc, sock=16
02/20/2018 09:18:00;0100;Server@node2;Req;;Type 71 request received from Scheduler@node2.supernodexp.hpc, sock=16
02/20/2018 09:18:00;0100;Server@node2;Req;;Type 58 request received from Scheduler@node2.supernodexp.hpc, sock=16
02/20/2018 09:18:00;0100;Server@node2;Req;;Type 20 request received from Scheduler@node2.supernodexp.hpc, sock=16
02/20/2018 09:18:00;0100;Server@node2;Req;;Type 51 request received from Scheduler@node2.supernodexp.hpc, sock=16
02/20/2018 09:18:00;0100;Server@node2;Req;;Type 23 request received from Scheduler@node2.supernodexp.hpc, sock=16
02/20/2018 09:18:00;0008;Server@node2;Job;4615.node2.supernodexp.hpc;Job Run at request of Scheduler@node2.supernodexp.hpc on exec_vnode (node14:ncpus=16:mem=8388608kb)
02/20/2018 09:18:00;0001;Server@node2;Svr;Server@node2;Success (0) in req_runjob2, return value of svr_startjob is 0
02/20/2018 09:18:00;0100;Server@node2;Req;;Type 11 request received from Scheduler@node2.supernodexp.hpc, sock=16
02/20/2018 09:18:00;0008;Server@node2;Job;3680.node2.supernodexp.hpc;Job Modified at request of Scheduler@node2.supernodexp.hpc
02/20/2018 09:18:02;0080;Server@node2;Job;4480.node2.supernodexp.hpc;Obit received momhop:1 serverhop:1 state:4 substate:42
02/20/2018 09:18:03;0010;Server@node2;Job;4480.node2.supernodexp.hpc;Exit_status=0 resources_used.cpupercent=880 resources_used.cput=00:56:12 resources_used.mem=1115316kb resources_used.ncpus=16 resources_used.vmem=9812340kb resources_used.walltime=00:03:42
02/20/2018 09:18:03;0100;Server@node2;Job;4480.node2.supernodexp.hpc;dequeuing from workq, state 5
02/20/2018 09:18:03;0040;Server@node2;Svr;node2.supernodexp.hpc;Scheduler sent command 2
02/20/2018 09:18:03;0040;Server@node2;Svr;node2.supernodexp.hpc;Scheduler sent command 0
02/20/2018 09:18:03;0100;Server@node2;Req;;Type 21 request received from Scheduler@node2.supernodexp.hpc, sock=16
02/20/2018 09:18:03;0100;Server@node2;Req;;Type 81 request received from Scheduler@node2.supernodexp.hpc, sock=16
02/20/2018 09:18:03;0100;Server@node2;Req;;Type 71 request received from Scheduler@node2.supernodexp.hpc, sock=16
02/20/2018 09:18:03;0100;Server@node2;Req;;Type 58 request received from Scheduler@node2.supernodexp.hpc, sock=16
02/20/2018 09:18:03;0100;Server@node2;Req;;Type 20 request received from Scheduler@node2.supernodexp.hpc, sock=16
02/20/2018 09:18:03;0100;Server@node2;Req;;Type 51 request received from Scheduler@node2.supernodexp.hpc, sock=16
02/20/2018 09:18:03;0100;Server@node2;Req;;Type 11 request received from Scheduler@node2.supernodexp.hpc, sock=16
02/20/2018 09:18:03;0008;Server@node2;Job;3680.node2.supernodexp.hpc;Job Modified at request of Scheduler@node2.supernodexp.hpc
02/20/2018 09:18:39;0080;Server@node2;Job;4554.node2.supernodexp.hpc;Obit received momhop:1 serverhop:1 state:4 substate:42
02/20/2018 09:18:40;0010;Server@node2;Job;4554.node2.supernodexp.hpc;Exit_status=0 resources_used.cpupercent=828 resources_used.cput=00:53:13 resources_used.mem=1114872kb resources_used.ncpus=16 resources_used.vmem=9776528kb resources_used.walltime=00:03:35
02/20/2018 09:18:40;0100;Server@node2;Job;4554.node2.supernodexp.hpc;dequeuing from workq, state 5
02/20/2018 09:18:40;0040;Server@node2;Svr;node2.supernodexp.hpc;Scheduler sent command 2
02/20/2018 09:18:40;0040;Server@node2;Svr;node2.supernodexp.hpc;Scheduler sent command 0
02/20/2018 09:18:40;0100;Server@node2;Req;;Type 21 request received from Scheduler@node2.supernodexp.hpc, sock=16
02/20/2018 09:18:40;0100;Server@node2;Req;;Type 81 request received from Scheduler@node2.supernodexp.hpc, sock=16
02/20/2018 09:18:40;0100;Server@node2;Req;;Type 71 request received from Scheduler@node2.supernodexp.hpc, sock=16
02/20/2018 09:18:40;0100;Server@node2;Req;;Type 58 request received from Scheduler@node2.supernodexp.hpc, sock=16
02/20/2018 09:18:40;0100;Server@node2;Req;;Type 20 request received from Scheduler@node2.supernodexp.hpc, sock=16
02/20/2018 09:18:40;0100;Server@node2;Req;;Type 51 request received from Scheduler@node2.supernodexp.hpc, sock=16
02/20/2018 09:18:40;0100;Server@node2;Req;;Type 11 request received from Scheduler@node2.supernodexp.hpc, sock=16
02/20/2018 09:18:40;0008;Server@node2;Job;3680.node2.supernodexp.hpc;Job Modified at request of Scheduler@node2.supernodexp.hpc
02/20/2018 09:18:56;0080;Server@node2;Job;4564.node2.supernodexp.hpc;Obit received momhop:1 serverhop:1 state:4 substate:42
02/20/2018 09:18:57;0010;Server@node2;Job;4564.node2.supernodexp.hpc;Exit_status=0 resources_used.cpupercent=849 resources_used.cput=00:55:37 resources_used.mem=1115052kb resources_used.ncpus=16 resources_used.vmem=9776604kb resources_used.walltime=00:03:38
02/20/2018 09:18:57;0100;Server@node2;Job;4564.node2.supernodexp.hpc;dequeuing from workq, state 5
02/20/2018 09:18:57;0040;Server@node2;Svr;node2.supernodexp.hpc;Scheduler sent command 2
02/20/2018 09:18:57;0040;Server@node2;Svr;node2.supernodexp.hpc;Scheduler sent command 0
02/20/2018 09:18:57;0100;Server@node2;Req;;Type 21 request received from Scheduler@node2.supernodexp.hpc, sock=16
02/20/2018 09:18:57;0100;Server@node2;Req;;Type 81 request received from Scheduler@node2.supernodexp.hpc, sock=16
02/20/2018 09:18:57;0100;Server@node2;Req;;Type 71 request received from Scheduler@node2.supernodexp.hpc, sock=16
02/20/2018 09:18:57;0100;Server@node2;Req;;Type 58 request received from Scheduler@node2.supernodexp.hpc, sock=16
02/20/2018 09:18:57;0100;Server@node2;Req;;Type 20 request received from Scheduler@node2.supernodexp.hpc, sock=16
02/20/2018 09:18:57;0100;Server@node2;Req;;Type 51 request received from Scheduler@node2.supernodexp.hpc, sock=16
02/20/2018 09:18:57;0100;Server@node2;Req;;Type 23 request received from Scheduler@node2.supernodexp.hpc, sock=16
02/20/2018 09:18:57;0008;Server@node2;Job;3680.node2.supernodexp.hpc;Job Run at request of Scheduler@node2.supernodexp.hpc on exec_vnode (node13:ncpus=24:mem=2097152kb)
02/20/2018 09:18:57;0001;Server@node2;Svr;Server@node2;Success (0) in req_runjob2, return value of svr_startjob is 0
02/20/2018 09:18:57;0100;Server@node2;Req;;Type 11 request received from Scheduler@node2.supernodexp.hpc, sock=16
02/20/2018 09:18:57;0008;Server@node2;Job;3684.node2.supernodexp.hpc;Job Modified at request of Scheduler@node2.supernodexp.hpc
02/20/2018 09:18:59;0080;Server@node2;Job;4604.node2.supernodexp.hpc;Obit received momhop:1 serverhop:1 state:4 substate:42
02/20/2018 09:19:00;0010;Server@node2;Job;4604.node2.supernodexp.hpc;Exit_status=0 resources_used.cpupercent=929 resources_used.cput=00:54:31 resources_used.mem=1115820kb resources_used.ncpus=16 resources_used.vmem=9777404kb resources_used.walltime=00:03:34
02/20/2018 09:19:00;0100;Server@node2;Job;4604.node2.supernodexp.hpc;dequeuing from workq, state 5
02/20/2018 09:19:00;0040;Server@node2;Svr;node2.supernodexp.hpc;Scheduler sent command 2
02/20/2018 09:19:00;0040;Server@node2;Svr;node2.supernodexp.hpc;Scheduler sent command 0
02/20/2018 09:19:00;0100;Server@node2;Req;;Type 21 request received from Scheduler@node2.supernodexp.hpc, sock=16
02/20/2018 09:19:00;0100;Server@node2;Req;;Type 81 request received from Scheduler@node2.supernodexp.hpc, sock=16
02/20/2018 09:19:00;0100;Server@node2;Req;;Type 71 request received from Scheduler@node2.supernodexp.hpc, sock=16
02/20/2018 09:19:00;0100;Server@node2;Req;;Type 58 request received from Scheduler@node2.supernodexp.hpc, sock=16
02/20/2018 09:19:00;0100;Server@node2;Req;;Type 20 request received from Scheduler@node2.supernodexp.hpc, sock=16
02/20/2018 09:19:00;0100;Server@node2;Req;;Type 51 request received from Scheduler@node2.supernodexp.hpc, sock=16
02/20/2018 09:19:00;0100;Server@node2;Req;;Type 23 request received from Scheduler@node2.supernodexp.hpc, sock=16
02/20/2018 09:19:00;0008;Server@node2;Job;3684.node2.supernodexp.hpc;Job Run at request of Scheduler@node2.supernodexp.hpc on exec_vnode (node13:ncpus=24:mem=2097152kb)
02/20/2018 09:19:00;0001;Server@node2;Svr;Server@node2;Success (0) in req_runjob2, return value of svr_startjob is 0
02/20/2018 09:19:00;0100;Server@node2;Req;;Type 11 request received from Scheduler@node2.supernodexp.hpc, sock=16
02/20/2018 09:19:00;0008;Server@node2;Job;3713.node2.supernodexp.hpc;Job Modified at request of Scheduler@node2.supernodexp.hpc
02/20/2018 09:19:04;0080;Server@node2;Job;3684.node2.supernodexp.hpc;Obit received momhop:1 serverhop:1 state:4 substate:42
02/20/2018 09:19:05;0010;Server@node2;Job;3684.node2.supernodexp.hpc;Exit_status=1 resources_used.cpupercent=50 resources_used.cput=00:00:02 resources_used.mem=0kb resources_used.ncpus=24 resources_used.vmem=0kb resources_used.walltime=00:00:04
02/20/2018 09:19:05;0100;Server@node2;Job;3684.node2.supernodexp.hpc;dequeuing from workq, state 5
02/20/2018 09:19:05;0040;Server@node2;Svr;node2.supernodexp.hpc;Scheduler sent command 2
02/20/2018 09:19:05;0040;Server@node2;Svr;node2.supernodexp.hpc;Scheduler sent command 0
02/20/2018 09:19:05;0100;Server@node2;Req;;Type 21 request received from Scheduler@node2.supernodexp.hpc, sock=16
02/20/2018 09:19:05;0100;Server@node2;Req;;Type 81 request received from Scheduler@node2.supernodexp.hpc, sock=16
02/20/2018 09:19:05;0100;Server@node2;Req;;Type 71 request received from Scheduler@node2.supernodexp.hpc, sock=16
02/20/2018 09:19:05;0100;Server@node2;Req;;Type 58 request received from Scheduler@node2.supernodexp.hpc, sock=16
02/20/2018 09:19:05;0100;Server@node2;Req;;Type 20 request received from Scheduler@node2.supernodexp.hpc, sock=16
02/20/2018 09:19:05;0100;Server@node2;Req;;Type 51 request received from Scheduler@node2.supernodexp.hpc, sock=16
02/20/2018 09:19:05;0100;Server@node2;Req;;Type 23 request received from Scheduler@node2.supernodexp.hpc, sock=16
02/20/2018 09:19:05;0008;Server@node2;Job;3713.node2.supernodexp.hpc;Job Run at request of Scheduler@node2.supernodexp.hpc on exec_vnode (node13:ncpus=24:mem=2097152kb)
02/20/2018 09:19:05;0001;Server@node2;Svr;Server@node2;Success (0) in req_runjob2, return value of svr_startjob is 0
02/20/2018 09:19:05;0100;Server@node2;Req;;Type 11 request received from Scheduler@node2.supernodexp.hpc, sock=16
02/20/2018 09:19:05;0008;Server@node2;Job;3715.node2.supernodexp.hpc;Job Modified at request of Scheduler@node2.supernodexp.hpc
02/20/2018 09:21:08;0080;Server@node2;Job;4606.node2.supernodexp.hpc;Obit received momhop:1 serverhop:1 state:4 substate:42
02/20/2018 09:21:10;0010;Server@node2;Job;4606.node2.supernodexp.hpc;Exit_status=0 resources_used.cpupercent=784 resources_used.cput=00:49:17 resources_used.mem=1115172kb resources_used.ncpus=16 resources_used.vmem=9811968kb resources_used.walltime=00:03:21
02/20/2018 09:21:10;0100;Server@node2;Job;4606.node2.supernodexp.hpc;dequeuing from workq, state 5
02/20/2018 09:21:10;0040;Server@node2;Svr;node2.supernodexp.hpc;Scheduler sent command 2
02/20/2018 09:21:10;0040;Server@node2;Svr;node2.supernodexp.hpc;Scheduler sent command 0
02/20/2018 09:21:10;0100;Server@node2;Req;;Type 21 request received from Scheduler@node2.supernodexp.hpc, sock=16
02/20/2018 09:21:10;0100;Server@node2;Req;;Type 81 request received from Scheduler@node2.supernodexp.hpc, sock=16
02/20/2018 09:21:10;0100;Server@node2;Req;;Type 71 request received from Scheduler@node2.supernodexp.hpc, sock=16
02/20/2018 09:21:10;0100;Server@node2;Req;;Type 58 request received from Scheduler@node2.supernodexp.hpc, sock=16
02/20/2018 09:21:10;0100;Server@node2;Req;;Type 20 request received from Scheduler@node2.supernodexp.hpc, sock=16
02/20/2018 09:21:10;0100;Server@node2;Req;;Type 51 request received from Scheduler@node2.supernodexp.hpc, sock=16
02/20/2018 09:21:10;0100;Server@node2;Req;;Type 23 request received from Scheduler@node2.supernodexp.hpc, sock=16
02/20/2018 09:21:10;0008;Server@node2;Job;3715.node2.supernodexp.hpc;Job Run at request of Scheduler@node2.supernodexp.hpc on exec_vnode (node14:ncpus=24:mem=2097152kb)
02/20/2018 09:21:10;0001;Server@node2;Svr;Server@node2;Success (0) in req_runjob2, return value of svr_startjob is 0
02/20/2018 09:21:10;0100;Server@node2;Req;;Type 11 request received from Scheduler@node2.supernodexp.hpc, sock=16
02/20/2018 09:21:10;0008;Server@node2;Job;3719.node2.supernodexp.hpc;Job Modified at request of Scheduler@node2.supernodexp.hpc
02/20/2018 09:21:22;0080;Server@node2;Job;4615.node2.supernodexp.hpc;Obit received momhop:1 serverhop:1 state:4 substate:42
02/20/2018 09:21:23;0010;Server@node2;Job;4615.node2.supernodexp.hpc;Exit_status=0 resources_used.cpupercent=871 resources_used.cput=00:50:44 resources_used.mem=1115076kb resources_used.ncpus=16 resources_used.vmem=9811868kb resources_used.walltime=00:03:22
02/20/2018 09:21:23;0100;Server@node2;Job;4615.node2.supernodexp.hpc;dequeuing from workq, state 5
02/20/2018 09:21:23;0040;Server@node2;Svr;node2.supernodexp.hpc;Scheduler sent command 2
02/20/2018 09:21:23;0040;Server@node2;Svr;node2.supernodexp.hpc;Scheduler sent command 0
02/20/2018 09:21:23;0100;Server@node2;Req;;Type 21 request received from Scheduler@node2.supernodexp.hpc, sock=16
02/20/2018 09:21:23;0100;Server@node2;Req;;Type 81 request received from Scheduler@node2.supernodexp.hpc, sock=16
02/20/2018 09:21:23;0100;Server@node2;Req;;Type 71 request received from Scheduler@node2.supernodexp.hpc, sock=16
02/20/2018 09:21:23;0100;Server@node2;Req;;Type 58 request received from Scheduler@node2.supernodexp.hpc, sock=16
02/20/2018 09:21:23;0100;Server@node2;Req;;Type 20 request received from Scheduler@node2.supernodexp.hpc, sock=16
02/20/2018 09:21:23;0100;Server@node2;Req;;Type 51 request received from Scheduler@node2.supernodexp.hpc, sock=16
02/20/2018 09:21:23;0100;Server@node2;Req;;Type 23 request received from Scheduler@node2.supernodexp.hpc, sock=16
02/20/2018 09:21:23;0008;Server@node2;Job;3719.node2.supernodexp.hpc;Job Run at request of Scheduler@node2.supernodexp.hpc on exec_vnode (node14:ncpus=24:mem=2097152kb)
02/20/2018 09:21:23;0001;Server@node2;Svr;Server@node2;Success (0) in req_runjob2, return value of svr_startjob is 0
02/20/2018 09:21:23;0100;Server@node2;Req;;Type 11 request received from Scheduler@node2.supernodexp.hpc, sock=16
02/20/2018 09:21:23;0008;Server@node2;Job;3722.node2.supernodexp.hpc;Job Modified at request of Scheduler@node2.supernodexp.hpc
02/20/2018 09:22:03;0080;Server@node2;Job;3680.node2.supernodexp.hpc;Obit received momhop:1 serverhop:1 state:4 substate:42
02/20/2018 09:22:05;0010;Server@node2;Job;3680.node2.supernodexp.hpc;Exit_status=0 resources_used.cpupercent=1100 resources_used.cput=01:08:17 resources_used.mem=1641876kb resources_used.ncpus=24 resources_used.vmem=14948164kb resources_used.walltime=00:03:06
02/20/2018 09:22:05;0100;Server@node2;Job;3680.node2.supernodexp.hpc;dequeuing from workq, state 5
02/20/2018 09:22:05;0040;Server@node2;Svr;node2.supernodexp.hpc;Scheduler sent command 2
02/20/2018 09:22:05;0040;Server@node2;Svr;node2.supernodexp.hpc;Scheduler sent command 0
02/20/2018 09:22:05;0100;Server@node2;Req;;Type 21 request received from Scheduler@node2.supernodexp.hpc, sock=16
02/20/2018 09:22:05;0100;Server@node2;Req;;Type 81 request received from Scheduler@node2.supernodexp.hpc, sock=16
02/20/2018 09:22:05;0100;Server@node2;Req;;Type 71 request received from Scheduler@node2.supernodexp.hpc, sock=16
02/20/2018 09:22:05;0100;Server@node2;Req;;Type 58 request received from Scheduler@node2.supernodexp.hpc, sock=16
02/20/2018 09:22:05;0100;Server@node2;Req;;Type 20 request received from Scheduler@node2.supernodexp.hpc, sock=16
02/20/2018 09:22:05;0100;Server@node2;Req;;Type 51 request received from Scheduler@node2.supernodexp.hpc, sock=16
02/20/2018 09:22:05;0100;Server@node2;Req;;Type 23 request received from Scheduler@node2.supernodexp.hpc, sock=16
02/20/2018 09:22:05;0008;Server@node2;Job;3722.node2.supernodexp.hpc;Job Run at request of Scheduler@node2.supernodexp.hpc on exec_vnode (node13:ncpus=24:mem=2097152kb)
02/20/2018 09:22:05;0001;Server@node2;Svr;Server@node2;Success (0) in req_runjob2, return value of svr_startjob is 0
02/20/2018 09:22:05;0100;Server@node2;Req;;Type 11 request received from Scheduler@node2.supernodexp.hpc, sock=16
02/20/2018 09:22:05;0008;Server@node2;Job;3739.node2.supernodexp.hpc;Job Modified at request of Scheduler@node2.supernodexp.hpc
02/20/2018 09:22:07;0080;Server@node2;Job;3713.node2.supernodexp.hpc;Obit received momhop:1 serverhop:1 state:4 substate:42
02/20/2018 09:22:08;0010;Server@node2;Job;3713.node2.supernodexp.hpc;Exit_status=0 resources_used.cpupercent=1357 resources_used.cput=01:08:25 resources_used.mem=1642784kb resources_used.ncpus=24 resources_used.vmem=14948228kb resources_used.walltime=00:03:02
02/20/2018 09:22:08;0100;Server@node2;Job;3713.node2.supernodexp.hpc;dequeuing from workq, state 5
02/20/2018 09:22:08;0040;Server@node2;Svr;node2.supernodexp.hpc;Scheduler sent command 2
02/20/2018 09:22:08;0040;Server@node2;Svr;node2.supernodexp.hpc;Scheduler sent command 0
02/20/2018 09:22:08;0100;Server@node2;Req;;Type 21 request received from Scheduler@node2.supernodexp.hpc, sock=16
02/20/2018 09:22:08;0100;Server@node2;Req;;Type 81 request received from Scheduler@node2.supernodexp.hpc, sock=16
02/20/2018 09:22:08;0100;Server@node2;Req;;Type 71 request received from Scheduler@node2.supernodexp.hpc, sock=16
02/20/2018 09:22:08;0100;Server@node2;Req;;Type 58 request received from Scheduler@node2.supernodexp.hpc, sock=16
02/20/2018 09:22:08;0100;Server@node2;Req;;Type 20 request received from Scheduler@node2.supernodexp.hpc, sock=16
02/20/2018 09:22:08;0100;Server@node2;Req;;Type 51 request received from Scheduler@node2.supernodexp.hpc, sock=16
02/20/2018 09:22:08;0100;Server@node2;Req;;Type 23 request received from Scheduler@node2.supernodexp.hpc, sock=16
02/20/2018 09:22:08;0008;Server@node2;Job;3739.node2.supernodexp.hpc;Job Run at request of Scheduler@node2.supernodexp.hpc on exec_vnode (node13:ncpus=24:mem=2097152kb)
02/20/2018 09:22:08;0001;Server@node2;Svr;Server@node2;Success (0) in req_runjob2, return value of svr_startjob is 0
02/20/2018 09:22:08;0100;Server@node2;Req;;Type 11 request received from Scheduler@node2.supernodexp.hpc, sock=16
02/20/2018 09:22:08;0008;Server@node2;Job;3751.node2.supernodexp.hpc;Job Modified at request of Scheduler@node2.supernodexp.hpc
02/20/2018 09:22:20;0080;Server@node2;Job;3722.node2.supernodexp.hpc;Obit received momhop:1 serverhop:1 state:4 substate:42
02/20/2018 09:22:21;0010;Server@node2;Job;3722.node2.supernodexp.hpc;Exit_status=1 resources_used.cpupercent=20 resources_used.cput=00:00:03 resources_used.mem=82024kb resources_used.ncpus=24 resources_used.vmem=1073044kb resources_used.walltime=00:00:15
02/20/2018 09:22:21;0100;Server@node2;Job;3722.node2.supernodexp.hpc;dequeuing from workq, state 5
02/20/2018 09:22:21;0040;Server@node2;Svr;node2.supernodexp.hpc;Scheduler sent command 2
02/20/2018 09:22:21;0040;Server@node2;Svr;node2.supernodexp.hpc;Scheduler sent command 0
02/20/2018 09:22:21;0100;Server@node2;Req;;Type 21 request received from Scheduler@node2.supernodexp.hpc, sock=16
02/20/2018 09:22:21;0100;Server@node2;Req;;Type 81 request received from Scheduler@node2.supernodexp.hpc, sock=16
02/20/2018 09:22:21;0100;Server@node2;Req;;Type 71 request received from Scheduler@node2.supernodexp.hpc, sock=16
02/20/2018 09:22:21;0100;Server@node2;Req;;Type 58 request received from Scheduler@node2.supernodexp.hpc, sock=16
02/20/2018 09:22:21;0100;Server@node2;Req;;Type 20 request received from Scheduler@node2.supernodexp.hpc, sock=16
02/20/2018 09:22:21;0100;Server@node2;Req;;Type 51 request received from Scheduler@node2.supernodexp.hpc, sock=16
02/20/2018 09:22:21;0100;Server@node2;Req;;Type 23 request received from Scheduler@node2.supernodexp.hpc, sock=16
02/20/2018 09:22:21;0008;Server@node2;Job;3751.node2.supernodexp.hpc;Job Run at request of Scheduler@node2.supernodexp.hpc on exec_vnode (node13:ncpus=24:mem=2097152kb)
02/20/2018 09:22:21;0001;Server@node2;Svr;Server@node2;Success (0) in req_runjob2, return value of svr_startjob is 0
02/20/2018 09:22:21;0100;Server@node2;Req;;Type 11 request received from Scheduler@node2.supernodexp.hpc, sock=16
02/20/2018 09:22:21;0008;Server@node2;Job;3771.node2.supernodexp.hpc;Job Modified at request of Scheduler@node2.supernodexp.hpc
02/20/2018 09:24:15;0080;Server@node2;Job;3715.node2.supernodexp.hpc;Obit received momhop:1 serverhop:1 state:4 substate:42
02/20/2018 09:24:16;0010;Server@node2;Job;3715.node2.supernodexp.hpc;Exit_status=0 resources_used.cpupercent=1067 resources_used.cput=01:07:03 resources_used.mem=1642432kb resources_used.ncpus=24 resources_used.vmem=15000336kb resources_used.walltime=00:03:05
02/20/2018 09:24:16;0100;Server@node2;Job;3715.node2.supernodexp.hpc;dequeuing from workq, state 5
02/20/2018 09:24:16;0040;Server@node2;Svr;node2.supernodexp.hpc;Scheduler sent command 2
02/20/2018 09:24:16;0040;Server@node2;Svr;node2.supernodexp.hpc;Scheduler sent command 0
02/20/2018 09:24:16;0100;Server@node2;Req;;Type 21 request received from Scheduler@node2.supernodexp.hpc, sock=16
02/20/2018 09:24:16;0100;Server@node2;Req;;Type 81 request received from Scheduler@node2.supernodexp.hpc, sock=16
02/20/2018 09:24:16;0100;Server@node2;Req;;Type 71 request received from Scheduler@node2.supernodexp.hpc, sock=16
02/20/2018 09:24:16;0100;Server@node2;Req;;Type 58 request received from Scheduler@node2.supernodexp.hpc, sock=16
02/20/2018 09:24:16;0100;Server@node2;Req;;Type 20 request received from Scheduler@node2.supernodexp.hpc, sock=16
02/20/2018 09:24:16;0100;Server@node2;Req;;Type 51 request received from Scheduler@node2.supernodexp.hpc, sock=16
02/20/2018 09:24:17;0100;Server@node2;Req;;Type 23 request received from Scheduler@node2.supernodexp.hpc, sock=16
02/20/2018 09:24:17;0008;Server@node2;Job;3771.node2.supernodexp.hpc;Job Run at request of Scheduler@node2.supernodexp.hpc on exec_vnode (node14:ncpus=24:mem=2097152kb)
02/20/2018 09:24:17;0001;Server@node2;Svr;Server@node2;Success (0) in req_runjob2, return value of svr_startjob is 0
02/20/2018 09:24:17;0100;Server@node2;Req;;Type 11 request received from Scheduler@node2.supernodexp.hpc, sock=16
02/20/2018 09:24:17;0008;Server@node2;Job;3785.node2.supernodexp.hpc;Job Modified at request of Scheduler@node2.supernodexp.hpc
02/20/2018 09:24:24;0080;Server@node2;Job;3719.node2.supernodexp.hpc;Obit received momhop:1 serverhop:1 state:4 substate:42
02/20/2018 09:24:25;0010;Server@node2;Job;3719.node2.supernodexp.hpc;Exit_status=0 resources_used.cpupercent=1096 resources_used.cput=01:07:27 resources_used.mem=1642904kb resources_used.ncpus=24 resources_used.vmem=15000376kb resources_used.walltime=00:03:01
02/20/2018 09:24:25;0100;Server@node2;Job;3719.node2.supernodexp.hpc;dequeuing from workq, state 5
02/20/2018 09:24:25;0040;Server@node2;Svr;node2.supernodexp.hpc;Scheduler sent command 2
02/20/2018 09:24:25;0040;Server@node2;Svr;node2.supernodexp.hpc;Scheduler sent command 0
02/20/2018 09:24:25;0100;Server@node2;Req;;Type 21 request received from Scheduler@node2.supernodexp.hpc, sock=16
02/20/2018 09:24:25;0100;Server@node2;Req;;Type 81 request received from Scheduler@node2.supernodexp.hpc, sock=16
02/20/2018 09:24:25;0100;Server@node2;Req;;Type 71 request received from Scheduler@node2.supernodexp.hpc, sock=16
02/20/2018 09:24:25;0100;Server@node2;Req;;Type 58 request received from Scheduler@node2.supernodexp.hpc, sock=16
02/20/2018 09:24:25;0100;Server@node2;Req;;Type 20 request received from Scheduler@node2.supernodexp.hpc, sock=16
02/20/2018 09:24:25;0100;Server@node2;Req;;Type 51 request received from Scheduler@node2.supernodexp.hpc, sock=16
02/20/2018 09:24:25;0100;Server@node2;Req;;Type 23 request received from Scheduler@node2.supernodexp.hpc, sock=16
02/20/2018 09:24:25;0008;Server@node2;Job;3785.node2.supernodexp.hpc;Job Run at request of Scheduler@node2.supernodexp.hpc on exec_vnode (node14:ncpus=24:mem=2097152kb)
02/20/2018 09:24:25;0001;Server@node2;Svr;Server@node2;Success (0) in req_runjob2, return value of svr_startjob is 0
02/20/2018 09:24:25;0100;Server@node2;Req;;Type 11 request received from Scheduler@node2.supernodexp.hpc, sock=16
02/20/2018 09:24:25;0008;Server@node2;Job;3791.node2.supernodexp.hpc;Job Modified at request of Scheduler@node2.supernodexp.hpc
02/20/2018 09:25:14;0080;Server@node2;Job;3739.node2.supernodexp.hpc;Obit received momhop:1 serverhop:1 state:4 substate:42
02/20/2018 09:25:16;0010;Server@node2;Job;3739.node2.supernodexp.hpc;Exit_status=0 resources_used.cpupercent=1081 resources_used.cput=01:07:54 resources_used.mem=1641544kb resources_used.ncpus=24 resources_used.vmem=14948212kb resources_used.walltime=00:03:06
02/20/2018 09:25:16;0100;Server@node2;Job;3739.node2.supernodexp.hpc;dequeuing from workq, state 5
02/20/2018 09:25:16;0040;Server@node2;Svr;node2.supernodexp.hpc;Scheduler sent command 2
02/20/2018 09:25:16;0040;Server@node2;Svr;node2.supernodexp.hpc;Scheduler sent command 0
02/20/2018 09:25:16;0100;Server@node2;Req;;Type 21 request received from Scheduler@node2.supernodexp.hpc, sock=16
02/20/2018 09:25:16;0100;Server@node2;Req;;Type 81 request received from Scheduler@node2.supernodexp.hpc, sock=16
02/20/2018 09:25:16;0100;Server@node2;Req;;Type 71 request received from Scheduler@node2.supernodexp.hpc, sock=16
02/20/2018 09:25:16;0100;Server@node2;Req;;Type 58 request received from Scheduler@node2.supernodexp.hpc, sock=16
02/20/2018 09:25:16;0100;Server@node2;Req;;Type 20 request received from Scheduler@node2.supernodexp.hpc, sock=16
02/20/2018 09:25:16;0100;Server@node2;Req;;Type 51 request received from Scheduler@node2.supernodexp.hpc, sock=16
02/20/2018 09:25:16;0100;Server@node2;Req;;Type 23 request received from Scheduler@node2.supernodexp.hpc, sock=16
02/20/2018 09:25:16;0008;Server@node2;Job;3791.node2.supernodexp.hpc;Job Run at request of Scheduler@node2.supernodexp.hpc on exec_vnode (node13:ncpus=24:mem=2097152kb)
02/20/2018 09:25:16;0001;Server@node2;Svr;Server@node2;Success (0) in req_runjob2, return value of svr_startjob is 0
02/20/2018 09:25:16;0100;Server@node2;Req;;Type 11 request received from Scheduler@node2.supernodexp.hpc, sock=16
02/20/2018 09:25:16;0008;Server@node2;Job;3795.node2.supernodexp.hpc;Job Modified at request of Scheduler@node2.supernodexp.hpc
02/20/2018 09:25:24;0080;Server@node2;Job;3751.node2.supernodexp.hpc;Obit received momhop:1 serverhop:1 state:4 substate:42
02/20/2018 09:25:25;0010;Server@node2;Job;3751.node2.supernodexp.hpc;Exit_status=0 resources_used.cpupercent=1095 resources_used.cput=01:07:46 resources_used.mem=1641892kb resources_used.ncpus=24 resources_used.vmem=14948240kb resources_used.walltime=00:03:03
02/20/2018 09:25:25;0100;Server@node2;Job;3751.node2.supernodexp.hpc;dequeuing from workq, state 5
02/20/2018 09:25:25;0040;Server@node2;Svr;node2.supernodexp.hpc;Scheduler sent command 2
02/20/2018 09:25:25;0040;Server@node2;Svr;node2.supernodexp.hpc;Scheduler sent command 0
02/20/2018 09:25:25;0100;Server@node2;Req;;Type 21 request received from Scheduler@node2.supernodexp.hpc, sock=16
02/20/2018 09:25:25;0100;Server@node2;Req;;Type 81 request received from Scheduler@node2.supernodexp.hpc, sock=16
02/20/2018 09:25:25;0100;Server@node2;Req;;Type 71 request received from Scheduler@node2.supernodexp.hpc, sock=16
02/20/2018 09:25:25;0100;Server@node2;Req;;Type 58 request received from Scheduler@node2.supernodexp.hpc, sock=16
02/20/2018 09:25:25;0100;Server@node2;Req;;Type 20 request received from Scheduler@node2.supernodexp.hpc, sock=16
02/20/2018 09:25:25;0100;Server@node2;Req;;Type 51 request received from Scheduler@node2.supernodexp.hpc, sock=16
02/20/2018 09:25:25;0100;Server@node2;Req;;Type 23 request received from Scheduler@node2.supernodexp.hpc, sock=16
02/20/2018 09:25:25;0008;Server@node2;Job;3795.node2.supernodexp.hpc;Job Run at request of Scheduler@node2.supernodexp.hpc on exec_vnode (node13:ncpus=24:mem=2097152kb)
02/20/2018 09:25:25;0001;Server@node2;Svr;Server@node2;Success (0) in req_runjob2, return value of svr_startjob is 0
02/20/2018 09:25:25;0100;Server@node2;Req;;Type 11 request received from Scheduler@node2.supernodexp.hpc, sock=16
02/20/2018 09:25:25;0008;Server@node2;Job;3828.node2.supernodexp.hpc;Job Modified at request of Scheduler@node2.supernodexp.hpc
02/20/2018 09:27:20;0080;Server@node2;Job;3771.node2.supernodexp.hpc;Obit received momhop:1 serverhop:1 state:4 substate:42
02/20/2018 09:27:22;0010;Server@node2;Job;3771.node2.supernodexp.hpc;Exit_status=0 resources_used.cpupercent=1088 resources_used.cput=01:07:46 resources_used.mem=1641940kb resources_used.ncpus=24 resources_used.vmem=15000312kb resources_used.walltime=00:03:04
02/20/2018 09:27:22;0100;Server@node2;Job;3771.node2.supernodexp.hpc;dequeuing from workq, state 5
02/20/2018 09:27:22;0040;Server@node2;Svr;node2.supernodexp.hpc;Scheduler sent command 2
02/20/2018 09:27:22;0040;Server@node2;Svr;node2.supernodexp.hpc;Scheduler sent command 0
02/20/2018 09:27:22;0100;Server@node2;Req;;Type 21 request received from Scheduler@node2.supernodexp.hpc, sock=16
02/20/2018 09:27:22;0100;Server@node2;Req;;Type 81 request received from Scheduler@node2.supernodexp.hpc, sock=16
02/20/2018 09:27:22;0100;Server@node2;Req;;Type 71 request received from Scheduler@node2.supernodexp.hpc, sock=16
02/20/2018 09:27:22;0100;Server@node2;Req;;Type 58 request received from Scheduler@node2.supernodexp.hpc, sock=16
02/20/2018 09:27:22;0100;Server@node2;Req;;Type 20 request received from Scheduler@node2.supernodexp.hpc, sock=16
02/20/2018 09:27:22;0100;Server@node2;Req;;Type 51 request received from Scheduler@node2.supernodexp.hpc, sock=16
02/20/2018 09:27:22;0100;Server@node2;Req;;Type 23 request received from Scheduler@node2.supernodexp.hpc, sock=16
02/20/2018 09:27:22;0008;Server@node2;Job;3828.node2.supernodexp.hpc;Job Run at request of Scheduler@node2.supernodexp.hpc on exec_vnode (node14:ncpus=24:mem=2097152kb)
02/20/2018 09:27:22;0001;Server@node2;Svr;Server@node2;Success (0) in req_runjob2, return value of svr_startjob is 0
02/20/2018 09:27:22;0100;Server@node2;Req;;Type 11 request received from Scheduler@node2.supernodexp.hpc, sock=16
02/20/2018 09:27:22;0008;Server@node2;Job;3839.node2.supernodexp.hpc;Job Modified at request of Scheduler@node2.supernodexp.hpc
02/20/2018 09:27:25;0080;Server@node2;Job;3785.node2.supernodexp.hpc;Obit received momhop:1 serverhop:1 state:4 substate:42
02/20/2018 09:27:26;0010;Server@node2;Job;3785.node2.supernodexp.hpc;Exit_status=0 resources_used.cpupercent=1097 resources_used.cput=01:07:07 resources_used.mem=1642180kb resources_used.ncpus=24 resources_used.vmem=15000468kb resources_used.walltime=00:03:00
02/20/2018 09:27:26;0100;Server@node2;Job;3785.node2.supernodexp.hpc;dequeuing from workq, state 5
02/20/2018 09:27:26;0040;Server@node2;Svr;node2.supernodexp.hpc;Scheduler sent command 2
02/20/2018 09:27:26;0040;Server@node2;Svr;node2.supernodexp.hpc;Scheduler sent command 0
02/20/2018 09:27:26;0100;Server@node2;Req;;Type 21 request received from Scheduler@node2.supernodexp.hpc, sock=16
02/20/2018 09:27:26;0100;Server@node2;Req;;Type 81 request received from Scheduler@node2.supernodexp.hpc, sock=16
02/20/2018 09:27:26;0100;Server@node2;Req;;Type 71 request received from Scheduler@node2.supernodexp.hpc, sock=16
02/20/2018 09:27:26;0100;Server@node2;Req;;Type 58 request received from Scheduler@node2.supernodexp.hpc, sock=16
02/20/2018 09:27:26;0100;Server@node2;Req;;Type 20 request received from Scheduler@node2.supernodexp.hpc, sock=16
02/20/2018 09:27:26;0100;Server@node2;Req;;Type 51 request received from Scheduler@node2.supernodexp.hpc, sock=16
02/20/2018 09:27:26;0100;Server@node2;Req;;Type 23 request received from Scheduler@node2.supernodexp.hpc, sock=16
02/20/2018 09:27:26;0008;Server@node2;Job;3839.node2.supernodexp.hpc;Job Run at request of Scheduler@node2.supernodexp.hpc on exec_vnode (node14:ncpus=24:mem=2097152kb)
02/20/2018 09:27:26;0001;Server@node2;Svr;Server@node2;Success (0) in req_runjob2, return value of svr_startjob is 0
02/20/2018 09:27:26;0100;Server@node2;Req;;Type 11 request received from Scheduler@node2.supernodexp.hpc, sock=16
02/20/2018 09:27:26;0008;Server@node2;Job;3857.node2.supernodexp.hpc;Job Modified at request of Scheduler@node2.supernodexp.hpc
02/20/2018 09:27:37;0080;Server@node2;Job;3839.node2.supernodexp.hpc;Obit received momhop:1 serverhop:1 state:4 substate:42
02/20/2018 09:27:38;0010;Server@node2;Job;3839.node2.supernodexp.hpc;Exit_status=1 resources_used.cpupercent=29 resources_used.cput=00:00:03 resources_used.mem=82072kb resources_used.ncpus=24 resources_used.vmem=1073048kb resources_used.walltime=00:00:11
02/20/2018 09:27:38;0100;Server@node2;Job;3839.node2.supernodexp.hpc;dequeuing from workq, state 5
02/20/2018 09:27:38;0040;Server@node2;Svr;node2.supernodexp.hpc;Scheduler sent command 2
02/20/2018 09:27:38;0040;Server@node2;Svr;node2.supernodexp.hpc;Scheduler sent command 0
02/20/2018 09:27:38;0100;Server@node2;Req;;Type 21 request received from Scheduler@node2.supernodexp.hpc, sock=16
02/20/2018 09:27:38;0100;Server@node2;Req;;Type 81 request received from Scheduler@node2.supernodexp.hpc, sock=16
02/20/2018 09:27:38;0100;Server@node2;Req;;Type 71 request received from Scheduler@node2.supernodexp.hpc, sock=16
02/20/2018 09:27:38;0100;Server@node2;Req;;Type 58 request received from Scheduler@node2.supernodexp.hpc, sock=16
02/20/2018 09:27:38;0100;Server@node2;Req;;Type 20 request received from Scheduler@node2.supernodexp.hpc, sock=16
02/20/2018 09:27:38;0100;Server@node2;Req;;Type 51 request received from Scheduler@node2.supernodexp.hpc, sock=16
02/20/2018 09:27:38;0100;Server@node2;Req;;Type 23 request received from Scheduler@node2.supernodexp.hpc, sock=16
02/20/2018 09:27:38;0008;Server@node2;Job;3857.node2.supernodexp.hpc;Job Run at request of Scheduler@node2.supernodexp.hpc on exec_vnode (node14:ncpus=24:mem=2097152kb)
02/20/2018 09:27:38;0001;Server@node2;Svr;Server@node2;Success (0) in req_runjob2, return value of svr_startjob is 0
02/20/2018 09:27:38;0100;Server@node2;Req;;Type 11 request received from Scheduler@node2.supernodexp.hpc, sock=16
02/20/2018 09:27:38;0008;Server@node2;Job;3864.node2.supernodexp.hpc;Job Modified at request of Scheduler@node2.supernodexp.hpc
02/20/2018 09:28:19;0080;Server@node2;Job;3791.node2.supernodexp.hpc;Obit received momhop:1 serverhop:1 state:4 substate:42
02/20/2018 09:28:21;0010;Server@node2;Job;3791.node2.supernodexp.hpc;Exit_status=0 resources_used.cpupercent=1088 resources_used.cput=01:07:28 resources_used.mem=1642292kb resources_used.ncpus=24 resources_used.vmem=14948692kb resources_used.walltime=00:03:03
02/20/2018 09:28:21;0100;Server@node2;Job;3791.node2.supernodexp.hpc;dequeuing from workq, state 5
02/20/2018 09:28:21;0040;Server@node2;Svr;node2.supernodexp.hpc;Scheduler sent command 2
02/20/2018 09:28:21;0040;Server@node2;Svr;node2.supernodexp.hpc;Scheduler sent command 0
02/20/2018 09:28:21;0100;Server@node2;Req;;Type 21 request received from Scheduler@node2.supernodexp.hpc, sock=16
02/20/2018 09:28:21;0100;Server@node2;Req;;Type 81 request received from Scheduler@node2.supernodexp.hpc, sock=16
02/20/2018 09:28:21;0100;Server@node2;Req;;Type 71 request received from Scheduler@node2.supernodexp.hpc, sock=16
02/20/2018 09:28:21;0100;Server@node2;Req;;Type 58 request received from Scheduler@node2.supernodexp.hpc, sock=16
02/20/2018 09:28:21;0100;Server@node2;Req;;Type 20 request received from Scheduler@node2.supernodexp.hpc, sock=16
02/20/2018 09:28:21;0100;Server@node2;Req;;Type 51 request received from Scheduler@node2.supernodexp.hpc, sock=16
02/20/2018 09:28:21;0100;Server@node2;Req;;Type 23 request received from Scheduler@node2.supernodexp.hpc, sock=16
02/20/2018 09:28:21;0008;Server@node2;Job;3864.node2.supernodexp.hpc;Job Run at request of Scheduler@node2.supernodexp.hpc on exec_vnode (node13:ncpus=24:mem=2097152kb)
02/20/2018 09:28:21;0001;Server@node2;Svr;Server@node2;Success (0) in req_runjob2, return value of svr_startjob is 0
02/20/2018 09:28:21;0100;Server@node2;Req;;Type 11 request received from Scheduler@node2.supernodexp.hpc, sock=16
02/20/2018 09:28:21;0008;Server@node2;Job;3872.node2.supernodexp.hpc;Job Modified at request of Scheduler@node2.supernodexp.hpc
02/20/2018 09:28:27;0080;Server@node2;Job;3795.node2.supernodexp.hpc;Obit received momhop:1 serverhop:1 state:4 substate:42
02/20/2018 09:28:28;0010;Server@node2;Job;3795.node2.supernodexp.hpc;Exit_status=0 resources_used.cpupercent=1087 resources_used.cput=01:06:45 resources_used.mem=1643992kb resources_used.ncpus=24 resources_used.vmem=14948320kb resources_used.walltime=00:03:02
02/20/2018 09:28:28;0100;Server@node2;Job;3795.node2.supernodexp.hpc;dequeuing from workq, state 5
02/20/2018 09:28:28;0040;Server@node2;Svr;node2.supernodexp.hpc;Scheduler sent command 2
02/20/2018 09:28:28;0040;Server@node2;Svr;node2.supernodexp.hpc;Scheduler sent command 0
02/20/2018 09:28:28;0100;Server@node2;Req;;Type 21 request received from Scheduler@node2.supernodexp.hpc, sock=16
02/20/2018 09:28:28;0100;Server@node2;Req;;Type 81 request received from Scheduler@node2.supernodexp.hpc, sock=16
02/20/2018 09:28:28;0100;Server@node2;Req;;Type 71 request received from Scheduler@node2.supernodexp.hpc, sock=16
02/20/2018 09:28:28;0100;Server@node2;Req;;Type 58 request received from Scheduler@node2.supernodexp.hpc, sock=16
02/20/2018 09:28:28;0100;Server@node2;Req;;Type 20 request received from Scheduler@node2.supernodexp.hpc, sock=16
02/20/2018 09:28:28;0100;Server@node2;Req;;Type 51 request received from Scheduler@node2.supernodexp.hpc, sock=16
02/20/2018 09:28:28;0100;Server@node2;Req;;Type 23 request received from Scheduler@node2.supernodexp.hpc, sock=16
02/20/2018 09:28:28;0008;Server@node2;Job;3872.node2.supernodexp.hpc;Job Run at request of Scheduler@node2.supernodexp.hpc on exec_vnode (node13:ncpus=24:mem=2097152kb)
02/20/2018 09:28:28;0001;Server@node2;Svr;Server@node2;Success (0) in req_runjob2, return value of svr_startjob is 0
02/20/2018 09:28:28;0100;Server@node2;Req;;Type 11 request received from Scheduler@node2.supernodexp.hpc, sock=16
02/20/2018 09:28:28;0008;Server@node2;Job;3881.node2.supernodexp.hpc;Job Modified at request of Scheduler@node2.supernodexp.hpc
02/20/2018 09:30:31;0080;Server@node2;Job;3828.node2.supernodexp.hpc;Obit received momhop:1 serverhop:1 state:4 substate:42
02/20/2018 09:30:33;0010;Server@node2;Job;3828.node2.supernodexp.hpc;Exit_status=0 resources_used.cpupercent=1077 resources_used.cput=01:07:16 resources_used.mem=1642528kb resources_used.ncpus=24 resources_used.vmem=15000496kb resources_used.walltime=00:03:09
02/20/2018 09:30:33;0100;Server@node2;Job;3828.node2.supernodexp.hpc;dequeuing from workq, state 5
02/20/2018 09:30:33;0040;Server@node2;Svr;node2.supernodexp.hpc;Scheduler sent command 2
02/20/2018 09:30:33;0040;Server@node2;Svr;node2.supernodexp.hpc;Scheduler sent command 0
02/20/2018 09:30:33;0100;Server@node2;Req;;Type 21 request received from Scheduler@node2.supernodexp.hpc, sock=16
02/20/2018 09:30:33;0100;Server@node2;Req;;Type 81 request received from Scheduler@node2.supernodexp.hpc, sock=16
02/20/2018 09:30:33;0100;Server@node2;Req;;Type 71 request received from Scheduler@node2.supernodexp.hpc, sock=16
02/20/2018 09:30:33;0100;Server@node2;Req;;Type 58 request received from Scheduler@node2.supernodexp.hpc, sock=16
02/20/2018 09:30:33;0100;Server@node2;Req;;Type 20 request received from Scheduler@node2.supernodexp.hpc, sock=16
02/20/2018 09:30:33;0100;Server@node2;Req;;Type 51 request received from Scheduler@node2.supernodexp.hpc, sock=16
02/20/2018 09:30:33;0100;Server@node2;Req;;Type 23 request received from Scheduler@node2.supernodexp.hpc, sock=16
02/20/2018 09:30:33;0008;Server@node2;Job;3881.node2.supernodexp.hpc;Job Run at request of Scheduler@node2.supernodexp.hpc on exec_vnode (node14:ncpus=24:mem=2097152kb)
02/20/2018 09:30:33;0001;Server@node2;Svr;Server@node2;Success (0) in req_runjob2, return value of svr_startjob is 0
02/20/2018 09:30:33;0100;Server@node2;Req;;Type 11 request received from Scheduler@node2.supernodexp.hpc, sock=16
02/20/2018 09:30:33;0008;Server@node2;Job;3926.node2.supernodexp.hpc;Job Modified at request of Scheduler@node2.supernodexp.hpc
02/20/2018 09:30:36;0080;Server@node2;Job;3857.node2.supernodexp.hpc;Obit received momhop:1 serverhop:1 state:4 substate:42
02/20/2018 09:30:38;0010;Server@node2;Job;3857.node2.supernodexp.hpc;Exit_status=0 resources_used.cpupercent=1350 resources_used.cput=01:07:22 resources_used.mem=1642376kb resources_used.ncpus=24 resources_used.vmem=15000364kb resources_used.walltime=00:02:59
02/20/2018 09:30:38;0100;Server@node2;Job;3857.node2.supernodexp.hpc;dequeuing from workq, state 5
02/20/2018 09:30:38;0040;Server@node2;Svr;node2.supernodexp.hpc;Scheduler sent command 2
02/20/2018 09:30:38;0040;Server@node2;Svr;node2.supernodexp.hpc;Scheduler sent command 0
02/20/2018 09:30:38;0100;Server@node2;Req;;Type 21 request received from Scheduler@node2.supernodexp.hpc, sock=16
02/20/2018 09:30:38;0100;Server@node2;Req;;Type 81 request received from Scheduler@node2.supernodexp.hpc, sock=16
02/20/2018 09:30:38;0100;Server@node2;Req;;Type 71 request received from Scheduler@node2.supernodexp.hpc, sock=16
02/20/2018 09:30:38;0100;Server@node2;Req;;Type 58 request received from Scheduler@node2.supernodexp.hpc, sock=16
02/20/2018 09:30:38;0100;Server@node2;Req;;Type 20 request received from Scheduler@node2.supernodexp.hpc, sock=16
02/20/2018 09:30:38;0100;Server@node2;Req;;Type 51 request received from Scheduler@node2.supernodexp.hpc, sock=16
02/20/2018 09:30:38;0100;Server@node2;Req;;Type 23 request received from Scheduler@node2.supernodexp.hpc, sock=16
02/20/2018 09:30:38;0008;Server@node2;Job;3926.node2.supernodexp.hpc;Job Run at request of Scheduler@node2.supernodexp.hpc on exec_vnode (node14:ncpus=24:mem=2097152kb)
02/20/2018 09:30:38;0001;Server@node2;Svr;Server@node2;Success (0) in req_runjob2, return value of svr_startjob is 0
02/20/2018 09:30:38;0100;Server@node2;Req;;Type 11 request received from Scheduler@node2.supernodexp.hpc, sock=16
02/20/2018 09:30:38;0008;Server@node2;Job;3944.node2.supernodexp.hpc;Job Modified at request of Scheduler@node2.supernodexp.hpc
02/20/2018 09:31:27;0080;Server@node2;Job;3864.node2.supernodexp.hpc;Obit received momhop:1 serverhop:1 state:4 substate:42
02/20/2018 09:31:29;0010;Server@node2;Job;3864.node2.supernodexp.hpc;Exit_status=0 resources_used.cpupercent=1109 resources_used.cput=01:08:59 resources_used.mem=1642096kb resources_used.ncpus=24 resources_used.vmem=14948112kb resources_used.walltime=00:03:06
02/20/2018 09:31:29;0100;Server@node2;Job;3864.node2.supernodexp.hpc;dequeuing from workq, state 5
02/20/2018 09:31:29;0040;Server@node2;Svr;node2.supernodexp.hpc;Scheduler sent command 2
02/20/2018 09:31:29;0040;Server@node2;Svr;node2.supernodexp.hpc;Scheduler sent command 0
02/20/2018 09:31:29;0100;Server@node2;Req;;Type 21 request received from Scheduler@node2.supernodexp.hpc, sock=16
02/20/2018 09:31:29;0100;Server@node2;Req;;Type 81 request received from Scheduler@node2.supernodexp.hpc, sock=16
02/20/2018 09:31:29;0100;Server@node2;Req;;Type 71 request received from Scheduler@node2.supernodexp.hpc, sock=16
02/20/2018 09:31:29;0100;Server@node2;Req;;Type 58 request received from Scheduler@node2.supernodexp.hpc, sock=16
02/20/2018 09:31:29;0100;Server@node2;Req;;Type 20 request received from Scheduler@node2.supernodexp.hpc, sock=16
02/20/2018 09:31:29;0100;Server@node2;Req;;Type 51 request received from Scheduler@node2.supernodexp.hpc, sock=16
02/20/2018 09:31:29;0100;Server@node2;Req;;Type 23 request received from Scheduler@node2.supernodexp.hpc, sock=16
02/20/2018 09:31:29;0008;Server@node2;Job;3944.node2.supernodexp.hpc;Job Run at request of Scheduler@node2.supernodexp.hpc on exec_vnode (node13:ncpus=24:mem=2097152kb)
02/20/2018 09:31:29;0001;Server@node2;Svr;Server@node2;Success (0) in req_runjob2, return value of svr_startjob is 0
02/20/2018 09:31:29;0100;Server@node2;Req;;Type 11 request received from Scheduler@node2.supernodexp.hpc, sock=16
02/20/2018 09:31:29;0008;Server@node2;Job;3947.node2.supernodexp.hpc;Job Modified at request of Scheduler@node2.supernodexp.hpc
02/20/2018 09:31:37;0080;Server@node2;Job;3872.node2.supernodexp.hpc;Obit received momhop:1 serverhop:1 state:4 substate:42
02/20/2018 09:31:38;0010;Server@node2;Job;3872.node2.supernodexp.hpc;Exit_status=0 resources_used.cpupercent=1116 resources_used.cput=01:10:30 resources_used.mem=1644556kb resources_used.ncpus=24 resources_used.vmem=14949836kb resources_used.walltime=00:03:09
02/20/2018 09:31:38;0100;Server@node2;Job;3872.node2.supernodexp.hpc;dequeuing from workq, state 5
02/20/2018 09:31:38;0040;Server@node2;Svr;node2.supernodexp.hpc;Scheduler sent command 2
02/20/2018 09:31:38;0040;Server@node2;Svr;node2.supernodexp.hpc;Scheduler sent command 0
02/20/2018 09:31:38;0100;Server@node2;Req;;Type 21 request received from Scheduler@node2.supernodexp.hpc, sock=16
02/20/2018 09:31:38;0100;Server@node2;Req;;Type 81 request received from Scheduler@node2.supernodexp.hpc, sock=16
02/20/2018 09:31:38;0100;Server@node2;Req;;Type 71 request received from Scheduler@node2.supernodexp.hpc, sock=16
02/20/2018 09:31:38;0100;Server@node2;Req;;Type 58 request received from Scheduler@node2.supernodexp.hpc, sock=16
02/20/2018 09:31:38;0100;Server@node2;Req;;Type 20 request received from Scheduler@node2.supernodexp.hpc, sock=16
02/20/2018 09:31:38;0100;Server@node2;Req;;Type 51 request received from Scheduler@node2.supernodexp.hpc, sock=16
02/20/2018 09:31:39;0100;Server@node2;Req;;Type 23 request received from Scheduler@node2.supernodexp.hpc, sock=16
02/20/2018 09:31:39;0008;Server@node2;Job;3947.node2.supernodexp.hpc;Job Run at request of Scheduler@node2.supernodexp.hpc on exec_vnode (node13:ncpus=24:mem=2097152kb)
02/20/2018 09:31:39;0001;Server@node2;Svr;Server@node2;Success (0) in req_runjob2, return value of svr_startjob is 0
02/20/2018 09:31:39;0100;Server@node2;Req;;Type 11 request received from Scheduler@node2.supernodexp.hpc, sock=16
02/20/2018 09:31:39;0008;Server@node2;Job;3951.node2.supernodexp.hpc;Job Modified at request of Scheduler@node2.supernodexp.hpc
02/20/2018 09:33:41;0080;Server@node2;Job;3881.node2.supernodexp.hpc;Obit received momhop:1 serverhop:1 state:4 substate:42
02/20/2018 09:33:42;0080;Server@node2;Job;3926.node2.supernodexp.hpc;Obit received momhop:1 serverhop:1 state:4 substate:42
02/20/2018 09:33:42;0010;Server@node2;Job;3881.node2.supernodexp.hpc;Exit_status=0 resources_used.cpupercent=1120 resources_used.cput=01:08:27 resources_used.mem=1641996kb resources_used.ncpus=24 resources_used.vmem=15000520kb resources_used.walltime=00:03:08
02/20/2018 09:33:42;0100;Server@node2;Job;3881.node2.supernodexp.hpc;dequeuing from workq, state 5
02/20/2018 09:33:42;0040;Server@node2;Svr;node2.supernodexp.hpc;Scheduler sent command 2
02/20/2018 09:33:42;0040;Server@node2;Svr;node2.supernodexp.hpc;Scheduler sent command 0
02/20/2018 09:33:42;0100;Server@node2;Req;;Type 21 request received from Scheduler@node2.supernodexp.hpc, sock=16
02/20/2018 09:33:42;0100;Server@node2;Req;;Type 81 request received from Scheduler@node2.supernodexp.hpc, sock=16
02/20/2018 09:33:42;0100;Server@node2;Req;;Type 71 request received from Scheduler@node2.supernodexp.hpc, sock=16
02/20/2018 09:33:42;0100;Server@node2;Req;;Type 58 request received from Scheduler@node2.supernodexp.hpc, sock=16
02/20/2018 09:33:42;0100;Server@node2;Req;;Type 20 request received from Scheduler@node2.supernodexp.hpc, sock=16
02/20/2018 09:33:42;0100;Server@node2;Req;;Type 51 request received from Scheduler@node2.supernodexp.hpc, sock=16
02/20/2018 09:33:43;0100;Server@node2;Req;;Type 23 request received from Scheduler@node2.supernodexp.hpc, sock=16
02/20/2018 09:33:43;0008;Server@node2;Job;3951.node2.supernodexp.hpc;Job Run at request of Scheduler@node2.supernodexp.hpc on exec_vnode (node14:ncpus=24:mem=2097152kb)
02/20/2018 09:33:43;0001;Server@node2;Svr;Server@node2;Success (0) in req_runjob2, return value of svr_startjob is 0
02/20/2018 09:33:43;0100;Server@node2;Req;;Type 11 request received from Scheduler@node2.supernodexp.hpc, sock=16
02/20/2018 09:33:43;0008;Server@node2;Job;3973.node2.supernodexp.hpc;Job Modified at request of Scheduler@node2.supernodexp.hpc
02/20/2018 09:33:43;0010;Server@node2;Job;3926.node2.supernodexp.hpc;Exit_status=0 resources_used.cpupercent=1357 resources_used.cput=01:09:02 resources_used.mem=1641796kb resources_used.ncpus=24 resources_used.vmem=15000416kb resources_used.walltime=00:03:04
02/20/2018 09:33:43;0100;Server@node2;Job;3926.node2.supernodexp.hpc;dequeuing from workq, state 5
02/20/2018 09:33:43;0040;Server@node2;Svr;node2.supernodexp.hpc;Scheduler sent command 2
02/20/2018 09:33:43;0040;Server@node2;Svr;node2.supernodexp.hpc;Scheduler sent command 0
02/20/2018 09:33:43;0100;Server@node2;Req;;Type 21 request received from Scheduler@node2.supernodexp.hpc, sock=16
02/20/2018 09:33:43;0100;Server@node2;Req;;Type 81 request received from Scheduler@node2.supernodexp.hpc, sock=16
02/20/2018 09:33:43;0100;Server@node2;Req;;Type 71 request received from Scheduler@node2.supernodexp.hpc, sock=16
02/20/2018 09:33:43;0100;Server@node2;Req;;Type 58 request received from Scheduler@node2.supernodexp.hpc, sock=16
02/20/2018 09:33:43;0100;Server@node2;Req;;Type 20 request received from Scheduler@node2.supernodexp.hpc, sock=16
02/20/2018 09:33:43;0100;Server@node2;Req;;Type 51 request received from Scheduler@node2.supernodexp.hpc, sock=16
02/20/2018 09:33:44;0100;Server@node2;Req;;Type 23 request received from Scheduler@node2.supernodexp.hpc, sock=16
02/20/2018 09:33:44;0008;Server@node2;Job;3973.node2.supernodexp.hpc;Job Run at request of Scheduler@node2.supernodexp.hpc on exec_vnode (node14:ncpus=24:mem=2097152kb)
02/20/2018 09:33:44;0001;Server@node2;Svr;Server@node2;Success (0) in req_runjob2, return value of svr_startjob is 0
02/20/2018 09:33:44;0100;Server@node2;Req;;Type 11 request received from Scheduler@node2.supernodexp.hpc, sock=16
02/20/2018 09:33:44;0008;Server@node2;Job;4004.node2.supernodexp.hpc;Job Modified at request of Scheduler@node2.supernodexp.hpc
02/20/2018 09:33:55;0080;Server@node2;Job;3973.node2.supernodexp.hpc;Obit received momhop:1 serverhop:1 state:4 substate:42
02/20/2018 09:33:56;0010;Server@node2;Job;3973.node2.supernodexp.hpc;Exit_status=1 resources_used.cpupercent=20 resources_used.cput=00:00:03 resources_used.mem=81956kb resources_used.ncpus=24 resources_used.vmem=1073048kb resources_used.walltime=00:00:12
02/20/2018 09:33:56;0100;Server@node2;Job;3973.node2.supernodexp.hpc;dequeuing from workq, state 5
02/20/2018 09:33:56;0040;Server@node2;Svr;node2.supernodexp.hpc;Scheduler sent command 2
02/20/2018 09:33:56;0040;Server@node2;Svr;node2.supernodexp.hpc;Scheduler sent command 0
02/20/2018 09:33:56;0100;Server@node2;Req;;Type 21 request received from Scheduler@node2.supernodexp.hpc, sock=16
02/20/2018 09:33:56;0100;Server@node2;Req;;Type 81 request received from Scheduler@node2.supernodexp.hpc, sock=16
02/20/2018 09:33:56;0100;Server@node2;Req;;Type 71 request received from Scheduler@node2.supernodexp.hpc, sock=16
02/20/2018 09:33:56;0100;Server@node2;Req;;Type 58 request received from Scheduler@node2.supernodexp.hpc, sock=16
02/20/2018 09:33:57;0100;Server@node2;Req;;Type 20 request received from Scheduler@node2.supernodexp.hpc, sock=16
02/20/2018 09:33:57;0100;Server@node2;Req;;Type 51 request received from Scheduler@node2.supernodexp.hpc, sock=16
02/20/2018 09:33:57;0100;Server@node2;Req;;Type 23 request received from Scheduler@node2.supernodexp.hpc, sock=16
02/20/2018 09:33:57;0008;Server@node2;Job;4004.node2.supernodexp.hpc;Job Run at request of Scheduler@node2.supernodexp.hpc on exec_vnode (node14:ncpus=24:mem=2097152kb)
02/20/2018 09:33:57;0001;Server@node2;Svr;Server@node2;Success (0) in req_runjob2, return value of svr_startjob is 0
02/20/2018 09:33:57;0100;Server@node2;Req;;Type 11 request received from Scheduler@node2.supernodexp.hpc, sock=16
02/20/2018 09:33:57;0008;Server@node2;Job;4010.node2.supernodexp.hpc;Job Modified at request of Scheduler@node2.supernodexp.hpc
02/20/2018 09:34:33;0080;Server@node2;Job;3944.node2.supernodexp.hpc;Obit received momhop:1 serverhop:1 state:4 substate:42
02/20/2018 09:34:34;0010;Server@node2;Job;3944.node2.supernodexp.hpc;Exit_status=0 resources_used.cpupercent=1121 resources_used.cput=01:09:02 resources_used.mem=1642340kb resources_used.ncpus=24 resources_used.vmem=14948148kb resources_used.walltime=00:03:05
02/20/2018 09:34:34;0100;Server@node2;Job;3944.node2.supernodexp.hpc;dequeuing from workq, state 5
02/20/2018 09:34:34;0040;Server@node2;Svr;node2.supernodexp.hpc;Scheduler sent command 2
02/20/2018 09:34:34;0040;Server@node2;Svr;node2.supernodexp.hpc;Scheduler sent command 0
02/20/2018 09:34:34;0100;Server@node2;Req;;Type 21 request received from Scheduler@node2.supernodexp.hpc, sock=16
02/20/2018 09:34:34;0100;Server@node2;Req;;Type 81 request received from Scheduler@node2.supernodexp.hpc, sock=16
02/20/2018 09:34:34;0100;Server@node2;Req;;Type 71 request received from Scheduler@node2.supernodexp.hpc, sock=16
02/20/2018 09:34:34;0100;Server@node2;Req;;Type 58 request received from Scheduler@node2.supernodexp.hpc, sock=16
02/20/2018 09:34:34;0100;Server@node2;Req;;Type 20 request received from Scheduler@node2.supernodexp.hpc, sock=16
02/20/2018 09:34:34;0100;Server@node2;Req;;Type 51 request received from Scheduler@node2.supernodexp.hpc, sock=16
02/20/2018 09:34:35;0100;Server@node2;Req;;Type 23 request received from Scheduler@node2.supernodexp.hpc, sock=16
02/20/2018 09:34:35;0008;Server@node2;Job;4010.node2.supernodexp.hpc;Job Run at request of Scheduler@node2.supernodexp.hpc on exec_vnode (node13:ncpus=24:mem=2097152kb)
02/20/2018 09:34:35;0001;Server@node2;Svr;Server@node2;Success (0) in req_runjob2, return value of svr_startjob is 0
02/20/2018 09:34:35;0100;Server@node2;Req;;Type 11 request received from Scheduler@node2.supernodexp.hpc, sock=16
02/20/2018 09:34:35;0008;Server@node2;Job;4015.node2.supernodexp.hpc;Job Modified at request of Scheduler@node2.supernodexp.hpc
02/20/2018 09:34:38;0080;Server@node2;Job;3947.node2.supernodexp.hpc;Obit received momhop:1 serverhop:1 state:4 substate:42
02/20/2018 09:34:39;0010;Server@node2;Job;3947.node2.supernodexp.hpc;Exit_status=0 resources_used.cpupercent=1099 resources_used.cput=01:07:45 resources_used.mem=1642316kb resources_used.ncpus=24 resources_used.vmem=14948088kb resources_used.walltime=00:02:59
02/20/2018 09:34:39;0100;Server@node2;Job;3947.node2.supernodexp.hpc;dequeuing from workq, state 5
02/20/2018 09:34:39;0040;Server@node2;Svr;node2.supernodexp.hpc;Scheduler sent command 2
02/20/2018 09:34:39;0040;Server@node2;Svr;node2.supernodexp.hpc;Scheduler sent command 0
02/20/2018 09:34:39;0100;Server@node2;Req;;Type 21 request received from Scheduler@node2.supernodexp.hpc, sock=16
02/20/2018 09:34:39;0100;Server@node2;Req;;Type 81 request received from Scheduler@node2.supernodexp.hpc, sock=16
02/20/2018 09:34:39;0100;Server@node2;Req;;Type 71 request received from Scheduler@node2.supernodexp.hpc, sock=16
02/20/2018 09:34:39;0100;Server@node2;Req;;Type 58 request received from Scheduler@node2.supernodexp.hpc, sock=16
02/20/2018 09:34:39;0100;Server@node2;Req;;Type 20 request received from Scheduler@node2.supernodexp.hpc, sock=16
02/20/2018 09:34:39;0100;Server@node2;Req;;Type 51 request received from Scheduler@node2.supernodexp.hpc, sock=16
02/20/2018 09:34:39;0100;Server@node2;Req;;Type 23 request received from Scheduler@node2.supernodexp.hpc, sock=16
02/20/2018 09:34:39;0008;Server@node2;Job;4015.node2.supernodexp.hpc;Job Run at request of Scheduler@node2.supernodexp.hpc on exec_vnode (node13:ncpus=24:mem=2097152kb)
02/20/2018 09:34:39;0001;Server@node2;Svr;Server@node2;Success (0) in req_runjob2, return value of svr_startjob is 0
02/20/2018 09:34:39;0100;Server@node2;Req;;Type 11 request received from Scheduler@node2.supernodexp.hpc, sock=16
02/20/2018 09:34:39;0008;Server@node2;Job;4025.node2.supernodexp.hpc;Job Modified at request of Scheduler@node2.supernodexp.hpc
02/20/2018 09:36:53;0080;Server@node2;Job;3951.node2.supernodexp.hpc;Obit received momhop:1 serverhop:1 state:4 substate:42
02/20/2018 09:36:55;0010;Server@node2;Job;3951.node2.supernodexp.hpc;Exit_status=0 resources_used.cpupercent=1075 resources_used.cput=01:07:38 resources_used.mem=1641852kb resources_used.ncpus=24 resources_used.vmem=15000580kb resources_used.walltime=00:03:10
02/20/2018 09:36:55;0100;Server@node2;Job;3951.node2.supernodexp.hpc;dequeuing from workq, state 5
02/20/2018 09:36:55;0040;Server@node2;Svr;node2.supernodexp.hpc;Scheduler sent command 2
02/20/2018 09:36:55;0040;Server@node2;Svr;node2.supernodexp.hpc;Scheduler sent command 0
02/20/2018 09:36:55;0100;Server@node2;Req;;Type 21 request received from Scheduler@node2.supernodexp.hpc, sock=16
02/20/2018 09:36:55;0100;Server@node2;Req;;Type 81 request received from Scheduler@node2.supernodexp.hpc, sock=16
02/20/2018 09:36:55;0100;Server@node2;Req;;Type 71 request received from Scheduler@node2.supernodexp.hpc, sock=16
02/20/2018 09:36:55;0100;Server@node2;Req;;Type 58 request received from Scheduler@node2.supernodexp.hpc, sock=16
02/20/2018 09:36:55;0100;Server@node2;Req;;Type 20 request received from Scheduler@node2.supernodexp.hpc, sock=16
02/20/2018 09:36:55;0100;Server@node2;Req;;Type 51 request received from Scheduler@node2.supernodexp.hpc, sock=16
02/20/2018 09:36:55;0100;Server@node2;Req;;Type 23 request received from Scheduler@node2.supernodexp.hpc, sock=16
02/20/2018 09:36:55;0008;Server@node2;Job;4025.node2.supernodexp.hpc;Job Run at request of Scheduler@node2.supernodexp.hpc on exec_vnode (node14:ncpus=24:mem=2097152kb)
02/20/2018 09:36:55;0001;Server@node2;Svr;Server@node2;Success (0) in req_runjob2, return value of svr_startjob is 0
02/20/2018 09:36:55;0100;Server@node2;Req;;Type 11 request received from Scheduler@node2.supernodexp.hpc, sock=16
02/20/2018 09:36:55;0008;Server@node2;Job;4058.node2.supernodexp.hpc;Job Modified at request of Scheduler@node2.supernodexp.hpc
02/20/2018 09:36:57;0080;Server@node2;Job;4004.node2.supernodexp.hpc;Obit received momhop:1 serverhop:1 state:4 substate:42
02/20/2018 09:36:58;0010;Server@node2;Job;4004.node2.supernodexp.hpc;Exit_status=0 resources_used.cpupercent=1088 resources_used.cput=01:07:17 resources_used.mem=1642272kb resources_used.ncpus=24 resources_used.vmem=15000412kb resources_used.walltime=00:03:00
02/20/2018 09:36:58;0100;Server@node2;Job;4004.node2.supernodexp.hpc;dequeuing from workq, state 5
02/20/2018 09:36:58;0040;Server@node2;Svr;node2.supernodexp.hpc;Scheduler sent command 2
02/20/2018 09:36:58;0040;Server@node2;Svr;node2.supernodexp.hpc;Scheduler sent command 0
02/20/2018 09:36:58;0100;Server@node2;Req;;Type 21 request received from Scheduler@node2.supernodexp.hpc, sock=16
02/20/2018 09:36:58;0100;Server@node2;Req;;Type 81 request received from Scheduler@node2.supernodexp.hpc, sock=16
02/20/2018 09:36:58;0100;Server@node2;Req;;Type 71 request received from Scheduler@node2.supernodexp.hpc, sock=16
02/20/2018 09:36:58;0100;Server@node2;Req;;Type 58 request received from Scheduler@node2.supernodexp.hpc, sock=16
02/20/2018 09:36:58;0100;Server@node2;Req;;Type 20 request received from Scheduler@node2.supernodexp.hpc, sock=16
02/20/2018 09:36:58;0100;Server@node2;Req;;Type 51 request received from Scheduler@node2.supernodexp.hpc, sock=16
02/20/2018 09:36:58;0100;Server@node2;Req;;Type 23 request received from Scheduler@node2.supernodexp.hpc, sock=16
02/20/2018 09:36:58;0008;Server@node2;Job;4058.node2.supernodexp.hpc;Job Run at request of Scheduler@node2.supernodexp.hpc on exec_vnode (node14:ncpus=24:mem=2097152kb)
02/20/2018 09:36:58;0001;Server@node2;Svr;Server@node2;Success (0) in req_runjob2, return value of svr_startjob is 0
02/20/2018 09:36:58;0100;Server@node2;Req;;Type 11 request received from Scheduler@node2.supernodexp.hpc, sock=16
02/20/2018 09:36:58;0008;Server@node2;Job;4098.node2.supernodexp.hpc;Job Modified at request of Scheduler@node2.supernodexp.hpc
02/20/2018 09:37:01;0080;Server@node2;Job;4025.node2.supernodexp.hpc;Obit received momhop:1 serverhop:1 state:4 substate:42
02/20/2018 09:37:02;0010;Server@node2;Job;4025.node2.supernodexp.hpc;Exit_status=1 resources_used.cpupercent=66 resources_used.cput=00:00:02 resources_used.mem=34132kb resources_used.ncpus=24 resources_used.vmem=647132kb resources_used.walltime=00:00:06
02/20/2018 09:37:02;0100;Server@node2;Job;4025.node2.supernodexp.hpc;dequeuing from workq, state 5
02/20/2018 09:37:02;0040;Server@node2;Svr;node2.supernodexp.hpc;Scheduler sent command 2
02/20/2018 09:37:02;0040;Server@node2;Svr;node2.supernodexp.hpc;Scheduler sent command 0
02/20/2018 09:37:02;0100;Server@node2;Req;;Type 21 request received from Scheduler@node2.supernodexp.hpc, sock=16
02/20/2018 09:37:02;0100;Server@node2;Req;;Type 81 request received from Scheduler@node2.supernodexp.hpc, sock=16
02/20/2018 09:37:02;0100;Server@node2;Req;;Type 71 request received from Scheduler@node2.supernodexp.hpc, sock=16
02/20/2018 09:37:02;0100;Server@node2;Req;;Type 58 request received from Scheduler@node2.supernodexp.hpc, sock=16
02/20/2018 09:37:02;0100;Server@node2;Req;;Type 20 request received from Scheduler@node2.supernodexp.hpc, sock=16
02/20/2018 09:37:02;0100;Server@node2;Req;;Type 51 request received from Scheduler@node2.supernodexp.hpc, sock=16
02/20/2018 09:37:02;0100;Server@node2;Req;;Type 23 request received from Scheduler@node2.supernodexp.hpc, sock=16
02/20/2018 09:37:02;0008;Server@node2;Job;4098.node2.supernodexp.hpc;Job Run at request of Scheduler@node2.supernodexp.hpc on exec_vnode (node14:ncpus=24:mem=2097152kb)
02/20/2018 09:37:02;0001;Server@node2;Svr;Server@node2;Success (0) in req_runjob2, return value of svr_startjob is 0
02/20/2018 09:37:02;0100;Server@node2;Req;;Type 11 request received from Scheduler@node2.supernodexp.hpc, sock=16
02/20/2018 09:37:02;0008;Server@node2;Job;4121.node2.supernodexp.hpc;Job Modified at request of Scheduler@node2.supernodexp.hpc
02/20/2018 09:37:37;0080;Server@node2;Job;4010.node2.supernodexp.hpc;Obit received momhop:1 serverhop:1 state:4 substate:42
02/20/2018 09:37:38;0010;Server@node2;Job;4010.node2.supernodexp.hpc;Exit_status=0 resources_used.cpupercent=1126 resources_used.cput=01:08:48 resources_used.mem=1641856kb resources_used.ncpus=24 resources_used.vmem=14948084kb resources_used.walltime=00:03:03
02/20/2018 09:37:38;0100;Server@node2;Job;4010.node2.supernodexp.hpc;dequeuing from workq, state 5
02/20/2018 09:37:38;0040;Server@node2;Svr;node2.supernodexp.hpc;Scheduler sent command 2
02/20/2018 09:37:38;0040;Server@node2;Svr;node2.supernodexp.hpc;Scheduler sent command 0
02/20/2018 09:37:38;0100;Server@node2;Req;;Type 21 request received from Scheduler@node2.supernodexp.hpc, sock=16
02/20/2018 09:37:38;0100;Server@node2;Req;;Type 81 request received from Scheduler@node2.supernodexp.hpc, sock=16
02/20/2018 09:37:38;0100;Server@node2;Req;;Type 71 request received from Scheduler@node2.supernodexp.hpc, sock=16
02/20/2018 09:37:38;0100;Server@node2;Req;;Type 58 request received from Scheduler@node2.supernodexp.hpc, sock=16
02/20/2018 09:37:38;0100;Server@node2;Req;;Type 20 request received from Scheduler@node2.supernodexp.hpc, sock=16
02/20/2018 09:37:38;0100;Server@node2;Req;;Type 51 request received from Scheduler@node2.supernodexp.hpc, sock=16
02/20/2018 09:37:39;0100;Server@node2;Req;;Type 23 request received from Scheduler@node2.supernodexp.hpc, sock=16
02/20/2018 09:37:39;0008;Server@node2;Job;4121.node2.supernodexp.hpc;Job Run at request of Scheduler@node2.supernodexp.hpc on exec_vnode (node13:ncpus=24:mem=2097152kb)
02/20/2018 09:37:39;0001;Server@node2;Svr;Server@node2;Success (0) in req_runjob2, return value of svr_startjob is 0
02/20/2018 09:37:39;0100;Server@node2;Req;;Type 11 request received from Scheduler@node2.supernodexp.hpc, sock=16
02/20/2018 09:37:39;0008;Server@node2;Job;4144.node2.supernodexp.hpc;Job Modified at request of Scheduler@node2.supernodexp.hpc
02/20/2018 09:37:41;0080;Server@node2;Job;4015.node2.supernodexp.hpc;Obit received momhop:1 serverhop:1 state:4 substate:42
02/20/2018 09:37:42;0010;Server@node2;Job;4015.node2.supernodexp.hpc;Exit_status=0 resources_used.cpupercent=1318 resources_used.cput=01:07:56 resources_used.mem=1642220kb resources_used.ncpus=24 resources_used.vmem=14948168kb resources_used.walltime=00:03:02
02/20/2018 09:37:42;0100;Server@node2;Job;4015.node2.supernodexp.hpc;dequeuing from workq, state 5
02/20/2018 09:37:42;0040;Server@node2;Svr;node2.supernodexp.hpc;Scheduler sent command 2
02/20/2018 09:37:42;0040;Server@node2;Svr;node2.supernodexp.hpc;Scheduler sent command 0
02/20/2018 09:37:42;0100;Server@node2;Req;;Type 21 request received from Scheduler@node2.supernodexp.hpc, sock=16
02/20/2018 09:37:42;0100;Server@node2;Req;;Type 81 request received from Scheduler@node2.supernodexp.hpc, sock=16
02/20/2018 09:37:42;0100;Server@node2;Req;;Type 71 request received from Scheduler@node2.supernodexp.hpc, sock=16
02/20/2018 09:37:42;0100;Server@node2;Req;;Type 58 request received from Scheduler@node2.supernodexp.hpc, sock=16
02/20/2018 09:37:42;0100;Server@node2;Req;;Type 20 request received from Scheduler@node2.supernodexp.hpc, sock=16
02/20/2018 09:37:42;0100;Server@node2;Req;;Type 51 request received from Scheduler@node2.supernodexp.hpc, sock=16
02/20/2018 09:37:42;0100;Server@node2;Req;;Type 23 request received from Scheduler@node2.supernodexp.hpc, sock=16
02/20/2018 09:37:42;0008;Server@node2;Job;4144.node2.supernodexp.hpc;Job Run at request of Scheduler@node2.supernodexp.hpc on exec_vnode (node13:ncpus=24:mem=2097152kb)
02/20/2018 09:37:42;0001;Server@node2;Svr;Server@node2;Success (0) in req_runjob2, return value of svr_startjob is 0
02/20/2018 09:37:42;0100;Server@node2;Req;;Type 11 request received from Scheduler@node2.supernodexp.hpc, sock=16
02/20/2018 09:37:42;0008;Server@node2;Job;4145.node2.supernodexp.hpc;Job Modified at request of Scheduler@node2.supernodexp.hpc
02/20/2018 09:39:58;0080;Server@node2;Job;4058.node2.supernodexp.hpc;Obit received momhop:1 serverhop:1 state:4 substate:42
02/20/2018 09:40:00;0010;Server@node2;Job;4058.node2.supernodexp.hpc;Exit_status=0 resources_used.cpupercent=1128 resources_used.cput=01:07:57 resources_used.mem=1642332kb resources_used.ncpus=24 resources_used.vmem=15000424kb resources_used.walltime=00:03:00
02/20/2018 09:40:00;0100;Server@node2;Job;4058.node2.supernodexp.hpc;dequeuing from workq, state 5
02/20/2018 09:40:00;0040;Server@node2;Svr;node2.supernodexp.hpc;Scheduler sent command 2
02/20/2018 09:40:00;0040;Server@node2;Svr;node2.supernodexp.hpc;Scheduler sent command 0
02/20/2018 09:40:00;0100;Server@node2;Req;;Type 21 request received from Scheduler@node2.supernodexp.hpc, sock=16
02/20/2018 09:40:00;0100;Server@node2;Req;;Type 81 request received from Scheduler@node2.supernodexp.hpc, sock=16
02/20/2018 09:40:00;0100;Server@node2;Req;;Type 71 request received from Scheduler@node2.supernodexp.hpc, sock=16
02/20/2018 09:40:00;0100;Server@node2;Req;;Type 58 request received from Scheduler@node2.supernodexp.hpc, sock=16
02/20/2018 09:40:00;0100;Server@node2;Req;;Type 20 request received from Scheduler@node2.supernodexp.hpc, sock=16
02/20/2018 09:40:00;0100;Server@node2;Req;;Type 51 request received from Scheduler@node2.supernodexp.hpc, sock=16
02/20/2018 09:40:00;0100;Server@node2;Req;;Type 23 request received from Scheduler@node2.supernodexp.hpc, sock=16
02/20/2018 09:40:00;0008;Server@node2;Job;4145.node2.supernodexp.hpc;Job Run at request of Scheduler@node2.supernodexp.hpc on exec_vnode (node14:ncpus=24:mem=2097152kb)
02/20/2018 09:40:00;0001;Server@node2;Svr;Server@node2;Success (0) in req_runjob2, return value of svr_startjob is 0
02/20/2018 09:40:00;0100;Server@node2;Req;;Type 11 request received from Scheduler@node2.supernodexp.hpc, sock=16
02/20/2018 09:40:00;0008;Server@node2;Job;4154.node2.supernodexp.hpc;Job Modified at request of Scheduler@node2.supernodexp.hpc
02/20/2018 09:40:01;0080;Server@node2;Job;4098.node2.supernodexp.hpc;Obit received momhop:1 serverhop:1 state:4 substate:42
02/20/2018 09:40:02;0010;Server@node2;Job;4098.node2.supernodexp.hpc;Exit_status=0 resources_used.cpupercent=1350 resources_used.cput=01:07:47 resources_used.mem=1642468kb resources_used.ncpus=24 resources_used.vmem=15000496kb resources_used.walltime=00:02:59
02/20/2018 09:40:02;0100;Server@node2;Job;4098.node2.supernodexp.hpc;dequeuing from workq, state 5
02/20/2018 09:40:02;0040;Server@node2;Svr;node2.supernodexp.hpc;Scheduler sent command 2
02/20/2018 09:40:02;0040;Server@node2;Svr;node2.supernodexp.hpc;Scheduler sent command 0
02/20/2018 09:40:02;0100;Server@node2;Req;;Type 21 request received from Scheduler@node2.supernodexp.hpc, sock=16
02/20/2018 09:40:02;0100;Server@node2;Req;;Type 81 request received from Scheduler@node2.supernodexp.hpc, sock=16
02/20/2018 09:40:02;0100;Server@node2;Req;;Type 71 request received from Scheduler@node2.supernodexp.hpc, sock=16
02/20/2018 09:40:02;0100;Server@node2;Req;;Type 58 request received from Scheduler@node2.supernodexp.hpc, sock=16
02/20/2018 09:40:02;0100;Server@node2;Req;;Type 20 request received from Scheduler@node2.supernodexp.hpc, sock=16
02/20/2018 09:40:02;0100;Server@node2;Req;;Type 51 request received from Scheduler@node2.supernodexp.hpc, sock=16
02/20/2018 09:40:02;0100;Server@node2;Req;;Type 23 request received from Scheduler@node2.supernodexp.hpc, sock=16
02/20/2018 09:40:02;0008;Server@node2;Job;4154.node2.supernodexp.hpc;Job Run at request of Scheduler@node2.supernodexp.hpc on exec_vnode (node14:ncpus=24:mem=2097152kb)
02/20/2018 09:40:02;0001;Server@node2;Svr;Server@node2;Success (0) in req_runjob2, return value of svr_startjob is 0
02/20/2018 09:40:02;0100;Server@node2;Req;;Type 11 request received from Scheduler@node2.supernodexp.hpc, sock=16
02/20/2018 09:40:02;0008;Server@node2;Job;4156.node2.supernodexp.hpc;Job Modified at request of Scheduler@node2.supernodexp.hpc
02/20/2018 09:40:47;0080;Server@node2;Job;4121.node2.supernodexp.hpc;Obit received momhop:1 serverhop:1 state:4 substate:42
02/20/2018 09:40:47;0080;Server@node2;Job;4144.node2.supernodexp.hpc;Obit received momhop:1 serverhop:1 state:4 substate:42
02/20/2018 09:40:49;0010;Server@node2;Job;4121.node2.supernodexp.hpc;Exit_status=0 resources_used.cpupercent=1132 resources_used.cput=01:09:33 resources_used.mem=1642540kb resources_used.ncpus=24 resources_used.vmem=14948276kb resources_used.walltime=00:03:09
02/20/2018 09:40:49;0100;Server@node2;Job;4121.node2.supernodexp.hpc;dequeuing from workq, state 5
02/20/2018 09:40:49;0010;Server@node2;Job;4144.node2.supernodexp.hpc;Exit_status=0 resources_used.cpupercent=1348 resources_used.cput=01:09:06 resources_used.mem=1642200kb resources_used.ncpus=24 resources_used.vmem=14948096kb resources_used.walltime=00:03:05
02/20/2018 09:40:49;0100;Server@node2;Job;4144.node2.supernodexp.hpc;dequeuing from workq, state 5
02/20/2018 09:40:49;0040;Server@node2;Svr;node2.supernodexp.hpc;Scheduler sent command 2
02/20/2018 09:40:49;0040;Server@node2;Svr;node2.supernodexp.hpc;Scheduler sent command 0
02/20/2018 09:40:49;0100;Server@node2;Req;;Type 21 request received from Scheduler@node2.supernodexp.hpc, sock=16
02/20/2018 09:40:49;0100;Server@node2;Req;;Type 81 request received from Scheduler@node2.supernodexp.hpc, sock=16
02/20/2018 09:40:49;0100;Server@node2;Req;;Type 71 request received from Scheduler@node2.supernodexp.hpc, sock=16
02/20/2018 09:40:49;0100;Server@node2;Req;;Type 58 request received from Scheduler@node2.supernodexp.hpc, sock=16
02/20/2018 09:40:49;0100;Server@node2;Req;;Type 20 request received from Scheduler@node2.supernodexp.hpc, sock=16
02/20/2018 09:40:49;0100;Server@node2;Req;;Type 51 request received from Scheduler@node2.supernodexp.hpc, sock=16
02/20/2018 09:40:49;0100;Server@node2;Req;;Type 23 request received from Scheduler@node2.supernodexp.hpc, sock=16
02/20/2018 09:40:49;0008;Server@node2;Job;4156.node2.supernodexp.hpc;Job Run at request of Scheduler@node2.supernodexp.hpc on exec_vnode (node13:ncpus=24:mem=2097152kb)
02/20/2018 09:40:49;0001;Server@node2;Svr;Server@node2;Success (0) in req_runjob2, return value of svr_startjob is 0
02/20/2018 09:40:49;0100;Server@node2;Req;;Type 23 request received from Scheduler@node2.supernodexp.hpc, sock=16
02/20/2018 09:40:49;0008;Server@node2;Job;4162.node2.supernodexp.hpc;Job Run at request of Scheduler@node2.supernodexp.hpc on exec_vnode (node13:ncpus=24:mem=2097152kb)
02/20/2018 09:40:49;0001;Server@node2;Svr;Server@node2;Success (0) in req_runjob2, return value of svr_startjob is 0
02/20/2018 09:40:49;0100;Server@node2;Req;;Type 11 request received from Scheduler@node2.supernodexp.hpc, sock=16
02/20/2018 09:40:49;0008;Server@node2;Job;4163.node2.supernodexp.hpc;Job Modified at request of Scheduler@node2.supernodexp.hpc
02/20/2018 09:41:03;0080;Server@node2;Job;4156.node2.supernodexp.hpc;Obit received momhop:1 serverhop:1 state:4 substate:42
02/20/2018 09:41:05;0010;Server@node2;Job;4156.node2.supernodexp.hpc;Exit_status=1 resources_used.cpupercent=20 resources_used.cput=00:00:03 resources_used.mem=82024kb resources_used.ncpus=24 resources_used.vmem=1073008kb resources_used.walltime=00:00:14
02/20/2018 09:41:05;0100;Server@node2;Job;4156.node2.supernodexp.hpc;dequeuing from workq, state 5
02/20/2018 09:41:05;0040;Server@node2;Svr;node2.supernodexp.hpc;Scheduler sent command 2
02/20/2018 09:41:05;0040;Server@node2;Svr;node2.supernodexp.hpc;Scheduler sent command 0
02/20/2018 09:41:05;0100;Server@node2;Req;;Type 21 request received from Scheduler@node2.supernodexp.hpc, sock=16
02/20/2018 09:41:05;0100;Server@node2;Req;;Type 81 request received from Scheduler@node2.supernodexp.hpc, sock=16
02/20/2018 09:41:05;0100;Server@node2;Req;;Type 71 request received from Scheduler@node2.supernodexp.hpc, sock=16
02/20/2018 09:41:05;0100;Server@node2;Req;;Type 58 request received from Scheduler@node2.supernodexp.hpc, sock=16
02/20/2018 09:41:05;0100;Server@node2;Req;;Type 20 request received from Scheduler@node2.supernodexp.hpc, sock=16
02/20/2018 09:41:05;0100;Server@node2;Req;;Type 51 request received from Scheduler@node2.supernodexp.hpc, sock=16
02/20/2018 09:41:05;0100;Server@node2;Req;;Type 23 request received from Scheduler@node2.supernodexp.hpc, sock=16
02/20/2018 09:41:05;0008;Server@node2;Job;4163.node2.supernodexp.hpc;Job Run at request of Scheduler@node2.supernodexp.hpc on exec_vnode (node13:ncpus=24:mem=2097152kb)
02/20/2018 09:41:05;0001;Server@node2;Svr;Server@node2;Success (0) in req_runjob2, return value of svr_startjob is 0
02/20/2018 09:41:05;0100;Server@node2;Req;;Type 11 request received from Scheduler@node2.supernodexp.hpc, sock=16
02/20/2018 09:41:05;0008;Server@node2;Job;4167.node2.supernodexp.hpc;Job Modified at request of Scheduler@node2.supernodexp.hpc
02/20/2018 09:42:59;0080;Server@node2;Job;4145.node2.supernodexp.hpc;Obit received momhop:1 serverhop:1 state:4 substate:42
02/20/2018 09:43:03;0080;Server@node2;Job;4154.node2.supernodexp.hpc;Obit received momhop:1 serverhop:1 state:4 substate:42
02/20/2018 09:43:05;0010;Server@node2;Job;4154.node2.supernodexp.hpc;Exit_status=0 resources_used.cpupercent=1487 resources_used.cput=01:08:32 resources_used.mem=1643628kb resources_used.ncpus=24 resources_used.vmem=15001396kb resources_used.walltime=00:03:01
02/20/2018 09:43:05;0100;Server@node2;Job;4154.node2.supernodexp.hpc;dequeuing from workq, state 5
02/20/2018 09:43:05;0040;Server@node2;Svr;node2.supernodexp.hpc;Scheduler sent command 2
02/20/2018 09:43:05;0040;Server@node2;Svr;node2.supernodexp.hpc;Scheduler sent command 0
02/20/2018 09:43:05;0100;Server@node2;Req;;Type 21 request received from Scheduler@node2.supernodexp.hpc, sock=16
02/20/2018 09:43:05;0100;Server@node2;Req;;Type 81 request received from Scheduler@node2.supernodexp.hpc, sock=16
02/20/2018 09:43:05;0100;Server@node2;Req;;Type 71 request received from Scheduler@node2.supernodexp.hpc, sock=16
02/20/2018 09:43:05;0100;Server@node2;Req;;Type 58 request received from Scheduler@node2.supernodexp.hpc, sock=16
02/20/2018 09:43:05;0100;Server@node2;Req;;Type 20 request received from Scheduler@node2.supernodexp.hpc, sock=16
02/20/2018 09:43:05;0100;Server@node2;Req;;Type 51 request received from Scheduler@node2.supernodexp.hpc, sock=16
02/20/2018 09:43:05;0100;Server@node2;Req;;Type 23 request received from Scheduler@node2.supernodexp.hpc, sock=16
02/20/2018 09:43:05;0008;Server@node2;Job;4167.node2.supernodexp.hpc;Job Run at request of Scheduler@node2.supernodexp.hpc on exec_vnode (node14:ncpus=24:mem=2097152kb)
02/20/2018 09:43:05;0001;Server@node2;Svr;Server@node2;Success (0) in req_runjob2, return value of svr_startjob is 0
02/20/2018 09:43:05;0100;Server@node2;Req;;Type 11 request received from Scheduler@node2.supernodexp.hpc, sock=16
02/20/2018 09:43:05;0008;Server@node2;Job;4176.node2.supernodexp.hpc;Job Modified at request of Scheduler@node2.supernodexp.hpc
02/20/2018 09:43:06;0010;Server@node2;Job;4145.node2.supernodexp.hpc;Exit_status=0 resources_used.cpupercent=1125 resources_used.cput=01:08:01 resources_used.mem=1641852kb resources_used.ncpus=24 resources_used.vmem=15000504kb resources_used.walltime=00:02:59
02/20/2018 09:43:06;0100;Server@node2;Job;4145.node2.supernodexp.hpc;dequeuing from workq, state 5
02/20/2018 09:43:06;0040;Server@node2;Svr;node2.supernodexp.hpc;Scheduler sent command 2
02/20/2018 09:43:06;0040;Server@node2;Svr;node2.supernodexp.hpc;Scheduler sent command 0
02/20/2018 09:43:06;0100;Server@node2;Req;;Type 21 request received from Scheduler@node2.supernodexp.hpc, sock=16
02/20/2018 09:43:06;0100;Server@node2;Req;;Type 81 request received from Scheduler@node2.supernodexp.hpc, sock=16
02/20/2018 09:43:06;0100;Server@node2;Req;;Type 71 request received from Scheduler@node2.supernodexp.hpc, sock=16
02/20/2018 09:43:06;0100;Server@node2;Req;;Type 58 request received from Scheduler@node2.supernodexp.hpc, sock=16
02/20/2018 09:43:06;0100;Server@node2;Req;;Type 20 request received from Scheduler@node2.supernodexp.hpc, sock=16
02/20/2018 09:43:06;0100;Server@node2;Req;;Type 51 request received from Scheduler@node2.supernodexp.hpc, sock=16
02/20/2018 09:43:06;0100;Server@node2;Req;;Type 23 request received from Scheduler@node2.supernodexp.hpc, sock=16
02/20/2018 09:43:06;0008;Server@node2;Job;4176.node2.supernodexp.hpc;Job Run at request of Scheduler@node2.supernodexp.hpc on exec_vnode (node14:ncpus=24:mem=2097152kb)
02/20/2018 09:43:06;0001;Server@node2;Svr;Server@node2;Success (0) in req_runjob2, return value of svr_startjob is 0
02/20/2018 09:43:06;0100;Server@node2;Req;;Type 11 request received from Scheduler@node2.supernodexp.hpc, sock=16
02/20/2018 09:43:06;0008;Server@node2;Job;4207.node2.supernodexp.hpc;Job Modified at request of Scheduler@node2.supernodexp.hpc
02/20/2018 09:44:00;0080;Server@node2;Job;4162.node2.supernodexp.hpc;Obit received momhop:1 serverhop:1 state:4 substate:42
02/20/2018 09:44:02;0010;Server@node2;Job;4162.node2.supernodexp.hpc;Exit_status=0 resources_used.cpupercent=1073 resources_used.cput=01:07:42 resources_used.mem=1641924kb resources_used.ncpus=24 resources_used.vmem=14948332kb resources_used.walltime=00:03:11
02/20/2018 09:44:02;0100;Server@node2;Job;4162.node2.supernodexp.hpc;dequeuing from workq, state 5
02/20/2018 09:44:02;0040;Server@node2;Svr;node2.supernodexp.hpc;Scheduler sent command 2
02/20/2018 09:44:02;0040;Server@node2;Svr;node2.supernodexp.hpc;Scheduler sent command 0
02/20/2018 09:44:02;0100;Server@node2;Req;;Type 21 request received from Scheduler@node2.supernodexp.hpc, sock=16
02/20/2018 09:44:02;0100;Server@node2;Req;;Type 81 request received from Scheduler@node2.supernodexp.hpc, sock=16
02/20/2018 09:44:02;0100;Server@node2;Req;;Type 71 request received from Scheduler@node2.supernodexp.hpc, sock=16
02/20/2018 09:44:02;0100;Server@node2;Req;;Type 58 request received from Scheduler@node2.supernodexp.hpc, sock=16
02/20/2018 09:44:02;0100;Server@node2;Req;;Type 20 request received from Scheduler@node2.supernodexp.hpc, sock=16
02/20/2018 09:44:02;0100;Server@node2;Req;;Type 51 request received from Scheduler@node2.supernodexp.hpc, sock=16
02/20/2018 09:44:02;0100;Server@node2;Req;;Type 23 request received from Scheduler@node2.supernodexp.hpc, sock=16
02/20/2018 09:44:02;0008;Server@node2;Job;4207.node2.supernodexp.hpc;Job Run at request of Scheduler@node2.supernodexp.hpc on exec_vnode (node13:ncpus=24:mem=2097152kb)
02/20/2018 09:44:02;0001;Server@node2;Svr;Server@node2;Success (0) in req_runjob2, return value of svr_startjob is 0
02/20/2018 09:44:02;0100;Server@node2;Req;;Type 11 request received from Scheduler@node2.supernodexp.hpc, sock=16
02/20/2018 09:44:02;0008;Server@node2;Job;4213.node2.supernodexp.hpc;Job Modified at request of Scheduler@node2.supernodexp.hpc
02/20/2018 09:44:08;0080;Server@node2;Job;4163.node2.supernodexp.hpc;Obit received momhop:1 serverhop:1 state:4 substate:42
02/20/2018 09:44:09;0010;Server@node2;Job;4163.node2.supernodexp.hpc;Exit_status=0 resources_used.cpupercent=1095 resources_used.cput=01:07:41 resources_used.mem=1643676kb resources_used.ncpus=24 resources_used.vmem=14949768kb resources_used.walltime=00:03:03
02/20/2018 09:44:09;0100;Server@node2;Job;4163.node2.supernodexp.hpc;dequeuing from workq, state 5
02/20/2018 09:44:09;0040;Server@node2;Svr;node2.supernodexp.hpc;Scheduler sent command 2
02/20/2018 09:44:09;0040;Server@node2;Svr;node2.supernodexp.hpc;Scheduler sent command 0
02/20/2018 09:44:09;0100;Server@node2;Req;;Type 21 request received from Scheduler@node2.supernodexp.hpc, sock=16
02/20/2018 09:44:09;0100;Server@node2;Req;;Type 81 request received from Scheduler@node2.supernodexp.hpc, sock=16
02/20/2018 09:44:09;0100;Server@node2;Req;;Type 71 request received from Scheduler@node2.supernodexp.hpc, sock=16
02/20/2018 09:44:09;0100;Server@node2;Req;;Type 58 request received from Scheduler@node2.supernodexp.hpc, sock=16
02/20/2018 09:44:09;0100;Server@node2;Req;;Type 20 request received from Scheduler@node2.supernodexp.hpc, sock=16
02/20/2018 09:44:09;0100;Server@node2;Req;;Type 51 request received from Scheduler@node2.supernodexp.hpc, sock=16
02/20/2018 09:44:10;0100;Server@node2;Req;;Type 23 request received from Scheduler@node2.supernodexp.hpc, sock=16
02/20/2018 09:44:10;0008;Server@node2;Job;4213.node2.supernodexp.hpc;Job Run at request of Scheduler@node2.supernodexp.hpc on exec_vnode (node13:ncpus=24:mem=2097152kb)
02/20/2018 09:44:10;0001;Server@node2;Svr;Server@node2;Success (0) in req_runjob2, return value of svr_startjob is 0
02/20/2018 09:44:10;0100;Server@node2;Req;;Type 11 request received from Scheduler@node2.supernodexp.hpc, sock=16
02/20/2018 09:44:10;0008;Server@node2;Job;4240.node2.supernodexp.hpc;Job Modified at request of Scheduler@node2.supernodexp.hpc
02/20/2018 09:46:08;0080;Server@node2;Job;4167.node2.supernodexp.hpc;Obit received momhop:1 serverhop:1 state:4 substate:42
02/20/2018 09:46:08;0080;Server@node2;Job;4176.node2.supernodexp.hpc;Obit received momhop:1 serverhop:1 state:4 substate:42
02/20/2018 09:46:09;0010;Server@node2;Job;4167.node2.supernodexp.hpc;Exit_status=0 resources_used.cpupercent=1137 resources_used.cput=01:09:03 resources_used.mem=1642408kb resources_used.ncpus=24 resources_used.vmem=15000664kb resources_used.walltime=00:03:03
02/20/2018 09:46:09;0100;Server@node2;Job;4167.node2.supernodexp.hpc;dequeuing from workq, state 5
02/20/2018 09:46:09;0040;Server@node2;Svr;node2.supernodexp.hpc;Scheduler sent command 2
02/20/2018 09:46:09;0040;Server@node2;Svr;node2.supernodexp.hpc;Scheduler sent command 0
02/20/2018 09:46:09;0100;Server@node2;Req;;Type 21 request received from Scheduler@node2.supernodexp.hpc, sock=16
02/20/2018 09:46:09;0100;Server@node2;Req;;Type 81 request received from Scheduler@node2.supernodexp.hpc, sock=16
02/20/2018 09:46:09;0100;Server@node2;Req;;Type 71 request received from Scheduler@node2.supernodexp.hpc, sock=16
02/20/2018 09:46:09;0100;Server@node2;Req;;Type 58 request received from Scheduler@node2.supernodexp.hpc, sock=16
02/20/2018 09:46:09;0100;Server@node2;Req;;Type 20 request received from Scheduler@node2.supernodexp.hpc, sock=16
02/20/2018 09:46:09;0100;Server@node2;Req;;Type 51 request received from Scheduler@node2.supernodexp.hpc, sock=16
02/20/2018 09:46:09;0100;Server@node2;Req;;Type 23 request received from Scheduler@node2.supernodexp.hpc, sock=16
02/20/2018 09:46:09;0008;Server@node2;Job;4240.node2.supernodexp.hpc;Job Run at request of Scheduler@node2.supernodexp.hpc on exec_vnode (node14:ncpus=24:mem=2097152kb)
02/20/2018 09:46:09;0001;Server@node2;Svr;Server@node2;Success (0) in req_runjob2, return value of svr_startjob is 0
02/20/2018 09:46:09;0010;Server@node2;Job;4176.node2.supernodexp.hpc;Exit_status=0 resources_used.cpupercent=1231 resources_used.cput=01:08:42 resources_used.mem=1642320kb resources_used.ncpus=24 resources_used.vmem=15000348kb resources_used.walltime=00:03:02
02/20/2018 09:46:09;0100;Server@node2;Job;4176.node2.supernodexp.hpc;dequeuing from workq, state 5
02/20/2018 09:46:09;0100;Server@node2;Req;;Type 11 request received from Scheduler@node2.supernodexp.hpc, sock=16
02/20/2018 09:46:09;0008;Server@node2;Job;4254.node2.supernodexp.hpc;Job Modified at request of Scheduler@node2.supernodexp.hpc
02/20/2018 09:46:09;0040;Server@node2;Svr;node2.supernodexp.hpc;Scheduler sent command 2
02/20/2018 09:46:09;0040;Server@node2;Svr;node2.supernodexp.hpc;Scheduler sent command 0
02/20/2018 09:46:09;0100;Server@node2;Req;;Type 21 request received from Scheduler@node2.supernodexp.hpc, sock=16
02/20/2018 09:46:09;0100;Server@node2;Req;;Type 81 request received from Scheduler@node2.supernodexp.hpc, sock=16
02/20/2018 09:46:09;0100;Server@node2;Req;;Type 71 request received from Scheduler@node2.supernodexp.hpc, sock=16
02/20/2018 09:46:09;0100;Server@node2;Req;;Type 58 request received from Scheduler@node2.supernodexp.hpc, sock=16
02/20/2018 09:46:10;0100;Server@node2;Req;;Type 20 request received from Scheduler@node2.supernodexp.hpc, sock=16
02/20/2018 09:46:10;0100;Server@node2;Req;;Type 51 request received from Scheduler@node2.supernodexp.hpc, sock=16
02/20/2018 09:46:10;0100;Server@node2;Req;;Type 23 request received from Scheduler@node2.supernodexp.hpc, sock=16
02/20/2018 09:46:10;0008;Server@node2;Job;4254.node2.supernodexp.hpc;Job Run at request of Scheduler@node2.supernodexp.hpc on exec_vnode (node14:ncpus=24:mem=2097152kb)
02/20/2018 09:46:10;0001;Server@node2;Svr;Server@node2;Success (0) in req_runjob2, return value of svr_startjob is 0
02/20/2018 09:46:10;0100;Server@node2;Req;;Type 11 request received from Scheduler@node2.supernodexp.hpc, sock=16
02/20/2018 09:46:10;0008;Server@node2;Job;4268.node2.supernodexp.hpc;Job Modified at request of Scheduler@node2.supernodexp.hpc
02/20/2018 09:46:20;0080;Server@node2;Job;4254.node2.supernodexp.hpc;Obit received momhop:1 serverhop:1 state:4 substate:42
02/20/2018 09:46:22;0010;Server@node2;Job;4254.node2.supernodexp.hpc;Exit_status=1 resources_used.cpupercent=29 resources_used.cput=00:00:03 resources_used.mem=82084kb resources_used.ncpus=24 resources_used.vmem=1073048kb resources_used.walltime=00:00:11
02/20/2018 09:46:22;0100;Server@node2;Job;4254.node2.supernodexp.hpc;dequeuing from workq, state 5
02/20/2018 09:46:22;0040;Server@node2;Svr;node2.supernodexp.hpc;Scheduler sent command 2
02/20/2018 09:46:22;0040;Server@node2;Svr;node2.supernodexp.hpc;Scheduler sent command 0
02/20/2018 09:46:22;0100;Server@node2;Req;;Type 21 request received from Scheduler@node2.supernodexp.hpc, sock=16
02/20/2018 09:46:22;0100;Server@node2;Req;;Type 81 request received from Scheduler@node2.supernodexp.hpc, sock=16
02/20/2018 09:46:22;0100;Server@node2;Req;;Type 71 request received from Scheduler@node2.supernodexp.hpc, sock=16
02/20/2018 09:46:22;0100;Server@node2;Req;;Type 58 request received from Scheduler@node2.supernodexp.hpc, sock=16
02/20/2018 09:46:22;0100;Server@node2;Req;;Type 20 request received from Scheduler@node2.supernodexp.hpc, sock=16
02/20/2018 09:46:22;0100;Server@node2;Req;;Type 51 request received from Scheduler@node2.supernodexp.hpc, sock=16
02/20/2018 09:46:22;0100;Server@node2;Req;;Type 23 request received from Scheduler@node2.supernodexp.hpc, sock=16
02/20/2018 09:46:22;0008;Server@node2;Job;4268.node2.supernodexp.hpc;Job Run at request of Scheduler@node2.supernodexp.hpc on exec_vnode (node14:ncpus=24:mem=2097152kb)
02/20/2018 09:46:22;0001;Server@node2;Svr;Server@node2;Success (0) in req_runjob2, return value of svr_startjob is 0
02/20/2018 09:46:22;0100;Server@node2;Req;;Type 11 request received from Scheduler@node2.supernodexp.hpc, sock=16
02/20/2018 09:46:22;0008;Server@node2;Job;4278.node2.supernodexp.hpc;Job Modified at request of Scheduler@node2.supernodexp.hpc
02/20/2018 09:47:08;0080;Server@node2;Job;4207.node2.supernodexp.hpc;Obit received momhop:1 serverhop:1 state:4 substate:42
02/20/2018 09:47:09;0010;Server@node2;Job;4207.node2.supernodexp.hpc;Exit_status=0 resources_used.cpupercent=1130 resources_used.cput=01:08:02 resources_used.mem=1644128kb resources_used.ncpus=24 resources_used.vmem=14948188kb resources_used.walltime=00:03:05
02/20/2018 09:47:09;0100;Server@node2;Job;4207.node2.supernodexp.hpc;dequeuing from workq, state 5
02/20/2018 09:47:09;0040;Server@node2;Svr;node2.supernodexp.hpc;Scheduler sent command 2
02/20/2018 09:47:09;0040;Server@node2;Svr;node2.supernodexp.hpc;Scheduler sent command 0
02/20/2018 09:47:09;0100;Server@node2;Req;;Type 21 request received from Scheduler@node2.supernodexp.hpc, sock=16
02/20/2018 09:47:09;0100;Server@node2;Req;;Type 81 request received from Scheduler@node2.supernodexp.hpc, sock=16
02/20/2018 09:47:09;0100;Server@node2;Req;;Type 71 request received from Scheduler@node2.supernodexp.hpc, sock=16
02/20/2018 09:47:09;0100;Server@node2;Req;;Type 58 request received from Scheduler@node2.supernodexp.hpc, sock=16
02/20/2018 09:47:09;0100;Server@node2;Req;;Type 20 request received from Scheduler@node2.supernodexp.hpc, sock=16
02/20/2018 09:47:09;0100;Server@node2;Req;;Type 51 request received from Scheduler@node2.supernodexp.hpc, sock=16
02/20/2018 09:47:09;0100;Server@node2;Req;;Type 23 request received from Scheduler@node2.supernodexp.hpc, sock=16
02/20/2018 09:47:09;0008;Server@node2;Job;4278.node2.supernodexp.hpc;Job Run at request of Scheduler@node2.supernodexp.hpc on exec_vnode (node13:ncpus=24:mem=2097152kb)
02/20/2018 09:47:09;0001;Server@node2;Svr;Server@node2;Success (0) in req_runjob2, return value of svr_startjob is 0
02/20/2018 09:47:09;0100;Server@node2;Req;;Type 11 request received from Scheduler@node2.supernodexp.hpc, sock=16
02/20/2018 09:47:09;0008;Server@node2;Job;4279.node2.supernodexp.hpc;Job Modified at request of Scheduler@node2.supernodexp.hpc
02/20/2018 09:47:12;0080;Server@node2;Job;4213.node2.supernodexp.hpc;Obit received momhop:1 serverhop:1 state:4 substate:42
02/20/2018 09:47:14;0010;Server@node2;Job;4213.node2.supernodexp.hpc;Exit_status=0 resources_used.cpupercent=1358 resources_used.cput=01:08:39 resources_used.mem=1643964kb resources_used.ncpus=24 resources_used.vmem=14948076kb resources_used.walltime=00:03:03
02/20/2018 09:47:14;0100;Server@node2;Job;4213.node2.supernodexp.hpc;dequeuing from workq, state 5
02/20/2018 09:47:14;0040;Server@node2;Svr;node2.supernodexp.hpc;Scheduler sent command 2
02/20/2018 09:47:14;0040;Server@node2;Svr;node2.supernodexp.hpc;Scheduler sent command 0
02/20/2018 09:47:14;0100;Server@node2;Req;;Type 21 request received from Scheduler@node2.supernodexp.hpc, sock=16
02/20/2018 09:47:14;0100;Server@node2;Req;;Type 81 request received from Scheduler@node2.supernodexp.hpc, sock=16
02/20/2018 09:47:14;0100;Server@node2;Req;;Type 71 request received from Scheduler@node2.supernodexp.hpc, sock=16
02/20/2018 09:47:14;0100;Server@node2;Req;;Type 58 request received from Scheduler@node2.supernodexp.hpc, sock=16
02/20/2018 09:47:14;0100;Server@node2;Req;;Type 20 request received from Scheduler@node2.supernodexp.hpc, sock=16
02/20/2018 09:47:14;0100;Server@node2;Req;;Type 51 request received from Scheduler@node2.supernodexp.hpc, sock=16
02/20/2018 09:47:14;0100;Server@node2;Req;;Type 23 request received from Scheduler@node2.supernodexp.hpc, sock=16
02/20/2018 09:47:14;0008;Server@node2;Job;4279.node2.supernodexp.hpc;Job Run at request of Scheduler@node2.supernodexp.hpc on exec_vnode (node13:ncpus=24:mem=2097152kb)
02/20/2018 09:47:14;0001;Server@node2;Svr;Server@node2;Success (0) in req_runjob2, return value of svr_startjob is 0
02/20/2018 09:47:14;0100;Server@node2;Req;;Type 11 request received from Scheduler@node2.supernodexp.hpc, sock=16
02/20/2018 09:47:14;0008;Server@node2;Job;4291.node2.supernodexp.hpc;Job Modified at request of Scheduler@node2.supernodexp.hpc
02/20/2018 09:49:17;0080;Server@node2;Job;4240.node2.supernodexp.hpc;Obit received momhop:1 serverhop:1 state:4 substate:42
02/20/2018 09:49:18;0010;Server@node2;Job;4240.node2.supernodexp.hpc;Exit_status=0 resources_used.cpupercent=1090 resources_used.cput=01:08:15 resources_used.mem=1642484kb resources_used.ncpus=24 resources_used.vmem=15000404kb resources_used.walltime=00:03:07
02/20/2018 09:49:18;0100;Server@node2;Job;4240.node2.supernodexp.hpc;dequeuing from workq, state 5
02/20/2018 09:49:18;0040;Server@node2;Svr;node2.supernodexp.hpc;Scheduler sent command 2
02/20/2018 09:49:18;0040;Server@node2;Svr;node2.supernodexp.hpc;Scheduler sent command 0
02/20/2018 09:49:18;0100;Server@node2;Req;;Type 21 request received from Scheduler@node2.supernodexp.hpc, sock=16
02/20/2018 09:49:18;0100;Server@node2;Req;;Type 81 request received from Scheduler@node2.supernodexp.hpc, sock=16
02/20/2018 09:49:18;0100;Server@node2;Req;;Type 71 request received from Scheduler@node2.supernodexp.hpc, sock=16
02/20/2018 09:49:18;0100;Server@node2;Req;;Type 58 request received from Scheduler@node2.supernodexp.hpc, sock=16
02/20/2018 09:49:18;0100;Server@node2;Req;;Type 20 request received from Scheduler@node2.supernodexp.hpc, sock=16
02/20/2018 09:49:18;0100;Server@node2;Req;;Type 51 request received from Scheduler@node2.supernodexp.hpc, sock=16
02/20/2018 09:49:18;0100;Server@node2;Req;;Type 23 request received from Scheduler@node2.supernodexp.hpc, sock=16
02/20/2018 09:49:18;0008;Server@node2;Job;4291.node2.supernodexp.hpc;Job Run at request of Scheduler@node2.supernodexp.hpc on exec_vnode (node14:ncpus=24:mem=2097152kb)
02/20/2018 09:49:18;0001;Server@node2;Svr;Server@node2;Success (0) in req_runjob2, return value of svr_startjob is 0
02/20/2018 09:49:18;0100;Server@node2;Req;;Type 11 request received from Scheduler@node2.supernodexp.hpc, sock=16
02/20/2018 09:49:18;0008;Server@node2;Job;4292.node2.supernodexp.hpc;Job Modified at request of Scheduler@node2.supernodexp.hpc
02/20/2018 09:49:23;0080;Server@node2;Job;4268.node2.supernodexp.hpc;Obit received momhop:1 serverhop:1 state:4 substate:42
02/20/2018 09:49:30;0010;Server@node2;Job;4268.node2.supernodexp.hpc;Exit_status=0 resources_used.cpupercent=1098 resources_used.cput=01:07:42 resources_used.mem=1642660kb resources_used.ncpus=24 resources_used.vmem=15000364kb resources_used.walltime=00:03:01
02/20/2018 09:49:30;0100;Server@node2;Job;4268.node2.supernodexp.hpc;dequeuing from workq, state 5
02/20/2018 09:49:30;0040;Server@node2;Svr;node2.supernodexp.hpc;Scheduler sent command 2
02/20/2018 09:49:30;0040;Server@node2;Svr;node2.supernodexp.hpc;Scheduler sent command 0
02/20/2018 09:49:30;0100;Server@node2;Req;;Type 21 request received from Scheduler@node2.supernodexp.hpc, sock=16
02/20/2018 09:49:30;0100;Server@node2;Req;;Type 81 request received from Scheduler@node2.supernodexp.hpc, sock=16
02/20/2018 09:49:30;0100;Server@node2;Req;;Type 71 request received from Scheduler@node2.supernodexp.hpc, sock=16
02/20/2018 09:49:30;0100;Server@node2;Req;;Type 58 request received from Scheduler@node2.supernodexp.hpc, sock=16
02/20/2018 09:49:30;0100;Server@node2;Req;;Type 20 request received from Scheduler@node2.supernodexp.hpc, sock=16
02/20/2018 09:49:30;0100;Server@node2;Req;;Type 51 request received from Scheduler@node2.supernodexp.hpc, sock=16
02/20/2018 09:49:30;0100;Server@node2;Req;;Type 23 request received from Scheduler@node2.supernodexp.hpc, sock=16
02/20/2018 09:49:30;0008;Server@node2;Job;4292.node2.supernodexp.hpc;Job Run at request of Scheduler@node2.supernodexp.hpc on exec_vnode (node14:ncpus=24:mem=2097152kb)
02/20/2018 09:49:30;0001;Server@node2;Svr;Server@node2;Success (0) in req_runjob2, return value of svr_startjob is 0
02/20/2018 09:49:30;0100;Server@node2;Req;;Type 11 request received from Scheduler@node2.supernodexp.hpc, sock=16
02/20/2018 09:49:30;0008;Server@node2;Job;4294.node2.supernodexp.hpc;Job Modified at request of Scheduler@node2.supernodexp.hpc
02/20/2018 09:50:17;0080;Server@node2;Job;4278.node2.supernodexp.hpc;Obit received momhop:1 serverhop:1 state:4 substate:42
02/20/2018 09:50:19;0080;Server@node2;Job;4279.node2.supernodexp.hpc;Obit received momhop:1 serverhop:1 state:4 substate:42
02/20/2018 09:50:19;0010;Server@node2;Job;4278.node2.supernodexp.hpc;Exit_status=0 resources_used.cpupercent=1131 resources_used.cput=01:09:07 resources_used.mem=1642332kb resources_used.ncpus=24 resources_used.vmem=14948348kb resources_used.walltime=00:03:08
02/20/2018 09:50:19;0100;Server@node2;Job;4278.node2.supernodexp.hpc;dequeuing from workq, state 5
02/20/2018 09:50:19;0040;Server@node2;Svr;node2.supernodexp.hpc;Scheduler sent command 2
02/20/2018 09:50:19;0040;Server@node2;Svr;node2.supernodexp.hpc;Scheduler sent command 0
02/20/2018 09:50:19;0100;Server@node2;Req;;Type 21 request received from Scheduler@node2.supernodexp.hpc, sock=16
02/20/2018 09:50:19;0100;Server@node2;Req;;Type 81 request received from Scheduler@node2.supernodexp.hpc, sock=16
02/20/2018 09:50:19;0100;Server@node2;Req;;Type 71 request received from Scheduler@node2.supernodexp.hpc, sock=16
02/20/2018 09:50:19;0100;Server@node2;Req;;Type 58 request received from Scheduler@node2.supernodexp.hpc, sock=16
02/20/2018 09:50:19;0100;Server@node2;Req;;Type 20 request received from Scheduler@node2.supernodexp.hpc, sock=16
02/20/2018 09:50:19;0100;Server@node2;Req;;Type 51 request received from Scheduler@node2.supernodexp.hpc, sock=16
02/20/2018 09:50:19;0100;Server@node2;Req;;Type 23 request received from Scheduler@node2.supernodexp.hpc, sock=16
02/20/2018 09:50:19;0008;Server@node2;Job;4294.node2.supernodexp.hpc;Job Run at request of Scheduler@node2.supernodexp.hpc on exec_vnode (node13:ncpus=24:mem=2097152kb)
02/20/2018 09:50:19;0001;Server@node2;Svr;Server@node2;Success (0) in req_runjob2, return value of svr_startjob is 0
02/20/2018 09:50:19;0100;Server@node2;Req;;Type 11 request received from Scheduler@node2.supernodexp.hpc, sock=16
02/20/2018 09:50:19;0008;Server@node2;Job;4331.node2.supernodexp.hpc;Job Modified at request of Scheduler@node2.supernodexp.hpc
02/20/2018 09:50:20;0010;Server@node2;Job;4279.node2.supernodexp.hpc;Exit_status=0 resources_used.cpupercent=1480 resources_used.cput=01:09:14 resources_used.mem=1642092kb resources_used.ncpus=24 resources_used.vmem=14948148kb resources_used.walltime=00:03:05
02/20/2018 09:50:20;0100;Server@node2;Job;4279.node2.supernodexp.hpc;dequeuing from workq, state 5
02/20/2018 09:50:20;0040;Server@node2;Svr;node2.supernodexp.hpc;Scheduler sent command 2
02/20/2018 09:50:20;0040;Server@node2;Svr;node2.supernodexp.hpc;Scheduler sent command 0
02/20/2018 09:50:20;0100;Server@node2;Req;;Type 21 request received from Scheduler@node2.supernodexp.hpc, sock=16
02/20/2018 09:50:20;0100;Server@node2;Req;;Type 81 request received from Scheduler@node2.supernodexp.hpc, sock=16
02/20/2018 09:50:20;0100;Server@node2;Req;;Type 71 request received from Scheduler@node2.supernodexp.hpc, sock=16
02/20/2018 09:50:20;0100;Server@node2;Req;;Type 58 request received from Scheduler@node2.supernodexp.hpc, sock=16
02/20/2018 09:50:20;0100;Server@node2;Req;;Type 20 request received from Scheduler@node2.supernodexp.hpc, sock=16
02/20/2018 09:50:20;0100;Server@node2;Req;;Type 51 request received from Scheduler@node2.supernodexp.hpc, sock=16
02/20/2018 09:50:21;0100;Server@node2;Req;;Type 23 request received from Scheduler@node2.supernodexp.hpc, sock=16
02/20/2018 09:50:21;0008;Server@node2;Job;4331.node2.supernodexp.hpc;Job Run at request of Scheduler@node2.supernodexp.hpc on exec_vnode (node13:ncpus=24:mem=2097152kb)
02/20/2018 09:50:21;0001;Server@node2;Svr;Server@node2;Success (0) in req_runjob2, return value of svr_startjob is 0
02/20/2018 09:50:21;0100;Server@node2;Req;;Type 11 request received from Scheduler@node2.supernodexp.hpc, sock=16
02/20/2018 09:50:21;0008;Server@node2;Job;4349.node2.supernodexp.hpc;Job Modified at request of Scheduler@node2.supernodexp.hpc
02/20/2018 09:50:27;0080;Server@node2;Job;4331.node2.supernodexp.hpc;Obit received momhop:1 serverhop:1 state:4 substate:42
02/20/2018 09:50:28;0010;Server@node2;Job;4331.node2.supernodexp.hpc;Exit_status=1 resources_used.cpupercent=33 resources_used.cput=00:00:02 resources_used.mem=0kb resources_used.ncpus=24 resources_used.vmem=0kb resources_used.walltime=00:00:07
02/20/2018 09:50:28;0100;Server@node2;Job;4331.node2.supernodexp.hpc;dequeuing from workq, state 5
02/20/2018 09:50:28;0040;Server@node2;Svr;node2.supernodexp.hpc;Scheduler sent command 2
02/20/2018 09:50:28;0040;Server@node2;Svr;node2.supernodexp.hpc;Scheduler sent command 0
02/20/2018 09:50:28;0100;Server@node2;Req;;Type 21 request received from Scheduler@node2.supernodexp.hpc, sock=16
02/20/2018 09:50:28;0100;Server@node2;Req;;Type 81 request received from Scheduler@node2.supernodexp.hpc, sock=16
02/20/2018 09:50:28;0100;Server@node2;Req;;Type 71 request received from Scheduler@node2.supernodexp.hpc, sock=16
