S02/19/2018 16:17:49;0100;Server@node2;Job;3627.node2.supernodexp.hpc;enqueuing into workq, state 1 hop 1
02/19/2018 16:17:49;0008;Server@node2;Job;3627.node2.supernodexp.hpc;Job Queued at request of ctminh@node2.supernodexp.hpc, owner = ctminh@node2.supernodexp.hpc, job name = jacobi, queue = workq
02/19/2018 16:17:49;0040;Server@node2;Svr;node2.supernodexp.hpc;Scheduler sent command 1
02/19/2018 16:17:49;0040;Server@node2;Svr;node2.supernodexp.hpc;Scheduler sent command 0
02/19/2018 16:17:49;0100;Server@node2;Req;;Type 21 request received from Scheduler@node2.supernodexp.hpc, sock=20
02/19/2018 16:17:49;0100;Server@node2;Req;;Type 1 request received from ctminh@node2.supernodexp.hpc, sock=16
02/19/2018 16:17:49;0100;Server@node2;Req;;Type 3 request received from ctminh@node2.supernodexp.hpc, sock=16
02/19/2018 16:17:49;0100;Server@node2;Req;;Type 5 request received from ctminh@node2.supernodexp.hpc, sock=16
02/19/2018 16:17:49;0100;Server@node2;Job;3628.node2.supernodexp.hpc;enqueuing into workq, state 1 hop 1
02/19/2018 16:17:49;0008;Server@node2;Job;3628.node2.supernodexp.hpc;Job Queued at request of ctminh@node2.supernodexp.hpc, owner = ctminh@node2.supernodexp.hpc, job name = telemac3, queue = workq
02/19/2018 16:17:49;0100;Server@node2;Req;;Type 81 request received from Scheduler@node2.supernodexp.hpc, sock=20
02/19/2018 16:17:49;0100;Server@node2;Req;;Type 71 request received from Scheduler@node2.supernodexp.hpc, sock=20
02/19/2018 16:17:49;0100;Server@node2;Req;;Type 58 request received from Scheduler@node2.supernodexp.hpc, sock=20
02/19/2018 16:17:49;0100;Server@node2;Req;;Type 20 request received from Scheduler@node2.supernodexp.hpc, sock=20
02/19/2018 16:17:49;0100;Server@node2;Req;;Type 51 request received from Scheduler@node2.supernodexp.hpc, sock=20
02/19/2018 16:17:49;0100;Server@node2;Req;;Type 23 request received from Scheduler@node2.supernodexp.hpc, sock=20
02/19/2018 16:17:49;0008;Server@node2;Job;3628.node2.supernodexp.hpc;Job Run at request of Scheduler@node2.supernodexp.hpc on exec_vnode (node13:ncpus=24:mem=4194304kb)+(node13:ncpus=24:mem=4194304kb)
02/19/2018 16:17:49;0001;Server@node2;Svr;Server@node2;Success (0) in req_runjob2, return value of svr_startjob is 0
02/19/2018 16:17:49;0100;Server@node2;Req;;Type 23 request received from Scheduler@node2.supernodexp.hpc, sock=20
02/19/2018 16:17:49;0008;Server@node2;Job;3627.node2.supernodexp.hpc;Job Run at request of Scheduler@node2.supernodexp.hpc on exec_vnode (node14:ncpus=16:mem=2097152kb)
02/19/2018 16:17:49;0001;Server@node2;Svr;Server@node2;Success (0) in req_runjob2, return value of svr_startjob is 0
02/19/2018 16:17:49;0040;Server@node2;Svr;node2.supernodexp.hpc;Scheduler sent command 1
02/19/2018 16:17:49;0040;Server@node2;Svr;node2.supernodexp.hpc;Scheduler sent command 0
02/19/2018 16:17:49;0100;Server@node2;Req;;Type 21 request received from Scheduler@node2.supernodexp.hpc, sock=20
02/19/2018 16:17:49;0100;Server@node2;Req;;Type 81 request received from Scheduler@node2.supernodexp.hpc, sock=20
02/19/2018 16:17:49;0100;Server@node2;Req;;Type 71 request received from Scheduler@node2.supernodexp.hpc, sock=20
02/19/2018 16:17:49;0100;Server@node2;Req;;Type 58 request received from Scheduler@node2.supernodexp.hpc, sock=20
02/19/2018 16:17:49;0100;Server@node2;Req;;Type 20 request received from Scheduler@node2.supernodexp.hpc, sock=20
02/19/2018 16:17:49;0100;Server@node2;Req;;Type 51 request received from Scheduler@node2.supernodexp.hpc, sock=20
02/19/2018 16:17:50;0100;Server@node2;Req;;Type 1 request received from ctminh@node2.supernodexp.hpc, sock=16
02/19/2018 16:17:50;0100;Server@node2;Req;;Type 3 request received from ctminh@node2.supernodexp.hpc, sock=16
02/19/2018 16:17:50;0100;Server@node2;Req;;Type 5 request received from ctminh@node2.supernodexp.hpc, sock=16
02/19/2018 16:17:50;0100;Server@node2;Job;3629.node2.supernodexp.hpc;enqueuing into workq, state 1 hop 1
02/19/2018 16:17:50;0008;Server@node2;Job;3629.node2.supernodexp.hpc;Job Queued at request of ctminh@node2.supernodexp.hpc, owner = ctminh@node2.supernodexp.hpc, job name = telemac1, queue = workq
02/19/2018 16:17:50;0040;Server@node2;Svr;node2.supernodexp.hpc;Scheduler sent command 1
02/19/2018 16:17:50;0040;Server@node2;Svr;node2.supernodexp.hpc;Scheduler sent command 0
02/19/2018 16:17:50;0100;Server@node2;Req;;Type 21 request received from Scheduler@node2.supernodexp.hpc, sock=20
02/19/2018 16:17:50;0100;Server@node2;Req;;Type 81 request received from Scheduler@node2.supernodexp.hpc, sock=20
02/19/2018 16:17:50;0100;Server@node2;Req;;Type 71 request received from Scheduler@node2.supernodexp.hpc, sock=20
02/19/2018 16:17:50;0100;Server@node2;Req;;Type 58 request received from Scheduler@node2.supernodexp.hpc, sock=20
02/19/2018 16:17:50;0100;Server@node2;Req;;Type 20 request received from Scheduler@node2.supernodexp.hpc, sock=20
02/19/2018 16:17:50;0100;Server@node2;Req;;Type 51 request received from Scheduler@node2.supernodexp.hpc, sock=20
02/19/2018 16:17:50;0100;Server@node2;Req;;Type 23 request received from Scheduler@node2.supernodexp.hpc, sock=20
02/19/2018 16:17:50;0008;Server@node2;Job;3629.node2.supernodexp.hpc;Job Run at request of Scheduler@node2.supernodexp.hpc on exec_vnode (node14:ncpus=24:mem=2097152kb)
02/19/2018 16:17:50;0001;Server@node2;Svr;Server@node2;Success (0) in req_runjob2, return value of svr_startjob is 0
02/19/2018 16:18:21;0100;Server@node2;Req;;Type 1 request received from ctminh@node2.supernodexp.hpc, sock=16
02/19/2018 16:18:21;0100;Server@node2;Req;;Type 3 request received from ctminh@node2.supernodexp.hpc, sock=16
02/19/2018 16:18:21;0100;Server@node2;Req;;Type 5 request received from ctminh@node2.supernodexp.hpc, sock=16
02/19/2018 16:18:21;0100;Server@node2;Job;3630.node2.supernodexp.hpc;enqueuing into workq, state 1 hop 1
02/19/2018 16:18:21;0008;Server@node2;Job;3630.node2.supernodexp.hpc;Job Queued at request of ctminh@node2.supernodexp.hpc, owner = ctminh@node2.supernodexp.hpc, job name = lu-decomp, queue = workq
02/19/2018 16:18:21;0040;Server@node2;Svr;node2.supernodexp.hpc;Scheduler sent command 1
02/19/2018 16:18:21;0040;Server@node2;Svr;node2.supernodexp.hpc;Scheduler sent command 0
02/19/2018 16:18:21;0100;Server@node2;Req;;Type 21 request received from Scheduler@node2.supernodexp.hpc, sock=20
02/19/2018 16:18:21;0100;Server@node2;Req;;Type 81 request received from Scheduler@node2.supernodexp.hpc, sock=20
02/19/2018 16:18:21;0100;Server@node2;Req;;Type 71 request received from Scheduler@node2.supernodexp.hpc, sock=20
02/19/2018 16:18:21;0100;Server@node2;Req;;Type 58 request received from Scheduler@node2.supernodexp.hpc, sock=20
02/19/2018 16:18:21;0100;Server@node2;Req;;Type 20 request received from Scheduler@node2.supernodexp.hpc, sock=20
02/19/2018 16:18:21;0100;Server@node2;Req;;Type 51 request received from Scheduler@node2.supernodexp.hpc, sock=20
02/19/2018 16:18:21;0100;Server@node2;Req;;Type 11 request received from Scheduler@node2.supernodexp.hpc, sock=20
02/19/2018 16:18:21;0008;Server@node2;Job;3630.node2.supernodexp.hpc;Job Modified at request of Scheduler@node2.supernodexp.hpc
02/19/2018 16:18:31;0100;Server@node2;Req;;Type 1 request received from ctminh@node2.supernodexp.hpc, sock=16
02/19/2018 16:18:31;0100;Server@node2;Req;;Type 3 request received from ctminh@node2.supernodexp.hpc, sock=16
02/19/2018 16:18:31;0100;Server@node2;Req;;Type 5 request received from ctminh@node2.supernodexp.hpc, sock=16
02/19/2018 16:18:31;0100;Server@node2;Job;3631.node2.supernodexp.hpc;enqueuing into workq, state 1 hop 1
02/19/2018 16:18:31;0008;Server@node2;Job;3631.node2.supernodexp.hpc;Job Queued at request of ctminh@node2.supernodexp.hpc, owner = ctminh@node2.supernodexp.hpc, job name = nbody, queue = workq
02/19/2018 16:18:31;0040;Server@node2;Svr;node2.supernodexp.hpc;Scheduler sent command 1
02/19/2018 16:18:31;0040;Server@node2;Svr;node2.supernodexp.hpc;Scheduler sent command 0
02/19/2018 16:18:31;0100;Server@node2;Req;;Type 21 request received from Scheduler@node2.supernodexp.hpc, sock=20
02/19/2018 16:18:31;0100;Server@node2;Req;;Type 81 request received from Scheduler@node2.supernodexp.hpc, sock=20
02/19/2018 16:18:31;0100;Server@node2;Req;;Type 71 request received from Scheduler@node2.supernodexp.hpc, sock=20
02/19/2018 16:18:31;0100;Server@node2;Req;;Type 58 request received from Scheduler@node2.supernodexp.hpc, sock=20
02/19/2018 16:18:31;0100;Server@node2;Req;;Type 20 request received from Scheduler@node2.supernodexp.hpc, sock=20
02/19/2018 16:18:31;0100;Server@node2;Req;;Type 51 request received from Scheduler@node2.supernodexp.hpc, sock=20
02/19/2018 16:18:31;0100;Server@node2;Req;;Type 11 request received from Scheduler@node2.supernodexp.hpc, sock=20
02/19/2018 16:18:31;0008;Server@node2;Job;3630.node2.supernodexp.hpc;Job Modified at request of Scheduler@node2.supernodexp.hpc
02/19/2018 16:18:31;0100;Server@node2;Req;;Type 11 request received from Scheduler@node2.supernodexp.hpc, sock=20
02/19/2018 16:18:31;0008;Server@node2;Job;3631.node2.supernodexp.hpc;Job Modified at request of Scheduler@node2.supernodexp.hpc
02/19/2018 16:18:34;0100;Server@node2;Req;;Type 1 request received from ctminh@node2.supernodexp.hpc, sock=16
02/19/2018 16:18:34;0100;Server@node2;Req;;Type 3 request received from ctminh@node2.supernodexp.hpc, sock=16
02/19/2018 16:18:34;0100;Server@node2;Req;;Type 5 request received from ctminh@node2.supernodexp.hpc, sock=16
02/19/2018 16:18:34;0100;Server@node2;Job;3632.node2.supernodexp.hpc;enqueuing into workq, state 1 hop 1
02/19/2018 16:18:34;0008;Server@node2;Job;3632.node2.supernodexp.hpc;Job Queued at request of ctminh@node2.supernodexp.hpc, owner = ctminh@node2.supernodexp.hpc, job name = jacobi, queue = workq
02/19/2018 16:18:34;0040;Server@node2;Svr;node2.supernodexp.hpc;Scheduler sent command 1
02/19/2018 16:18:34;0040;Server@node2;Svr;node2.supernodexp.hpc;Scheduler sent command 0
02/19/2018 16:18:34;0100;Server@node2;Req;;Type 21 request received from Scheduler@node2.supernodexp.hpc, sock=20
02/19/2018 16:18:34;0100;Server@node2;Req;;Type 81 request received from Scheduler@node2.supernodexp.hpc, sock=20
02/19/2018 16:18:34;0100;Server@node2;Req;;Type 71 request received from Scheduler@node2.supernodexp.hpc, sock=20
02/19/2018 16:18:34;0100;Server@node2;Req;;Type 58 request received from Scheduler@node2.supernodexp.hpc, sock=20
02/19/2018 16:18:34;0100;Server@node2;Req;;Type 20 request received from Scheduler@node2.supernodexp.hpc, sock=20
02/19/2018 16:18:34;0100;Server@node2;Req;;Type 51 request received from Scheduler@node2.supernodexp.hpc, sock=20
02/19/2018 16:18:34;0100;Server@node2;Req;;Type 11 request received from Scheduler@node2.supernodexp.hpc, sock=20
02/19/2018 16:18:34;0008;Server@node2;Job;3631.node2.supernodexp.hpc;Job Modified at request of Scheduler@node2.supernodexp.hpc
02/19/2018 16:18:34;0100;Server@node2;Req;;Type 11 request received from Scheduler@node2.supernodexp.hpc, sock=20
02/19/2018 16:18:34;0008;Server@node2;Job;3632.node2.supernodexp.hpc;Job Modified at request of Scheduler@node2.supernodexp.hpc
02/19/2018 16:18:36;0080;Server@node2;Job;3627.node2.supernodexp.hpc;Obit received momhop:1 serverhop:1 state:4 substate:42
02/19/2018 16:18:38;0010;Server@node2;Job;3627.node2.supernodexp.hpc;Exit_status=0 resources_used.cpupercent=1444 resources_used.cput=00:12:19 resources_used.mem=97048kb resources_used.ncpus=16 resources_used.vmem=1468340kb resources_used.walltime=00:00:48
02/19/2018 16:18:38;0100;Server@node2;Job;3627.node2.supernodexp.hpc;dequeuing from workq, state 5
02/19/2018 16:18:38;0040;Server@node2;Svr;node2.supernodexp.hpc;Scheduler sent command 2
02/19/2018 16:18:38;0040;Server@node2;Svr;node2.supernodexp.hpc;Scheduler sent command 0
02/19/2018 16:18:38;0100;Server@node2;Req;;Type 21 request received from Scheduler@node2.supernodexp.hpc, sock=20
02/19/2018 16:18:38;0100;Server@node2;Req;;Type 81 request received from Scheduler@node2.supernodexp.hpc, sock=20
02/19/2018 16:18:38;0100;Server@node2;Req;;Type 71 request received from Scheduler@node2.supernodexp.hpc, sock=20
02/19/2018 16:18:38;0100;Server@node2;Req;;Type 58 request received from Scheduler@node2.supernodexp.hpc, sock=20
02/19/2018 16:18:38;0100;Server@node2;Req;;Type 20 request received from Scheduler@node2.supernodexp.hpc, sock=20
02/19/2018 16:18:38;0100;Server@node2;Req;;Type 51 request received from Scheduler@node2.supernodexp.hpc, sock=20
02/19/2018 16:18:38;0100;Server@node2;Req;;Type 23 request received from Scheduler@node2.supernodexp.hpc, sock=20
02/19/2018 16:18:38;0008;Server@node2;Job;3632.node2.supernodexp.hpc;Job Run at request of Scheduler@node2.supernodexp.hpc on exec_vnode (node14:ncpus=16:mem=2097152kb)
02/19/2018 16:18:38;0001;Server@node2;Svr;Server@node2;Success (0) in req_runjob2, return value of svr_startjob is 0
02/19/2018 16:18:38;0100;Server@node2;Req;;Type 11 request received from Scheduler@node2.supernodexp.hpc, sock=20
02/19/2018 16:18:38;0008;Server@node2;Job;3631.node2.supernodexp.hpc;Job Modified at request of Scheduler@node2.supernodexp.hpc
02/19/2018 16:18:46;0100;Server@node2;Req;;Type 1 request received from ctminh@node2.supernodexp.hpc, sock=16
02/19/2018 16:18:46;0100;Server@node2;Req;;Type 3 request received from ctminh@node2.supernodexp.hpc, sock=16
02/19/2018 16:18:46;0100;Server@node2;Req;;Type 5 request received from ctminh@node2.supernodexp.hpc, sock=16
02/19/2018 16:18:46;0100;Server@node2;Job;3633.node2.supernodexp.hpc;enqueuing into workq, state 1 hop 1
02/19/2018 16:18:46;0008;Server@node2;Job;3633.node2.supernodexp.hpc;Job Queued at request of ctminh@node2.supernodexp.hpc, owner = ctminh@node2.supernodexp.hpc, job name = vectorization, queue = workq
02/19/2018 16:18:46;0040;Server@node2;Svr;node2.supernodexp.hpc;Scheduler sent command 1
02/19/2018 16:18:46;0040;Server@node2;Svr;node2.supernodexp.hpc;Scheduler sent command 0
02/19/2018 16:18:46;0100;Server@node2;Req;;Type 21 request received from Scheduler@node2.supernodexp.hpc, sock=20
02/19/2018 16:18:46;0100;Server@node2;Req;;Type 81 request received from Scheduler@node2.supernodexp.hpc, sock=20
02/19/2018 16:18:46;0100;Server@node2;Req;;Type 71 request received from Scheduler@node2.supernodexp.hpc, sock=20
02/19/2018 16:18:46;0100;Server@node2;Req;;Type 58 request received from Scheduler@node2.supernodexp.hpc, sock=20
02/19/2018 16:18:46;0100;Server@node2;Req;;Type 20 request received from Scheduler@node2.supernodexp.hpc, sock=20
02/19/2018 16:18:46;0100;Server@node2;Req;;Type 51 request received from Scheduler@node2.supernodexp.hpc, sock=20
02/19/2018 16:18:46;0100;Server@node2;Req;;Type 11 request received from Scheduler@node2.supernodexp.hpc, sock=20
02/19/2018 16:18:46;0008;Server@node2;Job;3633.node2.supernodexp.hpc;Job Modified at request of Scheduler@node2.supernodexp.hpc
02/19/2018 16:18:48;0100;Server@node2;Req;;Type 1 request received from ctminh@node2.supernodexp.hpc, sock=16
02/19/2018 16:18:48;0100;Server@node2;Req;;Type 3 request received from ctminh@node2.supernodexp.hpc, sock=16
02/19/2018 16:18:48;0100;Server@node2;Req;;Type 5 request received from ctminh@node2.supernodexp.hpc, sock=16
02/19/2018 16:18:48;0100;Server@node2;Job;3634.node2.supernodexp.hpc;enqueuing into workq, state 1 hop 1
02/19/2018 16:18:48;0008;Server@node2;Job;3634.node2.supernodexp.hpc;Job Queued at request of ctminh@node2.supernodexp.hpc, owner = ctminh@node2.supernodexp.hpc, job name = telemac3, queue = workq
02/19/2018 16:18:48;0040;Server@node2;Svr;node2.supernodexp.hpc;Scheduler sent command 1
02/19/2018 16:18:48;0040;Server@node2;Svr;node2.supernodexp.hpc;Scheduler sent command 0
02/19/2018 16:18:48;0100;Server@node2;Req;;Type 21 request received from Scheduler@node2.supernodexp.hpc, sock=20
02/19/2018 16:18:48;0100;Server@node2;Req;;Type 81 request received from Scheduler@node2.supernodexp.hpc, sock=20
02/19/2018 16:18:48;0100;Server@node2;Req;;Type 71 request received from Scheduler@node2.supernodexp.hpc, sock=20
02/19/2018 16:18:48;0100;Server@node2;Req;;Type 58 request received from Scheduler@node2.supernodexp.hpc, sock=20
02/19/2018 16:18:48;0100;Server@node2;Req;;Type 20 request received from Scheduler@node2.supernodexp.hpc, sock=20
02/19/2018 16:18:48;0100;Server@node2;Req;;Type 51 request received from Scheduler@node2.supernodexp.hpc, sock=20
02/19/2018 16:18:48;0100;Server@node2;Req;;Type 11 request received from Scheduler@node2.supernodexp.hpc, sock=20
02/19/2018 16:18:48;0008;Server@node2;Job;3631.node2.supernodexp.hpc;Job Modified at request of Scheduler@node2.supernodexp.hpc
02/19/2018 16:18:48;0100;Server@node2;Req;;Type 11 request received from Scheduler@node2.supernodexp.hpc, sock=20
02/19/2018 16:18:48;0008;Server@node2;Job;3634.node2.supernodexp.hpc;Job Modified at request of Scheduler@node2.supernodexp.hpc
02/19/2018 16:19:08;0100;Server@node2;Req;;Type 1 request received from ctminh@node2.supernodexp.hpc, sock=16
02/19/2018 16:19:08;0100;Server@node2;Req;;Type 3 request received from ctminh@node2.supernodexp.hpc, sock=16
02/19/2018 16:19:08;0100;Server@node2;Req;;Type 5 request received from ctminh@node2.supernodexp.hpc, sock=16
02/19/2018 16:19:08;0100;Server@node2;Job;3635.node2.supernodexp.hpc;enqueuing into workq, state 1 hop 1
02/19/2018 16:19:08;0008;Server@node2;Job;3635.node2.supernodexp.hpc;Job Queued at request of ctminh@node2.supernodexp.hpc, owner = ctminh@node2.supernodexp.hpc, job name = nbody, queue = workq
02/19/2018 16:19:08;0040;Server@node2;Svr;node2.supernodexp.hpc;Scheduler sent command 1
02/19/2018 16:19:08;0040;Server@node2;Svr;node2.supernodexp.hpc;Scheduler sent command 0
02/19/2018 16:19:08;0100;Server@node2;Req;;Type 21 request received from Scheduler@node2.supernodexp.hpc, sock=20
02/19/2018 16:19:08;0100;Server@node2;Req;;Type 81 request received from Scheduler@node2.supernodexp.hpc, sock=20
02/19/2018 16:19:08;0100;Server@node2;Req;;Type 71 request received from Scheduler@node2.supernodexp.hpc, sock=20
02/19/2018 16:19:08;0100;Server@node2;Req;;Type 58 request received from Scheduler@node2.supernodexp.hpc, sock=20
02/19/2018 16:19:08;0100;Server@node2;Req;;Type 20 request received from Scheduler@node2.supernodexp.hpc, sock=20
02/19/2018 16:19:08;0100;Server@node2;Req;;Type 51 request received from Scheduler@node2.supernodexp.hpc, sock=20
02/19/2018 16:19:08;0100;Server@node2;Req;;Type 11 request received from Scheduler@node2.supernodexp.hpc, sock=20
02/19/2018 16:19:08;0008;Server@node2;Job;3635.node2.supernodexp.hpc;Job Modified at request of Scheduler@node2.supernodexp.hpc
02/19/2018 16:19:32;0100;Server@node2;Req;;Type 1 request received from ctminh@node2.supernodexp.hpc, sock=16
02/19/2018 16:19:32;0100;Server@node2;Req;;Type 3 request received from ctminh@node2.supernodexp.hpc, sock=16
02/19/2018 16:19:32;0100;Server@node2;Req;;Type 5 request received from ctminh@node2.supernodexp.hpc, sock=16
02/19/2018 16:19:32;0100;Server@node2;Job;3636.node2.supernodexp.hpc;enqueuing into workq, state 1 hop 1
02/19/2018 16:19:32;0008;Server@node2;Job;3636.node2.supernodexp.hpc;Job Queued at request of ctminh@node2.supernodexp.hpc, owner = ctminh@node2.supernodexp.hpc, job name = telemac1, queue = workq
02/19/2018 16:19:32;0040;Server@node2;Svr;node2.supernodexp.hpc;Scheduler sent command 1
02/19/2018 16:19:32;0040;Server@node2;Svr;node2.supernodexp.hpc;Scheduler sent command 0
02/19/2018 16:19:32;0100;Server@node2;Req;;Type 21 request received from Scheduler@node2.supernodexp.hpc, sock=20
02/19/2018 16:19:32;0100;Server@node2;Req;;Type 81 request received from Scheduler@node2.supernodexp.hpc, sock=20
02/19/2018 16:19:32;0100;Server@node2;Req;;Type 71 request received from Scheduler@node2.supernodexp.hpc, sock=20
02/19/2018 16:19:32;0100;Server@node2;Req;;Type 58 request received from Scheduler@node2.supernodexp.hpc, sock=20
02/19/2018 16:19:32;0100;Server@node2;Req;;Type 20 request received from Scheduler@node2.supernodexp.hpc, sock=20
02/19/2018 16:19:32;0100;Server@node2;Req;;Type 51 request received from Scheduler@node2.supernodexp.hpc, sock=20
02/19/2018 16:19:32;0100;Server@node2;Req;;Type 11 request received from Scheduler@node2.supernodexp.hpc, sock=20
02/19/2018 16:19:32;0008;Server@node2;Job;3634.node2.supernodexp.hpc;Job Modified at request of Scheduler@node2.supernodexp.hpc
02/19/2018 16:19:32;0100;Server@node2;Req;;Type 11 request received from Scheduler@node2.supernodexp.hpc, sock=20
02/19/2018 16:19:32;0008;Server@node2;Job;3636.node2.supernodexp.hpc;Job Modified at request of Scheduler@node2.supernodexp.hpc
02/19/2018 16:19:36;0080;Server@node2;Job;3632.node2.supernodexp.hpc;Obit received momhop:1 serverhop:1 state:4 substate:42
02/19/2018 16:19:37;0010;Server@node2;Job;3632.node2.supernodexp.hpc;Exit_status=0 resources_used.cpupercent=1316 resources_used.cput=00:14:47 resources_used.mem=95016kb resources_used.ncpus=16 resources_used.vmem=1468340kb resources_used.walltime=00:00:58
02/19/2018 16:19:37;0100;Server@node2;Job;3632.node2.supernodexp.hpc;dequeuing from workq, state 5
02/19/2018 16:19:37;0040;Server@node2;Svr;node2.supernodexp.hpc;Scheduler sent command 2
02/19/2018 16:19:37;0040;Server@node2;Svr;node2.supernodexp.hpc;Scheduler sent command 0
02/19/2018 16:19:37;0100;Server@node2;Req;;Type 21 request received from Scheduler@node2.supernodexp.hpc, sock=20
02/19/2018 16:19:37;0100;Server@node2;Req;;Type 81 request received from Scheduler@node2.supernodexp.hpc, sock=20
02/19/2018 16:19:37;0100;Server@node2;Req;;Type 71 request received from Scheduler@node2.supernodexp.hpc, sock=20
02/19/2018 16:19:37;0100;Server@node2;Req;;Type 58 request received from Scheduler@node2.supernodexp.hpc, sock=20
02/19/2018 16:19:37;0100;Server@node2;Req;;Type 20 request received from Scheduler@node2.supernodexp.hpc, sock=20
02/19/2018 16:19:37;0100;Server@node2;Req;;Type 51 request received from Scheduler@node2.supernodexp.hpc, sock=20
02/19/2018 16:19:37;0100;Server@node2;Req;;Type 23 request received from Scheduler@node2.supernodexp.hpc, sock=20
02/19/2018 16:19:37;0008;Server@node2;Job;3636.node2.supernodexp.hpc;Job Run at request of Scheduler@node2.supernodexp.hpc on exec_vnode (node14:ncpus=24:mem=2097152kb)
02/19/2018 16:19:37;0001;Server@node2;Svr;Server@node2;Success (0) in req_runjob2, return value of svr_startjob is 0
02/19/2018 16:19:37;0100;Server@node2;Req;;Type 11 request received from Scheduler@node2.supernodexp.hpc, sock=20
02/19/2018 16:19:37;0008;Server@node2;Job;3634.node2.supernodexp.hpc;Job Modified at request of Scheduler@node2.supernodexp.hpc
02/19/2018 16:19:43;0100;Server@node2;Req;;Type 1 request received from ctminh@node2.supernodexp.hpc, sock=16
02/19/2018 16:19:43;0100;Server@node2;Req;;Type 3 request received from ctminh@node2.supernodexp.hpc, sock=16
02/19/2018 16:19:43;0100;Server@node2;Req;;Type 5 request received from ctminh@node2.supernodexp.hpc, sock=16
02/19/2018 16:19:43;0100;Server@node2;Job;3637.node2.supernodexp.hpc;enqueuing into workq, state 1 hop 1
02/19/2018 16:19:43;0008;Server@node2;Job;3637.node2.supernodexp.hpc;Job Queued at request of ctminh@node2.supernodexp.hpc, owner = ctminh@node2.supernodexp.hpc, job name = matrix-x-vector, queue = workq
02/19/2018 16:19:43;0040;Server@node2;Svr;node2.supernodexp.hpc;Scheduler sent command 1
02/19/2018 16:19:43;0040;Server@node2;Svr;node2.supernodexp.hpc;Scheduler sent command 0
02/19/2018 16:19:43;0100;Server@node2;Req;;Type 21 request received from Scheduler@node2.supernodexp.hpc, sock=20
02/19/2018 16:19:43;0100;Server@node2;Req;;Type 81 request received from Scheduler@node2.supernodexp.hpc, sock=20
02/19/2018 16:19:43;0100;Server@node2;Req;;Type 71 request received from Scheduler@node2.supernodexp.hpc, sock=20
02/19/2018 16:19:43;0100;Server@node2;Req;;Type 58 request received from Scheduler@node2.supernodexp.hpc, sock=20
02/19/2018 16:19:43;0100;Server@node2;Req;;Type 20 request received from Scheduler@node2.supernodexp.hpc, sock=20
02/19/2018 16:19:43;0100;Server@node2;Req;;Type 51 request received from Scheduler@node2.supernodexp.hpc, sock=20
02/19/2018 16:19:43;0100;Server@node2;Req;;Type 11 request received from Scheduler@node2.supernodexp.hpc, sock=20
02/19/2018 16:19:43;0008;Server@node2;Job;3637.node2.supernodexp.hpc;Job Modified at request of Scheduler@node2.supernodexp.hpc
02/19/2018 16:19:53;0100;Server@node2;Req;;Type 1 request received from ctminh@node2.supernodexp.hpc, sock=16
02/19/2018 16:19:53;0100;Server@node2;Req;;Type 3 request received from ctminh@node2.supernodexp.hpc, sock=16
02/19/2018 16:19:53;0100;Server@node2;Req;;Type 5 request received from ctminh@node2.supernodexp.hpc, sock=16
02/19/2018 16:19:53;0100;Server@node2;Job;3638.node2.supernodexp.hpc;enqueuing into workq, state 1 hop 1
02/19/2018 16:19:53;0008;Server@node2;Job;3638.node2.supernodexp.hpc;Job Queued at request of ctminh@node2.supernodexp.hpc, owner = ctminh@node2.supernodexp.hpc, job name = telemac3, queue = workq
02/19/2018 16:19:53;0040;Server@node2;Svr;node2.supernodexp.hpc;Scheduler sent command 1
02/19/2018 16:19:53;0040;Server@node2;Svr;node2.supernodexp.hpc;Scheduler sent command 0
02/19/2018 16:19:53;0100;Server@node2;Req;;Type 21 request received from Scheduler@node2.supernodexp.hpc, sock=20
02/19/2018 16:19:53;0100;Server@node2;Req;;Type 81 request received from Scheduler@node2.supernodexp.hpc, sock=20
02/19/2018 16:19:53;0100;Server@node2;Req;;Type 71 request received from Scheduler@node2.supernodexp.hpc, sock=20
02/19/2018 16:19:53;0100;Server@node2;Req;;Type 58 request received from Scheduler@node2.supernodexp.hpc, sock=20
02/19/2018 16:19:53;0100;Server@node2;Req;;Type 20 request received from Scheduler@node2.supernodexp.hpc, sock=20
02/19/2018 16:19:53;0100;Server@node2;Req;;Type 51 request received from Scheduler@node2.supernodexp.hpc, sock=20
02/19/2018 16:19:54;0100;Server@node2;Req;;Type 11 request received from Scheduler@node2.supernodexp.hpc, sock=20
02/19/2018 16:19:54;0008;Server@node2;Job;3638.node2.supernodexp.hpc;Job Modified at request of Scheduler@node2.supernodexp.hpc
02/19/2018 16:19:54;0100;Server@node2;Req;;Type 1 request received from ctminh@node2.supernodexp.hpc, sock=16
02/19/2018 16:19:54;0100;Server@node2;Req;;Type 3 request received from ctminh@node2.supernodexp.hpc, sock=16
02/19/2018 16:19:54;0100;Server@node2;Req;;Type 5 request received from ctminh@node2.supernodexp.hpc, sock=16
02/19/2018 16:19:54;0100;Server@node2;Job;3639.node2.supernodexp.hpc;enqueuing into workq, state 1 hop 1
02/19/2018 16:19:54;0008;Server@node2;Job;3639.node2.supernodexp.hpc;Job Queued at request of ctminh@node2.supernodexp.hpc, owner = ctminh@node2.supernodexp.hpc, job name = vectorization, queue = workq
02/19/2018 16:19:54;0040;Server@node2;Svr;node2.supernodexp.hpc;Scheduler sent command 1
02/19/2018 16:19:54;0040;Server@node2;Svr;node2.supernodexp.hpc;Scheduler sent command 0
02/19/2018 16:19:54;0100;Server@node2;Req;;Type 21 request received from Scheduler@node2.supernodexp.hpc, sock=20
02/19/2018 16:19:54;0100;Server@node2;Req;;Type 81 request received from Scheduler@node2.supernodexp.hpc, sock=20
02/19/2018 16:19:54;0100;Server@node2;Req;;Type 71 request received from Scheduler@node2.supernodexp.hpc, sock=20
02/19/2018 16:19:54;0100;Server@node2;Req;;Type 58 request received from Scheduler@node2.supernodexp.hpc, sock=20
02/19/2018 16:19:55;0100;Server@node2;Req;;Type 20 request received from Scheduler@node2.supernodexp.hpc, sock=20
02/19/2018 16:19:55;0100;Server@node2;Req;;Type 51 request received from Scheduler@node2.supernodexp.hpc, sock=20
02/19/2018 16:19:55;0100;Server@node2;Req;;Type 11 request received from Scheduler@node2.supernodexp.hpc, sock=20
02/19/2018 16:19:55;0008;Server@node2;Job;3639.node2.supernodexp.hpc;Job Modified at request of Scheduler@node2.supernodexp.hpc
02/19/2018 16:20:50;0080;Server@node2;Job;3629.node2.supernodexp.hpc;Obit received momhop:1 serverhop:1 state:4 substate:42
02/19/2018 16:20:52;0010;Server@node2;Job;3629.node2.supernodexp.hpc;Exit_status=0 resources_used.cpupercent=1040 resources_used.cput=01:05:52 resources_used.mem=1642756kb resources_used.ncpus=24 resources_used.vmem=15000440kb resources_used.walltime=00:03:00
02/19/2018 16:20:52;0100;Server@node2;Job;3629.node2.supernodexp.hpc;dequeuing from workq, state 5
02/19/2018 16:20:52;0040;Server@node2;Svr;node2.supernodexp.hpc;Scheduler sent command 2
02/19/2018 16:20:52;0040;Server@node2;Svr;node2.supernodexp.hpc;Scheduler sent command 0
02/19/2018 16:20:52;0100;Server@node2;Req;;Type 21 request received from Scheduler@node2.supernodexp.hpc, sock=20
02/19/2018 16:20:52;0100;Server@node2;Req;;Type 81 request received from Scheduler@node2.supernodexp.hpc, sock=20
02/19/2018 16:20:52;0100;Server@node2;Req;;Type 71 request received from Scheduler@node2.supernodexp.hpc, sock=20
02/19/2018 16:20:52;0100;Server@node2;Req;;Type 58 request received from Scheduler@node2.supernodexp.hpc, sock=20
02/19/2018 16:20:52;0100;Server@node2;Req;;Type 20 request received from Scheduler@node2.supernodexp.hpc, sock=20
02/19/2018 16:20:52;0100;Server@node2;Req;;Type 51 request received from Scheduler@node2.supernodexp.hpc, sock=20
02/19/2018 16:20:52;0100;Server@node2;Req;;Type 11 request received from Scheduler@node2.supernodexp.hpc, sock=20
02/19/2018 16:20:52;0008;Server@node2;Job;3634.node2.supernodexp.hpc;Job Modified at request of Scheduler@node2.supernodexp.hpc
02/19/2018 16:20:54;0080;Server@node2;Job;3628.node2.supernodexp.hpc;Obit received momhop:1 serverhop:1 state:4 substate:42
02/19/2018 16:20:56;0010;Server@node2;Job;3628.node2.supernodexp.hpc;Exit_status=0 resources_used.cpupercent=2128 resources_used.cput=02:13:38 resources_used.mem=3250404kb resources_used.ncpus=48 resources_used.vmem=33619920kb resources_used.walltime=00:03:08
02/19/2018 16:20:56;0100;Server@node2;Job;3628.node2.supernodexp.hpc;dequeuing from workq, state 5
02/19/2018 16:20:56;0040;Server@node2;Svr;node2.supernodexp.hpc;Scheduler sent command 2
02/19/2018 16:20:56;0040;Server@node2;Svr;node2.supernodexp.hpc;Scheduler sent command 0
02/19/2018 16:20:56;0100;Server@node2;Req;;Type 21 request received from Scheduler@node2.supernodexp.hpc, sock=16
02/19/2018 16:20:56;0100;Server@node2;Req;;Type 81 request received from Scheduler@node2.supernodexp.hpc, sock=16
02/19/2018 16:20:56;0100;Server@node2;Req;;Type 71 request received from Scheduler@node2.supernodexp.hpc, sock=16
02/19/2018 16:20:56;0100;Server@node2;Req;;Type 58 request received from Scheduler@node2.supernodexp.hpc, sock=16
02/19/2018 16:20:56;0100;Server@node2;Req;;Type 20 request received from Scheduler@node2.supernodexp.hpc, sock=16
02/19/2018 16:20:56;0100;Server@node2;Req;;Type 51 request received from Scheduler@node2.supernodexp.hpc, sock=16
02/19/2018 16:20:56;0100;Server@node2;Req;;Type 23 request received from Scheduler@node2.supernodexp.hpc, sock=16
02/19/2018 16:20:56;0008;Server@node2;Job;3634.node2.supernodexp.hpc;Job Run at request of Scheduler@node2.supernodexp.hpc on exec_vnode (node13:ncpus=24:mem=4194304kb)+(node13:ncpus=24:mem=4194304kb)
02/19/2018 16:20:56;0001;Server@node2;Svr;Server@node2;Success (0) in req_runjob2, return value of svr_startjob is 0
02/19/2018 16:20:56;0100;Server@node2;Req;;Type 11 request received from Scheduler@node2.supernodexp.hpc, sock=16
02/19/2018 16:20:56;0008;Server@node2;Job;3638.node2.supernodexp.hpc;Job Modified at request of Scheduler@node2.supernodexp.hpc
02/19/2018 16:21:54;0080;Server@node2;Job;3636.node2.supernodexp.hpc;Obit received momhop:1 serverhop:1 state:4 substate:42
02/19/2018 16:21:55;0010;Server@node2;Job;3636.node2.supernodexp.hpc;Exit_status=0 resources_used.cpupercent=809 resources_used.cput=00:46:22 resources_used.mem=1642804kb resources_used.ncpus=24 resources_used.vmem=15000536kb resources_used.walltime=00:02:17
02/19/2018 16:21:55;0100;Server@node2;Job;3636.node2.supernodexp.hpc;dequeuing from workq, state 5
02/19/2018 16:21:55;0040;Server@node2;Svr;node2.supernodexp.hpc;Scheduler sent command 2
02/19/2018 16:21:55;0040;Server@node2;Svr;node2.supernodexp.hpc;Scheduler sent command 0
02/19/2018 16:21:55;0100;Server@node2;Req;;Type 21 request received from Scheduler@node2.supernodexp.hpc, sock=16
02/19/2018 16:21:55;0100;Server@node2;Req;;Type 81 request received from Scheduler@node2.supernodexp.hpc, sock=16
02/19/2018 16:21:55;0100;Server@node2;Req;;Type 71 request received from Scheduler@node2.supernodexp.hpc, sock=16
02/19/2018 16:21:55;0100;Server@node2;Req;;Type 58 request received from Scheduler@node2.supernodexp.hpc, sock=16
02/19/2018 16:21:55;0100;Server@node2;Req;;Type 20 request received from Scheduler@node2.supernodexp.hpc, sock=16
02/19/2018 16:21:55;0100;Server@node2;Req;;Type 51 request received from Scheduler@node2.supernodexp.hpc, sock=16
02/19/2018 16:21:56;0100;Server@node2;Req;;Type 23 request received from Scheduler@node2.supernodexp.hpc, sock=16
02/19/2018 16:21:56;0008;Server@node2;Job;3638.node2.supernodexp.hpc;Job Run at request of Scheduler@node2.supernodexp.hpc on exec_vnode (node14:ncpus=24:mem=4194304kb)+(node14:ncpus=24:mem=4194304kb)
02/19/2018 16:21:56;0001;Server@node2;Svr;Server@node2;Success (0) in req_runjob2, return value of svr_startjob is 0
02/19/2018 16:21:56;0100;Server@node2;Req;;Type 11 request received from Scheduler@node2.supernodexp.hpc, sock=16
02/19/2018 16:21:56;0008;Server@node2;Job;3631.node2.supernodexp.hpc;Job Modified at request of Scheduler@node2.supernodexp.hpc
02/19/2018 16:23:34;0080;Server@node2;Job;3634.node2.supernodexp.hpc;Obit received momhop:1 serverhop:1 state:4 substate:42
02/19/2018 16:23:35;0010;Server@node2;Job;3634.node2.supernodexp.hpc;Exit_status=0 resources_used.cpupercent=1856 resources_used.cput=01:51:40 resources_used.mem=3250556kb resources_used.ncpus=48 resources_used.vmem=33619972kb resources_used.walltime=00:02:38
02/19/2018 16:23:35;0100;Server@node2;Job;3634.node2.supernodexp.hpc;dequeuing from workq, state 5
02/19/2018 16:23:35;0040;Server@node2;Svr;node2.supernodexp.hpc;Scheduler sent command 2
02/19/2018 16:23:35;0040;Server@node2;Svr;node2.supernodexp.hpc;Scheduler sent command 0
02/19/2018 16:23:35;0100;Server@node2;Req;;Type 21 request received from Scheduler@node2.supernodexp.hpc, sock=16
02/19/2018 16:23:35;0100;Server@node2;Req;;Type 81 request received from Scheduler@node2.supernodexp.hpc, sock=16
02/19/2018 16:23:35;0100;Server@node2;Req;;Type 71 request received from Scheduler@node2.supernodexp.hpc, sock=16
02/19/2018 16:23:35;0100;Server@node2;Req;;Type 58 request received from Scheduler@node2.supernodexp.hpc, sock=16
02/19/2018 16:23:35;0100;Server@node2;Req;;Type 20 request received from Scheduler@node2.supernodexp.hpc, sock=16
02/19/2018 16:23:35;0100;Server@node2;Req;;Type 51 request received from Scheduler@node2.supernodexp.hpc, sock=16
02/19/2018 16:23:35;0100;Server@node2;Req;;Type 23 request received from Scheduler@node2.supernodexp.hpc, sock=16
02/19/2018 16:23:35;0008;Server@node2;Job;3631.node2.supernodexp.hpc;Job Run at request of Scheduler@node2.supernodexp.hpc on exec_vnode (node13:ncpus=12:mem=1048576kb)
02/19/2018 16:23:35;0001;Server@node2;Svr;Server@node2;Success (0) in req_runjob2, return value of svr_startjob is 0
02/19/2018 16:23:35;0100;Server@node2;Req;;Type 23 request received from Scheduler@node2.supernodexp.hpc, sock=16
02/19/2018 16:23:35;0008;Server@node2;Job;3635.node2.supernodexp.hpc;Job Run at request of Scheduler@node2.supernodexp.hpc on exec_vnode (node13:ncpus=12:mem=1048576kb)
02/19/2018 16:23:35;0001;Server@node2;Svr;Server@node2;Success (0) in req_runjob2, return value of svr_startjob is 0
02/19/2018 16:23:35;0100;Server@node2;Req;;Type 23 request received from Scheduler@node2.supernodexp.hpc, sock=16
02/19/2018 16:23:35;0008;Server@node2;Job;3633.node2.supernodexp.hpc;Job Run at request of Scheduler@node2.supernodexp.hpc on exec_vnode (node13:ncpus=12:mem=1048576kb)
02/19/2018 16:23:35;0001;Server@node2;Svr;Server@node2;Success (0) in req_runjob2, return value of svr_startjob is 0
02/19/2018 16:23:35;0100;Server@node2;Req;;Type 23 request received from Scheduler@node2.supernodexp.hpc, sock=16
02/19/2018 16:23:35;0008;Server@node2;Job;3639.node2.supernodexp.hpc;Job Run at request of Scheduler@node2.supernodexp.hpc on exec_vnode (node13:ncpus=12:mem=1048576kb)
02/19/2018 16:23:35;0001;Server@node2;Svr;Server@node2;Success (0) in req_runjob2, return value of svr_startjob is 0
02/19/2018 16:23:35;0100;Server@node2;Req;;Type 11 request received from Scheduler@node2.supernodexp.hpc, sock=16
02/19/2018 16:23:35;0008;Server@node2;Job;3630.node2.supernodexp.hpc;Job Modified at request of Scheduler@node2.supernodexp.hpc
02/19/2018 16:23:42;0080;Server@node2;Job;3639.node2.supernodexp.hpc;Obit received momhop:1 serverhop:1 state:4 substate:42
02/19/2018 16:23:42;0080;Server@node2;Job;3633.node2.supernodexp.hpc;Obit received momhop:1 serverhop:1 state:4 substate:42
02/19/2018 16:23:44;0010;Server@node2;Job;3633.node2.supernodexp.hpc;Exit_status=0 resources_used.cpupercent=1200 resources_used.cput=00:01:19 resources_used.mem=28360kb resources_used.ncpus=12 resources_used.vmem=1125532kb resources_used.walltime=00:00:07
02/19/2018 16:23:44;0100;Server@node2;Job;3633.node2.supernodexp.hpc;dequeuing from workq, state 5
02/19/2018 16:23:44;0010;Server@node2;Job;3639.node2.supernodexp.hpc;Exit_status=0 resources_used.cpupercent=1201 resources_used.cput=00:01:16 resources_used.mem=0kb resources_used.ncpus=12 resources_used.vmem=0kb resources_used.walltime=00:00:06
02/19/2018 16:23:44;0100;Server@node2;Job;3639.node2.supernodexp.hpc;dequeuing from workq, state 5
02/19/2018 16:23:44;0040;Server@node2;Svr;node2.supernodexp.hpc;Scheduler sent command 2
02/19/2018 16:23:44;0040;Server@node2;Svr;node2.supernodexp.hpc;Scheduler sent command 0
02/19/2018 16:23:44;0100;Server@node2;Req;;Type 21 request received from Scheduler@node2.supernodexp.hpc, sock=16
02/19/2018 16:23:44;0100;Server@node2;Req;;Type 81 request received from Scheduler@node2.supernodexp.hpc, sock=16
02/19/2018 16:23:44;0100;Server@node2;Req;;Type 71 request received from Scheduler@node2.supernodexp.hpc, sock=16
02/19/2018 16:23:44;0100;Server@node2;Req;;Type 58 request received from Scheduler@node2.supernodexp.hpc, sock=16
02/19/2018 16:23:44;0100;Server@node2;Req;;Type 20 request received from Scheduler@node2.supernodexp.hpc, sock=16
02/19/2018 16:23:44;0100;Server@node2;Req;;Type 51 request received from Scheduler@node2.supernodexp.hpc, sock=16
02/19/2018 16:23:44;0100;Server@node2;Req;;Type 23 request received from Scheduler@node2.supernodexp.hpc, sock=16
02/19/2018 16:23:44;0008;Server@node2;Job;3630.node2.supernodexp.hpc;Job Run at request of Scheduler@node2.supernodexp.hpc on exec_vnode (node13:ncpus=24:mem=1048576kb)
02/19/2018 16:23:44;0001;Server@node2;Svr;Server@node2;Success (0) in req_runjob2, return value of svr_startjob is 0
02/19/2018 16:23:44;0100;Server@node2;Req;;Type 11 request received from Scheduler@node2.supernodexp.hpc, sock=16
02/19/2018 16:23:44;0008;Server@node2;Job;3637.node2.supernodexp.hpc;Job Modified at request of Scheduler@node2.supernodexp.hpc
02/19/2018 16:23:44;0080;Server@node2;Job;3631.node2.supernodexp.hpc;Obit received momhop:1 serverhop:1 state:4 substate:42
02/19/2018 16:23:44;0080;Server@node2;Job;3635.node2.supernodexp.hpc;Obit received momhop:1 serverhop:1 state:4 substate:42
02/19/2018 16:23:45;0080;Server@node2;Job;3630.node2.supernodexp.hpc;Obit received momhop:1 serverhop:1 state:4 substate:42
02/19/2018 16:23:46;0010;Server@node2;Job;3631.node2.supernodexp.hpc;Exit_status=0 resources_used.cpupercent=100 resources_used.cput=00:00:08 resources_used.mem=11624kb resources_used.ncpus=12 resources_used.vmem=343400kb resources_used.walltime=00:00:09
02/19/2018 16:23:46;0100;Server@node2;Job;3631.node2.supernodexp.hpc;dequeuing from workq, state 5
02/19/2018 16:23:46;0010;Server@node2;Job;3635.node2.supernodexp.hpc;Exit_status=0 resources_used.cpupercent=100 resources_used.cput=00:00:08 resources_used.mem=11624kb resources_used.ncpus=12 resources_used.vmem=343400kb resources_used.walltime=00:00:08
02/19/2018 16:23:46;0100;Server@node2;Job;3635.node2.supernodexp.hpc;dequeuing from workq, state 5
02/19/2018 16:23:46;0040;Server@node2;Svr;node2.supernodexp.hpc;Scheduler sent command 2
02/19/2018 16:23:46;0040;Server@node2;Svr;node2.supernodexp.hpc;Scheduler sent command 0
02/19/2018 16:23:46;0100;Server@node2;Req;;Type 21 request received from Scheduler@node2.supernodexp.hpc, sock=16
02/19/2018 16:23:46;0100;Server@node2;Req;;Type 81 request received from Scheduler@node2.supernodexp.hpc, sock=16
02/19/2018 16:23:46;0100;Server@node2;Req;;Type 71 request received from Scheduler@node2.supernodexp.hpc, sock=16
02/19/2018 16:23:46;0100;Server@node2;Req;;Type 58 request received from Scheduler@node2.supernodexp.hpc, sock=16
02/19/2018 16:23:46;0100;Server@node2;Req;;Type 20 request received from Scheduler@node2.supernodexp.hpc, sock=16
02/19/2018 16:23:46;0100;Server@node2;Req;;Type 51 request received from Scheduler@node2.supernodexp.hpc, sock=16
02/19/2018 16:23:46;0100;Server@node2;Req;;Type 23 request received from Scheduler@node2.supernodexp.hpc, sock=16
02/19/2018 16:23:46;0008;Server@node2;Job;3637.node2.supernodexp.hpc;Job Run at request of Scheduler@node2.supernodexp.hpc on exec_vnode (node13:ncpus=16:mem=5242880kb)
02/19/2018 16:23:46;0001;Server@node2;Svr;Server@node2;Success (0) in req_runjob2, return value of svr_startjob is 0
02/19/2018 16:23:47;0010;Server@node2;Job;3630.node2.supernodexp.hpc;Exit_status=0 resources_used.cpupercent=607 resources_used.cput=00:00:36 resources_used.mem=1298312kb resources_used.ncpus=24 resources_used.vmem=3151052kb resources_used.walltime=00:00:02
02/19/2018 16:23:47;0100;Server@node2;Job;3630.node2.supernodexp.hpc;dequeuing from workq, state 5
02/19/2018 16:23:47;0040;Server@node2;Svr;node2.supernodexp.hpc;Scheduler sent command 2
02/19/2018 16:23:47;0040;Server@node2;Svr;node2.supernodexp.hpc;Scheduler sent command 0
02/19/2018 16:23:47;0100;Server@node2;Req;;Type 21 request received from Scheduler@node2.supernodexp.hpc, sock=16
02/19/2018 16:23:47;0100;Server@node2;Req;;Type 81 request received from Scheduler@node2.supernodexp.hpc, sock=16
02/19/2018 16:23:47;0100;Server@node2;Req;;Type 71 request received from Scheduler@node2.supernodexp.hpc, sock=16
02/19/2018 16:23:47;0100;Server@node2;Req;;Type 58 request received from Scheduler@node2.supernodexp.hpc, sock=16
02/19/2018 16:23:47;0080;Server@node2;Job;3637.node2.supernodexp.hpc;Obit received momhop:1 serverhop:1 state:4 substate:42
02/19/2018 16:23:47;0100;Server@node2;Req;;Type 20 request received from Scheduler@node2.supernodexp.hpc, sock=16
02/19/2018 16:23:47;0100;Server@node2;Req;;Type 51 request received from Scheduler@node2.supernodexp.hpc, sock=16
02/19/2018 16:23:48;0010;Server@node2;Job;3637.node2.supernodexp.hpc;Exit_status=0 resources_used.cpupercent=700 resources_used.cput=00:00:09 resources_used.mem=4209684kb resources_used.ncpus=16 resources_used.vmem=5507028kb resources_used.walltime=00:00:01
02/19/2018 16:23:48;0100;Server@node2;Job;3637.node2.supernodexp.hpc;dequeuing from workq, state 5
02/19/2018 16:23:48;0040;Server@node2;Svr;node2.supernodexp.hpc;Scheduler sent command 2
02/19/2018 16:23:48;0040;Server@node2;Svr;node2.supernodexp.hpc;Scheduler sent command 0
02/19/2018 16:23:48;0100;Server@node2;Req;;Type 21 request received from Scheduler@node2.supernodexp.hpc, sock=16
02/19/2018 16:23:48;0100;Server@node2;Req;;Type 81 request received from Scheduler@node2.supernodexp.hpc, sock=16
02/19/2018 16:23:48;0100;Server@node2;Req;;Type 71 request received from Scheduler@node2.supernodexp.hpc, sock=16
02/19/2018 16:23:48;0100;Server@node2;Req;;Type 58 request received from Scheduler@node2.supernodexp.hpc, sock=16
02/19/2018 16:23:48;0100;Server@node2;Req;;Type 20 request received from Scheduler@node2.supernodexp.hpc, sock=16
02/19/2018 16:23:48;0100;Server@node2;Req;;Type 51 request received from Scheduler@node2.supernodexp.hpc, sock=16
02/19/2018 16:24:38;0080;Server@node2;Job;3638.node2.supernodexp.hpc;Obit received momhop:1 serverhop:1 state:4 substate:42
02/19/2018 16:24:40;0010;Server@node2;Job;3638.node2.supernodexp.hpc;Exit_status=0 resources_used.cpupercent=1906 resources_used.cput=01:55:20 resources_used.mem=3253432kb resources_used.ncpus=48 resources_used.vmem=33722080kb resources_used.walltime=00:02:43
02/19/2018 16:24:40;0100;Server@node2;Job;3638.node2.supernodexp.hpc;dequeuing from workq, state 5
02/19/2018 16:24:40;0040;Server@node2;Svr;node2.supernodexp.hpc;Scheduler sent command 2
02/19/2018 16:24:40;0040;Server@node2;Svr;node2.supernodexp.hpc;Scheduler sent command 0
02/19/2018 16:24:40;0100;Server@node2;Req;;Type 21 request received from Scheduler@node2.supernodexp.hpc, sock=16
02/19/2018 16:24:40;0100;Server@node2;Req;;Type 81 request received from Scheduler@node2.supernodexp.hpc, sock=16
02/19/2018 16:24:40;0100;Server@node2;Req;;Type 71 request received from Scheduler@node2.supernodexp.hpc, sock=16
02/19/2018 16:24:40;0100;Server@node2;Req;;Type 58 request received from Scheduler@node2.supernodexp.hpc, sock=16
02/19/2018 16:24:40;0100;Server@node2;Req;;Type 20 request received from Scheduler@node2.supernodexp.hpc, sock=16
02/19/2018 16:24:40;0100;Server@node2;Req;;Type 51 request received from Scheduler@node2.supernodexp.hpc, sock=16
02/19/2018 16:24:55;0100;Server@node2;Req;;Type 0 request received from ctminh@node2.supernodexp.hpc, sock=16
02/19/2018 16:24:55;0100;Server@node2;Req;;Type 49 request received from ctminh@node2.supernodexp.hpc, sock=20
02/19/2018 16:24:55;0100;Server@node2;Req;;Type 21 request received from ctminh@node2.supernodexp.hpc, sock=16
02/19/2018 16:24:55;0100;Server@node2;Req;;Type 1 request received from ctminh@node2.supernodexp.hpc, sock=16
02/19/2018 16:24:55;0100;Server@node2;Req;;Type 3 request received from ctminh@node2.supernodexp.hpc, sock=16
02/19/2018 16:24:55;0100;Server@node2;Req;;Type 5 request received from ctminh@node2.supernodexp.hpc, sock=16
02/19/2018 16:24:55;0100;Server@node2;Job;3640.node2.supernodexp.hpc;enqueuing into workq, state 1 hop 1
02/19/2018 16:24:55;0008;Server@node2;Job;3640.node2.supernodexp.hpc;Job Queued at request of ctminh@node2.supernodexp.hpc, owner = ctminh@node2.supernodexp.hpc, job name = matrix-x-vector, queue = workq
02/19/2018 16:24:55;0040;Server@node2;Svr;node2.supernodexp.hpc;Scheduler sent command 1
02/19/2018 16:24:55;0040;Server@node2;Svr;node2.supernodexp.hpc;Scheduler sent command 0
02/19/2018 16:24:55;0100;Server@node2;Req;;Type 21 request received from Scheduler@node2.supernodexp.hpc, sock=20
02/19/2018 16:24:55;0100;Server@node2;Req;;Type 81 request received from Scheduler@node2.supernodexp.hpc, sock=20
02/19/2018 16:24:55;0100;Server@node2;Req;;Type 71 request received from Scheduler@node2.supernodexp.hpc, sock=20
02/19/2018 16:24:55;0100;Server@node2;Req;;Type 58 request received from Scheduler@node2.supernodexp.hpc, sock=20
02/19/2018 16:24:55;0100;Server@node2;Req;;Type 20 request received from Scheduler@node2.supernodexp.hpc, sock=20
02/19/2018 16:24:55;0100;Server@node2;Req;;Type 51 request received from Scheduler@node2.supernodexp.hpc, sock=20
02/19/2018 16:24:55;0100;Server@node2;Req;;Type 23 request received from Scheduler@node2.supernodexp.hpc, sock=20
02/19/2018 16:24:55;0008;Server@node2;Job;3640.node2.supernodexp.hpc;Job Run at request of Scheduler@node2.supernodexp.hpc on exec_vnode (node13:ncpus=16:mem=5242880kb)
02/19/2018 16:24:55;0001;Server@node2;Svr;Server@node2;Success (0) in req_runjob2, return value of svr_startjob is 0
02/19/2018 16:24:56;0080;Server@node2;Job;3640.node2.supernodexp.hpc;Obit received momhop:1 serverhop:1 state:4 substate:42
02/19/2018 16:24:57;0010;Server@node2;Job;3640.node2.supernodexp.hpc;Exit_status=0 resources_used.cpupercent=900 resources_used.cput=00:00:09 resources_used.mem=0kb resources_used.ncpus=16 resources_used.vmem=0kb resources_used.walltime=00:00:03
02/19/2018 16:24:57;0100;Server@node2;Job;3640.node2.supernodexp.hpc;dequeuing from workq, state 5
02/19/2018 16:24:57;0040;Server@node2;Svr;node2.supernodexp.hpc;Scheduler sent command 2
02/19/2018 16:24:57;0040;Server@node2;Svr;node2.supernodexp.hpc;Scheduler sent command 0
02/19/2018 16:24:57;0100;Server@node2;Req;;Type 21 request received from Scheduler@node2.supernodexp.hpc, sock=20
02/19/2018 16:24:57;0100;Server@node2;Req;;Type 81 request received from Scheduler@node2.supernodexp.hpc, sock=20
02/19/2018 16:24:57;0100;Server@node2;Req;;Type 71 request received from Scheduler@node2.supernodexp.hpc, sock=20
02/19/2018 16:24:57;0100;Server@node2;Req;;Type 58 request received from Scheduler@node2.supernodexp.hpc, sock=20
02/19/2018 16:24:57;0100;Server@node2;Req;;Type 20 request received from Scheduler@node2.supernodexp.hpc, sock=20
02/19/2018 16:24:57;0100;Server@node2;Req;;Type 51 request received from Scheduler@node2.supernodexp.hpc, sock=20
02/19/2018 16:25:02;0100;Server@node2;Req;;Type 1 request received from ctminh@node2.supernodexp.hpc, sock=16
02/19/2018 16:25:02;0100;Server@node2;Req;;Type 3 request received from ctminh@node2.supernodexp.hpc, sock=16
02/19/2018 16:25:02;0100;Server@node2;Req;;Type 5 request received from ctminh@node2.supernodexp.hpc, sock=16
02/19/2018 16:25:02;0100;Server@node2;Job;3641.node2.supernodexp.hpc;enqueuing into workq, state 1 hop 1
02/19/2018 16:25:02;0008;Server@node2;Job;3641.node2.supernodexp.hpc;Job Queued at request of ctminh@node2.supernodexp.hpc, owner = ctminh@node2.supernodexp.hpc, job name = qe_mic_test, queue = workq
02/19/2018 16:25:02;0040;Server@node2;Svr;node2.supernodexp.hpc;Scheduler sent command 1
02/19/2018 16:25:02;0040;Server@node2;Svr;node2.supernodexp.hpc;Scheduler sent command 0
02/19/2018 16:25:02;0100;Server@node2;Req;;Type 21 request received from Scheduler@node2.supernodexp.hpc, sock=20
02/19/2018 16:25:02;0100;Server@node2;Req;;Type 81 request received from Scheduler@node2.supernodexp.hpc, sock=20
02/19/2018 16:25:02;0100;Server@node2;Req;;Type 71 request received from Scheduler@node2.supernodexp.hpc, sock=20
02/19/2018 16:25:02;0100;Server@node2;Req;;Type 58 request received from Scheduler@node2.supernodexp.hpc, sock=20
02/19/2018 16:25:02;0100;Server@node2;Req;;Type 20 request received from Scheduler@node2.supernodexp.hpc, sock=20
02/19/2018 16:25:02;0100;Server@node2;Req;;Type 51 request received from Scheduler@node2.supernodexp.hpc, sock=20
02/19/2018 16:25:02;0100;Server@node2;Req;;Type 23 request received from Scheduler@node2.supernodexp.hpc, sock=20
02/19/2018 16:25:02;0008;Server@node2;Job;3641.node2.supernodexp.hpc;Job Run at request of Scheduler@node2.supernodexp.hpc on exec_vnode (node13:ncpus=32:nmics=1:mem=16777216kb)
02/19/2018 16:25:02;0001;Server@node2;Svr;Server@node2;Success (0) in req_runjob2, return value of svr_startjob is 0
02/19/2018 16:25:19;0100;Server@node2;Req;;Type 1 request received from ctminh@node2.supernodexp.hpc, sock=16
02/19/2018 16:25:19;0100;Server@node2;Req;;Type 3 request received from ctminh@node2.supernodexp.hpc, sock=16
02/19/2018 16:25:19;0100;Server@node2;Req;;Type 5 request received from ctminh@node2.supernodexp.hpc, sock=16
02/19/2018 16:25:19;0100;Server@node2;Job;3642.node2.supernodexp.hpc;enqueuing into workq, state 1 hop 1
02/19/2018 16:25:19;0008;Server@node2;Job;3642.node2.supernodexp.hpc;Job Queued at request of ctminh@node2.supernodexp.hpc, owner = ctminh@node2.supernodexp.hpc, job name = matrix-x-vector, queue = workq
02/19/2018 16:25:19;0040;Server@node2;Svr;node2.supernodexp.hpc;Scheduler sent command 1
02/19/2018 16:25:19;0040;Server@node2;Svr;node2.supernodexp.hpc;Scheduler sent command 0
02/19/2018 16:25:19;0100;Server@node2;Req;;Type 21 request received from Scheduler@node2.supernodexp.hpc, sock=20
02/19/2018 16:25:19;0100;Server@node2;Req;;Type 81 request received from Scheduler@node2.supernodexp.hpc, sock=20
02/19/2018 16:25:19;0100;Server@node2;Req;;Type 71 request received from Scheduler@node2.supernodexp.hpc, sock=20
02/19/2018 16:25:19;0100;Server@node2;Req;;Type 58 request received from Scheduler@node2.supernodexp.hpc, sock=20
02/19/2018 16:25:19;0100;Server@node2;Req;;Type 1 request received from ctminh@node2.supernodexp.hpc, sock=16
02/19/2018 16:25:19;0100;Server@node2;Req;;Type 3 request received from ctminh@node2.supernodexp.hpc, sock=16
02/19/2018 16:25:19;0100;Server@node2;Req;;Type 5 request received from ctminh@node2.supernodexp.hpc, sock=16
02/19/2018 16:25:19;0100;Server@node2;Job;3643.node2.supernodexp.hpc;enqueuing into workq, state 1 hop 1
02/19/2018 16:25:19;0008;Server@node2;Job;3643.node2.supernodexp.hpc;Job Queued at request of ctminh@node2.supernodexp.hpc, owner = ctminh@node2.supernodexp.hpc, job name = vectorization, queue = workq
02/19/2018 16:25:19;0100;Server@node2;Req;;Type 20 request received from Scheduler@node2.supernodexp.hpc, sock=20
02/19/2018 16:25:19;0100;Server@node2;Req;;Type 51 request received from Scheduler@node2.supernodexp.hpc, sock=20
02/19/2018 16:25:19;0100;Server@node2;Req;;Type 23 request received from Scheduler@node2.supernodexp.hpc, sock=20
02/19/2018 16:25:19;0008;Server@node2;Job;3643.node2.supernodexp.hpc;Job Run at request of Scheduler@node2.supernodexp.hpc on exec_vnode (node13:ncpus=12:mem=1048576kb)
02/19/2018 16:25:19;0001;Server@node2;Svr;Server@node2;Success (0) in req_runjob2, return value of svr_startjob is 0
02/19/2018 16:25:19;0100;Server@node2;Req;;Type 23 request received from Scheduler@node2.supernodexp.hpc, sock=20
02/19/2018 16:25:19;0008;Server@node2;Job;3642.node2.supernodexp.hpc;Job Run at request of Scheduler@node2.supernodexp.hpc on exec_vnode (node14:ncpus=16:mem=5242880kb)
02/19/2018 16:25:19;0001;Server@node2;Svr;Server@node2;Success (0) in req_runjob2, return value of svr_startjob is 0
02/19/2018 16:25:19;0040;Server@node2;Svr;node2.supernodexp.hpc;Scheduler sent command 1
02/19/2018 16:25:19;0040;Server@node2;Svr;node2.supernodexp.hpc;Scheduler sent command 0
02/19/2018 16:25:19;0100;Server@node2;Req;;Type 21 request received from Scheduler@node2.supernodexp.hpc, sock=20
02/19/2018 16:25:19;0100;Server@node2;Req;;Type 81 request received from Scheduler@node2.supernodexp.hpc, sock=20
02/19/2018 16:25:19;0100;Server@node2;Req;;Type 71 request received from Scheduler@node2.supernodexp.hpc, sock=20
02/19/2018 16:25:19;0100;Server@node2;Req;;Type 58 request received from Scheduler@node2.supernodexp.hpc, sock=20
02/19/2018 16:25:19;0100;Server@node2;Req;;Type 20 request received from Scheduler@node2.supernodexp.hpc, sock=20
02/19/2018 16:25:19;0100;Server@node2;Req;;Type 51 request received from Scheduler@node2.supernodexp.hpc, sock=20
02/19/2018 16:25:20;0080;Server@node2;Job;3642.node2.supernodexp.hpc;Obit received momhop:1 serverhop:1 state:4 substate:42
02/19/2018 16:25:21;0010;Server@node2;Job;3642.node2.supernodexp.hpc;Exit_status=0 resources_used.cpupercent=900 resources_used.cput=00:00:09 resources_used.mem=0kb resources_used.ncpus=16 resources_used.vmem=0kb resources_used.walltime=00:00:01
02/19/2018 16:25:21;0100;Server@node2;Job;3642.node2.supernodexp.hpc;dequeuing from workq, state 5
02/19/2018 16:25:21;0040;Server@node2;Svr;node2.supernodexp.hpc;Scheduler sent command 2
02/19/2018 16:25:21;0040;Server@node2;Svr;node2.supernodexp.hpc;Scheduler sent command 0
02/19/2018 16:25:21;0100;Server@node2;Req;;Type 21 request received from Scheduler@node2.supernodexp.hpc, sock=20
02/19/2018 16:25:21;0100;Server@node2;Req;;Type 81 request received from Scheduler@node2.supernodexp.hpc, sock=20
02/19/2018 16:25:21;0100;Server@node2;Req;;Type 71 request received from Scheduler@node2.supernodexp.hpc, sock=20
02/19/2018 16:25:21;0100;Server@node2;Req;;Type 58 request received from Scheduler@node2.supernodexp.hpc, sock=20
02/19/2018 16:25:21;0100;Server@node2;Req;;Type 20 request received from Scheduler@node2.supernodexp.hpc, sock=20
02/19/2018 16:25:21;0100;Server@node2;Req;;Type 51 request received from Scheduler@node2.supernodexp.hpc, sock=20
02/19/2018 16:25:22;0100;Server@node2;Req;;Type 1 request received from ctminh@node2.supernodexp.hpc, sock=16
02/19/2018 16:25:22;0100;Server@node2;Req;;Type 3 request received from ctminh@node2.supernodexp.hpc, sock=16
02/19/2018 16:25:22;0100;Server@node2;Req;;Type 5 request received from ctminh@node2.supernodexp.hpc, sock=16
02/19/2018 16:25:22;0100;Server@node2;Job;3644.node2.supernodexp.hpc;enqueuing into workq, state 1 hop 1
02/19/2018 16:25:22;0008;Server@node2;Job;3644.node2.supernodexp.hpc;Job Queued at request of ctminh@node2.supernodexp.hpc, owner = ctminh@node2.supernodexp.hpc, job name = sweep, queue = workq
02/19/2018 16:25:22;0040;Server@node2;Svr;node2.supernodexp.hpc;Scheduler sent command 1
02/19/2018 16:25:22;0040;Server@node2;Svr;node2.supernodexp.hpc;Scheduler sent command 0
02/19/2018 16:25:22;0100;Server@node2;Req;;Type 21 request received from Scheduler@node2.supernodexp.hpc, sock=20
02/19/2018 16:25:22;0100;Server@node2;Req;;Type 81 request received from Scheduler@node2.supernodexp.hpc, sock=20
02/19/2018 16:25:22;0100;Server@node2;Req;;Type 71 request received from Scheduler@node2.supernodexp.hpc, sock=20
02/19/2018 16:25:22;0100;Server@node2;Req;;Type 58 request received from Scheduler@node2.supernodexp.hpc, sock=20
02/19/2018 16:25:22;0100;Server@node2;Req;;Type 1 request received from ctminh@node2.supernodexp.hpc, sock=16
02/19/2018 16:25:22;0100;Server@node2;Req;;Type 3 request received from ctminh@node2.supernodexp.hpc, sock=16
02/19/2018 16:25:22;0100;Server@node2;Req;;Type 5 request received from ctminh@node2.supernodexp.hpc, sock=16
02/19/2018 16:25:22;0100;Server@node2;Job;3645.node2.supernodexp.hpc;enqueuing into workq, state 1 hop 1
02/19/2018 16:25:22;0008;Server@node2;Job;3645.node2.supernodexp.hpc;Job Queued at request of ctminh@node2.supernodexp.hpc, owner = ctminh@node2.supernodexp.hpc, job name = nbody, queue = workq
02/19/2018 16:25:22;0100;Server@node2;Req;;Type 20 request received from Scheduler@node2.supernodexp.hpc, sock=20
02/19/2018 16:25:22;0100;Server@node2;Req;;Type 51 request received from Scheduler@node2.supernodexp.hpc, sock=20
02/19/2018 16:25:22;0100;Server@node2;Req;;Type 23 request received from Scheduler@node2.supernodexp.hpc, sock=20
02/19/2018 16:25:22;0008;Server@node2;Job;3645.node2.supernodexp.hpc;Job Run at request of Scheduler@node2.supernodexp.hpc on exec_vnode (node14:ncpus=12:mem=1048576kb)
02/19/2018 16:25:22;0001;Server@node2;Svr;Server@node2;Success (0) in req_runjob2, return value of svr_startjob is 0
02/19/2018 16:25:22;0100;Server@node2;Req;;Type 23 request received from Scheduler@node2.supernodexp.hpc, sock=20
02/19/2018 16:25:22;0008;Server@node2;Job;3644.node2.supernodexp.hpc;Job Run at request of Scheduler@node2.supernodexp.hpc on exec_vnode (node14:ncpus=8:mem=3145728kb)
02/19/2018 16:25:22;0001;Server@node2;Svr;Server@node2;Success (0) in req_runjob2, return value of svr_startjob is 0
02/19/2018 16:25:22;0040;Server@node2;Svr;node2.supernodexp.hpc;Scheduler sent command 1
02/19/2018 16:25:22;0040;Server@node2;Svr;node2.supernodexp.hpc;Scheduler sent command 0
02/19/2018 16:25:22;0100;Server@node2;Req;;Type 21 request received from Scheduler@node2.supernodexp.hpc, sock=20
02/19/2018 16:25:22;0100;Server@node2;Req;;Type 81 request received from Scheduler@node2.supernodexp.hpc, sock=20
02/19/2018 16:25:22;0100;Server@node2;Req;;Type 71 request received from Scheduler@node2.supernodexp.hpc, sock=20
02/19/2018 16:25:22;0100;Server@node2;Req;;Type 58 request received from Scheduler@node2.supernodexp.hpc, sock=20
02/19/2018 16:25:22;0100;Server@node2;Req;;Type 20 request received from Scheduler@node2.supernodexp.hpc, sock=20
02/19/2018 16:25:22;0100;Server@node2;Req;;Type 51 request received from Scheduler@node2.supernodexp.hpc, sock=20
02/19/2018 16:25:23;0080;Server@node2;Job;3644.node2.supernodexp.hpc;Obit received momhop:1 serverhop:1 state:4 substate:42
02/19/2018 16:25:24;0010;Server@node2;Job;3644.node2.supernodexp.hpc;Exit_status=0 resources_used.cpupercent=800 resources_used.cput=00:00:08 resources_used.mem=0kb resources_used.ncpus=8 resources_used.vmem=0kb resources_used.walltime=00:00:01
02/19/2018 16:25:24;0100;Server@node2;Job;3644.node2.supernodexp.hpc;dequeuing from workq, state 5
02/19/2018 16:25:24;0040;Server@node2;Svr;node2.supernodexp.hpc;Scheduler sent command 2
02/19/2018 16:25:24;0040;Server@node2;Svr;node2.supernodexp.hpc;Scheduler sent command 0
02/19/2018 16:25:24;0100;Server@node2;Req;;Type 21 request received from Scheduler@node2.supernodexp.hpc, sock=20
02/19/2018 16:25:24;0100;Server@node2;Req;;Type 81 request received from Scheduler@node2.supernodexp.hpc, sock=20
02/19/2018 16:25:24;0100;Server@node2;Req;;Type 71 request received from Scheduler@node2.supernodexp.hpc, sock=20
02/19/2018 16:25:24;0100;Server@node2;Req;;Type 58 request received from Scheduler@node2.supernodexp.hpc, sock=20
02/19/2018 16:25:24;0100;Server@node2;Req;;Type 20 request received from Scheduler@node2.supernodexp.hpc, sock=20
02/19/2018 16:25:24;0100;Server@node2;Req;;Type 51 request received from Scheduler@node2.supernodexp.hpc, sock=20
02/19/2018 16:25:26;0080;Server@node2;Job;3643.node2.supernodexp.hpc;Obit received momhop:1 serverhop:1 state:4 substate:42
02/19/2018 16:25:26;0100;Server@node2;Req;;Type 1 request received from ctminh@node2.supernodexp.hpc, sock=16
02/19/2018 16:25:26;0100;Server@node2;Req;;Type 3 request received from ctminh@node2.supernodexp.hpc, sock=16
02/19/2018 16:25:26;0100;Server@node2;Req;;Type 5 request received from ctminh@node2.supernodexp.hpc, sock=16
02/19/2018 16:25:26;0100;Server@node2;Job;3646.node2.supernodexp.hpc;enqueuing into workq, state 1 hop 1
02/19/2018 16:25:26;0008;Server@node2;Job;3646.node2.supernodexp.hpc;Job Queued at request of ctminh@node2.supernodexp.hpc, owner = ctminh@node2.supernodexp.hpc, job name = telemac2, queue = workq
02/19/2018 16:25:26;0040;Server@node2;Svr;node2.supernodexp.hpc;Scheduler sent command 1
02/19/2018 16:25:26;0040;Server@node2;Svr;node2.supernodexp.hpc;Scheduler sent command 0
02/19/2018 16:25:26;0100;Server@node2;Req;;Type 21 request received from Scheduler@node2.supernodexp.hpc, sock=20
02/19/2018 16:25:26;0100;Server@node2;Req;;Type 81 request received from Scheduler@node2.supernodexp.hpc, sock=20
02/19/2018 16:25:26;0100;Server@node2;Req;;Type 71 request received from Scheduler@node2.supernodexp.hpc, sock=20
02/19/2018 16:25:26;0100;Server@node2;Req;;Type 58 request received from Scheduler@node2.supernodexp.hpc, sock=20
02/19/2018 16:25:26;0100;Server@node2;Req;;Type 20 request received from Scheduler@node2.supernodexp.hpc, sock=20
02/19/2018 16:25:26;0100;Server@node2;Req;;Type 51 request received from Scheduler@node2.supernodexp.hpc, sock=20
02/19/2018 16:25:26;0100;Server@node2;Req;;Type 23 request received from Scheduler@node2.supernodexp.hpc, sock=20
02/19/2018 16:25:26;0008;Server@node2;Job;3646.node2.supernodexp.hpc;Job Run at request of Scheduler@node2.supernodexp.hpc on exec_vnode (node14:ncpus=16:mem=8388608kb)
02/19/2018 16:25:26;0001;Server@node2;Svr;Server@node2;Success (0) in req_runjob2, return value of svr_startjob is 0
02/19/2018 16:25:27;0010;Server@node2;Job;3643.node2.supernodexp.hpc;Exit_status=0 resources_used.cpupercent=1099 resources_used.cput=00:01:17 resources_used.mem=0kb resources_used.ncpus=12 resources_used.vmem=0kb resources_used.walltime=00:00:08
02/19/2018 16:25:27;0100;Server@node2;Job;3643.node2.supernodexp.hpc;dequeuing from workq, state 5
02/19/2018 16:25:27;0040;Server@node2;Svr;node2.supernodexp.hpc;Scheduler sent command 2
02/19/2018 16:25:27;0040;Server@node2;Svr;node2.supernodexp.hpc;Scheduler sent command 0
02/19/2018 16:25:27;0100;Server@node2;Req;;Type 21 request received from Scheduler@node2.supernodexp.hpc, sock=20
02/19/2018 16:25:27;0100;Server@node2;Req;;Type 81 request received from Scheduler@node2.supernodexp.hpc, sock=20
02/19/2018 16:25:27;0100;Server@node2;Req;;Type 71 request received from Scheduler@node2.supernodexp.hpc, sock=20
02/19/2018 16:25:27;0100;Server@node2;Req;;Type 58 request received from Scheduler@node2.supernodexp.hpc, sock=20
02/19/2018 16:25:27;0100;Server@node2;Req;;Type 20 request received from Scheduler@node2.supernodexp.hpc, sock=20
02/19/2018 16:25:27;0100;Server@node2;Req;;Type 51 request received from Scheduler@node2.supernodexp.hpc, sock=20
02/19/2018 16:25:30;0080;Server@node2;Job;3645.node2.supernodexp.hpc;Obit received momhop:1 serverhop:1 state:4 substate:42
02/19/2018 16:25:31;0010;Server@node2;Job;3645.node2.supernodexp.hpc;Exit_status=0 resources_used.cpupercent=100 resources_used.cput=00:00:08 resources_used.mem=11840kb resources_used.ncpus=12 resources_used.vmem=343404kb resources_used.walltime=00:00:09
02/19/2018 16:25:31;0100;Server@node2;Job;3645.node2.supernodexp.hpc;dequeuing from workq, state 5
02/19/2018 16:25:31;0040;Server@node2;Svr;node2.supernodexp.hpc;Scheduler sent command 2
02/19/2018 16:25:31;0040;Server@node2;Svr;node2.supernodexp.hpc;Scheduler sent command 0
02/19/2018 16:25:31;0100;Server@node2;Req;;Type 21 request received from Scheduler@node2.supernodexp.hpc, sock=20
02/19/2018 16:25:31;0100;Server@node2;Req;;Type 81 request received from Scheduler@node2.supernodexp.hpc, sock=20
02/19/2018 16:25:31;0100;Server@node2;Req;;Type 71 request received from Scheduler@node2.supernodexp.hpc, sock=20
02/19/2018 16:25:31;0100;Server@node2;Req;;Type 58 request received from Scheduler@node2.supernodexp.hpc, sock=20
02/19/2018 16:25:31;0100;Server@node2;Req;;Type 20 request received from Scheduler@node2.supernodexp.hpc, sock=20
02/19/2018 16:25:31;0100;Server@node2;Req;;Type 51 request received from Scheduler@node2.supernodexp.hpc, sock=20
02/19/2018 16:25:33;0100;Server@node2;Req;;Type 1 request received from ctminh@node2.supernodexp.hpc, sock=16
02/19/2018 16:25:33;0100;Server@node2;Req;;Type 3 request received from ctminh@node2.supernodexp.hpc, sock=16
02/19/2018 16:25:33;0100;Server@node2;Req;;Type 5 request received from ctminh@node2.supernodexp.hpc, sock=16
02/19/2018 16:25:33;0100;Server@node2;Job;3647.node2.supernodexp.hpc;enqueuing into workq, state 1 hop 1
02/19/2018 16:25:33;0008;Server@node2;Job;3647.node2.supernodexp.hpc;Job Queued at request of ctminh@node2.supernodexp.hpc, owner = ctminh@node2.supernodexp.hpc, job name = telemac3, queue = workq
02/19/2018 16:25:33;0040;Server@node2;Svr;node2.supernodexp.hpc;Scheduler sent command 1
02/19/2018 16:25:33;0040;Server@node2;Svr;node2.supernodexp.hpc;Scheduler sent command 0
02/19/2018 16:25:33;0100;Server@node2;Req;;Type 21 request received from Scheduler@node2.supernodexp.hpc, sock=20
02/19/2018 16:25:33;0100;Server@node2;Req;;Type 81 request received from Scheduler@node2.supernodexp.hpc, sock=20
02/19/2018 16:25:33;0100;Server@node2;Req;;Type 71 request received from Scheduler@node2.supernodexp.hpc, sock=20
02/19/2018 16:25:33;0100;Server@node2;Req;;Type 58 request received from Scheduler@node2.supernodexp.hpc, sock=20
02/19/2018 16:25:33;0100;Server@node2;Req;;Type 20 request received from Scheduler@node2.supernodexp.hpc, sock=20
02/19/2018 16:25:33;0100;Server@node2;Req;;Type 51 request received from Scheduler@node2.supernodexp.hpc, sock=20
02/19/2018 16:25:33;0100;Server@node2;Req;;Type 11 request received from Scheduler@node2.supernodexp.hpc, sock=20
02/19/2018 16:25:33;0008;Server@node2;Job;3647.node2.supernodexp.hpc;Job Modified at request of Scheduler@node2.supernodexp.hpc
02/19/2018 16:25:36;0100;Server@node2;Req;;Type 1 request received from ctminh@node2.supernodexp.hpc, sock=16
02/19/2018 16:25:36;0100;Server@node2;Req;;Type 3 request received from ctminh@node2.supernodexp.hpc, sock=16
02/19/2018 16:25:36;0100;Server@node2;Req;;Type 5 request received from ctminh@node2.supernodexp.hpc, sock=16
02/19/2018 16:25:36;0100;Server@node2;Job;3648.node2.supernodexp.hpc;enqueuing into workq, state 1 hop 1
02/19/2018 16:25:36;0008;Server@node2;Job;3648.node2.supernodexp.hpc;Job Queued at request of ctminh@node2.supernodexp.hpc, owner = ctminh@node2.supernodexp.hpc, job name = lu-decomp, queue = workq
02/19/2018 16:25:36;0040;Server@node2;Svr;node2.supernodexp.hpc;Scheduler sent command 1
02/19/2018 16:25:36;0040;Server@node2;Svr;node2.supernodexp.hpc;Scheduler sent command 0
02/19/2018 16:25:36;0100;Server@node2;Req;;Type 21 request received from Scheduler@node2.supernodexp.hpc, sock=20
02/19/2018 16:25:36;0100;Server@node2;Req;;Type 81 request received from Scheduler@node2.supernodexp.hpc, sock=20
02/19/2018 16:25:36;0100;Server@node2;Req;;Type 71 request received from Scheduler@node2.supernodexp.hpc, sock=20
02/19/2018 16:25:36;0100;Server@node2;Req;;Type 58 request received from Scheduler@node2.supernodexp.hpc, sock=20
02/19/2018 16:25:36;0100;Server@node2;Req;;Type 20 request received from Scheduler@node2.supernodexp.hpc, sock=20
02/19/2018 16:25:36;0100;Server@node2;Req;;Type 51 request received from Scheduler@node2.supernodexp.hpc, sock=20
02/19/2018 16:25:36;0100;Server@node2;Req;;Type 11 request received from Scheduler@node2.supernodexp.hpc, sock=20
02/19/2018 16:25:36;0008;Server@node2;Job;3648.node2.supernodexp.hpc;Job Modified at request of Scheduler@node2.supernodexp.hpc
02/19/2018 16:25:37;0100;Server@node2;Req;;Type 1 request received from ctminh@node2.supernodexp.hpc, sock=16
02/19/2018 16:25:37;0100;Server@node2;Req;;Type 3 request received from ctminh@node2.supernodexp.hpc, sock=16
02/19/2018 16:25:37;0100;Server@node2;Req;;Type 5 request received from ctminh@node2.supernodexp.hpc, sock=16
02/19/2018 16:25:37;0100;Server@node2;Job;3649.node2.supernodexp.hpc;enqueuing into workq, state 1 hop 1
02/19/2018 16:25:37;0008;Server@node2;Job;3649.node2.supernodexp.hpc;Job Queued at request of ctminh@node2.supernodexp.hpc, owner = ctminh@node2.supernodexp.hpc, job name = jacobi, queue = workq
02/19/2018 16:25:37;0040;Server@node2;Svr;node2.supernodexp.hpc;Scheduler sent command 1
02/19/2018 16:25:37;0040;Server@node2;Svr;node2.supernodexp.hpc;Scheduler sent command 0
02/19/2018 16:25:37;0100;Server@node2;Req;;Type 21 request received from Scheduler@node2.supernodexp.hpc, sock=20
02/19/2018 16:25:37;0100;Server@node2;Req;;Type 81 request received from Scheduler@node2.supernodexp.hpc, sock=20
02/19/2018 16:25:37;0100;Server@node2;Req;;Type 71 request received from Scheduler@node2.supernodexp.hpc, sock=20
02/19/2018 16:25:37;0100;Server@node2;Req;;Type 58 request received from Scheduler@node2.supernodexp.hpc, sock=20
02/19/2018 16:25:37;0100;Server@node2;Req;;Type 20 request received from Scheduler@node2.supernodexp.hpc, sock=20
02/19/2018 16:25:37;0100;Server@node2;Req;;Type 51 request received from Scheduler@node2.supernodexp.hpc, sock=20
02/19/2018 16:25:37;0100;Server@node2;Req;;Type 11 request received from Scheduler@node2.supernodexp.hpc, sock=20
02/19/2018 16:25:37;0008;Server@node2;Job;3649.node2.supernodexp.hpc;Job Modified at request of Scheduler@node2.supernodexp.hpc
02/19/2018 16:25:38;0100;Server@node2;Req;;Type 1 request received from ctminh@node2.supernodexp.hpc, sock=16
02/19/2018 16:25:38;0100;Server@node2;Req;;Type 3 request received from ctminh@node2.supernodexp.hpc, sock=16
02/19/2018 16:25:38;0100;Server@node2;Req;;Type 5 request received from ctminh@node2.supernodexp.hpc, sock=16
02/19/2018 16:25:38;0100;Server@node2;Job;3650.node2.supernodexp.hpc;enqueuing into workq, state 1 hop 1
02/19/2018 16:25:38;0008;Server@node2;Job;3650.node2.supernodexp.hpc;Job Queued at request of ctminh@node2.supernodexp.hpc, owner = ctminh@node2.supernodexp.hpc, job name = thread-affinity, queue = workq
02/19/2018 16:25:38;0040;Server@node2;Svr;node2.supernodexp.hpc;Scheduler sent command 1
02/19/2018 16:25:38;0040;Server@node2;Svr;node2.supernodexp.hpc;Scheduler sent command 0
02/19/2018 16:25:38;0100;Server@node2;Req;;Type 21 request received from Scheduler@node2.supernodexp.hpc, sock=20
02/19/2018 16:25:38;0100;Server@node2;Req;;Type 81 request received from Scheduler@node2.supernodexp.hpc, sock=20
02/19/2018 16:25:38;0100;Server@node2;Req;;Type 71 request received from Scheduler@node2.supernodexp.hpc, sock=20
02/19/2018 16:25:38;0100;Server@node2;Req;;Type 58 request received from Scheduler@node2.supernodexp.hpc, sock=20
02/19/2018 16:25:38;0100;Server@node2;Req;;Type 20 request received from Scheduler@node2.supernodexp.hpc, sock=20
02/19/2018 16:25:38;0100;Server@node2;Req;;Type 51 request received from Scheduler@node2.supernodexp.hpc, sock=20
02/19/2018 16:25:38;0100;Server@node2;Req;;Type 11 request received from Scheduler@node2.supernodexp.hpc, sock=20
02/19/2018 16:25:38;0008;Server@node2;Job;3650.node2.supernodexp.hpc;Job Modified at request of Scheduler@node2.supernodexp.hpc
02/19/2018 16:25:47;0100;Server@node2;Req;;Type 1 request received from ctminh@node2.supernodexp.hpc, sock=16
02/19/2018 16:25:47;0100;Server@node2;Req;;Type 3 request received from ctminh@node2.supernodexp.hpc, sock=16
02/19/2018 16:25:47;0100;Server@node2;Req;;Type 5 request received from ctminh@node2.supernodexp.hpc, sock=16
02/19/2018 16:25:47;0100;Server@node2;Job;3651.node2.supernodexp.hpc;enqueuing into workq, state 1 hop 1
02/19/2018 16:25:47;0008;Server@node2;Job;3651.node2.supernodexp.hpc;Job Queued at request of ctminh@node2.supernodexp.hpc, owner = ctminh@node2.supernodexp.hpc, job name = vectorization, queue = workq
02/19/2018 16:25:47;0040;Server@node2;Svr;node2.supernodexp.hpc;Scheduler sent command 1
02/19/2018 16:25:47;0040;Server@node2;Svr;node2.supernodexp.hpc;Scheduler sent command 0
02/19/2018 16:25:47;0100;Server@node2;Req;;Type 21 request received from Scheduler@node2.supernodexp.hpc, sock=20
02/19/2018 16:25:47;0100;Server@node2;Req;;Type 81 request received from Scheduler@node2.supernodexp.hpc, sock=20
02/19/2018 16:25:47;0100;Server@node2;Req;;Type 71 request received from Scheduler@node2.supernodexp.hpc, sock=20
02/19/2018 16:25:47;0100;Server@node2;Req;;Type 58 request received from Scheduler@node2.supernodexp.hpc, sock=20
02/19/2018 16:25:47;0100;Server@node2;Req;;Type 20 request received from Scheduler@node2.supernodexp.hpc, sock=20
02/19/2018 16:25:47;0100;Server@node2;Req;;Type 51 request received from Scheduler@node2.supernodexp.hpc, sock=20
02/19/2018 16:25:47;0100;Server@node2;Req;;Type 11 request received from Scheduler@node2.supernodexp.hpc, sock=20
02/19/2018 16:25:47;0008;Server@node2;Job;3651.node2.supernodexp.hpc;Job Modified at request of Scheduler@node2.supernodexp.hpc
02/19/2018 16:25:51;0100;Server@node2;Req;;Type 1 request received from ctminh@node2.supernodexp.hpc, sock=16
02/19/2018 16:25:51;0100;Server@node2;Req;;Type 3 request received from ctminh@node2.supernodexp.hpc, sock=16
02/19/2018 16:25:51;0100;Server@node2;Req;;Type 5 request received from ctminh@node2.supernodexp.hpc, sock=16
02/19/2018 16:25:51;0100;Server@node2;Job;3652.node2.supernodexp.hpc;enqueuing into workq, state 1 hop 1
02/19/2018 16:25:51;0008;Server@node2;Job;3652.node2.supernodexp.hpc;Job Queued at request of ctminh@node2.supernodexp.hpc, owner = ctminh@node2.supernodexp.hpc, job name = vectorization, queue = workq
02/19/2018 16:25:51;0040;Server@node2;Svr;node2.supernodexp.hpc;Scheduler sent command 1
02/19/2018 16:25:51;0040;Server@node2;Svr;node2.supernodexp.hpc;Scheduler sent command 0
02/19/2018 16:25:51;0100;Server@node2;Req;;Type 21 request received from Scheduler@node2.supernodexp.hpc, sock=20
02/19/2018 16:25:51;0100;Server@node2;Req;;Type 81 request received from Scheduler@node2.supernodexp.hpc, sock=20
02/19/2018 16:25:51;0100;Server@node2;Req;;Type 71 request received from Scheduler@node2.supernodexp.hpc, sock=20
02/19/2018 16:25:51;0100;Server@node2;Req;;Type 58 request received from Scheduler@node2.supernodexp.hpc, sock=20
02/19/2018 16:25:51;0100;Server@node2;Req;;Type 20 request received from Scheduler@node2.supernodexp.hpc, sock=20
02/19/2018 16:25:51;0100;Server@node2;Req;;Type 51 request received from Scheduler@node2.supernodexp.hpc, sock=20
02/19/2018 16:25:51;0100;Server@node2;Req;;Type 11 request received from Scheduler@node2.supernodexp.hpc, sock=20
02/19/2018 16:25:51;0008;Server@node2;Job;3652.node2.supernodexp.hpc;Job Modified at request of Scheduler@node2.supernodexp.hpc
02/19/2018 16:25:53;0100;Server@node2;Req;;Type 1 request received from ctminh@node2.supernodexp.hpc, sock=16
02/19/2018 16:25:53;0100;Server@node2;Req;;Type 3 request received from ctminh@node2.supernodexp.hpc, sock=16
02/19/2018 16:25:53;0100;Server@node2;Req;;Type 5 request received from ctminh@node2.supernodexp.hpc, sock=16
02/19/2018 16:25:53;0100;Server@node2;Job;3653.node2.supernodexp.hpc;enqueuing into workq, state 1 hop 1
02/19/2018 16:25:53;0008;Server@node2;Job;3653.node2.supernodexp.hpc;Job Queued at request of ctminh@node2.supernodexp.hpc, owner = ctminh@node2.supernodexp.hpc, job name = lu-decomp, queue = workq
02/19/2018 16:25:53;0040;Server@node2;Svr;node2.supernodexp.hpc;Scheduler sent command 1
02/19/2018 16:25:53;0040;Server@node2;Svr;node2.supernodexp.hpc;Scheduler sent command 0
02/19/2018 16:25:53;0100;Server@node2;Req;;Type 21 request received from Scheduler@node2.supernodexp.hpc, sock=20
02/19/2018 16:25:53;0100;Server@node2;Req;;Type 81 request received from Scheduler@node2.supernodexp.hpc, sock=20
02/19/2018 16:25:53;0100;Server@node2;Req;;Type 71 request received from Scheduler@node2.supernodexp.hpc, sock=20
02/19/2018 16:25:53;0100;Server@node2;Req;;Type 58 request received from Scheduler@node2.supernodexp.hpc, sock=20
02/19/2018 16:25:53;0100;Server@node2;Req;;Type 20 request received from Scheduler@node2.supernodexp.hpc, sock=20
02/19/2018 16:25:53;0100;Server@node2;Req;;Type 51 request received from Scheduler@node2.supernodexp.hpc, sock=20
02/19/2018 16:25:53;0100;Server@node2;Req;;Type 11 request received from Scheduler@node2.supernodexp.hpc, sock=20
02/19/2018 16:25:53;0008;Server@node2;Job;3653.node2.supernodexp.hpc;Job Modified at request of Scheduler@node2.supernodexp.hpc
02/19/2018 16:25:55;0100;Server@node2;Req;;Type 1 request received from ctminh@node2.supernodexp.hpc, sock=16
02/19/2018 16:25:55;0100;Server@node2;Req;;Type 3 request received from ctminh@node2.supernodexp.hpc, sock=16
02/19/2018 16:25:55;0100;Server@node2;Req;;Type 5 request received from ctminh@node2.supernodexp.hpc, sock=16
02/19/2018 16:25:55;0100;Server@node2;Job;3654.node2.supernodexp.hpc;enqueuing into workq, state 1 hop 1
02/19/2018 16:25:55;0008;Server@node2;Job;3654.node2.supernodexp.hpc;Job Queued at request of ctminh@node2.supernodexp.hpc, owner = ctminh@node2.supernodexp.hpc, job name = matrix-x-vector, queue = workq
02/19/2018 16:25:55;0040;Server@node2;Svr;node2.supernodexp.hpc;Scheduler sent command 1
02/19/2018 16:25:55;0040;Server@node2;Svr;node2.supernodexp.hpc;Scheduler sent command 0
02/19/2018 16:25:55;0100;Server@node2;Req;;Type 21 request received from Scheduler@node2.supernodexp.hpc, sock=20
02/19/2018 16:25:55;0100;Server@node2;Req;;Type 81 request received from Scheduler@node2.supernodexp.hpc, sock=20
02/19/2018 16:25:55;0100;Server@node2;Req;;Type 71 request received from Scheduler@node2.supernodexp.hpc, sock=20
02/19/2018 16:25:55;0100;Server@node2;Req;;Type 58 request received from Scheduler@node2.supernodexp.hpc, sock=20
02/19/2018 16:25:55;0100;Server@node2;Req;;Type 20 request received from Scheduler@node2.supernodexp.hpc, sock=20
02/19/2018 16:25:55;0100;Server@node2;Req;;Type 51 request received from Scheduler@node2.supernodexp.hpc, sock=20
02/19/2018 16:25:55;0100;Server@node2;Req;;Type 1 request received from ctminh@node2.supernodexp.hpc, sock=16
02/19/2018 16:25:55;0100;Server@node2;Req;;Type 3 request received from ctminh@node2.supernodexp.hpc, sock=16
02/19/2018 16:25:55;0100;Server@node2;Req;;Type 5 request received from ctminh@node2.supernodexp.hpc, sock=16
02/19/2018 16:25:55;0100;Server@node2;Job;3655.node2.supernodexp.hpc;enqueuing into workq, state 1 hop 1
02/19/2018 16:25:55;0008;Server@node2;Job;3655.node2.supernodexp.hpc;Job Queued at request of ctminh@node2.supernodexp.hpc, owner = ctminh@node2.supernodexp.hpc, job name = vast1, queue = workq
02/19/2018 16:25:55;0100;Server@node2;Req;;Type 1 request received from ctminh@node2.supernodexp.hpc, sock=16
02/19/2018 16:25:55;0100;Server@node2;Req;;Type 3 request received from ctminh@node2.supernodexp.hpc, sock=16
02/19/2018 16:25:55;0100;Server@node2;Req;;Type 5 request received from ctminh@node2.supernodexp.hpc, sock=16
02/19/2018 16:25:55;0100;Server@node2;Job;3656.node2.supernodexp.hpc;enqueuing into workq, state 1 hop 1
02/19/2018 16:25:55;0008;Server@node2;Job;3656.node2.supernodexp.hpc;Job Queued at request of ctminh@node2.supernodexp.hpc, owner = ctminh@node2.supernodexp.hpc, job name = vectorization, queue = workq
02/19/2018 16:25:55;0100;Server@node2;Req;;Type 11 request received from Scheduler@node2.supernodexp.hpc, sock=20
02/19/2018 16:25:55;0008;Server@node2;Job;3654.node2.supernodexp.hpc;Job Modified at request of Scheduler@node2.supernodexp.hpc
02/19/2018 16:25:55;0040;Server@node2;Svr;node2.supernodexp.hpc;Scheduler sent command 1
02/19/2018 16:25:55;0040;Server@node2;Svr;node2.supernodexp.hpc;Scheduler sent command 0
02/19/2018 16:25:55;0100;Server@node2;Req;;Type 21 request received from Scheduler@node2.supernodexp.hpc, sock=20
02/19/2018 16:25:55;0100;Server@node2;Req;;Type 81 request received from Scheduler@node2.supernodexp.hpc, sock=20
02/19/2018 16:25:55;0100;Server@node2;Req;;Type 71 request received from Scheduler@node2.supernodexp.hpc, sock=20
02/19/2018 16:25:55;0100;Server@node2;Req;;Type 58 request received from Scheduler@node2.supernodexp.hpc, sock=20
02/19/2018 16:25:55;0100;Server@node2;Req;;Type 20 request received from Scheduler@node2.supernodexp.hpc, sock=20
02/19/2018 16:25:55;0100;Server@node2;Req;;Type 51 request received from Scheduler@node2.supernodexp.hpc, sock=20
02/19/2018 16:25:55;0100;Server@node2;Req;;Type 11 request received from Scheduler@node2.supernodexp.hpc, sock=20
02/19/2018 16:25:55;0008;Server@node2;Job;3647.node2.supernodexp.hpc;Job Modified at request of Scheduler@node2.supernodexp.hpc
02/19/2018 16:25:55;0100;Server@node2;Req;;Type 11 request received from Scheduler@node2.supernodexp.hpc, sock=20
02/19/2018 16:25:55;0008;Server@node2;Job;3656.node2.supernodexp.hpc;Job Modified at request of Scheduler@node2.supernodexp.hpc
02/19/2018 16:25:55;0100;Server@node2;Req;;Type 11 request received from Scheduler@node2.supernodexp.hpc, sock=20
02/19/2018 16:25:55;0008;Server@node2;Job;3655.node2.supernodexp.hpc;Job Modified at request of Scheduler@node2.supernodexp.hpc
02/19/2018 16:25:57;0100;Server@node2;Req;;Type 1 request received from ctminh@node2.supernodexp.hpc, sock=16
02/19/2018 16:25:57;0100;Server@node2;Req;;Type 3 request received from ctminh@node2.supernodexp.hpc, sock=16
02/19/2018 16:25:57;0100;Server@node2;Req;;Type 5 request received from ctminh@node2.supernodexp.hpc, sock=16
02/19/2018 16:25:57;0100;Server@node2;Job;3657.node2.supernodexp.hpc;enqueuing into workq, state 1 hop 1
02/19/2018 16:25:57;0008;Server@node2;Job;3657.node2.supernodexp.hpc;Job Queued at request of ctminh@node2.supernodexp.hpc, owner = ctminh@node2.supernodexp.hpc, job name = vectorization, queue = workq
02/19/2018 16:25:57;0040;Server@node2;Svr;node2.supernodexp.hpc;Scheduler sent command 1
02/19/2018 16:25:57;0040;Server@node2;Svr;node2.supernodexp.hpc;Scheduler sent command 0
02/19/2018 16:25:57;0100;Server@node2;Req;;Type 21 request received from Scheduler@node2.supernodexp.hpc, sock=20
02/19/2018 16:25:57;0100;Server@node2;Req;;Type 81 request received from Scheduler@node2.supernodexp.hpc, sock=20
02/19/2018 16:25:57;0100;Server@node2;Req;;Type 71 request received from Scheduler@node2.supernodexp.hpc, sock=20
02/19/2018 16:25:57;0100;Server@node2;Req;;Type 58 request received from Scheduler@node2.supernodexp.hpc, sock=20
02/19/2018 16:25:57;0100;Server@node2;Req;;Type 1 request received from ctminh@node2.supernodexp.hpc, sock=16
02/19/2018 16:25:57;0100;Server@node2;Req;;Type 3 request received from ctminh@node2.supernodexp.hpc, sock=16
02/19/2018 16:25:57;0100;Server@node2;Req;;Type 5 request received from ctminh@node2.supernodexp.hpc, sock=16
02/19/2018 16:25:57;0100;Server@node2;Job;3658.node2.supernodexp.hpc;enqueuing into workq, state 1 hop 1
02/19/2018 16:25:57;0008;Server@node2;Job;3658.node2.supernodexp.hpc;Job Queued at request of ctminh@node2.supernodexp.hpc, owner = ctminh@node2.supernodexp.hpc, job name = sweep, queue = workq
02/19/2018 16:25:57;0100;Server@node2;Req;;Type 20 request received from Scheduler@node2.supernodexp.hpc, sock=20
02/19/2018 16:25:57;0100;Server@node2;Req;;Type 51 request received from Scheduler@node2.supernodexp.hpc, sock=20
02/19/2018 16:25:57;0100;Server@node2;Req;;Type 11 request received from Scheduler@node2.supernodexp.hpc, sock=20
02/19/2018 16:25:57;0008;Server@node2;Job;3657.node2.supernodexp.hpc;Job Modified at request of Scheduler@node2.supernodexp.hpc
02/19/2018 16:25:57;0100;Server@node2;Req;;Type 11 request received from Scheduler@node2.supernodexp.hpc, sock=20
02/19/2018 16:25:57;0008;Server@node2;Job;3658.node2.supernodexp.hpc;Job Modified at request of Scheduler@node2.supernodexp.hpc
02/19/2018 16:25:57;0040;Server@node2;Svr;node2.supernodexp.hpc;Scheduler sent command 1
02/19/2018 16:25:57;0040;Server@node2;Svr;node2.supernodexp.hpc;Scheduler sent command 0
02/19/2018 16:25:57;0100;Server@node2;Req;;Type 21 request received from Scheduler@node2.supernodexp.hpc, sock=20
02/19/2018 16:25:57;0100;Server@node2;Req;;Type 81 request received from Scheduler@node2.supernodexp.hpc, sock=20
02/19/2018 16:25:57;0100;Server@node2;Req;;Type 71 request received from Scheduler@node2.supernodexp.hpc, sock=20
02/19/2018 16:25:57;0100;Server@node2;Req;;Type 58 request received from Scheduler@node2.supernodexp.hpc, sock=20
02/19/2018 16:25:57;0100;Server@node2;Req;;Type 20 request received from Scheduler@node2.supernodexp.hpc, sock=20
02/19/2018 16:25:57;0100;Server@node2;Req;;Type 51 request received from Scheduler@node2.supernodexp.hpc, sock=20
02/19/2018 16:25:59;0100;Server@node2;Req;;Type 1 request received from ctminh@node2.supernodexp.hpc, sock=16
02/19/2018 16:25:59;0100;Server@node2;Req;;Type 3 request received from ctminh@node2.supernodexp.hpc, sock=16
02/19/2018 16:25:59;0100;Server@node2;Req;;Type 5 request received from ctminh@node2.supernodexp.hpc, sock=16
02/19/2018 16:25:59;0100;Server@node2;Job;3659.node2.supernodexp.hpc;enqueuing into workq, state 1 hop 1
02/19/2018 16:25:59;0008;Server@node2;Job;3659.node2.supernodexp.hpc;Job Queued at request of ctminh@node2.supernodexp.hpc, owner = ctminh@node2.supernodexp.hpc, job name = thread-affinity, queue = workq
02/19/2018 16:25:59;0040;Server@node2;Svr;node2.supernodexp.hpc;Scheduler sent command 1
02/19/2018 16:25:59;0040;Server@node2;Svr;node2.supernodexp.hpc;Scheduler sent command 0
02/19/2018 16:25:59;0100;Server@node2;Req;;Type 21 request received from Scheduler@node2.supernodexp.hpc, sock=20
02/19/2018 16:25:59;0100;Server@node2;Req;;Type 81 request received from Scheduler@node2.supernodexp.hpc, sock=20
02/19/2018 16:25:59;0100;Server@node2;Req;;Type 71 request received from Scheduler@node2.supernodexp.hpc, sock=20
02/19/2018 16:25:59;0100;Server@node2;Req;;Type 58 request received from Scheduler@node2.supernodexp.hpc, sock=20
02/19/2018 16:25:59;0100;Server@node2;Req;;Type 20 request received from Scheduler@node2.supernodexp.hpc, sock=20
02/19/2018 16:25:59;0100;Server@node2;Req;;Type 51 request received from Scheduler@node2.supernodexp.hpc, sock=20
02/19/2018 16:25:59;0100;Server@node2;Req;;Type 11 request received from Scheduler@node2.supernodexp.hpc, sock=20
02/19/2018 16:25:59;0008;Server@node2;Job;3659.node2.supernodexp.hpc;Job Modified at request of Scheduler@node2.supernodexp.hpc
02/19/2018 16:26:04;0100;Server@node2;Req;;Type 1 request received from ctminh@node2.supernodexp.hpc, sock=16
02/19/2018 16:26:04;0100;Server@node2;Req;;Type 3 request received from ctminh@node2.supernodexp.hpc, sock=16
02/19/2018 16:26:04;0100;Server@node2;Req;;Type 5 request received from ctminh@node2.supernodexp.hpc, sock=16
02/19/2018 16:26:04;0100;Server@node2;Job;3660.node2.supernodexp.hpc;enqueuing into workq, state 1 hop 1
02/19/2018 16:26:04;0008;Server@node2;Job;3660.node2.supernodexp.hpc;Job Queued at request of ctminh@node2.supernodexp.hpc, owner = ctminh@node2.supernodexp.hpc, job name = histogram, queue = workq
02/19/2018 16:26:04;0040;Server@node2;Svr;node2.supernodexp.hpc;Scheduler sent command 1
02/19/2018 16:26:04;0040;Server@node2;Svr;node2.supernodexp.hpc;Scheduler sent command 0
02/19/2018 16:26:04;0100;Server@node2;Req;;Type 21 request received from Scheduler@node2.supernodexp.hpc, sock=20
02/19/2018 16:26:04;0100;Server@node2;Req;;Type 81 request received from Scheduler@node2.supernodexp.hpc, sock=20
02/19/2018 16:26:04;0100;Server@node2;Req;;Type 71 request received from Scheduler@node2.supernodexp.hpc, sock=20
02/19/2018 16:26:04;0100;Server@node2;Req;;Type 58 request received from Scheduler@node2.supernodexp.hpc, sock=20
02/19/2018 16:26:04;0100;Server@node2;Req;;Type 20 request received from Scheduler@node2.supernodexp.hpc, sock=20
02/19/2018 16:26:04;0100;Server@node2;Req;;Type 51 request received from Scheduler@node2.supernodexp.hpc, sock=20
02/19/2018 16:26:04;0100;Server@node2;Req;;Type 11 request received from Scheduler@node2.supernodexp.hpc, sock=20
02/19/2018 16:26:04;0008;Server@node2;Job;3660.node2.supernodexp.hpc;Job Modified at request of Scheduler@node2.supernodexp.hpc
02/19/2018 16:26:06;0100;Server@node2;Req;;Type 1 request received from ctminh@node2.supernodexp.hpc, sock=16
02/19/2018 16:26:06;0100;Server@node2;Req;;Type 3 request received from ctminh@node2.supernodexp.hpc, sock=16
02/19/2018 16:26:06;0100;Server@node2;Req;;Type 5 request received from ctminh@node2.supernodexp.hpc, sock=16
02/19/2018 16:26:06;0100;Server@node2;Job;3661.node2.supernodexp.hpc;enqueuing into workq, state 1 hop 1
02/19/2018 16:26:06;0008;Server@node2;Job;3661.node2.supernodexp.hpc;Job Queued at request of ctminh@node2.supernodexp.hpc, owner = ctminh@node2.supernodexp.hpc, job name = matrix-x-vector, queue = workq
02/19/2018 16:26:06;0040;Server@node2;Svr;node2.supernodexp.hpc;Scheduler sent command 1
02/19/2018 16:26:06;0040;Server@node2;Svr;node2.supernodexp.hpc;Scheduler sent command 0
02/19/2018 16:26:06;0100;Server@node2;Req;;Type 21 request received from Scheduler@node2.supernodexp.hpc, sock=20
02/19/2018 16:26:06;0100;Server@node2;Req;;Type 81 request received from Scheduler@node2.supernodexp.hpc, sock=20
02/19/2018 16:26:06;0100;Server@node2;Req;;Type 71 request received from Scheduler@node2.supernodexp.hpc, sock=20
02/19/2018 16:26:06;0100;Server@node2;Req;;Type 58 request received from Scheduler@node2.supernodexp.hpc, sock=20
02/19/2018 16:26:06;0100;Server@node2;Req;;Type 20 request received from Scheduler@node2.supernodexp.hpc, sock=20
02/19/2018 16:26:06;0100;Server@node2;Req;;Type 51 request received from Scheduler@node2.supernodexp.hpc, sock=20
02/19/2018 16:26:06;0100;Server@node2;Req;;Type 11 request received from Scheduler@node2.supernodexp.hpc, sock=20
02/19/2018 16:26:06;0008;Server@node2;Job;3661.node2.supernodexp.hpc;Job Modified at request of Scheduler@node2.supernodexp.hpc
02/19/2018 16:26:10;0100;Server@node2;Req;;Type 1 request received from ctminh@node2.supernodexp.hpc, sock=16
02/19/2018 16:26:10;0100;Server@node2;Req;;Type 3 request received from ctminh@node2.supernodexp.hpc, sock=16
02/19/2018 16:26:10;0100;Server@node2;Req;;Type 5 request received from ctminh@node2.supernodexp.hpc, sock=16
02/19/2018 16:26:10;0100;Server@node2;Job;3662.node2.supernodexp.hpc;enqueuing into workq, state 1 hop 1
02/19/2018 16:26:10;0008;Server@node2;Job;3662.node2.supernodexp.hpc;Job Queued at request of ctminh@node2.supernodexp.hpc, owner = ctminh@node2.supernodexp.hpc, job name = nbody, queue = workq
02/19/2018 16:26:10;0040;Server@node2;Svr;node2.supernodexp.hpc;Scheduler sent command 1
02/19/2018 16:26:10;0040;Server@node2;Svr;node2.supernodexp.hpc;Scheduler sent command 0
02/19/2018 16:26:10;0100;Server@node2;Req;;Type 21 request received from Scheduler@node2.supernodexp.hpc, sock=20
02/19/2018 16:26:10;0100;Server@node2;Req;;Type 81 request received from Scheduler@node2.supernodexp.hpc, sock=20
02/19/2018 16:26:10;0100;Server@node2;Req;;Type 71 request received from Scheduler@node2.supernodexp.hpc, sock=20
02/19/2018 16:26:10;0100;Server@node2;Req;;Type 58 request received from Scheduler@node2.supernodexp.hpc, sock=20
02/19/2018 16:26:10;0100;Server@node2;Req;;Type 1 request received from ctminh@node2.supernodexp.hpc, sock=16
02/19/2018 16:26:10;0100;Server@node2;Req;;Type 3 request received from ctminh@node2.supernodexp.hpc, sock=16
02/19/2018 16:26:10;0100;Server@node2;Req;;Type 5 request received from ctminh@node2.supernodexp.hpc, sock=16
02/19/2018 16:26:10;0100;Server@node2;Job;3663.node2.supernodexp.hpc;enqueuing into workq, state 1 hop 1
02/19/2018 16:26:10;0008;Server@node2;Job;3663.node2.supernodexp.hpc;Job Queued at request of ctminh@node2.supernodexp.hpc, owner = ctminh@node2.supernodexp.hpc, job name = vectorization, queue = workq
02/19/2018 16:26:10;0100;Server@node2;Req;;Type 20 request received from Scheduler@node2.supernodexp.hpc, sock=20
02/19/2018 16:26:10;0100;Server@node2;Req;;Type 51 request received from Scheduler@node2.supernodexp.hpc, sock=20
02/19/2018 16:26:10;0100;Server@node2;Req;;Type 11 request received from Scheduler@node2.supernodexp.hpc, sock=20
02/19/2018 16:26:10;0008;Server@node2;Job;3662.node2.supernodexp.hpc;Job Modified at request of Scheduler@node2.supernodexp.hpc
02/19/2018 16:26:10;0100;Server@node2;Req;;Type 11 request received from Scheduler@node2.supernodexp.hpc, sock=20
02/19/2018 16:26:10;0008;Server@node2;Job;3663.node2.supernodexp.hpc;Job Modified at request of Scheduler@node2.supernodexp.hpc
02/19/2018 16:26:10;0040;Server@node2;Svr;node2.supernodexp.hpc;Scheduler sent command 1
02/19/2018 16:26:10;0040;Server@node2;Svr;node2.supernodexp.hpc;Scheduler sent command 0
02/19/2018 16:26:10;0100;Server@node2;Req;;Type 21 request received from Scheduler@node2.supernodexp.hpc, sock=20
02/19/2018 16:26:10;0100;Server@node2;Req;;Type 81 request received from Scheduler@node2.supernodexp.hpc, sock=20
02/19/2018 16:26:10;0100;Server@node2;Req;;Type 71 request received from Scheduler@node2.supernodexp.hpc, sock=20
02/19/2018 16:26:10;0100;Server@node2;Req;;Type 58 request received from Scheduler@node2.supernodexp.hpc, sock=20
02/19/2018 16:26:11;0100;Server@node2;Req;;Type 20 request received from Scheduler@node2.supernodexp.hpc, sock=20
02/19/2018 16:26:11;0100;Server@node2;Req;;Type 51 request received from Scheduler@node2.supernodexp.hpc, sock=20
02/19/2018 16:26:16;0100;Server@node2;Req;;Type 1 request received from ctminh@node2.supernodexp.hpc, sock=16
02/19/2018 16:26:16;0100;Server@node2;Req;;Type 3 request received from ctminh@node2.supernodexp.hpc, sock=16
02/19/2018 16:26:16;0100;Server@node2;Req;;Type 5 request received from ctminh@node2.supernodexp.hpc, sock=16
02/19/2018 16:26:16;0100;Server@node2;Job;3664.node2.supernodexp.hpc;enqueuing into workq, state 1 hop 1
02/19/2018 16:26:16;0008;Server@node2;Job;3664.node2.supernodexp.hpc;Job Queued at request of ctminh@node2.supernodexp.hpc, owner = ctminh@node2.supernodexp.hpc, job name = matrix-x-vector, queue = workq
02/19/2018 16:26:16;0040;Server@node2;Svr;node2.supernodexp.hpc;Scheduler sent command 1
02/19/2018 16:26:16;0040;Server@node2;Svr;node2.supernodexp.hpc;Scheduler sent command 0
02/19/2018 16:26:16;0100;Server@node2;Req;;Type 21 request received from Scheduler@node2.supernodexp.hpc, sock=20
02/19/2018 16:26:16;0100;Server@node2;Req;;Type 81 request received from Scheduler@node2.supernodexp.hpc, sock=20
02/19/2018 16:26:16;0100;Server@node2;Req;;Type 71 request received from Scheduler@node2.supernodexp.hpc, sock=20
02/19/2018 16:26:16;0100;Server@node2;Req;;Type 58 request received from Scheduler@node2.supernodexp.hpc, sock=20
02/19/2018 16:26:16;0100;Server@node2;Req;;Type 1 request received from ctminh@node2.supernodexp.hpc, sock=16
02/19/2018 16:26:16;0100;Server@node2;Req;;Type 3 request received from ctminh@node2.supernodexp.hpc, sock=16
02/19/2018 16:26:16;0100;Server@node2;Req;;Type 5 request received from ctminh@node2.supernodexp.hpc, sock=16
02/19/2018 16:26:16;0100;Server@node2;Job;3665.node2.supernodexp.hpc;enqueuing into workq, state 1 hop 1
02/19/2018 16:26:16;0008;Server@node2;Job;3665.node2.supernodexp.hpc;Job Queued at request of ctminh@node2.supernodexp.hpc, owner = ctminh@node2.supernodexp.hpc, job name = qe_mic_test, queue = workq
02/19/2018 16:26:16;0100;Server@node2;Req;;Type 20 request received from Scheduler@node2.supernodexp.hpc, sock=20
02/19/2018 16:26:16;0100;Server@node2;Req;;Type 51 request received from Scheduler@node2.supernodexp.hpc, sock=20
02/19/2018 16:26:17;0100;Server@node2;Req;;Type 23 request received from Scheduler@node2.supernodexp.hpc, sock=20
02/19/2018 16:26:17;0008;Server@node2;Job;3665.node2.supernodexp.hpc;Job Run at request of Scheduler@node2.supernodexp.hpc on exec_vnode (node14:ncpus=32:nmics=1:mem=16777216kb)
02/19/2018 16:26:17;0001;Server@node2;Svr;Server@node2;Success (0) in req_runjob2, return value of svr_startjob is 0
02/19/2018 16:26:17;0100;Server@node2;Req;;Type 11 request received from Scheduler@node2.supernodexp.hpc, sock=20
02/19/2018 16:26:17;0008;Server@node2;Job;3664.node2.supernodexp.hpc;Job Modified at request of Scheduler@node2.supernodexp.hpc
02/19/2018 16:26:17;0100;Server@node2;Req;;Type 11 request received from Scheduler@node2.supernodexp.hpc, sock=20
02/19/2018 16:26:17;0008;Server@node2;Job;3655.node2.supernodexp.hpc;Job Modified at request of Scheduler@node2.supernodexp.hpc
02/19/2018 16:26:17;0040;Server@node2;Svr;node2.supernodexp.hpc;Scheduler sent command 1
02/19/2018 16:26:17;0040;Server@node2;Svr;node2.supernodexp.hpc;Scheduler sent command 0
02/19/2018 16:26:17;0100;Server@node2;Req;;Type 21 request received from Scheduler@node2.supernodexp.hpc, sock=20
02/19/2018 16:26:17;0100;Server@node2;Req;;Type 81 request received from Scheduler@node2.supernodexp.hpc, sock=20
02/19/2018 16:26:17;0100;Server@node2;Req;;Type 71 request received from Scheduler@node2.supernodexp.hpc, sock=20
02/19/2018 16:26:17;0100;Server@node2;Req;;Type 58 request received from Scheduler@node2.supernodexp.hpc, sock=20
02/19/2018 16:26:17;0100;Server@node2;Req;;Type 20 request received from Scheduler@node2.supernodexp.hpc, sock=20
02/19/2018 16:26:17;0100;Server@node2;Req;;Type 51 request received from Scheduler@node2.supernodexp.hpc, sock=20
02/19/2018 16:26:17;0100;Server@node2;Req;;Type 1 request received from ctminh@node2.supernodexp.hpc, sock=16
02/19/2018 16:26:17;0100;Server@node2;Req;;Type 3 request received from ctminh@node2.supernodexp.hpc, sock=16
02/19/2018 16:26:17;0100;Server@node2;Req;;Type 5 request received from ctminh@node2.supernodexp.hpc, sock=16
02/19/2018 16:26:17;0100;Server@node2;Job;3666.node2.supernodexp.hpc;enqueuing into workq, state 1 hop 1
02/19/2018 16:26:17;0008;Server@node2;Job;3666.node2.supernodexp.hpc;Job Queued at request of ctminh@node2.supernodexp.hpc, owner = ctminh@node2.supernodexp.hpc, job name = nbody, queue = workq
02/19/2018 16:26:17;0040;Server@node2;Svr;node2.supernodexp.hpc;Scheduler sent command 1
02/19/2018 16:26:17;0040;Server@node2;Svr;node2.supernodexp.hpc;Scheduler sent command 0
02/19/2018 16:26:17;0100;Server@node2;Req;;Type 21 request received from Scheduler@node2.supernodexp.hpc, sock=20
02/19/2018 16:26:17;0100;Server@node2;Req;;Type 81 request received from Scheduler@node2.supernodexp.hpc, sock=20
02/19/2018 16:26:17;0100;Server@node2;Req;;Type 71 request received from Scheduler@node2.supernodexp.hpc, sock=20
02/19/2018 16:26:17;0100;Server@node2;Req;;Type 58 request received from Scheduler@node2.supernodexp.hpc, sock=20
02/19/2018 16:26:17;0100;Server@node2;Req;;Type 1 request received from ctminh@node2.supernodexp.hpc, sock=16
02/19/2018 16:26:18;0100;Server@node2;Req;;Type 3 request received from ctminh@node2.supernodexp.hpc, sock=16
02/19/2018 16:26:18;0100;Server@node2;Req;;Type 5 request received from ctminh@node2.supernodexp.hpc, sock=16
02/19/2018 16:26:18;0100;Server@node2;Job;3667.node2.supernodexp.hpc;enqueuing into workq, state 1 hop 1
02/19/2018 16:26:18;0008;Server@node2;Job;3667.node2.supernodexp.hpc;Job Queued at request of ctminh@node2.supernodexp.hpc, owner = ctminh@node2.supernodexp.hpc, job name = nbody, queue = workq
02/19/2018 16:26:18;0100;Server@node2;Req;;Type 1 request received from ctminh@node2.supernodexp.hpc, sock=16
02/19/2018 16:26:18;0100;Server@node2;Req;;Type 3 request received from ctminh@node2.supernodexp.hpc, sock=16
02/19/2018 16:26:18;0100;Server@node2;Req;;Type 5 request received from ctminh@node2.supernodexp.hpc, sock=16
02/19/2018 16:26:18;0100;Server@node2;Job;3668.node2.supernodexp.hpc;enqueuing into workq, state 1 hop 1
02/19/2018 16:26:18;0008;Server@node2;Job;3668.node2.supernodexp.hpc;Job Queued at request of ctminh@node2.supernodexp.hpc, owner = ctminh@node2.supernodexp.hpc, job name = qe_mic_test, queue = workq
02/19/2018 16:26:18;0100;Server@node2;Req;;Type 20 request received from Scheduler@node2.supernodexp.hpc, sock=20
02/19/2018 16:26:18;0100;Server@node2;Req;;Type 51 request received from Scheduler@node2.supernodexp.hpc, sock=20
02/19/2018 16:26:18;0100;Server@node2;Req;;Type 1 request received from ctminh@node2.supernodexp.hpc, sock=16
02/19/2018 16:26:18;0100;Server@node2;Req;;Type 3 request received from ctminh@node2.supernodexp.hpc, sock=16
02/19/2018 16:26:18;0100;Server@node2;Req;;Type 5 request received from ctminh@node2.supernodexp.hpc, sock=16
02/19/2018 16:26:18;0100;Server@node2;Job;3669.node2.supernodexp.hpc;enqueuing into workq, state 1 hop 1
02/19/2018 16:26:18;0008;Server@node2;Job;3669.node2.supernodexp.hpc;Job Queued at request of ctminh@node2.supernodexp.hpc, owner = ctminh@node2.supernodexp.hpc, job name = telemac2, queue = workq
02/19/2018 16:26:18;0100;Server@node2;Req;;Type 11 request received from Scheduler@node2.supernodexp.hpc, sock=20
02/19/2018 16:26:18;0008;Server@node2;Job;3655.node2.supernodexp.hpc;Job Modified at request of Scheduler@node2.supernodexp.hpc
02/19/2018 16:26:18;0100;Server@node2;Req;;Type 11 request received from Scheduler@node2.supernodexp.hpc, sock=20
02/19/2018 16:26:18;0008;Server@node2;Job;3666.node2.supernodexp.hpc;Job Modified at request of Scheduler@node2.supernodexp.hpc
02/19/2018 16:26:18;0100;Server@node2;Req;;Type 11 request received from Scheduler@node2.supernodexp.hpc, sock=20
02/19/2018 16:26:18;0008;Server@node2;Job;3667.node2.supernodexp.hpc;Job Modified at request of Scheduler@node2.supernodexp.hpc
02/19/2018 16:26:18;0100;Server@node2;Req;;Type 11 request received from Scheduler@node2.supernodexp.hpc, sock=20
02/19/2018 16:26:18;0008;Server@node2;Job;3668.node2.supernodexp.hpc;Job Modified at request of Scheduler@node2.supernodexp.hpc
02/19/2018 16:26:18;0040;Server@node2;Svr;node2.supernodexp.hpc;Scheduler sent command 1
02/19/2018 16:26:18;0040;Server@node2;Svr;node2.supernodexp.hpc;Scheduler sent command 0
02/19/2018 16:26:18;0100;Server@node2;Req;;Type 21 request received from Scheduler@node2.supernodexp.hpc, sock=20
02/19/2018 16:26:18;0100;Server@node2;Req;;Type 81 request received from Scheduler@node2.supernodexp.hpc, sock=20
02/19/2018 16:26:18;0100;Server@node2;Req;;Type 71 request received from Scheduler@node2.supernodexp.hpc, sock=20
02/19/2018 16:26:18;0100;Server@node2;Req;;Type 58 request received from Scheduler@node2.supernodexp.hpc, sock=20
02/19/2018 16:26:18;0100;Server@node2;Req;;Type 20 request received from Scheduler@node2.supernodexp.hpc, sock=20
02/19/2018 16:26:18;0100;Server@node2;Req;;Type 51 request received from Scheduler@node2.supernodexp.hpc, sock=20
02/19/2018 16:26:18;0100;Server@node2;Req;;Type 11 request received from Scheduler@node2.supernodexp.hpc, sock=20
02/19/2018 16:26:18;0008;Server@node2;Job;3669.node2.supernodexp.hpc;Job Modified at request of Scheduler@node2.supernodexp.hpc
02/19/2018 16:26:22;0100;Server@node2;Req;;Type 1 request received from ctminh@node2.supernodexp.hpc, sock=16
02/19/2018 16:26:22;0100;Server@node2;Req;;Type 3 request received from ctminh@node2.supernodexp.hpc, sock=16
02/19/2018 16:26:22;0100;Server@node2;Req;;Type 5 request received from ctminh@node2.supernodexp.hpc, sock=16
02/19/2018 16:26:22;0100;Server@node2;Job;3670.node2.supernodexp.hpc;enqueuing into workq, state 1 hop 1
02/19/2018 16:26:22;0008;Server@node2;Job;3670.node2.supernodexp.hpc;Job Queued at request of ctminh@node2.supernodexp.hpc, owner = ctminh@node2.supernodexp.hpc, job name = sweep, queue = workq
02/19/2018 16:26:22;0040;Server@node2;Svr;node2.supernodexp.hpc;Scheduler sent command 1
02/19/2018 16:26:22;0040;Server@node2;Svr;node2.supernodexp.hpc;Scheduler sent command 0
02/19/2018 16:26:22;0100;Server@node2;Req;;Type 21 request received from Scheduler@node2.supernodexp.hpc, sock=20
02/19/2018 16:26:22;0100;Server@node2;Req;;Type 81 request received from Scheduler@node2.supernodexp.hpc, sock=20
02/19/2018 16:26:22;0100;Server@node2;Req;;Type 71 request received from Scheduler@node2.supernodexp.hpc, sock=20
02/19/2018 16:26:22;0100;Server@node2;Req;;Type 58 request received from Scheduler@node2.supernodexp.hpc, sock=20
02/19/2018 16:26:22;0100;Server@node2;Req;;Type 20 request received from Scheduler@node2.supernodexp.hpc, sock=20
02/19/2018 16:26:22;0100;Server@node2;Req;;Type 51 request received from Scheduler@node2.supernodexp.hpc, sock=20
02/19/2018 16:26:22;0100;Server@node2;Req;;Type 11 request received from Scheduler@node2.supernodexp.hpc, sock=20
02/19/2018 16:26:22;0008;Server@node2;Job;3670.node2.supernodexp.hpc;Job Modified at request of Scheduler@node2.supernodexp.hpc
02/19/2018 16:26:26;0100;Server@node2;Req;;Type 1 request received from ctminh@node2.supernodexp.hpc, sock=16
02/19/2018 16:26:26;0100;Server@node2;Req;;Type 3 request received from ctminh@node2.supernodexp.hpc, sock=16
02/19/2018 16:26:26;0100;Server@node2;Req;;Type 5 request received from ctminh@node2.supernodexp.hpc, sock=16
02/19/2018 16:26:26;0100;Server@node2;Job;3671.node2.supernodexp.hpc;enqueuing into workq, state 1 hop 1
02/19/2018 16:26:26;0008;Server@node2;Job;3671.node2.supernodexp.hpc;Job Queued at request of ctminh@node2.supernodexp.hpc, owner = ctminh@node2.supernodexp.hpc, job name = nbody, queue = workq
02/19/2018 16:26:26;0040;Server@node2;Svr;node2.supernodexp.hpc;Scheduler sent command 1
02/19/2018 16:26:26;0040;Server@node2;Svr;node2.supernodexp.hpc;Scheduler sent command 0
02/19/2018 16:26:26;0100;Server@node2;Req;;Type 21 request received from Scheduler@node2.supernodexp.hpc, sock=20
02/19/2018 16:26:26;0100;Server@node2;Req;;Type 81 request received from Scheduler@node2.supernodexp.hpc, sock=20
02/19/2018 16:26:26;0100;Server@node2;Req;;Type 71 request received from Scheduler@node2.supernodexp.hpc, sock=20
02/19/2018 16:26:26;0100;Server@node2;Req;;Type 58 request received from Scheduler@node2.supernodexp.hpc, sock=20
02/19/2018 16:26:26;0100;Server@node2;Req;;Type 20 request received from Scheduler@node2.supernodexp.hpc, sock=20
02/19/2018 16:26:26;0100;Server@node2;Req;;Type 51 request received from Scheduler@node2.supernodexp.hpc, sock=20
02/19/2018 16:26:26;0100;Server@node2;Req;;Type 11 request received from Scheduler@node2.supernodexp.hpc, sock=20
02/19/2018 16:26:26;0008;Server@node2;Job;3671.node2.supernodexp.hpc;Job Modified at request of Scheduler@node2.supernodexp.hpc
02/19/2018 16:26:27;0100;Server@node2;Req;;Type 1 request received from ctminh@node2.supernodexp.hpc, sock=16
02/19/2018 16:26:27;0100;Server@node2;Req;;Type 3 request received from ctminh@node2.supernodexp.hpc, sock=16
02/19/2018 16:26:27;0100;Server@node2;Req;;Type 5 request received from ctminh@node2.supernodexp.hpc, sock=16
02/19/2018 16:26:27;0100;Server@node2;Job;3672.node2.supernodexp.hpc;enqueuing into workq, state 1 hop 1
02/19/2018 16:26:27;0008;Server@node2;Job;3672.node2.supernodexp.hpc;Job Queued at request of ctminh@node2.supernodexp.hpc, owner = ctminh@node2.supernodexp.hpc, job name = qe_mic_test, queue = workq
02/19/2018 16:26:27;0040;Server@node2;Svr;node2.supernodexp.hpc;Scheduler sent command 1
02/19/2018 16:26:27;0040;Server@node2;Svr;node2.supernodexp.hpc;Scheduler sent command 0
02/19/2018 16:26:27;0100;Server@node2;Req;;Type 21 request received from Scheduler@node2.supernodexp.hpc, sock=20
02/19/2018 16:26:27;0100;Server@node2;Req;;Type 81 request received from Scheduler@node2.supernodexp.hpc, sock=20
02/19/2018 16:26:27;0100;Server@node2;Req;;Type 71 request received from Scheduler@node2.supernodexp.hpc, sock=20
02/19/2018 16:26:27;0100;Server@node2;Req;;Type 58 request received from Scheduler@node2.supernodexp.hpc, sock=20
02/19/2018 16:26:27;0100;Server@node2;Req;;Type 1 request received from ctminh@node2.supernodexp.hpc, sock=16
02/19/2018 16:26:27;0100;Server@node2;Req;;Type 3 request received from ctminh@node2.supernodexp.hpc, sock=16
02/19/2018 16:26:27;0100;Server@node2;Req;;Type 5 request received from ctminh@node2.supernodexp.hpc, sock=16
02/19/2018 16:26:27;0100;Server@node2;Job;3673.node2.supernodexp.hpc;enqueuing into workq, state 1 hop 1
02/19/2018 16:26:27;0008;Server@node2;Job;3673.node2.supernodexp.hpc;Job Queued at request of ctminh@node2.supernodexp.hpc, owner = ctminh@node2.supernodexp.hpc, job name = nbody, queue = workq
02/19/2018 16:26:27;0100;Server@node2;Req;;Type 20 request received from Scheduler@node2.supernodexp.hpc, sock=20
02/19/2018 16:26:27;0100;Server@node2;Req;;Type 51 request received from Scheduler@node2.supernodexp.hpc, sock=20
02/19/2018 16:26:27;0100;Server@node2;Req;;Type 11 request received from Scheduler@node2.supernodexp.hpc, sock=20
02/19/2018 16:26:27;0008;Server@node2;Job;3672.node2.supernodexp.hpc;Job Modified at request of Scheduler@node2.supernodexp.hpc
02/19/2018 16:26:27;0100;Server@node2;Req;;Type 11 request received from Scheduler@node2.supernodexp.hpc, sock=20
02/19/2018 16:26:27;0008;Server@node2;Job;3673.node2.supernodexp.hpc;Job Modified at request of Scheduler@node2.supernodexp.hpc
02/19/2018 16:26:27;0040;Server@node2;Svr;node2.supernodexp.hpc;Scheduler sent command 1
02/19/2018 16:26:27;0040;Server@node2;Svr;node2.supernodexp.hpc;Scheduler sent command 0
02/19/2018 16:26:27;0100;Server@node2;Req;;Type 21 request received from Scheduler@node2.supernodexp.hpc, sock=20
02/19/2018 16:26:27;0100;Server@node2;Req;;Type 81 request received from Scheduler@node2.supernodexp.hpc, sock=20
02/19/2018 16:26:27;0100;Server@node2;Req;;Type 71 request received from Scheduler@node2.supernodexp.hpc, sock=20
02/19/2018 16:26:27;0100;Server@node2;Req;;Type 58 request received from Scheduler@node2.supernodexp.hpc, sock=20
02/19/2018 16:26:27;0100;Server@node2;Req;;Type 20 request received from Scheduler@node2.supernodexp.hpc, sock=20
02/19/2018 16:26:27;0100;Server@node2;Req;;Type 51 request received from Scheduler@node2.supernodexp.hpc, sock=20
02/19/2018 16:27:55;0080;Server@node2;Job;3646.node2.supernodexp.hpc;Obit received momhop:1 serverhop:1 state:4 substate:42
02/19/2018 16:27:57;0010;Server@node2;Job;3646.node2.supernodexp.hpc;Exit_status=0 resources_used.cpupercent=659 resources_used.cput=00:36:38 resources_used.mem=1115092kb resources_used.ncpus=16 resources_used.vmem=9811900kb resources_used.walltime=00:02:31
02/19/2018 16:27:57;0100;Server@node2;Job;3646.node2.supernodexp.hpc;dequeuing from workq, state 5
02/19/2018 16:27:57;0040;Server@node2;Svr;node2.supernodexp.hpc;Scheduler sent command 2
02/19/2018 16:27:57;0040;Server@node2;Svr;node2.supernodexp.hpc;Scheduler sent command 0
02/19/2018 16:27:57;0100;Server@node2;Req;;Type 21 request received from Scheduler@node2.supernodexp.hpc, sock=16
02/19/2018 16:27:57;0100;Server@node2;Req;;Type 81 request received from Scheduler@node2.supernodexp.hpc, sock=16
02/19/2018 16:27:57;0100;Server@node2;Req;;Type 71 request received from Scheduler@node2.supernodexp.hpc, sock=16
02/19/2018 16:27:57;0100;Server@node2;Req;;Type 58 request received from Scheduler@node2.supernodexp.hpc, sock=16
02/19/2018 16:27:57;0100;Server@node2;Req;;Type 20 request received from Scheduler@node2.supernodexp.hpc, sock=16
02/19/2018 16:27:57;0100;Server@node2;Req;;Type 51 request received from Scheduler@node2.supernodexp.hpc, sock=16
02/19/2018 16:27:57;0100;Server@node2;Req;;Type 11 request received from Scheduler@node2.supernodexp.hpc, sock=16
02/19/2018 16:27:57;0008;Server@node2;Job;3668.node2.supernodexp.hpc;Job Modified at request of Scheduler@node2.supernodexp.hpc
02/19/2018 16:30:43;0100;Server@node2;Req;;Type 0 request received from ctminh@node2.supernodexp.hpc, sock=16
02/19/2018 16:30:43;0100;Server@node2;Req;;Type 49 request received from ctminh@node2.supernodexp.hpc, sock=20
02/19/2018 16:30:43;0100;Server@node2;Req;;Type 21 request received from ctminh@node2.supernodexp.hpc, sock=16
02/19/2018 16:30:43;0100;Server@node2;Req;;Type 1 request received from ctminh@node2.supernodexp.hpc, sock=16
02/19/2018 16:30:43;0100;Server@node2;Req;;Type 3 request received from ctminh@node2.supernodexp.hpc, sock=16
02/19/2018 16:30:43;0100;Server@node2;Req;;Type 5 request received from ctminh@node2.supernodexp.hpc, sock=16
02/19/2018 16:30:43;0100;Server@node2;Job;3674.node2.supernodexp.hpc;enqueuing into workq, state 1 hop 1
02/19/2018 16:30:43;0008;Server@node2;Job;3674.node2.supernodexp.hpc;Job Queued at request of ctminh@node2.supernodexp.hpc, owner = ctminh@node2.supernodexp.hpc, job name = matrix-x-vector, queue = workq
02/19/2018 16:30:43;0040;Server@node2;Svr;node2.supernodexp.hpc;Scheduler sent command 1
02/19/2018 16:30:43;0040;Server@node2;Svr;node2.supernodexp.hpc;Scheduler sent command 0
02/19/2018 16:30:43;0100;Server@node2;Req;;Type 21 request received from Scheduler@node2.supernodexp.hpc, sock=20
02/19/2018 16:30:43;0100;Server@node2;Req;;Type 81 request received from Scheduler@node2.supernodexp.hpc, sock=20
02/19/2018 16:30:43;0100;Server@node2;Req;;Type 71 request received from Scheduler@node2.supernodexp.hpc, sock=20
02/19/2018 16:30:43;0100;Server@node2;Req;;Type 58 request received from Scheduler@node2.supernodexp.hpc, sock=20
02/19/2018 16:30:43;0100;Server@node2;Req;;Type 20 request received from Scheduler@node2.supernodexp.hpc, sock=20
02/19/2018 16:30:43;0100;Server@node2;Req;;Type 51 request received from Scheduler@node2.supernodexp.hpc, sock=20
02/19/2018 16:30:43;0100;Server@node2;Req;;Type 11 request received from Scheduler@node2.supernodexp.hpc, sock=20
02/19/2018 16:30:43;0008;Server@node2;Job;3674.node2.supernodexp.hpc;Job Modified at request of Scheduler@node2.supernodexp.hpc
02/19/2018 16:31:28;0100;Server@node2;Req;;Type 1 request received from ctminh@node2.supernodexp.hpc, sock=16
02/19/2018 16:31:28;0100;Server@node2;Req;;Type 3 request received from ctminh@node2.supernodexp.hpc, sock=16
02/19/2018 16:31:28;0100;Server@node2;Req;;Type 5 request received from ctminh@node2.supernodexp.hpc, sock=16
02/19/2018 16:31:28;0100;Server@node2;Job;3675.node2.supernodexp.hpc;enqueuing into workq, state 1 hop 1
02/19/2018 16:31:28;0008;Server@node2;Job;3675.node2.supernodexp.hpc;Job Queued at request of ctminh@node2.supernodexp.hpc, owner = ctminh@node2.supernodexp.hpc, job name = telemac2, queue = workq
02/19/2018 16:31:28;0040;Server@node2;Svr;node2.supernodexp.hpc;Scheduler sent command 1
02/19/2018 16:31:28;0040;Server@node2;Svr;node2.supernodexp.hpc;Scheduler sent command 0
02/19/2018 16:31:28;0100;Server@node2;Req;;Type 21 request received from Scheduler@node2.supernodexp.hpc, sock=20
02/19/2018 16:31:28;0100;Server@node2;Req;;Type 81 request received from Scheduler@node2.supernodexp.hpc, sock=20
02/19/2018 16:31:28;0100;Server@node2;Req;;Type 71 request received from Scheduler@node2.supernodexp.hpc, sock=20
02/19/2018 16:31:28;0100;Server@node2;Req;;Type 58 request received from Scheduler@node2.supernodexp.hpc, sock=20
02/19/2018 16:31:28;0100;Server@node2;Req;;Type 20 request received from Scheduler@node2.supernodexp.hpc, sock=20
02/19/2018 16:31:28;0100;Server@node2;Req;;Type 51 request received from Scheduler@node2.supernodexp.hpc, sock=20
02/19/2018 16:31:28;0100;Server@node2;Req;;Type 11 request received from Scheduler@node2.supernodexp.hpc, sock=20
02/19/2018 16:31:28;0008;Server@node2;Job;3675.node2.supernodexp.hpc;Job Modified at request of Scheduler@node2.supernodexp.hpc
02/19/2018 16:31:39;0100;Server@node2;Req;;Type 1 request received from ctminh@node2.supernodexp.hpc, sock=16
02/19/2018 16:31:39;0100;Server@node2;Req;;Type 3 request received from ctminh@node2.supernodexp.hpc, sock=16
02/19/2018 16:31:39;0100;Server@node2;Req;;Type 5 request received from ctminh@node2.supernodexp.hpc, sock=16
02/19/2018 16:31:39;0100;Server@node2;Job;3676.node2.supernodexp.hpc;enqueuing into workq, state 1 hop 1
02/19/2018 16:31:39;0008;Server@node2;Job;3676.node2.supernodexp.hpc;Job Queued at request of ctminh@node2.supernodexp.hpc, owner = ctminh@node2.supernodexp.hpc, job name = qe_mic_test, queue = workq
02/19/2018 16:31:39;0040;Server@node2;Svr;node2.supernodexp.hpc;Scheduler sent command 1
02/19/2018 16:31:39;0040;Server@node2;Svr;node2.supernodexp.hpc;Scheduler sent command 0
02/19/2018 16:31:39;0100;Server@node2;Req;;Type 21 request received from Scheduler@node2.supernodexp.hpc, sock=20
02/19/2018 16:31:39;0100;Server@node2;Req;;Type 81 request received from Scheduler@node2.supernodexp.hpc, sock=20
02/19/2018 16:31:39;0100;Server@node2;Req;;Type 71 request received from Scheduler@node2.supernodexp.hpc, sock=20
02/19/2018 16:31:39;0100;Server@node2;Req;;Type 58 request received from Scheduler@node2.supernodexp.hpc, sock=20
02/19/2018 16:31:39;0100;Server@node2;Req;;Type 20 request received from Scheduler@node2.supernodexp.hpc, sock=20
02/19/2018 16:31:39;0100;Server@node2;Req;;Type 51 request received from Scheduler@node2.supernodexp.hpc, sock=20
02/19/2018 16:31:39;0100;Server@node2;Req;;Type 11 request received from Scheduler@node2.supernodexp.hpc, sock=20
02/19/2018 16:31:39;0008;Server@node2;Job;3676.node2.supernodexp.hpc;Job Modified at request of Scheduler@node2.supernodexp.hpc
02/19/2018 16:31:40;0100;Server@node2;Req;;Type 1 request received from ctminh@node2.supernodexp.hpc, sock=16
02/19/2018 16:31:40;0100;Server@node2;Req;;Type 3 request received from ctminh@node2.supernodexp.hpc, sock=16
02/19/2018 16:31:40;0100;Server@node2;Req;;Type 5 request received from ctminh@node2.supernodexp.hpc, sock=16
02/19/2018 16:31:40;0100;Server@node2;Job;3677.node2.supernodexp.hpc;enqueuing into workq, state 1 hop 1
02/19/2018 16:31:40;0008;Server@node2;Job;3677.node2.supernodexp.hpc;Job Queued at request of ctminh@node2.supernodexp.hpc, owner = ctminh@node2.supernodexp.hpc, job name = telemac3, queue = workq
02/19/2018 16:31:40;0040;Server@node2;Svr;node2.supernodexp.hpc;Scheduler sent command 1
02/19/2018 16:31:40;0040;Server@node2;Svr;node2.supernodexp.hpc;Scheduler sent command 0
02/19/2018 16:31:40;0100;Server@node2;Req;;Type 21 request received from Scheduler@node2.supernodexp.hpc, sock=20
02/19/2018 16:31:40;0100;Server@node2;Req;;Type 81 request received from Scheduler@node2.supernodexp.hpc, sock=20
02/19/2018 16:31:40;0100;Server@node2;Req;;Type 71 request received from Scheduler@node2.supernodexp.hpc, sock=20
02/19/2018 16:31:40;0100;Server@node2;Req;;Type 58 request received from Scheduler@node2.supernodexp.hpc, sock=20
02/19/2018 16:31:40;0100;Server@node2;Req;;Type 20 request received from Scheduler@node2.supernodexp.hpc, sock=20
02/19/2018 16:31:40;0100;Server@node2;Req;;Type 51 request received from Scheduler@node2.supernodexp.hpc, sock=20
02/19/2018 16:31:40;0100;Server@node2;Req;;Type 11 request received from Scheduler@node2.supernodexp.hpc, sock=20
02/19/2018 16:31:40;0008;Server@node2;Job;3677.node2.supernodexp.hpc;Job Modified at request of Scheduler@node2.supernodexp.hpc
02/19/2018 16:31:42;0100;Server@node2;Req;;Type 1 request received from ctminh@node2.supernodexp.hpc, sock=16
02/19/2018 16:31:42;0100;Server@node2;Req;;Type 3 request received from ctminh@node2.supernodexp.hpc, sock=16
02/19/2018 16:31:42;0100;Server@node2;Req;;Type 5 request received from ctminh@node2.supernodexp.hpc, sock=16
02/19/2018 16:31:42;0100;Server@node2;Job;3678.node2.supernodexp.hpc;enqueuing into workq, state 1 hop 1
02/19/2018 16:31:42;0008;Server@node2;Job;3678.node2.supernodexp.hpc;Job Queued at request of ctminh@node2.supernodexp.hpc, owner = ctminh@node2.supernodexp.hpc, job name = nbody, queue = workq
02/19/2018 16:31:42;0040;Server@node2;Svr;node2.supernodexp.hpc;Scheduler sent command 1
02/19/2018 16:31:42;0040;Server@node2;Svr;node2.supernodexp.hpc;Scheduler sent command 0
02/19/2018 16:31:42;0100;Server@node2;Req;;Type 21 request received from Scheduler@node2.supernodexp.hpc, sock=20
02/19/2018 16:31:42;0100;Server@node2;Req;;Type 81 request received from Scheduler@node2.supernodexp.hpc, sock=20
02/19/2018 16:31:42;0100;Server@node2;Req;;Type 71 request received from Scheduler@node2.supernodexp.hpc, sock=20
02/19/2018 16:31:42;0100;Server@node2;Req;;Type 58 request received from Scheduler@node2.supernodexp.hpc, sock=20
02/19/2018 16:31:42;0100;Server@node2;Req;;Type 20 request received from Scheduler@node2.supernodexp.hpc, sock=20
02/19/2018 16:31:42;0100;Server@node2;Req;;Type 51 request received from Scheduler@node2.supernodexp.hpc, sock=20
02/19/2018 16:31:42;0100;Server@node2;Req;;Type 11 request received from Scheduler@node2.supernodexp.hpc, sock=20
02/19/2018 16:31:42;0008;Server@node2;Job;3678.node2.supernodexp.hpc;Job Modified at request of Scheduler@node2.supernodexp.hpc
02/19/2018 16:31:44;0100;Server@node2;Req;;Type 1 request received from ctminh@node2.supernodexp.hpc, sock=16
02/19/2018 16:31:44;0100;Server@node2;Req;;Type 3 request received from ctminh@node2.supernodexp.hpc, sock=16
02/19/2018 16:31:44;0100;Server@node2;Req;;Type 5 request received from ctminh@node2.supernodexp.hpc, sock=16
02/19/2018 16:31:44;0100;Server@node2;Job;3679.node2.supernodexp.hpc;enqueuing into workq, state 1 hop 1
02/19/2018 16:31:44;0008;Server@node2;Job;3679.node2.supernodexp.hpc;Job Queued at request of ctminh@node2.supernodexp.hpc, owner = ctminh@node2.supernodexp.hpc, job name = qe_mic_test, queue = workq
02/19/2018 16:31:44;0040;Server@node2;Svr;node2.supernodexp.hpc;Scheduler sent command 1
02/19/2018 16:31:44;0040;Server@node2;Svr;node2.supernodexp.hpc;Scheduler sent command 0
02/19/2018 16:31:44;0100;Server@node2;Req;;Type 21 request received from Scheduler@node2.supernodexp.hpc, sock=20
02/19/2018 16:31:44;0100;Server@node2;Req;;Type 81 request received from Scheduler@node2.supernodexp.hpc, sock=20
02/19/2018 16:31:44;0100;Server@node2;Req;;Type 71 request received from Scheduler@node2.supernodexp.hpc, sock=20
02/19/2018 16:31:44;0100;Server@node2;Req;;Type 58 request received from Scheduler@node2.supernodexp.hpc, sock=20
02/19/2018 16:31:44;0100;Server@node2;Req;;Type 20 request received from Scheduler@node2.supernodexp.hpc, sock=20
02/19/2018 16:31:44;0100;Server@node2;Req;;Type 51 request received from Scheduler@node2.supernodexp.hpc, sock=20
02/19/2018 16:31:44;0100;Server@node2;Req;;Type 11 request received from Scheduler@node2.supernodexp.hpc, sock=20
02/19/2018 16:31:44;0008;Server@node2;Job;3679.node2.supernodexp.hpc;Job Modified at request of Scheduler@node2.supernodexp.hpc
02/19/2018 16:31:45;0100;Server@node2;Req;;Type 1 request received from ctminh@node2.supernodexp.hpc, sock=16
02/19/2018 16:31:45;0100;Server@node2;Req;;Type 3 request received from ctminh@node2.supernodexp.hpc, sock=16
02/19/2018 16:31:45;0100;Server@node2;Req;;Type 5 request received from ctminh@node2.supernodexp.hpc, sock=16
02/19/2018 16:31:45;0100;Server@node2;Job;3680.node2.supernodexp.hpc;enqueuing into workq, state 1 hop 1
02/19/2018 16:31:45;0008;Server@node2;Job;3680.node2.supernodexp.hpc;Job Queued at request of ctminh@node2.supernodexp.hpc, owner = ctminh@node2.supernodexp.hpc, job name = telemac1, queue = workq
02/19/2018 16:31:45;0040;Server@node2;Svr;node2.supernodexp.hpc;Scheduler sent command 1
02/19/2018 16:31:45;0040;Server@node2;Svr;node2.supernodexp.hpc;Scheduler sent command 0
02/19/2018 16:31:45;0100;Server@node2;Req;;Type 21 request received from Scheduler@node2.supernodexp.hpc, sock=20
02/19/2018 16:31:45;0100;Server@node2;Req;;Type 81 request received from Scheduler@node2.supernodexp.hpc, sock=20
02/19/2018 16:31:45;0100;Server@node2;Req;;Type 71 request received from Scheduler@node2.supernodexp.hpc, sock=20
02/19/2018 16:31:45;0100;Server@node2;Req;;Type 58 request received from Scheduler@node2.supernodexp.hpc, sock=20
02/19/2018 16:31:45;0100;Server@node2;Req;;Type 20 request received from Scheduler@node2.supernodexp.hpc, sock=20
02/19/2018 16:31:45;0100;Server@node2;Req;;Type 51 request received from Scheduler@node2.supernodexp.hpc, sock=20
02/19/2018 16:31:45;0100;Server@node2;Req;;Type 11 request received from Scheduler@node2.supernodexp.hpc, sock=20
02/19/2018 16:31:45;0008;Server@node2;Job;3680.node2.supernodexp.hpc;Job Modified at request of Scheduler@node2.supernodexp.hpc
02/19/2018 16:31:49;0100;Server@node2;Req;;Type 1 request received from ctminh@node2.supernodexp.hpc, sock=16
02/19/2018 16:31:49;0100;Server@node2;Req;;Type 3 request received from ctminh@node2.supernodexp.hpc, sock=16
02/19/2018 16:31:49;0100;Server@node2;Req;;Type 5 request received from ctminh@node2.supernodexp.hpc, sock=16
02/19/2018 16:31:49;0100;Server@node2;Job;3681.node2.supernodexp.hpc;enqueuing into workq, state 1 hop 1
02/19/2018 16:31:49;0008;Server@node2;Job;3681.node2.supernodexp.hpc;Job Queued at request of ctminh@node2.supernodexp.hpc, owner = ctminh@node2.supernodexp.hpc, job name = telemac3, queue = workq
02/19/2018 16:31:49;0040;Server@node2;Svr;node2.supernodexp.hpc;Scheduler sent command 1
02/19/2018 16:31:49;0040;Server@node2;Svr;node2.supernodexp.hpc;Scheduler sent command 0
02/19/2018 16:31:49;0100;Server@node2;Req;;Type 21 request received from Scheduler@node2.supernodexp.hpc, sock=20
02/19/2018 16:31:49;0100;Server@node2;Req;;Type 81 request received from Scheduler@node2.supernodexp.hpc, sock=20
02/19/2018 16:31:49;0100;Server@node2;Req;;Type 71 request received from Scheduler@node2.supernodexp.hpc, sock=20
02/19/2018 16:31:49;0100;Server@node2;Req;;Type 58 request received from Scheduler@node2.supernodexp.hpc, sock=20
02/19/2018 16:31:49;0100;Server@node2;Req;;Type 1 request received from ctminh@node2.supernodexp.hpc, sock=16
02/19/2018 16:31:49;0100;Server@node2;Req;;Type 3 request received from ctminh@node2.supernodexp.hpc, sock=16
02/19/2018 16:31:49;0100;Server@node2;Req;;Type 5 request received from ctminh@node2.supernodexp.hpc, sock=16
02/19/2018 16:31:49;0100;Server@node2;Job;3682.node2.supernodexp.hpc;enqueuing into workq, state 1 hop 1
02/19/2018 16:31:49;0008;Server@node2;Job;3682.node2.supernodexp.hpc;Job Queued at request of ctminh@node2.supernodexp.hpc, owner = ctminh@node2.supernodexp.hpc, job name = vectorization, queue = workq
02/19/2018 16:31:49;0100;Server@node2;Req;;Type 20 request received from Scheduler@node2.supernodexp.hpc, sock=20
02/19/2018 16:31:49;0100;Server@node2;Req;;Type 51 request received from Scheduler@node2.supernodexp.hpc, sock=20
02/19/2018 16:31:49;0100;Server@node2;Req;;Type 1 request received from ctminh@node2.supernodexp.hpc, sock=16
02/19/2018 16:31:49;0100;Server@node2;Req;;Type 3 request received from ctminh@node2.supernodexp.hpc, sock=16
02/19/2018 16:31:49;0100;Server@node2;Req;;Type 5 request received from ctminh@node2.supernodexp.hpc, sock=16
02/19/2018 16:31:49;0100;Server@node2;Job;3683.node2.supernodexp.hpc;enqueuing into workq, state 1 hop 1
02/19/2018 16:31:49;0008;Server@node2;Job;3683.node2.supernodexp.hpc;Job Queued at request of ctminh@node2.supernodexp.hpc, owner = ctminh@node2.supernodexp.hpc, job name = thread-affinity, queue = workq
02/19/2018 16:31:49;0100;Server@node2;Req;;Type 1 request received from ctminh@node2.supernodexp.hpc, sock=16
02/19/2018 16:31:49;0100;Server@node2;Req;;Type 3 request received from ctminh@node2.supernodexp.hpc, sock=16
02/19/2018 16:31:49;0100;Server@node2;Req;;Type 5 request received from ctminh@node2.supernodexp.hpc, sock=16
02/19/2018 16:31:49;0100;Server@node2;Job;3684.node2.supernodexp.hpc;enqueuing into workq, state 1 hop 1
02/19/2018 16:31:49;0008;Server@node2;Job;3684.node2.supernodexp.hpc;Job Queued at request of ctminh@node2.supernodexp.hpc, owner = ctminh@node2.supernodexp.hpc, job name = telemac1, queue = workq
02/19/2018 16:31:49;0100;Server@node2;Req;;Type 11 request received from Scheduler@node2.supernodexp.hpc, sock=20
02/19/2018 16:31:49;0008;Server@node2;Job;3681.node2.supernodexp.hpc;Job Modified at request of Scheduler@node2.supernodexp.hpc
02/19/2018 16:31:49;0100;Server@node2;Req;;Type 11 request received from Scheduler@node2.supernodexp.hpc, sock=20
02/19/2018 16:31:49;0008;Server@node2;Job;3682.node2.supernodexp.hpc;Job Modified at request of Scheduler@node2.supernodexp.hpc
02/19/2018 16:31:49;0040;Server@node2;Svr;node2.supernodexp.hpc;Scheduler sent command 1
02/19/2018 16:31:49;0040;Server@node2;Svr;node2.supernodexp.hpc;Scheduler sent command 0
02/19/2018 16:31:49;0100;Server@node2;Req;;Type 21 request received from Scheduler@node2.supernodexp.hpc, sock=20
02/19/2018 16:31:49;0100;Server@node2;Req;;Type 81 request received from Scheduler@node2.supernodexp.hpc, sock=20
02/19/2018 16:31:49;0100;Server@node2;Req;;Type 71 request received from Scheduler@node2.supernodexp.hpc, sock=20
02/19/2018 16:31:49;0100;Server@node2;Req;;Type 58 request received from Scheduler@node2.supernodexp.hpc, sock=20
02/19/2018 16:31:49;0100;Server@node2;Req;;Type 20 request received from Scheduler@node2.supernodexp.hpc, sock=20
02/19/2018 16:31:49;0100;Server@node2;Req;;Type 51 request received from Scheduler@node2.supernodexp.hpc, sock=20
02/19/2018 16:31:49;0100;Server@node2;Req;;Type 11 request received from Scheduler@node2.supernodexp.hpc, sock=20
02/19/2018 16:31:49;0008;Server@node2;Job;3684.node2.supernodexp.hpc;Job Modified at request of Scheduler@node2.supernodexp.hpc
02/19/2018 16:31:49;0100;Server@node2;Req;;Type 11 request received from Scheduler@node2.supernodexp.hpc, sock=20
02/19/2018 16:31:49;0008;Server@node2;Job;3683.node2.supernodexp.hpc;Job Modified at request of Scheduler@node2.supernodexp.hpc
02/19/2018 16:31:50;0100;Server@node2;Req;;Type 1 request received from ctminh@node2.supernodexp.hpc, sock=16
02/19/2018 16:31:50;0100;Server@node2;Req;;Type 3 request received from ctminh@node2.supernodexp.hpc, sock=16
02/19/2018 16:31:50;0100;Server@node2;Req;;Type 5 request received from ctminh@node2.supernodexp.hpc, sock=16
02/19/2018 16:31:50;0100;Server@node2;Job;3685.node2.supernodexp.hpc;enqueuing into workq, state 1 hop 1
02/19/2018 16:31:50;0008;Server@node2;Job;3685.node2.supernodexp.hpc;Job Queued at request of ctminh@node2.supernodexp.hpc, owner = ctminh@node2.supernodexp.hpc, job name = vast1, queue = workq
02/19/2018 16:31:50;0040;Server@node2;Svr;node2.supernodexp.hpc;Scheduler sent command 1
02/19/2018 16:31:50;0040;Server@node2;Svr;node2.supernodexp.hpc;Scheduler sent command 0
02/19/2018 16:31:50;0100;Server@node2;Req;;Type 21 request received from Scheduler@node2.supernodexp.hpc, sock=20
02/19/2018 16:31:50;0100;Server@node2;Req;;Type 81 request received from Scheduler@node2.supernodexp.hpc, sock=20
02/19/2018 16:31:50;0100;Server@node2;Req;;Type 71 request received from Scheduler@node2.supernodexp.hpc, sock=20
02/19/2018 16:31:50;0100;Server@node2;Req;;Type 58 request received from Scheduler@node2.supernodexp.hpc, sock=20
02/19/2018 16:31:50;0100;Server@node2;Req;;Type 20 request received from Scheduler@node2.supernodexp.hpc, sock=20
02/19/2018 16:31:50;0100;Server@node2;Req;;Type 51 request received from Scheduler@node2.supernodexp.hpc, sock=20
02/19/2018 16:31:50;0100;Server@node2;Req;;Type 11 request received from Scheduler@node2.supernodexp.hpc, sock=20
02/19/2018 16:31:50;0008;Server@node2;Job;3685.node2.supernodexp.hpc;Job Modified at request of Scheduler@node2.supernodexp.hpc
02/19/2018 16:31:52;0100;Server@node2;Req;;Type 1 request received from ctminh@node2.supernodexp.hpc, sock=16
02/19/2018 16:31:52;0100;Server@node2;Req;;Type 3 request received from ctminh@node2.supernodexp.hpc, sock=16
02/19/2018 16:31:52;0100;Server@node2;Req;;Type 5 request received from ctminh@node2.supernodexp.hpc, sock=16
02/19/2018 16:31:52;0100;Server@node2;Job;3686.node2.supernodexp.hpc;enqueuing into workq, state 1 hop 1
02/19/2018 16:31:52;0008;Server@node2;Job;3686.node2.supernodexp.hpc;Job Queued at request of ctminh@node2.supernodexp.hpc, owner = ctminh@node2.supernodexp.hpc, job name = qe_mic_test, queue = workq
02/19/2018 16:31:52;0040;Server@node2;Svr;node2.supernodexp.hpc;Scheduler sent command 1
02/19/2018 16:31:52;0040;Server@node2;Svr;node2.supernodexp.hpc;Scheduler sent command 0
02/19/2018 16:31:52;0100;Server@node2;Req;;Type 21 request received from Scheduler@node2.supernodexp.hpc, sock=20
02/19/2018 16:31:52;0100;Server@node2;Req;;Type 81 request received from Scheduler@node2.supernodexp.hpc, sock=20
02/19/2018 16:31:52;0100;Server@node2;Req;;Type 71 request received from Scheduler@node2.supernodexp.hpc, sock=20
02/19/2018 16:31:52;0100;Server@node2;Req;;Type 58 request received from Scheduler@node2.supernodexp.hpc, sock=20
02/19/2018 16:31:52;0100;Server@node2;Req;;Type 20 request received from Scheduler@node2.supernodexp.hpc, sock=20
02/19/2018 16:31:52;0100;Server@node2;Req;;Type 51 request received from Scheduler@node2.supernodexp.hpc, sock=20
02/19/2018 16:31:52;0100;Server@node2;Req;;Type 11 request received from Scheduler@node2.supernodexp.hpc, sock=20
02/19/2018 16:31:52;0008;Server@node2;Job;3686.node2.supernodexp.hpc;Job Modified at request of Scheduler@node2.supernodexp.hpc
02/19/2018 16:31:53;0100;Server@node2;Req;;Type 1 request received from ctminh@node2.supernodexp.hpc, sock=16
02/19/2018 16:31:53;0100;Server@node2;Req;;Type 3 request received from ctminh@node2.supernodexp.hpc, sock=16
02/19/2018 16:31:53;0100;Server@node2;Req;;Type 5 request received from ctminh@node2.supernodexp.hpc, sock=16
02/19/2018 16:31:53;0100;Server@node2;Job;3687.node2.supernodexp.hpc;enqueuing into workq, state 1 hop 1
02/19/2018 16:31:53;0008;Server@node2;Job;3687.node2.supernodexp.hpc;Job Queued at request of ctminh@node2.supernodexp.hpc, owner = ctminh@node2.supernodexp.hpc, job name = nbody, queue = workq
02/19/2018 16:31:53;0040;Server@node2;Svr;node2.supernodexp.hpc;Scheduler sent command 1
02/19/2018 16:31:53;0040;Server@node2;Svr;node2.supernodexp.hpc;Scheduler sent command 0
02/19/2018 16:31:53;0100;Server@node2;Req;;Type 21 request received from Scheduler@node2.supernodexp.hpc, sock=20
02/19/2018 16:31:53;0100;Server@node2;Req;;Type 81 request received from Scheduler@node2.supernodexp.hpc, sock=20
02/19/2018 16:31:53;0100;Server@node2;Req;;Type 71 request received from Scheduler@node2.supernodexp.hpc, sock=20
02/19/2018 16:31:53;0100;Server@node2;Req;;Type 58 request received from Scheduler@node2.supernodexp.hpc, sock=20
02/19/2018 16:31:53;0100;Server@node2;Req;;Type 20 request received from Scheduler@node2.supernodexp.hpc, sock=20
02/19/2018 16:31:53;0100;Server@node2;Req;;Type 51 request received from Scheduler@node2.supernodexp.hpc, sock=20
02/19/2018 16:31:53;0100;Server@node2;Req;;Type 11 request received from Scheduler@node2.supernodexp.hpc, sock=20
02/19/2018 16:31:53;0008;Server@node2;Job;3687.node2.supernodexp.hpc;Job Modified at request of Scheduler@node2.supernodexp.hpc
02/19/2018 16:31:54;0100;Server@node2;Req;;Type 1 request received from ctminh@node2.supernodexp.hpc, sock=16
02/19/2018 16:31:54;0100;Server@node2;Req;;Type 3 request received from ctminh@node2.supernodexp.hpc, sock=16
02/19/2018 16:31:54;0100;Server@node2;Req;;Type 5 request received from ctminh@node2.supernodexp.hpc, sock=16
02/19/2018 16:31:54;0100;Server@node2;Job;3688.node2.supernodexp.hpc;enqueuing into workq, state 1 hop 1
02/19/2018 16:31:54;0008;Server@node2;Job;3688.node2.supernodexp.hpc;Job Queued at request of ctminh@node2.supernodexp.hpc, owner = ctminh@node2.supernodexp.hpc, job name = lu-decomp, queue = workq
02/19/2018 16:31:54;0040;Server@node2;Svr;node2.supernodexp.hpc;Scheduler sent command 1
02/19/2018 16:31:54;0040;Server@node2;Svr;node2.supernodexp.hpc;Scheduler sent command 0
02/19/2018 16:31:54;0100;Server@node2;Req;;Type 21 request received from Scheduler@node2.supernodexp.hpc, sock=20
02/19/2018 16:31:54;0100;Server@node2;Req;;Type 81 request received from Scheduler@node2.supernodexp.hpc, sock=20
02/19/2018 16:31:54;0100;Server@node2;Req;;Type 71 request received from Scheduler@node2.supernodexp.hpc, sock=20
02/19/2018 16:31:54;0100;Server@node2;Req;;Type 58 request received from Scheduler@node2.supernodexp.hpc, sock=20
02/19/2018 16:31:54;0100;Server@node2;Req;;Type 20 request received from Scheduler@node2.supernodexp.hpc, sock=20
02/19/2018 16:31:54;0100;Server@node2;Req;;Type 51 request received from Scheduler@node2.supernodexp.hpc, sock=20
02/19/2018 16:31:54;0100;Server@node2;Req;;Type 11 request received from Scheduler@node2.supernodexp.hpc, sock=20
02/19/2018 16:31:54;0008;Server@node2;Job;3688.node2.supernodexp.hpc;Job Modified at request of Scheduler@node2.supernodexp.hpc
02/19/2018 16:31:56;0100;Server@node2;Req;;Type 1 request received from ctminh@node2.supernodexp.hpc, sock=16
02/19/2018 16:31:56;0100;Server@node2;Req;;Type 3 request received from ctminh@node2.supernodexp.hpc, sock=16
02/19/2018 16:31:56;0100;Server@node2;Req;;Type 5 request received from ctminh@node2.supernodexp.hpc, sock=16
02/19/2018 16:31:56;0100;Server@node2;Job;3689.node2.supernodexp.hpc;enqueuing into workq, state 1 hop 1
02/19/2018 16:31:56;0008;Server@node2;Job;3689.node2.supernodexp.hpc;Job Queued at request of ctminh@node2.supernodexp.hpc, owner = ctminh@node2.supernodexp.hpc, job name = vast1, queue = workq
02/19/2018 16:31:56;0040;Server@node2;Svr;node2.supernodexp.hpc;Scheduler sent command 1
02/19/2018 16:31:56;0040;Server@node2;Svr;node2.supernodexp.hpc;Scheduler sent command 0
02/19/2018 16:31:56;0100;Server@node2;Req;;Type 21 request received from Scheduler@node2.supernodexp.hpc, sock=20
02/19/2018 16:31:56;0100;Server@node2;Req;;Type 81 request received from Scheduler@node2.supernodexp.hpc, sock=20
02/19/2018 16:31:56;0100;Server@node2;Req;;Type 71 request received from Scheduler@node2.supernodexp.hpc, sock=20
02/19/2018 16:31:56;0100;Server@node2;Req;;Type 58 request received from Scheduler@node2.supernodexp.hpc, sock=20
02/19/2018 16:31:56;0100;Server@node2;Req;;Type 20 request received from Scheduler@node2.supernodexp.hpc, sock=20
02/19/2018 16:31:56;0100;Server@node2;Req;;Type 51 request received from Scheduler@node2.supernodexp.hpc, sock=20
02/19/2018 16:31:56;0100;Server@node2;Req;;Type 11 request received from Scheduler@node2.supernodexp.hpc, sock=20
02/19/2018 16:31:56;0008;Server@node2;Job;3689.node2.supernodexp.hpc;Job Modified at request of Scheduler@node2.supernodexp.hpc
02/19/2018 16:31:57;0100;Server@node2;Req;;Type 1 request received from ctminh@node2.supernodexp.hpc, sock=16
02/19/2018 16:31:57;0100;Server@node2;Req;;Type 3 request received from ctminh@node2.supernodexp.hpc, sock=16
02/19/2018 16:31:57;0100;Server@node2;Req;;Type 5 request received from ctminh@node2.supernodexp.hpc, sock=16
02/19/2018 16:31:57;0100;Server@node2;Job;3690.node2.supernodexp.hpc;enqueuing into workq, state 1 hop 1
02/19/2018 16:31:57;0008;Server@node2;Job;3690.node2.supernodexp.hpc;Job Queued at request of ctminh@node2.supernodexp.hpc, owner = ctminh@node2.supernodexp.hpc, job name = lu-decomp, queue = workq
02/19/2018 16:31:57;0040;Server@node2;Svr;node2.supernodexp.hpc;Scheduler sent command 1
02/19/2018 16:31:57;0040;Server@node2;Svr;node2.supernodexp.hpc;Scheduler sent command 0
02/19/2018 16:31:57;0100;Server@node2;Req;;Type 21 request received from Scheduler@node2.supernodexp.hpc, sock=20
02/19/2018 16:31:57;0100;Server@node2;Req;;Type 81 request received from Scheduler@node2.supernodexp.hpc, sock=20
02/19/2018 16:31:57;0100;Server@node2;Req;;Type 71 request received from Scheduler@node2.supernodexp.hpc, sock=20
02/19/2018 16:31:57;0100;Server@node2;Req;;Type 58 request received from Scheduler@node2.supernodexp.hpc, sock=20
02/19/2018 16:31:57;0100;Server@node2;Req;;Type 1 request received from ctminh@node2.supernodexp.hpc, sock=16
02/19/2018 16:31:57;0100;Server@node2;Req;;Type 3 request received from ctminh@node2.supernodexp.hpc, sock=16
02/19/2018 16:31:57;0100;Server@node2;Req;;Type 5 request received from ctminh@node2.supernodexp.hpc, sock=16
02/19/2018 16:31:57;0100;Server@node2;Job;3691.node2.supernodexp.hpc;enqueuing into workq, state 1 hop 1
02/19/2018 16:31:57;0008;Server@node2;Job;3691.node2.supernodexp.hpc;Job Queued at request of ctminh@node2.supernodexp.hpc, owner = ctminh@node2.supernodexp.hpc, job name = vectorization, queue = workq
02/19/2018 16:31:57;0100;Server@node2;Req;;Type 20 request received from Scheduler@node2.supernodexp.hpc, sock=20
02/19/2018 16:31:57;0100;Server@node2;Req;;Type 51 request received from Scheduler@node2.supernodexp.hpc, sock=20
02/19/2018 16:31:58;0100;Server@node2;Req;;Type 11 request received from Scheduler@node2.supernodexp.hpc, sock=20
02/19/2018 16:31:58;0008;Server@node2;Job;3691.node2.supernodexp.hpc;Job Modified at request of Scheduler@node2.supernodexp.hpc
02/19/2018 16:31:58;0100;Server@node2;Req;;Type 11 request received from Scheduler@node2.supernodexp.hpc, sock=20
02/19/2018 16:31:58;0008;Server@node2;Job;3690.node2.supernodexp.hpc;Job Modified at request of Scheduler@node2.supernodexp.hpc
02/19/2018 16:31:58;0040;Server@node2;Svr;node2.supernodexp.hpc;Scheduler sent command 1
02/19/2018 16:31:58;0040;Server@node2;Svr;node2.supernodexp.hpc;Scheduler sent command 0
02/19/2018 16:31:58;0100;Server@node2;Req;;Type 21 request received from Scheduler@node2.supernodexp.hpc, sock=20
02/19/2018 16:31:58;0100;Server@node2;Req;;Type 81 request received from Scheduler@node2.supernodexp.hpc, sock=20
02/19/2018 16:31:58;0100;Server@node2;Req;;Type 71 request received from Scheduler@node2.supernodexp.hpc, sock=20
02/19/2018 16:31:58;0100;Server@node2;Req;;Type 58 request received from Scheduler@node2.supernodexp.hpc, sock=20
02/19/2018 16:31:58;0100;Server@node2;Req;;Type 20 request received from Scheduler@node2.supernodexp.hpc, sock=20
02/19/2018 16:31:58;0100;Server@node2;Req;;Type 51 request received from Scheduler@node2.supernodexp.hpc, sock=20
02/19/2018 16:31:58;0100;Server@node2;Req;;Type 1 request received from ctminh@node2.supernodexp.hpc, sock=16
02/19/2018 16:31:58;0100;Server@node2;Req;;Type 3 request received from ctminh@node2.supernodexp.hpc, sock=16
02/19/2018 16:31:58;0100;Server@node2;Req;;Type 5 request received from ctminh@node2.supernodexp.hpc, sock=16
02/19/2018 16:31:58;0100;Server@node2;Job;3692.node2.supernodexp.hpc;enqueuing into workq, state 1 hop 1
02/19/2018 16:31:58;0008;Server@node2;Job;3692.node2.supernodexp.hpc;Job Queued at request of ctminh@node2.supernodexp.hpc, owner = ctminh@node2.supernodexp.hpc, job name = nbody, queue = workq
02/19/2018 16:31:58;0040;Server@node2;Svr;node2.supernodexp.hpc;Scheduler sent command 1
02/19/2018 16:31:58;0040;Server@node2;Svr;node2.supernodexp.hpc;Scheduler sent command 0
02/19/2018 16:31:58;0100;Server@node2;Req;;Type 21 request received from Scheduler@node2.supernodexp.hpc, sock=20
02/19/2018 16:31:58;0100;Server@node2;Req;;Type 81 request received from Scheduler@node2.supernodexp.hpc, sock=20
02/19/2018 16:31:58;0100;Server@node2;Req;;Type 71 request received from Scheduler@node2.supernodexp.hpc, sock=20
02/19/2018 16:31:58;0100;Server@node2;Req;;Type 58 request received from Scheduler@node2.supernodexp.hpc, sock=20
02/19/2018 16:31:58;0100;Server@node2;Req;;Type 1 request received from ctminh@node2.supernodexp.hpc, sock=16
02/19/2018 16:31:58;0100;Server@node2;Req;;Type 3 request received from ctminh@node2.supernodexp.hpc, sock=16
02/19/2018 16:31:58;0100;Server@node2;Req;;Type 5 request received from ctminh@node2.supernodexp.hpc, sock=16
02/19/2018 16:31:58;0100;Server@node2;Job;3693.node2.supernodexp.hpc;enqueuing into workq, state 1 hop 1
02/19/2018 16:31:58;0008;Server@node2;Job;3693.node2.supernodexp.hpc;Job Queued at request of ctminh@node2.supernodexp.hpc, owner = ctminh@node2.supernodexp.hpc, job name = telemac2, queue = workq
02/19/2018 16:31:58;0100;Server@node2;Req;;Type 1 request received from ctminh@node2.supernodexp.hpc, sock=16
02/19/2018 16:31:58;0100;Server@node2;Req;;Type 3 request received from ctminh@node2.supernodexp.hpc, sock=16
02/19/2018 16:31:58;0100;Server@node2;Req;;Type 5 request received from ctminh@node2.supernodexp.hpc, sock=16
02/19/2018 16:31:58;0100;Server@node2;Job;3694.node2.supernodexp.hpc;enqueuing into workq, state 1 hop 1
02/19/2018 16:31:58;0008;Server@node2;Job;3694.node2.supernodexp.hpc;Job Queued at request of ctminh@node2.supernodexp.hpc, owner = ctminh@node2.supernodexp.hpc, job name = lu-decomp, queue = workq
02/19/2018 16:31:58;0100;Server@node2;Req;;Type 1 request received from ctminh@node2.supernodexp.hpc, sock=16
02/19/2018 16:31:59;0100;Server@node2;Req;;Type 3 request received from ctminh@node2.supernodexp.hpc, sock=16
02/19/2018 16:31:59;0100;Server@node2;Req;;Type 5 request received from ctminh@node2.supernodexp.hpc, sock=16
02/19/2018 16:31:59;0100;Server@node2;Job;3695.node2.supernodexp.hpc;enqueuing into workq, state 1 hop 1
02/19/2018 16:31:59;0008;Server@node2;Job;3695.node2.supernodexp.hpc;Job Queued at request of ctminh@node2.supernodexp.hpc, owner = ctminh@node2.supernodexp.hpc, job name = vast1, queue = workq
02/19/2018 16:31:59;0100;Server@node2;Req;;Type 20 request received from Scheduler@node2.supernodexp.hpc, sock=20
02/19/2018 16:31:59;0100;Server@node2;Req;;Type 51 request received from Scheduler@node2.supernodexp.hpc, sock=20
02/19/2018 16:31:59;0100;Server@node2;Req;;Type 11 request received from Scheduler@node2.supernodexp.hpc, sock=20
02/19/2018 16:31:59;0008;Server@node2;Job;3695.node2.supernodexp.hpc;Job Modified at request of Scheduler@node2.supernodexp.hpc
02/19/2018 16:31:59;0100;Server@node2;Req;;Type 11 request received from Scheduler@node2.supernodexp.hpc, sock=20
02/19/2018 16:31:59;0008;Server@node2;Job;3693.node2.supernodexp.hpc;Job Modified at request of Scheduler@node2.supernodexp.hpc
02/19/2018 16:31:59;0100;Server@node2;Req;;Type 11 request received from Scheduler@node2.supernodexp.hpc, sock=20
02/19/2018 16:31:59;0008;Server@node2;Job;3692.node2.supernodexp.hpc;Job Modified at request of Scheduler@node2.supernodexp.hpc
02/19/2018 16:31:59;0100;Server@node2;Req;;Type 11 request received from Scheduler@node2.supernodexp.hpc, sock=20
02/19/2018 16:31:59;0008;Server@node2;Job;3694.node2.supernodexp.hpc;Job Modified at request of Scheduler@node2.supernodexp.hpc
02/19/2018 16:31:59;0040;Server@node2;Svr;node2.supernodexp.hpc;Scheduler sent command 1
02/19/2018 16:31:59;0040;Server@node2;Svr;node2.supernodexp.hpc;Scheduler sent command 0
02/19/2018 16:31:59;0100;Server@node2;Req;;Type 21 request received from Scheduler@node2.supernodexp.hpc, sock=20
02/19/2018 16:31:59;0100;Server@node2;Req;;Type 81 request received from Scheduler@node2.supernodexp.hpc, sock=20
02/19/2018 16:31:59;0100;Server@node2;Req;;Type 71 request received from Scheduler@node2.supernodexp.hpc, sock=20
02/19/2018 16:31:59;0100;Server@node2;Req;;Type 58 request received from Scheduler@node2.supernodexp.hpc, sock=20
02/19/2018 16:31:59;0100;Server@node2;Req;;Type 20 request received from Scheduler@node2.supernodexp.hpc, sock=20
02/19/2018 16:31:59;0100;Server@node2;Req;;Type 51 request received from Scheduler@node2.supernodexp.hpc, sock=20
02/19/2018 16:32:00;0100;Server@node2;Req;;Type 1 request received from ctminh@node2.supernodexp.hpc, sock=16
02/19/2018 16:32:00;0100;Server@node2;Req;;Type 3 request received from ctminh@node2.supernodexp.hpc, sock=16
02/19/2018 16:32:00;0100;Server@node2;Req;;Type 5 request received from ctminh@node2.supernodexp.hpc, sock=16
02/19/2018 16:32:00;0100;Server@node2;Job;3696.node2.supernodexp.hpc;enqueuing into workq, state 1 hop 1
02/19/2018 16:32:00;0008;Server@node2;Job;3696.node2.supernodexp.hpc;Job Queued at request of ctminh@node2.supernodexp.hpc, owner = ctminh@node2.supernodexp.hpc, job name = matrix-x-vector, queue = workq
02/19/2018 16:32:00;0040;Server@node2;Svr;node2.supernodexp.hpc;Scheduler sent command 1
02/19/2018 16:32:00;0040;Server@node2;Svr;node2.supernodexp.hpc;Scheduler sent command 0
02/19/2018 16:32:00;0100;Server@node2;Req;;Type 21 request received from Scheduler@node2.supernodexp.hpc, sock=20
02/19/2018 16:32:00;0100;Server@node2;Req;;Type 81 request received from Scheduler@node2.supernodexp.hpc, sock=20
02/19/2018 16:32:00;0100;Server@node2;Req;;Type 71 request received from Scheduler@node2.supernodexp.hpc, sock=20
02/19/2018 16:32:00;0100;Server@node2;Req;;Type 58 request received from Scheduler@node2.supernodexp.hpc, sock=20
02/19/2018 16:32:00;0100;Server@node2;Req;;Type 20 request received from Scheduler@node2.supernodexp.hpc, sock=20
02/19/2018 16:32:00;0100;Server@node2;Req;;Type 51 request received from Scheduler@node2.supernodexp.hpc, sock=20
02/19/2018 16:32:00;0100;Server@node2;Req;;Type 11 request received from Scheduler@node2.supernodexp.hpc, sock=20
02/19/2018 16:32:00;0008;Server@node2;Job;3696.node2.supernodexp.hpc;Job Modified at request of Scheduler@node2.supernodexp.hpc
02/19/2018 16:33:02;0100;Server@node2;Req;;Type 0 request received from ctminh@node2.supernodexp.hpc, sock=16
02/19/2018 16:33:02;0100;Server@node2;Req;;Type 49 request received from ctminh@node2.supernodexp.hpc, sock=20
02/19/2018 16:33:02;0100;Server@node2;Req;;Type 21 request received from ctminh@node2.supernodexp.hpc, sock=16
02/19/2018 16:33:02;0100;Server@node2;Req;;Type 1 request received from ctminh@node2.supernodexp.hpc, sock=16
02/19/2018 16:33:02;0100;Server@node2;Req;;Type 3 request received from ctminh@node2.supernodexp.hpc, sock=16
02/19/2018 16:33:02;0100;Server@node2;Req;;Type 5 request received from ctminh@node2.supernodexp.hpc, sock=16
02/19/2018 16:33:02;0100;Server@node2;Job;3697.node2.supernodexp.hpc;enqueuing into workq, state 1 hop 1
02/19/2018 16:33:02;0008;Server@node2;Job;3697.node2.supernodexp.hpc;Job Queued at request of ctminh@node2.supernodexp.hpc, owner = ctminh@node2.supernodexp.hpc, job name = vectorization, queue = workq
02/19/2018 16:33:02;0040;Server@node2;Svr;node2.supernodexp.hpc;Scheduler sent command 1
02/19/2018 16:33:02;0040;Server@node2;Svr;node2.supernodexp.hpc;Scheduler sent command 0
02/19/2018 16:33:02;0100;Server@node2;Req;;Type 21 request received from Scheduler@node2.supernodexp.hpc, sock=20
02/19/2018 16:33:02;0100;Server@node2;Req;;Type 81 request received from Scheduler@node2.supernodexp.hpc, sock=20
02/19/2018 16:33:02;0100;Server@node2;Req;;Type 71 request received from Scheduler@node2.supernodexp.hpc, sock=20
02/19/2018 16:33:02;0100;Server@node2;Req;;Type 58 request received from Scheduler@node2.supernodexp.hpc, sock=20
02/19/2018 16:33:02;0100;Server@node2;Req;;Type 20 request received from Scheduler@node2.supernodexp.hpc, sock=20
02/19/2018 16:33:02;0100;Server@node2;Req;;Type 51 request received from Scheduler@node2.supernodexp.hpc, sock=20
02/19/2018 16:33:02;0100;Server@node2;Req;;Type 11 request received from Scheduler@node2.supernodexp.hpc, sock=20
02/19/2018 16:33:02;0008;Server@node2;Job;3697.node2.supernodexp.hpc;Job Modified at request of Scheduler@node2.supernodexp.hpc
02/19/2018 16:33:05;0100;Server@node2;Req;;Type 1 request received from ctminh@node2.supernodexp.hpc, sock=16
02/19/2018 16:33:05;0100;Server@node2;Req;;Type 3 request received from ctminh@node2.supernodexp.hpc, sock=16
02/19/2018 16:33:05;0100;Server@node2;Req;;Type 5 request received from ctminh@node2.supernodexp.hpc, sock=16
02/19/2018 16:33:05;0100;Server@node2;Job;3698.node2.supernodexp.hpc;enqueuing into workq, state 1 hop 1
02/19/2018 16:33:05;0008;Server@node2;Job;3698.node2.supernodexp.hpc;Job Queued at request of ctminh@node2.supernodexp.hpc, owner = ctminh@node2.supernodexp.hpc, job name = jacobi, queue = workq
02/19/2018 16:33:05;0040;Server@node2;Svr;node2.supernodexp.hpc;Scheduler sent command 1
02/19/2018 16:33:05;0040;Server@node2;Svr;node2.supernodexp.hpc;Scheduler sent command 0
02/19/2018 16:33:05;0100;Server@node2;Req;;Type 21 request received from Scheduler@node2.supernodexp.hpc, sock=20
02/19/2018 16:33:05;0100;Server@node2;Req;;Type 81 request received from Scheduler@node2.supernodexp.hpc, sock=20
02/19/2018 16:33:05;0100;Server@node2;Req;;Type 71 request received from Scheduler@node2.supernodexp.hpc, sock=20
02/19/2018 16:33:05;0100;Server@node2;Req;;Type 58 request received from Scheduler@node2.supernodexp.hpc, sock=20
02/19/2018 16:33:05;0100;Server@node2;Req;;Type 1 request received from ctminh@node2.supernodexp.hpc, sock=16
02/19/2018 16:33:05;0100;Server@node2;Req;;Type 3 request received from ctminh@node2.supernodexp.hpc, sock=16
02/19/2018 16:33:05;0100;Server@node2;Req;;Type 5 request received from ctminh@node2.supernodexp.hpc, sock=16
02/19/2018 16:33:05;0100;Server@node2;Job;3699.node2.supernodexp.hpc;enqueuing into workq, state 1 hop 1
02/19/2018 16:33:05;0008;Server@node2;Job;3699.node2.supernodexp.hpc;Job Queued at request of ctminh@node2.supernodexp.hpc, owner = ctminh@node2.supernodexp.hpc, job name = sweep, queue = workq
02/19/2018 16:33:05;0100;Server@node2;Req;;Type 20 request received from Scheduler@node2.supernodexp.hpc, sock=20
02/19/2018 16:33:05;0100;Server@node2;Req;;Type 51 request received from Scheduler@node2.supernodexp.hpc, sock=20
02/19/2018 16:33:05;0100;Server@node2;Req;;Type 11 request received from Scheduler@node2.supernodexp.hpc, sock=20
02/19/2018 16:33:05;0008;Server@node2;Job;3698.node2.supernodexp.hpc;Job Modified at request of Scheduler@node2.supernodexp.hpc
02/19/2018 16:33:05;0100;Server@node2;Req;;Type 11 request received from Scheduler@node2.supernodexp.hpc, sock=20
02/19/2018 16:33:05;0008;Server@node2;Job;3699.node2.supernodexp.hpc;Job Modified at request of Scheduler@node2.supernodexp.hpc
02/19/2018 16:33:05;0040;Server@node2;Svr;node2.supernodexp.hpc;Scheduler sent command 1
02/19/2018 16:33:05;0040;Server@node2;Svr;node2.supernodexp.hpc;Scheduler sent command 0
02/19/2018 16:33:05;0100;Server@node2;Req;;Type 21 request received from Scheduler@node2.supernodexp.hpc, sock=20
02/19/2018 16:33:05;0100;Server@node2;Req;;Type 81 request received from Scheduler@node2.supernodexp.hpc, sock=20
02/19/2018 16:33:05;0100;Server@node2;Req;;Type 71 request received from Scheduler@node2.supernodexp.hpc, sock=20
02/19/2018 16:33:05;0100;Server@node2;Req;;Type 58 request received from Scheduler@node2.supernodexp.hpc, sock=20
02/19/2018 16:33:05;0100;Server@node2;Req;;Type 20 request received from Scheduler@node2.supernodexp.hpc, sock=20
02/19/2018 16:33:05;0100;Server@node2;Req;;Type 51 request received from Scheduler@node2.supernodexp.hpc, sock=20
02/19/2018 16:33:07;0100;Server@node2;Req;;Type 1 request received from ctminh@node2.supernodexp.hpc, sock=16
02/19/2018 16:33:07;0100;Server@node2;Req;;Type 3 request received from ctminh@node2.supernodexp.hpc, sock=16
02/19/2018 16:33:07;0100;Server@node2;Req;;Type 5 request received from ctminh@node2.supernodexp.hpc, sock=16
02/19/2018 16:33:07;0100;Server@node2;Job;3700.node2.supernodexp.hpc;enqueuing into workq, state 1 hop 1
02/19/2018 16:33:07;0008;Server@node2;Job;3700.node2.supernodexp.hpc;Job Queued at request of ctminh@node2.supernodexp.hpc, owner = ctminh@node2.supernodexp.hpc, job name = vast1, queue = workq
02/19/2018 16:33:07;0040;Server@node2;Svr;node2.supernodexp.hpc;Scheduler sent command 1
02/19/2018 16:33:07;0040;Server@node2;Svr;node2.supernodexp.hpc;Scheduler sent command 0
02/19/2018 16:33:07;0100;Server@node2;Req;;Type 21 request received from Scheduler@node2.supernodexp.hpc, sock=20
02/19/2018 16:33:07;0100;Server@node2;Req;;Type 81 request received from Scheduler@node2.supernodexp.hpc, sock=20
02/19/2018 16:33:07;0100;Server@node2;Req;;Type 71 request received from Scheduler@node2.supernodexp.hpc, sock=20
02/19/2018 16:33:07;0100;Server@node2;Req;;Type 58 request received from Scheduler@node2.supernodexp.hpc, sock=20
02/19/2018 16:33:07;0100;Server@node2;Req;;Type 20 request received from Scheduler@node2.supernodexp.hpc, sock=20
02/19/2018 16:33:07;0100;Server@node2;Req;;Type 51 request received from Scheduler@node2.supernodexp.hpc, sock=20
02/19/2018 16:33:07;0100;Server@node2;Req;;Type 11 request received from Scheduler@node2.supernodexp.hpc, sock=20
02/19/2018 16:33:07;0008;Server@node2;Job;3700.node2.supernodexp.hpc;Job Modified at request of Scheduler@node2.supernodexp.hpc
02/19/2018 16:33:13;0100;Server@node2;Req;;Type 1 request received from ctminh@node2.supernodexp.hpc, sock=16
02/19/2018 16:33:13;0100;Server@node2;Req;;Type 3 request received from ctminh@node2.supernodexp.hpc, sock=16
02/19/2018 16:33:13;0100;Server@node2;Req;;Type 5 request received from ctminh@node2.supernodexp.hpc, sock=16
02/19/2018 16:33:13;0100;Server@node2;Job;3701.node2.supernodexp.hpc;enqueuing into workq, state 1 hop 1
02/19/2018 16:33:13;0008;Server@node2;Job;3701.node2.supernodexp.hpc;Job Queued at request of ctminh@node2.supernodexp.hpc, owner = ctminh@node2.supernodexp.hpc, job name = vast1, queue = workq
02/19/2018 16:33:13;0040;Server@node2;Svr;node2.supernodexp.hpc;Scheduler sent command 1
02/19/2018 16:33:13;0040;Server@node2;Svr;node2.supernodexp.hpc;Scheduler sent command 0
02/19/2018 16:33:13;0100;Server@node2;Req;;Type 21 request received from Scheduler@node2.supernodexp.hpc, sock=20
02/19/2018 16:33:13;0100;Server@node2;Req;;Type 81 request received from Scheduler@node2.supernodexp.hpc, sock=20
02/19/2018 16:33:13;0100;Server@node2;Req;;Type 71 request received from Scheduler@node2.supernodexp.hpc, sock=20
02/19/2018 16:33:13;0100;Server@node2;Req;;Type 58 request received from Scheduler@node2.supernodexp.hpc, sock=20
02/19/2018 16:33:13;0100;Server@node2;Req;;Type 20 request received from Scheduler@node2.supernodexp.hpc, sock=20
02/19/2018 16:33:13;0100;Server@node2;Req;;Type 51 request received from Scheduler@node2.supernodexp.hpc, sock=20
02/19/2018 16:33:13;0100;Server@node2;Req;;Type 11 request received from Scheduler@node2.supernodexp.hpc, sock=20
02/19/2018 16:33:13;0008;Server@node2;Job;3701.node2.supernodexp.hpc;Job Modified at request of Scheduler@node2.supernodexp.hpc
02/19/2018 16:33:16;0100;Server@node2;Req;;Type 1 request received from ctminh@node2.supernodexp.hpc, sock=16
02/19/2018 16:33:16;0100;Server@node2;Req;;Type 3 request received from ctminh@node2.supernodexp.hpc, sock=16
02/19/2018 16:33:16;0100;Server@node2;Req;;Type 5 request received from ctminh@node2.supernodexp.hpc, sock=16
02/19/2018 16:33:16;0100;Server@node2;Job;3702.node2.supernodexp.hpc;enqueuing into workq, state 1 hop 1
02/19/2018 16:33:16;0008;Server@node2;Job;3702.node2.supernodexp.hpc;Job Queued at request of ctminh@node2.supernodexp.hpc, owner = ctminh@node2.supernodexp.hpc, job name = thread-affinity, queue = workq
02/19/2018 16:33:16;0040;Server@node2;Svr;node2.supernodexp.hpc;Scheduler sent command 1
02/19/2018 16:33:16;0040;Server@node2;Svr;node2.supernodexp.hpc;Scheduler sent command 0
02/19/2018 16:33:16;0100;Server@node2;Req;;Type 21 request received from Scheduler@node2.supernodexp.hpc, sock=20
02/19/2018 16:33:16;0100;Server@node2;Req;;Type 81 request received from Scheduler@node2.supernodexp.hpc, sock=20
02/19/2018 16:33:16;0100;Server@node2;Req;;Type 71 request received from Scheduler@node2.supernodexp.hpc, sock=20
02/19/2018 16:33:16;0100;Server@node2;Req;;Type 58 request received from Scheduler@node2.supernodexp.hpc, sock=20
02/19/2018 16:33:16;0100;Server@node2;Req;;Type 20 request received from Scheduler@node2.supernodexp.hpc, sock=20
02/19/2018 16:33:16;0100;Server@node2;Req;;Type 51 request received from Scheduler@node2.supernodexp.hpc, sock=20
02/19/2018 16:33:16;0100;Server@node2;Req;;Type 11 request received from Scheduler@node2.supernodexp.hpc, sock=20
02/19/2018 16:33:16;0008;Server@node2;Job;3702.node2.supernodexp.hpc;Job Modified at request of Scheduler@node2.supernodexp.hpc
02/19/2018 16:33:22;0100;Server@node2;Req;;Type 1 request received from ctminh@node2.supernodexp.hpc, sock=16
02/19/2018 16:33:22;0100;Server@node2;Req;;Type 3 request received from ctminh@node2.supernodexp.hpc, sock=16
02/19/2018 16:33:22;0100;Server@node2;Req;;Type 5 request received from ctminh@node2.supernodexp.hpc, sock=16
02/19/2018 16:33:22;0100;Server@node2;Job;3703.node2.supernodexp.hpc;enqueuing into workq, state 1 hop 1
02/19/2018 16:33:22;0008;Server@node2;Job;3703.node2.supernodexp.hpc;Job Queued at request of ctminh@node2.supernodexp.hpc, owner = ctminh@node2.supernodexp.hpc, job name = telemac2, queue = workq
02/19/2018 16:33:22;0040;Server@node2;Svr;node2.supernodexp.hpc;Scheduler sent command 1
02/19/2018 16:33:22;0040;Server@node2;Svr;node2.supernodexp.hpc;Scheduler sent command 0
02/19/2018 16:33:22;0100;Server@node2;Req;;Type 21 request received from Scheduler@node2.supernodexp.hpc, sock=20
02/19/2018 16:33:22;0100;Server@node2;Req;;Type 81 request received from Scheduler@node2.supernodexp.hpc, sock=20
02/19/2018 16:33:22;0100;Server@node2;Req;;Type 71 request received from Scheduler@node2.supernodexp.hpc, sock=20
02/19/2018 16:33:22;0100;Server@node2;Req;;Type 58 request received from Scheduler@node2.supernodexp.hpc, sock=20
02/19/2018 16:33:22;0100;Server@node2;Req;;Type 20 request received from Scheduler@node2.supernodexp.hpc, sock=20
02/19/2018 16:33:22;0100;Server@node2;Req;;Type 51 request received from Scheduler@node2.supernodexp.hpc, sock=20
02/19/2018 16:33:22;0100;Server@node2;Req;;Type 11 request received from Scheduler@node2.supernodexp.hpc, sock=20
02/19/2018 16:33:22;0008;Server@node2;Job;3703.node2.supernodexp.hpc;Job Modified at request of Scheduler@node2.supernodexp.hpc
02/19/2018 16:33:34;0100;Server@node2;Req;;Type 1 request received from ctminh@node2.supernodexp.hpc, sock=16
02/19/2018 16:33:34;0100;Server@node2;Req;;Type 3 request received from ctminh@node2.supernodexp.hpc, sock=16
02/19/2018 16:33:34;0100;Server@node2;Req;;Type 5 request received from ctminh@node2.supernodexp.hpc, sock=16
02/19/2018 16:33:34;0100;Server@node2;Job;3704.node2.supernodexp.hpc;enqueuing into workq, state 1 hop 1
02/19/2018 16:33:34;0008;Server@node2;Job;3704.node2.supernodexp.hpc;Job Queued at request of ctminh@node2.supernodexp.hpc, owner = ctminh@node2.supernodexp.hpc, job name = vast1, queue = workq
02/19/2018 16:33:34;0040;Server@node2;Svr;node2.supernodexp.hpc;Scheduler sent command 1
02/19/2018 16:33:34;0040;Server@node2;Svr;node2.supernodexp.hpc;Scheduler sent command 0
02/19/2018 16:33:34;0100;Server@node2;Req;;Type 21 request received from Scheduler@node2.supernodexp.hpc, sock=20
02/19/2018 16:33:34;0100;Server@node2;Req;;Type 81 request received from Scheduler@node2.supernodexp.hpc, sock=20
02/19/2018 16:33:34;0100;Server@node2;Req;;Type 71 request received from Scheduler@node2.supernodexp.hpc, sock=20
02/19/2018 16:33:34;0100;Server@node2;Req;;Type 58 request received from Scheduler@node2.supernodexp.hpc, sock=20
02/19/2018 16:33:34;0100;Server@node2;Req;;Type 20 request received from Scheduler@node2.supernodexp.hpc, sock=20
02/19/2018 16:33:34;0100;Server@node2;Req;;Type 51 request received from Scheduler@node2.supernodexp.hpc, sock=20
02/19/2018 16:33:34;0100;Server@node2;Req;;Type 11 request received from Scheduler@node2.supernodexp.hpc, sock=20
02/19/2018 16:33:34;0008;Server@node2;Job;3704.node2.supernodexp.hpc;Job Modified at request of Scheduler@node2.supernodexp.hpc
02/19/2018 16:33:35;0100;Server@node2;Req;;Type 1 request received from ctminh@node2.supernodexp.hpc, sock=16
02/19/2018 16:33:35;0100;Server@node2;Req;;Type 3 request received from ctminh@node2.supernodexp.hpc, sock=16
02/19/2018 16:33:35;0100;Server@node2;Req;;Type 5 request received from ctminh@node2.supernodexp.hpc, sock=16
02/19/2018 16:33:35;0100;Server@node2;Job;3705.node2.supernodexp.hpc;enqueuing into workq, state 1 hop 1
02/19/2018 16:33:35;0008;Server@node2;Job;3705.node2.supernodexp.hpc;Job Queued at request of ctminh@node2.supernodexp.hpc, owner = ctminh@node2.supernodexp.hpc, job name = nbody, queue = workq
02/19/2018 16:33:35;0040;Server@node2;Svr;node2.supernodexp.hpc;Scheduler sent command 1
02/19/2018 16:33:35;0040;Server@node2;Svr;node2.supernodexp.hpc;Scheduler sent command 0
02/19/2018 16:33:35;0100;Server@node2;Req;;Type 21 request received from Scheduler@node2.supernodexp.hpc, sock=20
02/19/2018 16:33:35;0100;Server@node2;Req;;Type 81 request received from Scheduler@node2.supernodexp.hpc, sock=20
02/19/2018 16:33:35;0100;Server@node2;Req;;Type 71 request received from Scheduler@node2.supernodexp.hpc, sock=20
02/19/2018 16:33:35;0100;Server@node2;Req;;Type 58 request received from Scheduler@node2.supernodexp.hpc, sock=20
02/19/2018 16:33:35;0100;Server@node2;Req;;Type 20 request received from Scheduler@node2.supernodexp.hpc, sock=20
02/19/2018 16:33:35;0100;Server@node2;Req;;Type 51 request received from Scheduler@node2.supernodexp.hpc, sock=20
02/19/2018 16:33:35;0100;Server@node2;Req;;Type 11 request received from Scheduler@node2.supernodexp.hpc, sock=20
02/19/2018 16:33:35;0008;Server@node2;Job;3705.node2.supernodexp.hpc;Job Modified at request of Scheduler@node2.supernodexp.hpc
02/19/2018 16:33:36;0100;Server@node2;Req;;Type 1 request received from ctminh@node2.supernodexp.hpc, sock=16
02/19/2018 16:33:36;0100;Server@node2;Req;;Type 3 request received from ctminh@node2.supernodexp.hpc, sock=16
02/19/2018 16:33:36;0100;Server@node2;Req;;Type 5 request received from ctminh@node2.supernodexp.hpc, sock=16
02/19/2018 16:33:36;0100;Server@node2;Job;3706.node2.supernodexp.hpc;enqueuing into workq, state 1 hop 1
02/19/2018 16:33:36;0008;Server@node2;Job;3706.node2.supernodexp.hpc;Job Queued at request of ctminh@node2.supernodexp.hpc, owner = ctminh@node2.supernodexp.hpc, job name = telemac3, queue = workq
02/19/2018 16:33:36;0040;Server@node2;Svr;node2.supernodexp.hpc;Scheduler sent command 1
02/19/2018 16:33:36;0040;Server@node2;Svr;node2.supernodexp.hpc;Scheduler sent command 0
02/19/2018 16:33:36;0100;Server@node2;Req;;Type 21 request received from Scheduler@node2.supernodexp.hpc, sock=20
02/19/2018 16:33:36;0100;Server@node2;Req;;Type 81 request received from Scheduler@node2.supernodexp.hpc, sock=20
02/19/2018 16:33:36;0100;Server@node2;Req;;Type 71 request received from Scheduler@node2.supernodexp.hpc, sock=20
02/19/2018 16:33:36;0100;Server@node2;Req;;Type 58 request received from Scheduler@node2.supernodexp.hpc, sock=20
02/19/2018 16:33:36;0100;Server@node2;Req;;Type 1 request received from ctminh@node2.supernodexp.hpc, sock=16
02/19/2018 16:33:36;0100;Server@node2;Req;;Type 3 request received from ctminh@node2.supernodexp.hpc, sock=16
02/19/2018 16:33:36;0100;Server@node2;Req;;Type 5 request received from ctminh@node2.supernodexp.hpc, sock=16
02/19/2018 16:33:36;0100;Server@node2;Job;3707.node2.supernodexp.hpc;enqueuing into workq, state 1 hop 1
02/19/2018 16:33:36;0008;Server@node2;Job;3707.node2.supernodexp.hpc;Job Queued at request of ctminh@node2.supernodexp.hpc, owner = ctminh@node2.supernodexp.hpc, job name = sweep, queue = workq
02/19/2018 16:33:36;0100;Server@node2;Req;;Type 1 request received from ctminh@node2.supernodexp.hpc, sock=16
02/19/2018 16:33:36;0100;Server@node2;Req;;Type 3 request received from ctminh@node2.supernodexp.hpc, sock=16
02/19/2018 16:33:36;0100;Server@node2;Req;;Type 5 request received from ctminh@node2.supernodexp.hpc, sock=16
02/19/2018 16:33:36;0100;Server@node2;Job;3708.node2.supernodexp.hpc;enqueuing into workq, state 1 hop 1
02/19/2018 16:33:36;0008;Server@node2;Job;3708.node2.supernodexp.hpc;Job Queued at request of ctminh@node2.supernodexp.hpc, owner = ctminh@node2.supernodexp.hpc, job name = sweep, queue = workq
02/19/2018 16:33:36;0100;Server@node2;Req;;Type 20 request received from Scheduler@node2.supernodexp.hpc, sock=20
02/19/2018 16:33:36;0100;Server@node2;Req;;Type 51 request received from Scheduler@node2.supernodexp.hpc, sock=20
02/19/2018 16:33:36;0100;Server@node2;Req;;Type 11 request received from Scheduler@node2.supernodexp.hpc, sock=20
02/19/2018 16:33:36;0008;Server@node2;Job;3706.node2.supernodexp.hpc;Job Modified at request of Scheduler@node2.supernodexp.hpc
02/19/2018 16:33:36;0100;Server@node2;Req;;Type 11 request received from Scheduler@node2.supernodexp.hpc, sock=20
02/19/2018 16:33:36;0008;Server@node2;Job;3707.node2.supernodexp.hpc;Job Modified at request of Scheduler@node2.supernodexp.hpc
02/19/2018 16:33:36;0100;Server@node2;Req;;Type 11 request received from Scheduler@node2.supernodexp.hpc, sock=20
02/19/2018 16:33:36;0008;Server@node2;Job;3708.node2.supernodexp.hpc;Job Modified at request of Scheduler@node2.supernodexp.hpc
02/19/2018 16:33:36;0040;Server@node2;Svr;node2.supernodexp.hpc;Scheduler sent command 1
02/19/2018 16:33:36;0040;Server@node2;Svr;node2.supernodexp.hpc;Scheduler sent command 0
02/19/2018 16:33:36;0100;Server@node2;Req;;Type 21 request received from Scheduler@node2.supernodexp.hpc, sock=20
02/19/2018 16:33:36;0100;Server@node2;Req;;Type 81 request received from Scheduler@node2.supernodexp.hpc, sock=20
02/19/2018 16:33:36;0100;Server@node2;Req;;Type 71 request received from Scheduler@node2.supernodexp.hpc, sock=20
02/19/2018 16:33:36;0100;Server@node2;Req;;Type 58 request received from Scheduler@node2.supernodexp.hpc, sock=20
02/19/2018 16:33:36;0100;Server@node2;Req;;Type 20 request received from Scheduler@node2.supernodexp.hpc, sock=20
02/19/2018 16:33:36;0100;Server@node2;Req;;Type 51 request received from Scheduler@node2.supernodexp.hpc, sock=20
02/19/2018 16:33:37;0100;Server@node2;Req;;Type 1 request received from ctminh@node2.supernodexp.hpc, sock=16
02/19/2018 16:33:37;0100;Server@node2;Req;;Type 3 request received from ctminh@node2.supernodexp.hpc, sock=16
02/19/2018 16:33:37;0100;Server@node2;Req;;Type 5 request received from ctminh@node2.supernodexp.hpc, sock=16
02/19/2018 16:33:37;0100;Server@node2;Job;3709.node2.supernodexp.hpc;enqueuing into workq, state 1 hop 1
02/19/2018 16:33:37;0008;Server@node2;Job;3709.node2.supernodexp.hpc;Job Queued at request of ctminh@node2.supernodexp.hpc, owner = ctminh@node2.supernodexp.hpc, job name = vectorization, queue = workq
02/19/2018 16:33:37;0040;Server@node2;Svr;node2.supernodexp.hpc;Scheduler sent command 1
02/19/2018 16:33:37;0040;Server@node2;Svr;node2.supernodexp.hpc;Scheduler sent command 0
02/19/2018 16:33:37;0100;Server@node2;Req;;Type 21 request received from Scheduler@node2.supernodexp.hpc, sock=20
02/19/2018 16:33:37;0100;Server@node2;Req;;Type 81 request received from Scheduler@node2.supernodexp.hpc, sock=20
02/19/2018 16:33:37;0100;Server@node2;Req;;Type 71 request received from Scheduler@node2.supernodexp.hpc, sock=20
02/19/2018 16:33:37;0100;Server@node2;Req;;Type 58 request received from Scheduler@node2.supernodexp.hpc, sock=20
02/19/2018 16:33:37;0100;Server@node2;Req;;Type 20 request received from Scheduler@node2.supernodexp.hpc, sock=20
02/19/2018 16:33:37;0100;Server@node2;Req;;Type 51 request received from Scheduler@node2.supernodexp.hpc, sock=20
02/19/2018 16:33:37;0100;Server@node2;Req;;Type 11 request received from Scheduler@node2.supernodexp.hpc, sock=20
02/19/2018 16:33:37;0008;Server@node2;Job;3709.node2.supernodexp.hpc;Job Modified at request of Scheduler@node2.supernodexp.hpc
02/19/2018 16:33:39;0100;Server@node2;Req;;Type 1 request received from ctminh@node2.supernodexp.hpc, sock=16
02/19/2018 16:33:39;0100;Server@node2;Req;;Type 3 request received from ctminh@node2.supernodexp.hpc, sock=16
02/19/2018 16:33:39;0100;Server@node2;Req;;Type 5 request received from ctminh@node2.supernodexp.hpc, sock=16
02/19/2018 16:33:39;0100;Server@node2;Job;3710.node2.supernodexp.hpc;enqueuing into workq, state 1 hop 1
02/19/2018 16:33:39;0008;Server@node2;Job;3710.node2.supernodexp.hpc;Job Queued at request of ctminh@node2.supernodexp.hpc, owner = ctminh@node2.supernodexp.hpc, job name = histogram, queue = workq
02/19/2018 16:33:39;0040;Server@node2;Svr;node2.supernodexp.hpc;Scheduler sent command 1
02/19/2018 16:33:39;0040;Server@node2;Svr;node2.supernodexp.hpc;Scheduler sent command 0
02/19/2018 16:33:39;0100;Server@node2;Req;;Type 21 request received from Scheduler@node2.supernodexp.hpc, sock=20
02/19/2018 16:33:39;0100;Server@node2;Req;;Type 81 request received from Scheduler@node2.supernodexp.hpc, sock=20
02/19/2018 16:33:39;0100;Server@node2;Req;;Type 71 request received from Scheduler@node2.supernodexp.hpc, sock=20
02/19/2018 16:33:39;0100;Server@node2;Req;;Type 58 request received from Scheduler@node2.supernodexp.hpc, sock=20
02/19/2018 16:33:39;0100;Server@node2;Req;;Type 20 request received from Scheduler@node2.supernodexp.hpc, sock=20
02/19/2018 16:33:39;0100;Server@node2;Req;;Type 51 request received from Scheduler@node2.supernodexp.hpc, sock=20
02/19/2018 16:33:39;0100;Server@node2;Req;;Type 11 request received from Scheduler@node2.supernodexp.hpc, sock=20
02/19/2018 16:33:39;0008;Server@node2;Job;3710.node2.supernodexp.hpc;Job Modified at request of Scheduler@node2.supernodexp.hpc
02/19/2018 16:34:35;0100;Server@node2;Req;;Type 1 request received from ctminh@node2.supernodexp.hpc, sock=16
02/19/2018 16:34:35;0100;Server@node2;Req;;Type 3 request received from ctminh@node2.supernodexp.hpc, sock=16
02/19/2018 16:34:35;0100;Server@node2;Req;;Type 5 request received from ctminh@node2.supernodexp.hpc, sock=16
02/19/2018 16:34:35;0100;Server@node2;Job;3711.node2.supernodexp.hpc;enqueuing into workq, state 1 hop 1
02/19/2018 16:34:35;0008;Server@node2;Job;3711.node2.supernodexp.hpc;Job Queued at request of ctminh@node2.supernodexp.hpc, owner = ctminh@node2.supernodexp.hpc, job name = qe_mic_test, queue = workq
02/19/2018 16:34:35;0040;Server@node2;Svr;node2.supernodexp.hpc;Scheduler sent command 1
02/19/2018 16:34:35;0040;Server@node2;Svr;node2.supernodexp.hpc;Scheduler sent command 0
02/19/2018 16:34:35;0100;Server@node2;Req;;Type 21 request received from Scheduler@node2.supernodexp.hpc, sock=20
02/19/2018 16:34:35;0100;Server@node2;Req;;Type 81 request received from Scheduler@node2.supernodexp.hpc, sock=20
02/19/2018 16:34:35;0100;Server@node2;Req;;Type 71 request received from Scheduler@node2.supernodexp.hpc, sock=20
02/19/2018 16:34:35;0100;Server@node2;Req;;Type 58 request received from Scheduler@node2.supernodexp.hpc, sock=20
02/19/2018 16:34:35;0100;Server@node2;Req;;Type 20 request received from Scheduler@node2.supernodexp.hpc, sock=20
02/19/2018 16:34:35;0100;Server@node2;Req;;Type 51 request received from Scheduler@node2.supernodexp.hpc, sock=20
02/19/2018 16:34:35;0100;Server@node2;Req;;Type 11 request received from Scheduler@node2.supernodexp.hpc, sock=20
02/19/2018 16:34:35;0008;Server@node2;Job;3711.node2.supernodexp.hpc;Job Modified at request of Scheduler@node2.supernodexp.hpc
02/19/2018 16:34:48;0100;Server@node2;Req;;Type 1 request received from ctminh@node2.supernodexp.hpc, sock=16
02/19/2018 16:34:48;0100;Server@node2;Req;;Type 3 request received from ctminh@node2.supernodexp.hpc, sock=16
02/19/2018 16:34:48;0100;Server@node2;Req;;Type 5 request received from ctminh@node2.supernodexp.hpc, sock=16
02/19/2018 16:34:48;0100;Server@node2;Job;3712.node2.supernodexp.hpc;enqueuing into workq, state 1 hop 1
02/19/2018 16:34:48;0008;Server@node2;Job;3712.node2.supernodexp.hpc;Job Queued at request of ctminh@node2.supernodexp.hpc, owner = ctminh@node2.supernodexp.hpc, job name = vectorization, queue = workq
02/19/2018 16:34:48;0040;Server@node2;Svr;node2.supernodexp.hpc;Scheduler sent command 1
02/19/2018 16:34:48;0040;Server@node2;Svr;node2.supernodexp.hpc;Scheduler sent command 0
02/19/2018 16:34:48;0100;Server@node2;Req;;Type 21 request received from Scheduler@node2.supernodexp.hpc, sock=20
02/19/2018 16:34:48;0100;Server@node2;Req;;Type 81 request received from Scheduler@node2.supernodexp.hpc, sock=20
02/19/2018 16:34:48;0100;Server@node2;Req;;Type 71 request received from Scheduler@node2.supernodexp.hpc, sock=20
02/19/2018 16:34:48;0100;Server@node2;Req;;Type 58 request received from Scheduler@node2.supernodexp.hpc, sock=20
02/19/2018 16:34:48;0100;Server@node2;Req;;Type 20 request received from Scheduler@node2.supernodexp.hpc, sock=20
02/19/2018 16:34:48;0100;Server@node2;Req;;Type 51 request received from Scheduler@node2.supernodexp.hpc, sock=20
02/19/2018 16:34:48;0100;Server@node2;Req;;Type 11 request received from Scheduler@node2.supernodexp.hpc, sock=20
02/19/2018 16:34:48;0008;Server@node2;Job;3712.node2.supernodexp.hpc;Job Modified at request of Scheduler@node2.supernodexp.hpc
02/19/2018 16:34:51;0100;Server@node2;Req;;Type 1 request received from ctminh@node2.supernodexp.hpc, sock=16
02/19/2018 16:34:51;0100;Server@node2;Req;;Type 3 request received from ctminh@node2.supernodexp.hpc, sock=16
02/19/2018 16:34:51;0100;Server@node2;Req;;Type 5 request received from ctminh@node2.supernodexp.hpc, sock=16
02/19/2018 16:34:51;0100;Server@node2;Job;3713.node2.supernodexp.hpc;enqueuing into workq, state 1 hop 1
02/19/2018 16:34:51;0008;Server@node2;Job;3713.node2.supernodexp.hpc;Job Queued at request of ctminh@node2.supernodexp.hpc, owner = ctminh@node2.supernodexp.hpc, job name = telemac1, queue = workq
02/19/2018 16:34:51;0040;Server@node2;Svr;node2.supernodexp.hpc;Scheduler sent command 1
02/19/2018 16:34:51;0040;Server@node2;Svr;node2.supernodexp.hpc;Scheduler sent command 0
02/19/2018 16:34:51;0100;Server@node2;Req;;Type 21 request received from Scheduler@node2.supernodexp.hpc, sock=20
02/19/2018 16:34:51;0100;Server@node2;Req;;Type 81 request received from Scheduler@node2.supernodexp.hpc, sock=20
02/19/2018 16:34:51;0100;Server@node2;Req;;Type 71 request received from Scheduler@node2.supernodexp.hpc, sock=20
02/19/2018 16:34:51;0100;Server@node2;Req;;Type 58 request received from Scheduler@node2.supernodexp.hpc, sock=20
02/19/2018 16:34:51;0100;Server@node2;Req;;Type 20 request received from Scheduler@node2.supernodexp.hpc, sock=20
02/19/2018 16:34:51;0100;Server@node2;Req;;Type 51 request received from Scheduler@node2.supernodexp.hpc, sock=20
02/19/2018 16:34:51;0100;Server@node2;Req;;Type 11 request received from Scheduler@node2.supernodexp.hpc, sock=20
02/19/2018 16:34:51;0008;Server@node2;Job;3713.node2.supernodexp.hpc;Job Modified at request of Scheduler@node2.supernodexp.hpc
02/19/2018 16:34:58;0100;Server@node2;Req;;Type 1 request received from ctminh@node2.supernodexp.hpc, sock=16
02/19/2018 16:34:58;0100;Server@node2;Req;;Type 3 request received from ctminh@node2.supernodexp.hpc, sock=16
02/19/2018 16:34:58;0100;Server@node2;Req;;Type 5 request received from ctminh@node2.supernodexp.hpc, sock=16
02/19/2018 16:34:58;0100;Server@node2;Job;3714.node2.supernodexp.hpc;enqueuing into workq, state 1 hop 1
02/19/2018 16:34:58;0008;Server@node2;Job;3714.node2.supernodexp.hpc;Job Queued at request of ctminh@node2.supernodexp.hpc, owner = ctminh@node2.supernodexp.hpc, job name = jacobi, queue = workq
02/19/2018 16:34:58;0040;Server@node2;Svr;node2.supernodexp.hpc;Scheduler sent command 1
02/19/2018 16:34:58;0040;Server@node2;Svr;node2.supernodexp.hpc;Scheduler sent command 0
02/19/2018 16:34:58;0100;Server@node2;Req;;Type 21 request received from Scheduler@node2.supernodexp.hpc, sock=20
02/19/2018 16:34:58;0100;Server@node2;Req;;Type 81 request received from Scheduler@node2.supernodexp.hpc, sock=20
02/19/2018 16:34:58;0100;Server@node2;Req;;Type 71 request received from Scheduler@node2.supernodexp.hpc, sock=20
02/19/2018 16:34:58;0100;Server@node2;Req;;Type 58 request received from Scheduler@node2.supernodexp.hpc, sock=20
02/19/2018 16:34:58;0100;Server@node2;Req;;Type 20 request received from Scheduler@node2.supernodexp.hpc, sock=20
02/19/2018 16:34:58;0100;Server@node2;Req;;Type 51 request received from Scheduler@node2.supernodexp.hpc, sock=20
02/19/2018 16:34:59;0100;Server@node2;Req;;Type 11 request received from Scheduler@node2.supernodexp.hpc, sock=20
02/19/2018 16:34:59;0008;Server@node2;Job;3714.node2.supernodexp.hpc;Job Modified at request of Scheduler@node2.supernodexp.hpc
02/19/2018 16:36:10;0100;Server@node2;Req;;Type 0 request received from ctminh@node2.supernodexp.hpc, sock=16
02/19/2018 16:36:10;0100;Server@node2;Req;;Type 49 request received from ctminh@node2.supernodexp.hpc, sock=20
02/19/2018 16:36:10;0100;Server@node2;Req;;Type 21 request received from ctminh@node2.supernodexp.hpc, sock=16
02/19/2018 16:36:10;0100;Server@node2;Req;;Type 1 request received from ctminh@node2.supernodexp.hpc, sock=16
02/19/2018 16:36:10;0100;Server@node2;Req;;Type 3 request received from ctminh@node2.supernodexp.hpc, sock=16
02/19/2018 16:36:10;0100;Server@node2;Req;;Type 5 request received from ctminh@node2.supernodexp.hpc, sock=16
02/19/2018 16:36:10;0100;Server@node2;Job;3715.node2.supernodexp.hpc;enqueuing into workq, state 1 hop 1
02/19/2018 16:36:10;0008;Server@node2;Job;3715.node2.supernodexp.hpc;Job Queued at request of ctminh@node2.supernodexp.hpc, owner = ctminh@node2.supernodexp.hpc, job name = telemac1, queue = workq
02/19/2018 16:36:10;0040;Server@node2;Svr;node2.supernodexp.hpc;Scheduler sent command 1
02/19/2018 16:36:10;0040;Server@node2;Svr;node2.supernodexp.hpc;Scheduler sent command 0
02/19/2018 16:36:10;0100;Server@node2;Req;;Type 21 request received from Scheduler@node2.supernodexp.hpc, sock=20
02/19/2018 16:36:10;0100;Server@node2;Req;;Type 81 request received from Scheduler@node2.supernodexp.hpc, sock=20
02/19/2018 16:36:10;0100;Server@node2;Req;;Type 71 request received from Scheduler@node2.supernodexp.hpc, sock=20
02/19/2018 16:36:10;0100;Server@node2;Req;;Type 58 request received from Scheduler@node2.supernodexp.hpc, sock=20
02/19/2018 16:36:10;0100;Server@node2;Req;;Type 20 request received from Scheduler@node2.supernodexp.hpc, sock=20
02/19/2018 16:36:10;0100;Server@node2;Req;;Type 51 request received from Scheduler@node2.supernodexp.hpc, sock=20
02/19/2018 16:36:10;0100;Server@node2;Req;;Type 11 request received from Scheduler@node2.supernodexp.hpc, sock=20
02/19/2018 16:36:10;0008;Server@node2;Job;3715.node2.supernodexp.hpc;Job Modified at request of Scheduler@node2.supernodexp.hpc
02/19/2018 16:36:11;0100;Server@node2;Req;;Type 1 request received from ctminh@node2.supernodexp.hpc, sock=16
02/19/2018 16:36:11;0100;Server@node2;Req;;Type 3 request received from ctminh@node2.supernodexp.hpc, sock=16
02/19/2018 16:36:11;0100;Server@node2;Req;;Type 5 request received from ctminh@node2.supernodexp.hpc, sock=16
02/19/2018 16:36:11;0100;Server@node2;Job;3716.node2.supernodexp.hpc;enqueuing into workq, state 1 hop 1
02/19/2018 16:36:11;0008;Server@node2;Job;3716.node2.supernodexp.hpc;Job Queued at request of ctminh@node2.supernodexp.hpc, owner = ctminh@node2.supernodexp.hpc, job name = telemac2, queue = workq
02/19/2018 16:36:11;0040;Server@node2;Svr;node2.supernodexp.hpc;Scheduler sent command 1
02/19/2018 16:36:11;0040;Server@node2;Svr;node2.supernodexp.hpc;Scheduler sent command 0
02/19/2018 16:36:11;0100;Server@node2;Req;;Type 21 request received from Scheduler@node2.supernodexp.hpc, sock=20
02/19/2018 16:36:11;0100;Server@node2;Req;;Type 81 request received from Scheduler@node2.supernodexp.hpc, sock=20
02/19/2018 16:36:11;0100;Server@node2;Req;;Type 71 request received from Scheduler@node2.supernodexp.hpc, sock=20
02/19/2018 16:36:11;0100;Server@node2;Req;;Type 58 request received from Scheduler@node2.supernodexp.hpc, sock=20
02/19/2018 16:36:11;0100;Server@node2;Req;;Type 20 request received from Scheduler@node2.supernodexp.hpc, sock=20
02/19/2018 16:36:11;0100;Server@node2;Req;;Type 51 request received from Scheduler@node2.supernodexp.hpc, sock=20
02/19/2018 16:36:11;0100;Server@node2;Req;;Type 11 request received from Scheduler@node2.supernodexp.hpc, sock=20
02/19/2018 16:36:11;0008;Server@node2;Job;3716.node2.supernodexp.hpc;Job Modified at request of Scheduler@node2.supernodexp.hpc
02/19/2018 16:36:14;0100;Server@node2;Req;;Type 1 request received from ctminh@node2.supernodexp.hpc, sock=16
02/19/2018 16:36:14;0100;Server@node2;Req;;Type 3 request received from ctminh@node2.supernodexp.hpc, sock=16
02/19/2018 16:36:14;0100;Server@node2;Req;;Type 5 request received from ctminh@node2.supernodexp.hpc, sock=16
02/19/2018 16:36:14;0100;Server@node2;Job;3717.node2.supernodexp.hpc;enqueuing into workq, state 1 hop 1
02/19/2018 16:36:14;0008;Server@node2;Job;3717.node2.supernodexp.hpc;Job Queued at request of ctminh@node2.supernodexp.hpc, owner = ctminh@node2.supernodexp.hpc, job name = thread-affinity, queue = workq
02/19/2018 16:36:14;0040;Server@node2;Svr;node2.supernodexp.hpc;Scheduler sent command 1
02/19/2018 16:36:14;0040;Server@node2;Svr;node2.supernodexp.hpc;Scheduler sent command 0
02/19/2018 16:36:14;0100;Server@node2;Req;;Type 21 request received from Scheduler@node2.supernodexp.hpc, sock=20
02/19/2018 16:36:14;0100;Server@node2;Req;;Type 81 request received from Scheduler@node2.supernodexp.hpc, sock=20
02/19/2018 16:36:14;0100;Server@node2;Req;;Type 71 request received from Scheduler@node2.supernodexp.hpc, sock=20
02/19/2018 16:36:14;0100;Server@node2;Req;;Type 58 request received from Scheduler@node2.supernodexp.hpc, sock=20
02/19/2018 16:36:14;0100;Server@node2;Req;;Type 20 request received from Scheduler@node2.supernodexp.hpc, sock=20
02/19/2018 16:36:14;0100;Server@node2;Req;;Type 51 request received from Scheduler@node2.supernodexp.hpc, sock=20
02/19/2018 16:36:14;0100;Server@node2;Req;;Type 11 request received from Scheduler@node2.supernodexp.hpc, sock=20
02/19/2018 16:36:14;0008;Server@node2;Job;3717.node2.supernodexp.hpc;Job Modified at request of Scheduler@node2.supernodexp.hpc
02/19/2018 16:41:14;0100;Server@node2;Req;;Type 0 request received from ctminh@node2.supernodexp.hpc, sock=16
02/19/2018 16:41:14;0100;Server@node2;Req;;Type 49 request received from ctminh@node2.supernodexp.hpc, sock=20
02/19/2018 16:41:14;0100;Server@node2;Req;;Type 21 request received from ctminh@node2.supernodexp.hpc, sock=16
02/19/2018 16:41:14;0100;Server@node2;Req;;Type 1 request received from ctminh@node2.supernodexp.hpc, sock=16
02/19/2018 16:41:14;0100;Server@node2;Req;;Type 3 request received from ctminh@node2.supernodexp.hpc, sock=16
02/19/2018 16:41:14;0100;Server@node2;Req;;Type 5 request received from ctminh@node2.supernodexp.hpc, sock=16
02/19/2018 16:41:14;0100;Server@node2;Job;3718.node2.supernodexp.hpc;enqueuing into workq, state 1 hop 1
02/19/2018 16:41:14;0008;Server@node2;Job;3718.node2.supernodexp.hpc;Job Queued at request of ctminh@node2.supernodexp.hpc, owner = ctminh@node2.supernodexp.hpc, job name = thread-affinity, queue = workq
02/19/2018 16:41:14;0040;Server@node2;Svr;node2.supernodexp.hpc;Scheduler sent command 1
02/19/2018 16:41:14;0040;Server@node2;Svr;node2.supernodexp.hpc;Scheduler sent command 0
02/19/2018 16:41:14;0100;Server@node2;Req;;Type 21 request received from Scheduler@node2.supernodexp.hpc, sock=20
02/19/2018 16:41:14;0100;Server@node2;Req;;Type 81 request received from Scheduler@node2.supernodexp.hpc, sock=20
02/19/2018 16:41:14;0100;Server@node2;Req;;Type 71 request received from Scheduler@node2.supernodexp.hpc, sock=20
02/19/2018 16:41:14;0100;Server@node2;Req;;Type 58 request received from Scheduler@node2.supernodexp.hpc, sock=20
02/19/2018 16:41:14;0100;Server@node2;Req;;Type 20 request received from Scheduler@node2.supernodexp.hpc, sock=20
02/19/2018 16:41:14;0100;Server@node2;Req;;Type 51 request received from Scheduler@node2.supernodexp.hpc, sock=20
02/19/2018 16:41:14;0100;Server@node2;Req;;Type 11 request received from Scheduler@node2.supernodexp.hpc, sock=20
02/19/2018 16:41:14;0008;Server@node2;Job;3718.node2.supernodexp.hpc;Job Modified at request of Scheduler@node2.supernodexp.hpc
02/19/2018 16:41:42;0100;Server@node2;Req;;Type 1 request received from ctminh@node2.supernodexp.hpc, sock=16
02/19/2018 16:41:42;0100;Server@node2;Req;;Type 3 request received from ctminh@node2.supernodexp.hpc, sock=16
02/19/2018 16:41:42;0100;Server@node2;Req;;Type 5 request received from ctminh@node2.supernodexp.hpc, sock=16
02/19/2018 16:41:42;0100;Server@node2;Job;3719.node2.supernodexp.hpc;enqueuing into workq, state 1 hop 1
02/19/2018 16:41:42;0008;Server@node2;Job;3719.node2.supernodexp.hpc;Job Queued at request of ctminh@node2.supernodexp.hpc, owner = ctminh@node2.supernodexp.hpc, job name = telemac1, queue = workq
02/19/2018 16:41:42;0040;Server@node2;Svr;node2.supernodexp.hpc;Scheduler sent command 1
02/19/2018 16:41:42;0040;Server@node2;Svr;node2.supernodexp.hpc;Scheduler sent command 0
02/19/2018 16:41:42;0100;Server@node2;Req;;Type 21 request received from Scheduler@node2.supernodexp.hpc, sock=20
02/19/2018 16:41:42;0100;Server@node2;Req;;Type 81 request received from Scheduler@node2.supernodexp.hpc, sock=20
02/19/2018 16:41:42;0100;Server@node2;Req;;Type 71 request received from Scheduler@node2.supernodexp.hpc, sock=20
02/19/2018 16:41:42;0100;Server@node2;Req;;Type 58 request received from Scheduler@node2.supernodexp.hpc, sock=20
02/19/2018 16:41:42;0100;Server@node2;Req;;Type 20 request received from Scheduler@node2.supernodexp.hpc, sock=20
02/19/2018 16:41:42;0100;Server@node2;Req;;Type 51 request received from Scheduler@node2.supernodexp.hpc, sock=20
02/19/2018 16:41:42;0100;Server@node2;Req;;Type 11 request received from Scheduler@node2.supernodexp.hpc, sock=20
02/19/2018 16:41:42;0008;Server@node2;Job;3719.node2.supernodexp.hpc;Job Modified at request of Scheduler@node2.supernodexp.hpc
02/19/2018 16:41:44;0100;Server@node2;Req;;Type 1 request received from ctminh@node2.supernodexp.hpc, sock=16
02/19/2018 16:41:44;0100;Server@node2;Req;;Type 3 request received from ctminh@node2.supernodexp.hpc, sock=16
02/19/2018 16:41:44;0100;Server@node2;Req;;Type 5 request received from ctminh@node2.supernodexp.hpc, sock=16
02/19/2018 16:41:44;0100;Server@node2;Job;3720.node2.supernodexp.hpc;enqueuing into workq, state 1 hop 1
02/19/2018 16:41:44;0008;Server@node2;Job;3720.node2.supernodexp.hpc;Job Queued at request of ctminh@node2.supernodexp.hpc, owner = ctminh@node2.supernodexp.hpc, job name = jacobi, queue = workq
02/19/2018 16:41:44;0040;Server@node2;Svr;node2.supernodexp.hpc;Scheduler sent command 1
02/19/2018 16:41:44;0040;Server@node2;Svr;node2.supernodexp.hpc;Scheduler sent command 0
02/19/2018 16:41:44;0100;Server@node2;Req;;Type 21 request received from Scheduler@node2.supernodexp.hpc, sock=20
02/19/2018 16:41:44;0100;Server@node2;Req;;Type 81 request received from Scheduler@node2.supernodexp.hpc, sock=20
02/19/2018 16:41:44;0100;Server@node2;Req;;Type 71 request received from Scheduler@node2.supernodexp.hpc, sock=20
02/19/2018 16:41:44;0100;Server@node2;Req;;Type 58 request received from Scheduler@node2.supernodexp.hpc, sock=20
02/19/2018 16:41:44;0100;Server@node2;Req;;Type 20 request received from Scheduler@node2.supernodexp.hpc, sock=20
02/19/2018 16:41:44;0100;Server@node2;Req;;Type 51 request received from Scheduler@node2.supernodexp.hpc, sock=20
02/19/2018 16:41:44;0100;Server@node2;Req;;Type 11 request received from Scheduler@node2.supernodexp.hpc, sock=20
02/19/2018 16:41:44;0008;Server@node2;Job;3720.node2.supernodexp.hpc;Job Modified at request of Scheduler@node2.supernodexp.hpc
02/19/2018 16:41:55;0100;Server@node2;Req;;Type 1 request received from ctminh@node2.supernodexp.hpc, sock=16
02/19/2018 16:41:55;0100;Server@node2;Req;;Type 3 request received from ctminh@node2.supernodexp.hpc, sock=16
02/19/2018 16:41:55;0100;Server@node2;Req;;Type 5 request received from ctminh@node2.supernodexp.hpc, sock=16
02/19/2018 16:41:55;0100;Server@node2;Job;3721.node2.supernodexp.hpc;enqueuing into workq, state 1 hop 1
02/19/2018 16:41:55;0008;Server@node2;Job;3721.node2.supernodexp.hpc;Job Queued at request of ctminh@node2.supernodexp.hpc, owner = ctminh@node2.supernodexp.hpc, job name = sweep, queue = workq
02/19/2018 16:41:55;0040;Server@node2;Svr;node2.supernodexp.hpc;Scheduler sent command 1
02/19/2018 16:41:55;0040;Server@node2;Svr;node2.supernodexp.hpc;Scheduler sent command 0
02/19/2018 16:41:55;0100;Server@node2;Req;;Type 21 request received from Scheduler@node2.supernodexp.hpc, sock=20
02/19/2018 16:41:55;0100;Server@node2;Req;;Type 81 request received from Scheduler@node2.supernodexp.hpc, sock=20
02/19/2018 16:41:55;0100;Server@node2;Req;;Type 71 request received from Scheduler@node2.supernodexp.hpc, sock=20
02/19/2018 16:41:55;0100;Server@node2;Req;;Type 58 request received from Scheduler@node2.supernodexp.hpc, sock=20
02/19/2018 16:41:55;0100;Server@node2;Req;;Type 1 request received from ctminh@node2.supernodexp.hpc, sock=16
02/19/2018 16:41:55;0100;Server@node2;Req;;Type 3 request received from ctminh@node2.supernodexp.hpc, sock=16
02/19/2018 16:41:55;0100;Server@node2;Req;;Type 5 request received from ctminh@node2.supernodexp.hpc, sock=16
02/19/2018 16:41:55;0100;Server@node2;Job;3722.node2.supernodexp.hpc;enqueuing into workq, state 1 hop 1
02/19/2018 16:41:55;0008;Server@node2;Job;3722.node2.supernodexp.hpc;Job Queued at request of ctminh@node2.supernodexp.hpc, owner = ctminh@node2.supernodexp.hpc, job name = telemac1, queue = workq
02/19/2018 16:41:55;0100;Server@node2;Req;;Type 20 request received from Scheduler@node2.supernodexp.hpc, sock=20
02/19/2018 16:41:55;0100;Server@node2;Req;;Type 51 request received from Scheduler@node2.supernodexp.hpc, sock=20
02/19/2018 16:41:55;0100;Server@node2;Req;;Type 11 request received from Scheduler@node2.supernodexp.hpc, sock=20
02/19/2018 16:41:55;0008;Server@node2;Job;3722.node2.supernodexp.hpc;Job Modified at request of Scheduler@node2.supernodexp.hpc
02/19/2018 16:41:55;0100;Server@node2;Req;;Type 11 request received from Scheduler@node2.supernodexp.hpc, sock=20
02/19/2018 16:41:55;0008;Server@node2;Job;3721.node2.supernodexp.hpc;Job Modified at request of Scheduler@node2.supernodexp.hpc
02/19/2018 16:41:55;0040;Server@node2;Svr;node2.supernodexp.hpc;Scheduler sent command 1
02/19/2018 16:41:55;0040;Server@node2;Svr;node2.supernodexp.hpc;Scheduler sent command 0
02/19/2018 16:41:55;0100;Server@node2;Req;;Type 21 request received from Scheduler@node2.supernodexp.hpc, sock=20
02/19/2018 16:41:55;0100;Server@node2;Req;;Type 81 request received from Scheduler@node2.supernodexp.hpc, sock=20
02/19/2018 16:41:55;0100;Server@node2;Req;;Type 71 request received from Scheduler@node2.supernodexp.hpc, sock=20
02/19/2018 16:41:55;0100;Server@node2;Req;;Type 58 request received from Scheduler@node2.supernodexp.hpc, sock=20
02/19/2018 16:41:55;0100;Server@node2;Req;;Type 20 request received from Scheduler@node2.supernodexp.hpc, sock=20
02/19/2018 16:41:55;0100;Server@node2;Req;;Type 51 request received from Scheduler@node2.supernodexp.hpc, sock=20
02/19/2018 16:42:04;0100;Server@node2;Req;;Type 1 request received from ctminh@node2.supernodexp.hpc, sock=16
02/19/2018 16:42:04;0100;Server@node2;Req;;Type 3 request received from ctminh@node2.supernodexp.hpc, sock=16
02/19/2018 16:42:04;0100;Server@node2;Req;;Type 5 request received from ctminh@node2.supernodexp.hpc, sock=16
02/19/2018 16:42:04;0100;Server@node2;Job;3723.node2.supernodexp.hpc;enqueuing into workq, state 1 hop 1
02/19/2018 16:42:04;0008;Server@node2;Job;3723.node2.supernodexp.hpc;Job Queued at request of ctminh@node2.supernodexp.hpc, owner = ctminh@node2.supernodexp.hpc, job name = lu-decomp, queue = workq
02/19/2018 16:42:04;0040;Server@node2;Svr;node2.supernodexp.hpc;Scheduler sent command 1
02/19/2018 16:42:04;0040;Server@node2;Svr;node2.supernodexp.hpc;Scheduler sent command 0
02/19/2018 16:42:04;0100;Server@node2;Req;;Type 21 request received from Scheduler@node2.supernodexp.hpc, sock=20
02/19/2018 16:42:04;0100;Server@node2;Req;;Type 81 request received from Scheduler@node2.supernodexp.hpc, sock=20
02/19/2018 16:42:04;0100;Server@node2;Req;;Type 71 request received from Scheduler@node2.supernodexp.hpc, sock=20
02/19/2018 16:42:04;0100;Server@node2;Req;;Type 58 request received from Scheduler@node2.supernodexp.hpc, sock=20
02/19/2018 16:42:04;0100;Server@node2;Req;;Type 20 request received from Scheduler@node2.supernodexp.hpc, sock=20
02/19/2018 16:42:04;0100;Server@node2;Req;;Type 51 request received from Scheduler@node2.supernodexp.hpc, sock=20
02/19/2018 16:42:04;0100;Server@node2;Req;;Type 11 request received from Scheduler@node2.supernodexp.hpc, sock=20
02/19/2018 16:42:04;0008;Server@node2;Job;3723.node2.supernodexp.hpc;Job Modified at request of Scheduler@node2.supernodexp.hpc
02/19/2018 16:42:31;0100;Server@node2;Req;;Type 1 request received from ctminh@node2.supernodexp.hpc, sock=16
02/19/2018 16:42:31;0100;Server@node2;Req;;Type 3 request received from ctminh@node2.supernodexp.hpc, sock=16
02/19/2018 16:42:31;0100;Server@node2;Req;;Type 5 request received from ctminh@node2.supernodexp.hpc, sock=16
02/19/2018 16:42:31;0100;Server@node2;Job;3724.node2.supernodexp.hpc;enqueuing into workq, state 1 hop 1
02/19/2018 16:42:31;0008;Server@node2;Job;3724.node2.supernodexp.hpc;Job Queued at request of ctminh@node2.supernodexp.hpc, owner = ctminh@node2.supernodexp.hpc, job name = jacobi, queue = workq
02/19/2018 16:42:31;0040;Server@node2;Svr;node2.supernodexp.hpc;Scheduler sent command 1
02/19/2018 16:42:31;0040;Server@node2;Svr;node2.supernodexp.hpc;Scheduler sent command 0
02/19/2018 16:42:31;0100;Server@node2;Req;;Type 21 request received from Scheduler@node2.supernodexp.hpc, sock=20
02/19/2018 16:42:31;0100;Server@node2;Req;;Type 81 request received from Scheduler@node2.supernodexp.hpc, sock=20
02/19/2018 16:42:31;0100;Server@node2;Req;;Type 71 request received from Scheduler@node2.supernodexp.hpc, sock=20
02/19/2018 16:42:31;0100;Server@node2;Req;;Type 58 request received from Scheduler@node2.supernodexp.hpc, sock=20
02/19/2018 16:42:31;0100;Server@node2;Req;;Type 20 request received from Scheduler@node2.supernodexp.hpc, sock=20
02/19/2018 16:42:31;0100;Server@node2;Req;;Type 51 request received from Scheduler@node2.supernodexp.hpc, sock=20
02/19/2018 16:42:31;0100;Server@node2;Req;;Type 11 request received from Scheduler@node2.supernodexp.hpc, sock=20
02/19/2018 16:42:31;0008;Server@node2;Job;3724.node2.supernodexp.hpc;Job Modified at request of Scheduler@node2.supernodexp.hpc
02/19/2018 16:42:56;0100;Server@node2;Req;;Type 1 request received from ctminh@node2.supernodexp.hpc, sock=16
02/19/2018 16:42:56;0100;Server@node2;Req;;Type 3 request received from ctminh@node2.supernodexp.hpc, sock=16
02/19/2018 16:42:56;0100;Server@node2;Req;;Type 5 request received from ctminh@node2.supernodexp.hpc, sock=16
02/19/2018 16:42:56;0100;Server@node2;Job;3725.node2.supernodexp.hpc;enqueuing into workq, state 1 hop 1
02/19/2018 16:42:56;0008;Server@node2;Job;3725.node2.supernodexp.hpc;Job Queued at request of ctminh@node2.supernodexp.hpc, owner = ctminh@node2.supernodexp.hpc, job name = sweep, queue = workq
02/19/2018 16:42:56;0040;Server@node2;Svr;node2.supernodexp.hpc;Scheduler sent command 1
02/19/2018 16:42:56;0040;Server@node2;Svr;node2.supernodexp.hpc;Scheduler sent command 0
02/19/2018 16:42:56;0100;Server@node2;Req;;Type 21 request received from Scheduler@node2.supernodexp.hpc, sock=20
02/19/2018 16:42:56;0100;Server@node2;Req;;Type 81 request received from Scheduler@node2.supernodexp.hpc, sock=20
02/19/2018 16:42:56;0100;Server@node2;Req;;Type 71 request received from Scheduler@node2.supernodexp.hpc, sock=20
02/19/2018 16:42:56;0100;Server@node2;Req;;Type 58 request received from Scheduler@node2.supernodexp.hpc, sock=20
02/19/2018 16:42:56;0100;Server@node2;Req;;Type 20 request received from Scheduler@node2.supernodexp.hpc, sock=20
02/19/2018 16:42:56;0100;Server@node2;Req;;Type 51 request received from Scheduler@node2.supernodexp.hpc, sock=20
02/19/2018 16:42:56;0100;Server@node2;Req;;Type 11 request received from Scheduler@node2.supernodexp.hpc, sock=20
02/19/2018 16:42:56;0008;Server@node2;Job;3725.node2.supernodexp.hpc;Job Modified at request of Scheduler@node2.supernodexp.hpc
02/19/2018 16:43:22;0080;Server@node2;Job;3641.node2.supernodexp.hpc;Obit received momhop:1 serverhop:1 state:4 substate:42
02/19/2018 16:43:23;0010;Server@node2;Job;3641.node2.supernodexp.hpc;Exit_status=2 resources_used.cpupercent=2230 resources_used.cput=06:30:30 resources_used.mem=22033188kb resources_used.ncpus=32 resources_used.vmem=25063192kb resources_used.walltime=00:18:22
02/19/2018 16:43:23;0100;Server@node2;Job;3641.node2.supernodexp.hpc;dequeuing from workq, state 5
02/19/2018 16:43:23;0040;Server@node2;Svr;node2.supernodexp.hpc;Scheduler sent command 2
02/19/2018 16:43:23;0040;Server@node2;Svr;node2.supernodexp.hpc;Scheduler sent command 0
02/19/2018 16:43:23;0100;Server@node2;Req;;Type 21 request received from Scheduler@node2.supernodexp.hpc, sock=20
02/19/2018 16:43:23;0100;Server@node2;Req;;Type 81 request received from Scheduler@node2.supernodexp.hpc, sock=20
02/19/2018 16:43:23;0100;Server@node2;Req;;Type 71 request received from Scheduler@node2.supernodexp.hpc, sock=20
02/19/2018 16:43:23;0100;Server@node2;Req;;Type 58 request received from Scheduler@node2.supernodexp.hpc, sock=20
02/19/2018 16:43:23;0100;Server@node2;Req;;Type 20 request received from Scheduler@node2.supernodexp.hpc, sock=20
02/19/2018 16:43:23;0100;Server@node2;Req;;Type 51 request received from Scheduler@node2.supernodexp.hpc, sock=20
02/19/2018 16:43:23;0100;Server@node2;Req;;Type 23 request received from Scheduler@node2.supernodexp.hpc, sock=20
02/19/2018 16:43:23;0008;Server@node2;Job;3668.node2.supernodexp.hpc;Job Run at request of Scheduler@node2.supernodexp.hpc on exec_vnode (node13:ncpus=32:nmics=1:mem=16777216kb)
02/19/2018 16:43:23;0001;Server@node2;Svr;Server@node2;Success (0) in req_runjob2, return value of svr_startjob is 0
02/19/2018 16:43:23;0100;Server@node2;Req;;Type 11 request received from Scheduler@node2.supernodexp.hpc, sock=20
02/19/2018 16:43:23;0008;Server@node2;Job;3672.node2.supernodexp.hpc;Job Modified at request of Scheduler@node2.supernodexp.hpc
02/19/2018 16:43:31;0100;Server@node2;Req;;Type 1 request received from ctminh@node2.supernodexp.hpc, sock=16
02/19/2018 16:43:31;0100;Server@node2;Hook;_pbs_python_event_set;Restarting Python interpreter to reduce mem usage
02/19/2018 16:43:31;0100;Server@node2;Svr;Server@node2;--> Stopping Python interpreter <--
02/19/2018 16:43:31;0100;Server@node2;Svr;Server@node2;--> Python Interpreter started, compiled with version:'2.7.5' <--
02/19/2018 16:43:31;0100;Server@node2;Svr;Server@node2;sys.modules= {'pbs.v1._svr_types': <module 'pbs.v1._svr_types' from '/opt/pbs/lib/python/altair/pbs/v1/_svr_types.pyo'>, 'copy_reg': <module 'copy_reg' from '/usr/lib64/python2.7/copy_reg.pyo'>, 'pbs.v1._pbs_v1': None, '__main__': <module '__main__' (built-in)>, '__builtin__': <module '__builtin__' (built-in)>, '_pbs_v1.svr_types': <module '_pbs_v1.svr_types' (built-in)>, 'encodings': <module 'encodings' from '/usr/lib64/python2.7/encodings/__init__.pyo'>, 'encodings.encodings': None, 'abc': <module 'abc' from '/usr/lib64/python2.7/abc.pyo'>, 'pbs._pbs_v1': None, 'posixpath': <module 'posixpath' from '/usr/lib64/python2.7/posixpath.pyo'>, '_weakrefset': <module '_weakrefset' from '/usr/lib64/python2.7/_weakrefset.pyo'>, 'pbs.v1': <module 'pbs.v1' from '/opt/pbs/lib/python/altair/pbs/v1/__init__.pyo'>, 'errno': <module 'errno' (built-in)>, 'encodings.codecs': None, 'pbs.v1._export_types': <module 'pbs.v1._export_types' from '/opt/pbs/lib/python/altair/pbs/v1/_export_types.pyo'>, 'pbs.v1.os': None, '_abcoll': <module '_abcoll' from '/usr/lib64/python2.7/_abcoll.pyo'>, 'os.path': <module 'posixpath' from '/usr/lib64/python2.7/posixpath.pyo'>, 'UserDict': <module 'UserDict' from '/usr/lib64/python2.7/UserDict.pyo'>, '_warnings': <module '_warnings' (built-in)>, 'genericpath': <module 'genericpath' from '/usr/lib64/python2.7/genericpath.pyo'>, 'stat': <module 'stat' from '/usr/lib64/python2.7/stat.pyo'>, 'zipimport': <module 'zipimport' (built-in)>, 'encodings.__builtin__': None, 'pbs.pbs': None, 'warnings': <module 'warnings' from '/usr/lib64/python2.7/warnings.pyo'>, '_codecs': <module '_codecs' (built-in)>, 'encodings.ascii': <module 'encodings.ascii' from '/usr/lib64/python2.7/encodings/ascii.pyo'>, 'sys': <module 'sys' (built-in)>, 'pbs.v1._base_types': <module 'pbs.v1._base_types' from '/opt/pbs/lib/python/altair/pbs/v1/_base_types.pyo'>, 'pbs.v1.sys': None, 'codecs': <module 'codecs' from '/usr/lib64/python2.7/codecs.pyo'>, 'types': <module 'types' from '/usr/lib64/python2.7/types.pyo'>, 'pbs': <module 'pbs' from '/opt/pbs/lib/python/altair/pbs/__init__.pyo'>, 'os': <module 'os' from '/usr/lib64/python2.7/os.pyo'>, 'signal': <module 'signal' (built-in)>, 'linecache': <module 'linecache' from '/usr/lib64/python2.7/linecache.pyo'>, '_pbs_v1': <module '_pbs_v1' (built-in)>, 'posix': <module 'posix' (built-in)>, 'encodings.aliases': <module 'encodings.aliases' from '/usr/lib64/python2.7/encodings/aliases.pyo'>, 'exceptions': <module 'exceptions' (built-in)>, 'pbs.v1._exc_types': <module 'pbs.v1._exc_types' from '/opt/pbs/lib/python/altair/pbs/v1/_exc_types.pyo'>, '_weakref': <module '_weakref' (built-in)>}
02/19/2018 16:43:31;0106;Server@node2;Svr;Server@node2;BEGIN setting up all resource attributes 
02/19/2018 16:43:31;0106;Server@node2;Svr;Server@node2;DONE setting up all resource attributes, number set <51>
02/19/2018 16:43:31;0106;Server@node2;Svr;Server@node2;BEGIN setting up all queue attributes 
02/19/2018 16:43:31;0106;Server@node2;Svr;Server@node2;DONE setting up all queue attributes, number set <55>
02/19/2018 16:43:31;0106;Server@node2;Svr;Server@node2;BEGIN setting up all job attributes 
02/19/2018 16:43:31;0106;Server@node2;Svr;Server@node2;DONE setting up all job attributes, number set <94>
02/19/2018 16:43:31;0106;Server@node2;Svr;Server@node2;BEGIN setting up all server attributes 
02/19/2018 16:43:31;0106;Server@node2;Svr;Server@node2;DONE setting up all server attributes, number set <88>
02/19/2018 16:43:31;0106;Server@node2;Svr;Server@node2;BEGIN setting up all reservation attributes 
02/19/2018 16:43:31;0106;Server@node2;Svr;Server@node2;DONE setting up all reservation attributes, number set <43>
02/19/2018 16:43:31;0106;Server@node2;Svr;Server@node2;BEGIN setting up all vnode attributes 
02/19/2018 16:43:31;0106;Server@node2;Svr;Server@node2;DONE setting up all vnode attributes, number set <28>
02/19/2018 16:43:31;0100;Server@node2;Hook;_pbs_python_event_set;Current memory usage: VmSize=321652kB, VmRSS=13052kB
02/19/2018 16:43:31;0100;Server@node2;Req;;Type 3 request received from ctminh@node2.supernodexp.hpc, sock=16
02/19/2018 16:43:31;0100;Server@node2;Req;;Type 5 request received from ctminh@node2.supernodexp.hpc, sock=16
02/19/2018 16:43:31;0100;Server@node2;Job;3726.node2.supernodexp.hpc;enqueuing into workq, state 1 hop 1
02/19/2018 16:43:31;0008;Server@node2;Job;3726.node2.supernodexp.hpc;Job Queued at request of ctminh@node2.supernodexp.hpc, owner = ctminh@node2.supernodexp.hpc, job name = histogram, queue = workq
02/19/2018 16:43:31;0040;Server@node2;Svr;node2.supernodexp.hpc;Scheduler sent command 1
02/19/2018 16:43:31;0040;Server@node2;Svr;node2.supernodexp.hpc;Scheduler sent command 0
02/19/2018 16:43:31;0100;Server@node2;Req;;Type 21 request received from Scheduler@node2.supernodexp.hpc, sock=20
02/19/2018 16:43:31;0100;Server@node2;Req;;Type 81 request received from Scheduler@node2.supernodexp.hpc, sock=20
02/19/2018 16:43:31;0100;Server@node2;Req;;Type 71 request received from Scheduler@node2.supernodexp.hpc, sock=20
02/19/2018 16:43:31;0100;Server@node2;Req;;Type 58 request received from Scheduler@node2.supernodexp.hpc, sock=20
02/19/2018 16:43:31;0100;Server@node2;Req;;Type 20 request received from Scheduler@node2.supernodexp.hpc, sock=20
02/19/2018 16:43:31;0100;Server@node2;Req;;Type 51 request received from Scheduler@node2.supernodexp.hpc, sock=20
02/19/2018 16:43:31;0100;Server@node2;Req;;Type 11 request received from Scheduler@node2.supernodexp.hpc, sock=20
02/19/2018 16:43:31;0008;Server@node2;Job;3726.node2.supernodexp.hpc;Job Modified at request of Scheduler@node2.supernodexp.hpc
02/19/2018 16:43:35;0100;Server@node2;Req;;Type 1 request received from ctminh@node2.supernodexp.hpc, sock=16
02/19/2018 16:43:35;0100;Server@node2;Req;;Type 3 request received from ctminh@node2.supernodexp.hpc, sock=16
02/19/2018 16:43:35;0100;Server@node2;Req;;Type 5 request received from ctminh@node2.supernodexp.hpc, sock=16
02/19/2018 16:43:35;0100;Server@node2;Job;3727.node2.supernodexp.hpc;enqueuing into workq, state 1 hop 1
02/19/2018 16:43:35;0008;Server@node2;Job;3727.node2.supernodexp.hpc;Job Queued at request of ctminh@node2.supernodexp.hpc, owner = ctminh@node2.supernodexp.hpc, job name = qe_mic_test, queue = workq
02/19/2018 16:43:35;0040;Server@node2;Svr;node2.supernodexp.hpc;Scheduler sent command 1
02/19/2018 16:43:35;0040;Server@node2;Svr;node2.supernodexp.hpc;Scheduler sent command 0
02/19/2018 16:43:35;0100;Server@node2;Req;;Type 21 request received from Scheduler@node2.supernodexp.hpc, sock=20
02/19/2018 16:43:35;0100;Server@node2;Req;;Type 81 request received from Scheduler@node2.supernodexp.hpc, sock=20
02/19/2018 16:43:35;0100;Server@node2;Req;;Type 71 request received from Scheduler@node2.supernodexp.hpc, sock=20
02/19/2018 16:43:35;0100;Server@node2;Req;;Type 58 request received from Scheduler@node2.supernodexp.hpc, sock=20
02/19/2018 16:43:35;0100;Server@node2;Req;;Type 20 request received from Scheduler@node2.supernodexp.hpc, sock=20
02/19/2018 16:43:35;0100;Server@node2;Req;;Type 51 request received from Scheduler@node2.supernodexp.hpc, sock=20
02/19/2018 16:43:36;0100;Server@node2;Req;;Type 11 request received from Scheduler@node2.supernodexp.hpc, sock=20
02/19/2018 16:43:36;0008;Server@node2;Job;3727.node2.supernodexp.hpc;Job Modified at request of Scheduler@node2.supernodexp.hpc
02/19/2018 16:44:33;0100;Server@node2;Req;;Type 1 request received from ctminh@node2.supernodexp.hpc, sock=16
02/19/2018 16:44:33;0100;Server@node2;Req;;Type 3 request received from ctminh@node2.supernodexp.hpc, sock=16
02/19/2018 16:44:33;0100;Server@node2;Req;;Type 5 request received from ctminh@node2.supernodexp.hpc, sock=16
02/19/2018 16:44:33;0100;Server@node2;Job;3728.node2.supernodexp.hpc;enqueuing into workq, state 1 hop 1
02/19/2018 16:44:33;0008;Server@node2;Job;3728.node2.supernodexp.hpc;Job Queued at request of ctminh@node2.supernodexp.hpc, owner = ctminh@node2.supernodexp.hpc, job name = matrix-x-vector, queue = workq
02/19/2018 16:44:33;0040;Server@node2;Svr;node2.supernodexp.hpc;Scheduler sent command 1
02/19/2018 16:44:33;0040;Server@node2;Svr;node2.supernodexp.hpc;Scheduler sent command 0
02/19/2018 16:44:33;0100;Server@node2;Req;;Type 21 request received from Scheduler@node2.supernodexp.hpc, sock=20
02/19/2018 16:44:33;0100;Server@node2;Req;;Type 81 request received from Scheduler@node2.supernodexp.hpc, sock=20
02/19/2018 16:44:33;0100;Server@node2;Req;;Type 71 request received from Scheduler@node2.supernodexp.hpc, sock=20
02/19/2018 16:44:33;0100;Server@node2;Req;;Type 58 request received from Scheduler@node2.supernodexp.hpc, sock=20
02/19/2018 16:44:33;0100;Server@node2;Req;;Type 20 request received from Scheduler@node2.supernodexp.hpc, sock=20
02/19/2018 16:44:33;0100;Server@node2;Req;;Type 51 request received from Scheduler@node2.supernodexp.hpc, sock=20
02/19/2018 16:44:33;0100;Server@node2;Req;;Type 11 request received from Scheduler@node2.supernodexp.hpc, sock=20
02/19/2018 16:44:33;0008;Server@node2;Job;3728.node2.supernodexp.hpc;Job Modified at request of Scheduler@node2.supernodexp.hpc
02/19/2018 16:44:42;0100;Server@node2;Req;;Type 1 request received from ctminh@node2.supernodexp.hpc, sock=16
02/19/2018 16:44:42;0100;Server@node2;Req;;Type 3 request received from ctminh@node2.supernodexp.hpc, sock=16
02/19/2018 16:44:42;0100;Server@node2;Req;;Type 5 request received from ctminh@node2.supernodexp.hpc, sock=16
02/19/2018 16:44:42;0100;Server@node2;Job;3729.node2.supernodexp.hpc;enqueuing into workq, state 1 hop 1
02/19/2018 16:44:42;0008;Server@node2;Job;3729.node2.supernodexp.hpc;Job Queued at request of ctminh@node2.supernodexp.hpc, owner = ctminh@node2.supernodexp.hpc, job name = jacobi, queue = workq
02/19/2018 16:44:42;0040;Server@node2;Svr;node2.supernodexp.hpc;Scheduler sent command 1
02/19/2018 16:44:42;0040;Server@node2;Svr;node2.supernodexp.hpc;Scheduler sent command 0
02/19/2018 16:44:42;0100;Server@node2;Req;;Type 21 request received from Scheduler@node2.supernodexp.hpc, sock=20
02/19/2018 16:44:42;0100;Server@node2;Req;;Type 81 request received from Scheduler@node2.supernodexp.hpc, sock=20
02/19/2018 16:44:42;0100;Server@node2;Req;;Type 71 request received from Scheduler@node2.supernodexp.hpc, sock=20
02/19/2018 16:44:42;0100;Server@node2;Req;;Type 58 request received from Scheduler@node2.supernodexp.hpc, sock=20
02/19/2018 16:44:42;0100;Server@node2;Req;;Type 20 request received from Scheduler@node2.supernodexp.hpc, sock=20
02/19/2018 16:44:42;0100;Server@node2;Req;;Type 51 request received from Scheduler@node2.supernodexp.hpc, sock=20
02/19/2018 16:44:42;0100;Server@node2;Req;;Type 11 request received from Scheduler@node2.supernodexp.hpc, sock=20
02/19/2018 16:44:42;0008;Server@node2;Job;3729.node2.supernodexp.hpc;Job Modified at request of Scheduler@node2.supernodexp.hpc
02/19/2018 16:44:47;0100;Server@node2;Req;;Type 1 request received from ctminh@node2.supernodexp.hpc, sock=16
02/19/2018 16:44:47;0100;Server@node2;Req;;Type 3 request received from ctminh@node2.supernodexp.hpc, sock=16
02/19/2018 16:44:47;0100;Server@node2;Req;;Type 5 request received from ctminh@node2.supernodexp.hpc, sock=16
02/19/2018 16:44:47;0100;Server@node2;Job;3730.node2.supernodexp.hpc;enqueuing into workq, state 1 hop 1
02/19/2018 16:44:47;0008;Server@node2;Job;3730.node2.supernodexp.hpc;Job Queued at request of ctminh@node2.supernodexp.hpc, owner = ctminh@node2.supernodexp.hpc, job name = histogram, queue = workq
02/19/2018 16:44:47;0040;Server@node2;Svr;node2.supernodexp.hpc;Scheduler sent command 1
02/19/2018 16:44:47;0040;Server@node2;Svr;node2.supernodexp.hpc;Scheduler sent command 0
02/19/2018 16:44:47;0100;Server@node2;Req;;Type 21 request received from Scheduler@node2.supernodexp.hpc, sock=20
02/19/2018 16:44:47;0100;Server@node2;Req;;Type 81 request received from Scheduler@node2.supernodexp.hpc, sock=20
02/19/2018 16:44:47;0100;Server@node2;Req;;Type 71 request received from Scheduler@node2.supernodexp.hpc, sock=20
02/19/2018 16:44:47;0100;Server@node2;Req;;Type 58 request received from Scheduler@node2.supernodexp.hpc, sock=20
02/19/2018 16:44:47;0100;Server@node2;Req;;Type 20 request received from Scheduler@node2.supernodexp.hpc, sock=20
02/19/2018 16:44:47;0100;Server@node2;Req;;Type 51 request received from Scheduler@node2.supernodexp.hpc, sock=20
02/19/2018 16:44:47;0100;Server@node2;Req;;Type 11 request received from Scheduler@node2.supernodexp.hpc, sock=20
02/19/2018 16:44:47;0008;Server@node2;Job;3730.node2.supernodexp.hpc;Job Modified at request of Scheduler@node2.supernodexp.hpc
02/19/2018 16:45:15;0100;Server@node2;Req;;Type 1 request received from ctminh@node2.supernodexp.hpc, sock=16
02/19/2018 16:45:15;0100;Server@node2;Req;;Type 3 request received from ctminh@node2.supernodexp.hpc, sock=16
02/19/2018 16:45:15;0100;Server@node2;Req;;Type 5 request received from ctminh@node2.supernodexp.hpc, sock=16
02/19/2018 16:45:15;0100;Server@node2;Job;3731.node2.supernodexp.hpc;enqueuing into workq, state 1 hop 1
02/19/2018 16:45:15;0008;Server@node2;Job;3731.node2.supernodexp.hpc;Job Queued at request of ctminh@node2.supernodexp.hpc, owner = ctminh@node2.supernodexp.hpc, job name = matrix-x-vector, queue = workq
02/19/2018 16:45:15;0040;Server@node2;Svr;node2.supernodexp.hpc;Scheduler sent command 1
02/19/2018 16:45:15;0040;Server@node2;Svr;node2.supernodexp.hpc;Scheduler sent command 0
02/19/2018 16:45:15;0100;Server@node2;Req;;Type 21 request received from Scheduler@node2.supernodexp.hpc, sock=20
02/19/2018 16:45:15;0100;Server@node2;Req;;Type 81 request received from Scheduler@node2.supernodexp.hpc, sock=20
02/19/2018 16:45:15;0100;Server@node2;Req;;Type 71 request received from Scheduler@node2.supernodexp.hpc, sock=20
02/19/2018 16:45:15;0100;Server@node2;Req;;Type 58 request received from Scheduler@node2.supernodexp.hpc, sock=20
02/19/2018 16:45:15;0100;Server@node2;Req;;Type 20 request received from Scheduler@node2.supernodexp.hpc, sock=20
02/19/2018 16:45:15;0100;Server@node2;Req;;Type 51 request received from Scheduler@node2.supernodexp.hpc, sock=20
02/19/2018 16:45:15;0100;Server@node2;Req;;Type 11 request received from Scheduler@node2.supernodexp.hpc, sock=20
02/19/2018 16:45:15;0008;Server@node2;Job;3731.node2.supernodexp.hpc;Job Modified at request of Scheduler@node2.supernodexp.hpc
02/19/2018 16:45:17;0080;Server@node2;Job;3665.node2.supernodexp.hpc;Obit received momhop:1 serverhop:1 state:4 substate:42
02/19/2018 16:45:19;0010;Server@node2;Job;3665.node2.supernodexp.hpc;Exit_status=2 resources_used.cpupercent=2176 resources_used.cput=06:19:56 resources_used.mem=22165948kb resources_used.ncpus=32 resources_used.vmem=24899036kb resources_used.walltime=00:19:02
02/19/2018 16:45:19;0100;Server@node2;Job;3665.node2.supernodexp.hpc;dequeuing from workq, state 5
02/19/2018 16:45:19;0040;Server@node2;Svr;node2.supernodexp.hpc;Scheduler sent command 2
02/19/2018 16:45:19;0040;Server@node2;Svr;node2.supernodexp.hpc;Scheduler sent command 0
02/19/2018 16:45:19;0100;Server@node2;Req;;Type 21 request received from Scheduler@node2.supernodexp.hpc, sock=20
02/19/2018 16:45:19;0100;Server@node2;Req;;Type 81 request received from Scheduler@node2.supernodexp.hpc, sock=20
02/19/2018 16:45:19;0100;Server@node2;Req;;Type 71 request received from Scheduler@node2.supernodexp.hpc, sock=20
02/19/2018 16:45:19;0100;Server@node2;Req;;Type 58 request received from Scheduler@node2.supernodexp.hpc, sock=20
02/19/2018 16:45:19;0100;Server@node2;Req;;Type 20 request received from Scheduler@node2.supernodexp.hpc, sock=20
02/19/2018 16:45:19;0100;Server@node2;Req;;Type 51 request received from Scheduler@node2.supernodexp.hpc, sock=20
02/19/2018 16:45:19;0100;Server@node2;Req;;Type 23 request received from Scheduler@node2.supernodexp.hpc, sock=20
02/19/2018 16:45:19;0008;Server@node2;Job;3672.node2.supernodexp.hpc;Job Run at request of Scheduler@node2.supernodexp.hpc on exec_vnode (node14:ncpus=32:nmics=1:mem=16777216kb)
02/19/2018 16:45:19;0001;Server@node2;Svr;Server@node2;Success (0) in req_runjob2, return value of svr_startjob is 0
02/19/2018 16:45:19;0100;Server@node2;Req;;Type 11 request received from Scheduler@node2.supernodexp.hpc, sock=20
02/19/2018 16:45:19;0008;Server@node2;Job;3676.node2.supernodexp.hpc;Job Modified at request of Scheduler@node2.supernodexp.hpc
02/19/2018 16:45:22;0100;Server@node2;Req;;Type 1 request received from ctminh@node2.supernodexp.hpc, sock=16
02/19/2018 16:45:22;0100;Server@node2;Req;;Type 3 request received from ctminh@node2.supernodexp.hpc, sock=16
02/19/2018 16:45:22;0100;Server@node2;Req;;Type 5 request received from ctminh@node2.supernodexp.hpc, sock=16
02/19/2018 16:45:22;0100;Server@node2;Job;3732.node2.supernodexp.hpc;enqueuing into workq, state 1 hop 1
02/19/2018 16:45:22;0008;Server@node2;Job;3732.node2.supernodexp.hpc;Job Queued at request of ctminh@node2.supernodexp.hpc, owner = ctminh@node2.supernodexp.hpc, job name = nbody, queue = workq
02/19/2018 16:45:22;0040;Server@node2;Svr;node2.supernodexp.hpc;Scheduler sent command 1
02/19/2018 16:45:22;0040;Server@node2;Svr;node2.supernodexp.hpc;Scheduler sent command 0
02/19/2018 16:45:22;0100;Server@node2;Req;;Type 21 request received from Scheduler@node2.supernodexp.hpc, sock=20
02/19/2018 16:45:22;0100;Server@node2;Req;;Type 81 request received from Scheduler@node2.supernodexp.hpc, sock=20
02/19/2018 16:45:22;0100;Server@node2;Req;;Type 71 request received from Scheduler@node2.supernodexp.hpc, sock=20
02/19/2018 16:45:22;0100;Server@node2;Req;;Type 58 request received from Scheduler@node2.supernodexp.hpc, sock=20
02/19/2018 16:45:22;0100;Server@node2;Req;;Type 20 request received from Scheduler@node2.supernodexp.hpc, sock=20
02/19/2018 16:45:22;0100;Server@node2;Req;;Type 51 request received from Scheduler@node2.supernodexp.hpc, sock=20
02/19/2018 16:45:22;0100;Server@node2;Req;;Type 11 request received from Scheduler@node2.supernodexp.hpc, sock=20
02/19/2018 16:45:22;0008;Server@node2;Job;3732.node2.supernodexp.hpc;Job Modified at request of Scheduler@node2.supernodexp.hpc
02/19/2018 16:45:29;0100;Server@node2;Req;;Type 1 request received from ctminh@node2.supernodexp.hpc, sock=16
02/19/2018 16:45:29;0100;Server@node2;Req;;Type 3 request received from ctminh@node2.supernodexp.hpc, sock=16
02/19/2018 16:45:29;0100;Server@node2;Req;;Type 5 request received from ctminh@node2.supernodexp.hpc, sock=16
02/19/2018 16:45:29;0100;Server@node2;Job;3733.node2.supernodexp.hpc;enqueuing into workq, state 1 hop 1
02/19/2018 16:45:29;0008;Server@node2;Job;3733.node2.supernodexp.hpc;Job Queued at request of ctminh@node2.supernodexp.hpc, owner = ctminh@node2.supernodexp.hpc, job name = qe_mic_test, queue = workq
02/19/2018 16:45:29;0040;Server@node2;Svr;node2.supernodexp.hpc;Scheduler sent command 1
02/19/2018 16:45:29;0040;Server@node2;Svr;node2.supernodexp.hpc;Scheduler sent command 0
02/19/2018 16:45:29;0100;Server@node2;Req;;Type 21 request received from Scheduler@node2.supernodexp.hpc, sock=20
02/19/2018 16:45:29;0100;Server@node2;Req;;Type 81 request received from Scheduler@node2.supernodexp.hpc, sock=20
02/19/2018 16:45:29;0100;Server@node2;Req;;Type 71 request received from Scheduler@node2.supernodexp.hpc, sock=20
02/19/2018 16:45:29;0100;Server@node2;Req;;Type 58 request received from Scheduler@node2.supernodexp.hpc, sock=20
02/19/2018 16:45:29;0100;Server@node2;Req;;Type 20 request received from Scheduler@node2.supernodexp.hpc, sock=20
02/19/2018 16:45:29;0100;Server@node2;Req;;Type 51 request received from Scheduler@node2.supernodexp.hpc, sock=20
02/19/2018 16:45:29;0100;Server@node2;Req;;Type 11 request received from Scheduler@node2.supernodexp.hpc, sock=20
02/19/2018 16:45:29;0008;Server@node2;Job;3733.node2.supernodexp.hpc;Job Modified at request of Scheduler@node2.supernodexp.hpc
02/19/2018 16:46:31;0100;Server@node2;Req;;Type 0 request received from ctminh@node2.supernodexp.hpc, sock=16
02/19/2018 16:46:31;0100;Server@node2;Req;;Type 49 request received from ctminh@node2.supernodexp.hpc, sock=20
02/19/2018 16:46:31;0100;Server@node2;Req;;Type 21 request received from ctminh@node2.supernodexp.hpc, sock=16
02/19/2018 16:46:31;0100;Server@node2;Req;;Type 1 request received from ctminh@node2.supernodexp.hpc, sock=16
02/19/2018 16:46:31;0100;Server@node2;Req;;Type 3 request received from ctminh@node2.supernodexp.hpc, sock=16
02/19/2018 16:46:31;0100;Server@node2;Req;;Type 5 request received from ctminh@node2.supernodexp.hpc, sock=16
02/19/2018 16:46:31;0100;Server@node2;Job;3734.node2.supernodexp.hpc;enqueuing into workq, state 1 hop 1
02/19/2018 16:46:31;0008;Server@node2;Job;3734.node2.supernodexp.hpc;Job Queued at request of ctminh@node2.supernodexp.hpc, owner = ctminh@node2.supernodexp.hpc, job name = telemac3, queue = workq
02/19/2018 16:46:31;0040;Server@node2;Svr;node2.supernodexp.hpc;Scheduler sent command 1
02/19/2018 16:46:31;0040;Server@node2;Svr;node2.supernodexp.hpc;Scheduler sent command 0
02/19/2018 16:46:31;0100;Server@node2;Req;;Type 21 request received from Scheduler@node2.supernodexp.hpc, sock=20
02/19/2018 16:46:31;0100;Server@node2;Req;;Type 81 request received from Scheduler@node2.supernodexp.hpc, sock=20
02/19/2018 16:46:31;0100;Server@node2;Req;;Type 71 request received from Scheduler@node2.supernodexp.hpc, sock=20
02/19/2018 16:46:31;0100;Server@node2;Req;;Type 58 request received from Scheduler@node2.supernodexp.hpc, sock=20
02/19/2018 16:46:31;0100;Server@node2;Req;;Type 20 request received from Scheduler@node2.supernodexp.hpc, sock=20
02/19/2018 16:46:31;0100;Server@node2;Req;;Type 51 request received from Scheduler@node2.supernodexp.hpc, sock=20
02/19/2018 16:46:31;0100;Server@node2;Req;;Type 11 request received from Scheduler@node2.supernodexp.hpc, sock=20
02/19/2018 16:46:31;0008;Server@node2;Job;3734.node2.supernodexp.hpc;Job Modified at request of Scheduler@node2.supernodexp.hpc
02/19/2018 16:47:16;0100;Server@node2;Req;;Type 1 request received from ctminh@node2.supernodexp.hpc, sock=16
02/19/2018 16:47:16;0100;Server@node2;Req;;Type 3 request received from ctminh@node2.supernodexp.hpc, sock=16
02/19/2018 16:47:16;0100;Server@node2;Req;;Type 5 request received from ctminh@node2.supernodexp.hpc, sock=16
02/19/2018 16:47:16;0100;Server@node2;Job;3735.node2.supernodexp.hpc;enqueuing into workq, state 1 hop 1
02/19/2018 16:47:16;0008;Server@node2;Job;3735.node2.supernodexp.hpc;Job Queued at request of ctminh@node2.supernodexp.hpc, owner = ctminh@node2.supernodexp.hpc, job name = nbody, queue = workq
02/19/2018 16:47:16;0040;Server@node2;Svr;node2.supernodexp.hpc;Scheduler sent command 1
02/19/2018 16:47:16;0040;Server@node2;Svr;node2.supernodexp.hpc;Scheduler sent command 0
02/19/2018 16:47:16;0100;Server@node2;Req;;Type 21 request received from Scheduler@node2.supernodexp.hpc, sock=20
02/19/2018 16:47:16;0100;Server@node2;Req;;Type 81 request received from Scheduler@node2.supernodexp.hpc, sock=20
02/19/2018 16:47:16;0100;Server@node2;Req;;Type 71 request received from Scheduler@node2.supernodexp.hpc, sock=20
02/19/2018 16:47:16;0100;Server@node2;Req;;Type 58 request received from Scheduler@node2.supernodexp.hpc, sock=20
02/19/2018 16:47:16;0100;Server@node2;Req;;Type 20 request received from Scheduler@node2.supernodexp.hpc, sock=20
02/19/2018 16:47:16;0100;Server@node2;Req;;Type 51 request received from Scheduler@node2.supernodexp.hpc, sock=20
02/19/2018 16:47:16;0100;Server@node2;Req;;Type 11 request received from Scheduler@node2.supernodexp.hpc, sock=20
02/19/2018 16:47:16;0008;Server@node2;Job;3735.node2.supernodexp.hpc;Job Modified at request of Scheduler@node2.supernodexp.hpc
02/19/2018 16:47:17;0100;Server@node2;Req;;Type 1 request received from ctminh@node2.supernodexp.hpc, sock=16
02/19/2018 16:47:17;0100;Server@node2;Req;;Type 3 request received from ctminh@node2.supernodexp.hpc, sock=16
02/19/2018 16:47:17;0100;Server@node2;Req;;Type 5 request received from ctminh@node2.supernodexp.hpc, sock=16
02/19/2018 16:47:17;0100;Server@node2;Job;3736.node2.supernodexp.hpc;enqueuing into workq, state 1 hop 1
02/19/2018 16:47:17;0008;Server@node2;Job;3736.node2.supernodexp.hpc;Job Queued at request of ctminh@node2.supernodexp.hpc, owner = ctminh@node2.supernodexp.hpc, job name = telemac3, queue = workq
02/19/2018 16:47:17;0040;Server@node2;Svr;node2.supernodexp.hpc;Scheduler sent command 1
02/19/2018 16:47:17;0040;Server@node2;Svr;node2.supernodexp.hpc;Scheduler sent command 0
02/19/2018 16:47:17;0100;Server@node2;Req;;Type 21 request received from Scheduler@node2.supernodexp.hpc, sock=20
02/19/2018 16:47:17;0100;Server@node2;Req;;Type 81 request received from Scheduler@node2.supernodexp.hpc, sock=20
02/19/2018 16:47:17;0100;Server@node2;Req;;Type 71 request received from Scheduler@node2.supernodexp.hpc, sock=20
02/19/2018 16:47:17;0100;Server@node2;Req;;Type 58 request received from Scheduler@node2.supernodexp.hpc, sock=20
02/19/2018 16:47:17;0100;Server@node2;Req;;Type 1 request received from ctminh@node2.supernodexp.hpc, sock=16
02/19/2018 16:47:17;0100;Server@node2;Req;;Type 3 request received from ctminh@node2.supernodexp.hpc, sock=16
02/19/2018 16:47:17;0100;Server@node2;Req;;Type 5 request received from ctminh@node2.supernodexp.hpc, sock=16
02/19/2018 16:47:17;0100;Server@node2;Job;3737.node2.supernodexp.hpc;enqueuing into workq, state 1 hop 1
02/19/2018 16:47:17;0008;Server@node2;Job;3737.node2.supernodexp.hpc;Job Queued at request of ctminh@node2.supernodexp.hpc, owner = ctminh@node2.supernodexp.hpc, job name = vectorization, queue = workq
02/19/2018 16:47:17;0100;Server@node2;Req;;Type 20 request received from Scheduler@node2.supernodexp.hpc, sock=20
02/19/2018 16:47:17;0100;Server@node2;Req;;Type 51 request received from Scheduler@node2.supernodexp.hpc, sock=20
02/19/2018 16:47:17;0100;Server@node2;Req;;Type 11 request received from Scheduler@node2.supernodexp.hpc, sock=20
02/19/2018 16:47:17;0008;Server@node2;Job;3736.node2.supernodexp.hpc;Job Modified at request of Scheduler@node2.supernodexp.hpc
02/19/2018 16:47:17;0100;Server@node2;Req;;Type 11 request received from Scheduler@node2.supernodexp.hpc, sock=20
02/19/2018 16:47:17;0008;Server@node2;Job;3737.node2.supernodexp.hpc;Job Modified at request of Scheduler@node2.supernodexp.hpc
02/19/2018 16:47:17;0040;Server@node2;Svr;node2.supernodexp.hpc;Scheduler sent command 1
02/19/2018 16:47:17;0040;Server@node2;Svr;node2.supernodexp.hpc;Scheduler sent command 0
02/19/2018 16:47:17;0100;Server@node2;Req;;Type 21 request received from Scheduler@node2.supernodexp.hpc, sock=20
02/19/2018 16:47:17;0100;Server@node2;Req;;Type 81 request received from Scheduler@node2.supernodexp.hpc, sock=20
02/19/2018 16:47:17;0100;Server@node2;Req;;Type 71 request received from Scheduler@node2.supernodexp.hpc, sock=20
02/19/2018 16:47:17;0100;Server@node2;Req;;Type 58 request received from Scheduler@node2.supernodexp.hpc, sock=20
02/19/2018 16:47:17;0100;Server@node2;Req;;Type 20 request received from Scheduler@node2.supernodexp.hpc, sock=20
02/19/2018 16:47:17;0100;Server@node2;Req;;Type 51 request received from Scheduler@node2.supernodexp.hpc, sock=20
02/19/2018 16:47:30;0100;Server@node2;Req;;Type 1 request received from ctminh@node2.supernodexp.hpc, sock=16
02/19/2018 16:47:30;0100;Server@node2;Req;;Type 3 request received from ctminh@node2.supernodexp.hpc, sock=16
02/19/2018 16:47:30;0100;Server@node2;Req;;Type 5 request received from ctminh@node2.supernodexp.hpc, sock=16
02/19/2018 16:47:30;0100;Server@node2;Job;3738.node2.supernodexp.hpc;enqueuing into workq, state 1 hop 1
02/19/2018 16:47:30;0008;Server@node2;Job;3738.node2.supernodexp.hpc;Job Queued at request of ctminh@node2.supernodexp.hpc, owner = ctminh@node2.supernodexp.hpc, job name = thread-affinity, queue = workq
02/19/2018 16:47:30;0040;Server@node2;Svr;node2.supernodexp.hpc;Scheduler sent command 1
02/19/2018 16:47:30;0040;Server@node2;Svr;node2.supernodexp.hpc;Scheduler sent command 0
02/19/2018 16:47:30;0100;Server@node2;Req;;Type 21 request received from Scheduler@node2.supernodexp.hpc, sock=20
02/19/2018 16:47:30;0100;Server@node2;Req;;Type 81 request received from Scheduler@node2.supernodexp.hpc, sock=20
02/19/2018 16:47:30;0100;Server@node2;Req;;Type 71 request received from Scheduler@node2.supernodexp.hpc, sock=20
02/19/2018 16:47:30;0100;Server@node2;Req;;Type 58 request received from Scheduler@node2.supernodexp.hpc, sock=20
02/19/2018 16:47:30;0100;Server@node2;Req;;Type 20 request received from Scheduler@node2.supernodexp.hpc, sock=20
02/19/2018 16:47:30;0100;Server@node2;Req;;Type 51 request received from Scheduler@node2.supernodexp.hpc, sock=20
02/19/2018 16:47:30;0100;Server@node2;Req;;Type 11 request received from Scheduler@node2.supernodexp.hpc, sock=20
02/19/2018 16:47:30;0008;Server@node2;Job;3738.node2.supernodexp.hpc;Job Modified at request of Scheduler@node2.supernodexp.hpc
02/19/2018 16:47:46;0100;Server@node2;Req;;Type 1 request received from ctminh@node2.supernodexp.hpc, sock=16
02/19/2018 16:47:47;0100;Server@node2;Req;;Type 3 request received from ctminh@node2.supernodexp.hpc, sock=16
02/19/2018 16:47:47;0100;Server@node2;Req;;Type 5 request received from ctminh@node2.supernodexp.hpc, sock=16
02/19/2018 16:47:47;0100;Server@node2;Job;3739.node2.supernodexp.hpc;enqueuing into workq, state 1 hop 1
02/19/2018 16:47:47;0008;Server@node2;Job;3739.node2.supernodexp.hpc;Job Queued at request of ctminh@node2.supernodexp.hpc, owner = ctminh@node2.supernodexp.hpc, job name = telemac1, queue = workq
02/19/2018 16:47:47;0040;Server@node2;Svr;node2.supernodexp.hpc;Scheduler sent command 1
02/19/2018 16:47:47;0040;Server@node2;Svr;node2.supernodexp.hpc;Scheduler sent command 0
02/19/2018 16:47:47;0100;Server@node2;Req;;Type 21 request received from Scheduler@node2.supernodexp.hpc, sock=20
02/19/2018 16:47:47;0100;Server@node2;Req;;Type 81 request received from Scheduler@node2.supernodexp.hpc, sock=20
02/19/2018 16:47:47;0100;Server@node2;Req;;Type 71 request received from Scheduler@node2.supernodexp.hpc, sock=20
02/19/2018 16:47:47;0100;Server@node2;Req;;Type 58 request received from Scheduler@node2.supernodexp.hpc, sock=20
02/19/2018 16:47:47;0100;Server@node2;Req;;Type 20 request received from Scheduler@node2.supernodexp.hpc, sock=20
02/19/2018 16:47:47;0100;Server@node2;Req;;Type 51 request received from Scheduler@node2.supernodexp.hpc, sock=20
02/19/2018 16:47:47;0100;Server@node2;Req;;Type 11 request received from Scheduler@node2.supernodexp.hpc, sock=20
02/19/2018 16:47:47;0008;Server@node2;Job;3739.node2.supernodexp.hpc;Job Modified at request of Scheduler@node2.supernodexp.hpc
02/19/2018 16:47:59;0100;Server@node2;Req;;Type 1 request received from ctminh@node2.supernodexp.hpc, sock=16
02/19/2018 16:47:59;0100;Server@node2;Req;;Type 3 request received from ctminh@node2.supernodexp.hpc, sock=16
02/19/2018 16:47:59;0100;Server@node2;Req;;Type 5 request received from ctminh@node2.supernodexp.hpc, sock=16
02/19/2018 16:47:59;0100;Server@node2;Job;3740.node2.supernodexp.hpc;enqueuing into workq, state 1 hop 1
02/19/2018 16:47:59;0008;Server@node2;Job;3740.node2.supernodexp.hpc;Job Queued at request of ctminh@node2.supernodexp.hpc, owner = ctminh@node2.supernodexp.hpc, job name = lu-decomp, queue = workq
02/19/2018 16:47:59;0040;Server@node2;Svr;node2.supernodexp.hpc;Scheduler sent command 1
02/19/2018 16:47:59;0040;Server@node2;Svr;node2.supernodexp.hpc;Scheduler sent command 0
02/19/2018 16:47:59;0100;Server@node2;Req;;Type 21 request received from Scheduler@node2.supernodexp.hpc, sock=20
02/19/2018 16:47:59;0100;Server@node2;Req;;Type 81 request received from Scheduler@node2.supernodexp.hpc, sock=20
02/19/2018 16:47:59;0100;Server@node2;Req;;Type 71 request received from Scheduler@node2.supernodexp.hpc, sock=20
02/19/2018 16:47:59;0100;Server@node2;Req;;Type 58 request received from Scheduler@node2.supernodexp.hpc, sock=20
02/19/2018 16:47:59;0100;Server@node2;Req;;Type 20 request received from Scheduler@node2.supernodexp.hpc, sock=20
02/19/2018 16:47:59;0100;Server@node2;Req;;Type 51 request received from Scheduler@node2.supernodexp.hpc, sock=20
02/19/2018 16:47:59;0100;Server@node2;Req;;Type 11 request received from Scheduler@node2.supernodexp.hpc, sock=20
02/19/2018 16:47:59;0008;Server@node2;Job;3740.node2.supernodexp.hpc;Job Modified at request of Scheduler@node2.supernodexp.hpc
02/19/2018 16:48:47;0100;Server@node2;Req;;Type 1 request received from ctminh@node2.supernodexp.hpc, sock=16
02/19/2018 16:48:47;0100;Server@node2;Req;;Type 3 request received from ctminh@node2.supernodexp.hpc, sock=16
02/19/2018 16:48:47;0100;Server@node2;Req;;Type 5 request received from ctminh@node2.supernodexp.hpc, sock=16
02/19/2018 16:48:47;0100;Server@node2;Job;3741.node2.supernodexp.hpc;enqueuing into workq, state 1 hop 1
02/19/2018 16:48:47;0008;Server@node2;Job;3741.node2.supernodexp.hpc;Job Queued at request of ctminh@node2.supernodexp.hpc, owner = ctminh@node2.supernodexp.hpc, job name = histogram, queue = workq
02/19/2018 16:48:47;0040;Server@node2;Svr;node2.supernodexp.hpc;Scheduler sent command 1
02/19/2018 16:48:47;0040;Server@node2;Svr;node2.supernodexp.hpc;Scheduler sent command 0
02/19/2018 16:48:47;0100;Server@node2;Req;;Type 21 request received from Scheduler@node2.supernodexp.hpc, sock=20
02/19/2018 16:48:47;0100;Server@node2;Req;;Type 81 request received from Scheduler@node2.supernodexp.hpc, sock=20
02/19/2018 16:48:47;0100;Server@node2;Req;;Type 71 request received from Scheduler@node2.supernodexp.hpc, sock=20
02/19/2018 16:48:47;0100;Server@node2;Req;;Type 58 request received from Scheduler@node2.supernodexp.hpc, sock=20
02/19/2018 16:48:47;0100;Server@node2;Req;;Type 20 request received from Scheduler@node2.supernodexp.hpc, sock=20
02/19/2018 16:48:47;0100;Server@node2;Req;;Type 51 request received from Scheduler@node2.supernodexp.hpc, sock=20
02/19/2018 16:48:47;0100;Server@node2;Req;;Type 11 request received from Scheduler@node2.supernodexp.hpc, sock=20
02/19/2018 16:48:47;0008;Server@node2;Job;3741.node2.supernodexp.hpc;Job Modified at request of Scheduler@node2.supernodexp.hpc
02/19/2018 16:48:48;0100;Server@node2;Req;;Type 1 request received from ctminh@node2.supernodexp.hpc, sock=16
02/19/2018 16:48:48;0100;Server@node2;Req;;Type 3 request received from ctminh@node2.supernodexp.hpc, sock=16
02/19/2018 16:48:48;0100;Server@node2;Req;;Type 5 request received from ctminh@node2.supernodexp.hpc, sock=16
02/19/2018 16:48:48;0100;Server@node2;Job;3742.node2.supernodexp.hpc;enqueuing into workq, state 1 hop 1
02/19/2018 16:48:48;0008;Server@node2;Job;3742.node2.supernodexp.hpc;Job Queued at request of ctminh@node2.supernodexp.hpc, owner = ctminh@node2.supernodexp.hpc, job name = telemac2, queue = workq
02/19/2018 16:48:48;0040;Server@node2;Svr;node2.supernodexp.hpc;Scheduler sent command 1
02/19/2018 16:48:48;0040;Server@node2;Svr;node2.supernodexp.hpc;Scheduler sent command 0
02/19/2018 16:48:48;0100;Server@node2;Req;;Type 21 request received from Scheduler@node2.supernodexp.hpc, sock=20
02/19/2018 16:48:48;0100;Server@node2;Req;;Type 81 request received from Scheduler@node2.supernodexp.hpc, sock=20
02/19/2018 16:48:48;0100;Server@node2;Req;;Type 71 request received from Scheduler@node2.supernodexp.hpc, sock=20
02/19/2018 16:48:48;0100;Server@node2;Req;;Type 58 request received from Scheduler@node2.supernodexp.hpc, sock=20
02/19/2018 16:48:48;0100;Server@node2;Req;;Type 20 request received from Scheduler@node2.supernodexp.hpc, sock=20
02/19/2018 16:48:48;0100;Server@node2;Req;;Type 51 request received from Scheduler@node2.supernodexp.hpc, sock=20
02/19/2018 16:48:48;0100;Server@node2;Req;;Type 11 request received from Scheduler@node2.supernodexp.hpc, sock=20
02/19/2018 16:48:48;0008;Server@node2;Job;3742.node2.supernodexp.hpc;Job Modified at request of Scheduler@node2.supernodexp.hpc
02/19/2018 16:48:57;0100;Server@node2;Req;;Type 1 request received from ctminh@node2.supernodexp.hpc, sock=16
02/19/2018 16:48:57;0100;Server@node2;Req;;Type 3 request received from ctminh@node2.supernodexp.hpc, sock=16
02/19/2018 16:48:57;0100;Server@node2;Req;;Type 5 request received from ctminh@node2.supernodexp.hpc, sock=16
02/19/2018 16:48:57;0100;Server@node2;Job;3743.node2.supernodexp.hpc;enqueuing into workq, state 1 hop 1
02/19/2018 16:48:57;0008;Server@node2;Job;3743.node2.supernodexp.hpc;Job Queued at request of ctminh@node2.supernodexp.hpc, owner = ctminh@node2.supernodexp.hpc, job name = telemac2, queue = workq
02/19/2018 16:48:57;0040;Server@node2;Svr;node2.supernodexp.hpc;Scheduler sent command 1
02/19/2018 16:48:57;0040;Server@node2;Svr;node2.supernodexp.hpc;Scheduler sent command 0
02/19/2018 16:48:57;0100;Server@node2;Req;;Type 21 request received from Scheduler@node2.supernodexp.hpc, sock=20
02/19/2018 16:48:57;0100;Server@node2;Req;;Type 81 request received from Scheduler@node2.supernodexp.hpc, sock=20
02/19/2018 16:48:57;0100;Server@node2;Req;;Type 71 request received from Scheduler@node2.supernodexp.hpc, sock=20
02/19/2018 16:48:57;0100;Server@node2;Req;;Type 58 request received from Scheduler@node2.supernodexp.hpc, sock=20
02/19/2018 16:48:57;0100;Server@node2;Req;;Type 1 request received from ctminh@node2.supernodexp.hpc, sock=16
02/19/2018 16:48:57;0100;Server@node2;Req;;Type 3 request received from ctminh@node2.supernodexp.hpc, sock=16
02/19/2018 16:48:57;0100;Server@node2;Req;;Type 5 request received from ctminh@node2.supernodexp.hpc, sock=16
02/19/2018 16:48:57;0100;Server@node2;Job;3744.node2.supernodexp.hpc;enqueuing into workq, state 1 hop 1
02/19/2018 16:48:57;0008;Server@node2;Job;3744.node2.supernodexp.hpc;Job Queued at request of ctminh@node2.supernodexp.hpc, owner = ctminh@node2.supernodexp.hpc, job name = lu-decomp, queue = workq
02/19/2018 16:48:57;0100;Server@node2;Req;;Type 20 request received from Scheduler@node2.supernodexp.hpc, sock=20
02/19/2018 16:48:57;0100;Server@node2;Req;;Type 51 request received from Scheduler@node2.supernodexp.hpc, sock=20
02/19/2018 16:48:57;0100;Server@node2;Req;;Type 11 request received from Scheduler@node2.supernodexp.hpc, sock=20
02/19/2018 16:48:57;0008;Server@node2;Job;3743.node2.supernodexp.hpc;Job Modified at request of Scheduler@node2.supernodexp.hpc
02/19/2018 16:48:57;0100;Server@node2;Req;;Type 11 request received from Scheduler@node2.supernodexp.hpc, sock=20
02/19/2018 16:48:57;0008;Server@node2;Job;3744.node2.supernodexp.hpc;Job Modified at request of Scheduler@node2.supernodexp.hpc
02/19/2018 16:48:57;0040;Server@node2;Svr;node2.supernodexp.hpc;Scheduler sent command 1
02/19/2018 16:48:57;0040;Server@node2;Svr;node2.supernodexp.hpc;Scheduler sent command 0
02/19/2018 16:48:57;0100;Server@node2;Req;;Type 21 request received from Scheduler@node2.supernodexp.hpc, sock=20
02/19/2018 16:48:57;0100;Server@node2;Req;;Type 81 request received from Scheduler@node2.supernodexp.hpc, sock=20
02/19/2018 16:48:57;0100;Server@node2;Req;;Type 71 request received from Scheduler@node2.supernodexp.hpc, sock=20
02/19/2018 16:48:57;0100;Server@node2;Req;;Type 58 request received from Scheduler@node2.supernodexp.hpc, sock=20
02/19/2018 16:48:57;0100;Server@node2;Req;;Type 20 request received from Scheduler@node2.supernodexp.hpc, sock=20
02/19/2018 16:48:57;0100;Server@node2;Req;;Type 51 request received from Scheduler@node2.supernodexp.hpc, sock=20
02/19/2018 16:49:24;0100;Server@node2;Req;;Type 1 request received from ctminh@node2.supernodexp.hpc, sock=16
02/19/2018 16:49:24;0100;Server@node2;Req;;Type 3 request received from ctminh@node2.supernodexp.hpc, sock=16
02/19/2018 16:49:24;0100;Server@node2;Req;;Type 5 request received from ctminh@node2.supernodexp.hpc, sock=16
02/19/2018 16:49:24;0100;Server@node2;Job;3745.node2.supernodexp.hpc;enqueuing into workq, state 1 hop 1
02/19/2018 16:49:24;0008;Server@node2;Job;3745.node2.supernodexp.hpc;Job Queued at request of ctminh@node2.supernodexp.hpc, owner = ctminh@node2.supernodexp.hpc, job name = sweep, queue = workq
02/19/2018 16:49:24;0040;Server@node2;Svr;node2.supernodexp.hpc;Scheduler sent command 1
02/19/2018 16:49:24;0040;Server@node2;Svr;node2.supernodexp.hpc;Scheduler sent command 0
02/19/2018 16:49:24;0100;Server@node2;Req;;Type 21 request received from Scheduler@node2.supernodexp.hpc, sock=20
02/19/2018 16:49:24;0100;Server@node2;Req;;Type 81 request received from Scheduler@node2.supernodexp.hpc, sock=20
02/19/2018 16:49:24;0100;Server@node2;Req;;Type 71 request received from Scheduler@node2.supernodexp.hpc, sock=20
02/19/2018 16:49:24;0100;Server@node2;Req;;Type 58 request received from Scheduler@node2.supernodexp.hpc, sock=20
02/19/2018 16:49:24;0100;Server@node2;Req;;Type 1 request received from ctminh@node2.supernodexp.hpc, sock=16
02/19/2018 16:49:24;0100;Server@node2;Req;;Type 3 request received from ctminh@node2.supernodexp.hpc, sock=16
02/19/2018 16:49:24;0100;Server@node2;Req;;Type 5 request received from ctminh@node2.supernodexp.hpc, sock=16
02/19/2018 16:49:24;0100;Server@node2;Job;3746.node2.supernodexp.hpc;enqueuing into workq, state 1 hop 1
02/19/2018 16:49:24;0008;Server@node2;Job;3746.node2.supernodexp.hpc;Job Queued at request of ctminh@node2.supernodexp.hpc, owner = ctminh@node2.supernodexp.hpc, job name = vectorization, queue = workq
02/19/2018 16:49:24;0100;Server@node2;Req;;Type 20 request received from Scheduler@node2.supernodexp.hpc, sock=20
02/19/2018 16:49:24;0100;Server@node2;Req;;Type 51 request received from Scheduler@node2.supernodexp.hpc, sock=20
02/19/2018 16:49:24;0100;Server@node2;Req;;Type 11 request received from Scheduler@node2.supernodexp.hpc, sock=20
02/19/2018 16:49:24;0008;Server@node2;Job;3745.node2.supernodexp.hpc;Job Modified at request of Scheduler@node2.supernodexp.hpc
02/19/2018 16:49:24;0100;Server@node2;Req;;Type 11 request received from Scheduler@node2.supernodexp.hpc, sock=20
02/19/2018 16:49:24;0008;Server@node2;Job;3746.node2.supernodexp.hpc;Job Modified at request of Scheduler@node2.supernodexp.hpc
02/19/2018 16:49:24;0040;Server@node2;Svr;node2.supernodexp.hpc;Scheduler sent command 1
02/19/2018 16:49:24;0040;Server@node2;Svr;node2.supernodexp.hpc;Scheduler sent command 0
02/19/2018 16:49:24;0100;Server@node2;Req;;Type 21 request received from Scheduler@node2.supernodexp.hpc, sock=20
02/19/2018 16:49:24;0100;Server@node2;Req;;Type 81 request received from Scheduler@node2.supernodexp.hpc, sock=20
02/19/2018 16:49:24;0100;Server@node2;Req;;Type 71 request received from Scheduler@node2.supernodexp.hpc, sock=20
02/19/2018 16:49:24;0100;Server@node2;Req;;Type 58 request received from Scheduler@node2.supernodexp.hpc, sock=20
02/19/2018 16:49:24;0100;Server@node2;Req;;Type 20 request received from Scheduler@node2.supernodexp.hpc, sock=20
02/19/2018 16:49:24;0100;Server@node2;Req;;Type 51 request received from Scheduler@node2.supernodexp.hpc, sock=20
02/19/2018 16:49:28;0100;Server@node2;Req;;Type 1 request received from ctminh@node2.supernodexp.hpc, sock=16
02/19/2018 16:49:28;0100;Server@node2;Req;;Type 3 request received from ctminh@node2.supernodexp.hpc, sock=16
02/19/2018 16:49:28;0100;Server@node2;Req;;Type 5 request received from ctminh@node2.supernodexp.hpc, sock=16
02/19/2018 16:49:28;0100;Server@node2;Job;3747.node2.supernodexp.hpc;enqueuing into workq, state 1 hop 1
02/19/2018 16:49:28;0008;Server@node2;Job;3747.node2.supernodexp.hpc;Job Queued at request of ctminh@node2.supernodexp.hpc, owner = ctminh@node2.supernodexp.hpc, job name = vast1, queue = workq
02/19/2018 16:49:28;0040;Server@node2;Svr;node2.supernodexp.hpc;Scheduler sent command 1
02/19/2018 16:49:28;0040;Server@node2;Svr;node2.supernodexp.hpc;Scheduler sent command 0
02/19/2018 16:49:28;0100;Server@node2;Req;;Type 21 request received from Scheduler@node2.supernodexp.hpc, sock=20
02/19/2018 16:49:28;0100;Server@node2;Req;;Type 81 request received from Scheduler@node2.supernodexp.hpc, sock=20
02/19/2018 16:49:28;0100;Server@node2;Req;;Type 71 request received from Scheduler@node2.supernodexp.hpc, sock=20
02/19/2018 16:49:28;0100;Server@node2;Req;;Type 58 request received from Scheduler@node2.supernodexp.hpc, sock=20
02/19/2018 16:49:28;0100;Server@node2;Req;;Type 20 request received from Scheduler@node2.supernodexp.hpc, sock=20
02/19/2018 16:49:28;0100;Server@node2;Req;;Type 51 request received from Scheduler@node2.supernodexp.hpc, sock=20
02/19/2018 16:49:28;0100;Server@node2;Req;;Type 11 request received from Scheduler@node2.supernodexp.hpc, sock=20
02/19/2018 16:49:28;0008;Server@node2;Job;3747.node2.supernodexp.hpc;Job Modified at request of Scheduler@node2.supernodexp.hpc
02/19/2018 16:49:29;0100;Server@node2;Req;;Type 1 request received from ctminh@node2.supernodexp.hpc, sock=16
02/19/2018 16:49:29;0100;Server@node2;Req;;Type 3 request received from ctminh@node2.supernodexp.hpc, sock=16
02/19/2018 16:49:29;0100;Server@node2;Req;;Type 5 request received from ctminh@node2.supernodexp.hpc, sock=16
02/19/2018 16:49:29;0100;Server@node2;Job;3748.node2.supernodexp.hpc;enqueuing into workq, state 1 hop 1
02/19/2018 16:49:29;0008;Server@node2;Job;3748.node2.supernodexp.hpc;Job Queued at request of ctminh@node2.supernodexp.hpc, owner = ctminh@node2.supernodexp.hpc, job name = histogram, queue = workq
02/19/2018 16:49:29;0040;Server@node2;Svr;node2.supernodexp.hpc;Scheduler sent command 1
02/19/2018 16:49:29;0040;Server@node2;Svr;node2.supernodexp.hpc;Scheduler sent command 0
02/19/2018 16:49:29;0100;Server@node2;Req;;Type 21 request received from Scheduler@node2.supernodexp.hpc, sock=20
02/19/2018 16:49:29;0100;Server@node2;Req;;Type 81 request received from Scheduler@node2.supernodexp.hpc, sock=20
02/19/2018 16:49:29;0100;Server@node2;Req;;Type 71 request received from Scheduler@node2.supernodexp.hpc, sock=20
02/19/2018 16:49:29;0100;Server@node2;Req;;Type 58 request received from Scheduler@node2.supernodexp.hpc, sock=20
02/19/2018 16:49:29;0100;Server@node2;Req;;Type 20 request received from Scheduler@node2.supernodexp.hpc, sock=20
02/19/2018 16:49:29;0100;Server@node2;Req;;Type 51 request received from Scheduler@node2.supernodexp.hpc, sock=20
02/19/2018 16:49:29;0100;Server@node2;Req;;Type 11 request received from Scheduler@node2.supernodexp.hpc, sock=20
02/19/2018 16:49:29;0008;Server@node2;Job;3748.node2.supernodexp.hpc;Job Modified at request of Scheduler@node2.supernodexp.hpc
02/19/2018 16:49:30;0100;Server@node2;Req;;Type 1 request received from ctminh@node2.supernodexp.hpc, sock=16
02/19/2018 16:49:30;0100;Server@node2;Req;;Type 3 request received from ctminh@node2.supernodexp.hpc, sock=16
02/19/2018 16:49:30;0100;Server@node2;Req;;Type 5 request received from ctminh@node2.supernodexp.hpc, sock=16
02/19/2018 16:49:30;0100;Server@node2;Job;3749.node2.supernodexp.hpc;enqueuing into workq, state 1 hop 1
02/19/2018 16:49:30;0008;Server@node2;Job;3749.node2.supernodexp.hpc;Job Queued at request of ctminh@node2.supernodexp.hpc, owner = ctminh@node2.supernodexp.hpc, job name = vast1, queue = workq
02/19/2018 16:49:30;0040;Server@node2;Svr;node2.supernodexp.hpc;Scheduler sent command 1
02/19/2018 16:49:30;0040;Server@node2;Svr;node2.supernodexp.hpc;Scheduler sent command 0
02/19/2018 16:49:30;0100;Server@node2;Req;;Type 21 request received from Scheduler@node2.supernodexp.hpc, sock=20
02/19/2018 16:49:30;0100;Server@node2;Req;;Type 81 request received from Scheduler@node2.supernodexp.hpc, sock=20
02/19/2018 16:49:30;0100;Server@node2;Req;;Type 71 request received from Scheduler@node2.supernodexp.hpc, sock=20
02/19/2018 16:49:30;0100;Server@node2;Req;;Type 58 request received from Scheduler@node2.supernodexp.hpc, sock=20
02/19/2018 16:49:30;0100;Server@node2;Req;;Type 20 request received from Scheduler@node2.supernodexp.hpc, sock=20
02/19/2018 16:49:30;0100;Server@node2;Req;;Type 51 request received from Scheduler@node2.supernodexp.hpc, sock=20
02/19/2018 16:49:30;0100;Server@node2;Req;;Type 11 request received from Scheduler@node2.supernodexp.hpc, sock=20
02/19/2018 16:49:30;0008;Server@node2;Job;3749.node2.supernodexp.hpc;Job Modified at request of Scheduler@node2.supernodexp.hpc
02/19/2018 16:50:00;0100;Server@node2;Req;;Type 1 request received from ctminh@node2.supernodexp.hpc, sock=16
02/19/2018 16:50:00;0100;Server@node2;Req;;Type 3 request received from ctminh@node2.supernodexp.hpc, sock=16
02/19/2018 16:50:00;0100;Server@node2;Req;;Type 5 request received from ctminh@node2.supernodexp.hpc, sock=16
02/19/2018 16:50:00;0100;Server@node2;Job;3750.node2.supernodexp.hpc;enqueuing into workq, state 1 hop 1
02/19/2018 16:50:00;0008;Server@node2;Job;3750.node2.supernodexp.hpc;Job Queued at request of ctminh@node2.supernodexp.hpc, owner = ctminh@node2.supernodexp.hpc, job name = telemac2, queue = workq
02/19/2018 16:50:00;0040;Server@node2;Svr;node2.supernodexp.hpc;Scheduler sent command 1
02/19/2018 16:50:00;0040;Server@node2;Svr;node2.supernodexp.hpc;Scheduler sent command 0
02/19/2018 16:50:00;0100;Server@node2;Req;;Type 21 request received from Scheduler@node2.supernodexp.hpc, sock=20
02/19/2018 16:50:00;0100;Server@node2;Req;;Type 81 request received from Scheduler@node2.supernodexp.hpc, sock=20
02/19/2018 16:50:00;0100;Server@node2;Req;;Type 71 request received from Scheduler@node2.supernodexp.hpc, sock=20
02/19/2018 16:50:00;0100;Server@node2;Req;;Type 58 request received from Scheduler@node2.supernodexp.hpc, sock=20
02/19/2018 16:50:00;0100;Server@node2;Req;;Type 20 request received from Scheduler@node2.supernodexp.hpc, sock=20
02/19/2018 16:50:00;0100;Server@node2;Req;;Type 51 request received from Scheduler@node2.supernodexp.hpc, sock=20
02/19/2018 16:50:00;0100;Server@node2;Req;;Type 11 request received from Scheduler@node2.supernodexp.hpc, sock=20
02/19/2018 16:50:00;0008;Server@node2;Job;3750.node2.supernodexp.hpc;Job Modified at request of Scheduler@node2.supernodexp.hpc
02/19/2018 16:50:07;0100;Server@node2;Req;;Type 1 request received from ctminh@node2.supernodexp.hpc, sock=16
02/19/2018 16:50:07;0100;Server@node2;Req;;Type 3 request received from ctminh@node2.supernodexp.hpc, sock=16
02/19/2018 16:50:07;0100;Server@node2;Req;;Type 5 request received from ctminh@node2.supernodexp.hpc, sock=16
02/19/2018 16:50:07;0100;Server@node2;Job;3751.node2.supernodexp.hpc;enqueuing into workq, state 1 hop 1
02/19/2018 16:50:07;0008;Server@node2;Job;3751.node2.supernodexp.hpc;Job Queued at request of ctminh@node2.supernodexp.hpc, owner = ctminh@node2.supernodexp.hpc, job name = telemac1, queue = workq
02/19/2018 16:50:07;0040;Server@node2;Svr;node2.supernodexp.hpc;Scheduler sent command 1
02/19/2018 16:50:07;0040;Server@node2;Svr;node2.supernodexp.hpc;Scheduler sent command 0
02/19/2018 16:50:07;0100;Server@node2;Req;;Type 21 request received from Scheduler@node2.supernodexp.hpc, sock=20
02/19/2018 16:50:07;0100;Server@node2;Req;;Type 81 request received from Scheduler@node2.supernodexp.hpc, sock=20
02/19/2018 16:50:07;0100;Server@node2;Req;;Type 71 request received from Scheduler@node2.supernodexp.hpc, sock=20
02/19/2018 16:50:07;0100;Server@node2;Req;;Type 58 request received from Scheduler@node2.supernodexp.hpc, sock=20
02/19/2018 16:50:07;0100;Server@node2;Req;;Type 20 request received from Scheduler@node2.supernodexp.hpc, sock=20
02/19/2018 16:50:07;0100;Server@node2;Req;;Type 51 request received from Scheduler@node2.supernodexp.hpc, sock=20
02/19/2018 16:50:07;0100;Server@node2;Req;;Type 11 request received from Scheduler@node2.supernodexp.hpc, sock=20
02/19/2018 16:50:07;0008;Server@node2;Job;3751.node2.supernodexp.hpc;Job Modified at request of Scheduler@node2.supernodexp.hpc
02/19/2018 16:50:22;0100;Server@node2;Req;;Type 1 request received from ctminh@node2.supernodexp.hpc, sock=16
02/19/2018 16:50:22;0100;Server@node2;Req;;Type 3 request received from ctminh@node2.supernodexp.hpc, sock=16
02/19/2018 16:50:22;0100;Server@node2;Req;;Type 5 request received from ctminh@node2.supernodexp.hpc, sock=16
02/19/2018 16:50:22;0100;Server@node2;Job;3752.node2.supernodexp.hpc;enqueuing into workq, state 1 hop 1
02/19/2018 16:50:22;0008;Server@node2;Job;3752.node2.supernodexp.hpc;Job Queued at request of ctminh@node2.supernodexp.hpc, owner = ctminh@node2.supernodexp.hpc, job name = sweep, queue = workq
02/19/2018 16:50:22;0040;Server@node2;Svr;node2.supernodexp.hpc;Scheduler sent command 1
02/19/2018 16:50:22;0040;Server@node2;Svr;node2.supernodexp.hpc;Scheduler sent command 0
02/19/2018 16:50:22;0100;Server@node2;Req;;Type 21 request received from Scheduler@node2.supernodexp.hpc, sock=20
02/19/2018 16:50:22;0100;Server@node2;Req;;Type 81 request received from Scheduler@node2.supernodexp.hpc, sock=20
02/19/2018 16:50:22;0100;Server@node2;Req;;Type 71 request received from Scheduler@node2.supernodexp.hpc, sock=20
02/19/2018 16:50:22;0100;Server@node2;Req;;Type 58 request received from Scheduler@node2.supernodexp.hpc, sock=20
02/19/2018 16:50:22;0100;Server@node2;Req;;Type 20 request received from Scheduler@node2.supernodexp.hpc, sock=20
02/19/2018 16:50:22;0100;Server@node2;Req;;Type 51 request received from Scheduler@node2.supernodexp.hpc, sock=20
02/19/2018 16:50:22;0100;Server@node2;Req;;Type 11 request received from Scheduler@node2.supernodexp.hpc, sock=20
02/19/2018 16:50:22;0008;Server@node2;Job;3752.node2.supernodexp.hpc;Job Modified at request of Scheduler@node2.supernodexp.hpc
02/19/2018 16:50:25;0100;Server@node2;Req;;Type 1 request received from ctminh@node2.supernodexp.hpc, sock=16
02/19/2018 16:50:25;0100;Server@node2;Req;;Type 3 request received from ctminh@node2.supernodexp.hpc, sock=16
02/19/2018 16:50:25;0100;Server@node2;Req;;Type 5 request received from ctminh@node2.supernodexp.hpc, sock=16
02/19/2018 16:50:25;0100;Server@node2;Job;3753.node2.supernodexp.hpc;enqueuing into workq, state 1 hop 1
02/19/2018 16:50:25;0008;Server@node2;Job;3753.node2.supernodexp.hpc;Job Queued at request of ctminh@node2.supernodexp.hpc, owner = ctminh@node2.supernodexp.hpc, job name = histogram, queue = workq
02/19/2018 16:50:25;0040;Server@node2;Svr;node2.supernodexp.hpc;Scheduler sent command 1
02/19/2018 16:50:25;0040;Server@node2;Svr;node2.supernodexp.hpc;Scheduler sent command 0
02/19/2018 16:50:25;0100;Server@node2;Req;;Type 21 request received from Scheduler@node2.supernodexp.hpc, sock=20
02/19/2018 16:50:25;0100;Server@node2;Req;;Type 81 request received from Scheduler@node2.supernodexp.hpc, sock=20
02/19/2018 16:50:25;0100;Server@node2;Req;;Type 71 request received from Scheduler@node2.supernodexp.hpc, sock=20
02/19/2018 16:50:25;0100;Server@node2;Req;;Type 58 request received from Scheduler@node2.supernodexp.hpc, sock=20
02/19/2018 16:50:25;0100;Server@node2;Req;;Type 20 request received from Scheduler@node2.supernodexp.hpc, sock=20
02/19/2018 16:50:25;0100;Server@node2;Req;;Type 51 request received from Scheduler@node2.supernodexp.hpc, sock=20
02/19/2018 16:50:25;0100;Server@node2;Req;;Type 11 request received from Scheduler@node2.supernodexp.hpc, sock=20
02/19/2018 16:50:25;0008;Server@node2;Job;3753.node2.supernodexp.hpc;Job Modified at request of Scheduler@node2.supernodexp.hpc
02/19/2018 16:50:28;0100;Server@node2;Req;;Type 1 request received from ctminh@node2.supernodexp.hpc, sock=16
02/19/2018 16:50:28;0100;Server@node2;Req;;Type 3 request received from ctminh@node2.supernodexp.hpc, sock=16
02/19/2018 16:50:28;0100;Server@node2;Req;;Type 5 request received from ctminh@node2.supernodexp.hpc, sock=16
02/19/2018 16:50:28;0100;Server@node2;Job;3754.node2.supernodexp.hpc;enqueuing into workq, state 1 hop 1
02/19/2018 16:50:28;0008;Server@node2;Job;3754.node2.supernodexp.hpc;Job Queued at request of ctminh@node2.supernodexp.hpc, owner = ctminh@node2.supernodexp.hpc, job name = telemac3, queue = workq
02/19/2018 16:50:28;0040;Server@node2;Svr;node2.supernodexp.hpc;Scheduler sent command 1
02/19/2018 16:50:28;0040;Server@node2;Svr;node2.supernodexp.hpc;Scheduler sent command 0
02/19/2018 16:50:28;0100;Server@node2;Req;;Type 21 request received from Scheduler@node2.supernodexp.hpc, sock=20
02/19/2018 16:50:28;0100;Server@node2;Req;;Type 81 request received from Scheduler@node2.supernodexp.hpc, sock=20
02/19/2018 16:50:28;0100;Server@node2;Req;;Type 71 request received from Scheduler@node2.supernodexp.hpc, sock=20
02/19/2018 16:50:28;0100;Server@node2;Req;;Type 58 request received from Scheduler@node2.supernodexp.hpc, sock=20
02/19/2018 16:50:28;0100;Server@node2;Req;;Type 20 request received from Scheduler@node2.supernodexp.hpc, sock=20
02/19/2018 16:50:28;0100;Server@node2;Req;;Type 51 request received from Scheduler@node2.supernodexp.hpc, sock=20
02/19/2018 16:50:28;0100;Server@node2;Req;;Type 11 request received from Scheduler@node2.supernodexp.hpc, sock=20
02/19/2018 16:50:28;0008;Server@node2;Job;3754.node2.supernodexp.hpc;Job Modified at request of Scheduler@node2.supernodexp.hpc
02/19/2018 16:50:35;0100;Server@node2;Req;;Type 1 request received from ctminh@node2.supernodexp.hpc, sock=16
02/19/2018 16:50:35;0100;Server@node2;Req;;Type 3 request received from ctminh@node2.supernodexp.hpc, sock=16
02/19/2018 16:50:35;0100;Server@node2;Req;;Type 5 request received from ctminh@node2.supernodexp.hpc, sock=16
02/19/2018 16:50:35;0100;Server@node2;Job;3755.node2.supernodexp.hpc;enqueuing into workq, state 1 hop 1
02/19/2018 16:50:35;0008;Server@node2;Job;3755.node2.supernodexp.hpc;Job Queued at request of ctminh@node2.supernodexp.hpc, owner = ctminh@node2.supernodexp.hpc, job name = lu-decomp, queue = workq
02/19/2018 16:50:35;0040;Server@node2;Svr;node2.supernodexp.hpc;Scheduler sent command 1
02/19/2018 16:50:35;0040;Server@node2;Svr;node2.supernodexp.hpc;Scheduler sent command 0
02/19/2018 16:50:35;0100;Server@node2;Req;;Type 21 request received from Scheduler@node2.supernodexp.hpc, sock=20
02/19/2018 16:50:35;0100;Server@node2;Req;;Type 81 request received from Scheduler@node2.supernodexp.hpc, sock=20
02/19/2018 16:50:35;0100;Server@node2;Req;;Type 71 request received from Scheduler@node2.supernodexp.hpc, sock=20
02/19/2018 16:50:35;0100;Server@node2;Req;;Type 58 request received from Scheduler@node2.supernodexp.hpc, sock=20
02/19/2018 16:50:35;0100;Server@node2;Req;;Type 1 request received from ctminh@node2.supernodexp.hpc, sock=16
02/19/2018 16:50:35;0100;Server@node2;Req;;Type 3 request received from ctminh@node2.supernodexp.hpc, sock=16
02/19/2018 16:50:35;0100;Server@node2;Req;;Type 5 request received from ctminh@node2.supernodexp.hpc, sock=16
02/19/2018 16:50:35;0100;Server@node2;Job;3756.node2.supernodexp.hpc;enqueuing into workq, state 1 hop 1
02/19/2018 16:50:35;0008;Server@node2;Job;3756.node2.supernodexp.hpc;Job Queued at request of ctminh@node2.supernodexp.hpc, owner = ctminh@node2.supernodexp.hpc, job name = sweep, queue = workq
02/19/2018 16:50:35;0100;Server@node2;Req;;Type 20 request received from Scheduler@node2.supernodexp.hpc, sock=20
02/19/2018 16:50:35;0100;Server@node2;Req;;Type 51 request received from Scheduler@node2.supernodexp.hpc, sock=20
02/19/2018 16:50:36;0100;Server@node2;Req;;Type 11 request received from Scheduler@node2.supernodexp.hpc, sock=20
02/19/2018 16:50:36;0008;Server@node2;Job;3756.node2.supernodexp.hpc;Job Modified at request of Scheduler@node2.supernodexp.hpc
02/19/2018 16:50:36;0100;Server@node2;Req;;Type 11 request received from Scheduler@node2.supernodexp.hpc, sock=20
02/19/2018 16:50:36;0008;Server@node2;Job;3755.node2.supernodexp.hpc;Job Modified at request of Scheduler@node2.supernodexp.hpc
02/19/2018 16:50:36;0040;Server@node2;Svr;node2.supernodexp.hpc;Scheduler sent command 1
02/19/2018 16:50:36;0040;Server@node2;Svr;node2.supernodexp.hpc;Scheduler sent command 0
02/19/2018 16:50:36;0100;Server@node2;Req;;Type 21 request received from Scheduler@node2.supernodexp.hpc, sock=20
02/19/2018 16:50:36;0100;Server@node2;Req;;Type 81 request received from Scheduler@node2.supernodexp.hpc, sock=20
02/19/2018 16:50:36;0100;Server@node2;Req;;Type 71 request received from Scheduler@node2.supernodexp.hpc, sock=20
02/19/2018 16:50:36;0100;Server@node2;Req;;Type 58 request received from Scheduler@node2.supernodexp.hpc, sock=20
02/19/2018 16:50:36;0100;Server@node2;Req;;Type 20 request received from Scheduler@node2.supernodexp.hpc, sock=20
02/19/2018 16:50:36;0100;Server@node2;Req;;Type 51 request received from Scheduler@node2.supernodexp.hpc, sock=20
02/19/2018 16:50:41;0100;Server@node2;Req;;Type 1 request received from ctminh@node2.supernodexp.hpc, sock=16
02/19/2018 16:50:41;0100;Server@node2;Req;;Type 3 request received from ctminh@node2.supernodexp.hpc, sock=16
02/19/2018 16:50:41;0100;Server@node2;Req;;Type 5 request received from ctminh@node2.supernodexp.hpc, sock=16
02/19/2018 16:50:41;0100;Server@node2;Job;3757.node2.supernodexp.hpc;enqueuing into workq, state 1 hop 1
02/19/2018 16:50:41;0008;Server@node2;Job;3757.node2.supernodexp.hpc;Job Queued at request of ctminh@node2.supernodexp.hpc, owner = ctminh@node2.supernodexp.hpc, job name = histogram, queue = workq
02/19/2018 16:50:41;0040;Server@node2;Svr;node2.supernodexp.hpc;Scheduler sent command 1
02/19/2018 16:50:41;0040;Server@node2;Svr;node2.supernodexp.hpc;Scheduler sent command 0
02/19/2018 16:50:41;0100;Server@node2;Req;;Type 21 request received from Scheduler@node2.supernodexp.hpc, sock=20
02/19/2018 16:50:41;0100;Server@node2;Req;;Type 81 request received from Scheduler@node2.supernodexp.hpc, sock=20
02/19/2018 16:50:41;0100;Server@node2;Req;;Type 71 request received from Scheduler@node2.supernodexp.hpc, sock=20
02/19/2018 16:50:41;0100;Server@node2;Req;;Type 58 request received from Scheduler@node2.supernodexp.hpc, sock=20
02/19/2018 16:50:42;0100;Server@node2;Req;;Type 20 request received from Scheduler@node2.supernodexp.hpc, sock=20
02/19/2018 16:50:42;0100;Server@node2;Req;;Type 51 request received from Scheduler@node2.supernodexp.hpc, sock=20
02/19/2018 16:50:42;0100;Server@node2;Req;;Type 11 request received from Scheduler@node2.supernodexp.hpc, sock=20
02/19/2018 16:50:42;0008;Server@node2;Job;3757.node2.supernodexp.hpc;Job Modified at request of Scheduler@node2.supernodexp.hpc
02/19/2018 16:55:42;0100;Server@node2;Req;;Type 0 request received from ctminh@node2.supernodexp.hpc, sock=16
02/19/2018 16:55:42;0100;Server@node2;Req;;Type 49 request received from ctminh@node2.supernodexp.hpc, sock=20
02/19/2018 16:55:42;0100;Server@node2;Req;;Type 21 request received from ctminh@node2.supernodexp.hpc, sock=16
02/19/2018 16:55:42;0100;Server@node2;Req;;Type 1 request received from ctminh@node2.supernodexp.hpc, sock=16
02/19/2018 16:55:42;0100;Server@node2;Req;;Type 3 request received from ctminh@node2.supernodexp.hpc, sock=16
02/19/2018 16:55:42;0100;Server@node2;Req;;Type 5 request received from ctminh@node2.supernodexp.hpc, sock=16
02/19/2018 16:55:42;0100;Server@node2;Job;3758.node2.supernodexp.hpc;enqueuing into workq, state 1 hop 1
02/19/2018 16:55:42;0008;Server@node2;Job;3758.node2.supernodexp.hpc;Job Queued at request of ctminh@node2.supernodexp.hpc, owner = ctminh@node2.supernodexp.hpc, job name = jacobi, queue = workq
02/19/2018 16:55:42;0040;Server@node2;Svr;node2.supernodexp.hpc;Scheduler sent command 1
02/19/2018 16:55:42;0040;Server@node2;Svr;node2.supernodexp.hpc;Scheduler sent command 0
02/19/2018 16:55:42;0100;Server@node2;Req;;Type 21 request received from Scheduler@node2.supernodexp.hpc, sock=20
02/19/2018 16:55:42;0100;Server@node2;Req;;Type 81 request received from Scheduler@node2.supernodexp.hpc, sock=20
02/19/2018 16:55:42;0100;Server@node2;Req;;Type 71 request received from Scheduler@node2.supernodexp.hpc, sock=20
02/19/2018 16:55:42;0100;Server@node2;Req;;Type 58 request received from Scheduler@node2.supernodexp.hpc, sock=20
02/19/2018 16:55:42;0100;Server@node2;Req;;Type 1 request received from ctminh@node2.supernodexp.hpc, sock=16
02/19/2018 16:55:42;0100;Server@node2;Req;;Type 3 request received from ctminh@node2.supernodexp.hpc, sock=16
02/19/2018 16:55:42;0100;Server@node2;Req;;Type 5 request received from ctminh@node2.supernodexp.hpc, sock=16
02/19/2018 16:55:42;0100;Server@node2;Job;3759.node2.supernodexp.hpc;enqueuing into workq, state 1 hop 1
02/19/2018 16:55:42;0008;Server@node2;Job;3759.node2.supernodexp.hpc;Job Queued at request of ctminh@node2.supernodexp.hpc, owner = ctminh@node2.supernodexp.hpc, job name = telemac3, queue = workq
02/19/2018 16:55:42;0100;Server@node2;Req;;Type 20 request received from Scheduler@node2.supernodexp.hpc, sock=20
02/19/2018 16:55:42;0100;Server@node2;Req;;Type 51 request received from Scheduler@node2.supernodexp.hpc, sock=20
02/19/2018 16:55:42;0100;Server@node2;Req;;Type 11 request received from Scheduler@node2.supernodexp.hpc, sock=20
02/19/2018 16:55:42;0008;Server@node2;Job;3759.node2.supernodexp.hpc;Job Modified at request of Scheduler@node2.supernodexp.hpc
02/19/2018 16:55:42;0100;Server@node2;Req;;Type 11 request received from Scheduler@node2.supernodexp.hpc, sock=20
02/19/2018 16:55:42;0008;Server@node2;Job;3758.node2.supernodexp.hpc;Job Modified at request of Scheduler@node2.supernodexp.hpc
02/19/2018 16:55:42;0040;Server@node2;Svr;node2.supernodexp.hpc;Scheduler sent command 1
02/19/2018 16:55:42;0040;Server@node2;Svr;node2.supernodexp.hpc;Scheduler sent command 0
02/19/2018 16:55:42;0100;Server@node2;Req;;Type 21 request received from Scheduler@node2.supernodexp.hpc, sock=20
02/19/2018 16:55:42;0100;Server@node2;Req;;Type 81 request received from Scheduler@node2.supernodexp.hpc, sock=20
02/19/2018 16:55:42;0100;Server@node2;Req;;Type 71 request received from Scheduler@node2.supernodexp.hpc, sock=20
02/19/2018 16:55:42;0100;Server@node2;Req;;Type 58 request received from Scheduler@node2.supernodexp.hpc, sock=20
02/19/2018 16:55:42;0100;Server@node2;Req;;Type 20 request received from Scheduler@node2.supernodexp.hpc, sock=20
02/19/2018 16:55:42;0100;Server@node2;Req;;Type 51 request received from Scheduler@node2.supernodexp.hpc, sock=20
02/19/2018 16:55:45;0100;Server@node2;Req;;Type 1 request received from ctminh@node2.supernodexp.hpc, sock=16
02/19/2018 16:55:45;0100;Server@node2;Req;;Type 3 request received from ctminh@node2.supernodexp.hpc, sock=16
02/19/2018 16:55:45;0100;Server@node2;Req;;Type 5 request received from ctminh@node2.supernodexp.hpc, sock=16
02/19/2018 16:55:45;0100;Server@node2;Job;3760.node2.supernodexp.hpc;enqueuing into workq, state 1 hop 1
02/19/2018 16:55:45;0008;Server@node2;Job;3760.node2.supernodexp.hpc;Job Queued at request of ctminh@node2.supernodexp.hpc, owner = ctminh@node2.supernodexp.hpc, job name = lu-decomp, queue = workq
02/19/2018 16:55:45;0040;Server@node2;Svr;node2.supernodexp.hpc;Scheduler sent command 1
02/19/2018 16:55:45;0040;Server@node2;Svr;node2.supernodexp.hpc;Scheduler sent command 0
02/19/2018 16:55:45;0100;Server@node2;Req;;Type 21 request received from Scheduler@node2.supernodexp.hpc, sock=20
02/19/2018 16:55:45;0100;Server@node2;Req;;Type 81 request received from Scheduler@node2.supernodexp.hpc, sock=20
02/19/2018 16:55:45;0100;Server@node2;Req;;Type 71 request received from Scheduler@node2.supernodexp.hpc, sock=20
02/19/2018 16:55:45;0100;Server@node2;Req;;Type 58 request received from Scheduler@node2.supernodexp.hpc, sock=20
02/19/2018 16:55:45;0100;Server@node2;Req;;Type 1 request received from ctminh@node2.supernodexp.hpc, sock=16
02/19/2018 16:55:45;0100;Server@node2;Req;;Type 3 request received from ctminh@node2.supernodexp.hpc, sock=16
02/19/2018 16:55:45;0100;Server@node2;Req;;Type 5 request received from ctminh@node2.supernodexp.hpc, sock=16
02/19/2018 16:55:45;0100;Server@node2;Job;3761.node2.supernodexp.hpc;enqueuing into workq, state 1 hop 1
02/19/2018 16:55:45;0008;Server@node2;Job;3761.node2.supernodexp.hpc;Job Queued at request of ctminh@node2.supernodexp.hpc, owner = ctminh@node2.supernodexp.hpc, job name = vast1, queue = workq
02/19/2018 16:55:45;0100;Server@node2;Req;;Type 20 request received from Scheduler@node2.supernodexp.hpc, sock=20
02/19/2018 16:55:45;0100;Server@node2;Req;;Type 51 request received from Scheduler@node2.supernodexp.hpc, sock=20
02/19/2018 16:55:45;0100;Server@node2;Req;;Type 11 request received from Scheduler@node2.supernodexp.hpc, sock=20
02/19/2018 16:55:45;0008;Server@node2;Job;3761.node2.supernodexp.hpc;Job Modified at request of Scheduler@node2.supernodexp.hpc
02/19/2018 16:55:45;0100;Server@node2;Req;;Type 11 request received from Scheduler@node2.supernodexp.hpc, sock=20
02/19/2018 16:55:45;0008;Server@node2;Job;3760.node2.supernodexp.hpc;Job Modified at request of Scheduler@node2.supernodexp.hpc
02/19/2018 16:55:45;0040;Server@node2;Svr;node2.supernodexp.hpc;Scheduler sent command 1
02/19/2018 16:55:45;0040;Server@node2;Svr;node2.supernodexp.hpc;Scheduler sent command 0
02/19/2018 16:55:45;0100;Server@node2;Req;;Type 21 request received from Scheduler@node2.supernodexp.hpc, sock=20
02/19/2018 16:55:45;0100;Server@node2;Req;;Type 81 request received from Scheduler@node2.supernodexp.hpc, sock=20
02/19/2018 16:55:45;0100;Server@node2;Req;;Type 71 request received from Scheduler@node2.supernodexp.hpc, sock=20
02/19/2018 16:55:45;0100;Server@node2;Req;;Type 58 request received from Scheduler@node2.supernodexp.hpc, sock=20
02/19/2018 16:55:45;0100;Server@node2;Req;;Type 20 request received from Scheduler@node2.supernodexp.hpc, sock=20
02/19/2018 16:55:45;0100;Server@node2;Req;;Type 51 request received from Scheduler@node2.supernodexp.hpc, sock=20
02/19/2018 16:55:46;0100;Server@node2;Req;;Type 1 request received from ctminh@node2.supernodexp.hpc, sock=16
02/19/2018 16:55:46;0100;Server@node2;Req;;Type 3 request received from ctminh@node2.supernodexp.hpc, sock=16
02/19/2018 16:55:46;0100;Server@node2;Req;;Type 5 request received from ctminh@node2.supernodexp.hpc, sock=16
02/19/2018 16:55:46;0100;Server@node2;Job;3762.node2.supernodexp.hpc;enqueuing into workq, state 1 hop 1
02/19/2018 16:55:46;0008;Server@node2;Job;3762.node2.supernodexp.hpc;Job Queued at request of ctminh@node2.supernodexp.hpc, owner = ctminh@node2.supernodexp.hpc, job name = thread-affinity, queue = workq
02/19/2018 16:55:46;0040;Server@node2;Svr;node2.supernodexp.hpc;Scheduler sent command 1
02/19/2018 16:55:46;0040;Server@node2;Svr;node2.supernodexp.hpc;Scheduler sent command 0
02/19/2018 16:55:46;0100;Server@node2;Req;;Type 21 request received from Scheduler@node2.supernodexp.hpc, sock=20
02/19/2018 16:55:46;0100;Server@node2;Req;;Type 81 request received from Scheduler@node2.supernodexp.hpc, sock=20
02/19/2018 16:55:46;0100;Server@node2;Req;;Type 71 request received from Scheduler@node2.supernodexp.hpc, sock=20
02/19/2018 16:55:46;0100;Server@node2;Req;;Type 58 request received from Scheduler@node2.supernodexp.hpc, sock=20
02/19/2018 16:55:46;0100;Server@node2;Req;;Type 20 request received from Scheduler@node2.supernodexp.hpc, sock=20
02/19/2018 16:55:46;0100;Server@node2;Req;;Type 51 request received from Scheduler@node2.supernodexp.hpc, sock=20
02/19/2018 16:55:46;0100;Server@node2;Req;;Type 11 request received from Scheduler@node2.supernodexp.hpc, sock=20
02/19/2018 16:55:46;0008;Server@node2;Job;3762.node2.supernodexp.hpc;Job Modified at request of Scheduler@node2.supernodexp.hpc
02/19/2018 16:55:51;0100;Server@node2;Req;;Type 1 request received from ctminh@node2.supernodexp.hpc, sock=16
02/19/2018 16:55:51;0100;Server@node2;Req;;Type 3 request received from ctminh@node2.supernodexp.hpc, sock=16
02/19/2018 16:55:51;0100;Server@node2;Req;;Type 5 request received from ctminh@node2.supernodexp.hpc, sock=16
02/19/2018 16:55:51;0100;Server@node2;Job;3763.node2.supernodexp.hpc;enqueuing into workq, state 1 hop 1
02/19/2018 16:55:51;0008;Server@node2;Job;3763.node2.supernodexp.hpc;Job Queued at request of ctminh@node2.supernodexp.hpc, owner = ctminh@node2.supernodexp.hpc, job name = thread-affinity, queue = workq
02/19/2018 16:55:51;0040;Server@node2;Svr;node2.supernodexp.hpc;Scheduler sent command 1
02/19/2018 16:55:51;0040;Server@node2;Svr;node2.supernodexp.hpc;Scheduler sent command 0
02/19/2018 16:55:51;0100;Server@node2;Req;;Type 21 request received from Scheduler@node2.supernodexp.hpc, sock=20
02/19/2018 16:55:51;0100;Server@node2;Req;;Type 81 request received from Scheduler@node2.supernodexp.hpc, sock=20
02/19/2018 16:55:51;0100;Server@node2;Req;;Type 71 request received from Scheduler@node2.supernodexp.hpc, sock=20
02/19/2018 16:55:51;0100;Server@node2;Req;;Type 58 request received from Scheduler@node2.supernodexp.hpc, sock=20
02/19/2018 16:55:51;0100;Server@node2;Req;;Type 20 request received from Scheduler@node2.supernodexp.hpc, sock=20
02/19/2018 16:55:51;0100;Server@node2;Req;;Type 51 request received from Scheduler@node2.supernodexp.hpc, sock=20
02/19/2018 16:55:51;0100;Server@node2;Req;;Type 11 request received from Scheduler@node2.supernodexp.hpc, sock=20
02/19/2018 16:55:51;0008;Server@node2;Job;3763.node2.supernodexp.hpc;Job Modified at request of Scheduler@node2.supernodexp.hpc
02/19/2018 16:55:53;0100;Server@node2;Req;;Type 1 request received from ctminh@node2.supernodexp.hpc, sock=16
02/19/2018 16:55:53;0100;Server@node2;Req;;Type 3 request received from ctminh@node2.supernodexp.hpc, sock=16
02/19/2018 16:55:53;0100;Server@node2;Req;;Type 5 request received from ctminh@node2.supernodexp.hpc, sock=16
02/19/2018 16:55:53;0100;Server@node2;Job;3764.node2.supernodexp.hpc;enqueuing into workq, state 1 hop 1
02/19/2018 16:55:53;0008;Server@node2;Job;3764.node2.supernodexp.hpc;Job Queued at request of ctminh@node2.supernodexp.hpc, owner = ctminh@node2.supernodexp.hpc, job name = lu-decomp, queue = workq
02/19/2018 16:55:53;0040;Server@node2;Svr;node2.supernodexp.hpc;Scheduler sent command 1
02/19/2018 16:55:53;0040;Server@node2;Svr;node2.supernodexp.hpc;Scheduler sent command 0
02/19/2018 16:55:53;0100;Server@node2;Req;;Type 21 request received from Scheduler@node2.supernodexp.hpc, sock=20
02/19/2018 16:55:53;0100;Server@node2;Req;;Type 81 request received from Scheduler@node2.supernodexp.hpc, sock=20
02/19/2018 16:55:53;0100;Server@node2;Req;;Type 71 request received from Scheduler@node2.supernodexp.hpc, sock=20
02/19/2018 16:55:53;0100;Server@node2;Req;;Type 58 request received from Scheduler@node2.supernodexp.hpc, sock=20
02/19/2018 16:55:53;0100;Server@node2;Req;;Type 20 request received from Scheduler@node2.supernodexp.hpc, sock=20
02/19/2018 16:55:53;0100;Server@node2;Req;;Type 51 request received from Scheduler@node2.supernodexp.hpc, sock=20
02/19/2018 16:55:53;0100;Server@node2;Req;;Type 11 request received from Scheduler@node2.supernodexp.hpc, sock=20
02/19/2018 16:55:53;0008;Server@node2;Job;3764.node2.supernodexp.hpc;Job Modified at request of Scheduler@node2.supernodexp.hpc
02/19/2018 16:55:55;0100;Server@node2;Req;;Type 1 request received from ctminh@node2.supernodexp.hpc, sock=16
02/19/2018 16:55:55;0100;Server@node2;Req;;Type 3 request received from ctminh@node2.supernodexp.hpc, sock=16
02/19/2018 16:55:55;0100;Server@node2;Req;;Type 5 request received from ctminh@node2.supernodexp.hpc, sock=16
02/19/2018 16:55:55;0100;Server@node2;Job;3765.node2.supernodexp.hpc;enqueuing into workq, state 1 hop 1
02/19/2018 16:55:55;0008;Server@node2;Job;3765.node2.supernodexp.hpc;Job Queued at request of ctminh@node2.supernodexp.hpc, owner = ctminh@node2.supernodexp.hpc, job name = thread-affinity, queue = workq
02/19/2018 16:55:55;0040;Server@node2;Svr;node2.supernodexp.hpc;Scheduler sent command 1
02/19/2018 16:55:55;0040;Server@node2;Svr;node2.supernodexp.hpc;Scheduler sent command 0
02/19/2018 16:55:55;0100;Server@node2;Req;;Type 21 request received from Scheduler@node2.supernodexp.hpc, sock=20
02/19/2018 16:55:55;0100;Server@node2;Req;;Type 81 request received from Scheduler@node2.supernodexp.hpc, sock=20
02/19/2018 16:55:55;0100;Server@node2;Req;;Type 71 request received from Scheduler@node2.supernodexp.hpc, sock=20
02/19/2018 16:55:55;0100;Server@node2;Req;;Type 58 request received from Scheduler@node2.supernodexp.hpc, sock=20
02/19/2018 16:55:55;0100;Server@node2;Req;;Type 20 request received from Scheduler@node2.supernodexp.hpc, sock=20
02/19/2018 16:55:55;0100;Server@node2;Req;;Type 51 request received from Scheduler@node2.supernodexp.hpc, sock=20
02/19/2018 16:55:55;0100;Server@node2;Req;;Type 11 request received from Scheduler@node2.supernodexp.hpc, sock=20
02/19/2018 16:55:55;0008;Server@node2;Job;3765.node2.supernodexp.hpc;Job Modified at request of Scheduler@node2.supernodexp.hpc
02/19/2018 16:56:18;0100;Server@node2;Req;;Type 1 request received from ctminh@node2.supernodexp.hpc, sock=16
02/19/2018 16:56:18;0100;Server@node2;Req;;Type 3 request received from ctminh@node2.supernodexp.hpc, sock=16
02/19/2018 16:56:18;0100;Server@node2;Req;;Type 5 request received from ctminh@node2.supernodexp.hpc, sock=16
02/19/2018 16:56:18;0100;Server@node2;Job;3766.node2.supernodexp.hpc;enqueuing into workq, state 1 hop 1
02/19/2018 16:56:18;0008;Server@node2;Job;3766.node2.supernodexp.hpc;Job Queued at request of ctminh@node2.supernodexp.hpc, owner = ctminh@node2.supernodexp.hpc, job name = lu-decomp, queue = workq
02/19/2018 16:56:18;0040;Server@node2;Svr;node2.supernodexp.hpc;Scheduler sent command 1
02/19/2018 16:56:18;0040;Server@node2;Svr;node2.supernodexp.hpc;Scheduler sent command 0
02/19/2018 16:56:18;0100;Server@node2;Req;;Type 21 request received from Scheduler@node2.supernodexp.hpc, sock=20
02/19/2018 16:56:18;0100;Server@node2;Req;;Type 81 request received from Scheduler@node2.supernodexp.hpc, sock=20
02/19/2018 16:56:18;0100;Server@node2;Req;;Type 71 request received from Scheduler@node2.supernodexp.hpc, sock=20
02/19/2018 16:56:18;0100;Server@node2;Req;;Type 58 request received from Scheduler@node2.supernodexp.hpc, sock=20
02/19/2018 16:56:18;0100;Server@node2;Req;;Type 1 request received from ctminh@node2.supernodexp.hpc, sock=16
02/19/2018 16:56:18;0100;Server@node2;Req;;Type 3 request received from ctminh@node2.supernodexp.hpc, sock=16
02/19/2018 16:56:18;0100;Server@node2;Req;;Type 5 request received from ctminh@node2.supernodexp.hpc, sock=16
02/19/2018 16:56:18;0100;Server@node2;Job;3767.node2.supernodexp.hpc;enqueuing into workq, state 1 hop 1
02/19/2018 16:56:18;0008;Server@node2;Job;3767.node2.supernodexp.hpc;Job Queued at request of ctminh@node2.supernodexp.hpc, owner = ctminh@node2.supernodexp.hpc, job name = qe_mic_test, queue = workq
02/19/2018 16:56:18;0100;Server@node2;Req;;Type 20 request received from Scheduler@node2.supernodexp.hpc, sock=20
02/19/2018 16:56:18;0100;Server@node2;Req;;Type 51 request received from Scheduler@node2.supernodexp.hpc, sock=20
02/19/2018 16:56:18;0100;Server@node2;Req;;Type 1 request received from ctminh@node2.supernodexp.hpc, sock=16
02/19/2018 16:56:18;0100;Server@node2;Req;;Type 3 request received from ctminh@node2.supernodexp.hpc, sock=16
02/19/2018 16:56:18;0100;Server@node2;Req;;Type 5 request received from ctminh@node2.supernodexp.hpc, sock=16
02/19/2018 16:56:18;0100;Server@node2;Job;3768.node2.supernodexp.hpc;enqueuing into workq, state 1 hop 1
02/19/2018 16:56:18;0008;Server@node2;Job;3768.node2.supernodexp.hpc;Job Queued at request of ctminh@node2.supernodexp.hpc, owner = ctminh@node2.supernodexp.hpc, job name = histogram, queue = workq
02/19/2018 16:56:18;0100;Server@node2;Req;;Type 1 request received from ctminh@node2.supernodexp.hpc, sock=16
02/19/2018 16:56:18;0100;Server@node2;Req;;Type 3 request received from ctminh@node2.supernodexp.hpc, sock=16
02/19/2018 16:56:18;0100;Server@node2;Req;;Type 5 request received from ctminh@node2.supernodexp.hpc, sock=16
02/19/2018 16:56:18;0100;Server@node2;Job;3769.node2.supernodexp.hpc;enqueuing into workq, state 1 hop 1
02/19/2018 16:56:18;0008;Server@node2;Job;3769.node2.supernodexp.hpc;Job Queued at request of ctminh@node2.supernodexp.hpc, owner = ctminh@node2.supernodexp.hpc, job name = sweep, queue = workq
02/19/2018 16:56:18;0100;Server@node2;Req;;Type 1 request received from ctminh@node2.supernodexp.hpc, sock=16
02/19/2018 16:56:18;0100;Server@node2;Req;;Type 3 request received from ctminh@node2.supernodexp.hpc, sock=16
02/19/2018 16:56:18;0100;Server@node2;Req;;Type 5 request received from ctminh@node2.supernodexp.hpc, sock=16
02/19/2018 16:56:18;0100;Server@node2;Job;3770.node2.supernodexp.hpc;enqueuing into workq, state 1 hop 1
02/19/2018 16:56:18;0008;Server@node2;Job;3770.node2.supernodexp.hpc;Job Queued at request of ctminh@node2.supernodexp.hpc, owner = ctminh@node2.supernodexp.hpc, job name = histogram, queue = workq
02/19/2018 16:56:18;0100;Server@node2;Req;;Type 1 request received from ctminh@node2.supernodexp.hpc, sock=16
02/19/2018 16:56:18;0100;Server@node2;Req;;Type 3 request received from ctminh@node2.supernodexp.hpc, sock=16
02/19/2018 16:56:18;0100;Server@node2;Req;;Type 5 request received from ctminh@node2.supernodexp.hpc, sock=16
02/19/2018 16:56:18;0100;Server@node2;Job;3771.node2.supernodexp.hpc;enqueuing into workq, state 1 hop 1
02/19/2018 16:56:18;0008;Server@node2;Job;3771.node2.supernodexp.hpc;Job Queued at request of ctminh@node2.supernodexp.hpc, owner = ctminh@node2.supernodexp.hpc, job name = telemac1, queue = workq
02/19/2018 16:56:18;0100;Server@node2;Req;;Type 11 request received from Scheduler@node2.supernodexp.hpc, sock=20
02/19/2018 16:56:18;0008;Server@node2;Job;3767.node2.supernodexp.hpc;Job Modified at request of Scheduler@node2.supernodexp.hpc
02/19/2018 16:56:18;0100;Server@node2;Req;;Type 11 request received from Scheduler@node2.supernodexp.hpc, sock=20
02/19/2018 16:56:18;0008;Server@node2;Job;3766.node2.supernodexp.hpc;Job Modified at request of Scheduler@node2.supernodexp.hpc
02/19/2018 16:56:18;0040;Server@node2;Svr;node2.supernodexp.hpc;Scheduler sent command 1
02/19/2018 16:56:18;0040;Server@node2;Svr;node2.supernodexp.hpc;Scheduler sent command 0
02/19/2018 16:56:18;0100;Server@node2;Req;;Type 21 request received from Scheduler@node2.supernodexp.hpc, sock=20
02/19/2018 16:56:18;0100;Server@node2;Req;;Type 81 request received from Scheduler@node2.supernodexp.hpc, sock=20
02/19/2018 16:56:18;0100;Server@node2;Req;;Type 71 request received from Scheduler@node2.supernodexp.hpc, sock=20
02/19/2018 16:56:18;0100;Server@node2;Req;;Type 58 request received from Scheduler@node2.supernodexp.hpc, sock=20
02/19/2018 16:56:18;0100;Server@node2;Req;;Type 20 request received from Scheduler@node2.supernodexp.hpc, sock=20
02/19/2018 16:56:18;0100;Server@node2;Req;;Type 51 request received from Scheduler@node2.supernodexp.hpc, sock=20
02/19/2018 16:56:18;0100;Server@node2;Req;;Type 11 request received from Scheduler@node2.supernodexp.hpc, sock=20
02/19/2018 16:56:18;0008;Server@node2;Job;3771.node2.supernodexp.hpc;Job Modified at request of Scheduler@node2.supernodexp.hpc
02/19/2018 16:56:18;0100;Server@node2;Req;;Type 11 request received from Scheduler@node2.supernodexp.hpc, sock=20
02/19/2018 16:56:18;0008;Server@node2;Job;3768.node2.supernodexp.hpc;Job Modified at request of Scheduler@node2.supernodexp.hpc
02/19/2018 16:56:18;0100;Server@node2;Req;;Type 11 request received from Scheduler@node2.supernodexp.hpc, sock=20
02/19/2018 16:56:18;0008;Server@node2;Job;3769.node2.supernodexp.hpc;Job Modified at request of Scheduler@node2.supernodexp.hpc
02/19/2018 16:56:18;0100;Server@node2;Req;;Type 11 request received from Scheduler@node2.supernodexp.hpc, sock=20
02/19/2018 16:56:18;0008;Server@node2;Job;3770.node2.supernodexp.hpc;Job Modified at request of Scheduler@node2.supernodexp.hpc
02/19/2018 16:56:30;0100;Server@node2;Req;;Type 1 request received from ctminh@node2.supernodexp.hpc, sock=16
02/19/2018 16:56:30;0100;Server@node2;Req;;Type 3 request received from ctminh@node2.supernodexp.hpc, sock=16
02/19/2018 16:56:30;0100;Server@node2;Req;;Type 5 request received from ctminh@node2.supernodexp.hpc, sock=16
02/19/2018 16:56:30;0100;Server@node2;Job;3772.node2.supernodexp.hpc;enqueuing into workq, state 1 hop 1
02/19/2018 16:56:30;0008;Server@node2;Job;3772.node2.supernodexp.hpc;Job Queued at request of ctminh@node2.supernodexp.hpc, owner = ctminh@node2.supernodexp.hpc, job name = matrix-x-vector, queue = workq
02/19/2018 16:56:30;0040;Server@node2;Svr;node2.supernodexp.hpc;Scheduler sent command 1
02/19/2018 16:56:30;0040;Server@node2;Svr;node2.supernodexp.hpc;Scheduler sent command 0
02/19/2018 16:56:30;0100;Server@node2;Req;;Type 21 request received from Scheduler@node2.supernodexp.hpc, sock=20
02/19/2018 16:56:30;0100;Server@node2;Req;;Type 81 request received from Scheduler@node2.supernodexp.hpc, sock=20
02/19/2018 16:56:30;0100;Server@node2;Req;;Type 71 request received from Scheduler@node2.supernodexp.hpc, sock=20
02/19/2018 16:56:30;0100;Server@node2;Req;;Type 58 request received from Scheduler@node2.supernodexp.hpc, sock=20
02/19/2018 16:56:30;0100;Server@node2;Req;;Type 1 request received from ctminh@node2.supernodexp.hpc, sock=16
02/19/2018 16:56:30;0100;Server@node2;Req;;Type 3 request received from ctminh@node2.supernodexp.hpc, sock=16
02/19/2018 16:56:30;0100;Server@node2;Req;;Type 5 request received from ctminh@node2.supernodexp.hpc, sock=16
02/19/2018 16:56:30;0100;Server@node2;Job;3773.node2.supernodexp.hpc;enqueuing into workq, state 1 hop 1
02/19/2018 16:56:30;0008;Server@node2;Job;3773.node2.supernodexp.hpc;Job Queued at request of ctminh@node2.supernodexp.hpc, owner = ctminh@node2.supernodexp.hpc, job name = sweep, queue = workq
02/19/2018 16:56:30;0100;Server@node2;Req;;Type 20 request received from Scheduler@node2.supernodexp.hpc, sock=20
02/19/2018 16:56:30;0100;Server@node2;Req;;Type 51 request received from Scheduler@node2.supernodexp.hpc, sock=20
02/19/2018 16:56:30;0100;Server@node2;Req;;Type 11 request received from Scheduler@node2.supernodexp.hpc, sock=20
02/19/2018 16:56:30;0008;Server@node2;Job;3773.node2.supernodexp.hpc;Job Modified at request of Scheduler@node2.supernodexp.hpc
02/19/2018 16:56:30;0100;Server@node2;Req;;Type 11 request received from Scheduler@node2.supernodexp.hpc, sock=20
02/19/2018 16:56:30;0008;Server@node2;Job;3772.node2.supernodexp.hpc;Job Modified at request of Scheduler@node2.supernodexp.hpc
02/19/2018 16:56:30;0040;Server@node2;Svr;node2.supernodexp.hpc;Scheduler sent command 1
02/19/2018 16:56:30;0040;Server@node2;Svr;node2.supernodexp.hpc;Scheduler sent command 0
02/19/2018 16:56:30;0100;Server@node2;Req;;Type 21 request received from Scheduler@node2.supernodexp.hpc, sock=20
02/19/2018 16:56:30;0100;Server@node2;Req;;Type 81 request received from Scheduler@node2.supernodexp.hpc, sock=20
02/19/2018 16:56:30;0100;Server@node2;Req;;Type 71 request received from Scheduler@node2.supernodexp.hpc, sock=20
02/19/2018 16:56:30;0100;Server@node2;Req;;Type 58 request received from Scheduler@node2.supernodexp.hpc, sock=20
02/19/2018 16:56:30;0100;Server@node2;Req;;Type 20 request received from Scheduler@node2.supernodexp.hpc, sock=20
02/19/2018 16:56:30;0100;Server@node2;Req;;Type 51 request received from Scheduler@node2.supernodexp.hpc, sock=20
02/19/2018 16:56:31;0100;Server@node2;Req;;Type 1 request received from ctminh@node2.supernodexp.hpc, sock=16
02/19/2018 16:56:31;0100;Server@node2;Req;;Type 3 request received from ctminh@node2.supernodexp.hpc, sock=16
02/19/2018 16:56:31;0100;Server@node2;Req;;Type 5 request received from ctminh@node2.supernodexp.hpc, sock=16
02/19/2018 16:56:31;0100;Server@node2;Job;3774.node2.supernodexp.hpc;enqueuing into workq, state 1 hop 1
02/19/2018 16:56:31;0008;Server@node2;Job;3774.node2.supernodexp.hpc;Job Queued at request of ctminh@node2.supernodexp.hpc, owner = ctminh@node2.supernodexp.hpc, job name = telemac2, queue = workq
02/19/2018 16:56:31;0040;Server@node2;Svr;node2.supernodexp.hpc;Scheduler sent command 1
02/19/2018 16:56:31;0040;Server@node2;Svr;node2.supernodexp.hpc;Scheduler sent command 0
02/19/2018 16:56:31;0100;Server@node2;Req;;Type 21 request received from Scheduler@node2.supernodexp.hpc, sock=20
02/19/2018 16:56:31;0100;Server@node2;Req;;Type 81 request received from Scheduler@node2.supernodexp.hpc, sock=20
02/19/2018 16:56:31;0100;Server@node2;Req;;Type 71 request received from Scheduler@node2.supernodexp.hpc, sock=20
02/19/2018 16:56:31;0100;Server@node2;Req;;Type 58 request received from Scheduler@node2.supernodexp.hpc, sock=20
02/19/2018 16:56:31;0100;Server@node2;Req;;Type 20 request received from Scheduler@node2.supernodexp.hpc, sock=20
02/19/2018 16:56:31;0100;Server@node2;Req;;Type 51 request received from Scheduler@node2.supernodexp.hpc, sock=20
02/19/2018 16:56:31;0100;Server@node2;Req;;Type 11 request received from Scheduler@node2.supernodexp.hpc, sock=20
02/19/2018 16:56:31;0008;Server@node2;Job;3774.node2.supernodexp.hpc;Job Modified at request of Scheduler@node2.supernodexp.hpc
02/19/2018 16:56:32;0100;Server@node2;Req;;Type 1 request received from ctminh@node2.supernodexp.hpc, sock=16
02/19/2018 16:56:32;0100;Server@node2;Req;;Type 3 request received from ctminh@node2.supernodexp.hpc, sock=16
02/19/2018 16:56:32;0100;Server@node2;Req;;Type 5 request received from ctminh@node2.supernodexp.hpc, sock=16
02/19/2018 16:56:32;0100;Server@node2;Job;3775.node2.supernodexp.hpc;enqueuing into workq, state 1 hop 1
02/19/2018 16:56:32;0008;Server@node2;Job;3775.node2.supernodexp.hpc;Job Queued at request of ctminh@node2.supernodexp.hpc, owner = ctminh@node2.supernodexp.hpc, job name = nbody, queue = workq
02/19/2018 16:56:32;0040;Server@node2;Svr;node2.supernodexp.hpc;Scheduler sent command 1
02/19/2018 16:56:32;0040;Server@node2;Svr;node2.supernodexp.hpc;Scheduler sent command 0
02/19/2018 16:56:32;0100;Server@node2;Req;;Type 21 request received from Scheduler@node2.supernodexp.hpc, sock=20
02/19/2018 16:56:32;0100;Server@node2;Req;;Type 81 request received from Scheduler@node2.supernodexp.hpc, sock=20
02/19/2018 16:56:32;0100;Server@node2;Req;;Type 71 request received from Scheduler@node2.supernodexp.hpc, sock=20
02/19/2018 16:56:32;0100;Server@node2;Req;;Type 58 request received from Scheduler@node2.supernodexp.hpc, sock=20
02/19/2018 16:56:32;0100;Server@node2;Req;;Type 20 request received from Scheduler@node2.supernodexp.hpc, sock=20
02/19/2018 16:56:32;0100;Server@node2;Req;;Type 51 request received from Scheduler@node2.supernodexp.hpc, sock=20
02/19/2018 16:56:32;0100;Server@node2;Req;;Type 11 request received from Scheduler@node2.supernodexp.hpc, sock=20
02/19/2018 16:56:32;0008;Server@node2;Job;3775.node2.supernodexp.hpc;Job Modified at request of Scheduler@node2.supernodexp.hpc
02/19/2018 16:56:37;0100;Server@node2;Req;;Type 1 request received from ctminh@node2.supernodexp.hpc, sock=16
02/19/2018 16:56:37;0100;Server@node2;Req;;Type 3 request received from ctminh@node2.supernodexp.hpc, sock=16
02/19/2018 16:56:37;0100;Server@node2;Req;;Type 5 request received from ctminh@node2.supernodexp.hpc, sock=16
02/19/2018 16:56:37;0100;Server@node2;Job;3776.node2.supernodexp.hpc;enqueuing into workq, state 1 hop 1
02/19/2018 16:56:37;0008;Server@node2;Job;3776.node2.supernodexp.hpc;Job Queued at request of ctminh@node2.supernodexp.hpc, owner = ctminh@node2.supernodexp.hpc, job name = qe_mic_test, queue = workq
02/19/2018 16:56:37;0040;Server@node2;Svr;node2.supernodexp.hpc;Scheduler sent command 1
02/19/2018 16:56:37;0040;Server@node2;Svr;node2.supernodexp.hpc;Scheduler sent command 0
02/19/2018 16:56:37;0100;Server@node2;Req;;Type 21 request received from Scheduler@node2.supernodexp.hpc, sock=20
02/19/2018 16:56:37;0100;Server@node2;Req;;Type 81 request received from Scheduler@node2.supernodexp.hpc, sock=20
02/19/2018 16:56:37;0100;Server@node2;Req;;Type 71 request received from Scheduler@node2.supernodexp.hpc, sock=20
02/19/2018 16:56:37;0100;Server@node2;Req;;Type 58 request received from Scheduler@node2.supernodexp.hpc, sock=20
02/19/2018 16:56:37;0100;Server@node2;Req;;Type 20 request received from Scheduler@node2.supernodexp.hpc, sock=20
02/19/2018 16:56:37;0100;Server@node2;Req;;Type 51 request received from Scheduler@node2.supernodexp.hpc, sock=20
02/19/2018 16:56:37;0100;Server@node2;Req;;Type 11 request received from Scheduler@node2.supernodexp.hpc, sock=20
02/19/2018 16:56:37;0008;Server@node2;Job;3776.node2.supernodexp.hpc;Job Modified at request of Scheduler@node2.supernodexp.hpc
02/19/2018 16:56:40;0100;Server@node2;Req;;Type 1 request received from ctminh@node2.supernodexp.hpc, sock=16
02/19/2018 16:56:40;0100;Server@node2;Req;;Type 3 request received from ctminh@node2.supernodexp.hpc, sock=16
02/19/2018 16:56:40;0100;Server@node2;Req;;Type 5 request received from ctminh@node2.supernodexp.hpc, sock=16
02/19/2018 16:56:40;0100;Server@node2;Job;3777.node2.supernodexp.hpc;enqueuing into workq, state 1 hop 1
02/19/2018 16:56:40;0008;Server@node2;Job;3777.node2.supernodexp.hpc;Job Queued at request of ctminh@node2.supernodexp.hpc, owner = ctminh@node2.supernodexp.hpc, job name = vectorization, queue = workq
02/19/2018 16:56:40;0040;Server@node2;Svr;node2.supernodexp.hpc;Scheduler sent command 1
02/19/2018 16:56:40;0040;Server@node2;Svr;node2.supernodexp.hpc;Scheduler sent command 0
02/19/2018 16:56:40;0100;Server@node2;Req;;Type 21 request received from Scheduler@node2.supernodexp.hpc, sock=20
02/19/2018 16:56:40;0100;Server@node2;Req;;Type 81 request received from Scheduler@node2.supernodexp.hpc, sock=20
02/19/2018 16:56:40;0100;Server@node2;Req;;Type 71 request received from Scheduler@node2.supernodexp.hpc, sock=20
02/19/2018 16:56:40;0100;Server@node2;Req;;Type 58 request received from Scheduler@node2.supernodexp.hpc, sock=20
02/19/2018 16:56:40;0100;Server@node2;Req;;Type 20 request received from Scheduler@node2.supernodexp.hpc, sock=20
02/19/2018 16:56:40;0100;Server@node2;Req;;Type 51 request received from Scheduler@node2.supernodexp.hpc, sock=20
02/19/2018 16:56:40;0100;Server@node2;Req;;Type 11 request received from Scheduler@node2.supernodexp.hpc, sock=20
02/19/2018 16:56:40;0008;Server@node2;Job;3777.node2.supernodexp.hpc;Job Modified at request of Scheduler@node2.supernodexp.hpc
02/19/2018 16:57:09;0100;Server@node2;Req;;Type 1 request received from ctminh@node2.supernodexp.hpc, sock=16
02/19/2018 16:57:09;0100;Server@node2;Req;;Type 3 request received from ctminh@node2.supernodexp.hpc, sock=16
02/19/2018 16:57:09;0100;Server@node2;Req;;Type 5 request received from ctminh@node2.supernodexp.hpc, sock=16
02/19/2018 16:57:09;0100;Server@node2;Job;3778.node2.supernodexp.hpc;enqueuing into workq, state 1 hop 1
02/19/2018 16:57:09;0008;Server@node2;Job;3778.node2.supernodexp.hpc;Job Queued at request of ctminh@node2.supernodexp.hpc, owner = ctminh@node2.supernodexp.hpc, job name = telemac2, queue = workq
02/19/2018 16:57:09;0040;Server@node2;Svr;node2.supernodexp.hpc;Scheduler sent command 1
02/19/2018 16:57:09;0040;Server@node2;Svr;node2.supernodexp.hpc;Scheduler sent command 0
02/19/2018 16:57:09;0100;Server@node2;Req;;Type 21 request received from Scheduler@node2.supernodexp.hpc, sock=20
02/19/2018 16:57:09;0100;Server@node2;Req;;Type 81 request received from Scheduler@node2.supernodexp.hpc, sock=20
02/19/2018 16:57:09;0100;Server@node2;Req;;Type 71 request received from Scheduler@node2.supernodexp.hpc, sock=20
02/19/2018 16:57:09;0100;Server@node2;Req;;Type 58 request received from Scheduler@node2.supernodexp.hpc, sock=20
02/19/2018 16:57:09;0100;Server@node2;Req;;Type 1 request received from ctminh@node2.supernodexp.hpc, sock=16
02/19/2018 16:57:09;0100;Server@node2;Req;;Type 3 request received from ctminh@node2.supernodexp.hpc, sock=16
02/19/2018 16:57:09;0100;Server@node2;Req;;Type 5 request received from ctminh@node2.supernodexp.hpc, sock=16
02/19/2018 16:57:09;0100;Server@node2;Job;3779.node2.supernodexp.hpc;enqueuing into workq, state 1 hop 1
02/19/2018 16:57:09;0008;Server@node2;Job;3779.node2.supernodexp.hpc;Job Queued at request of ctminh@node2.supernodexp.hpc, owner = ctminh@node2.supernodexp.hpc, job name = telemac3, queue = workq
02/19/2018 16:57:09;0100;Server@node2;Req;;Type 20 request received from Scheduler@node2.supernodexp.hpc, sock=20
02/19/2018 16:57:09;0100;Server@node2;Req;;Type 51 request received from Scheduler@node2.supernodexp.hpc, sock=20
02/19/2018 16:57:09;0100;Server@node2;Req;;Type 11 request received from Scheduler@node2.supernodexp.hpc, sock=20
02/19/2018 16:57:09;0008;Server@node2;Job;3778.node2.supernodexp.hpc;Job Modified at request of Scheduler@node2.supernodexp.hpc
02/19/2018 16:57:09;0100;Server@node2;Req;;Type 11 request received from Scheduler@node2.supernodexp.hpc, sock=20
02/19/2018 16:57:09;0008;Server@node2;Job;3779.node2.supernodexp.hpc;Job Modified at request of Scheduler@node2.supernodexp.hpc
02/19/2018 16:57:09;0040;Server@node2;Svr;node2.supernodexp.hpc;Scheduler sent command 1
02/19/2018 16:57:09;0040;Server@node2;Svr;node2.supernodexp.hpc;Scheduler sent command 0
02/19/2018 16:57:09;0100;Server@node2;Req;;Type 21 request received from Scheduler@node2.supernodexp.hpc, sock=20
02/19/2018 16:57:09;0100;Server@node2;Req;;Type 81 request received from Scheduler@node2.supernodexp.hpc, sock=20
02/19/2018 16:57:09;0100;Server@node2;Req;;Type 71 request received from Scheduler@node2.supernodexp.hpc, sock=20
02/19/2018 16:57:09;0100;Server@node2;Req;;Type 58 request received from Scheduler@node2.supernodexp.hpc, sock=20
02/19/2018 16:57:10;0100;Server@node2;Req;;Type 20 request received from Scheduler@node2.supernodexp.hpc, sock=20
02/19/2018 16:57:10;0100;Server@node2;Req;;Type 51 request received from Scheduler@node2.supernodexp.hpc, sock=20
02/19/2018 16:57:42;0100;Server@node2;Req;;Type 1 request received from ctminh@node2.supernodexp.hpc, sock=16
02/19/2018 16:57:42;0100;Server@node2;Req;;Type 3 request received from ctminh@node2.supernodexp.hpc, sock=16
02/19/2018 16:57:42;0100;Server@node2;Req;;Type 5 request received from ctminh@node2.supernodexp.hpc, sock=16
02/19/2018 16:57:42;0100;Server@node2;Job;3780.node2.supernodexp.hpc;enqueuing into workq, state 1 hop 1
02/19/2018 16:57:43;0008;Server@node2;Job;3780.node2.supernodexp.hpc;Job Queued at request of ctminh@node2.supernodexp.hpc, owner = ctminh@node2.supernodexp.hpc, job name = jacobi, queue = workq
02/19/2018 16:57:43;0040;Server@node2;Svr;node2.supernodexp.hpc;Scheduler sent command 1
02/19/2018 16:57:43;0040;Server@node2;Svr;node2.supernodexp.hpc;Scheduler sent command 0
02/19/2018 16:57:43;0100;Server@node2;Req;;Type 21 request received from Scheduler@node2.supernodexp.hpc, sock=20
02/19/2018 16:57:43;0100;Server@node2;Req;;Type 81 request received from Scheduler@node2.supernodexp.hpc, sock=20
02/19/2018 16:57:43;0100;Server@node2;Req;;Type 71 request received from Scheduler@node2.supernodexp.hpc, sock=20
02/19/2018 16:57:43;0100;Server@node2;Req;;Type 58 request received from Scheduler@node2.supernodexp.hpc, sock=20
02/19/2018 16:57:43;0100;Server@node2;Req;;Type 20 request received from Scheduler@node2.supernodexp.hpc, sock=20
02/19/2018 16:57:43;0100;Server@node2;Req;;Type 51 request received from Scheduler@node2.supernodexp.hpc, sock=20
02/19/2018 16:57:43;0100;Server@node2;Req;;Type 11 request received from Scheduler@node2.supernodexp.hpc, sock=20
02/19/2018 16:57:43;0008;Server@node2;Job;3780.node2.supernodexp.hpc;Job Modified at request of Scheduler@node2.supernodexp.hpc
02/19/2018 16:57:48;0100;Server@node2;Req;;Type 1 request received from ctminh@node2.supernodexp.hpc, sock=16
02/19/2018 16:57:48;0100;Server@node2;Req;;Type 3 request received from ctminh@node2.supernodexp.hpc, sock=16
02/19/2018 16:57:48;0100;Server@node2;Req;;Type 5 request received from ctminh@node2.supernodexp.hpc, sock=16
02/19/2018 16:57:48;0100;Server@node2;Job;3781.node2.supernodexp.hpc;enqueuing into workq, state 1 hop 1
02/19/2018 16:57:48;0008;Server@node2;Job;3781.node2.supernodexp.hpc;Job Queued at request of ctminh@node2.supernodexp.hpc, owner = ctminh@node2.supernodexp.hpc, job name = qe_mic_test, queue = workq
02/19/2018 16:57:48;0040;Server@node2;Svr;node2.supernodexp.hpc;Scheduler sent command 1
02/19/2018 16:57:48;0040;Server@node2;Svr;node2.supernodexp.hpc;Scheduler sent command 0
02/19/2018 16:57:48;0100;Server@node2;Req;;Type 21 request received from Scheduler@node2.supernodexp.hpc, sock=20
02/19/2018 16:57:48;0100;Server@node2;Req;;Type 81 request received from Scheduler@node2.supernodexp.hpc, sock=20
02/19/2018 16:57:48;0100;Server@node2;Req;;Type 71 request received from Scheduler@node2.supernodexp.hpc, sock=20
02/19/2018 16:57:48;0100;Server@node2;Req;;Type 58 request received from Scheduler@node2.supernodexp.hpc, sock=20
02/19/2018 16:57:48;0100;Server@node2;Req;;Type 20 request received from Scheduler@node2.supernodexp.hpc, sock=20
02/19/2018 16:57:48;0100;Server@node2;Req;;Type 51 request received from Scheduler@node2.supernodexp.hpc, sock=20
02/19/2018 16:57:48;0100;Server@node2;Req;;Type 11 request received from Scheduler@node2.supernodexp.hpc, sock=20
02/19/2018 16:57:48;0008;Server@node2;Job;3781.node2.supernodexp.hpc;Job Modified at request of Scheduler@node2.supernodexp.hpc
02/19/2018 16:57:49;0100;Server@node2;Req;;Type 1 request received from ctminh@node2.supernodexp.hpc, sock=16
02/19/2018 16:57:49;0100;Server@node2;Req;;Type 3 request received from ctminh@node2.supernodexp.hpc, sock=16
02/19/2018 16:57:49;0100;Server@node2;Req;;Type 5 request received from ctminh@node2.supernodexp.hpc, sock=16
02/19/2018 16:57:49;0100;Server@node2;Job;3782.node2.supernodexp.hpc;enqueuing into workq, state 1 hop 1
02/19/2018 16:57:49;0008;Server@node2;Job;3782.node2.supernodexp.hpc;Job Queued at request of ctminh@node2.supernodexp.hpc, owner = ctminh@node2.supernodexp.hpc, job name = histogram, queue = workq
02/19/2018 16:57:49;0040;Server@node2;Svr;node2.supernodexp.hpc;Scheduler sent command 1
02/19/2018 16:57:49;0040;Server@node2;Svr;node2.supernodexp.hpc;Scheduler sent command 0
02/19/2018 16:57:49;0100;Server@node2;Req;;Type 21 request received from Scheduler@node2.supernodexp.hpc, sock=20
02/19/2018 16:57:49;0100;Server@node2;Req;;Type 81 request received from Scheduler@node2.supernodexp.hpc, sock=20
02/19/2018 16:57:49;0100;Server@node2;Req;;Type 71 request received from Scheduler@node2.supernodexp.hpc, sock=20
02/19/2018 16:57:49;0100;Server@node2;Req;;Type 58 request received from Scheduler@node2.supernodexp.hpc, sock=20
02/19/2018 16:57:49;0100;Server@node2;Req;;Type 20 request received from Scheduler@node2.supernodexp.hpc, sock=20
02/19/2018 16:57:49;0100;Server@node2;Req;;Type 51 request received from Scheduler@node2.supernodexp.hpc, sock=20
02/19/2018 16:57:49;0100;Server@node2;Req;;Type 11 request received from Scheduler@node2.supernodexp.hpc, sock=20
02/19/2018 16:57:49;0008;Server@node2;Job;3782.node2.supernodexp.hpc;Job Modified at request of Scheduler@node2.supernodexp.hpc
02/19/2018 16:57:52;0100;Server@node2;Req;;Type 1 request received from ctminh@node2.supernodexp.hpc, sock=16
02/19/2018 16:57:52;0100;Server@node2;Req;;Type 3 request received from ctminh@node2.supernodexp.hpc, sock=16
02/19/2018 16:57:52;0100;Server@node2;Req;;Type 5 request received from ctminh@node2.supernodexp.hpc, sock=16
02/19/2018 16:57:52;0100;Server@node2;Job;3783.node2.supernodexp.hpc;enqueuing into workq, state 1 hop 1
02/19/2018 16:57:52;0008;Server@node2;Job;3783.node2.supernodexp.hpc;Job Queued at request of ctminh@node2.supernodexp.hpc, owner = ctminh@node2.supernodexp.hpc, job name = lu-decomp, queue = workq
02/19/2018 16:57:52;0040;Server@node2;Svr;node2.supernodexp.hpc;Scheduler sent command 1
02/19/2018 16:57:52;0040;Server@node2;Svr;node2.supernodexp.hpc;Scheduler sent command 0
02/19/2018 16:57:52;0100;Server@node2;Req;;Type 21 request received from Scheduler@node2.supernodexp.hpc, sock=20
02/19/2018 16:57:52;0100;Server@node2;Req;;Type 81 request received from Scheduler@node2.supernodexp.hpc, sock=20
02/19/2018 16:57:52;0100;Server@node2;Req;;Type 71 request received from Scheduler@node2.supernodexp.hpc, sock=20
02/19/2018 16:57:52;0100;Server@node2;Req;;Type 58 request received from Scheduler@node2.supernodexp.hpc, sock=20
02/19/2018 16:57:52;0100;Server@node2;Req;;Type 20 request received from Scheduler@node2.supernodexp.hpc, sock=20
02/19/2018 16:57:52;0100;Server@node2;Req;;Type 51 request received from Scheduler@node2.supernodexp.hpc, sock=20
02/19/2018 16:57:52;0100;Server@node2;Req;;Type 11 request received from Scheduler@node2.supernodexp.hpc, sock=20
02/19/2018 16:57:52;0008;Server@node2;Job;3783.node2.supernodexp.hpc;Job Modified at request of Scheduler@node2.supernodexp.hpc
02/19/2018 16:57:53;0100;Server@node2;Req;;Type 1 request received from ctminh@node2.supernodexp.hpc, sock=16
02/19/2018 16:57:53;0100;Server@node2;Req;;Type 3 request received from ctminh@node2.supernodexp.hpc, sock=16
02/19/2018 16:57:53;0100;Server@node2;Req;;Type 5 request received from ctminh@node2.supernodexp.hpc, sock=16
02/19/2018 16:57:53;0100;Server@node2;Job;3784.node2.supernodexp.hpc;enqueuing into workq, state 1 hop 1
02/19/2018 16:57:53;0008;Server@node2;Job;3784.node2.supernodexp.hpc;Job Queued at request of ctminh@node2.supernodexp.hpc, owner = ctminh@node2.supernodexp.hpc, job name = jacobi, queue = workq
02/19/2018 16:57:53;0040;Server@node2;Svr;node2.supernodexp.hpc;Scheduler sent command 1
02/19/2018 16:57:53;0040;Server@node2;Svr;node2.supernodexp.hpc;Scheduler sent command 0
02/19/2018 16:57:53;0100;Server@node2;Req;;Type 21 request received from Scheduler@node2.supernodexp.hpc, sock=20
02/19/2018 16:57:53;0100;Server@node2;Req;;Type 81 request received from Scheduler@node2.supernodexp.hpc, sock=20
02/19/2018 16:57:53;0100;Server@node2;Req;;Type 71 request received from Scheduler@node2.supernodexp.hpc, sock=20
02/19/2018 16:57:53;0100;Server@node2;Req;;Type 58 request received from Scheduler@node2.supernodexp.hpc, sock=20
02/19/2018 16:57:53;0100;Server@node2;Req;;Type 20 request received from Scheduler@node2.supernodexp.hpc, sock=20
02/19/2018 16:57:53;0100;Server@node2;Req;;Type 51 request received from Scheduler@node2.supernodexp.hpc, sock=20
02/19/2018 16:57:53;0100;Server@node2;Req;;Type 11 request received from Scheduler@node2.supernodexp.hpc, sock=20
02/19/2018 16:57:53;0008;Server@node2;Job;3784.node2.supernodexp.hpc;Job Modified at request of Scheduler@node2.supernodexp.hpc
02/19/2018 16:57:55;0100;Server@node2;Req;;Type 1 request received from ctminh@node2.supernodexp.hpc, sock=16
02/19/2018 16:57:55;0100;Server@node2;Req;;Type 3 request received from ctminh@node2.supernodexp.hpc, sock=16
02/19/2018 16:57:55;0100;Server@node2;Req;;Type 5 request received from ctminh@node2.supernodexp.hpc, sock=16
02/19/2018 16:57:55;0100;Server@node2;Job;3785.node2.supernodexp.hpc;enqueuing into workq, state 1 hop 1
02/19/2018 16:57:55;0008;Server@node2;Job;3785.node2.supernodexp.hpc;Job Queued at request of ctminh@node2.supernodexp.hpc, owner = ctminh@node2.supernodexp.hpc, job name = telemac1, queue = workq
02/19/2018 16:57:55;0040;Server@node2;Svr;node2.supernodexp.hpc;Scheduler sent command 1
02/19/2018 16:57:55;0040;Server@node2;Svr;node2.supernodexp.hpc;Scheduler sent command 0
02/19/2018 16:57:55;0100;Server@node2;Req;;Type 21 request received from Scheduler@node2.supernodexp.hpc, sock=20
02/19/2018 16:57:55;0100;Server@node2;Req;;Type 81 request received from Scheduler@node2.supernodexp.hpc, sock=20
02/19/2018 16:57:55;0100;Server@node2;Req;;Type 71 request received from Scheduler@node2.supernodexp.hpc, sock=20
02/19/2018 16:57:55;0100;Server@node2;Req;;Type 58 request received from Scheduler@node2.supernodexp.hpc, sock=20
02/19/2018 16:57:55;0100;Server@node2;Req;;Type 20 request received from Scheduler@node2.supernodexp.hpc, sock=20
02/19/2018 16:57:55;0100;Server@node2;Req;;Type 51 request received from Scheduler@node2.supernodexp.hpc, sock=20
02/19/2018 16:57:55;0100;Server@node2;Req;;Type 11 request received from Scheduler@node2.supernodexp.hpc, sock=20
02/19/2018 16:57:55;0008;Server@node2;Job;3785.node2.supernodexp.hpc;Job Modified at request of Scheduler@node2.supernodexp.hpc
02/19/2018 16:58:20;0100;Server@node2;Req;;Type 1 request received from ctminh@node2.supernodexp.hpc, sock=16
02/19/2018 16:58:20;0100;Server@node2;Req;;Type 3 request received from ctminh@node2.supernodexp.hpc, sock=16
02/19/2018 16:58:20;0100;Server@node2;Req;;Type 5 request received from ctminh@node2.supernodexp.hpc, sock=16
02/19/2018 16:58:20;0100;Server@node2;Job;3786.node2.supernodexp.hpc;enqueuing into workq, state 1 hop 1
02/19/2018 16:58:20;0008;Server@node2;Job;3786.node2.supernodexp.hpc;Job Queued at request of ctminh@node2.supernodexp.hpc, owner = ctminh@node2.supernodexp.hpc, job name = vast1, queue = workq
02/19/2018 16:58:20;0040;Server@node2;Svr;node2.supernodexp.hpc;Scheduler sent command 1
02/19/2018 16:58:20;0040;Server@node2;Svr;node2.supernodexp.hpc;Scheduler sent command 0
02/19/2018 16:58:20;0100;Server@node2;Req;;Type 21 request received from Scheduler@node2.supernodexp.hpc, sock=20
02/19/2018 16:58:20;0100;Server@node2;Req;;Type 81 request received from Scheduler@node2.supernodexp.hpc, sock=20
02/19/2018 16:58:20;0100;Server@node2;Req;;Type 71 request received from Scheduler@node2.supernodexp.hpc, sock=20
02/19/2018 16:58:20;0100;Server@node2;Req;;Type 58 request received from Scheduler@node2.supernodexp.hpc, sock=20
02/19/2018 16:58:20;0100;Server@node2;Req;;Type 20 request received from Scheduler@node2.supernodexp.hpc, sock=20
02/19/2018 16:58:20;0100;Server@node2;Req;;Type 51 request received from Scheduler@node2.supernodexp.hpc, sock=20
02/19/2018 16:58:20;0100;Server@node2;Req;;Type 11 request received from Scheduler@node2.supernodexp.hpc, sock=20
02/19/2018 16:58:20;0008;Server@node2;Job;3786.node2.supernodexp.hpc;Job Modified at request of Scheduler@node2.supernodexp.hpc
02/19/2018 16:58:21;0100;Server@node2;Req;;Type 1 request received from ctminh@node2.supernodexp.hpc, sock=16
02/19/2018 16:58:21;0100;Server@node2;Req;;Type 3 request received from ctminh@node2.supernodexp.hpc, sock=16
02/19/2018 16:58:21;0100;Server@node2;Req;;Type 5 request received from ctminh@node2.supernodexp.hpc, sock=16
02/19/2018 16:58:21;0100;Server@node2;Job;3787.node2.supernodexp.hpc;enqueuing into workq, state 1 hop 1
02/19/2018 16:58:21;0008;Server@node2;Job;3787.node2.supernodexp.hpc;Job Queued at request of ctminh@node2.supernodexp.hpc, owner = ctminh@node2.supernodexp.hpc, job name = vectorization, queue = workq
02/19/2018 16:58:21;0040;Server@node2;Svr;node2.supernodexp.hpc;Scheduler sent command 1
02/19/2018 16:58:21;0040;Server@node2;Svr;node2.supernodexp.hpc;Scheduler sent command 0
02/19/2018 16:58:21;0100;Server@node2;Req;;Type 21 request received from Scheduler@node2.supernodexp.hpc, sock=20
02/19/2018 16:58:21;0100;Server@node2;Req;;Type 81 request received from Scheduler@node2.supernodexp.hpc, sock=20
02/19/2018 16:58:21;0100;Server@node2;Req;;Type 71 request received from Scheduler@node2.supernodexp.hpc, sock=20
02/19/2018 16:58:21;0100;Server@node2;Req;;Type 58 request received from Scheduler@node2.supernodexp.hpc, sock=20
02/19/2018 16:58:21;0100;Server@node2;Req;;Type 20 request received from Scheduler@node2.supernodexp.hpc, sock=20
02/19/2018 16:58:21;0100;Server@node2;Req;;Type 51 request received from Scheduler@node2.supernodexp.hpc, sock=20
02/19/2018 16:58:21;0100;Server@node2;Req;;Type 11 request received from Scheduler@node2.supernodexp.hpc, sock=20
02/19/2018 16:58:21;0008;Server@node2;Job;3787.node2.supernodexp.hpc;Job Modified at request of Scheduler@node2.supernodexp.hpc
02/19/2018 16:58:41;0100;Server@node2;Req;;Type 1 request received from ctminh@node2.supernodexp.hpc, sock=16
02/19/2018 16:58:41;0100;Server@node2;Req;;Type 3 request received from ctminh@node2.supernodexp.hpc, sock=16
02/19/2018 16:58:41;0100;Server@node2;Req;;Type 5 request received from ctminh@node2.supernodexp.hpc, sock=16
02/19/2018 16:58:41;0100;Server@node2;Job;3788.node2.supernodexp.hpc;enqueuing into workq, state 1 hop 1
02/19/2018 16:58:41;0008;Server@node2;Job;3788.node2.supernodexp.hpc;Job Queued at request of ctminh@node2.supernodexp.hpc, owner = ctminh@node2.supernodexp.hpc, job name = vectorization, queue = workq
02/19/2018 16:58:41;0040;Server@node2;Svr;node2.supernodexp.hpc;Scheduler sent command 1
02/19/2018 16:58:41;0040;Server@node2;Svr;node2.supernodexp.hpc;Scheduler sent command 0
02/19/2018 16:58:41;0100;Server@node2;Req;;Type 21 request received from Scheduler@node2.supernodexp.hpc, sock=20
02/19/2018 16:58:41;0100;Server@node2;Req;;Type 81 request received from Scheduler@node2.supernodexp.hpc, sock=20
02/19/2018 16:58:41;0100;Server@node2;Req;;Type 71 request received from Scheduler@node2.supernodexp.hpc, sock=20
02/19/2018 16:58:41;0100;Server@node2;Req;;Type 58 request received from Scheduler@node2.supernodexp.hpc, sock=20
02/19/2018 16:58:41;0100;Server@node2;Req;;Type 20 request received from Scheduler@node2.supernodexp.hpc, sock=20
02/19/2018 16:58:41;0100;Server@node2;Req;;Type 51 request received from Scheduler@node2.supernodexp.hpc, sock=20
02/19/2018 16:58:41;0100;Server@node2;Req;;Type 11 request received from Scheduler@node2.supernodexp.hpc, sock=20
02/19/2018 16:58:41;0008;Server@node2;Job;3788.node2.supernodexp.hpc;Job Modified at request of Scheduler@node2.supernodexp.hpc
02/19/2018 16:58:45;0100;Server@node2;Req;;Type 1 request received from ctminh@node2.supernodexp.hpc, sock=16
02/19/2018 16:58:45;0100;Server@node2;Req;;Type 3 request received from ctminh@node2.supernodexp.hpc, sock=16
02/19/2018 16:58:45;0100;Server@node2;Req;;Type 5 request received from ctminh@node2.supernodexp.hpc, sock=16
02/19/2018 16:58:45;0100;Server@node2;Job;3789.node2.supernodexp.hpc;enqueuing into workq, state 1 hop 1
02/19/2018 16:58:45;0008;Server@node2;Job;3789.node2.supernodexp.hpc;Job Queued at request of ctminh@node2.supernodexp.hpc, owner = ctminh@node2.supernodexp.hpc, job name = jacobi, queue = workq
02/19/2018 16:58:45;0040;Server@node2;Svr;node2.supernodexp.hpc;Scheduler sent command 1
02/19/2018 16:58:45;0040;Server@node2;Svr;node2.supernodexp.hpc;Scheduler sent command 0
02/19/2018 16:58:45;0100;Server@node2;Req;;Type 21 request received from Scheduler@node2.supernodexp.hpc, sock=20
02/19/2018 16:58:45;0100;Server@node2;Req;;Type 81 request received from Scheduler@node2.supernodexp.hpc, sock=20
02/19/2018 16:58:45;0100;Server@node2;Req;;Type 71 request received from Scheduler@node2.supernodexp.hpc, sock=20
02/19/2018 16:58:45;0100;Server@node2;Req;;Type 58 request received from Scheduler@node2.supernodexp.hpc, sock=20
02/19/2018 16:58:45;0100;Server@node2;Req;;Type 20 request received from Scheduler@node2.supernodexp.hpc, sock=20
02/19/2018 16:58:45;0100;Server@node2;Req;;Type 51 request received from Scheduler@node2.supernodexp.hpc, sock=20
02/19/2018 16:58:45;0100;Server@node2;Req;;Type 11 request received from Scheduler@node2.supernodexp.hpc, sock=20
02/19/2018 16:58:45;0008;Server@node2;Job;3789.node2.supernodexp.hpc;Job Modified at request of Scheduler@node2.supernodexp.hpc
02/19/2018 16:58:46;0100;Server@node2;Req;;Type 1 request received from ctminh@node2.supernodexp.hpc, sock=16
02/19/2018 16:58:46;0100;Server@node2;Req;;Type 3 request received from ctminh@node2.supernodexp.hpc, sock=16
02/19/2018 16:58:46;0100;Server@node2;Req;;Type 5 request received from ctminh@node2.supernodexp.hpc, sock=16
02/19/2018 16:58:46;0100;Server@node2;Job;3790.node2.supernodexp.hpc;enqueuing into workq, state 1 hop 1
02/19/2018 16:58:46;0008;Server@node2;Job;3790.node2.supernodexp.hpc;Job Queued at request of ctminh@node2.supernodexp.hpc, owner = ctminh@node2.supernodexp.hpc, job name = lu-decomp, queue = workq
02/19/2018 16:58:46;0040;Server@node2;Svr;node2.supernodexp.hpc;Scheduler sent command 1
02/19/2018 16:58:46;0040;Server@node2;Svr;node2.supernodexp.hpc;Scheduler sent command 0
02/19/2018 16:58:46;0100;Server@node2;Req;;Type 21 request received from Scheduler@node2.supernodexp.hpc, sock=20
02/19/2018 16:58:46;0100;Server@node2;Req;;Type 81 request received from Scheduler@node2.supernodexp.hpc, sock=20
02/19/2018 16:58:46;0100;Server@node2;Req;;Type 71 request received from Scheduler@node2.supernodexp.hpc, sock=20
02/19/2018 16:58:46;0100;Server@node2;Req;;Type 58 request received from Scheduler@node2.supernodexp.hpc, sock=20
02/19/2018 16:58:46;0100;Server@node2;Req;;Type 1 request received from ctminh@node2.supernodexp.hpc, sock=16
02/19/2018 16:58:46;0100;Server@node2;Req;;Type 3 request received from ctminh@node2.supernodexp.hpc, sock=16
02/19/2018 16:58:46;0100;Server@node2;Req;;Type 5 request received from ctminh@node2.supernodexp.hpc, sock=16
02/19/2018 16:58:46;0100;Server@node2;Job;3791.node2.supernodexp.hpc;enqueuing into workq, state 1 hop 1
02/19/2018 16:58:46;0008;Server@node2;Job;3791.node2.supernodexp.hpc;Job Queued at request of ctminh@node2.supernodexp.hpc, owner = ctminh@node2.supernodexp.hpc, job name = telemac1, queue = workq
02/19/2018 16:58:46;0100;Server@node2;Req;;Type 20 request received from Scheduler@node2.supernodexp.hpc, sock=20
02/19/2018 16:58:46;0100;Server@node2;Req;;Type 51 request received from Scheduler@node2.supernodexp.hpc, sock=20
02/19/2018 16:58:46;0100;Server@node2;Req;;Type 11 request received from Scheduler@node2.supernodexp.hpc, sock=20
02/19/2018 16:58:46;0008;Server@node2;Job;3791.node2.supernodexp.hpc;Job Modified at request of Scheduler@node2.supernodexp.hpc
02/19/2018 16:58:46;0100;Server@node2;Req;;Type 11 request received from Scheduler@node2.supernodexp.hpc, sock=20
02/19/2018 16:58:46;0008;Server@node2;Job;3790.node2.supernodexp.hpc;Job Modified at request of Scheduler@node2.supernodexp.hpc
02/19/2018 16:58:46;0040;Server@node2;Svr;node2.supernodexp.hpc;Scheduler sent command 1
02/19/2018 16:58:46;0040;Server@node2;Svr;node2.supernodexp.hpc;Scheduler sent command 0
02/19/2018 16:58:46;0100;Server@node2;Req;;Type 21 request received from Scheduler@node2.supernodexp.hpc, sock=20
02/19/2018 16:58:46;0100;Server@node2;Req;;Type 81 request received from Scheduler@node2.supernodexp.hpc, sock=20
02/19/2018 16:58:46;0100;Server@node2;Req;;Type 71 request received from Scheduler@node2.supernodexp.hpc, sock=20
02/19/2018 16:58:46;0100;Server@node2;Req;;Type 58 request received from Scheduler@node2.supernodexp.hpc, sock=20
02/19/2018 16:58:46;0100;Server@node2;Req;;Type 20 request received from Scheduler@node2.supernodexp.hpc, sock=20
02/19/2018 16:58:46;0100;Server@node2;Req;;Type 51 request received from Scheduler@node2.supernodexp.hpc, sock=20
02/19/2018 16:58:57;0100;Server@node2;Req;;Type 1 request received from ctminh@node2.supernodexp.hpc, sock=16
02/19/2018 16:58:57;0100;Server@node2;Req;;Type 3 request received from ctminh@node2.supernodexp.hpc, sock=16
02/19/2018 16:58:57;0100;Server@node2;Req;;Type 5 request received from ctminh@node2.supernodexp.hpc, sock=16
02/19/2018 16:58:57;0100;Server@node2;Job;3792.node2.supernodexp.hpc;enqueuing into workq, state 1 hop 1
02/19/2018 16:58:57;0008;Server@node2;Job;3792.node2.supernodexp.hpc;Job Queued at request of ctminh@node2.supernodexp.hpc, owner = ctminh@node2.supernodexp.hpc, job name = telemac3, queue = workq
02/19/2018 16:58:57;0040;Server@node2;Svr;node2.supernodexp.hpc;Scheduler sent command 1
02/19/2018 16:58:57;0040;Server@node2;Svr;node2.supernodexp.hpc;Scheduler sent command 0
02/19/2018 16:58:57;0100;Server@node2;Req;;Type 21 request received from Scheduler@node2.supernodexp.hpc, sock=20
02/19/2018 16:58:57;0100;Server@node2;Req;;Type 81 request received from Scheduler@node2.supernodexp.hpc, sock=20
02/19/2018 16:58:57;0100;Server@node2;Req;;Type 71 request received from Scheduler@node2.supernodexp.hpc, sock=20
02/19/2018 16:58:57;0100;Server@node2;Req;;Type 58 request received from Scheduler@node2.supernodexp.hpc, sock=20
02/19/2018 16:58:57;0100;Server@node2;Req;;Type 20 request received from Scheduler@node2.supernodexp.hpc, sock=20
02/19/2018 16:58:57;0100;Server@node2;Req;;Type 51 request received from Scheduler@node2.supernodexp.hpc, sock=20
02/19/2018 16:58:57;0100;Server@node2;Req;;Type 11 request received from Scheduler@node2.supernodexp.hpc, sock=20
02/19/2018 16:58:57;0008;Server@node2;Job;3792.node2.supernodexp.hpc;Job Modified at request of Scheduler@node2.supernodexp.hpc
02/19/2018 17:00:08;0100;Server@node2;Req;;Type 0 request received from ctminh@node2.supernodexp.hpc, sock=16
02/19/2018 17:00:08;0100;Server@node2;Req;;Type 49 request received from ctminh@node2.supernodexp.hpc, sock=20
02/19/2018 17:00:08;0100;Server@node2;Req;;Type 21 request received from ctminh@node2.supernodexp.hpc, sock=16
02/19/2018 17:00:08;0100;Server@node2;Req;;Type 1 request received from ctminh@node2.supernodexp.hpc, sock=16
02/19/2018 17:00:08;0100;Server@node2;Req;;Type 3 request received from ctminh@node2.supernodexp.hpc, sock=16
02/19/2018 17:00:08;0100;Server@node2;Req;;Type 5 request received from ctminh@node2.supernodexp.hpc, sock=16
02/19/2018 17:00:08;0100;Server@node2;Job;3793.node2.supernodexp.hpc;enqueuing into workq, state 1 hop 1
02/19/2018 17:00:08;0008;Server@node2;Job;3793.node2.supernodexp.hpc;Job Queued at request of ctminh@node2.supernodexp.hpc, owner = ctminh@node2.supernodexp.hpc, job name = nbody, queue = workq
02/19/2018 17:00:08;0040;Server@node2;Svr;node2.supernodexp.hpc;Scheduler sent command 1
02/19/2018 17:00:08;0040;Server@node2;Svr;node2.supernodexp.hpc;Scheduler sent command 0
02/19/2018 17:00:08;0100;Server@node2;Req;;Type 21 request received from Scheduler@node2.supernodexp.hpc, sock=20
02/19/2018 17:00:08;0100;Server@node2;Req;;Type 81 request received from Scheduler@node2.supernodexp.hpc, sock=20
02/19/2018 17:00:08;0100;Server@node2;Req;;Type 71 request received from Scheduler@node2.supernodexp.hpc, sock=20
02/19/2018 17:00:08;0100;Server@node2;Req;;Type 58 request received from Scheduler@node2.supernodexp.hpc, sock=20
02/19/2018 17:00:08;0100;Server@node2;Req;;Type 20 request received from Scheduler@node2.supernodexp.hpc, sock=20
02/19/2018 17:00:08;0100;Server@node2;Req;;Type 51 request received from Scheduler@node2.supernodexp.hpc, sock=20
02/19/2018 17:00:08;0100;Server@node2;Req;;Type 11 request received from Scheduler@node2.supernodexp.hpc, sock=20
02/19/2018 17:00:08;0008;Server@node2;Job;3793.node2.supernodexp.hpc;Job Modified at request of Scheduler@node2.supernodexp.hpc
02/19/2018 17:00:09;0100;Server@node2;Req;;Type 1 request received from ctminh@node2.supernodexp.hpc, sock=16
02/19/2018 17:00:09;0100;Server@node2;Req;;Type 3 request received from ctminh@node2.supernodexp.hpc, sock=16
02/19/2018 17:00:09;0100;Server@node2;Req;;Type 5 request received from ctminh@node2.supernodexp.hpc, sock=16
02/19/2018 17:00:09;0100;Server@node2;Job;3794.node2.supernodexp.hpc;enqueuing into workq, state 1 hop 1
02/19/2018 17:00:09;0008;Server@node2;Job;3794.node2.supernodexp.hpc;Job Queued at request of ctminh@node2.supernodexp.hpc, owner = ctminh@node2.supernodexp.hpc, job name = thread-affinity, queue = workq
02/19/2018 17:00:09;0040;Server@node2;Svr;node2.supernodexp.hpc;Scheduler sent command 1
02/19/2018 17:00:09;0040;Server@node2;Svr;node2.supernodexp.hpc;Scheduler sent command 0
02/19/2018 17:00:09;0100;Server@node2;Req;;Type 21 request received from Scheduler@node2.supernodexp.hpc, sock=20
02/19/2018 17:00:09;0100;Server@node2;Req;;Type 81 request received from Scheduler@node2.supernodexp.hpc, sock=20
02/19/2018 17:00:09;0100;Server@node2;Req;;Type 71 request received from Scheduler@node2.supernodexp.hpc, sock=20
02/19/2018 17:00:09;0100;Server@node2;Req;;Type 58 request received from Scheduler@node2.supernodexp.hpc, sock=20
02/19/2018 17:00:09;0100;Server@node2;Req;;Type 1 request received from ctminh@node2.supernodexp.hpc, sock=16
02/19/2018 17:00:09;0100;Server@node2;Req;;Type 3 request received from ctminh@node2.supernodexp.hpc, sock=16
02/19/2018 17:00:09;0100;Server@node2;Req;;Type 5 request received from ctminh@node2.supernodexp.hpc, sock=16
02/19/2018 17:00:09;0100;Server@node2;Job;3795.node2.supernodexp.hpc;enqueuing into workq, state 1 hop 1
02/19/2018 17:00:09;0008;Server@node2;Job;3795.node2.supernodexp.hpc;Job Queued at request of ctminh@node2.supernodexp.hpc, owner = ctminh@node2.supernodexp.hpc, job name = telemac1, queue = workq
02/19/2018 17:00:09;0100;Server@node2;Req;;Type 20 request received from Scheduler@node2.supernodexp.hpc, sock=20
02/19/2018 17:00:09;0100;Server@node2;Req;;Type 51 request received from Scheduler@node2.supernodexp.hpc, sock=20
02/19/2018 17:00:09;0100;Server@node2;Req;;Type 11 request received from Scheduler@node2.supernodexp.hpc, sock=20
02/19/2018 17:00:09;0008;Server@node2;Job;3795.node2.supernodexp.hpc;Job Modified at request of Scheduler@node2.supernodexp.hpc
02/19/2018 17:00:09;0100;Server@node2;Req;;Type 11 request received from Scheduler@node2.supernodexp.hpc, sock=20
02/19/2018 17:00:09;0008;Server@node2;Job;3794.node2.supernodexp.hpc;Job Modified at request of Scheduler@node2.supernodexp.hpc
02/19/2018 17:00:09;0040;Server@node2;Svr;node2.supernodexp.hpc;Scheduler sent command 1
02/19/2018 17:00:09;0040;Server@node2;Svr;node2.supernodexp.hpc;Scheduler sent command 0
02/19/2018 17:00:09;0100;Server@node2;Req;;Type 21 request received from Scheduler@node2.supernodexp.hpc, sock=20
02/19/2018 17:00:09;0100;Server@node2;Req;;Type 81 request received from Scheduler@node2.supernodexp.hpc, sock=20
02/19/2018 17:00:09;0100;Server@node2;Req;;Type 71 request received from Scheduler@node2.supernodexp.hpc, sock=20
02/19/2018 17:00:09;0100;Server@node2;Req;;Type 58 request received from Scheduler@node2.supernodexp.hpc, sock=20
02/19/2018 17:00:09;0100;Server@node2;Req;;Type 20 request received from Scheduler@node2.supernodexp.hpc, sock=20
02/19/2018 17:00:09;0100;Server@node2;Req;;Type 51 request received from Scheduler@node2.supernodexp.hpc, sock=20
02/19/2018 17:00:11;0100;Server@node2;Req;;Type 1 request received from ctminh@node2.supernodexp.hpc, sock=16
02/19/2018 17:00:11;0100;Server@node2;Req;;Type 3 request received from ctminh@node2.supernodexp.hpc, sock=16
02/19/2018 17:00:11;0100;Server@node2;Req;;Type 5 request received from ctminh@node2.supernodexp.hpc, sock=16
02/19/2018 17:00:11;0100;Server@node2;Job;3796.node2.supernodexp.hpc;enqueuing into workq, state 1 hop 1
02/19/2018 17:00:11;0008;Server@node2;Job;3796.node2.supernodexp.hpc;Job Queued at request of ctminh@node2.supernodexp.hpc, owner = ctminh@node2.supernodexp.hpc, job name = thread-affinity, queue = workq
02/19/2018 17:00:11;0040;Server@node2;Svr;node2.supernodexp.hpc;Scheduler sent command 1
02/19/2018 17:00:11;0040;Server@node2;Svr;node2.supernodexp.hpc;Scheduler sent command 0
02/19/2018 17:00:11;0100;Server@node2;Req;;Type 21 request received from Scheduler@node2.supernodexp.hpc, sock=20
02/19/2018 17:00:11;0100;Server@node2;Req;;Type 81 request received from Scheduler@node2.supernodexp.hpc, sock=20
02/19/2018 17:00:11;0100;Server@node2;Req;;Type 71 request received from Scheduler@node2.supernodexp.hpc, sock=20
02/19/2018 17:00:11;0100;Server@node2;Req;;Type 58 request received from Scheduler@node2.supernodexp.hpc, sock=20
02/19/2018 17:00:11;0100;Server@node2;Req;;Type 20 request received from Scheduler@node2.supernodexp.hpc, sock=20
02/19/2018 17:00:11;0100;Server@node2;Req;;Type 51 request received from Scheduler@node2.supernodexp.hpc, sock=20
02/19/2018 17:00:11;0100;Server@node2;Req;;Type 11 request received from Scheduler@node2.supernodexp.hpc, sock=20
02/19/2018 17:00:11;0008;Server@node2;Job;3796.node2.supernodexp.hpc;Job Modified at request of Scheduler@node2.supernodexp.hpc
02/19/2018 17:00:14;0100;Server@node2;Req;;Type 1 request received from ctminh@node2.supernodexp.hpc, sock=16
02/19/2018 17:00:14;0100;Server@node2;Req;;Type 3 request received from ctminh@node2.supernodexp.hpc, sock=16
02/19/2018 17:00:14;0100;Server@node2;Req;;Type 5 request received from ctminh@node2.supernodexp.hpc, sock=16
02/19/2018 17:00:14;0100;Server@node2;Job;3797.node2.supernodexp.hpc;enqueuing into workq, state 1 hop 1
02/19/2018 17:00:14;0008;Server@node2;Job;3797.node2.supernodexp.hpc;Job Queued at request of ctminh@node2.supernodexp.hpc, owner = ctminh@node2.supernodexp.hpc, job name = vectorization, queue = workq
02/19/2018 17:00:14;0040;Server@node2;Svr;node2.supernodexp.hpc;Scheduler sent command 1
02/19/2018 17:00:14;0040;Server@node2;Svr;node2.supernodexp.hpc;Scheduler sent command 0
02/19/2018 17:00:14;0100;Server@node2;Req;;Type 21 request received from Scheduler@node2.supernodexp.hpc, sock=20
02/19/2018 17:00:14;0100;Server@node2;Req;;Type 81 request received from Scheduler@node2.supernodexp.hpc, sock=20
02/19/2018 17:00:14;0100;Server@node2;Req;;Type 71 request received from Scheduler@node2.supernodexp.hpc, sock=20
02/19/2018 17:00:14;0100;Server@node2;Req;;Type 58 request received from Scheduler@node2.supernodexp.hpc, sock=20
02/19/2018 17:00:14;0100;Server@node2;Req;;Type 20 request received from Scheduler@node2.supernodexp.hpc, sock=20
02/19/2018 17:00:14;0100;Server@node2;Req;;Type 51 request received from Scheduler@node2.supernodexp.hpc, sock=20
02/19/2018 17:00:15;0100;Server@node2;Req;;Type 11 request received from Scheduler@node2.supernodexp.hpc, sock=20
02/19/2018 17:00:15;0008;Server@node2;Job;3797.node2.supernodexp.hpc;Job Modified at request of Scheduler@node2.supernodexp.hpc
02/19/2018 17:00:25;0100;Server@node2;Req;;Type 1 request received from ctminh@node2.supernodexp.hpc, sock=16
02/19/2018 17:00:25;0100;Server@node2;Req;;Type 3 request received from ctminh@node2.supernodexp.hpc, sock=16
02/19/2018 17:00:25;0100;Server@node2;Req;;Type 5 request received from ctminh@node2.supernodexp.hpc, sock=16
02/19/2018 17:00:25;0100;Server@node2;Job;3798.node2.supernodexp.hpc;enqueuing into workq, state 1 hop 1
02/19/2018 17:00:25;0008;Server@node2;Job;3798.node2.supernodexp.hpc;Job Queued at request of ctminh@node2.supernodexp.hpc, owner = ctminh@node2.supernodexp.hpc, job name = telemac3, queue = workq
02/19/2018 17:00:25;0040;Server@node2;Svr;node2.supernodexp.hpc;Scheduler sent command 1
02/19/2018 17:00:25;0040;Server@node2;Svr;node2.supernodexp.hpc;Scheduler sent command 0
02/19/2018 17:00:25;0100;Server@node2;Req;;Type 21 request received from Scheduler@node2.supernodexp.hpc, sock=20
02/19/2018 17:00:25;0100;Server@node2;Req;;Type 81 request received from Scheduler@node2.supernodexp.hpc, sock=20
02/19/2018 17:00:25;0100;Server@node2;Req;;Type 71 request received from Scheduler@node2.supernodexp.hpc, sock=20
02/19/2018 17:00:25;0100;Server@node2;Req;;Type 58 request received from Scheduler@node2.supernodexp.hpc, sock=20
02/19/2018 17:00:25;0100;Server@node2;Req;;Type 20 request received from Scheduler@node2.supernodexp.hpc, sock=20
02/19/2018 17:00:25;0100;Server@node2;Req;;Type 51 request received from Scheduler@node2.supernodexp.hpc, sock=20
02/19/2018 17:00:26;0100;Server@node2;Req;;Type 11 request received from Scheduler@node2.supernodexp.hpc, sock=20
02/19/2018 17:00:26;0008;Server@node2;Job;3798.node2.supernodexp.hpc;Job Modified at request of Scheduler@node2.supernodexp.hpc
02/19/2018 17:00:49;0100;Server@node2;Req;;Type 1 request received from ctminh@node2.supernodexp.hpc, sock=16
02/19/2018 17:00:50;0100;Server@node2;Req;;Type 3 request received from ctminh@node2.supernodexp.hpc, sock=16
02/19/2018 17:00:50;0100;Server@node2;Req;;Type 5 request received from ctminh@node2.supernodexp.hpc, sock=16
02/19/2018 17:00:50;0100;Server@node2;Job;3799.node2.supernodexp.hpc;enqueuing into workq, state 1 hop 1
02/19/2018 17:00:50;0008;Server@node2;Job;3799.node2.supernodexp.hpc;Job Queued at request of ctminh@node2.supernodexp.hpc, owner = ctminh@node2.supernodexp.hpc, job name = lu-decomp, queue = workq
02/19/2018 17:00:50;0040;Server@node2;Svr;node2.supernodexp.hpc;Scheduler sent command 1
02/19/2018 17:00:50;0040;Server@node2;Svr;node2.supernodexp.hpc;Scheduler sent command 0
02/19/2018 17:00:50;0100;Server@node2;Req;;Type 21 request received from Scheduler@node2.supernodexp.hpc, sock=20
02/19/2018 17:00:50;0100;Server@node2;Req;;Type 81 request received from Scheduler@node2.supernodexp.hpc, sock=20
02/19/2018 17:00:50;0100;Server@node2;Req;;Type 71 request received from Scheduler@node2.supernodexp.hpc, sock=20
02/19/2018 17:00:50;0100;Server@node2;Req;;Type 58 request received from Scheduler@node2.supernodexp.hpc, sock=20
02/19/2018 17:00:50;0100;Server@node2;Req;;Type 20 request received from Scheduler@node2.supernodexp.hpc, sock=20
02/19/2018 17:00:50;0100;Server@node2;Req;;Type 51 request received from Scheduler@node2.supernodexp.hpc, sock=20
02/19/2018 17:00:50;0100;Server@node2;Req;;Type 11 request received from Scheduler@node2.supernodexp.hpc, sock=20
02/19/2018 17:00:50;0008;Server@node2;Job;3799.node2.supernodexp.hpc;Job Modified at request of Scheduler@node2.supernodexp.hpc
02/19/2018 17:00:51;0100;Server@node2;Req;;Type 1 request received from ctminh@node2.supernodexp.hpc, sock=16
02/19/2018 17:00:51;0100;Server@node2;Req;;Type 3 request received from ctminh@node2.supernodexp.hpc, sock=16
02/19/2018 17:00:51;0100;Server@node2;Req;;Type 5 request received from ctminh@node2.supernodexp.hpc, sock=16
02/19/2018 17:00:51;0100;Server@node2;Job;3800.node2.supernodexp.hpc;enqueuing into workq, state 1 hop 1
02/19/2018 17:00:51;0008;Server@node2;Job;3800.node2.supernodexp.hpc;Job Queued at request of ctminh@node2.supernodexp.hpc, owner = ctminh@node2.supernodexp.hpc, job name = thread-affinity, queue = workq
02/19/2018 17:00:51;0040;Server@node2;Svr;node2.supernodexp.hpc;Scheduler sent command 1
02/19/2018 17:00:51;0040;Server@node2;Svr;node2.supernodexp.hpc;Scheduler sent command 0
02/19/2018 17:00:51;0100;Server@node2;Req;;Type 21 request received from Scheduler@node2.supernodexp.hpc, sock=20
02/19/2018 17:00:51;0100;Server@node2;Req;;Type 81 request received from Scheduler@node2.supernodexp.hpc, sock=20
02/19/2018 17:00:51;0100;Server@node2;Req;;Type 71 request received from Scheduler@node2.supernodexp.hpc, sock=20
02/19/2018 17:00:51;0100;Server@node2;Req;;Type 58 request received from Scheduler@node2.supernodexp.hpc, sock=20
02/19/2018 17:00:51;0100;Server@node2;Req;;Type 20 request received from Scheduler@node2.supernodexp.hpc, sock=20
02/19/2018 17:00:51;0100;Server@node2;Req;;Type 51 request received from Scheduler@node2.supernodexp.hpc, sock=20
02/19/2018 17:00:51;0100;Server@node2;Req;;Type 11 request received from Scheduler@node2.supernodexp.hpc, sock=20
02/19/2018 17:00:51;0008;Server@node2;Job;3800.node2.supernodexp.hpc;Job Modified at request of Scheduler@node2.supernodexp.hpc
02/19/2018 17:00:56;0100;Server@node2;Req;;Type 1 request received from ctminh@node2.supernodexp.hpc, sock=16
02/19/2018 17:00:56;0100;Server@node2;Req;;Type 3 request received from ctminh@node2.supernodexp.hpc, sock=16
02/19/2018 17:00:56;0100;Server@node2;Req;;Type 5 request received from ctminh@node2.supernodexp.hpc, sock=16
02/19/2018 17:00:56;0100;Server@node2;Job;3801.node2.supernodexp.hpc;enqueuing into workq, state 1 hop 1
02/19/2018 17:00:56;0008;Server@node2;Job;3801.node2.supernodexp.hpc;Job Queued at request of ctminh@node2.supernodexp.hpc, owner = ctminh@node2.supernodexp.hpc, job name = vast1, queue = workq
02/19/2018 17:00:56;0040;Server@node2;Svr;node2.supernodexp.hpc;Scheduler sent command 1
02/19/2018 17:00:56;0040;Server@node2;Svr;node2.supernodexp.hpc;Scheduler sent command 0
02/19/2018 17:00:56;0100;Server@node2;Req;;Type 21 request received from Scheduler@node2.supernodexp.hpc, sock=20
02/19/2018 17:00:56;0100;Server@node2;Req;;Type 81 request received from Scheduler@node2.supernodexp.hpc, sock=20
02/19/2018 17:00:56;0100;Server@node2;Req;;Type 71 request received from Scheduler@node2.supernodexp.hpc, sock=20
02/19/2018 17:00:56;0100;Server@node2;Req;;Type 58 request received from Scheduler@node2.supernodexp.hpc, sock=20
02/19/2018 17:00:56;0100;Server@node2;Req;;Type 1 request received from ctminh@node2.supernodexp.hpc, sock=16
02/19/2018 17:00:56;0100;Server@node2;Req;;Type 3 request received from ctminh@node2.supernodexp.hpc, sock=16
02/19/2018 17:00:56;0100;Server@node2;Req;;Type 5 request received from ctminh@node2.supernodexp.hpc, sock=16
02/19/2018 17:00:56;0100;Server@node2;Job;3802.node2.supernodexp.hpc;enqueuing into workq, state 1 hop 1
02/19/2018 17:00:56;0008;Server@node2;Job;3802.node2.supernodexp.hpc;Job Queued at request of ctminh@node2.supernodexp.hpc, owner = ctminh@node2.supernodexp.hpc, job name = lu-decomp, queue = workq
02/19/2018 17:00:56;0100;Server@node2;Req;;Type 1 request received from ctminh@node2.supernodexp.hpc, sock=16
02/19/2018 17:00:56;0100;Server@node2;Req;;Type 3 request received from ctminh@node2.supernodexp.hpc, sock=16
02/19/2018 17:00:56;0100;Server@node2;Req;;Type 5 request received from ctminh@node2.supernodexp.hpc, sock=16
02/19/2018 17:00:56;0100;Server@node2;Job;3803.node2.supernodexp.hpc;enqueuing into workq, state 1 hop 1
02/19/2018 17:00:56;0008;Server@node2;Job;3803.node2.supernodexp.hpc;Job Queued at request of ctminh@node2.supernodexp.hpc, owner = ctminh@node2.supernodexp.hpc, job name = thread-affinity, queue = workq
02/19/2018 17:00:56;0100;Server@node2;Req;;Type 20 request received from Scheduler@node2.supernodexp.hpc, sock=20
02/19/2018 17:00:56;0100;Server@node2;Req;;Type 51 request received from Scheduler@node2.supernodexp.hpc, sock=20
02/19/2018 17:00:56;0100;Server@node2;Req;;Type 1 request received from ctminh@node2.supernodexp.hpc, sock=16
02/19/2018 17:00:56;0100;Server@node2;Req;;Type 3 request received from ctminh@node2.supernodexp.hpc, sock=16
02/19/2018 17:00:56;0100;Server@node2;Req;;Type 5 request received from ctminh@node2.supernodexp.hpc, sock=16
02/19/2018 17:00:56;0100;Server@node2;Job;3804.node2.supernodexp.hpc;enqueuing into workq, state 1 hop 1
02/19/2018 17:00:56;0008;Server@node2;Job;3804.node2.supernodexp.hpc;Job Queued at request of ctminh@node2.supernodexp.hpc, owner = ctminh@node2.supernodexp.hpc, job name = jacobi, queue = workq
02/19/2018 17:00:56;0100;Server@node2;Req;;Type 11 request received from Scheduler@node2.supernodexp.hpc, sock=20
02/19/2018 17:00:56;0008;Server@node2;Job;3801.node2.supernodexp.hpc;Job Modified at request of Scheduler@node2.supernodexp.hpc
02/19/2018 17:00:56;0100;Server@node2;Req;;Type 11 request received from Scheduler@node2.supernodexp.hpc, sock=20
02/19/2018 17:00:56;0008;Server@node2;Job;3803.node2.supernodexp.hpc;Job Modified at request of Scheduler@node2.supernodexp.hpc
02/19/2018 17:00:56;0100;Server@node2;Req;;Type 11 request received from Scheduler@node2.supernodexp.hpc, sock=20
02/19/2018 17:00:56;0008;Server@node2;Job;3802.node2.supernodexp.hpc;Job Modified at request of Scheduler@node2.supernodexp.hpc
02/19/2018 17:00:56;0040;Server@node2;Svr;node2.supernodexp.hpc;Scheduler sent command 1
02/19/2018 17:00:56;0040;Server@node2;Svr;node2.supernodexp.hpc;Scheduler sent command 0
02/19/2018 17:00:56;0100;Server@node2;Req;;Type 21 request received from Scheduler@node2.supernodexp.hpc, sock=20
02/19/2018 17:00:56;0100;Server@node2;Req;;Type 81 request received from Scheduler@node2.supernodexp.hpc, sock=20
02/19/2018 17:00:56;0100;Server@node2;Req;;Type 71 request received from Scheduler@node2.supernodexp.hpc, sock=20
02/19/2018 17:00:56;0100;Server@node2;Req;;Type 58 request received from Scheduler@node2.supernodexp.hpc, sock=20
02/19/2018 17:00:56;0100;Server@node2;Req;;Type 20 request received from Scheduler@node2.supernodexp.hpc, sock=20
02/19/2018 17:00:56;0100;Server@node2;Req;;Type 51 request received from Scheduler@node2.supernodexp.hpc, sock=20
02/19/2018 17:00:56;0100;Server@node2;Req;;Type 11 request received from Scheduler@node2.supernodexp.hpc, sock=20
02/19/2018 17:00:56;0008;Server@node2;Job;3804.node2.supernodexp.hpc;Job Modified at request of Scheduler@node2.supernodexp.hpc
02/19/2018 17:01:04;0100;Server@node2;Req;;Type 1 request received from ctminh@node2.supernodexp.hpc, sock=16
02/19/2018 17:01:04;0100;Server@node2;Req;;Type 3 request received from ctminh@node2.supernodexp.hpc, sock=16
02/19/2018 17:01:04;0100;Server@node2;Req;;Type 5 request received from ctminh@node2.supernodexp.hpc, sock=16
02/19/2018 17:01:04;0100;Server@node2;Job;3805.node2.supernodexp.hpc;enqueuing into workq, state 1 hop 1
02/19/2018 17:01:04;0008;Server@node2;Job;3805.node2.supernodexp.hpc;Job Queued at request of ctminh@node2.supernodexp.hpc, owner = ctminh@node2.supernodexp.hpc, job name = vectorization, queue = workq
02/19/2018 17:01:04;0040;Server@node2;Svr;node2.supernodexp.hpc;Scheduler sent command 1
02/19/2018 17:01:04;0040;Server@node2;Svr;node2.supernodexp.hpc;Scheduler sent command 0
02/19/2018 17:01:04;0100;Server@node2;Req;;Type 21 request received from Scheduler@node2.supernodexp.hpc, sock=20
02/19/2018 17:01:04;0100;Server@node2;Req;;Type 81 request received from Scheduler@node2.supernodexp.hpc, sock=20
02/19/2018 17:01:04;0100;Server@node2;Req;;Type 71 request received from Scheduler@node2.supernodexp.hpc, sock=20
02/19/2018 17:01:04;0100;Server@node2;Req;;Type 58 request received from Scheduler@node2.supernodexp.hpc, sock=20
02/19/2018 17:01:04;0100;Server@node2;Req;;Type 20 request received from Scheduler@node2.supernodexp.hpc, sock=20
02/19/2018 17:01:04;0100;Server@node2;Req;;Type 51 request received from Scheduler@node2.supernodexp.hpc, sock=20
02/19/2018 17:01:04;0100;Server@node2;Req;;Type 11 request received from Scheduler@node2.supernodexp.hpc, sock=20
02/19/2018 17:01:04;0008;Server@node2;Job;3805.node2.supernodexp.hpc;Job Modified at request of Scheduler@node2.supernodexp.hpc
02/19/2018 17:01:05;0100;Server@node2;Req;;Type 1 request received from ctminh@node2.supernodexp.hpc, sock=16
02/19/2018 17:01:05;0100;Server@node2;Req;;Type 3 request received from ctminh@node2.supernodexp.hpc, sock=16
02/19/2018 17:01:05;0100;Server@node2;Req;;Type 5 request received from ctminh@node2.supernodexp.hpc, sock=16
02/19/2018 17:01:05;0100;Server@node2;Job;3806.node2.supernodexp.hpc;enqueuing into workq, state 1 hop 1
02/19/2018 17:01:05;0008;Server@node2;Job;3806.node2.supernodexp.hpc;Job Queued at request of ctminh@node2.supernodexp.hpc, owner = ctminh@node2.supernodexp.hpc, job name = sweep, queue = workq
02/19/2018 17:01:05;0040;Server@node2;Svr;node2.supernodexp.hpc;Scheduler sent command 1
02/19/2018 17:01:05;0040;Server@node2;Svr;node2.supernodexp.hpc;Scheduler sent command 0
02/19/2018 17:01:05;0100;Server@node2;Req;;Type 21 request received from Scheduler@node2.supernodexp.hpc, sock=20
02/19/2018 17:01:05;0100;Server@node2;Req;;Type 81 request received from Scheduler@node2.supernodexp.hpc, sock=20
02/19/2018 17:01:05;0100;Server@node2;Req;;Type 71 request received from Scheduler@node2.supernodexp.hpc, sock=20
02/19/2018 17:01:05;0100;Server@node2;Req;;Type 58 request received from Scheduler@node2.supernodexp.hpc, sock=20
02/19/2018 17:01:05;0100;Server@node2;Req;;Type 20 request received from Scheduler@node2.supernodexp.hpc, sock=20
02/19/2018 17:01:05;0100;Server@node2;Req;;Type 51 request received from Scheduler@node2.supernodexp.hpc, sock=20
02/19/2018 17:01:05;0100;Server@node2;Req;;Type 11 request received from Scheduler@node2.supernodexp.hpc, sock=20
02/19/2018 17:01:05;0008;Server@node2;Job;3806.node2.supernodexp.hpc;Job Modified at request of Scheduler@node2.supernodexp.hpc
02/19/2018 17:01:09;0100;Server@node2;Req;;Type 1 request received from ctminh@node2.supernodexp.hpc, sock=16
02/19/2018 17:01:09;0100;Server@node2;Req;;Type 3 request received from ctminh@node2.supernodexp.hpc, sock=16
02/19/2018 17:01:09;0100;Server@node2;Req;;Type 5 request received from ctminh@node2.supernodexp.hpc, sock=16
02/19/2018 17:01:09;0100;Server@node2;Job;3807.node2.supernodexp.hpc;enqueuing into workq, state 1 hop 1
02/19/2018 17:01:09;0008;Server@node2;Job;3807.node2.supernodexp.hpc;Job Queued at request of ctminh@node2.supernodexp.hpc, owner = ctminh@node2.supernodexp.hpc, job name = nbody, queue = workq
02/19/2018 17:01:09;0040;Server@node2;Svr;node2.supernodexp.hpc;Scheduler sent command 1
02/19/2018 17:01:09;0040;Server@node2;Svr;node2.supernodexp.hpc;Scheduler sent command 0
02/19/2018 17:01:09;0100;Server@node2;Req;;Type 21 request received from Scheduler@node2.supernodexp.hpc, sock=20
02/19/2018 17:01:09;0100;Server@node2;Req;;Type 81 request received from Scheduler@node2.supernodexp.hpc, sock=20
02/19/2018 17:01:09;0100;Server@node2;Req;;Type 71 request received from Scheduler@node2.supernodexp.hpc, sock=20
02/19/2018 17:01:09;0100;Server@node2;Req;;Type 58 request received from Scheduler@node2.supernodexp.hpc, sock=20
02/19/2018 17:01:09;0100;Server@node2;Req;;Type 20 request received from Scheduler@node2.supernodexp.hpc, sock=20
02/19/2018 17:01:09;0100;Server@node2;Req;;Type 51 request received from Scheduler@node2.supernodexp.hpc, sock=20
02/19/2018 17:01:09;0100;Server@node2;Req;;Type 11 request received from Scheduler@node2.supernodexp.hpc, sock=20
02/19/2018 17:01:09;0008;Server@node2;Job;3807.node2.supernodexp.hpc;Job Modified at request of Scheduler@node2.supernodexp.hpc
02/19/2018 17:01:32;0100;Server@node2;Req;;Type 1 request received from ctminh@node2.supernodexp.hpc, sock=16
02/19/2018 17:01:32;0100;Server@node2;Req;;Type 3 request received from ctminh@node2.supernodexp.hpc, sock=16
02/19/2018 17:01:32;0100;Server@node2;Req;;Type 5 request received from ctminh@node2.supernodexp.hpc, sock=16
02/19/2018 17:01:32;0100;Server@node2;Job;3808.node2.supernodexp.hpc;enqueuing into workq, state 1 hop 1
02/19/2018 17:01:32;0008;Server@node2;Job;3808.node2.supernodexp.hpc;Job Queued at request of ctminh@node2.supernodexp.hpc, owner = ctminh@node2.supernodexp.hpc, job name = sweep, queue = workq
02/19/2018 17:01:32;0040;Server@node2;Svr;node2.supernodexp.hpc;Scheduler sent command 1
02/19/2018 17:01:32;0040;Server@node2;Svr;node2.supernodexp.hpc;Scheduler sent command 0
02/19/2018 17:01:32;0100;Server@node2;Req;;Type 21 request received from Scheduler@node2.supernodexp.hpc, sock=20
02/19/2018 17:01:32;0100;Server@node2;Req;;Type 81 request received from Scheduler@node2.supernodexp.hpc, sock=20
02/19/2018 17:01:32;0100;Server@node2;Req;;Type 71 request received from Scheduler@node2.supernodexp.hpc, sock=20
02/19/2018 17:01:32;0100;Server@node2;Req;;Type 58 request received from Scheduler@node2.supernodexp.hpc, sock=20
02/19/2018 17:01:32;0100;Server@node2;Req;;Type 20 request received from Scheduler@node2.supernodexp.hpc, sock=20
02/19/2018 17:01:32;0100;Server@node2;Req;;Type 51 request received from Scheduler@node2.supernodexp.hpc, sock=20
02/19/2018 17:01:32;0100;Server@node2;Req;;Type 11 request received from Scheduler@node2.supernodexp.hpc, sock=20
02/19/2018 17:01:32;0008;Server@node2;Job;3808.node2.supernodexp.hpc;Job Modified at request of Scheduler@node2.supernodexp.hpc
02/19/2018 17:01:33;0100;Server@node2;Req;;Type 1 request received from ctminh@node2.supernodexp.hpc, sock=16
02/19/2018 17:01:33;0100;Server@node2;Req;;Type 3 request received from ctminh@node2.supernodexp.hpc, sock=16
02/19/2018 17:01:33;0100;Server@node2;Req;;Type 5 request received from ctminh@node2.supernodexp.hpc, sock=16
02/19/2018 17:01:33;0100;Server@node2;Job;3809.node2.supernodexp.hpc;enqueuing into workq, state 1 hop 1
02/19/2018 17:01:33;0008;Server@node2;Job;3809.node2.supernodexp.hpc;Job Queued at request of ctminh@node2.supernodexp.hpc, owner = ctminh@node2.supernodexp.hpc, job name = matrix-x-vector, queue = workq
02/19/2018 17:01:33;0040;Server@node2;Svr;node2.supernodexp.hpc;Scheduler sent command 1
02/19/2018 17:01:33;0040;Server@node2;Svr;node2.supernodexp.hpc;Scheduler sent command 0
02/19/2018 17:01:33;0100;Server@node2;Req;;Type 21 request received from Scheduler@node2.supernodexp.hpc, sock=20
02/19/2018 17:01:33;0100;Server@node2;Req;;Type 81 request received from Scheduler@node2.supernodexp.hpc, sock=20
02/19/2018 17:01:33;0100;Server@node2;Req;;Type 71 request received from Scheduler@node2.supernodexp.hpc, sock=20
02/19/2018 17:01:33;0100;Server@node2;Req;;Type 58 request received from Scheduler@node2.supernodexp.hpc, sock=20
02/19/2018 17:01:33;0100;Server@node2;Req;;Type 20 request received from Scheduler@node2.supernodexp.hpc, sock=20
02/19/2018 17:01:33;0100;Server@node2;Req;;Type 51 request received from Scheduler@node2.supernodexp.hpc, sock=20
02/19/2018 17:01:33;0100;Server@node2;Req;;Type 11 request received from Scheduler@node2.supernodexp.hpc, sock=20
02/19/2018 17:01:33;0008;Server@node2;Job;3809.node2.supernodexp.hpc;Job Modified at request of Scheduler@node2.supernodexp.hpc
02/19/2018 17:01:34;0100;Server@node2;Req;;Type 1 request received from ctminh@node2.supernodexp.hpc, sock=16
02/19/2018 17:01:34;0100;Server@node2;Req;;Type 3 request received from ctminh@node2.supernodexp.hpc, sock=16
02/19/2018 17:01:34;0100;Server@node2;Req;;Type 5 request received from ctminh@node2.supernodexp.hpc, sock=16
02/19/2018 17:01:34;0100;Server@node2;Job;3810.node2.supernodexp.hpc;enqueuing into workq, state 1 hop 1
02/19/2018 17:01:34;0008;Server@node2;Job;3810.node2.supernodexp.hpc;Job Queued at request of ctminh@node2.supernodexp.hpc, owner = ctminh@node2.supernodexp.hpc, job name = telemac3, queue = workq
02/19/2018 17:01:34;0040;Server@node2;Svr;node2.supernodexp.hpc;Scheduler sent command 1
02/19/2018 17:01:34;0040;Server@node2;Svr;node2.supernodexp.hpc;Scheduler sent command 0
02/19/2018 17:01:34;0100;Server@node2;Req;;Type 21 request received from Scheduler@node2.supernodexp.hpc, sock=20
02/19/2018 17:01:34;0100;Server@node2;Req;;Type 81 request received from Scheduler@node2.supernodexp.hpc, sock=20
02/19/2018 17:01:34;0100;Server@node2;Req;;Type 71 request received from Scheduler@node2.supernodexp.hpc, sock=20
02/19/2018 17:01:34;0100;Server@node2;Req;;Type 58 request received from Scheduler@node2.supernodexp.hpc, sock=20
02/19/2018 17:01:34;0100;Server@node2;Req;;Type 20 request received from Scheduler@node2.supernodexp.hpc, sock=20
02/19/2018 17:01:34;0100;Server@node2;Req;;Type 51 request received from Scheduler@node2.supernodexp.hpc, sock=20
02/19/2018 17:01:34;0100;Server@node2;Req;;Type 11 request received from Scheduler@node2.supernodexp.hpc, sock=20
02/19/2018 17:01:34;0008;Server@node2;Job;3810.node2.supernodexp.hpc;Job Modified at request of Scheduler@node2.supernodexp.hpc
02/19/2018 17:01:35;0100;Server@node2;Req;;Type 1 request received from ctminh@node2.supernodexp.hpc, sock=16
02/19/2018 17:01:35;0100;Server@node2;Req;;Type 3 request received from ctminh@node2.supernodexp.hpc, sock=16
02/19/2018 17:01:35;0100;Server@node2;Req;;Type 5 request received from ctminh@node2.supernodexp.hpc, sock=16
02/19/2018 17:01:35;0100;Server@node2;Job;3811.node2.supernodexp.hpc;enqueuing into workq, state 1 hop 1
02/19/2018 17:01:35;0008;Server@node2;Job;3811.node2.supernodexp.hpc;Job Queued at request of ctminh@node2.supernodexp.hpc, owner = ctminh@node2.supernodexp.hpc, job name = jacobi, queue = workq
02/19/2018 17:01:35;0040;Server@node2;Svr;node2.supernodexp.hpc;Scheduler sent command 1
02/19/2018 17:01:35;0040;Server@node2;Svr;node2.supernodexp.hpc;Scheduler sent command 0
02/19/2018 17:01:35;0100;Server@node2;Req;;Type 21 request received from Scheduler@node2.supernodexp.hpc, sock=20
02/19/2018 17:01:35;0100;Server@node2;Req;;Type 81 request received from Scheduler@node2.supernodexp.hpc, sock=20
02/19/2018 17:01:35;0100;Server@node2;Req;;Type 71 request received from Scheduler@node2.supernodexp.hpc, sock=20
02/19/2018 17:01:35;0100;Server@node2;Req;;Type 58 request received from Scheduler@node2.supernodexp.hpc, sock=20
02/19/2018 17:01:35;0100;Server@node2;Req;;Type 20 request received from Scheduler@node2.supernodexp.hpc, sock=20
02/19/2018 17:01:35;0100;Server@node2;Req;;Type 51 request received from Scheduler@node2.supernodexp.hpc, sock=20
02/19/2018 17:01:35;0100;Server@node2;Req;;Type 11 request received from Scheduler@node2.supernodexp.hpc, sock=20
02/19/2018 17:01:35;0008;Server@node2;Job;3811.node2.supernodexp.hpc;Job Modified at request of Scheduler@node2.supernodexp.hpc
02/19/2018 17:01:45;0100;Server@node2;Req;;Type 1 request received from ctminh@node2.supernodexp.hpc, sock=16
02/19/2018 17:01:45;0100;Server@node2;Req;;Type 3 request received from ctminh@node2.supernodexp.hpc, sock=16
02/19/2018 17:01:45;0100;Server@node2;Req;;Type 5 request received from ctminh@node2.supernodexp.hpc, sock=16
02/19/2018 17:01:45;0100;Server@node2;Job;3812.node2.supernodexp.hpc;enqueuing into workq, state 1 hop 1
02/19/2018 17:01:45;0008;Server@node2;Job;3812.node2.supernodexp.hpc;Job Queued at request of ctminh@node2.supernodexp.hpc, owner = ctminh@node2.supernodexp.hpc, job name = telemac2, queue = workq
02/19/2018 17:01:45;0040;Server@node2;Svr;node2.supernodexp.hpc;Scheduler sent command 1
02/19/2018 17:01:45;0040;Server@node2;Svr;node2.supernodexp.hpc;Scheduler sent command 0
02/19/2018 17:01:45;0100;Server@node2;Req;;Type 21 request received from Scheduler@node2.supernodexp.hpc, sock=20
02/19/2018 17:01:45;0100;Server@node2;Req;;Type 81 request received from Scheduler@node2.supernodexp.hpc, sock=20
02/19/2018 17:01:45;0100;Server@node2;Req;;Type 71 request received from Scheduler@node2.supernodexp.hpc, sock=20
02/19/2018 17:01:45;0100;Server@node2;Req;;Type 58 request received from Scheduler@node2.supernodexp.hpc, sock=20
02/19/2018 17:01:45;0100;Server@node2;Req;;Type 1 request received from ctminh@node2.supernodexp.hpc, sock=16
02/19/2018 17:01:45;0100;Server@node2;Req;;Type 3 request received from ctminh@node2.supernodexp.hpc, sock=16
02/19/2018 17:01:45;0100;Server@node2;Req;;Type 5 request received from ctminh@node2.supernodexp.hpc, sock=16
02/19/2018 17:01:45;0100;Server@node2;Job;3813.node2.supernodexp.hpc;enqueuing into workq, state 1 hop 1
02/19/2018 17:01:45;0008;Server@node2;Job;3813.node2.supernodexp.hpc;Job Queued at request of ctminh@node2.supernodexp.hpc, owner = ctminh@node2.supernodexp.hpc, job name = nbody, queue = workq
02/19/2018 17:01:45;0100;Server@node2;Req;;Type 20 request received from Scheduler@node2.supernodexp.hpc, sock=20
02/19/2018 17:01:45;0100;Server@node2;Req;;Type 51 request received from Scheduler@node2.supernodexp.hpc, sock=20
02/19/2018 17:01:45;0100;Server@node2;Req;;Type 11 request received from Scheduler@node2.supernodexp.hpc, sock=20
02/19/2018 17:01:45;0008;Server@node2;Job;3812.node2.supernodexp.hpc;Job Modified at request of Scheduler@node2.supernodexp.hpc
02/19/2018 17:01:45;0100;Server@node2;Req;;Type 11 request received from Scheduler@node2.supernodexp.hpc, sock=20
02/19/2018 17:01:45;0008;Server@node2;Job;3813.node2.supernodexp.hpc;Job Modified at request of Scheduler@node2.supernodexp.hpc
02/19/2018 17:01:45;0040;Server@node2;Svr;node2.supernodexp.hpc;Scheduler sent command 1
02/19/2018 17:01:45;0040;Server@node2;Svr;node2.supernodexp.hpc;Scheduler sent command 0
02/19/2018 17:01:45;0100;Server@node2;Req;;Type 21 request received from Scheduler@node2.supernodexp.hpc, sock=20
02/19/2018 17:01:45;0100;Server@node2;Req;;Type 81 request received from Scheduler@node2.supernodexp.hpc, sock=20
02/19/2018 17:01:45;0100;Server@node2;Req;;Type 71 request received from Scheduler@node2.supernodexp.hpc, sock=20
02/19/2018 17:01:45;0100;Server@node2;Req;;Type 58 request received from Scheduler@node2.supernodexp.hpc, sock=20
02/19/2018 17:01:45;0100;Server@node2;Req;;Type 20 request received from Scheduler@node2.supernodexp.hpc, sock=20
02/19/2018 17:01:45;0100;Server@node2;Req;;Type 51 request received from Scheduler@node2.supernodexp.hpc, sock=20
02/19/2018 17:01:51;0100;Server@node2;Req;;Type 1 request received from ctminh@node2.supernodexp.hpc, sock=16
02/19/2018 17:01:51;0100;Server@node2;Req;;Type 3 request received from ctminh@node2.supernodexp.hpc, sock=16
02/19/2018 17:01:51;0100;Server@node2;Req;;Type 5 request received from ctminh@node2.supernodexp.hpc, sock=16
02/19/2018 17:01:51;0100;Server@node2;Job;3814.node2.supernodexp.hpc;enqueuing into workq, state 1 hop 1
02/19/2018 17:01:51;0008;Server@node2;Job;3814.node2.supernodexp.hpc;Job Queued at request of ctminh@node2.supernodexp.hpc, owner = ctminh@node2.supernodexp.hpc, job name = thread-affinity, queue = workq
02/19/2018 17:01:51;0040;Server@node2;Svr;node2.supernodexp.hpc;Scheduler sent command 1
02/19/2018 17:01:51;0040;Server@node2;Svr;node2.supernodexp.hpc;Scheduler sent command 0
02/19/2018 17:01:51;0100;Server@node2;Req;;Type 21 request received from Scheduler@node2.supernodexp.hpc, sock=20
02/19/2018 17:01:51;0100;Server@node2;Req;;Type 81 request received from Scheduler@node2.supernodexp.hpc, sock=20
02/19/2018 17:01:51;0100;Server@node2;Req;;Type 71 request received from Scheduler@node2.supernodexp.hpc, sock=20
02/19/2018 17:01:51;0100;Server@node2;Req;;Type 58 request received from Scheduler@node2.supernodexp.hpc, sock=20
02/19/2018 17:01:51;0100;Server@node2;Req;;Type 20 request received from Scheduler@node2.supernodexp.hpc, sock=20
02/19/2018 17:01:51;0100;Server@node2;Req;;Type 51 request received from Scheduler@node2.supernodexp.hpc, sock=20
02/19/2018 17:01:51;0100;Server@node2;Req;;Type 11 request received from Scheduler@node2.supernodexp.hpc, sock=20
02/19/2018 17:01:51;0008;Server@node2;Job;3814.node2.supernodexp.hpc;Job Modified at request of Scheduler@node2.supernodexp.hpc
02/19/2018 17:01:54;0080;Server@node2;Job;3668.node2.supernodexp.hpc;Obit received momhop:1 serverhop:1 state:4 substate:42
02/19/2018 17:01:57;0010;Server@node2;Job;3668.node2.supernodexp.hpc;Exit_status=2 resources_used.cpupercent=2239 resources_used.cput=06:37:32 resources_used.mem=22025848kb resources_used.ncpus=32 resources_used.vmem=25065432kb resources_used.walltime=00:18:32
02/19/2018 17:01:57;0100;Server@node2;Job;3668.node2.supernodexp.hpc;dequeuing from workq, state 5
02/19/2018 17:01:57;0040;Server@node2;Svr;node2.supernodexp.hpc;Scheduler sent command 2
02/19/2018 17:01:57;0040;Server@node2;Svr;node2.supernodexp.hpc;Scheduler sent command 0
02/19/2018 17:01:57;0100;Server@node2;Req;;Type 21 request received from Scheduler@node2.supernodexp.hpc, sock=20
02/19/2018 17:01:57;0100;Server@node2;Req;;Type 81 request received from Scheduler@node2.supernodexp.hpc, sock=20
02/19/2018 17:01:57;0100;Server@node2;Req;;Type 71 request received from Scheduler@node2.supernodexp.hpc, sock=20
02/19/2018 17:01:57;0100;Server@node2;Req;;Type 58 request received from Scheduler@node2.supernodexp.hpc, sock=20
02/19/2018 17:01:57;0100;Server@node2;Req;;Type 20 request received from Scheduler@node2.supernodexp.hpc, sock=20
02/19/2018 17:01:57;0100;Server@node2;Req;;Type 51 request received from Scheduler@node2.supernodexp.hpc, sock=20
02/19/2018 17:01:57;0100;Server@node2;Req;;Type 23 request received from Scheduler@node2.supernodexp.hpc, sock=20
02/19/2018 17:01:57;0008;Server@node2;Job;3676.node2.supernodexp.hpc;Job Run at request of Scheduler@node2.supernodexp.hpc on exec_vnode (node13:ncpus=32:nmics=1:mem=16777216kb)
02/19/2018 17:01:57;0001;Server@node2;Svr;Server@node2;Success (0) in req_runjob2, return value of svr_startjob is 0
02/19/2018 17:01:57;0100;Server@node2;Req;;Type 11 request received from Scheduler@node2.supernodexp.hpc, sock=20
02/19/2018 17:01:57;0008;Server@node2;Job;3679.node2.supernodexp.hpc;Job Modified at request of Scheduler@node2.supernodexp.hpc
02/19/2018 17:03:38;0080;Server@node2;Job;3672.node2.supernodexp.hpc;Obit received momhop:1 serverhop:1 state:4 substate:42
02/19/2018 17:03:39;0010;Server@node2;Job;3672.node2.supernodexp.hpc;Exit_status=2 resources_used.cpupercent=2128 resources_used.cput=06:13:05 resources_used.mem=21817680kb resources_used.ncpus=32 resources_used.vmem=24549716kb resources_used.walltime=00:18:19
02/19/2018 17:03:39;0100;Server@node2;Job;3672.node2.supernodexp.hpc;dequeuing from workq, state 5
02/19/2018 17:03:39;0040;Server@node2;Svr;node2.supernodexp.hpc;Scheduler sent command 2
02/19/2018 17:03:39;0040;Server@node2;Svr;node2.supernodexp.hpc;Scheduler sent command 0
02/19/2018 17:03:39;0100;Server@node2;Req;;Type 21 request received from Scheduler@node2.supernodexp.hpc, sock=16
02/19/2018 17:03:39;0100;Server@node2;Req;;Type 81 request received from Scheduler@node2.supernodexp.hpc, sock=16
02/19/2018 17:03:39;0100;Server@node2;Req;;Type 71 request received from Scheduler@node2.supernodexp.hpc, sock=16
02/19/2018 17:03:39;0100;Server@node2;Req;;Type 58 request received from Scheduler@node2.supernodexp.hpc, sock=16
02/19/2018 17:03:40;0100;Server@node2;Req;;Type 20 request received from Scheduler@node2.supernodexp.hpc, sock=16
02/19/2018 17:03:40;0100;Server@node2;Req;;Type 51 request received from Scheduler@node2.supernodexp.hpc, sock=16
02/19/2018 17:03:40;0100;Server@node2;Req;;Type 23 request received from Scheduler@node2.supernodexp.hpc, sock=16
02/19/2018 17:03:40;0008;Server@node2;Job;3679.node2.supernodexp.hpc;Job Run at request of Scheduler@node2.supernodexp.hpc on exec_vnode (node14:ncpus=32:nmics=1:mem=16777216kb)
02/19/2018 17:03:40;0001;Server@node2;Svr;Server@node2;Success (0) in req_runjob2, return value of svr_startjob is 0
02/19/2018 17:03:40;0100;Server@node2;Req;;Type 11 request received from Scheduler@node2.supernodexp.hpc, sock=16
02/19/2018 17:03:40;0008;Server@node2;Job;3686.node2.supernodexp.hpc;Job Modified at request of Scheduler@node2.supernodexp.hpc
02/19/2018 17:05:19;0100;Server@node2;Req;;Type 0 request received from ctminh@node2.supernodexp.hpc, sock=16
02/19/2018 17:05:19;0100;Server@node2;Req;;Type 49 request received from ctminh@node2.supernodexp.hpc, sock=20
02/19/2018 17:05:19;0100;Server@node2;Req;;Type 21 request received from ctminh@node2.supernodexp.hpc, sock=16
02/19/2018 17:05:19;0100;Server@node2;Req;;Type 1 request received from ctminh@node2.supernodexp.hpc, sock=16
02/19/2018 17:05:19;0100;Server@node2;Req;;Type 3 request received from ctminh@node2.supernodexp.hpc, sock=16
02/19/2018 17:05:19;0100;Server@node2;Req;;Type 5 request received from ctminh@node2.supernodexp.hpc, sock=16
02/19/2018 17:05:19;0100;Server@node2;Job;3815.node2.supernodexp.hpc;enqueuing into workq, state 1 hop 1
02/19/2018 17:05:19;0008;Server@node2;Job;3815.node2.supernodexp.hpc;Job Queued at request of ctminh@node2.supernodexp.hpc, owner = ctminh@node2.supernodexp.hpc, job name = qe_mic_test, queue = workq
02/19/2018 17:05:19;0040;Server@node2;Svr;node2.supernodexp.hpc;Scheduler sent command 1
02/19/2018 17:05:19;0040;Server@node2;Svr;node2.supernodexp.hpc;Scheduler sent command 0
02/19/2018 17:05:19;0100;Server@node2;Req;;Type 21 request received from Scheduler@node2.supernodexp.hpc, sock=20
02/19/2018 17:05:19;0100;Server@node2;Req;;Type 81 request received from Scheduler@node2.supernodexp.hpc, sock=20
02/19/2018 17:05:19;0100;Server@node2;Req;;Type 71 request received from Scheduler@node2.supernodexp.hpc, sock=20
02/19/2018 17:05:19;0100;Server@node2;Req;;Type 58 request received from Scheduler@node2.supernodexp.hpc, sock=20
02/19/2018 17:05:19;0100;Server@node2;Req;;Type 20 request received from Scheduler@node2.supernodexp.hpc, sock=20
02/19/2018 17:05:19;0100;Server@node2;Req;;Type 51 request received from Scheduler@node2.supernodexp.hpc, sock=20
02/19/2018 17:05:19;0100;Server@node2;Req;;Type 11 request received from Scheduler@node2.supernodexp.hpc, sock=20
02/19/2018 17:05:19;0008;Server@node2;Job;3815.node2.supernodexp.hpc;Job Modified at request of Scheduler@node2.supernodexp.hpc
02/19/2018 17:05:30;0100;Server@node2;Req;;Type 1 request received from ctminh@node2.supernodexp.hpc, sock=16
02/19/2018 17:05:30;0100;Server@node2;Req;;Type 3 request received from ctminh@node2.supernodexp.hpc, sock=16
02/19/2018 17:05:30;0100;Server@node2;Req;;Type 5 request received from ctminh@node2.supernodexp.hpc, sock=16
02/19/2018 17:05:30;0100;Server@node2;Job;3816.node2.supernodexp.hpc;enqueuing into workq, state 1 hop 1
02/19/2018 17:05:30;0008;Server@node2;Job;3816.node2.supernodexp.hpc;Job Queued at request of ctminh@node2.supernodexp.hpc, owner = ctminh@node2.supernodexp.hpc, job name = matrix-x-vector, queue = workq
02/19/2018 17:05:30;0040;Server@node2;Svr;node2.supernodexp.hpc;Scheduler sent command 1
02/19/2018 17:05:30;0040;Server@node2;Svr;node2.supernodexp.hpc;Scheduler sent command 0
02/19/2018 17:05:30;0100;Server@node2;Req;;Type 21 request received from Scheduler@node2.supernodexp.hpc, sock=20
02/19/2018 17:05:30;0100;Server@node2;Req;;Type 81 request received from Scheduler@node2.supernodexp.hpc, sock=20
02/19/2018 17:05:30;0100;Server@node2;Req;;Type 71 request received from Scheduler@node2.supernodexp.hpc, sock=20
02/19/2018 17:05:30;0100;Server@node2;Req;;Type 58 request received from Scheduler@node2.supernodexp.hpc, sock=20
02/19/2018 17:05:30;0100;Server@node2;Req;;Type 20 request received from Scheduler@node2.supernodexp.hpc, sock=20
02/19/2018 17:05:30;0100;Server@node2;Req;;Type 51 request received from Scheduler@node2.supernodexp.hpc, sock=20
02/19/2018 17:05:30;0100;Server@node2;Req;;Type 11 request received from Scheduler@node2.supernodexp.hpc, sock=20
02/19/2018 17:05:30;0008;Server@node2;Job;3816.node2.supernodexp.hpc;Job Modified at request of Scheduler@node2.supernodexp.hpc
02/19/2018 17:05:57;0100;Server@node2;Req;;Type 1 request received from ctminh@node2.supernodexp.hpc, sock=16
02/19/2018 17:05:57;0100;Server@node2;Req;;Type 3 request received from ctminh@node2.supernodexp.hpc, sock=16
02/19/2018 17:05:57;0100;Server@node2;Req;;Type 5 request received from ctminh@node2.supernodexp.hpc, sock=16
02/19/2018 17:05:57;0100;Server@node2;Job;3817.node2.supernodexp.hpc;enqueuing into workq, state 1 hop 1
02/19/2018 17:05:57;0008;Server@node2;Job;3817.node2.supernodexp.hpc;Job Queued at request of ctminh@node2.supernodexp.hpc, owner = ctminh@node2.supernodexp.hpc, job name = sweep, queue = workq
02/19/2018 17:05:57;0040;Server@node2;Svr;node2.supernodexp.hpc;Scheduler sent command 1
02/19/2018 17:05:57;0040;Server@node2;Svr;node2.supernodexp.hpc;Scheduler sent command 0
02/19/2018 17:05:57;0100;Server@node2;Req;;Type 21 request received from Scheduler@node2.supernodexp.hpc, sock=20
02/19/2018 17:05:57;0100;Server@node2;Req;;Type 81 request received from Scheduler@node2.supernodexp.hpc, sock=20
02/19/2018 17:05:57;0100;Server@node2;Req;;Type 71 request received from Scheduler@node2.supernodexp.hpc, sock=20
02/19/2018 17:05:57;0100;Server@node2;Req;;Type 58 request received from Scheduler@node2.supernodexp.hpc, sock=20
02/19/2018 17:05:57;0100;Server@node2;Req;;Type 20 request received from Scheduler@node2.supernodexp.hpc, sock=20
02/19/2018 17:05:57;0100;Server@node2;Req;;Type 51 request received from Scheduler@node2.supernodexp.hpc, sock=20
02/19/2018 17:05:57;0100;Server@node2;Req;;Type 11 request received from Scheduler@node2.supernodexp.hpc, sock=20
02/19/2018 17:05:57;0008;Server@node2;Job;3817.node2.supernodexp.hpc;Job Modified at request of Scheduler@node2.supernodexp.hpc
02/19/2018 17:05:58;0100;Server@node2;Req;;Type 1 request received from ctminh@node2.supernodexp.hpc, sock=16
02/19/2018 17:05:58;0100;Server@node2;Req;;Type 3 request received from ctminh@node2.supernodexp.hpc, sock=16
02/19/2018 17:05:58;0100;Server@node2;Req;;Type 5 request received from ctminh@node2.supernodexp.hpc, sock=16
02/19/2018 17:05:58;0100;Server@node2;Job;3818.node2.supernodexp.hpc;enqueuing into workq, state 1 hop 1
02/19/2018 17:05:58;0008;Server@node2;Job;3818.node2.supernodexp.hpc;Job Queued at request of ctminh@node2.supernodexp.hpc, owner = ctminh@node2.supernodexp.hpc, job name = vectorization, queue = workq
02/19/2018 17:05:58;0040;Server@node2;Svr;node2.supernodexp.hpc;Scheduler sent command 1
02/19/2018 17:05:58;0040;Server@node2;Svr;node2.supernodexp.hpc;Scheduler sent command 0
02/19/2018 17:05:58;0100;Server@node2;Req;;Type 21 request received from Scheduler@node2.supernodexp.hpc, sock=20
02/19/2018 17:05:58;0100;Server@node2;Req;;Type 81 request received from Scheduler@node2.supernodexp.hpc, sock=20
02/19/2018 17:05:58;0100;Server@node2;Req;;Type 71 request received from Scheduler@node2.supernodexp.hpc, sock=20
02/19/2018 17:05:58;0100;Server@node2;Req;;Type 58 request received from Scheduler@node2.supernodexp.hpc, sock=20
02/19/2018 17:05:58;0100;Server@node2;Req;;Type 20 request received from Scheduler@node2.supernodexp.hpc, sock=20
02/19/2018 17:05:58;0100;Server@node2;Req;;Type 51 request received from Scheduler@node2.supernodexp.hpc, sock=20
02/19/2018 17:05:58;0100;Server@node2;Req;;Type 11 request received from Scheduler@node2.supernodexp.hpc, sock=20
02/19/2018 17:05:58;0008;Server@node2;Job;3818.node2.supernodexp.hpc;Job Modified at request of Scheduler@node2.supernodexp.hpc
02/19/2018 17:06:00;0100;Server@node2;Req;;Type 1 request received from ctminh@node2.supernodexp.hpc, sock=16
02/19/2018 17:06:00;0100;Server@node2;Req;;Type 3 request received from ctminh@node2.supernodexp.hpc, sock=16
02/19/2018 17:06:00;0100;Server@node2;Req;;Type 5 request received from ctminh@node2.supernodexp.hpc, sock=16
02/19/2018 17:06:00;0100;Server@node2;Job;3819.node2.supernodexp.hpc;enqueuing into workq, state 1 hop 1
02/19/2018 17:06:00;0008;Server@node2;Job;3819.node2.supernodexp.hpc;Job Queued at request of ctminh@node2.supernodexp.hpc, owner = ctminh@node2.supernodexp.hpc, job name = thread-affinity, queue = workq
02/19/2018 17:06:00;0040;Server@node2;Svr;node2.supernodexp.hpc;Scheduler sent command 1
02/19/2018 17:06:00;0040;Server@node2;Svr;node2.supernodexp.hpc;Scheduler sent command 0
02/19/2018 17:06:00;0100;Server@node2;Req;;Type 21 request received from Scheduler@node2.supernodexp.hpc, sock=20
02/19/2018 17:06:00;0100;Server@node2;Req;;Type 81 request received from Scheduler@node2.supernodexp.hpc, sock=20
02/19/2018 17:06:00;0100;Server@node2;Req;;Type 71 request received from Scheduler@node2.supernodexp.hpc, sock=20
02/19/2018 17:06:00;0100;Server@node2;Req;;Type 58 request received from Scheduler@node2.supernodexp.hpc, sock=20
02/19/2018 17:06:00;0100;Server@node2;Req;;Type 20 request received from Scheduler@node2.supernodexp.hpc, sock=20
02/19/2018 17:06:00;0100;Server@node2;Req;;Type 51 request received from Scheduler@node2.supernodexp.hpc, sock=20
02/19/2018 17:06:00;0100;Server@node2;Req;;Type 11 request received from Scheduler@node2.supernodexp.hpc, sock=20
02/19/2018 17:06:00;0008;Server@node2;Job;3819.node2.supernodexp.hpc;Job Modified at request of Scheduler@node2.supernodexp.hpc
02/19/2018 17:06:01;0100;Server@node2;Req;;Type 1 request received from ctminh@node2.supernodexp.hpc, sock=16
02/19/2018 17:06:01;0100;Server@node2;Req;;Type 3 request received from ctminh@node2.supernodexp.hpc, sock=16
02/19/2018 17:06:01;0100;Server@node2;Req;;Type 5 request received from ctminh@node2.supernodexp.hpc, sock=16
02/19/2018 17:06:01;0100;Server@node2;Job;3820.node2.supernodexp.hpc;enqueuing into workq, state 1 hop 1
02/19/2018 17:06:01;0008;Server@node2;Job;3820.node2.supernodexp.hpc;Job Queued at request of ctminh@node2.supernodexp.hpc, owner = ctminh@node2.supernodexp.hpc, job name = jacobi, queue = workq
02/19/2018 17:06:01;0040;Server@node2;Svr;node2.supernodexp.hpc;Scheduler sent command 1
02/19/2018 17:06:01;0040;Server@node2;Svr;node2.supernodexp.hpc;Scheduler sent command 0
02/19/2018 17:06:01;0100;Server@node2;Req;;Type 21 request received from Scheduler@node2.supernodexp.hpc, sock=20
02/19/2018 17:06:01;0100;Server@node2;Req;;Type 81 request received from Scheduler@node2.supernodexp.hpc, sock=20
02/19/2018 17:06:01;0100;Server@node2;Req;;Type 71 request received from Scheduler@node2.supernodexp.hpc, sock=20
02/19/2018 17:06:01;0100;Server@node2;Req;;Type 58 request received from Scheduler@node2.supernodexp.hpc, sock=20
02/19/2018 17:06:01;0100;Server@node2;Req;;Type 20 request received from Scheduler@node2.supernodexp.hpc, sock=20
02/19/2018 17:06:01;0100;Server@node2;Req;;Type 51 request received from Scheduler@node2.supernodexp.hpc, sock=20
02/19/2018 17:06:02;0100;Server@node2;Req;;Type 11 request received from Scheduler@node2.supernodexp.hpc, sock=20
02/19/2018 17:06:02;0008;Server@node2;Job;3820.node2.supernodexp.hpc;Job Modified at request of Scheduler@node2.supernodexp.hpc
02/19/2018 17:06:02;0100;Server@node2;Req;;Type 1 request received from ctminh@node2.supernodexp.hpc, sock=16
02/19/2018 17:06:02;0100;Server@node2;Req;;Type 3 request received from ctminh@node2.supernodexp.hpc, sock=16
02/19/2018 17:06:02;0100;Server@node2;Req;;Type 5 request received from ctminh@node2.supernodexp.hpc, sock=16
02/19/2018 17:06:02;0100;Server@node2;Job;3821.node2.supernodexp.hpc;enqueuing into workq, state 1 hop 1
02/19/2018 17:06:02;0008;Server@node2;Job;3821.node2.supernodexp.hpc;Job Queued at request of ctminh@node2.supernodexp.hpc, owner = ctminh@node2.supernodexp.hpc, job name = matrix-x-vector, queue = workq
02/19/2018 17:06:02;0040;Server@node2;Svr;node2.supernodexp.hpc;Scheduler sent command 1
02/19/2018 17:06:02;0040;Server@node2;Svr;node2.supernodexp.hpc;Scheduler sent command 0
02/19/2018 17:06:02;0100;Server@node2;Req;;Type 21 request received from Scheduler@node2.supernodexp.hpc, sock=20
02/19/2018 17:06:02;0100;Server@node2;Req;;Type 81 request received from Scheduler@node2.supernodexp.hpc, sock=20
02/19/2018 17:06:02;0100;Server@node2;Req;;Type 71 request received from Scheduler@node2.supernodexp.hpc, sock=20
02/19/2018 17:06:02;0100;Server@node2;Req;;Type 58 request received from Scheduler@node2.supernodexp.hpc, sock=20
02/19/2018 17:06:02;0100;Server@node2;Req;;Type 20 request received from Scheduler@node2.supernodexp.hpc, sock=20
02/19/2018 17:06:02;0100;Server@node2;Req;;Type 51 request received from Scheduler@node2.supernodexp.hpc, sock=20
02/19/2018 17:06:03;0100;Server@node2;Req;;Type 11 request received from Scheduler@node2.supernodexp.hpc, sock=20
02/19/2018 17:06:03;0008;Server@node2;Job;3821.node2.supernodexp.hpc;Job Modified at request of Scheduler@node2.supernodexp.hpc
02/19/2018 17:06:10;0100;Server@node2;Req;;Type 1 request received from ctminh@node2.supernodexp.hpc, sock=16
02/19/2018 17:06:10;0100;Server@node2;Req;;Type 3 request received from ctminh@node2.supernodexp.hpc, sock=16
02/19/2018 17:06:10;0100;Server@node2;Req;;Type 5 request received from ctminh@node2.supernodexp.hpc, sock=16
02/19/2018 17:06:10;0100;Server@node2;Job;3822.node2.supernodexp.hpc;enqueuing into workq, state 1 hop 1
02/19/2018 17:06:10;0008;Server@node2;Job;3822.node2.supernodexp.hpc;Job Queued at request of ctminh@node2.supernodexp.hpc, owner = ctminh@node2.supernodexp.hpc, job name = nbody, queue = workq
02/19/2018 17:06:10;0040;Server@node2;Svr;node2.supernodexp.hpc;Scheduler sent command 1
02/19/2018 17:06:10;0040;Server@node2;Svr;node2.supernodexp.hpc;Scheduler sent command 0
02/19/2018 17:06:10;0100;Server@node2;Req;;Type 21 request received from Scheduler@node2.supernodexp.hpc, sock=20
02/19/2018 17:06:10;0100;Server@node2;Req;;Type 81 request received from Scheduler@node2.supernodexp.hpc, sock=20
02/19/2018 17:06:10;0100;Server@node2;Req;;Type 71 request received from Scheduler@node2.supernodexp.hpc, sock=20
02/19/2018 17:06:10;0100;Server@node2;Req;;Type 58 request received from Scheduler@node2.supernodexp.hpc, sock=20
02/19/2018 17:06:11;0100;Server@node2;Req;;Type 20 request received from Scheduler@node2.supernodexp.hpc, sock=20
02/19/2018 17:06:11;0100;Server@node2;Req;;Type 51 request received from Scheduler@node2.supernodexp.hpc, sock=20
02/19/2018 17:06:11;0100;Server@node2;Req;;Type 11 request received from Scheduler@node2.supernodexp.hpc, sock=20
02/19/2018 17:06:11;0008;Server@node2;Job;3822.node2.supernodexp.hpc;Job Modified at request of Scheduler@node2.supernodexp.hpc
02/19/2018 17:06:17;0100;Server@node2;Req;;Type 1 request received from ctminh@node2.supernodexp.hpc, sock=16
02/19/2018 17:06:17;0100;Server@node2;Req;;Type 3 request received from ctminh@node2.supernodexp.hpc, sock=16
02/19/2018 17:06:17;0100;Server@node2;Req;;Type 5 request received from ctminh@node2.supernodexp.hpc, sock=16
02/19/2018 17:06:17;0100;Server@node2;Job;3823.node2.supernodexp.hpc;enqueuing into workq, state 1 hop 1
02/19/2018 17:06:18;0008;Server@node2;Job;3823.node2.supernodexp.hpc;Job Queued at request of ctminh@node2.supernodexp.hpc, owner = ctminh@node2.supernodexp.hpc, job name = nbody, queue = workq
02/19/2018 17:06:18;0040;Server@node2;Svr;node2.supernodexp.hpc;Scheduler sent command 1
02/19/2018 17:06:18;0040;Server@node2;Svr;node2.supernodexp.hpc;Scheduler sent command 0
02/19/2018 17:06:18;0100;Server@node2;Req;;Type 21 request received from Scheduler@node2.supernodexp.hpc, sock=20
02/19/2018 17:06:18;0100;Server@node2;Req;;Type 81 request received from Scheduler@node2.supernodexp.hpc, sock=20
02/19/2018 17:06:18;0100;Server@node2;Req;;Type 71 request received from Scheduler@node2.supernodexp.hpc, sock=20
02/19/2018 17:06:18;0100;Server@node2;Req;;Type 58 request received from Scheduler@node2.supernodexp.hpc, sock=20
02/19/2018 17:06:18;0100;Server@node2;Req;;Type 20 request received from Scheduler@node2.supernodexp.hpc, sock=20
02/19/2018 17:06:18;0100;Server@node2;Req;;Type 51 request received from Scheduler@node2.supernodexp.hpc, sock=20
02/19/2018 17:06:18;0100;Server@node2;Req;;Type 11 request received from Scheduler@node2.supernodexp.hpc, sock=20
02/19/2018 17:06:18;0008;Server@node2;Job;3823.node2.supernodexp.hpc;Job Modified at request of Scheduler@node2.supernodexp.hpc
02/19/2018 17:06:24;0100;Server@node2;Req;;Type 1 request received from ctminh@node2.supernodexp.hpc, sock=16
02/19/2018 17:06:24;0100;Server@node2;Req;;Type 3 request received from ctminh@node2.supernodexp.hpc, sock=16
02/19/2018 17:06:24;0100;Server@node2;Req;;Type 5 request received from ctminh@node2.supernodexp.hpc, sock=16
02/19/2018 17:06:24;0100;Server@node2;Job;3824.node2.supernodexp.hpc;enqueuing into workq, state 1 hop 1
02/19/2018 17:06:24;0008;Server@node2;Job;3824.node2.supernodexp.hpc;Job Queued at request of ctminh@node2.supernodexp.hpc, owner = ctminh@node2.supernodexp.hpc, job name = nbody, queue = workq
02/19/2018 17:06:24;0040;Server@node2;Svr;node2.supernodexp.hpc;Scheduler sent command 1
02/19/2018 17:06:24;0040;Server@node2;Svr;node2.supernodexp.hpc;Scheduler sent command 0
02/19/2018 17:06:24;0100;Server@node2;Req;;Type 21 request received from Scheduler@node2.supernodexp.hpc, sock=20
02/19/2018 17:06:24;0100;Server@node2;Req;;Type 81 request received from Scheduler@node2.supernodexp.hpc, sock=20
02/19/2018 17:06:24;0100;Server@node2;Req;;Type 71 request received from Scheduler@node2.supernodexp.hpc, sock=20
02/19/2018 17:06:24;0100;Server@node2;Req;;Type 58 request received from Scheduler@node2.supernodexp.hpc, sock=20
02/19/2018 17:06:24;0100;Server@node2;Req;;Type 20 request received from Scheduler@node2.supernodexp.hpc, sock=20
02/19/2018 17:06:24;0100;Server@node2;Req;;Type 51 request received from Scheduler@node2.supernodexp.hpc, sock=20
02/19/2018 17:06:24;0100;Server@node2;Req;;Type 11 request received from Scheduler@node2.supernodexp.hpc, sock=20
02/19/2018 17:06:24;0008;Server@node2;Job;3824.node2.supernodexp.hpc;Job Modified at request of Scheduler@node2.supernodexp.hpc
02/19/2018 17:06:52;0100;Server@node2;Req;;Type 1 request received from ctminh@node2.supernodexp.hpc, sock=16
02/19/2018 17:06:52;0100;Server@node2;Req;;Type 3 request received from ctminh@node2.supernodexp.hpc, sock=16
02/19/2018 17:06:52;0100;Server@node2;Req;;Type 5 request received from ctminh@node2.supernodexp.hpc, sock=16
02/19/2018 17:06:52;0100;Server@node2;Job;3825.node2.supernodexp.hpc;enqueuing into workq, state 1 hop 1
02/19/2018 17:06:52;0008;Server@node2;Job;3825.node2.supernodexp.hpc;Job Queued at request of ctminh@node2.supernodexp.hpc, owner = ctminh@node2.supernodexp.hpc, job name = matrix-x-vector, queue = workq
02/19/2018 17:06:52;0040;Server@node2;Svr;node2.supernodexp.hpc;Scheduler sent command 1
02/19/2018 17:06:52;0040;Server@node2;Svr;node2.supernodexp.hpc;Scheduler sent command 0
02/19/2018 17:06:52;0100;Server@node2;Req;;Type 21 request received from Scheduler@node2.supernodexp.hpc, sock=20
02/19/2018 17:06:52;0100;Server@node2;Req;;Type 81 request received from Scheduler@node2.supernodexp.hpc, sock=20
02/19/2018 17:06:52;0100;Server@node2;Req;;Type 71 request received from Scheduler@node2.supernodexp.hpc, sock=20
02/19/2018 17:06:52;0100;Server@node2;Req;;Type 58 request received from Scheduler@node2.supernodexp.hpc, sock=20
02/19/2018 17:06:52;0100;Server@node2;Req;;Type 20 request received from Scheduler@node2.supernodexp.hpc, sock=20
02/19/2018 17:06:52;0100;Server@node2;Req;;Type 51 request received from Scheduler@node2.supernodexp.hpc, sock=20
02/19/2018 17:06:52;0100;Server@node2;Req;;Type 11 request received from Scheduler@node2.supernodexp.hpc, sock=20
02/19/2018 17:06:52;0008;Server@node2;Job;3825.node2.supernodexp.hpc;Job Modified at request of Scheduler@node2.supernodexp.hpc
02/19/2018 17:07:10;0100;Server@node2;Req;;Type 1 request received from ctminh@node2.supernodexp.hpc, sock=16
02/19/2018 17:07:10;0100;Server@node2;Hook;_pbs_python_event_set;Restarting Python interpreter to reduce mem usage
02/19/2018 17:07:10;0100;Server@node2;Svr;Server@node2;--> Stopping Python interpreter <--
02/19/2018 17:07:10;0100;Server@node2;Svr;Server@node2;--> Python Interpreter started, compiled with version:'2.7.5' <--
02/19/2018 17:07:10;0100;Server@node2;Svr;Server@node2;sys.modules= {'pbs.v1._svr_types': <module 'pbs.v1._svr_types' from '/opt/pbs/lib/python/altair/pbs/v1/_svr_types.pyo'>, 'copy_reg': <module 'copy_reg' from '/usr/lib64/python2.7/copy_reg.pyo'>, 'pbs.v1._pbs_v1': None, '__main__': <module '__main__' (built-in)>, '__builtin__': <module '__builtin__' (built-in)>, '_pbs_v1.svr_types': <module '_pbs_v1.svr_types' (built-in)>, 'encodings': <module 'encodings' from '/usr/lib64/python2.7/encodings/__init__.pyo'>, 'encodings.encodings': None, 'abc': <module 'abc' from '/usr/lib64/python2.7/abc.pyo'>, 'pbs._pbs_v1': None, 'posixpath': <module 'posixpath' from '/usr/lib64/python2.7/posixpath.pyo'>, '_weakrefset': <module '_weakrefset' from '/usr/lib64/python2.7/_weakrefset.pyo'>, 'pbs.v1': <module 'pbs.v1' from '/opt/pbs/lib/python/altair/pbs/v1/__init__.pyo'>, 'errno': <module 'errno' (built-in)>, 'encodings.codecs': None, 'pbs.v1._export_types': <module 'pbs.v1._export_types' from '/opt/pbs/lib/python/altair/pbs/v1/_export_types.pyo'>, 'pbs.v1.os': None, '_abcoll': <module '_abcoll' from '/usr/lib64/python2.7/_abcoll.pyo'>, 'os.path': <module 'posixpath' from '/usr/lib64/python2.7/posixpath.pyo'>, 'UserDict': <module 'UserDict' from '/usr/lib64/python2.7/UserDict.pyo'>, '_warnings': <module '_warnings' (built-in)>, 'genericpath': <module 'genericpath' from '/usr/lib64/python2.7/genericpath.pyo'>, 'stat': <module 'stat' from '/usr/lib64/python2.7/stat.pyo'>, 'zipimport': <module 'zipimport' (built-in)>, 'encodings.__builtin__': None, 'pbs.pbs': None, 'warnings': <module 'warnings' from '/usr/lib64/python2.7/warnings.pyo'>, '_codecs': <module '_codecs' (built-in)>, 'encodings.ascii': <module 'encodings.ascii' from '/usr/lib64/python2.7/encodings/ascii.pyo'>, 'sys': <module 'sys' (built-in)>, 'pbs.v1._base_types': <module 'pbs.v1._base_types' from '/opt/pbs/lib/python/altair/pbs/v1/_base_types.pyo'>, 'pbs.v1.sys': None, 'codecs': <module 'codecs' from '/usr/lib64/python2.7/codecs.pyo'>, 'types': <module 'types' from '/usr/lib64/python2.7/types.pyo'>, 'pbs': <module 'pbs' from '/opt/pbs/lib/python/altair/pbs/__init__.pyo'>, 'os': <module 'os' from '/usr/lib64/python2.7/os.pyo'>, 'signal': <module 'signal' (built-in)>, 'linecache': <module 'linecache' from '/usr/lib64/python2.7/linecache.pyo'>, '_pbs_v1': <module '_pbs_v1' (built-in)>, 'posix': <module 'posix' (built-in)>, 'encodings.aliases': <module 'encodings.aliases' from '/usr/lib64/python2.7/encodings/aliases.pyo'>, 'exceptions': <module 'exceptions' (built-in)>, 'pbs.v1._exc_types': <module 'pbs.v1._exc_types' from '/opt/pbs/lib/python/altair/pbs/v1/_exc_types.pyo'>, '_weakref': <module '_weakref' (built-in)>}
02/19/2018 17:07:10;0106;Server@node2;Svr;Server@node2;BEGIN setting up all resource attributes 
02/19/2018 17:07:10;0106;Server@node2;Svr;Server@node2;DONE setting up all resource attributes, number set <51>
02/19/2018 17:07:10;0106;Server@node2;Svr;Server@node2;BEGIN setting up all queue attributes 
02/19/2018 17:07:10;0106;Server@node2;Svr;Server@node2;DONE setting up all queue attributes, number set <55>
02/19/2018 17:07:10;0106;Server@node2;Svr;Server@node2;BEGIN setting up all job attributes 
02/19/2018 17:07:10;0106;Server@node2;Svr;Server@node2;DONE setting up all job attributes, number set <94>
02/19/2018 17:07:10;0106;Server@node2;Svr;Server@node2;BEGIN setting up all server attributes 
02/19/2018 17:07:10;0106;Server@node2;Svr;Server@node2;DONE setting up all server attributes, number set <88>
02/19/2018 17:07:10;0106;Server@node2;Svr;Server@node2;BEGIN setting up all reservation attributes 
02/19/2018 17:07:10;0106;Server@node2;Svr;Server@node2;DONE setting up all reservation attributes, number set <43>
02/19/2018 17:07:10;0106;Server@node2;Svr;Server@node2;BEGIN setting up all vnode attributes 
02/19/2018 17:07:10;0106;Server@node2;Svr;Server@node2;DONE setting up all vnode attributes, number set <28>
02/19/2018 17:07:10;0100;Server@node2;Hook;_pbs_python_event_set;Current memory usage: VmSize=325844kB, VmRSS=17476kB
02/19/2018 17:07:10;0100;Server@node2;Req;;Type 3 request received from ctminh@node2.supernodexp.hpc, sock=16
02/19/2018 17:07:10;0100;Server@node2;Req;;Type 5 request received from ctminh@node2.supernodexp.hpc, sock=16
02/19/2018 17:07:10;0100;Server@node2;Job;3826.node2.supernodexp.hpc;enqueuing into workq, state 1 hop 1
02/19/2018 17:07:10;0008;Server@node2;Job;3826.node2.supernodexp.hpc;Job Queued at request of ctminh@node2.supernodexp.hpc, owner = ctminh@node2.supernodexp.hpc, job name = jacobi, queue = workq
02/19/2018 17:07:10;0040;Server@node2;Svr;node2.supernodexp.hpc;Scheduler sent command 1
02/19/2018 17:07:10;0040;Server@node2;Svr;node2.supernodexp.hpc;Scheduler sent command 0
02/19/2018 17:07:10;0100;Server@node2;Req;;Type 21 request received from Scheduler@node2.supernodexp.hpc, sock=20
02/19/2018 17:07:10;0100;Server@node2;Req;;Type 81 request received from Scheduler@node2.supernodexp.hpc, sock=20
02/19/2018 17:07:10;0100;Server@node2;Req;;Type 71 request received from Scheduler@node2.supernodexp.hpc, sock=20
02/19/2018 17:07:10;0100;Server@node2;Req;;Type 58 request received from Scheduler@node2.supernodexp.hpc, sock=20
02/19/2018 17:07:10;0100;Server@node2;Req;;Type 1 request received from ctminh@node2.supernodexp.hpc, sock=16
02/19/2018 17:07:10;0100;Server@node2;Req;;Type 3 request received from ctminh@node2.supernodexp.hpc, sock=16
02/19/2018 17:07:10;0100;Server@node2;Req;;Type 5 request received from ctminh@node2.supernodexp.hpc, sock=16
02/19/2018 17:07:10;0100;Server@node2;Job;3827.node2.supernodexp.hpc;enqueuing into workq, state 1 hop 1
02/19/2018 17:07:10;0008;Server@node2;Job;3827.node2.supernodexp.hpc;Job Queued at request of ctminh@node2.supernodexp.hpc, owner = ctminh@node2.supernodexp.hpc, job name = nbody, queue = workq
02/19/2018 17:07:10;0100;Server@node2;Req;;Type 20 request received from Scheduler@node2.supernodexp.hpc, sock=20
02/19/2018 17:07:10;0100;Server@node2;Req;;Type 51 request received from Scheduler@node2.supernodexp.hpc, sock=20
02/19/2018 17:07:10;0100;Server@node2;Req;;Type 11 request received from Scheduler@node2.supernodexp.hpc, sock=20
02/19/2018 17:07:10;0008;Server@node2;Job;3826.node2.supernodexp.hpc;Job Modified at request of Scheduler@node2.supernodexp.hpc
02/19/2018 17:07:10;0100;Server@node2;Req;;Type 11 request received from Scheduler@node2.supernodexp.hpc, sock=20
02/19/2018 17:07:10;0008;Server@node2;Job;3827.node2.supernodexp.hpc;Job Modified at request of Scheduler@node2.supernodexp.hpc
02/19/2018 17:07:10;0040;Server@node2;Svr;node2.supernodexp.hpc;Scheduler sent command 1
02/19/2018 17:07:10;0040;Server@node2;Svr;node2.supernodexp.hpc;Scheduler sent command 0
02/19/2018 17:07:10;0100;Server@node2;Req;;Type 21 request received from Scheduler@node2.supernodexp.hpc, sock=20
02/19/2018 17:07:10;0100;Server@node2;Req;;Type 81 request received from Scheduler@node2.supernodexp.hpc, sock=20
02/19/2018 17:07:10;0100;Server@node2;Req;;Type 71 request received from Scheduler@node2.supernodexp.hpc, sock=20
02/19/2018 17:07:10;0100;Server@node2;Req;;Type 58 request received from Scheduler@node2.supernodexp.hpc, sock=20
02/19/2018 17:07:10;0100;Server@node2;Req;;Type 20 request received from Scheduler@node2.supernodexp.hpc, sock=20
02/19/2018 17:07:10;0100;Server@node2;Req;;Type 51 request received from Scheduler@node2.supernodexp.hpc, sock=20
02/19/2018 17:07:16;0100;Server@node2;Req;;Type 1 request received from ctminh@node2.supernodexp.hpc, sock=16
02/19/2018 17:07:16;0100;Server@node2;Req;;Type 3 request received from ctminh@node2.supernodexp.hpc, sock=16
02/19/2018 17:07:16;0100;Server@node2;Req;;Type 5 request received from ctminh@node2.supernodexp.hpc, sock=16
02/19/2018 17:07:16;0100;Server@node2;Job;3828.node2.supernodexp.hpc;enqueuing into workq, state 1 hop 1
02/19/2018 17:07:16;0008;Server@node2;Job;3828.node2.supernodexp.hpc;Job Queued at request of ctminh@node2.supernodexp.hpc, owner = ctminh@node2.supernodexp.hpc, job name = telemac1, queue = workq
02/19/2018 17:07:16;0040;Server@node2;Svr;node2.supernodexp.hpc;Scheduler sent command 1
02/19/2018 17:07:16;0040;Server@node2;Svr;node2.supernodexp.hpc;Scheduler sent command 0
02/19/2018 17:07:16;0100;Server@node2;Req;;Type 21 request received from Scheduler@node2.supernodexp.hpc, sock=20
02/19/2018 17:07:16;0100;Server@node2;Req;;Type 81 request received from Scheduler@node2.supernodexp.hpc, sock=20
02/19/2018 17:07:16;0100;Server@node2;Req;;Type 71 request received from Scheduler@node2.supernodexp.hpc, sock=20
02/19/2018 17:07:16;0100;Server@node2;Req;;Type 58 request received from Scheduler@node2.supernodexp.hpc, sock=20
02/19/2018 17:07:16;0100;Server@node2;Req;;Type 20 request received from Scheduler@node2.supernodexp.hpc, sock=20
02/19/2018 17:07:16;0100;Server@node2;Req;;Type 51 request received from Scheduler@node2.supernodexp.hpc, sock=20
02/19/2018 17:07:16;0100;Server@node2;Req;;Type 11 request received from Scheduler@node2.supernodexp.hpc, sock=20
02/19/2018 17:07:16;0008;Server@node2;Job;3828.node2.supernodexp.hpc;Job Modified at request of Scheduler@node2.supernodexp.hpc
02/19/2018 17:08:21;0100;Server@node2;Req;;Type 0 request received from ctminh@node2.supernodexp.hpc, sock=16
02/19/2018 17:08:21;0100;Server@node2;Req;;Type 49 request received from ctminh@node2.supernodexp.hpc, sock=20
02/19/2018 17:08:21;0100;Server@node2;Req;;Type 21 request received from ctminh@node2.supernodexp.hpc, sock=16
02/19/2018 17:08:21;0100;Server@node2;Req;;Type 1 request received from ctminh@node2.supernodexp.hpc, sock=16
02/19/2018 17:08:21;0100;Server@node2;Req;;Type 3 request received from ctminh@node2.supernodexp.hpc, sock=16
02/19/2018 17:08:21;0100;Server@node2;Req;;Type 5 request received from ctminh@node2.supernodexp.hpc, sock=16
02/19/2018 17:08:21;0100;Server@node2;Job;3829.node2.supernodexp.hpc;enqueuing into workq, state 1 hop 1
02/19/2018 17:08:21;0008;Server@node2;Job;3829.node2.supernodexp.hpc;Job Queued at request of ctminh@node2.supernodexp.hpc, owner = ctminh@node2.supernodexp.hpc, job name = qe_mic_test, queue = workq
02/19/2018 17:08:21;0040;Server@node2;Svr;node2.supernodexp.hpc;Scheduler sent command 1
02/19/2018 17:08:21;0040;Server@node2;Svr;node2.supernodexp.hpc;Scheduler sent command 0
02/19/2018 17:08:21;0100;Server@node2;Req;;Type 21 request received from Scheduler@node2.supernodexp.hpc, sock=20
02/19/2018 17:08:21;0100;Server@node2;Req;;Type 81 request received from Scheduler@node2.supernodexp.hpc, sock=20
02/19/2018 17:08:21;0100;Server@node2;Req;;Type 71 request received from Scheduler@node2.supernodexp.hpc, sock=20
02/19/2018 17:08:21;0100;Server@node2;Req;;Type 58 request received from Scheduler@node2.supernodexp.hpc, sock=20
02/19/2018 17:08:21;0100;Server@node2;Req;;Type 20 request received from Scheduler@node2.supernodexp.hpc, sock=20
02/19/2018 17:08:21;0100;Server@node2;Req;;Type 51 request received from Scheduler@node2.supernodexp.hpc, sock=20
02/19/2018 17:08:21;0100;Server@node2;Req;;Type 11 request received from Scheduler@node2.supernodexp.hpc, sock=20
02/19/2018 17:08:21;0008;Server@node2;Job;3829.node2.supernodexp.hpc;Job Modified at request of Scheduler@node2.supernodexp.hpc
02/19/2018 17:08:22;0100;Server@node2;Req;;Type 1 request received from ctminh@node2.supernodexp.hpc, sock=16
02/19/2018 17:08:22;0100;Server@node2;Req;;Type 3 request received from ctminh@node2.supernodexp.hpc, sock=16
02/19/2018 17:08:22;0100;Server@node2;Req;;Type 5 request received from ctminh@node2.supernodexp.hpc, sock=16
02/19/2018 17:08:22;0100;Server@node2;Job;3830.node2.supernodexp.hpc;enqueuing into workq, state 1 hop 1
02/19/2018 17:08:22;0008;Server@node2;Job;3830.node2.supernodexp.hpc;Job Queued at request of ctminh@node2.supernodexp.hpc, owner = ctminh@node2.supernodexp.hpc, job name = thread-affinity, queue = workq
02/19/2018 17:08:22;0040;Server@node2;Svr;node2.supernodexp.hpc;Scheduler sent command 1
02/19/2018 17:08:22;0040;Server@node2;Svr;node2.supernodexp.hpc;Scheduler sent command 0
02/19/2018 17:08:22;0100;Server@node2;Req;;Type 21 request received from Scheduler@node2.supernodexp.hpc, sock=20
02/19/2018 17:08:22;0100;Server@node2;Req;;Type 81 request received from Scheduler@node2.supernodexp.hpc, sock=20
02/19/2018 17:08:22;0100;Server@node2;Req;;Type 71 request received from Scheduler@node2.supernodexp.hpc, sock=20
02/19/2018 17:08:22;0100;Server@node2;Req;;Type 58 request received from Scheduler@node2.supernodexp.hpc, sock=20
02/19/2018 17:08:22;0100;Server@node2;Req;;Type 20 request received from Scheduler@node2.supernodexp.hpc, sock=20
02/19/2018 17:08:22;0100;Server@node2;Req;;Type 51 request received from Scheduler@node2.supernodexp.hpc, sock=20
02/19/2018 17:08:22;0100;Server@node2;Req;;Type 11 request received from Scheduler@node2.supernodexp.hpc, sock=20
02/19/2018 17:08:22;0008;Server@node2;Job;3830.node2.supernodexp.hpc;Job Modified at request of Scheduler@node2.supernodexp.hpc
02/19/2018 17:08:27;0100;Server@node2;Req;;Type 1 request received from ctminh@node2.supernodexp.hpc, sock=16
02/19/2018 17:08:27;0100;Server@node2;Req;;Type 3 request received from ctminh@node2.supernodexp.hpc, sock=16
02/19/2018 17:08:27;0100;Server@node2;Req;;Type 5 request received from ctminh@node2.supernodexp.hpc, sock=16
02/19/2018 17:08:27;0100;Server@node2;Job;3831.node2.supernodexp.hpc;enqueuing into workq, state 1 hop 1
02/19/2018 17:08:27;0008;Server@node2;Job;3831.node2.supernodexp.hpc;Job Queued at request of ctminh@node2.supernodexp.hpc, owner = ctminh@node2.supernodexp.hpc, job name = qe_mic_test, queue = workq
02/19/2018 17:08:27;0040;Server@node2;Svr;node2.supernodexp.hpc;Scheduler sent command 1
02/19/2018 17:08:27;0040;Server@node2;Svr;node2.supernodexp.hpc;Scheduler sent command 0
02/19/2018 17:08:27;0100;Server@node2;Req;;Type 21 request received from Scheduler@node2.supernodexp.hpc, sock=20
02/19/2018 17:08:27;0100;Server@node2;Req;;Type 81 request received from Scheduler@node2.supernodexp.hpc, sock=20
02/19/2018 17:08:27;0100;Server@node2;Req;;Type 71 request received from Scheduler@node2.supernodexp.hpc, sock=20
02/19/2018 17:08:27;0100;Server@node2;Req;;Type 58 request received from Scheduler@node2.supernodexp.hpc, sock=20
02/19/2018 17:08:27;0100;Server@node2;Req;;Type 20 request received from Scheduler@node2.supernodexp.hpc, sock=20
02/19/2018 17:08:27;0100;Server@node2;Req;;Type 51 request received from Scheduler@node2.supernodexp.hpc, sock=20
02/19/2018 17:08:27;0100;Server@node2;Req;;Type 11 request received from Scheduler@node2.supernodexp.hpc, sock=20
02/19/2018 17:08:27;0008;Server@node2;Job;3831.node2.supernodexp.hpc;Job Modified at request of Scheduler@node2.supernodexp.hpc
02/19/2018 17:08:31;0100;Server@node2;Req;;Type 1 request received from ctminh@node2.supernodexp.hpc, sock=16
02/19/2018 17:08:31;0100;Server@node2;Req;;Type 3 request received from ctminh@node2.supernodexp.hpc, sock=16
02/19/2018 17:08:31;0100;Server@node2;Req;;Type 5 request received from ctminh@node2.supernodexp.hpc, sock=16
02/19/2018 17:08:31;0100;Server@node2;Job;3832.node2.supernodexp.hpc;enqueuing into workq, state 1 hop 1
02/19/2018 17:08:31;0008;Server@node2;Job;3832.node2.supernodexp.hpc;Job Queued at request of ctminh@node2.supernodexp.hpc, owner = ctminh@node2.supernodexp.hpc, job name = vast1, queue = workq
02/19/2018 17:08:31;0040;Server@node2;Svr;node2.supernodexp.hpc;Scheduler sent command 1
02/19/2018 17:08:31;0040;Server@node2;Svr;node2.supernodexp.hpc;Scheduler sent command 0
02/19/2018 17:08:31;0100;Server@node2;Req;;Type 21 request received from Scheduler@node2.supernodexp.hpc, sock=20
02/19/2018 17:08:31;0100;Server@node2;Req;;Type 81 request received from Scheduler@node2.supernodexp.hpc, sock=20
02/19/2018 17:08:31;0100;Server@node2;Req;;Type 71 request received from Scheduler@node2.supernodexp.hpc, sock=20
02/19/2018 17:08:31;0100;Server@node2;Req;;Type 58 request received from Scheduler@node2.supernodexp.hpc, sock=20
02/19/2018 17:08:31;0100;Server@node2;Req;;Type 20 request received from Scheduler@node2.supernodexp.hpc, sock=20
02/19/2018 17:08:31;0100;Server@node2;Req;;Type 51 request received from Scheduler@node2.supernodexp.hpc, sock=20
02/19/2018 17:08:31;0100;Server@node2;Req;;Type 11 request received from Scheduler@node2.supernodexp.hpc, sock=20
02/19/2018 17:08:31;0008;Server@node2;Job;3832.node2.supernodexp.hpc;Job Modified at request of Scheduler@node2.supernodexp.hpc
02/19/2018 17:08:35;0100;Server@node2;Req;;Type 1 request received from ctminh@node2.supernodexp.hpc, sock=16
02/19/2018 17:08:35;0100;Server@node2;Req;;Type 3 request received from ctminh@node2.supernodexp.hpc, sock=16
02/19/2018 17:08:35;0100;Server@node2;Req;;Type 5 request received from ctminh@node2.supernodexp.hpc, sock=16
02/19/2018 17:08:35;0100;Server@node2;Job;3833.node2.supernodexp.hpc;enqueuing into workq, state 1 hop 1
02/19/2018 17:08:35;0008;Server@node2;Job;3833.node2.supernodexp.hpc;Job Queued at request of ctminh@node2.supernodexp.hpc, owner = ctminh@node2.supernodexp.hpc, job name = sweep, queue = workq
02/19/2018 17:08:35;0040;Server@node2;Svr;node2.supernodexp.hpc;Scheduler sent command 1
02/19/2018 17:08:35;0040;Server@node2;Svr;node2.supernodexp.hpc;Scheduler sent command 0
02/19/2018 17:08:35;0100;Server@node2;Req;;Type 21 request received from Scheduler@node2.supernodexp.hpc, sock=20
02/19/2018 17:08:35;0100;Server@node2;Req;;Type 81 request received from Scheduler@node2.supernodexp.hpc, sock=20
02/19/2018 17:08:35;0100;Server@node2;Req;;Type 71 request received from Scheduler@node2.supernodexp.hpc, sock=20
02/19/2018 17:08:35;0100;Server@node2;Req;;Type 58 request received from Scheduler@node2.supernodexp.hpc, sock=20
