02/14/2018 16:35:27;0086;Server@node2;Svr;Server@node2;Compiling script file: </var/spool/pbs/server_priv/hooks/evaluation.PY>
02/14/2018 16:35:27;0100;Server@node2;Req;;Type 3 request received from ctminh@node2.supernodexp.hpc, sock=16
02/14/2018 16:35:27;0100;Server@node2;Req;;Type 5 request received from ctminh@node2.supernodexp.hpc, sock=16
02/14/2018 16:35:27;0100;Server@node2;Job;1201.node2.supernodexp.hpc;enqueuing into workq, state 1 hop 1
02/14/2018 16:35:27;0008;Server@node2;Job;1201.node2.supernodexp.hpc;Job Queued at request of ctminh@node2.supernodexp.hpc, owner = ctminh@node2.supernodexp.hpc, job name = vast1, queue = workq
02/14/2018 16:35:27;0040;Server@node2;Svr;node2.supernodexp.hpc;Scheduler sent command 1
02/14/2018 16:35:27;0040;Server@node2;Svr;node2.supernodexp.hpc;Scheduler sent command 0
02/14/2018 16:35:27;0100;Server@node2;Req;;Type 21 request received from Scheduler@node2.supernodexp.hpc, sock=20
02/14/2018 16:35:27;0100;Server@node2;Req;;Type 81 request received from Scheduler@node2.supernodexp.hpc, sock=20
02/14/2018 16:35:27;0100;Server@node2;Req;;Type 71 request received from Scheduler@node2.supernodexp.hpc, sock=20
02/14/2018 16:35:27;0100;Server@node2;Req;;Type 58 request received from Scheduler@node2.supernodexp.hpc, sock=20
02/14/2018 16:35:27;0100;Server@node2;Req;;Type 1 request received from ctminh@node2.supernodexp.hpc, sock=16
02/14/2018 16:35:27;0100;Server@node2;Req;;Type 3 request received from ctminh@node2.supernodexp.hpc, sock=16
02/14/2018 16:35:27;0100;Server@node2;Req;;Type 5 request received from ctminh@node2.supernodexp.hpc, sock=16
02/14/2018 16:35:27;0100;Server@node2;Job;1202.node2.supernodexp.hpc;enqueuing into workq, state 1 hop 1
02/14/2018 16:35:27;0008;Server@node2;Job;1202.node2.supernodexp.hpc;Job Queued at request of ctminh@node2.supernodexp.hpc, owner = ctminh@node2.supernodexp.hpc, job name = sweep, queue = workq
02/14/2018 16:35:27;0100;Server@node2;Req;;Type 20 request received from Scheduler@node2.supernodexp.hpc, sock=20
02/14/2018 16:35:27;0100;Server@node2;Req;;Type 51 request received from Scheduler@node2.supernodexp.hpc, sock=20
02/14/2018 16:35:27;0100;Server@node2;Req;;Type 23 request received from Scheduler@node2.supernodexp.hpc, sock=20
02/14/2018 16:35:27;0008;Server@node2;Job;1201.node2.supernodexp.hpc;Job Run at request of Scheduler@node2.supernodexp.hpc on exec_vnode (node13:ncpus=48:mem=5242880kb)
02/14/2018 16:35:27;0001;Server@node2;Svr;Server@node2;Success (0) in req_runjob2, return value of svr_startjob is 0
02/14/2018 16:35:27;0100;Server@node2;Req;;Type 23 request received from Scheduler@node2.supernodexp.hpc, sock=20
02/14/2018 16:35:27;0008;Server@node2;Job;1202.node2.supernodexp.hpc;Job Run at request of Scheduler@node2.supernodexp.hpc on exec_vnode (node14:ncpus=8:mem=3145728kb)
02/14/2018 16:35:27;0001;Server@node2;Svr;Server@node2;Success (0) in req_runjob2, return value of svr_startjob is 0
02/14/2018 16:35:27;0040;Server@node2;Svr;node2.supernodexp.hpc;Scheduler sent command 1
02/14/2018 16:35:27;0040;Server@node2;Svr;node2.supernodexp.hpc;Scheduler sent command 0
02/14/2018 16:35:27;0100;Server@node2;Req;;Type 21 request received from Scheduler@node2.supernodexp.hpc, sock=20
02/14/2018 16:35:27;0100;Server@node2;Req;;Type 81 request received from Scheduler@node2.supernodexp.hpc, sock=20
02/14/2018 16:35:27;0100;Server@node2;Req;;Type 71 request received from Scheduler@node2.supernodexp.hpc, sock=20
02/14/2018 16:35:27;0100;Server@node2;Req;;Type 58 request received from Scheduler@node2.supernodexp.hpc, sock=20
02/14/2018 16:35:27;0100;Server@node2;Req;;Type 20 request received from Scheduler@node2.supernodexp.hpc, sock=20
02/14/2018 16:35:27;0100;Server@node2;Req;;Type 51 request received from Scheduler@node2.supernodexp.hpc, sock=20
02/14/2018 16:35:29;0080;Server@node2;Job;1202.node2.supernodexp.hpc;Obit received momhop:1 serverhop:1 state:4 substate:42
02/14/2018 16:35:30;0010;Server@node2;Job;1202.node2.supernodexp.hpc;Exit_status=0 resources_used.cpupercent=800 resources_used.cput=00:00:08 resources_used.mem=0kb resources_used.ncpus=8 resources_used.vmem=0kb resources_used.walltime=00:00:02
02/14/2018 16:35:30;0100;Server@node2;Job;1202.node2.supernodexp.hpc;dequeuing from workq, state 5
02/14/2018 16:35:30;0040;Server@node2;Svr;node2.supernodexp.hpc;Scheduler sent command 2
02/14/2018 16:35:30;0040;Server@node2;Svr;node2.supernodexp.hpc;Scheduler sent command 0
02/14/2018 16:35:30;0100;Server@node2;Req;;Type 21 request received from Scheduler@node2.supernodexp.hpc, sock=20
02/14/2018 16:35:30;0100;Server@node2;Req;;Type 81 request received from Scheduler@node2.supernodexp.hpc, sock=20
02/14/2018 16:35:30;0100;Server@node2;Req;;Type 71 request received from Scheduler@node2.supernodexp.hpc, sock=20
02/14/2018 16:35:30;0100;Server@node2;Req;;Type 58 request received from Scheduler@node2.supernodexp.hpc, sock=20
02/14/2018 16:35:30;0100;Server@node2;Req;;Type 20 request received from Scheduler@node2.supernodexp.hpc, sock=20
02/14/2018 16:35:30;0100;Server@node2;Req;;Type 51 request received from Scheduler@node2.supernodexp.hpc, sock=20
02/14/2018 16:36:03;0100;Server@node2;Req;;Type 1 request received from ctminh@node2.supernodexp.hpc, sock=16
02/14/2018 16:36:03;0100;Server@node2;Req;;Type 3 request received from ctminh@node2.supernodexp.hpc, sock=16
02/14/2018 16:36:03;0100;Server@node2;Req;;Type 5 request received from ctminh@node2.supernodexp.hpc, sock=16
02/14/2018 16:36:03;0100;Server@node2;Job;1203.node2.supernodexp.hpc;enqueuing into workq, state 1 hop 1
02/14/2018 16:36:03;0008;Server@node2;Job;1203.node2.supernodexp.hpc;Job Queued at request of ctminh@node2.supernodexp.hpc, owner = ctminh@node2.supernodexp.hpc, job name = sweep, queue = workq
02/14/2018 16:36:03;0040;Server@node2;Svr;node2.supernodexp.hpc;Scheduler sent command 1
02/14/2018 16:36:03;0040;Server@node2;Svr;node2.supernodexp.hpc;Scheduler sent command 0
02/14/2018 16:36:03;0100;Server@node2;Req;;Type 21 request received from Scheduler@node2.supernodexp.hpc, sock=20
02/14/2018 16:36:03;0100;Server@node2;Req;;Type 81 request received from Scheduler@node2.supernodexp.hpc, sock=20
02/14/2018 16:36:03;0100;Server@node2;Req;;Type 71 request received from Scheduler@node2.supernodexp.hpc, sock=20
02/14/2018 16:36:03;0100;Server@node2;Req;;Type 58 request received from Scheduler@node2.supernodexp.hpc, sock=20
02/14/2018 16:36:03;0100;Server@node2;Req;;Type 1 request received from ctminh@node2.supernodexp.hpc, sock=16
02/14/2018 16:36:03;0100;Server@node2;Req;;Type 3 request received from ctminh@node2.supernodexp.hpc, sock=16
02/14/2018 16:36:03;0100;Server@node2;Req;;Type 5 request received from ctminh@node2.supernodexp.hpc, sock=16
02/14/2018 16:36:03;0100;Server@node2;Job;1204.node2.supernodexp.hpc;enqueuing into workq, state 1 hop 1
02/14/2018 16:36:03;0008;Server@node2;Job;1204.node2.supernodexp.hpc;Job Queued at request of ctminh@node2.supernodexp.hpc, owner = ctminh@node2.supernodexp.hpc, job name = jacobi, queue = workq
02/14/2018 16:36:03;0100;Server@node2;Req;;Type 1 request received from ctminh@node2.supernodexp.hpc, sock=16
02/14/2018 16:36:03;0100;Server@node2;Req;;Type 3 request received from ctminh@node2.supernodexp.hpc, sock=16
02/14/2018 16:36:03;0100;Server@node2;Req;;Type 5 request received from ctminh@node2.supernodexp.hpc, sock=16
02/14/2018 16:36:03;0100;Server@node2;Job;1205.node2.supernodexp.hpc;enqueuing into workq, state 1 hop 1
02/14/2018 16:36:03;0008;Server@node2;Job;1205.node2.supernodexp.hpc;Job Queued at request of ctminh@node2.supernodexp.hpc, owner = ctminh@node2.supernodexp.hpc, job name = histogram, queue = workq
02/14/2018 16:36:03;0100;Server@node2;Req;;Type 20 request received from Scheduler@node2.supernodexp.hpc, sock=20
02/14/2018 16:36:03;0100;Server@node2;Req;;Type 51 request received from Scheduler@node2.supernodexp.hpc, sock=20
02/14/2018 16:36:03;0100;Server@node2;Req;;Type 1 request received from ctminh@node2.supernodexp.hpc, sock=16
02/14/2018 16:36:03;0100;Server@node2;Req;;Type 3 request received from ctminh@node2.supernodexp.hpc, sock=16
02/14/2018 16:36:03;0100;Server@node2;Req;;Type 5 request received from ctminh@node2.supernodexp.hpc, sock=16
02/14/2018 16:36:03;0100;Server@node2;Job;1206.node2.supernodexp.hpc;enqueuing into workq, state 1 hop 1
02/14/2018 16:36:03;0008;Server@node2;Job;1206.node2.supernodexp.hpc;Job Queued at request of ctminh@node2.supernodexp.hpc, owner = ctminh@node2.supernodexp.hpc, job name = thread-affinity, queue = workq
02/14/2018 16:36:03;0100;Server@node2;Req;;Type 1 request received from ctminh@node2.supernodexp.hpc, sock=16
02/14/2018 16:36:03;0100;Server@node2;Req;;Type 3 request received from ctminh@node2.supernodexp.hpc, sock=16
02/14/2018 16:36:03;0100;Server@node2;Req;;Type 5 request received from ctminh@node2.supernodexp.hpc, sock=16
02/14/2018 16:36:03;0100;Server@node2;Job;1207.node2.supernodexp.hpc;enqueuing into workq, state 1 hop 1
02/14/2018 16:36:03;0008;Server@node2;Job;1207.node2.supernodexp.hpc;Job Queued at request of ctminh@node2.supernodexp.hpc, owner = ctminh@node2.supernodexp.hpc, job name = telemac1, queue = workq
02/14/2018 16:36:03;0100;Server@node2;Req;;Type 1 request received from ctminh@node2.supernodexp.hpc, sock=16
02/14/2018 16:36:03;0100;Server@node2;Req;;Type 3 request received from ctminh@node2.supernodexp.hpc, sock=16
02/14/2018 16:36:03;0100;Server@node2;Req;;Type 5 request received from ctminh@node2.supernodexp.hpc, sock=16
02/14/2018 16:36:03;0100;Server@node2;Job;1208.node2.supernodexp.hpc;enqueuing into workq, state 1 hop 1
02/14/2018 16:36:03;0008;Server@node2;Job;1208.node2.supernodexp.hpc;Job Queued at request of ctminh@node2.supernodexp.hpc, owner = ctminh@node2.supernodexp.hpc, job name = telemac1, queue = workq
02/14/2018 16:36:03;0100;Server@node2;Req;;Type 23 request received from Scheduler@node2.supernodexp.hpc, sock=20
02/14/2018 16:36:03;0008;Server@node2;Job;1203.node2.supernodexp.hpc;Job Run at request of Scheduler@node2.supernodexp.hpc on exec_vnode (node14:ncpus=8:mem=3145728kb)
02/14/2018 16:36:03;0001;Server@node2;Svr;Server@node2;Success (0) in req_runjob2, return value of svr_startjob is 0
02/14/2018 16:36:03;0100;Server@node2;Req;;Type 1 request received from ctminh@node2.supernodexp.hpc, sock=16
02/14/2018 16:36:03;0100;Server@node2;Req;;Type 23 request received from Scheduler@node2.supernodexp.hpc, sock=20
02/14/2018 16:36:03;0008;Server@node2;Job;1204.node2.supernodexp.hpc;Job Run at request of Scheduler@node2.supernodexp.hpc on exec_vnode (node14:ncpus=16:mem=2097152kb)
02/14/2018 16:36:03;0001;Server@node2;Svr;Server@node2;Success (0) in req_runjob2, return value of svr_startjob is 0
02/14/2018 16:36:03;0100;Server@node2;Req;;Type 3 request received from ctminh@node2.supernodexp.hpc, sock=16
02/14/2018 16:36:03;0100;Server@node2;Req;;Type 11 request received from Scheduler@node2.supernodexp.hpc, sock=20
02/14/2018 16:36:03;0008;Server@node2;Job;1205.node2.supernodexp.hpc;Job Modified at request of Scheduler@node2.supernodexp.hpc
02/14/2018 16:36:03;0100;Server@node2;Req;;Type 5 request received from ctminh@node2.supernodexp.hpc, sock=16
02/14/2018 16:36:03;0100;Server@node2;Job;1209.node2.supernodexp.hpc;enqueuing into workq, state 1 hop 1
02/14/2018 16:36:03;0008;Server@node2;Job;1209.node2.supernodexp.hpc;Job Queued at request of ctminh@node2.supernodexp.hpc, owner = ctminh@node2.supernodexp.hpc, job name = telemac3, queue = workq
02/14/2018 16:36:03;0040;Server@node2;Svr;node2.supernodexp.hpc;Scheduler sent command 1
02/14/2018 16:36:03;0040;Server@node2;Svr;node2.supernodexp.hpc;Scheduler sent command 0
02/14/2018 16:36:03;0100;Server@node2;Req;;Type 21 request received from Scheduler@node2.supernodexp.hpc, sock=20
02/14/2018 16:36:03;0100;Server@node2;Req;;Type 81 request received from Scheduler@node2.supernodexp.hpc, sock=20
02/14/2018 16:36:03;0100;Server@node2;Req;;Type 71 request received from Scheduler@node2.supernodexp.hpc, sock=20
02/14/2018 16:36:03;0100;Server@node2;Req;;Type 58 request received from Scheduler@node2.supernodexp.hpc, sock=20
02/14/2018 16:36:03;0100;Server@node2;Req;;Type 1 request received from ctminh@node2.supernodexp.hpc, sock=16
02/14/2018 16:36:03;0100;Server@node2;Req;;Type 3 request received from ctminh@node2.supernodexp.hpc, sock=16
02/14/2018 16:36:03;0100;Server@node2;Req;;Type 5 request received from ctminh@node2.supernodexp.hpc, sock=16
02/14/2018 16:36:03;0100;Server@node2;Job;1210.node2.supernodexp.hpc;enqueuing into workq, state 1 hop 1
02/14/2018 16:36:03;0008;Server@node2;Job;1210.node2.supernodexp.hpc;Job Queued at request of ctminh@node2.supernodexp.hpc, owner = ctminh@node2.supernodexp.hpc, job name = nbody, queue = workq
02/14/2018 16:36:03;0100;Server@node2;Req;;Type 1 request received from ctminh@node2.supernodexp.hpc, sock=16
02/14/2018 16:36:03;0100;Server@node2;Req;;Type 3 request received from ctminh@node2.supernodexp.hpc, sock=16
02/14/2018 16:36:03;0100;Server@node2;Req;;Type 5 request received from ctminh@node2.supernodexp.hpc, sock=16
02/14/2018 16:36:03;0100;Server@node2;Job;1211.node2.supernodexp.hpc;enqueuing into workq, state 1 hop 1
02/14/2018 16:36:03;0008;Server@node2;Job;1211.node2.supernodexp.hpc;Job Queued at request of ctminh@node2.supernodexp.hpc, owner = ctminh@node2.supernodexp.hpc, job name = histogram, queue = workq
02/14/2018 16:36:03;0100;Server@node2;Req;;Type 1 request received from ctminh@node2.supernodexp.hpc, sock=16
02/14/2018 16:36:03;0100;Server@node2;Req;;Type 3 request received from ctminh@node2.supernodexp.hpc, sock=16
02/14/2018 16:36:03;0100;Server@node2;Req;;Type 5 request received from ctminh@node2.supernodexp.hpc, sock=16
02/14/2018 16:36:03;0100;Server@node2;Job;1212.node2.supernodexp.hpc;enqueuing into workq, state 1 hop 1
02/14/2018 16:36:03;0008;Server@node2;Job;1212.node2.supernodexp.hpc;Job Queued at request of ctminh@node2.supernodexp.hpc, owner = ctminh@node2.supernodexp.hpc, job name = qe_mic_test, queue = workq
02/14/2018 16:36:03;0100;Server@node2;Req;;Type 20 request received from Scheduler@node2.supernodexp.hpc, sock=20
02/14/2018 16:36:03;0100;Server@node2;Req;;Type 51 request received from Scheduler@node2.supernodexp.hpc, sock=20
02/14/2018 16:36:03;0100;Server@node2;Req;;Type 1 request received from ctminh@node2.supernodexp.hpc, sock=16
02/14/2018 16:36:03;0100;Server@node2;Req;;Type 3 request received from ctminh@node2.supernodexp.hpc, sock=16
02/14/2018 16:36:03;0100;Server@node2;Req;;Type 5 request received from ctminh@node2.supernodexp.hpc, sock=16
02/14/2018 16:36:03;0100;Server@node2;Job;1213.node2.supernodexp.hpc;enqueuing into workq, state 1 hop 1
02/14/2018 16:36:03;0008;Server@node2;Job;1213.node2.supernodexp.hpc;Job Queued at request of ctminh@node2.supernodexp.hpc, owner = ctminh@node2.supernodexp.hpc, job name = qe_mic_test, queue = workq
02/14/2018 16:36:03;0100;Server@node2;Req;;Type 1 request received from ctminh@node2.supernodexp.hpc, sock=16
02/14/2018 16:36:03;0100;Server@node2;Req;;Type 3 request received from ctminh@node2.supernodexp.hpc, sock=16
02/14/2018 16:36:03;0100;Server@node2;Req;;Type 5 request received from ctminh@node2.supernodexp.hpc, sock=16
02/14/2018 16:36:03;0100;Server@node2;Job;1214.node2.supernodexp.hpc;enqueuing into workq, state 1 hop 1
02/14/2018 16:36:03;0008;Server@node2;Job;1214.node2.supernodexp.hpc;Job Queued at request of ctminh@node2.supernodexp.hpc, owner = ctminh@node2.supernodexp.hpc, job name = thread-affinity, queue = workq
02/14/2018 16:36:03;0100;Server@node2;Req;;Type 1 request received from ctminh@node2.supernodexp.hpc, sock=16
02/14/2018 16:36:03;0100;Server@node2;Req;;Type 23 request received from Scheduler@node2.supernodexp.hpc, sock=20
02/14/2018 16:36:03;0008;Server@node2;Job;1206.node2.supernodexp.hpc;Job Run at request of Scheduler@node2.supernodexp.hpc on exec_vnode (node14:ncpus=24:mem=2097152kb)
02/14/2018 16:36:03;0001;Server@node2;Svr;Server@node2;Success (0) in req_runjob2, return value of svr_startjob is 0
02/14/2018 16:36:03;0100;Server@node2;Req;;Type 3 request received from ctminh@node2.supernodexp.hpc, sock=16
02/14/2018 16:36:03;0100;Server@node2;Req;;Type 11 request received from Scheduler@node2.supernodexp.hpc, sock=20
02/14/2018 16:36:03;0008;Server@node2;Job;1207.node2.supernodexp.hpc;Job Modified at request of Scheduler@node2.supernodexp.hpc
02/14/2018 16:36:03;0100;Server@node2;Req;;Type 5 request received from ctminh@node2.supernodexp.hpc, sock=16
02/14/2018 16:36:03;0100;Server@node2;Job;1215.node2.supernodexp.hpc;enqueuing into workq, state 1 hop 1
02/14/2018 16:36:03;0008;Server@node2;Job;1215.node2.supernodexp.hpc;Job Queued at request of ctminh@node2.supernodexp.hpc, owner = ctminh@node2.supernodexp.hpc, job name = jacobi, queue = workq
02/14/2018 16:36:03;0100;Server@node2;Req;;Type 11 request received from Scheduler@node2.supernodexp.hpc, sock=20
02/14/2018 16:36:03;0008;Server@node2;Job;1208.node2.supernodexp.hpc;Job Modified at request of Scheduler@node2.supernodexp.hpc
02/14/2018 16:36:03;0100;Server@node2;Req;;Type 11 request received from Scheduler@node2.supernodexp.hpc, sock=20
02/14/2018 16:36:03;0008;Server@node2;Job;1209.node2.supernodexp.hpc;Job Modified at request of Scheduler@node2.supernodexp.hpc
02/14/2018 16:36:03;0100;Server@node2;Req;;Type 11 request received from Scheduler@node2.supernodexp.hpc, sock=20
02/14/2018 16:36:03;0008;Server@node2;Job;1210.node2.supernodexp.hpc;Job Modified at request of Scheduler@node2.supernodexp.hpc
02/14/2018 16:36:03;0100;Server@node2;Req;;Type 11 request received from Scheduler@node2.supernodexp.hpc, sock=20
02/14/2018 16:36:03;0008;Server@node2;Job;1211.node2.supernodexp.hpc;Job Modified at request of Scheduler@node2.supernodexp.hpc
02/14/2018 16:36:03;0100;Server@node2;Req;;Type 11 request received from Scheduler@node2.supernodexp.hpc, sock=20
02/14/2018 16:36:03;0008;Server@node2;Job;1212.node2.supernodexp.hpc;Job Modified at request of Scheduler@node2.supernodexp.hpc
02/14/2018 16:36:03;0040;Server@node2;Svr;node2.supernodexp.hpc;Scheduler sent command 1
02/14/2018 16:36:03;0040;Server@node2;Svr;node2.supernodexp.hpc;Scheduler sent command 0
02/14/2018 16:36:03;0100;Server@node2;Req;;Type 21 request received from Scheduler@node2.supernodexp.hpc, sock=20
02/14/2018 16:36:03;0100;Server@node2;Req;;Type 81 request received from Scheduler@node2.supernodexp.hpc, sock=20
02/14/2018 16:36:03;0100;Server@node2;Req;;Type 71 request received from Scheduler@node2.supernodexp.hpc, sock=20
02/14/2018 16:36:03;0100;Server@node2;Req;;Type 58 request received from Scheduler@node2.supernodexp.hpc, sock=20
02/14/2018 16:36:03;0100;Server@node2;Req;;Type 1 request received from ctminh@node2.supernodexp.hpc, sock=16
02/14/2018 16:36:03;0100;Server@node2;Req;;Type 3 request received from ctminh@node2.supernodexp.hpc, sock=16
02/14/2018 16:36:03;0100;Server@node2;Req;;Type 5 request received from ctminh@node2.supernodexp.hpc, sock=16
02/14/2018 16:36:03;0100;Server@node2;Job;1216.node2.supernodexp.hpc;enqueuing into workq, state 1 hop 1
02/14/2018 16:36:03;0008;Server@node2;Job;1216.node2.supernodexp.hpc;Job Queued at request of ctminh@node2.supernodexp.hpc, owner = ctminh@node2.supernodexp.hpc, job name = vast1, queue = workq
02/14/2018 16:36:03;0100;Server@node2;Req;;Type 20 request received from Scheduler@node2.supernodexp.hpc, sock=20
02/14/2018 16:36:03;0100;Server@node2;Req;;Type 51 request received from Scheduler@node2.supernodexp.hpc, sock=20
02/14/2018 16:36:03;0100;Server@node2;Req;;Type 11 request received from Scheduler@node2.supernodexp.hpc, sock=20
02/14/2018 16:36:03;0008;Server@node2;Job;1205.node2.supernodexp.hpc;Job Modified at request of Scheduler@node2.supernodexp.hpc
02/14/2018 16:36:03;0100;Server@node2;Req;;Type 11 request received from Scheduler@node2.supernodexp.hpc, sock=20
02/14/2018 16:36:03;0008;Server@node2;Job;1213.node2.supernodexp.hpc;Job Modified at request of Scheduler@node2.supernodexp.hpc
02/14/2018 16:36:03;0100;Server@node2;Req;;Type 11 request received from Scheduler@node2.supernodexp.hpc, sock=20
02/14/2018 16:36:03;0008;Server@node2;Job;1214.node2.supernodexp.hpc;Job Modified at request of Scheduler@node2.supernodexp.hpc
02/14/2018 16:36:03;0100;Server@node2;Req;;Type 11 request received from Scheduler@node2.supernodexp.hpc, sock=20
02/14/2018 16:36:03;0008;Server@node2;Job;1215.node2.supernodexp.hpc;Job Modified at request of Scheduler@node2.supernodexp.hpc
02/14/2018 16:36:03;0100;Server@node2;Req;;Type 11 request received from Scheduler@node2.supernodexp.hpc, sock=20
02/14/2018 16:36:03;0008;Server@node2;Job;1216.node2.supernodexp.hpc;Job Modified at request of Scheduler@node2.supernodexp.hpc
02/14/2018 16:36:03;0040;Server@node2;Svr;node2.supernodexp.hpc;Scheduler sent command 1
02/14/2018 16:36:03;0040;Server@node2;Svr;node2.supernodexp.hpc;Scheduler sent command 0
02/14/2018 16:36:03;0100;Server@node2;Req;;Type 21 request received from Scheduler@node2.supernodexp.hpc, sock=20
02/14/2018 16:36:03;0100;Server@node2;Req;;Type 81 request received from Scheduler@node2.supernodexp.hpc, sock=20
02/14/2018 16:36:03;0100;Server@node2;Req;;Type 71 request received from Scheduler@node2.supernodexp.hpc, sock=20
02/14/2018 16:36:03;0100;Server@node2;Req;;Type 58 request received from Scheduler@node2.supernodexp.hpc, sock=20
02/14/2018 16:36:04;0100;Server@node2;Req;;Type 20 request received from Scheduler@node2.supernodexp.hpc, sock=20
02/14/2018 16:36:04;0100;Server@node2;Req;;Type 51 request received from Scheduler@node2.supernodexp.hpc, sock=20
02/14/2018 16:36:05;0080;Server@node2;Job;1203.node2.supernodexp.hpc;Obit received momhop:1 serverhop:1 state:4 substate:42
02/14/2018 16:36:06;0010;Server@node2;Job;1203.node2.supernodexp.hpc;Exit_status=0 resources_used.cpupercent=800 resources_used.cput=00:00:10 resources_used.mem=0kb resources_used.ncpus=8 resources_used.vmem=0kb resources_used.walltime=00:00:01
02/14/2018 16:36:06;0100;Server@node2;Job;1203.node2.supernodexp.hpc;dequeuing from workq, state 5
02/14/2018 16:36:06;0040;Server@node2;Svr;node2.supernodexp.hpc;Scheduler sent command 2
02/14/2018 16:36:06;0040;Server@node2;Svr;node2.supernodexp.hpc;Scheduler sent command 0
02/14/2018 16:36:06;0100;Server@node2;Req;;Type 21 request received from Scheduler@node2.supernodexp.hpc, sock=20
02/14/2018 16:36:06;0100;Server@node2;Req;;Type 81 request received from Scheduler@node2.supernodexp.hpc, sock=20
02/14/2018 16:36:06;0100;Server@node2;Req;;Type 71 request received from Scheduler@node2.supernodexp.hpc, sock=20
02/14/2018 16:36:06;0100;Server@node2;Req;;Type 58 request received from Scheduler@node2.supernodexp.hpc, sock=20
02/14/2018 16:36:06;0100;Server@node2;Req;;Type 20 request received from Scheduler@node2.supernodexp.hpc, sock=20
02/14/2018 16:36:06;0100;Server@node2;Req;;Type 51 request received from Scheduler@node2.supernodexp.hpc, sock=20
02/14/2018 16:36:06;0100;Server@node2;Req;;Type 11 request received from Scheduler@node2.supernodexp.hpc, sock=20
02/14/2018 16:36:06;0008;Server@node2;Job;1205.node2.supernodexp.hpc;Job Modified at request of Scheduler@node2.supernodexp.hpc
02/14/2018 16:36:06;0100;Server@node2;Req;;Type 11 request received from Scheduler@node2.supernodexp.hpc, sock=20
02/14/2018 16:36:06;0008;Server@node2;Job;1207.node2.supernodexp.hpc;Job Modified at request of Scheduler@node2.supernodexp.hpc
02/14/2018 16:36:06;0100;Server@node2;Req;;Type 11 request received from Scheduler@node2.supernodexp.hpc, sock=20
02/14/2018 16:36:06;0008;Server@node2;Job;1208.node2.supernodexp.hpc;Job Modified at request of Scheduler@node2.supernodexp.hpc
02/14/2018 16:36:06;0100;Server@node2;Req;;Type 11 request received from Scheduler@node2.supernodexp.hpc, sock=20
02/14/2018 16:36:06;0008;Server@node2;Job;1209.node2.supernodexp.hpc;Job Modified at request of Scheduler@node2.supernodexp.hpc
02/14/2018 16:36:06;0100;Server@node2;Req;;Type 11 request received from Scheduler@node2.supernodexp.hpc, sock=20
02/14/2018 16:36:06;0008;Server@node2;Job;1210.node2.supernodexp.hpc;Job Modified at request of Scheduler@node2.supernodexp.hpc
02/14/2018 16:36:06;0100;Server@node2;Req;;Type 11 request received from Scheduler@node2.supernodexp.hpc, sock=20
02/14/2018 16:36:06;0008;Server@node2;Job;1211.node2.supernodexp.hpc;Job Modified at request of Scheduler@node2.supernodexp.hpc
02/14/2018 16:36:06;0100;Server@node2;Req;;Type 11 request received from Scheduler@node2.supernodexp.hpc, sock=20
02/14/2018 16:36:06;0008;Server@node2;Job;1212.node2.supernodexp.hpc;Job Modified at request of Scheduler@node2.supernodexp.hpc
02/14/2018 16:36:06;0100;Server@node2;Req;;Type 11 request received from Scheduler@node2.supernodexp.hpc, sock=20
02/14/2018 16:36:06;0008;Server@node2;Job;1213.node2.supernodexp.hpc;Job Modified at request of Scheduler@node2.supernodexp.hpc
02/14/2018 16:36:06;0100;Server@node2;Req;;Type 11 request received from Scheduler@node2.supernodexp.hpc, sock=20
02/14/2018 16:36:06;0008;Server@node2;Job;1214.node2.supernodexp.hpc;Job Modified at request of Scheduler@node2.supernodexp.hpc
02/14/2018 16:36:06;0100;Server@node2;Req;;Type 11 request received from Scheduler@node2.supernodexp.hpc, sock=20
02/14/2018 16:36:06;0008;Server@node2;Job;1215.node2.supernodexp.hpc;Job Modified at request of Scheduler@node2.supernodexp.hpc
02/14/2018 16:36:06;0100;Server@node2;Req;;Type 11 request received from Scheduler@node2.supernodexp.hpc, sock=20
02/14/2018 16:36:06;0008;Server@node2;Job;1216.node2.supernodexp.hpc;Job Modified at request of Scheduler@node2.supernodexp.hpc
02/14/2018 16:36:28;0080;Server@node2;Job;1206.node2.supernodexp.hpc;Obit received momhop:1 serverhop:1 state:4 substate:42
02/14/2018 16:36:29;0010;Server@node2;Job;1206.node2.supernodexp.hpc;Exit_status=0 resources_used.cpupercent=2402 resources_used.cput=00:09:51 resources_used.mem=1560600kb resources_used.ncpus=24 resources_used.vmem=3513108kb resources_used.walltime=00:00:25
02/14/2018 16:36:29;0100;Server@node2;Job;1206.node2.supernodexp.hpc;dequeuing from workq, state 5
02/14/2018 16:36:29;0040;Server@node2;Svr;node2.supernodexp.hpc;Scheduler sent command 2
02/14/2018 16:36:29;0040;Server@node2;Svr;node2.supernodexp.hpc;Scheduler sent command 0
02/14/2018 16:36:29;0100;Server@node2;Req;;Type 21 request received from Scheduler@node2.supernodexp.hpc, sock=20
02/14/2018 16:36:29;0100;Server@node2;Req;;Type 81 request received from Scheduler@node2.supernodexp.hpc, sock=20
02/14/2018 16:36:29;0100;Server@node2;Req;;Type 71 request received from Scheduler@node2.supernodexp.hpc, sock=20
02/14/2018 16:36:29;0100;Server@node2;Req;;Type 58 request received from Scheduler@node2.supernodexp.hpc, sock=20
02/14/2018 16:36:30;0100;Server@node2;Req;;Type 20 request received from Scheduler@node2.supernodexp.hpc, sock=20
02/14/2018 16:36:30;0100;Server@node2;Req;;Type 51 request received from Scheduler@node2.supernodexp.hpc, sock=20
02/14/2018 16:36:30;0100;Server@node2;Req;;Type 23 request received from Scheduler@node2.supernodexp.hpc, sock=20
02/14/2018 16:36:30;0008;Server@node2;Job;1205.node2.supernodexp.hpc;Job Run at request of Scheduler@node2.supernodexp.hpc on exec_vnode (node14:ncpus=32:mem=2097152kb)
02/14/2018 16:36:30;0001;Server@node2;Svr;Server@node2;Success (0) in req_runjob2, return value of svr_startjob is 0
02/14/2018 16:36:30;0100;Server@node2;Req;;Type 11 request received from Scheduler@node2.supernodexp.hpc, sock=20
02/14/2018 16:36:30;0008;Server@node2;Job;1207.node2.supernodexp.hpc;Job Modified at request of Scheduler@node2.supernodexp.hpc
02/14/2018 16:36:30;0100;Server@node2;Req;;Type 11 request received from Scheduler@node2.supernodexp.hpc, sock=20
02/14/2018 16:36:30;0008;Server@node2;Job;1208.node2.supernodexp.hpc;Job Modified at request of Scheduler@node2.supernodexp.hpc
02/14/2018 16:36:30;0100;Server@node2;Req;;Type 11 request received from Scheduler@node2.supernodexp.hpc, sock=20
02/14/2018 16:36:30;0008;Server@node2;Job;1209.node2.supernodexp.hpc;Job Modified at request of Scheduler@node2.supernodexp.hpc
02/14/2018 16:36:30;0100;Server@node2;Req;;Type 11 request received from Scheduler@node2.supernodexp.hpc, sock=20
02/14/2018 16:36:30;0008;Server@node2;Job;1210.node2.supernodexp.hpc;Job Modified at request of Scheduler@node2.supernodexp.hpc
02/14/2018 16:36:30;0100;Server@node2;Req;;Type 11 request received from Scheduler@node2.supernodexp.hpc, sock=20
02/14/2018 16:36:30;0008;Server@node2;Job;1211.node2.supernodexp.hpc;Job Modified at request of Scheduler@node2.supernodexp.hpc
02/14/2018 16:36:30;0100;Server@node2;Req;;Type 11 request received from Scheduler@node2.supernodexp.hpc, sock=20
02/14/2018 16:36:30;0008;Server@node2;Job;1212.node2.supernodexp.hpc;Job Modified at request of Scheduler@node2.supernodexp.hpc
02/14/2018 16:36:30;0100;Server@node2;Req;;Type 11 request received from Scheduler@node2.supernodexp.hpc, sock=20
02/14/2018 16:36:30;0008;Server@node2;Job;1213.node2.supernodexp.hpc;Job Modified at request of Scheduler@node2.supernodexp.hpc
02/14/2018 16:36:30;0100;Server@node2;Req;;Type 11 request received from Scheduler@node2.supernodexp.hpc, sock=20
02/14/2018 16:36:30;0008;Server@node2;Job;1214.node2.supernodexp.hpc;Job Modified at request of Scheduler@node2.supernodexp.hpc
02/14/2018 16:36:30;0100;Server@node2;Req;;Type 11 request received from Scheduler@node2.supernodexp.hpc, sock=20
02/14/2018 16:36:30;0008;Server@node2;Job;1215.node2.supernodexp.hpc;Job Modified at request of Scheduler@node2.supernodexp.hpc
02/14/2018 16:36:30;0100;Server@node2;Req;;Type 11 request received from Scheduler@node2.supernodexp.hpc, sock=20
02/14/2018 16:36:30;0008;Server@node2;Job;1216.node2.supernodexp.hpc;Job Modified at request of Scheduler@node2.supernodexp.hpc
02/14/2018 16:36:34;0080;Server@node2;Job;1205.node2.supernodexp.hpc;Obit received momhop:1 serverhop:1 state:4 substate:42
02/14/2018 16:36:35;0010;Server@node2;Job;1205.node2.supernodexp.hpc;Exit_status=0 resources_used.cpupercent=79 resources_used.cput=00:00:04 resources_used.mem=0kb resources_used.ncpus=32 resources_used.vmem=0kb resources_used.walltime=00:00:05
02/14/2018 16:36:35;0100;Server@node2;Job;1205.node2.supernodexp.hpc;dequeuing from workq, state 5
02/14/2018 16:36:35;0040;Server@node2;Svr;node2.supernodexp.hpc;Scheduler sent command 2
02/14/2018 16:36:35;0040;Server@node2;Svr;node2.supernodexp.hpc;Scheduler sent command 0
02/14/2018 16:36:35;0100;Server@node2;Req;;Type 21 request received from Scheduler@node2.supernodexp.hpc, sock=20
02/14/2018 16:36:35;0100;Server@node2;Req;;Type 81 request received from Scheduler@node2.supernodexp.hpc, sock=20
02/14/2018 16:36:35;0100;Server@node2;Req;;Type 71 request received from Scheduler@node2.supernodexp.hpc, sock=20
02/14/2018 16:36:35;0100;Server@node2;Req;;Type 58 request received from Scheduler@node2.supernodexp.hpc, sock=20
02/14/2018 16:36:35;0100;Server@node2;Req;;Type 20 request received from Scheduler@node2.supernodexp.hpc, sock=20
02/14/2018 16:36:35;0100;Server@node2;Req;;Type 51 request received from Scheduler@node2.supernodexp.hpc, sock=20
02/14/2018 16:36:35;0100;Server@node2;Req;;Type 23 request received from Scheduler@node2.supernodexp.hpc, sock=20
02/14/2018 16:36:35;0008;Server@node2;Job;1207.node2.supernodexp.hpc;Job Run at request of Scheduler@node2.supernodexp.hpc on exec_vnode (node14:ncpus=24:mem=2097152kb)
02/14/2018 16:36:35;0001;Server@node2;Svr;Server@node2;Success (0) in req_runjob2, return value of svr_startjob is 0
02/14/2018 16:36:35;0100;Server@node2;Req;;Type 11 request received from Scheduler@node2.supernodexp.hpc, sock=20
02/14/2018 16:36:35;0008;Server@node2;Job;1208.node2.supernodexp.hpc;Job Modified at request of Scheduler@node2.supernodexp.hpc
02/14/2018 16:36:35;0100;Server@node2;Req;;Type 11 request received from Scheduler@node2.supernodexp.hpc, sock=20
02/14/2018 16:36:35;0008;Server@node2;Job;1209.node2.supernodexp.hpc;Job Modified at request of Scheduler@node2.supernodexp.hpc
02/14/2018 16:36:35;0100;Server@node2;Req;;Type 11 request received from Scheduler@node2.supernodexp.hpc, sock=20
02/14/2018 16:36:35;0008;Server@node2;Job;1210.node2.supernodexp.hpc;Job Modified at request of Scheduler@node2.supernodexp.hpc
02/14/2018 16:36:35;0100;Server@node2;Req;;Type 11 request received from Scheduler@node2.supernodexp.hpc, sock=20
02/14/2018 16:36:35;0008;Server@node2;Job;1211.node2.supernodexp.hpc;Job Modified at request of Scheduler@node2.supernodexp.hpc
02/14/2018 16:36:35;0100;Server@node2;Req;;Type 11 request received from Scheduler@node2.supernodexp.hpc, sock=20
02/14/2018 16:36:35;0008;Server@node2;Job;1212.node2.supernodexp.hpc;Job Modified at request of Scheduler@node2.supernodexp.hpc
02/14/2018 16:36:35;0100;Server@node2;Req;;Type 11 request received from Scheduler@node2.supernodexp.hpc, sock=20
02/14/2018 16:36:35;0008;Server@node2;Job;1213.node2.supernodexp.hpc;Job Modified at request of Scheduler@node2.supernodexp.hpc
02/14/2018 16:36:35;0100;Server@node2;Req;;Type 11 request received from Scheduler@node2.supernodexp.hpc, sock=20
02/14/2018 16:36:35;0008;Server@node2;Job;1214.node2.supernodexp.hpc;Job Modified at request of Scheduler@node2.supernodexp.hpc
02/14/2018 16:36:35;0100;Server@node2;Req;;Type 11 request received from Scheduler@node2.supernodexp.hpc, sock=20
02/14/2018 16:36:35;0008;Server@node2;Job;1215.node2.supernodexp.hpc;Job Modified at request of Scheduler@node2.supernodexp.hpc
02/14/2018 16:36:35;0100;Server@node2;Req;;Type 11 request received from Scheduler@node2.supernodexp.hpc, sock=20
02/14/2018 16:36:35;0008;Server@node2;Job;1216.node2.supernodexp.hpc;Job Modified at request of Scheduler@node2.supernodexp.hpc
02/14/2018 16:36:58;0080;Server@node2;Job;1204.node2.supernodexp.hpc;Obit received momhop:1 serverhop:1 state:4 substate:42
02/14/2018 16:36:58;0100;Server@node2;Req;;Type 1 request received from ctminh@node2.supernodexp.hpc, sock=16
02/14/2018 16:36:58;0100;Server@node2;Req;;Type 3 request received from ctminh@node2.supernodexp.hpc, sock=16
02/14/2018 16:36:58;0100;Server@node2;Req;;Type 5 request received from ctminh@node2.supernodexp.hpc, sock=16
02/14/2018 16:36:58;0100;Server@node2;Job;1217.node2.supernodexp.hpc;enqueuing into workq, state 1 hop 1
02/14/2018 16:36:58;0008;Server@node2;Job;1217.node2.supernodexp.hpc;Job Queued at request of ctminh@node2.supernodexp.hpc, owner = ctminh@node2.supernodexp.hpc, job name = sweep, queue = workq
02/14/2018 16:36:58;0040;Server@node2;Svr;node2.supernodexp.hpc;Scheduler sent command 1
02/14/2018 16:36:58;0040;Server@node2;Svr;node2.supernodexp.hpc;Scheduler sent command 0
02/14/2018 16:36:58;0100;Server@node2;Req;;Type 21 request received from Scheduler@node2.supernodexp.hpc, sock=20
02/14/2018 16:36:58;0100;Server@node2;Req;;Type 81 request received from Scheduler@node2.supernodexp.hpc, sock=20
02/14/2018 16:36:58;0100;Server@node2;Req;;Type 71 request received from Scheduler@node2.supernodexp.hpc, sock=20
02/14/2018 16:36:58;0100;Server@node2;Req;;Type 58 request received from Scheduler@node2.supernodexp.hpc, sock=20
02/14/2018 16:36:58;0100;Server@node2;Req;;Type 1 request received from ctminh@node2.supernodexp.hpc, sock=16
02/14/2018 16:36:58;0100;Server@node2;Req;;Type 3 request received from ctminh@node2.supernodexp.hpc, sock=16
02/14/2018 16:36:58;0100;Server@node2;Req;;Type 5 request received from ctminh@node2.supernodexp.hpc, sock=16
02/14/2018 16:36:58;0100;Server@node2;Job;1218.node2.supernodexp.hpc;enqueuing into workq, state 1 hop 1
02/14/2018 16:36:58;0008;Server@node2;Job;1218.node2.supernodexp.hpc;Job Queued at request of ctminh@node2.supernodexp.hpc, owner = ctminh@node2.supernodexp.hpc, job name = telemac3, queue = workq
02/14/2018 16:36:58;0100;Server@node2;Req;;Type 1 request received from ctminh@node2.supernodexp.hpc, sock=16
02/14/2018 16:36:58;0100;Server@node2;Req;;Type 3 request received from ctminh@node2.supernodexp.hpc, sock=16
02/14/2018 16:36:58;0100;Server@node2;Req;;Type 5 request received from ctminh@node2.supernodexp.hpc, sock=16
02/14/2018 16:36:58;0100;Server@node2;Job;1219.node2.supernodexp.hpc;enqueuing into workq, state 1 hop 1
02/14/2018 16:36:58;0008;Server@node2;Job;1219.node2.supernodexp.hpc;Job Queued at request of ctminh@node2.supernodexp.hpc, owner = ctminh@node2.supernodexp.hpc, job name = jacobi, queue = workq
02/14/2018 16:36:58;0100;Server@node2;Req;;Type 1 request received from ctminh@node2.supernodexp.hpc, sock=16
02/14/2018 16:36:58;0100;Server@node2;Req;;Type 3 request received from ctminh@node2.supernodexp.hpc, sock=16
02/14/2018 16:36:58;0100;Server@node2;Req;;Type 5 request received from ctminh@node2.supernodexp.hpc, sock=16
02/14/2018 16:36:58;0100;Server@node2;Job;1220.node2.supernodexp.hpc;enqueuing into workq, state 1 hop 1
02/14/2018 16:36:58;0008;Server@node2;Job;1220.node2.supernodexp.hpc;Job Queued at request of ctminh@node2.supernodexp.hpc, owner = ctminh@node2.supernodexp.hpc, job name = qe_mic_test, queue = workq
02/14/2018 16:36:58;0100;Server@node2;Req;;Type 20 request received from Scheduler@node2.supernodexp.hpc, sock=20
02/14/2018 16:36:58;0100;Server@node2;Req;;Type 51 request received from Scheduler@node2.supernodexp.hpc, sock=20
02/14/2018 16:36:58;0100;Server@node2;Req;;Type 1 request received from ctminh@node2.supernodexp.hpc, sock=16
02/14/2018 16:36:58;0100;Server@node2;Req;;Type 3 request received from ctminh@node2.supernodexp.hpc, sock=16
02/14/2018 16:36:58;0100;Server@node2;Req;;Type 5 request received from ctminh@node2.supernodexp.hpc, sock=16
02/14/2018 16:36:58;0100;Server@node2;Job;1221.node2.supernodexp.hpc;enqueuing into workq, state 1 hop 1
02/14/2018 16:36:58;0008;Server@node2;Job;1221.node2.supernodexp.hpc;Job Queued at request of ctminh@node2.supernodexp.hpc, owner = ctminh@node2.supernodexp.hpc, job name = telemac2, queue = workq
02/14/2018 16:36:58;0100;Server@node2;Req;;Type 1 request received from ctminh@node2.supernodexp.hpc, sock=16
02/14/2018 16:36:59;0100;Server@node2;Req;;Type 3 request received from ctminh@node2.supernodexp.hpc, sock=16
02/14/2018 16:36:59;0100;Server@node2;Req;;Type 5 request received from ctminh@node2.supernodexp.hpc, sock=16
02/14/2018 16:36:59;0100;Server@node2;Job;1222.node2.supernodexp.hpc;enqueuing into workq, state 1 hop 1
02/14/2018 16:36:59;0008;Server@node2;Job;1222.node2.supernodexp.hpc;Job Queued at request of ctminh@node2.supernodexp.hpc, owner = ctminh@node2.supernodexp.hpc, job name = telemac2, queue = workq
02/14/2018 16:36:59;0100;Server@node2;Req;;Type 1 request received from ctminh@node2.supernodexp.hpc, sock=16
02/14/2018 16:36:59;0100;Server@node2;Req;;Type 3 request received from ctminh@node2.supernodexp.hpc, sock=16
02/14/2018 16:36:59;0100;Server@node2;Req;;Type 5 request received from ctminh@node2.supernodexp.hpc, sock=16
02/14/2018 16:36:59;0100;Server@node2;Job;1223.node2.supernodexp.hpc;enqueuing into workq, state 1 hop 1
02/14/2018 16:36:59;0008;Server@node2;Job;1223.node2.supernodexp.hpc;Job Queued at request of ctminh@node2.supernodexp.hpc, owner = ctminh@node2.supernodexp.hpc, job name = vectorization, queue = workq
02/14/2018 16:36:59;0100;Server@node2;Req;;Type 23 request received from Scheduler@node2.supernodexp.hpc, sock=20
02/14/2018 16:36:59;0008;Server@node2;Job;1217.node2.supernodexp.hpc;Job Run at request of Scheduler@node2.supernodexp.hpc on exec_vnode (node14:ncpus=8:mem=3145728kb)
02/14/2018 16:36:59;0001;Server@node2;Svr;Server@node2;Success (0) in req_runjob2, return value of svr_startjob is 0
02/14/2018 16:36:59;0100;Server@node2;Req;;Type 1 request received from ctminh@node2.supernodexp.hpc, sock=16
02/14/2018 16:36:59;0100;Server@node2;Req;;Type 11 request received from Scheduler@node2.supernodexp.hpc, sock=20
02/14/2018 16:36:59;0008;Server@node2;Job;1218.node2.supernodexp.hpc;Job Modified at request of Scheduler@node2.supernodexp.hpc
02/14/2018 16:36:59;0100;Server@node2;Req;;Type 3 request received from ctminh@node2.supernodexp.hpc, sock=16
02/14/2018 16:36:59;0100;Server@node2;Req;;Type 11 request received from Scheduler@node2.supernodexp.hpc, sock=20
02/14/2018 16:36:59;0008;Server@node2;Job;1219.node2.supernodexp.hpc;Job Modified at request of Scheduler@node2.supernodexp.hpc
02/14/2018 16:36:59;0100;Server@node2;Req;;Type 5 request received from ctminh@node2.supernodexp.hpc, sock=16
02/14/2018 16:36:59;0100;Server@node2;Job;1224.node2.supernodexp.hpc;enqueuing into workq, state 1 hop 1
02/14/2018 16:36:59;0008;Server@node2;Job;1224.node2.supernodexp.hpc;Job Queued at request of ctminh@node2.supernodexp.hpc, owner = ctminh@node2.supernodexp.hpc, job name = matrix-x-vector, queue = workq
02/14/2018 16:36:59;0100;Server@node2;Req;;Type 11 request received from Scheduler@node2.supernodexp.hpc, sock=20
02/14/2018 16:36:59;0008;Server@node2;Job;1220.node2.supernodexp.hpc;Job Modified at request of Scheduler@node2.supernodexp.hpc
02/14/2018 16:36:59;0040;Server@node2;Svr;node2.supernodexp.hpc;Scheduler sent command 1
02/14/2018 16:36:59;0040;Server@node2;Svr;node2.supernodexp.hpc;Scheduler sent command 0
02/14/2018 16:36:59;0100;Server@node2;Req;;Type 21 request received from Scheduler@node2.supernodexp.hpc, sock=20
02/14/2018 16:36:59;0100;Server@node2;Req;;Type 81 request received from Scheduler@node2.supernodexp.hpc, sock=20
02/14/2018 16:36:59;0100;Server@node2;Req;;Type 71 request received from Scheduler@node2.supernodexp.hpc, sock=20
02/14/2018 16:36:59;0100;Server@node2;Req;;Type 58 request received from Scheduler@node2.supernodexp.hpc, sock=20
02/14/2018 16:36:59;0100;Server@node2;Req;;Type 1 request received from ctminh@node2.supernodexp.hpc, sock=16
02/14/2018 16:36:59;0100;Server@node2;Req;;Type 3 request received from ctminh@node2.supernodexp.hpc, sock=16
02/14/2018 16:36:59;0100;Server@node2;Req;;Type 5 request received from ctminh@node2.supernodexp.hpc, sock=16
02/14/2018 16:36:59;0100;Server@node2;Job;1225.node2.supernodexp.hpc;enqueuing into workq, state 1 hop 1
02/14/2018 16:36:59;0008;Server@node2;Job;1225.node2.supernodexp.hpc;Job Queued at request of ctminh@node2.supernodexp.hpc, owner = ctminh@node2.supernodexp.hpc, job name = histogram, queue = workq
02/14/2018 16:36:59;0100;Server@node2;Req;;Type 1 request received from ctminh@node2.supernodexp.hpc, sock=16
02/14/2018 16:36:59;0100;Server@node2;Req;;Type 3 request received from ctminh@node2.supernodexp.hpc, sock=16
02/14/2018 16:36:59;0100;Server@node2;Req;;Type 5 request received from ctminh@node2.supernodexp.hpc, sock=16
02/14/2018 16:36:59;0100;Server@node2;Job;1226.node2.supernodexp.hpc;enqueuing into workq, state 1 hop 1
02/14/2018 16:36:59;0008;Server@node2;Job;1226.node2.supernodexp.hpc;Job Queued at request of ctminh@node2.supernodexp.hpc, owner = ctminh@node2.supernodexp.hpc, job name = matrix-x-vector, queue = workq
02/14/2018 16:36:59;0100;Server@node2;Req;;Type 1 request received from ctminh@node2.supernodexp.hpc, sock=16
02/14/2018 16:36:59;0100;Server@node2;Req;;Type 3 request received from ctminh@node2.supernodexp.hpc, sock=16
02/14/2018 16:36:59;0100;Server@node2;Req;;Type 5 request received from ctminh@node2.supernodexp.hpc, sock=16
02/14/2018 16:36:59;0100;Server@node2;Job;1227.node2.supernodexp.hpc;enqueuing into workq, state 1 hop 1
02/14/2018 16:36:59;0008;Server@node2;Job;1227.node2.supernodexp.hpc;Job Queued at request of ctminh@node2.supernodexp.hpc, owner = ctminh@node2.supernodexp.hpc, job name = thread-affinity, queue = workq
02/14/2018 16:36:59;0100;Server@node2;Req;;Type 1 request received from ctminh@node2.supernodexp.hpc, sock=16
02/14/2018 16:36:59;0100;Server@node2;Req;;Type 3 request received from ctminh@node2.supernodexp.hpc, sock=16
02/14/2018 16:36:59;0100;Server@node2;Req;;Type 5 request received from ctminh@node2.supernodexp.hpc, sock=16
02/14/2018 16:36:59;0100;Server@node2;Job;1228.node2.supernodexp.hpc;enqueuing into workq, state 1 hop 1
02/14/2018 16:36:59;0008;Server@node2;Job;1228.node2.supernodexp.hpc;Job Queued at request of ctminh@node2.supernodexp.hpc, owner = ctminh@node2.supernodexp.hpc, job name = lu-decomp, queue = workq
02/14/2018 16:36:59;0100;Server@node2;Req;;Type 1 request received from ctminh@node2.supernodexp.hpc, sock=16
02/14/2018 16:36:59;0100;Server@node2;Req;;Type 20 request received from Scheduler@node2.supernodexp.hpc, sock=20
02/14/2018 16:36:59;0100;Server@node2;Req;;Type 3 request received from ctminh@node2.supernodexp.hpc, sock=16
02/14/2018 16:36:59;0100;Server@node2;Req;;Type 51 request received from Scheduler@node2.supernodexp.hpc, sock=20
02/14/2018 16:36:59;0100;Server@node2;Req;;Type 5 request received from ctminh@node2.supernodexp.hpc, sock=16
02/14/2018 16:36:59;0100;Server@node2;Job;1229.node2.supernodexp.hpc;enqueuing into workq, state 1 hop 1
02/14/2018 16:36:59;0008;Server@node2;Job;1229.node2.supernodexp.hpc;Job Queued at request of ctminh@node2.supernodexp.hpc, owner = ctminh@node2.supernodexp.hpc, job name = jacobi, queue = workq
02/14/2018 16:36:59;0100;Server@node2;Req;;Type 1 request received from ctminh@node2.supernodexp.hpc, sock=16
02/14/2018 16:36:59;0100;Server@node2;Req;;Type 3 request received from ctminh@node2.supernodexp.hpc, sock=16
02/14/2018 16:36:59;0100;Server@node2;Req;;Type 5 request received from ctminh@node2.supernodexp.hpc, sock=16
02/14/2018 16:36:59;0100;Server@node2;Job;1230.node2.supernodexp.hpc;enqueuing into workq, state 1 hop 1
02/14/2018 16:36:59;0008;Server@node2;Job;1230.node2.supernodexp.hpc;Job Queued at request of ctminh@node2.supernodexp.hpc, owner = ctminh@node2.supernodexp.hpc, job name = vectorization, queue = workq
02/14/2018 16:36:59;0100;Server@node2;Req;;Type 1 request received from ctminh@node2.supernodexp.hpc, sock=16
02/14/2018 16:36:59;0100;Server@node2;Req;;Type 3 request received from ctminh@node2.supernodexp.hpc, sock=16
02/14/2018 16:36:59;0100;Server@node2;Req;;Type 5 request received from ctminh@node2.supernodexp.hpc, sock=16
02/14/2018 16:36:59;0100;Server@node2;Job;1231.node2.supernodexp.hpc;enqueuing into workq, state 1 hop 1
02/14/2018 16:36:59;0008;Server@node2;Job;1231.node2.supernodexp.hpc;Job Queued at request of ctminh@node2.supernodexp.hpc, owner = ctminh@node2.supernodexp.hpc, job name = jacobi, queue = workq
02/14/2018 16:36:59;0100;Server@node2;Req;;Type 1 request received from ctminh@node2.supernodexp.hpc, sock=16
02/14/2018 16:36:59;0100;Server@node2;Req;;Type 3 request received from ctminh@node2.supernodexp.hpc, sock=16
02/14/2018 16:36:59;0100;Server@node2;Req;;Type 5 request received from ctminh@node2.supernodexp.hpc, sock=16
02/14/2018 16:36:59;0100;Server@node2;Job;1232.node2.supernodexp.hpc;enqueuing into workq, state 1 hop 1
02/14/2018 16:36:59;0008;Server@node2;Job;1232.node2.supernodexp.hpc;Job Queued at request of ctminh@node2.supernodexp.hpc, owner = ctminh@node2.supernodexp.hpc, job name = vectorization, queue = workq
02/14/2018 16:36:59;0100;Server@node2;Req;;Type 1 request received from ctminh@node2.supernodexp.hpc, sock=16
02/14/2018 16:36:59;0100;Server@node2;Req;;Type 3 request received from ctminh@node2.supernodexp.hpc, sock=16
02/14/2018 16:36:59;0100;Server@node2;Req;;Type 5 request received from ctminh@node2.supernodexp.hpc, sock=16
02/14/2018 16:36:59;0100;Server@node2;Job;1233.node2.supernodexp.hpc;enqueuing into workq, state 1 hop 1
02/14/2018 16:36:59;0008;Server@node2;Job;1233.node2.supernodexp.hpc;Job Queued at request of ctminh@node2.supernodexp.hpc, owner = ctminh@node2.supernodexp.hpc, job name = telemac1, queue = workq
02/14/2018 16:36:59;0100;Server@node2;Req;;Type 11 request received from Scheduler@node2.supernodexp.hpc, sock=20
02/14/2018 16:36:59;0008;Server@node2;Job;1208.node2.supernodexp.hpc;Job Modified at request of Scheduler@node2.supernodexp.hpc
02/14/2018 16:36:59;0100;Server@node2;Req;;Type 11 request received from Scheduler@node2.supernodexp.hpc, sock=20
02/14/2018 16:36:59;0008;Server@node2;Job;1209.node2.supernodexp.hpc;Job Modified at request of Scheduler@node2.supernodexp.hpc
02/14/2018 16:36:59;0100;Server@node2;Req;;Type 11 request received from Scheduler@node2.supernodexp.hpc, sock=20
02/14/2018 16:36:59;0008;Server@node2;Job;1210.node2.supernodexp.hpc;Job Modified at request of Scheduler@node2.supernodexp.hpc
02/14/2018 16:36:59;0100;Server@node2;Req;;Type 11 request received from Scheduler@node2.supernodexp.hpc, sock=20
02/14/2018 16:36:59;0008;Server@node2;Job;1211.node2.supernodexp.hpc;Job Modified at request of Scheduler@node2.supernodexp.hpc
02/14/2018 16:36:59;0100;Server@node2;Req;;Type 11 request received from Scheduler@node2.supernodexp.hpc, sock=20
02/14/2018 16:36:59;0008;Server@node2;Job;1212.node2.supernodexp.hpc;Job Modified at request of Scheduler@node2.supernodexp.hpc
02/14/2018 16:36:59;0100;Server@node2;Req;;Type 11 request received from Scheduler@node2.supernodexp.hpc, sock=20
02/14/2018 16:36:59;0008;Server@node2;Job;1213.node2.supernodexp.hpc;Job Modified at request of Scheduler@node2.supernodexp.hpc
02/14/2018 16:36:59;0100;Server@node2;Req;;Type 11 request received from Scheduler@node2.supernodexp.hpc, sock=20
02/14/2018 16:36:59;0008;Server@node2;Job;1214.node2.supernodexp.hpc;Job Modified at request of Scheduler@node2.supernodexp.hpc
02/14/2018 16:36:59;0100;Server@node2;Req;;Type 11 request received from Scheduler@node2.supernodexp.hpc, sock=20
02/14/2018 16:36:59;0008;Server@node2;Job;1215.node2.supernodexp.hpc;Job Modified at request of Scheduler@node2.supernodexp.hpc
02/14/2018 16:36:59;0100;Server@node2;Req;;Type 11 request received from Scheduler@node2.supernodexp.hpc, sock=20
02/14/2018 16:36:59;0008;Server@node2;Job;1216.node2.supernodexp.hpc;Job Modified at request of Scheduler@node2.supernodexp.hpc
02/14/2018 16:36:59;0100;Server@node2;Req;;Type 11 request received from Scheduler@node2.supernodexp.hpc, sock=20
02/14/2018 16:36:59;0008;Server@node2;Job;1221.node2.supernodexp.hpc;Job Modified at request of Scheduler@node2.supernodexp.hpc
02/14/2018 16:36:59;0100;Server@node2;Req;;Type 1 request received from ctminh@node2.supernodexp.hpc, sock=16
02/14/2018 16:36:59;0100;Server@node2;Req;;Type 11 request received from Scheduler@node2.supernodexp.hpc, sock=20
02/14/2018 16:36:59;0008;Server@node2;Job;1222.node2.supernodexp.hpc;Job Modified at request of Scheduler@node2.supernodexp.hpc
02/14/2018 16:36:59;0100;Server@node2;Req;;Type 3 request received from ctminh@node2.supernodexp.hpc, sock=16
02/14/2018 16:36:59;0100;Server@node2;Req;;Type 11 request received from Scheduler@node2.supernodexp.hpc, sock=20
02/14/2018 16:36:59;0008;Server@node2;Job;1223.node2.supernodexp.hpc;Job Modified at request of Scheduler@node2.supernodexp.hpc
02/14/2018 16:36:59;0100;Server@node2;Req;;Type 5 request received from ctminh@node2.supernodexp.hpc, sock=16
02/14/2018 16:36:59;0100;Server@node2;Job;1234.node2.supernodexp.hpc;enqueuing into workq, state 1 hop 1
02/14/2018 16:36:59;0008;Server@node2;Job;1234.node2.supernodexp.hpc;Job Queued at request of ctminh@node2.supernodexp.hpc, owner = ctminh@node2.supernodexp.hpc, job name = lu-decomp, queue = workq
02/14/2018 16:36:59;0100;Server@node2;Req;;Type 11 request received from Scheduler@node2.supernodexp.hpc, sock=20
02/14/2018 16:36:59;0008;Server@node2;Job;1224.node2.supernodexp.hpc;Job Modified at request of Scheduler@node2.supernodexp.hpc
02/14/2018 16:36:59;0100;Server@node2;Req;;Type 11 request received from Scheduler@node2.supernodexp.hpc, sock=20
02/14/2018 16:36:59;0008;Server@node2;Job;1225.node2.supernodexp.hpc;Job Modified at request of Scheduler@node2.supernodexp.hpc
02/14/2018 16:36:59;0100;Server@node2;Req;;Type 11 request received from Scheduler@node2.supernodexp.hpc, sock=20
02/14/2018 16:36:59;0008;Server@node2;Job;1226.node2.supernodexp.hpc;Job Modified at request of Scheduler@node2.supernodexp.hpc
02/14/2018 16:36:59;0100;Server@node2;Req;;Type 11 request received from Scheduler@node2.supernodexp.hpc, sock=20
02/14/2018 16:36:59;0008;Server@node2;Job;1227.node2.supernodexp.hpc;Job Modified at request of Scheduler@node2.supernodexp.hpc
02/14/2018 16:36:59;0100;Server@node2;Req;;Type 11 request received from Scheduler@node2.supernodexp.hpc, sock=20
02/14/2018 16:36:59;0008;Server@node2;Job;1228.node2.supernodexp.hpc;Job Modified at request of Scheduler@node2.supernodexp.hpc
02/14/2018 16:36:59;0040;Server@node2;Svr;node2.supernodexp.hpc;Scheduler sent command 1
02/14/2018 16:36:59;0040;Server@node2;Svr;node2.supernodexp.hpc;Scheduler sent command 0
02/14/2018 16:36:59;0100;Server@node2;Req;;Type 21 request received from Scheduler@node2.supernodexp.hpc, sock=20
02/14/2018 16:36:59;0100;Server@node2;Req;;Type 81 request received from Scheduler@node2.supernodexp.hpc, sock=20
02/14/2018 16:36:59;0100;Server@node2;Req;;Type 71 request received from Scheduler@node2.supernodexp.hpc, sock=20
02/14/2018 16:36:59;0100;Server@node2;Req;;Type 58 request received from Scheduler@node2.supernodexp.hpc, sock=20
02/14/2018 16:36:59;0100;Server@node2;Req;;Type 1 request received from ctminh@node2.supernodexp.hpc, sock=16
02/14/2018 16:36:59;0100;Server@node2;Req;;Type 3 request received from ctminh@node2.supernodexp.hpc, sock=16
02/14/2018 16:36:59;0100;Server@node2;Req;;Type 5 request received from ctminh@node2.supernodexp.hpc, sock=16
02/14/2018 16:36:59;0100;Server@node2;Job;1235.node2.supernodexp.hpc;enqueuing into workq, state 1 hop 1
02/14/2018 16:36:59;0008;Server@node2;Job;1235.node2.supernodexp.hpc;Job Queued at request of ctminh@node2.supernodexp.hpc, owner = ctminh@node2.supernodexp.hpc, job name = telemac1, queue = workq
02/14/2018 16:36:59;0100;Server@node2;Req;;Type 1 request received from ctminh@node2.supernodexp.hpc, sock=16
02/14/2018 16:36:59;0100;Server@node2;Req;;Type 3 request received from ctminh@node2.supernodexp.hpc, sock=16
02/14/2018 16:36:59;0100;Server@node2;Req;;Type 5 request received from ctminh@node2.supernodexp.hpc, sock=16
02/14/2018 16:36:59;0100;Server@node2;Job;1236.node2.supernodexp.hpc;enqueuing into workq, state 1 hop 1
02/14/2018 16:36:59;0008;Server@node2;Job;1236.node2.supernodexp.hpc;Job Queued at request of ctminh@node2.supernodexp.hpc, owner = ctminh@node2.supernodexp.hpc, job name = telemac3, queue = workq
02/14/2018 16:36:59;0100;Server@node2;Req;;Type 1 request received from ctminh@node2.supernodexp.hpc, sock=16
02/14/2018 16:36:59;0100;Server@node2;Req;;Type 3 request received from ctminh@node2.supernodexp.hpc, sock=16
02/14/2018 16:36:59;0100;Server@node2;Req;;Type 5 request received from ctminh@node2.supernodexp.hpc, sock=16
02/14/2018 16:36:59;0100;Server@node2;Job;1237.node2.supernodexp.hpc;enqueuing into workq, state 1 hop 1
02/14/2018 16:36:59;0008;Server@node2;Job;1237.node2.supernodexp.hpc;Job Queued at request of ctminh@node2.supernodexp.hpc, owner = ctminh@node2.supernodexp.hpc, job name = nbody, queue = workq
02/14/2018 16:36:59;0100;Server@node2;Req;;Type 1 request received from ctminh@node2.supernodexp.hpc, sock=16
02/14/2018 16:36:59;0100;Server@node2;Req;;Type 3 request received from ctminh@node2.supernodexp.hpc, sock=16
02/14/2018 16:36:59;0100;Server@node2;Req;;Type 5 request received from ctminh@node2.supernodexp.hpc, sock=16
02/14/2018 16:36:59;0100;Server@node2;Job;1238.node2.supernodexp.hpc;enqueuing into workq, state 1 hop 1
02/14/2018 16:36:59;0008;Server@node2;Job;1238.node2.supernodexp.hpc;Job Queued at request of ctminh@node2.supernodexp.hpc, owner = ctminh@node2.supernodexp.hpc, job name = qe_mic_test, queue = workq
02/14/2018 16:36:59;0100;Server@node2;Req;;Type 1 request received from ctminh@node2.supernodexp.hpc, sock=16
02/14/2018 16:36:59;0100;Server@node2;Req;;Type 3 request received from ctminh@node2.supernodexp.hpc, sock=16
02/14/2018 16:36:59;0100;Server@node2;Req;;Type 5 request received from ctminh@node2.supernodexp.hpc, sock=16
02/14/2018 16:36:59;0100;Server@node2;Job;1239.node2.supernodexp.hpc;enqueuing into workq, state 1 hop 1
02/14/2018 16:36:59;0008;Server@node2;Job;1239.node2.supernodexp.hpc;Job Queued at request of ctminh@node2.supernodexp.hpc, owner = ctminh@node2.supernodexp.hpc, job name = thread-affinity, queue = workq
02/14/2018 16:36:59;0100;Server@node2;Req;;Type 20 request received from Scheduler@node2.supernodexp.hpc, sock=20
02/14/2018 16:36:59;0100;Server@node2;Req;;Type 51 request received from Scheduler@node2.supernodexp.hpc, sock=20
02/14/2018 16:36:59;0010;Server@node2;Job;1204.node2.supernodexp.hpc;Exit_status=0 resources_used.cpupercent=1081 resources_used.cput=00:13:33 resources_used.mem=99100kb resources_used.ncpus=16 resources_used.vmem=1468340kb resources_used.walltime=00:00:54
02/14/2018 16:36:59;0100;Server@node2;Job;1204.node2.supernodexp.hpc;dequeuing from workq, state 5
02/14/2018 16:36:59;0100;Server@node2;Req;;Type 1 request received from ctminh@node2.supernodexp.hpc, sock=16
02/14/2018 16:36:59;0100;Server@node2;Req;;Type 3 request received from ctminh@node2.supernodexp.hpc, sock=16
02/14/2018 16:36:59;0100;Server@node2;Req;;Type 5 request received from ctminh@node2.supernodexp.hpc, sock=16
02/14/2018 16:36:59;0100;Server@node2;Job;1240.node2.supernodexp.hpc;enqueuing into workq, state 1 hop 1
02/14/2018 16:36:59;0008;Server@node2;Job;1240.node2.supernodexp.hpc;Job Queued at request of ctminh@node2.supernodexp.hpc, owner = ctminh@node2.supernodexp.hpc, job name = thread-affinity, queue = workq
02/14/2018 16:36:59;0100;Server@node2;Req;;Type 1 request received from ctminh@node2.supernodexp.hpc, sock=16
02/14/2018 16:36:59;0100;Server@node2;Req;;Type 3 request received from ctminh@node2.supernodexp.hpc, sock=16
02/14/2018 16:36:59;0100;Server@node2;Req;;Type 5 request received from ctminh@node2.supernodexp.hpc, sock=16
02/14/2018 16:36:59;0100;Server@node2;Job;1241.node2.supernodexp.hpc;enqueuing into workq, state 1 hop 1
02/14/2018 16:36:59;0008;Server@node2;Job;1241.node2.supernodexp.hpc;Job Queued at request of ctminh@node2.supernodexp.hpc, owner = ctminh@node2.supernodexp.hpc, job name = telemac2, queue = workq
02/14/2018 16:36:59;0100;Server@node2;Req;;Type 1 request received from ctminh@node2.supernodexp.hpc, sock=16
02/14/2018 16:36:59;0100;Server@node2;Req;;Type 3 request received from ctminh@node2.supernodexp.hpc, sock=16
02/14/2018 16:36:59;0100;Server@node2;Req;;Type 5 request received from ctminh@node2.supernodexp.hpc, sock=16
02/14/2018 16:36:59;0100;Server@node2;Job;1242.node2.supernodexp.hpc;enqueuing into workq, state 1 hop 1
02/14/2018 16:36:59;0008;Server@node2;Job;1242.node2.supernodexp.hpc;Job Queued at request of ctminh@node2.supernodexp.hpc, owner = ctminh@node2.supernodexp.hpc, job name = qe_mic_test, queue = workq
02/14/2018 16:36:59;0100;Server@node2;Req;;Type 11 request received from Scheduler@node2.supernodexp.hpc, sock=20
02/14/2018 16:36:59;0008;Server@node2;Job;1229.node2.supernodexp.hpc;Job Modified at request of Scheduler@node2.supernodexp.hpc
02/14/2018 16:36:59;0100;Server@node2;Req;;Type 11 request received from Scheduler@node2.supernodexp.hpc, sock=20
02/14/2018 16:36:59;0008;Server@node2;Job;1230.node2.supernodexp.hpc;Job Modified at request of Scheduler@node2.supernodexp.hpc
02/14/2018 16:36:59;0100;Server@node2;Req;;Type 11 request received from Scheduler@node2.supernodexp.hpc, sock=20
02/14/2018 16:36:59;0008;Server@node2;Job;1231.node2.supernodexp.hpc;Job Modified at request of Scheduler@node2.supernodexp.hpc
02/14/2018 16:36:59;0100;Server@node2;Req;;Type 11 request received from Scheduler@node2.supernodexp.hpc, sock=20
02/14/2018 16:36:59;0008;Server@node2;Job;1232.node2.supernodexp.hpc;Job Modified at request of Scheduler@node2.supernodexp.hpc
02/14/2018 16:36:59;0100;Server@node2;Req;;Type 11 request received from Scheduler@node2.supernodexp.hpc, sock=20
02/14/2018 16:36:59;0008;Server@node2;Job;1233.node2.supernodexp.hpc;Job Modified at request of Scheduler@node2.supernodexp.hpc
02/14/2018 16:36:59;0100;Server@node2;Req;;Type 11 request received from Scheduler@node2.supernodexp.hpc, sock=20
02/14/2018 16:36:59;0008;Server@node2;Job;1234.node2.supernodexp.hpc;Job Modified at request of Scheduler@node2.supernodexp.hpc
02/14/2018 16:36:59;0100;Server@node2;Req;;Type 11 request received from Scheduler@node2.supernodexp.hpc, sock=20
02/14/2018 16:36:59;0008;Server@node2;Job;1235.node2.supernodexp.hpc;Job Modified at request of Scheduler@node2.supernodexp.hpc
02/14/2018 16:36:59;0100;Server@node2;Req;;Type 11 request received from Scheduler@node2.supernodexp.hpc, sock=20
02/14/2018 16:36:59;0008;Server@node2;Job;1236.node2.supernodexp.hpc;Job Modified at request of Scheduler@node2.supernodexp.hpc
02/14/2018 16:36:59;0100;Server@node2;Req;;Type 11 request received from Scheduler@node2.supernodexp.hpc, sock=20
02/14/2018 16:36:59;0008;Server@node2;Job;1237.node2.supernodexp.hpc;Job Modified at request of Scheduler@node2.supernodexp.hpc
02/14/2018 16:36:59;0100;Server@node2;Req;;Type 11 request received from Scheduler@node2.supernodexp.hpc, sock=20
02/14/2018 16:36:59;0008;Server@node2;Job;1238.node2.supernodexp.hpc;Job Modified at request of Scheduler@node2.supernodexp.hpc
02/14/2018 16:36:59;0100;Server@node2;Req;;Type 11 request received from Scheduler@node2.supernodexp.hpc, sock=20
02/14/2018 16:36:59;0008;Server@node2;Job;1239.node2.supernodexp.hpc;Job Modified at request of Scheduler@node2.supernodexp.hpc
02/14/2018 16:36:59;0040;Server@node2;Svr;node2.supernodexp.hpc;Scheduler sent command 1
02/14/2018 16:36:59;0040;Server@node2;Svr;node2.supernodexp.hpc;Scheduler sent command 0
02/14/2018 16:36:59;0100;Server@node2;Req;;Type 21 request received from Scheduler@node2.supernodexp.hpc, sock=20
02/14/2018 16:36:59;0100;Server@node2;Req;;Type 81 request received from Scheduler@node2.supernodexp.hpc, sock=20
02/14/2018 16:36:59;0100;Server@node2;Req;;Type 71 request received from Scheduler@node2.supernodexp.hpc, sock=20
02/14/2018 16:36:59;0100;Server@node2;Req;;Type 58 request received from Scheduler@node2.supernodexp.hpc, sock=20
02/14/2018 16:36:59;0100;Server@node2;Req;;Type 1 request received from ctminh@node2.supernodexp.hpc, sock=16
02/14/2018 16:36:59;0100;Server@node2;Req;;Type 3 request received from ctminh@node2.supernodexp.hpc, sock=16
02/14/2018 16:36:59;0100;Server@node2;Req;;Type 5 request received from ctminh@node2.supernodexp.hpc, sock=16
02/14/2018 16:36:59;0100;Server@node2;Job;1243.node2.supernodexp.hpc;enqueuing into workq, state 1 hop 1
02/14/2018 16:36:59;0008;Server@node2;Job;1243.node2.supernodexp.hpc;Job Queued at request of ctminh@node2.supernodexp.hpc, owner = ctminh@node2.supernodexp.hpc, job name = telemac2, queue = workq
02/14/2018 16:36:59;0100;Server@node2;Req;;Type 1 request received from ctminh@node2.supernodexp.hpc, sock=16
02/14/2018 16:36:59;0100;Server@node2;Req;;Type 3 request received from ctminh@node2.supernodexp.hpc, sock=16
02/14/2018 16:36:59;0100;Server@node2;Req;;Type 5 request received from ctminh@node2.supernodexp.hpc, sock=16
02/14/2018 16:36:59;0100;Server@node2;Job;1244.node2.supernodexp.hpc;enqueuing into workq, state 1 hop 1
02/14/2018 16:36:59;0008;Server@node2;Job;1244.node2.supernodexp.hpc;Job Queued at request of ctminh@node2.supernodexp.hpc, owner = ctminh@node2.supernodexp.hpc, job name = sweep, queue = workq
02/14/2018 16:36:59;0100;Server@node2;Req;;Type 20 request received from Scheduler@node2.supernodexp.hpc, sock=20
02/14/2018 16:36:59;0100;Server@node2;Req;;Type 51 request received from Scheduler@node2.supernodexp.hpc, sock=20
02/14/2018 16:36:59;0100;Server@node2;Req;;Type 11 request received from Scheduler@node2.supernodexp.hpc, sock=20
02/14/2018 16:36:59;0008;Server@node2;Job;1208.node2.supernodexp.hpc;Job Modified at request of Scheduler@node2.supernodexp.hpc
02/14/2018 16:36:59;0100;Server@node2;Req;;Type 11 request received from Scheduler@node2.supernodexp.hpc, sock=20
02/14/2018 16:36:59;0008;Server@node2;Job;1209.node2.supernodexp.hpc;Job Modified at request of Scheduler@node2.supernodexp.hpc
02/14/2018 16:36:59;0100;Server@node2;Req;;Type 23 request received from Scheduler@node2.supernodexp.hpc, sock=20
02/14/2018 16:36:59;0008;Server@node2;Job;1210.node2.supernodexp.hpc;Job Run at request of Scheduler@node2.supernodexp.hpc on exec_vnode (node14:ncpus=12:mem=1048576kb)
02/14/2018 16:36:59;0001;Server@node2;Svr;Server@node2;Success (0) in req_runjob2, return value of svr_startjob is 0
02/14/2018 16:36:59;0100;Server@node2;Req;;Type 11 request received from Scheduler@node2.supernodexp.hpc, sock=20
02/14/2018 16:36:59;0008;Server@node2;Job;1211.node2.supernodexp.hpc;Job Modified at request of Scheduler@node2.supernodexp.hpc
02/14/2018 16:36:59;0100;Server@node2;Req;;Type 11 request received from Scheduler@node2.supernodexp.hpc, sock=20
02/14/2018 16:36:59;0008;Server@node2;Job;1212.node2.supernodexp.hpc;Job Modified at request of Scheduler@node2.supernodexp.hpc
02/14/2018 16:36:59;0100;Server@node2;Req;;Type 11 request received from Scheduler@node2.supernodexp.hpc, sock=20
02/14/2018 16:36:59;0008;Server@node2;Job;1213.node2.supernodexp.hpc;Job Modified at request of Scheduler@node2.supernodexp.hpc
02/14/2018 16:36:59;0100;Server@node2;Req;;Type 11 request received from Scheduler@node2.supernodexp.hpc, sock=20
02/14/2018 16:36:59;0008;Server@node2;Job;1214.node2.supernodexp.hpc;Job Modified at request of Scheduler@node2.supernodexp.hpc
02/14/2018 16:36:59;0100;Server@node2;Req;;Type 11 request received from Scheduler@node2.supernodexp.hpc, sock=20
02/14/2018 16:36:59;0008;Server@node2;Job;1215.node2.supernodexp.hpc;Job Modified at request of Scheduler@node2.supernodexp.hpc
02/14/2018 16:36:59;0100;Server@node2;Req;;Type 11 request received from Scheduler@node2.supernodexp.hpc, sock=20
02/14/2018 16:36:59;0008;Server@node2;Job;1216.node2.supernodexp.hpc;Job Modified at request of Scheduler@node2.supernodexp.hpc
02/14/2018 16:36:59;0100;Server@node2;Req;;Type 11 request received from Scheduler@node2.supernodexp.hpc, sock=20
02/14/2018 16:36:59;0008;Server@node2;Job;1218.node2.supernodexp.hpc;Job Modified at request of Scheduler@node2.supernodexp.hpc
02/14/2018 16:36:59;0100;Server@node2;Req;;Type 11 request received from Scheduler@node2.supernodexp.hpc, sock=20
02/14/2018 16:36:59;0008;Server@node2;Job;1219.node2.supernodexp.hpc;Job Modified at request of Scheduler@node2.supernodexp.hpc
02/14/2018 16:36:59;0100;Server@node2;Req;;Type 11 request received from Scheduler@node2.supernodexp.hpc, sock=20
02/14/2018 16:36:59;0008;Server@node2;Job;1220.node2.supernodexp.hpc;Job Modified at request of Scheduler@node2.supernodexp.hpc
02/14/2018 16:36:59;0100;Server@node2;Req;;Type 11 request received from Scheduler@node2.supernodexp.hpc, sock=20
02/14/2018 16:36:59;0008;Server@node2;Job;1221.node2.supernodexp.hpc;Job Modified at request of Scheduler@node2.supernodexp.hpc
02/14/2018 16:36:59;0100;Server@node2;Req;;Type 11 request received from Scheduler@node2.supernodexp.hpc, sock=20
02/14/2018 16:36:59;0008;Server@node2;Job;1222.node2.supernodexp.hpc;Job Modified at request of Scheduler@node2.supernodexp.hpc
02/14/2018 16:36:59;0100;Server@node2;Req;;Type 11 request received from Scheduler@node2.supernodexp.hpc, sock=20
02/14/2018 16:36:59;0008;Server@node2;Job;1223.node2.supernodexp.hpc;Job Modified at request of Scheduler@node2.supernodexp.hpc
02/14/2018 16:36:59;0100;Server@node2;Req;;Type 11 request received from Scheduler@node2.supernodexp.hpc, sock=20
02/14/2018 16:36:59;0008;Server@node2;Job;1224.node2.supernodexp.hpc;Job Modified at request of Scheduler@node2.supernodexp.hpc
02/14/2018 16:36:59;0100;Server@node2;Req;;Type 11 request received from Scheduler@node2.supernodexp.hpc, sock=20
02/14/2018 16:36:59;0008;Server@node2;Job;1225.node2.supernodexp.hpc;Job Modified at request of Scheduler@node2.supernodexp.hpc
02/14/2018 16:36:59;0100;Server@node2;Req;;Type 11 request received from Scheduler@node2.supernodexp.hpc, sock=20
02/14/2018 16:36:59;0008;Server@node2;Job;1226.node2.supernodexp.hpc;Job Modified at request of Scheduler@node2.supernodexp.hpc
02/14/2018 16:36:59;0100;Server@node2;Req;;Type 11 request received from Scheduler@node2.supernodexp.hpc, sock=20
02/14/2018 16:36:59;0008;Server@node2;Job;1227.node2.supernodexp.hpc;Job Modified at request of Scheduler@node2.supernodexp.hpc
02/14/2018 16:36:59;0100;Server@node2;Req;;Type 11 request received from Scheduler@node2.supernodexp.hpc, sock=20
02/14/2018 16:36:59;0008;Server@node2;Job;1228.node2.supernodexp.hpc;Job Modified at request of Scheduler@node2.supernodexp.hpc
02/14/2018 16:36:59;0100;Server@node2;Req;;Type 11 request received from Scheduler@node2.supernodexp.hpc, sock=20
02/14/2018 16:36:59;0008;Server@node2;Job;1229.node2.supernodexp.hpc;Job Modified at request of Scheduler@node2.supernodexp.hpc
02/14/2018 16:36:59;0100;Server@node2;Req;;Type 11 request received from Scheduler@node2.supernodexp.hpc, sock=20
02/14/2018 16:36:59;0008;Server@node2;Job;1230.node2.supernodexp.hpc;Job Modified at request of Scheduler@node2.supernodexp.hpc
02/14/2018 16:36:59;0100;Server@node2;Req;;Type 11 request received from Scheduler@node2.supernodexp.hpc, sock=20
02/14/2018 16:36:59;0008;Server@node2;Job;1231.node2.supernodexp.hpc;Job Modified at request of Scheduler@node2.supernodexp.hpc
02/14/2018 16:36:59;0100;Server@node2;Req;;Type 11 request received from Scheduler@node2.supernodexp.hpc, sock=20
02/14/2018 16:36:59;0008;Server@node2;Job;1232.node2.supernodexp.hpc;Job Modified at request of Scheduler@node2.supernodexp.hpc
02/14/2018 16:36:59;0100;Server@node2;Req;;Type 11 request received from Scheduler@node2.supernodexp.hpc, sock=20
02/14/2018 16:36:59;0008;Server@node2;Job;1233.node2.supernodexp.hpc;Job Modified at request of Scheduler@node2.supernodexp.hpc
02/14/2018 16:36:59;0100;Server@node2;Req;;Type 11 request received from Scheduler@node2.supernodexp.hpc, sock=20
02/14/2018 16:36:59;0008;Server@node2;Job;1234.node2.supernodexp.hpc;Job Modified at request of Scheduler@node2.supernodexp.hpc
02/14/2018 16:36:59;0100;Server@node2;Req;;Type 11 request received from Scheduler@node2.supernodexp.hpc, sock=20
02/14/2018 16:36:59;0008;Server@node2;Job;1235.node2.supernodexp.hpc;Job Modified at request of Scheduler@node2.supernodexp.hpc
02/14/2018 16:36:59;0100;Server@node2;Req;;Type 11 request received from Scheduler@node2.supernodexp.hpc, sock=20
02/14/2018 16:36:59;0008;Server@node2;Job;1236.node2.supernodexp.hpc;Job Modified at request of Scheduler@node2.supernodexp.hpc
02/14/2018 16:36:59;0100;Server@node2;Req;;Type 11 request received from Scheduler@node2.supernodexp.hpc, sock=20
02/14/2018 16:36:59;0008;Server@node2;Job;1237.node2.supernodexp.hpc;Job Modified at request of Scheduler@node2.supernodexp.hpc
02/14/2018 16:36:59;0100;Server@node2;Req;;Type 11 request received from Scheduler@node2.supernodexp.hpc, sock=20
02/14/2018 16:36:59;0008;Server@node2;Job;1238.node2.supernodexp.hpc;Job Modified at request of Scheduler@node2.supernodexp.hpc
02/14/2018 16:36:59;0100;Server@node2;Req;;Type 11 request received from Scheduler@node2.supernodexp.hpc, sock=20
02/14/2018 16:36:59;0008;Server@node2;Job;1239.node2.supernodexp.hpc;Job Modified at request of Scheduler@node2.supernodexp.hpc
02/14/2018 16:36:59;0100;Server@node2;Req;;Type 11 request received from Scheduler@node2.supernodexp.hpc, sock=20
02/14/2018 16:36:59;0008;Server@node2;Job;1240.node2.supernodexp.hpc;Job Modified at request of Scheduler@node2.supernodexp.hpc
02/14/2018 16:36:59;0100;Server@node2;Req;;Type 11 request received from Scheduler@node2.supernodexp.hpc, sock=20
02/14/2018 16:36:59;0008;Server@node2;Job;1241.node2.supernodexp.hpc;Job Modified at request of Scheduler@node2.supernodexp.hpc
02/14/2018 16:36:59;0100;Server@node2;Req;;Type 11 request received from Scheduler@node2.supernodexp.hpc, sock=20
02/14/2018 16:36:59;0008;Server@node2;Job;1242.node2.supernodexp.hpc;Job Modified at request of Scheduler@node2.supernodexp.hpc
02/14/2018 16:36:59;0100;Server@node2;Req;;Type 11 request received from Scheduler@node2.supernodexp.hpc, sock=20
02/14/2018 16:36:59;0008;Server@node2;Job;1243.node2.supernodexp.hpc;Job Modified at request of Scheduler@node2.supernodexp.hpc
02/14/2018 16:36:59;0100;Server@node2;Req;;Type 11 request received from Scheduler@node2.supernodexp.hpc, sock=20
02/14/2018 16:36:59;0008;Server@node2;Job;1244.node2.supernodexp.hpc;Job Modified at request of Scheduler@node2.supernodexp.hpc
02/14/2018 16:36:59;0040;Server@node2;Svr;node2.supernodexp.hpc;Scheduler sent command 1
02/14/2018 16:36:59;0040;Server@node2;Svr;node2.supernodexp.hpc;Scheduler sent command 0
02/14/2018 16:36:59;0100;Server@node2;Req;;Type 21 request received from Scheduler@node2.supernodexp.hpc, sock=20
02/14/2018 16:36:59;0100;Server@node2;Req;;Type 81 request received from Scheduler@node2.supernodexp.hpc, sock=20
02/14/2018 16:36:59;0100;Server@node2;Req;;Type 71 request received from Scheduler@node2.supernodexp.hpc, sock=20
02/14/2018 16:36:59;0100;Server@node2;Req;;Type 58 request received from Scheduler@node2.supernodexp.hpc, sock=20
02/14/2018 16:36:59;0100;Server@node2;Req;;Type 20 request received from Scheduler@node2.supernodexp.hpc, sock=20
02/14/2018 16:36:59;0100;Server@node2;Req;;Type 51 request received from Scheduler@node2.supernodexp.hpc, sock=20
02/14/2018 16:36:59;0100;Server@node2;Req;;Type 11 request received from Scheduler@node2.supernodexp.hpc, sock=20
02/14/2018 16:36:59;0008;Server@node2;Job;1208.node2.supernodexp.hpc;Job Modified at request of Scheduler@node2.supernodexp.hpc
02/14/2018 16:36:59;0100;Server@node2;Req;;Type 11 request received from Scheduler@node2.supernodexp.hpc, sock=20
02/14/2018 16:36:59;0008;Server@node2;Job;1209.node2.supernodexp.hpc;Job Modified at request of Scheduler@node2.supernodexp.hpc
02/14/2018 16:37:00;0080;Server@node2;Job;1217.node2.supernodexp.hpc;Obit received momhop:1 serverhop:1 state:4 substate:42
02/14/2018 16:37:01;0010;Server@node2;Job;1217.node2.supernodexp.hpc;Exit_status=0 resources_used.cpupercent=800 resources_used.cput=00:00:09 resources_used.mem=1108140kb resources_used.ncpus=8 resources_used.vmem=3942468kb resources_used.walltime=00:00:02
02/14/2018 16:37:01;0100;Server@node2;Job;1217.node2.supernodexp.hpc;dequeuing from workq, state 5
02/14/2018 16:37:01;0040;Server@node2;Svr;node2.supernodexp.hpc;Scheduler sent command 2
02/14/2018 16:37:01;0040;Server@node2;Svr;node2.supernodexp.hpc;Scheduler sent command 0
02/14/2018 16:37:01;0100;Server@node2;Req;;Type 21 request received from Scheduler@node2.supernodexp.hpc, sock=20
02/14/2018 16:37:01;0100;Server@node2;Req;;Type 81 request received from Scheduler@node2.supernodexp.hpc, sock=20
02/14/2018 16:37:01;0100;Server@node2;Req;;Type 71 request received from Scheduler@node2.supernodexp.hpc, sock=20
02/14/2018 16:37:01;0100;Server@node2;Req;;Type 58 request received from Scheduler@node2.supernodexp.hpc, sock=20
02/14/2018 16:37:01;0100;Server@node2;Req;;Type 20 request received from Scheduler@node2.supernodexp.hpc, sock=20
02/14/2018 16:37:01;0100;Server@node2;Req;;Type 51 request received from Scheduler@node2.supernodexp.hpc, sock=20
02/14/2018 16:37:01;0100;Server@node2;Req;;Type 11 request received from Scheduler@node2.supernodexp.hpc, sock=20
02/14/2018 16:37:01;0008;Server@node2;Job;1208.node2.supernodexp.hpc;Job Modified at request of Scheduler@node2.supernodexp.hpc
02/14/2018 16:37:01;0100;Server@node2;Req;;Type 11 request received from Scheduler@node2.supernodexp.hpc, sock=20
02/14/2018 16:37:01;0008;Server@node2;Job;1209.node2.supernodexp.hpc;Job Modified at request of Scheduler@node2.supernodexp.hpc
02/14/2018 16:37:01;0100;Server@node2;Req;;Type 11 request received from Scheduler@node2.supernodexp.hpc, sock=20
02/14/2018 16:37:01;0008;Server@node2;Job;1211.node2.supernodexp.hpc;Job Modified at request of Scheduler@node2.supernodexp.hpc
02/14/2018 16:37:01;0100;Server@node2;Req;;Type 11 request received from Scheduler@node2.supernodexp.hpc, sock=20
02/14/2018 16:37:01;0008;Server@node2;Job;1212.node2.supernodexp.hpc;Job Modified at request of Scheduler@node2.supernodexp.hpc
02/14/2018 16:37:01;0100;Server@node2;Req;;Type 11 request received from Scheduler@node2.supernodexp.hpc, sock=20
02/14/2018 16:37:01;0008;Server@node2;Job;1213.node2.supernodexp.hpc;Job Modified at request of Scheduler@node2.supernodexp.hpc
02/14/2018 16:37:01;0100;Server@node2;Req;;Type 11 request received from Scheduler@node2.supernodexp.hpc, sock=20
02/14/2018 16:37:01;0008;Server@node2;Job;1214.node2.supernodexp.hpc;Job Modified at request of Scheduler@node2.supernodexp.hpc
02/14/2018 16:37:01;0100;Server@node2;Req;;Type 11 request received from Scheduler@node2.supernodexp.hpc, sock=20
02/14/2018 16:37:01;0008;Server@node2;Job;1215.node2.supernodexp.hpc;Job Modified at request of Scheduler@node2.supernodexp.hpc
02/14/2018 16:37:01;0100;Server@node2;Req;;Type 11 request received from Scheduler@node2.supernodexp.hpc, sock=20
02/14/2018 16:37:01;0008;Server@node2;Job;1216.node2.supernodexp.hpc;Job Modified at request of Scheduler@node2.supernodexp.hpc
02/14/2018 16:37:01;0100;Server@node2;Req;;Type 11 request received from Scheduler@node2.supernodexp.hpc, sock=20
02/14/2018 16:37:01;0008;Server@node2;Job;1218.node2.supernodexp.hpc;Job Modified at request of Scheduler@node2.supernodexp.hpc
02/14/2018 16:37:01;0100;Server@node2;Req;;Type 11 request received from Scheduler@node2.supernodexp.hpc, sock=20
02/14/2018 16:37:01;0008;Server@node2;Job;1219.node2.supernodexp.hpc;Job Modified at request of Scheduler@node2.supernodexp.hpc
02/14/2018 16:37:01;0100;Server@node2;Req;;Type 11 request received from Scheduler@node2.supernodexp.hpc, sock=20
02/14/2018 16:37:01;0008;Server@node2;Job;1220.node2.supernodexp.hpc;Job Modified at request of Scheduler@node2.supernodexp.hpc
02/14/2018 16:37:01;0100;Server@node2;Req;;Type 11 request received from Scheduler@node2.supernodexp.hpc, sock=20
02/14/2018 16:37:01;0008;Server@node2;Job;1221.node2.supernodexp.hpc;Job Modified at request of Scheduler@node2.supernodexp.hpc
02/14/2018 16:37:01;0100;Server@node2;Req;;Type 11 request received from Scheduler@node2.supernodexp.hpc, sock=20
02/14/2018 16:37:01;0008;Server@node2;Job;1222.node2.supernodexp.hpc;Job Modified at request of Scheduler@node2.supernodexp.hpc
02/14/2018 16:37:01;0100;Server@node2;Req;;Type 23 request received from Scheduler@node2.supernodexp.hpc, sock=20
02/14/2018 16:37:01;0008;Server@node2;Job;1223.node2.supernodexp.hpc;Job Run at request of Scheduler@node2.supernodexp.hpc on exec_vnode (node14:ncpus=12:mem=1048576kb)
02/14/2018 16:37:01;0001;Server@node2;Svr;Server@node2;Success (0) in req_runjob2, return value of svr_startjob is 0
02/14/2018 16:37:01;0100;Server@node2;Req;;Type 11 request received from Scheduler@node2.supernodexp.hpc, sock=20
02/14/2018 16:37:01;0008;Server@node2;Job;1224.node2.supernodexp.hpc;Job Modified at request of Scheduler@node2.supernodexp.hpc
02/14/2018 16:37:01;0100;Server@node2;Req;;Type 11 request received from Scheduler@node2.supernodexp.hpc, sock=20
02/14/2018 16:37:01;0008;Server@node2;Job;1225.node2.supernodexp.hpc;Job Modified at request of Scheduler@node2.supernodexp.hpc
02/14/2018 16:37:01;0100;Server@node2;Req;;Type 11 request received from Scheduler@node2.supernodexp.hpc, sock=20
02/14/2018 16:37:01;0008;Server@node2;Job;1226.node2.supernodexp.hpc;Job Modified at request of Scheduler@node2.supernodexp.hpc
02/14/2018 16:37:01;0100;Server@node2;Req;;Type 11 request received from Scheduler@node2.supernodexp.hpc, sock=20
02/14/2018 16:37:01;0008;Server@node2;Job;1227.node2.supernodexp.hpc;Job Modified at request of Scheduler@node2.supernodexp.hpc
02/14/2018 16:37:01;0100;Server@node2;Req;;Type 11 request received from Scheduler@node2.supernodexp.hpc, sock=20
02/14/2018 16:37:01;0008;Server@node2;Job;1228.node2.supernodexp.hpc;Job Modified at request of Scheduler@node2.supernodexp.hpc
02/14/2018 16:37:01;0100;Server@node2;Req;;Type 11 request received from Scheduler@node2.supernodexp.hpc, sock=20
02/14/2018 16:37:01;0008;Server@node2;Job;1229.node2.supernodexp.hpc;Job Modified at request of Scheduler@node2.supernodexp.hpc
02/14/2018 16:37:01;0100;Server@node2;Req;;Type 11 request received from Scheduler@node2.supernodexp.hpc, sock=20
02/14/2018 16:37:01;0008;Server@node2;Job;1230.node2.supernodexp.hpc;Job Modified at request of Scheduler@node2.supernodexp.hpc
02/14/2018 16:37:01;0100;Server@node2;Req;;Type 11 request received from Scheduler@node2.supernodexp.hpc, sock=20
02/14/2018 16:37:01;0008;Server@node2;Job;1231.node2.supernodexp.hpc;Job Modified at request of Scheduler@node2.supernodexp.hpc
02/14/2018 16:37:01;0100;Server@node2;Req;;Type 11 request received from Scheduler@node2.supernodexp.hpc, sock=20
02/14/2018 16:37:01;0008;Server@node2;Job;1232.node2.supernodexp.hpc;Job Modified at request of Scheduler@node2.supernodexp.hpc
02/14/2018 16:37:01;0100;Server@node2;Req;;Type 11 request received from Scheduler@node2.supernodexp.hpc, sock=20
02/14/2018 16:37:01;0008;Server@node2;Job;1233.node2.supernodexp.hpc;Job Modified at request of Scheduler@node2.supernodexp.hpc
02/14/2018 16:37:01;0100;Server@node2;Req;;Type 11 request received from Scheduler@node2.supernodexp.hpc, sock=20
02/14/2018 16:37:01;0008;Server@node2;Job;1234.node2.supernodexp.hpc;Job Modified at request of Scheduler@node2.supernodexp.hpc
02/14/2018 16:37:01;0100;Server@node2;Req;;Type 11 request received from Scheduler@node2.supernodexp.hpc, sock=20
02/14/2018 16:37:01;0008;Server@node2;Job;1235.node2.supernodexp.hpc;Job Modified at request of Scheduler@node2.supernodexp.hpc
02/14/2018 16:37:01;0100;Server@node2;Req;;Type 11 request received from Scheduler@node2.supernodexp.hpc, sock=20
02/14/2018 16:37:01;0008;Server@node2;Job;1236.node2.supernodexp.hpc;Job Modified at request of Scheduler@node2.supernodexp.hpc
02/14/2018 16:37:01;0100;Server@node2;Req;;Type 11 request received from Scheduler@node2.supernodexp.hpc, sock=20
02/14/2018 16:37:01;0008;Server@node2;Job;1237.node2.supernodexp.hpc;Job Modified at request of Scheduler@node2.supernodexp.hpc
02/14/2018 16:37:01;0100;Server@node2;Req;;Type 11 request received from Scheduler@node2.supernodexp.hpc, sock=20
02/14/2018 16:37:01;0008;Server@node2;Job;1238.node2.supernodexp.hpc;Job Modified at request of Scheduler@node2.supernodexp.hpc
02/14/2018 16:37:01;0100;Server@node2;Req;;Type 11 request received from Scheduler@node2.supernodexp.hpc, sock=20
02/14/2018 16:37:01;0008;Server@node2;Job;1239.node2.supernodexp.hpc;Job Modified at request of Scheduler@node2.supernodexp.hpc
02/14/2018 16:37:01;0100;Server@node2;Req;;Type 11 request received from Scheduler@node2.supernodexp.hpc, sock=20
02/14/2018 16:37:01;0008;Server@node2;Job;1240.node2.supernodexp.hpc;Job Modified at request of Scheduler@node2.supernodexp.hpc
02/14/2018 16:37:01;0100;Server@node2;Req;;Type 11 request received from Scheduler@node2.supernodexp.hpc, sock=20
02/14/2018 16:37:01;0008;Server@node2;Job;1241.node2.supernodexp.hpc;Job Modified at request of Scheduler@node2.supernodexp.hpc
02/14/2018 16:37:01;0100;Server@node2;Req;;Type 11 request received from Scheduler@node2.supernodexp.hpc, sock=20
02/14/2018 16:37:01;0008;Server@node2;Job;1242.node2.supernodexp.hpc;Job Modified at request of Scheduler@node2.supernodexp.hpc
02/14/2018 16:37:01;0100;Server@node2;Req;;Type 11 request received from Scheduler@node2.supernodexp.hpc, sock=20
02/14/2018 16:37:01;0008;Server@node2;Job;1243.node2.supernodexp.hpc;Job Modified at request of Scheduler@node2.supernodexp.hpc
02/14/2018 16:37:01;0100;Server@node2;Req;;Type 11 request received from Scheduler@node2.supernodexp.hpc, sock=20
02/14/2018 16:37:01;0008;Server@node2;Job;1244.node2.supernodexp.hpc;Job Modified at request of Scheduler@node2.supernodexp.hpc
02/14/2018 16:37:10;0080;Server@node2;Job;1210.node2.supernodexp.hpc;Obit received momhop:1 serverhop:1 state:4 substate:42
02/14/2018 16:37:11;0080;Server@node2;Job;1223.node2.supernodexp.hpc;Obit received momhop:1 serverhop:1 state:4 substate:42
02/14/2018 16:37:12;0010;Server@node2;Job;1210.node2.supernodexp.hpc;Exit_status=0 resources_used.cpupercent=100 resources_used.cput=00:00:11 resources_used.mem=11620kb resources_used.ncpus=12 resources_used.vmem=531996kb resources_used.walltime=00:00:12
02/14/2018 16:37:12;0100;Server@node2;Job;1210.node2.supernodexp.hpc;dequeuing from workq, state 5
02/14/2018 16:37:12;0040;Server@node2;Svr;node2.supernodexp.hpc;Scheduler sent command 2
02/14/2018 16:37:12;0040;Server@node2;Svr;node2.supernodexp.hpc;Scheduler sent command 0
02/14/2018 16:37:12;0100;Server@node2;Req;;Type 21 request received from Scheduler@node2.supernodexp.hpc, sock=20
02/14/2018 16:37:12;0100;Server@node2;Req;;Type 81 request received from Scheduler@node2.supernodexp.hpc, sock=20
02/14/2018 16:37:12;0100;Server@node2;Req;;Type 71 request received from Scheduler@node2.supernodexp.hpc, sock=20
02/14/2018 16:37:12;0100;Server@node2;Req;;Type 58 request received from Scheduler@node2.supernodexp.hpc, sock=20
02/14/2018 16:37:12;0100;Server@node2;Req;;Type 20 request received from Scheduler@node2.supernodexp.hpc, sock=20
02/14/2018 16:37:12;0100;Server@node2;Req;;Type 51 request received from Scheduler@node2.supernodexp.hpc, sock=20
02/14/2018 16:37:12;0100;Server@node2;Req;;Type 11 request received from Scheduler@node2.supernodexp.hpc, sock=20
02/14/2018 16:37:12;0008;Server@node2;Job;1224.node2.supernodexp.hpc;Job Modified at request of Scheduler@node2.supernodexp.hpc
02/14/2018 16:37:12;0100;Server@node2;Req;;Type 11 request received from Scheduler@node2.supernodexp.hpc, sock=20
02/14/2018 16:37:12;0008;Server@node2;Job;1225.node2.supernodexp.hpc;Job Modified at request of Scheduler@node2.supernodexp.hpc
02/14/2018 16:37:12;0100;Server@node2;Req;;Type 11 request received from Scheduler@node2.supernodexp.hpc, sock=20
02/14/2018 16:37:12;0008;Server@node2;Job;1226.node2.supernodexp.hpc;Job Modified at request of Scheduler@node2.supernodexp.hpc
02/14/2018 16:37:12;0100;Server@node2;Req;;Type 11 request received from Scheduler@node2.supernodexp.hpc, sock=20
02/14/2018 16:37:12;0008;Server@node2;Job;1227.node2.supernodexp.hpc;Job Modified at request of Scheduler@node2.supernodexp.hpc
02/14/2018 16:37:12;0100;Server@node2;Req;;Type 11 request received from Scheduler@node2.supernodexp.hpc, sock=20
02/14/2018 16:37:12;0008;Server@node2;Job;1228.node2.supernodexp.hpc;Job Modified at request of Scheduler@node2.supernodexp.hpc
02/14/2018 16:37:12;0100;Server@node2;Req;;Type 11 request received from Scheduler@node2.supernodexp.hpc, sock=20
02/14/2018 16:37:12;0008;Server@node2;Job;1229.node2.supernodexp.hpc;Job Modified at request of Scheduler@node2.supernodexp.hpc
02/14/2018 16:37:12;0100;Server@node2;Req;;Type 23 request received from Scheduler@node2.supernodexp.hpc, sock=20
02/14/2018 16:37:12;0008;Server@node2;Job;1230.node2.supernodexp.hpc;Job Run at request of Scheduler@node2.supernodexp.hpc on exec_vnode (node14:ncpus=12:mem=1048576kb)
02/14/2018 16:37:12;0001;Server@node2;Svr;Server@node2;Success (0) in req_runjob2, return value of svr_startjob is 0
02/14/2018 16:37:12;0010;Server@node2;Job;1223.node2.supernodexp.hpc;Exit_status=0 resources_used.cpupercent=1200 resources_used.cput=00:01:52 resources_used.mem=29544kb resources_used.ncpus=12 resources_used.vmem=1125536kb resources_used.walltime=00:00:09
02/14/2018 16:37:12;0100;Server@node2;Job;1223.node2.supernodexp.hpc;dequeuing from workq, state 5
02/14/2018 16:37:12;0040;Server@node2;Svr;node2.supernodexp.hpc;Scheduler sent command 2
02/14/2018 16:37:12;0040;Server@node2;Svr;node2.supernodexp.hpc;Scheduler sent command 0
02/14/2018 16:37:12;0100;Server@node2;Req;;Type 21 request received from Scheduler@node2.supernodexp.hpc, sock=20
02/14/2018 16:37:12;0100;Server@node2;Req;;Type 81 request received from Scheduler@node2.supernodexp.hpc, sock=20
02/14/2018 16:37:12;0100;Server@node2;Req;;Type 71 request received from Scheduler@node2.supernodexp.hpc, sock=20
02/14/2018 16:37:12;0100;Server@node2;Req;;Type 58 request received from Scheduler@node2.supernodexp.hpc, sock=20
02/14/2018 16:37:12;0100;Server@node2;Req;;Type 20 request received from Scheduler@node2.supernodexp.hpc, sock=20
02/14/2018 16:37:12;0100;Server@node2;Req;;Type 51 request received from Scheduler@node2.supernodexp.hpc, sock=20
02/14/2018 16:37:12;0100;Server@node2;Req;;Type 11 request received from Scheduler@node2.supernodexp.hpc, sock=20
02/14/2018 16:37:12;0008;Server@node2;Job;1231.node2.supernodexp.hpc;Job Modified at request of Scheduler@node2.supernodexp.hpc
02/14/2018 16:37:12;0100;Server@node2;Req;;Type 23 request received from Scheduler@node2.supernodexp.hpc, sock=20
02/14/2018 16:37:12;0008;Server@node2;Job;1232.node2.supernodexp.hpc;Job Run at request of Scheduler@node2.supernodexp.hpc on exec_vnode (node14:ncpus=12:mem=1048576kb)
02/14/2018 16:37:12;0001;Server@node2;Svr;Server@node2;Success (0) in req_runjob2, return value of svr_startjob is 0
02/14/2018 16:37:22;0080;Server@node2;Job;1230.node2.supernodexp.hpc;Obit received momhop:1 serverhop:1 state:4 substate:42
02/14/2018 16:37:22;0080;Server@node2;Job;1232.node2.supernodexp.hpc;Obit received momhop:1 serverhop:1 state:4 substate:42
02/14/2018 16:37:23;0010;Server@node2;Job;1230.node2.supernodexp.hpc;Exit_status=0 resources_used.cpupercent=1081 resources_used.cput=00:01:59 resources_used.mem=0kb resources_used.ncpus=12 resources_used.vmem=0kb resources_used.walltime=00:00:11
02/14/2018 16:37:23;0100;Server@node2;Job;1230.node2.supernodexp.hpc;dequeuing from workq, state 5
02/14/2018 16:37:23;0040;Server@node2;Svr;node2.supernodexp.hpc;Scheduler sent command 2
02/14/2018 16:37:23;0040;Server@node2;Svr;node2.supernodexp.hpc;Scheduler sent command 0
02/14/2018 16:37:23;0100;Server@node2;Req;;Type 21 request received from Scheduler@node2.supernodexp.hpc, sock=20
02/14/2018 16:37:23;0100;Server@node2;Req;;Type 81 request received from Scheduler@node2.supernodexp.hpc, sock=20
02/14/2018 16:37:23;0100;Server@node2;Req;;Type 71 request received from Scheduler@node2.supernodexp.hpc, sock=20
02/14/2018 16:37:23;0100;Server@node2;Req;;Type 58 request received from Scheduler@node2.supernodexp.hpc, sock=20
02/14/2018 16:37:23;0100;Server@node2;Req;;Type 20 request received from Scheduler@node2.supernodexp.hpc, sock=20
02/14/2018 16:37:23;0100;Server@node2;Req;;Type 51 request received from Scheduler@node2.supernodexp.hpc, sock=20
02/14/2018 16:37:23;0100;Server@node2;Req;;Type 11 request received from Scheduler@node2.supernodexp.hpc, sock=20
02/14/2018 16:37:23;0008;Server@node2;Job;1233.node2.supernodexp.hpc;Job Modified at request of Scheduler@node2.supernodexp.hpc
02/14/2018 16:37:23;0100;Server@node2;Req;;Type 11 request received from Scheduler@node2.supernodexp.hpc, sock=20
02/14/2018 16:37:23;0008;Server@node2;Job;1234.node2.supernodexp.hpc;Job Modified at request of Scheduler@node2.supernodexp.hpc
02/14/2018 16:37:23;0100;Server@node2;Req;;Type 11 request received from Scheduler@node2.supernodexp.hpc, sock=20
02/14/2018 16:37:23;0008;Server@node2;Job;1235.node2.supernodexp.hpc;Job Modified at request of Scheduler@node2.supernodexp.hpc
02/14/2018 16:37:23;0100;Server@node2;Req;;Type 11 request received from Scheduler@node2.supernodexp.hpc, sock=20
02/14/2018 16:37:23;0008;Server@node2;Job;1236.node2.supernodexp.hpc;Job Modified at request of Scheduler@node2.supernodexp.hpc
02/14/2018 16:37:23;0100;Server@node2;Req;;Type 23 request received from Scheduler@node2.supernodexp.hpc, sock=20
02/14/2018 16:37:23;0008;Server@node2;Job;1237.node2.supernodexp.hpc;Job Run at request of Scheduler@node2.supernodexp.hpc on exec_vnode (node14:ncpus=12:mem=1048576kb)
02/14/2018 16:37:23;0001;Server@node2;Svr;Server@node2;Success (0) in req_runjob2, return value of svr_startjob is 0
02/14/2018 16:37:23;0010;Server@node2;Job;1232.node2.supernodexp.hpc;Exit_status=0 resources_used.cpupercent=1170 resources_used.cput=00:01:59 resources_used.mem=37796kb resources_used.ncpus=12 resources_used.vmem=1125536kb resources_used.walltime=00:00:11
02/14/2018 16:37:23;0100;Server@node2;Job;1232.node2.supernodexp.hpc;dequeuing from workq, state 5
02/14/2018 16:37:23;0040;Server@node2;Svr;node2.supernodexp.hpc;Scheduler sent command 2
02/14/2018 16:37:23;0040;Server@node2;Svr;node2.supernodexp.hpc;Scheduler sent command 0
02/14/2018 16:37:23;0100;Server@node2;Req;;Type 21 request received from Scheduler@node2.supernodexp.hpc, sock=20
02/14/2018 16:37:23;0100;Server@node2;Req;;Type 81 request received from Scheduler@node2.supernodexp.hpc, sock=20
02/14/2018 16:37:23;0100;Server@node2;Req;;Type 71 request received from Scheduler@node2.supernodexp.hpc, sock=20
02/14/2018 16:37:23;0100;Server@node2;Req;;Type 58 request received from Scheduler@node2.supernodexp.hpc, sock=20
02/14/2018 16:37:23;0100;Server@node2;Req;;Type 20 request received from Scheduler@node2.supernodexp.hpc, sock=20
02/14/2018 16:37:23;0100;Server@node2;Req;;Type 51 request received from Scheduler@node2.supernodexp.hpc, sock=20
02/14/2018 16:37:23;0100;Server@node2;Req;;Type 11 request received from Scheduler@node2.supernodexp.hpc, sock=20
02/14/2018 16:37:23;0008;Server@node2;Job;1238.node2.supernodexp.hpc;Job Modified at request of Scheduler@node2.supernodexp.hpc
02/14/2018 16:37:23;0100;Server@node2;Req;;Type 11 request received from Scheduler@node2.supernodexp.hpc, sock=20
02/14/2018 16:37:23;0008;Server@node2;Job;1239.node2.supernodexp.hpc;Job Modified at request of Scheduler@node2.supernodexp.hpc
02/14/2018 16:37:23;0100;Server@node2;Req;;Type 11 request received from Scheduler@node2.supernodexp.hpc, sock=20
02/14/2018 16:37:23;0008;Server@node2;Job;1240.node2.supernodexp.hpc;Job Modified at request of Scheduler@node2.supernodexp.hpc
02/14/2018 16:37:23;0100;Server@node2;Req;;Type 11 request received from Scheduler@node2.supernodexp.hpc, sock=20
02/14/2018 16:37:23;0008;Server@node2;Job;1241.node2.supernodexp.hpc;Job Modified at request of Scheduler@node2.supernodexp.hpc
02/14/2018 16:37:23;0100;Server@node2;Req;;Type 11 request received from Scheduler@node2.supernodexp.hpc, sock=20
02/14/2018 16:37:23;0008;Server@node2;Job;1242.node2.supernodexp.hpc;Job Modified at request of Scheduler@node2.supernodexp.hpc
02/14/2018 16:37:23;0100;Server@node2;Req;;Type 11 request received from Scheduler@node2.supernodexp.hpc, sock=20
02/14/2018 16:37:23;0008;Server@node2;Job;1243.node2.supernodexp.hpc;Job Modified at request of Scheduler@node2.supernodexp.hpc
02/14/2018 16:37:23;0100;Server@node2;Req;;Type 23 request received from Scheduler@node2.supernodexp.hpc, sock=20
02/14/2018 16:37:23;0008;Server@node2;Job;1244.node2.supernodexp.hpc;Job Run at request of Scheduler@node2.supernodexp.hpc on exec_vnode (node14:ncpus=8:mem=3145728kb)
02/14/2018 16:37:23;0001;Server@node2;Svr;Server@node2;Success (0) in req_runjob2, return value of svr_startjob is 0
02/14/2018 16:37:25;0080;Server@node2;Job;1244.node2.supernodexp.hpc;Obit received momhop:1 serverhop:1 state:4 substate:42
02/14/2018 16:37:26;0010;Server@node2;Job;1244.node2.supernodexp.hpc;Exit_status=0 resources_used.cpupercent=800 resources_used.cput=00:00:08 resources_used.mem=0kb resources_used.ncpus=8 resources_used.vmem=0kb resources_used.walltime=00:00:01
02/14/2018 16:37:26;0100;Server@node2;Job;1244.node2.supernodexp.hpc;dequeuing from workq, state 5
02/14/2018 16:37:26;0040;Server@node2;Svr;node2.supernodexp.hpc;Scheduler sent command 2
02/14/2018 16:37:26;0040;Server@node2;Svr;node2.supernodexp.hpc;Scheduler sent command 0
02/14/2018 16:37:26;0100;Server@node2;Req;;Type 21 request received from Scheduler@node2.supernodexp.hpc, sock=20
02/14/2018 16:37:26;0100;Server@node2;Req;;Type 81 request received from Scheduler@node2.supernodexp.hpc, sock=20
02/14/2018 16:37:26;0100;Server@node2;Req;;Type 71 request received from Scheduler@node2.supernodexp.hpc, sock=20
02/14/2018 16:37:26;0100;Server@node2;Req;;Type 58 request received from Scheduler@node2.supernodexp.hpc, sock=20
02/14/2018 16:37:26;0100;Server@node2;Req;;Type 20 request received from Scheduler@node2.supernodexp.hpc, sock=20
02/14/2018 16:37:26;0100;Server@node2;Req;;Type 51 request received from Scheduler@node2.supernodexp.hpc, sock=20
02/14/2018 16:37:35;0080;Server@node2;Job;1237.node2.supernodexp.hpc;Obit received momhop:1 serverhop:1 state:4 substate:42
02/14/2018 16:37:36;0010;Server@node2;Job;1237.node2.supernodexp.hpc;Exit_status=0 resources_used.cpupercent=100 resources_used.cput=00:00:11 resources_used.mem=11848kb resources_used.ncpus=12 resources_used.vmem=531996kb resources_used.walltime=00:00:12
02/14/2018 16:37:36;0100;Server@node2;Job;1237.node2.supernodexp.hpc;dequeuing from workq, state 5
02/14/2018 16:37:36;0040;Server@node2;Svr;node2.supernodexp.hpc;Scheduler sent command 2
02/14/2018 16:37:36;0040;Server@node2;Svr;node2.supernodexp.hpc;Scheduler sent command 0
02/14/2018 16:37:36;0100;Server@node2;Req;;Type 21 request received from Scheduler@node2.supernodexp.hpc, sock=20
02/14/2018 16:37:36;0100;Server@node2;Req;;Type 81 request received from Scheduler@node2.supernodexp.hpc, sock=20
02/14/2018 16:37:36;0100;Server@node2;Req;;Type 71 request received from Scheduler@node2.supernodexp.hpc, sock=20
02/14/2018 16:37:36;0100;Server@node2;Req;;Type 58 request received from Scheduler@node2.supernodexp.hpc, sock=20
02/14/2018 16:37:37;0100;Server@node2;Req;;Type 20 request received from Scheduler@node2.supernodexp.hpc, sock=20
02/14/2018 16:37:37;0100;Server@node2;Req;;Type 51 request received from Scheduler@node2.supernodexp.hpc, sock=20
02/14/2018 16:37:37;0100;Server@node2;Req;;Type 23 request received from Scheduler@node2.supernodexp.hpc, sock=20
02/14/2018 16:37:37;0008;Server@node2;Job;1208.node2.supernodexp.hpc;Job Run at request of Scheduler@node2.supernodexp.hpc on exec_vnode (node14:ncpus=24:mem=2097152kb)
02/14/2018 16:37:37;0001;Server@node2;Svr;Server@node2;Success (0) in req_runjob2, return value of svr_startjob is 0
02/14/2018 16:37:37;0100;Server@node2;Req;;Type 11 request received from Scheduler@node2.supernodexp.hpc, sock=20
02/14/2018 16:37:37;0008;Server@node2;Job;1209.node2.supernodexp.hpc;Job Modified at request of Scheduler@node2.supernodexp.hpc
02/14/2018 16:37:37;0100;Server@node2;Req;;Type 11 request received from Scheduler@node2.supernodexp.hpc, sock=20
02/14/2018 16:37:37;0008;Server@node2;Job;1211.node2.supernodexp.hpc;Job Modified at request of Scheduler@node2.supernodexp.hpc
02/14/2018 16:37:37;0100;Server@node2;Req;;Type 11 request received from Scheduler@node2.supernodexp.hpc, sock=20
02/14/2018 16:37:37;0008;Server@node2;Job;1212.node2.supernodexp.hpc;Job Modified at request of Scheduler@node2.supernodexp.hpc
02/14/2018 16:37:37;0100;Server@node2;Req;;Type 11 request received from Scheduler@node2.supernodexp.hpc, sock=20
02/14/2018 16:37:37;0008;Server@node2;Job;1213.node2.supernodexp.hpc;Job Modified at request of Scheduler@node2.supernodexp.hpc
02/14/2018 16:37:37;0100;Server@node2;Req;;Type 11 request received from Scheduler@node2.supernodexp.hpc, sock=20
02/14/2018 16:37:37;0008;Server@node2;Job;1214.node2.supernodexp.hpc;Job Modified at request of Scheduler@node2.supernodexp.hpc
02/14/2018 16:37:37;0100;Server@node2;Req;;Type 11 request received from Scheduler@node2.supernodexp.hpc, sock=20
02/14/2018 16:37:37;0008;Server@node2;Job;1215.node2.supernodexp.hpc;Job Modified at request of Scheduler@node2.supernodexp.hpc
02/14/2018 16:37:37;0100;Server@node2;Req;;Type 11 request received from Scheduler@node2.supernodexp.hpc, sock=20
02/14/2018 16:37:37;0008;Server@node2;Job;1216.node2.supernodexp.hpc;Job Modified at request of Scheduler@node2.supernodexp.hpc
02/14/2018 16:37:37;0100;Server@node2;Req;;Type 11 request received from Scheduler@node2.supernodexp.hpc, sock=20
02/14/2018 16:37:37;0008;Server@node2;Job;1218.node2.supernodexp.hpc;Job Modified at request of Scheduler@node2.supernodexp.hpc
02/14/2018 16:37:37;0100;Server@node2;Req;;Type 11 request received from Scheduler@node2.supernodexp.hpc, sock=20
02/14/2018 16:37:37;0008;Server@node2;Job;1219.node2.supernodexp.hpc;Job Modified at request of Scheduler@node2.supernodexp.hpc
02/14/2018 16:37:37;0100;Server@node2;Req;;Type 11 request received from Scheduler@node2.supernodexp.hpc, sock=20
02/14/2018 16:37:37;0008;Server@node2;Job;1220.node2.supernodexp.hpc;Job Modified at request of Scheduler@node2.supernodexp.hpc
02/14/2018 16:37:37;0100;Server@node2;Req;;Type 11 request received from Scheduler@node2.supernodexp.hpc, sock=20
02/14/2018 16:37:37;0008;Server@node2;Job;1221.node2.supernodexp.hpc;Job Modified at request of Scheduler@node2.supernodexp.hpc
02/14/2018 16:37:37;0100;Server@node2;Req;;Type 11 request received from Scheduler@node2.supernodexp.hpc, sock=20
02/14/2018 16:37:37;0008;Server@node2;Job;1222.node2.supernodexp.hpc;Job Modified at request of Scheduler@node2.supernodexp.hpc
02/14/2018 16:37:37;0100;Server@node2;Req;;Type 11 request received from Scheduler@node2.supernodexp.hpc, sock=20
02/14/2018 16:37:37;0008;Server@node2;Job;1224.node2.supernodexp.hpc;Job Modified at request of Scheduler@node2.supernodexp.hpc
02/14/2018 16:37:37;0100;Server@node2;Req;;Type 11 request received from Scheduler@node2.supernodexp.hpc, sock=20
02/14/2018 16:37:37;0008;Server@node2;Job;1225.node2.supernodexp.hpc;Job Modified at request of Scheduler@node2.supernodexp.hpc
02/14/2018 16:37:37;0100;Server@node2;Req;;Type 11 request received from Scheduler@node2.supernodexp.hpc, sock=20
02/14/2018 16:37:37;0008;Server@node2;Job;1226.node2.supernodexp.hpc;Job Modified at request of Scheduler@node2.supernodexp.hpc
02/14/2018 16:37:37;0100;Server@node2;Req;;Type 11 request received from Scheduler@node2.supernodexp.hpc, sock=20
02/14/2018 16:37:37;0008;Server@node2;Job;1227.node2.supernodexp.hpc;Job Modified at request of Scheduler@node2.supernodexp.hpc
02/14/2018 16:37:37;0100;Server@node2;Req;;Type 11 request received from Scheduler@node2.supernodexp.hpc, sock=20
02/14/2018 16:37:37;0008;Server@node2;Job;1228.node2.supernodexp.hpc;Job Modified at request of Scheduler@node2.supernodexp.hpc
02/14/2018 16:37:37;0100;Server@node2;Req;;Type 11 request received from Scheduler@node2.supernodexp.hpc, sock=20
02/14/2018 16:37:37;0008;Server@node2;Job;1229.node2.supernodexp.hpc;Job Modified at request of Scheduler@node2.supernodexp.hpc
02/14/2018 16:37:37;0100;Server@node2;Req;;Type 11 request received from Scheduler@node2.supernodexp.hpc, sock=20
02/14/2018 16:37:37;0008;Server@node2;Job;1231.node2.supernodexp.hpc;Job Modified at request of Scheduler@node2.supernodexp.hpc
02/14/2018 16:37:37;0100;Server@node2;Req;;Type 11 request received from Scheduler@node2.supernodexp.hpc, sock=20
02/14/2018 16:37:37;0008;Server@node2;Job;1233.node2.supernodexp.hpc;Job Modified at request of Scheduler@node2.supernodexp.hpc
02/14/2018 16:37:37;0100;Server@node2;Req;;Type 11 request received from Scheduler@node2.supernodexp.hpc, sock=20
02/14/2018 16:37:37;0008;Server@node2;Job;1234.node2.supernodexp.hpc;Job Modified at request of Scheduler@node2.supernodexp.hpc
02/14/2018 16:37:37;0100;Server@node2;Req;;Type 11 request received from Scheduler@node2.supernodexp.hpc, sock=20
02/14/2018 16:37:37;0008;Server@node2;Job;1235.node2.supernodexp.hpc;Job Modified at request of Scheduler@node2.supernodexp.hpc
02/14/2018 16:37:37;0100;Server@node2;Req;;Type 11 request received from Scheduler@node2.supernodexp.hpc, sock=20
02/14/2018 16:37:37;0008;Server@node2;Job;1236.node2.supernodexp.hpc;Job Modified at request of Scheduler@node2.supernodexp.hpc
02/14/2018 16:37:37;0100;Server@node2;Req;;Type 11 request received from Scheduler@node2.supernodexp.hpc, sock=20
02/14/2018 16:37:37;0008;Server@node2;Job;1238.node2.supernodexp.hpc;Job Modified at request of Scheduler@node2.supernodexp.hpc
02/14/2018 16:37:37;0100;Server@node2;Req;;Type 11 request received from Scheduler@node2.supernodexp.hpc, sock=20
02/14/2018 16:37:37;0008;Server@node2;Job;1239.node2.supernodexp.hpc;Job Modified at request of Scheduler@node2.supernodexp.hpc
02/14/2018 16:37:37;0100;Server@node2;Req;;Type 11 request received from Scheduler@node2.supernodexp.hpc, sock=20
02/14/2018 16:37:37;0008;Server@node2;Job;1240.node2.supernodexp.hpc;Job Modified at request of Scheduler@node2.supernodexp.hpc
02/14/2018 16:37:37;0100;Server@node2;Req;;Type 11 request received from Scheduler@node2.supernodexp.hpc, sock=20
02/14/2018 16:37:37;0008;Server@node2;Job;1241.node2.supernodexp.hpc;Job Modified at request of Scheduler@node2.supernodexp.hpc
02/14/2018 16:37:37;0100;Server@node2;Req;;Type 11 request received from Scheduler@node2.supernodexp.hpc, sock=20
02/14/2018 16:37:37;0008;Server@node2;Job;1242.node2.supernodexp.hpc;Job Modified at request of Scheduler@node2.supernodexp.hpc
02/14/2018 16:37:37;0100;Server@node2;Req;;Type 11 request received from Scheduler@node2.supernodexp.hpc, sock=20
02/14/2018 16:37:37;0008;Server@node2;Job;1243.node2.supernodexp.hpc;Job Modified at request of Scheduler@node2.supernodexp.hpc
02/14/2018 16:37:58;0100;Server@node2;Req;;Type 1 request received from ctminh@node2.supernodexp.hpc, sock=16
02/14/2018 16:37:58;0100;Server@node2;Req;;Type 3 request received from ctminh@node2.supernodexp.hpc, sock=16
02/14/2018 16:37:58;0100;Server@node2;Req;;Type 5 request received from ctminh@node2.supernodexp.hpc, sock=16
02/14/2018 16:37:58;0100;Server@node2;Job;1245.node2.supernodexp.hpc;enqueuing into workq, state 1 hop 1
02/14/2018 16:37:58;0008;Server@node2;Job;1245.node2.supernodexp.hpc;Job Queued at request of ctminh@node2.supernodexp.hpc, owner = ctminh@node2.supernodexp.hpc, job name = matrix-x-vector, queue = workq
02/14/2018 16:37:58;0040;Server@node2;Svr;node2.supernodexp.hpc;Scheduler sent command 1
02/14/2018 16:37:58;0040;Server@node2;Svr;node2.supernodexp.hpc;Scheduler sent command 0
02/14/2018 16:37:58;0100;Server@node2;Req;;Type 21 request received from Scheduler@node2.supernodexp.hpc, sock=20
02/14/2018 16:37:58;0100;Server@node2;Req;;Type 81 request received from Scheduler@node2.supernodexp.hpc, sock=20
02/14/2018 16:37:58;0100;Server@node2;Req;;Type 71 request received from Scheduler@node2.supernodexp.hpc, sock=20
02/14/2018 16:37:58;0100;Server@node2;Req;;Type 58 request received from Scheduler@node2.supernodexp.hpc, sock=20
02/14/2018 16:37:58;0100;Server@node2;Req;;Type 1 request received from ctminh@node2.supernodexp.hpc, sock=16
02/14/2018 16:37:58;0100;Server@node2;Req;;Type 20 request received from Scheduler@node2.supernodexp.hpc, sock=20
02/14/2018 16:37:58;0100;Server@node2;Req;;Type 3 request received from ctminh@node2.supernodexp.hpc, sock=16
02/14/2018 16:37:58;0100;Server@node2;Req;;Type 51 request received from Scheduler@node2.supernodexp.hpc, sock=20
02/14/2018 16:37:58;0100;Server@node2;Req;;Type 5 request received from ctminh@node2.supernodexp.hpc, sock=16
02/14/2018 16:37:58;0100;Server@node2;Job;1246.node2.supernodexp.hpc;enqueuing into workq, state 1 hop 1
02/14/2018 16:37:58;0008;Server@node2;Job;1246.node2.supernodexp.hpc;Job Queued at request of ctminh@node2.supernodexp.hpc, owner = ctminh@node2.supernodexp.hpc, job name = jacobi, queue = workq
02/14/2018 16:37:58;0100;Server@node2;Req;;Type 1 request received from ctminh@node2.supernodexp.hpc, sock=16
02/14/2018 16:37:58;0100;Server@node2;Req;;Type 3 request received from ctminh@node2.supernodexp.hpc, sock=16
02/14/2018 16:37:58;0100;Server@node2;Req;;Type 5 request received from ctminh@node2.supernodexp.hpc, sock=16
02/14/2018 16:37:58;0100;Server@node2;Job;1247.node2.supernodexp.hpc;enqueuing into workq, state 1 hop 1
02/14/2018 16:37:58;0008;Server@node2;Job;1247.node2.supernodexp.hpc;Job Queued at request of ctminh@node2.supernodexp.hpc, owner = ctminh@node2.supernodexp.hpc, job name = sweep, queue = workq
02/14/2018 16:37:58;0100;Server@node2;Req;;Type 11 request received from Scheduler@node2.supernodexp.hpc, sock=20
02/14/2018 16:37:58;0008;Server@node2;Job;1245.node2.supernodexp.hpc;Job Modified at request of Scheduler@node2.supernodexp.hpc
02/14/2018 16:37:58;0040;Server@node2;Svr;node2.supernodexp.hpc;Scheduler sent command 1
02/14/2018 16:37:58;0040;Server@node2;Svr;node2.supernodexp.hpc;Scheduler sent command 0
02/14/2018 16:37:58;0100;Server@node2;Req;;Type 21 request received from Scheduler@node2.supernodexp.hpc, sock=20
02/14/2018 16:37:58;0100;Server@node2;Req;;Type 81 request received from Scheduler@node2.supernodexp.hpc, sock=20
02/14/2018 16:37:58;0100;Server@node2;Req;;Type 71 request received from Scheduler@node2.supernodexp.hpc, sock=20
02/14/2018 16:37:58;0100;Server@node2;Req;;Type 58 request received from Scheduler@node2.supernodexp.hpc, sock=20
02/14/2018 16:37:58;0100;Server@node2;Req;;Type 1 request received from ctminh@node2.supernodexp.hpc, sock=16
02/14/2018 16:37:58;0100;Server@node2;Req;;Type 20 request received from Scheduler@node2.supernodexp.hpc, sock=20
02/14/2018 16:37:58;0100;Server@node2;Req;;Type 3 request received from ctminh@node2.supernodexp.hpc, sock=16
02/14/2018 16:37:58;0100;Server@node2;Req;;Type 51 request received from Scheduler@node2.supernodexp.hpc, sock=20
02/14/2018 16:37:58;0100;Server@node2;Req;;Type 5 request received from ctminh@node2.supernodexp.hpc, sock=16
02/14/2018 16:37:58;0100;Server@node2;Job;1248.node2.supernodexp.hpc;enqueuing into workq, state 1 hop 1
02/14/2018 16:37:58;0008;Server@node2;Job;1248.node2.supernodexp.hpc;Job Queued at request of ctminh@node2.supernodexp.hpc, owner = ctminh@node2.supernodexp.hpc, job name = telemac1, queue = workq
02/14/2018 16:37:58;0100;Server@node2;Req;;Type 1 request received from ctminh@node2.supernodexp.hpc, sock=16
02/14/2018 16:37:58;0100;Server@node2;Req;;Type 3 request received from ctminh@node2.supernodexp.hpc, sock=16
02/14/2018 16:37:58;0100;Server@node2;Req;;Type 5 request received from ctminh@node2.supernodexp.hpc, sock=16
02/14/2018 16:37:58;0100;Server@node2;Job;1249.node2.supernodexp.hpc;enqueuing into workq, state 1 hop 1
02/14/2018 16:37:58;0008;Server@node2;Job;1249.node2.supernodexp.hpc;Job Queued at request of ctminh@node2.supernodexp.hpc, owner = ctminh@node2.supernodexp.hpc, job name = lu-decomp, queue = workq
02/14/2018 16:37:58;0100;Server@node2;Req;;Type 11 request received from Scheduler@node2.supernodexp.hpc, sock=20
02/14/2018 16:37:58;0008;Server@node2;Job;1246.node2.supernodexp.hpc;Job Modified at request of Scheduler@node2.supernodexp.hpc
02/14/2018 16:37:58;0100;Server@node2;Req;;Type 11 request received from Scheduler@node2.supernodexp.hpc, sock=20
02/14/2018 16:37:58;0008;Server@node2;Job;1247.node2.supernodexp.hpc;Job Modified at request of Scheduler@node2.supernodexp.hpc
02/14/2018 16:37:58;0040;Server@node2;Svr;node2.supernodexp.hpc;Scheduler sent command 1
02/14/2018 16:37:58;0040;Server@node2;Svr;node2.supernodexp.hpc;Scheduler sent command 0
02/14/2018 16:37:58;0100;Server@node2;Req;;Type 21 request received from Scheduler@node2.supernodexp.hpc, sock=20
02/14/2018 16:37:58;0100;Server@node2;Req;;Type 81 request received from Scheduler@node2.supernodexp.hpc, sock=20
02/14/2018 16:37:58;0100;Server@node2;Req;;Type 71 request received from Scheduler@node2.supernodexp.hpc, sock=20
02/14/2018 16:37:58;0100;Server@node2;Req;;Type 58 request received from Scheduler@node2.supernodexp.hpc, sock=20
02/14/2018 16:37:58;0100;Server@node2;Req;;Type 1 request received from ctminh@node2.supernodexp.hpc, sock=16
02/14/2018 16:37:58;0100;Server@node2;Req;;Type 3 request received from ctminh@node2.supernodexp.hpc, sock=16
02/14/2018 16:37:58;0100;Server@node2;Req;;Type 5 request received from ctminh@node2.supernodexp.hpc, sock=16
02/14/2018 16:37:58;0100;Server@node2;Job;1250.node2.supernodexp.hpc;enqueuing into workq, state 1 hop 1
02/14/2018 16:37:58;0008;Server@node2;Job;1250.node2.supernodexp.hpc;Job Queued at request of ctminh@node2.supernodexp.hpc, owner = ctminh@node2.supernodexp.hpc, job name = lu-decomp, queue = workq
02/14/2018 16:37:58;0100;Server@node2;Req;;Type 20 request received from Scheduler@node2.supernodexp.hpc, sock=20
02/14/2018 16:37:58;0100;Server@node2;Req;;Type 51 request received from Scheduler@node2.supernodexp.hpc, sock=20
02/14/2018 16:37:58;0100;Server@node2;Req;;Type 11 request received from Scheduler@node2.supernodexp.hpc, sock=20
02/14/2018 16:37:58;0008;Server@node2;Job;1248.node2.supernodexp.hpc;Job Modified at request of Scheduler@node2.supernodexp.hpc
02/14/2018 16:37:58;0100;Server@node2;Req;;Type 11 request received from Scheduler@node2.supernodexp.hpc, sock=20
02/14/2018 16:37:58;0008;Server@node2;Job;1249.node2.supernodexp.hpc;Job Modified at request of Scheduler@node2.supernodexp.hpc
02/14/2018 16:37:58;0100;Server@node2;Req;;Type 11 request received from Scheduler@node2.supernodexp.hpc, sock=20
02/14/2018 16:37:58;0008;Server@node2;Job;1250.node2.supernodexp.hpc;Job Modified at request of Scheduler@node2.supernodexp.hpc
02/14/2018 16:37:58;0040;Server@node2;Svr;node2.supernodexp.hpc;Scheduler sent command 1
02/14/2018 16:37:58;0040;Server@node2;Svr;node2.supernodexp.hpc;Scheduler sent command 0
02/14/2018 16:37:58;0100;Server@node2;Req;;Type 21 request received from Scheduler@node2.supernodexp.hpc, sock=20
02/14/2018 16:37:58;0100;Server@node2;Req;;Type 81 request received from Scheduler@node2.supernodexp.hpc, sock=20
02/14/2018 16:37:58;0100;Server@node2;Req;;Type 71 request received from Scheduler@node2.supernodexp.hpc, sock=20
02/14/2018 16:37:58;0100;Server@node2;Req;;Type 58 request received from Scheduler@node2.supernodexp.hpc, sock=20
02/14/2018 16:37:58;0100;Server@node2;Req;;Type 1 request received from ctminh@node2.supernodexp.hpc, sock=16
02/14/2018 16:37:58;0100;Server@node2;Req;;Type 3 request received from ctminh@node2.supernodexp.hpc, sock=16
02/14/2018 16:37:58;0100;Server@node2;Req;;Type 5 request received from ctminh@node2.supernodexp.hpc, sock=16
02/14/2018 16:37:58;0100;Server@node2;Job;1251.node2.supernodexp.hpc;enqueuing into workq, state 1 hop 1
02/14/2018 16:37:58;0008;Server@node2;Job;1251.node2.supernodexp.hpc;Job Queued at request of ctminh@node2.supernodexp.hpc, owner = ctminh@node2.supernodexp.hpc, job name = vast1, queue = workq
02/14/2018 16:37:58;0100;Server@node2;Req;;Type 20 request received from Scheduler@node2.supernodexp.hpc, sock=20
02/14/2018 16:37:58;0100;Server@node2;Req;;Type 51 request received from Scheduler@node2.supernodexp.hpc, sock=20
02/14/2018 16:37:58;0100;Server@node2;Req;;Type 1 request received from ctminh@node2.supernodexp.hpc, sock=16
02/14/2018 16:37:58;0100;Server@node2;Req;;Type 3 request received from ctminh@node2.supernodexp.hpc, sock=16
02/14/2018 16:37:58;0100;Server@node2;Req;;Type 5 request received from ctminh@node2.supernodexp.hpc, sock=16
02/14/2018 16:37:58;0100;Server@node2;Job;1252.node2.supernodexp.hpc;enqueuing into workq, state 1 hop 1
02/14/2018 16:37:58;0008;Server@node2;Job;1252.node2.supernodexp.hpc;Job Queued at request of ctminh@node2.supernodexp.hpc, owner = ctminh@node2.supernodexp.hpc, job name = nbody, queue = workq
02/14/2018 16:37:58;0100;Server@node2;Req;;Type 11 request received from Scheduler@node2.supernodexp.hpc, sock=20
02/14/2018 16:37:58;0008;Server@node2;Job;1251.node2.supernodexp.hpc;Job Modified at request of Scheduler@node2.supernodexp.hpc
02/14/2018 16:37:58;0040;Server@node2;Svr;node2.supernodexp.hpc;Scheduler sent command 1
02/14/2018 16:37:58;0040;Server@node2;Svr;node2.supernodexp.hpc;Scheduler sent command 0
02/14/2018 16:37:58;0100;Server@node2;Req;;Type 21 request received from Scheduler@node2.supernodexp.hpc, sock=20
02/14/2018 16:37:58;0100;Server@node2;Req;;Type 81 request received from Scheduler@node2.supernodexp.hpc, sock=20
02/14/2018 16:37:58;0100;Server@node2;Req;;Type 71 request received from Scheduler@node2.supernodexp.hpc, sock=20
02/14/2018 16:37:58;0100;Server@node2;Req;;Type 58 request received from Scheduler@node2.supernodexp.hpc, sock=20
02/14/2018 16:37:58;0100;Server@node2;Req;;Type 1 request received from ctminh@node2.supernodexp.hpc, sock=16
02/14/2018 16:37:58;0100;Server@node2;Req;;Type 3 request received from ctminh@node2.supernodexp.hpc, sock=16
02/14/2018 16:37:58;0100;Server@node2;Req;;Type 5 request received from ctminh@node2.supernodexp.hpc, sock=16
02/14/2018 16:37:58;0100;Server@node2;Job;1253.node2.supernodexp.hpc;enqueuing into workq, state 1 hop 1
02/14/2018 16:37:58;0008;Server@node2;Job;1253.node2.supernodexp.hpc;Job Queued at request of ctminh@node2.supernodexp.hpc, owner = ctminh@node2.supernodexp.hpc, job name = jacobi, queue = workq
02/14/2018 16:37:58;0100;Server@node2;Req;;Type 20 request received from Scheduler@node2.supernodexp.hpc, sock=20
02/14/2018 16:37:58;0100;Server@node2;Req;;Type 51 request received from Scheduler@node2.supernodexp.hpc, sock=20
02/14/2018 16:37:58;0100;Server@node2;Req;;Type 1 request received from ctminh@node2.supernodexp.hpc, sock=16
02/14/2018 16:37:58;0100;Server@node2;Req;;Type 3 request received from ctminh@node2.supernodexp.hpc, sock=16
02/14/2018 16:37:58;0100;Server@node2;Req;;Type 5 request received from ctminh@node2.supernodexp.hpc, sock=16
02/14/2018 16:37:58;0100;Server@node2;Job;1254.node2.supernodexp.hpc;enqueuing into workq, state 1 hop 1
02/14/2018 16:37:58;0008;Server@node2;Job;1254.node2.supernodexp.hpc;Job Queued at request of ctminh@node2.supernodexp.hpc, owner = ctminh@node2.supernodexp.hpc, job name = vectorization, queue = workq
02/14/2018 16:37:58;0100;Server@node2;Req;;Type 11 request received from Scheduler@node2.supernodexp.hpc, sock=20
02/14/2018 16:37:58;0008;Server@node2;Job;1252.node2.supernodexp.hpc;Job Modified at request of Scheduler@node2.supernodexp.hpc
02/14/2018 16:37:58;0100;Server@node2;Req;;Type 11 request received from Scheduler@node2.supernodexp.hpc, sock=20
02/14/2018 16:37:58;0008;Server@node2;Job;1253.node2.supernodexp.hpc;Job Modified at request of Scheduler@node2.supernodexp.hpc
02/14/2018 16:37:58;0040;Server@node2;Svr;node2.supernodexp.hpc;Scheduler sent command 1
02/14/2018 16:37:58;0040;Server@node2;Svr;node2.supernodexp.hpc;Scheduler sent command 0
02/14/2018 16:37:58;0100;Server@node2;Req;;Type 21 request received from Scheduler@node2.supernodexp.hpc, sock=20
02/14/2018 16:37:58;0100;Server@node2;Req;;Type 81 request received from Scheduler@node2.supernodexp.hpc, sock=20
02/14/2018 16:37:58;0100;Server@node2;Req;;Type 71 request received from Scheduler@node2.supernodexp.hpc, sock=20
02/14/2018 16:37:58;0100;Server@node2;Req;;Type 58 request received from Scheduler@node2.supernodexp.hpc, sock=20
02/14/2018 16:37:58;0100;Server@node2;Req;;Type 1 request received from ctminh@node2.supernodexp.hpc, sock=16
02/14/2018 16:37:58;0100;Server@node2;Req;;Type 3 request received from ctminh@node2.supernodexp.hpc, sock=16
02/14/2018 16:37:58;0100;Server@node2;Req;;Type 5 request received from ctminh@node2.supernodexp.hpc, sock=16
02/14/2018 16:37:58;0100;Server@node2;Job;1255.node2.supernodexp.hpc;enqueuing into workq, state 1 hop 1
02/14/2018 16:37:58;0008;Server@node2;Job;1255.node2.supernodexp.hpc;Job Queued at request of ctminh@node2.supernodexp.hpc, owner = ctminh@node2.supernodexp.hpc, job name = histogram, queue = workq
02/14/2018 16:37:58;0100;Server@node2;Req;;Type 20 request received from Scheduler@node2.supernodexp.hpc, sock=20
02/14/2018 16:37:58;0100;Server@node2;Req;;Type 51 request received from Scheduler@node2.supernodexp.hpc, sock=20
02/14/2018 16:37:58;0100;Server@node2;Req;;Type 1 request received from ctminh@node2.supernodexp.hpc, sock=16
02/14/2018 16:37:58;0100;Server@node2;Req;;Type 3 request received from ctminh@node2.supernodexp.hpc, sock=16
02/14/2018 16:37:58;0100;Server@node2;Req;;Type 5 request received from ctminh@node2.supernodexp.hpc, sock=16
02/14/2018 16:37:58;0100;Server@node2;Job;1256.node2.supernodexp.hpc;enqueuing into workq, state 1 hop 1
02/14/2018 16:37:58;0008;Server@node2;Job;1256.node2.supernodexp.hpc;Job Queued at request of ctminh@node2.supernodexp.hpc, owner = ctminh@node2.supernodexp.hpc, job name = telemac1, queue = workq
02/14/2018 16:37:58;0100;Server@node2;Req;;Type 11 request received from Scheduler@node2.supernodexp.hpc, sock=20
02/14/2018 16:37:58;0008;Server@node2;Job;1254.node2.supernodexp.hpc;Job Modified at request of Scheduler@node2.supernodexp.hpc
02/14/2018 16:37:58;0100;Server@node2;Req;;Type 11 request received from Scheduler@node2.supernodexp.hpc, sock=20
02/14/2018 16:37:58;0008;Server@node2;Job;1255.node2.supernodexp.hpc;Job Modified at request of Scheduler@node2.supernodexp.hpc
02/14/2018 16:37:58;0040;Server@node2;Svr;node2.supernodexp.hpc;Scheduler sent command 1
02/14/2018 16:37:58;0040;Server@node2;Svr;node2.supernodexp.hpc;Scheduler sent command 0
02/14/2018 16:37:58;0100;Server@node2;Req;;Type 21 request received from Scheduler@node2.supernodexp.hpc, sock=20
02/14/2018 16:37:58;0100;Server@node2;Req;;Type 81 request received from Scheduler@node2.supernodexp.hpc, sock=20
02/14/2018 16:37:58;0100;Server@node2;Req;;Type 71 request received from Scheduler@node2.supernodexp.hpc, sock=20
02/14/2018 16:37:58;0100;Server@node2;Req;;Type 58 request received from Scheduler@node2.supernodexp.hpc, sock=20
02/14/2018 16:37:58;0100;Server@node2;Req;;Type 1 request received from ctminh@node2.supernodexp.hpc, sock=16
02/14/2018 16:37:58;0100;Server@node2;Req;;Type 20 request received from Scheduler@node2.supernodexp.hpc, sock=20
02/14/2018 16:37:58;0100;Server@node2;Req;;Type 3 request received from ctminh@node2.supernodexp.hpc, sock=16
02/14/2018 16:37:58;0100;Server@node2;Req;;Type 51 request received from Scheduler@node2.supernodexp.hpc, sock=20
02/14/2018 16:37:58;0100;Server@node2;Req;;Type 5 request received from ctminh@node2.supernodexp.hpc, sock=16
02/14/2018 16:37:58;0100;Server@node2;Job;1257.node2.supernodexp.hpc;enqueuing into workq, state 1 hop 1
02/14/2018 16:37:58;0008;Server@node2;Job;1257.node2.supernodexp.hpc;Job Queued at request of ctminh@node2.supernodexp.hpc, owner = ctminh@node2.supernodexp.hpc, job name = telemac1, queue = workq
02/14/2018 16:37:59;0100;Server@node2;Req;;Type 1 request received from ctminh@node2.supernodexp.hpc, sock=16
02/14/2018 16:37:59;0100;Server@node2;Req;;Type 11 request received from Scheduler@node2.supernodexp.hpc, sock=20
02/14/2018 16:37:59;0008;Server@node2;Job;1256.node2.supernodexp.hpc;Job Modified at request of Scheduler@node2.supernodexp.hpc
02/14/2018 16:37:59;0100;Server@node2;Req;;Type 3 request received from ctminh@node2.supernodexp.hpc, sock=16
02/14/2018 16:37:59;0100;Server@node2;Req;;Type 5 request received from ctminh@node2.supernodexp.hpc, sock=16
02/14/2018 16:37:59;0100;Server@node2;Job;1258.node2.supernodexp.hpc;enqueuing into workq, state 1 hop 1
02/14/2018 16:37:59;0008;Server@node2;Job;1258.node2.supernodexp.hpc;Job Queued at request of ctminh@node2.supernodexp.hpc, owner = ctminh@node2.supernodexp.hpc, job name = sweep, queue = workq
02/14/2018 16:37:59;0040;Server@node2;Svr;node2.supernodexp.hpc;Scheduler sent command 1
02/14/2018 16:37:59;0040;Server@node2;Svr;node2.supernodexp.hpc;Scheduler sent command 0
02/14/2018 16:37:59;0100;Server@node2;Req;;Type 21 request received from Scheduler@node2.supernodexp.hpc, sock=20
02/14/2018 16:37:59;0100;Server@node2;Req;;Type 81 request received from Scheduler@node2.supernodexp.hpc, sock=20
02/14/2018 16:37:59;0100;Server@node2;Req;;Type 71 request received from Scheduler@node2.supernodexp.hpc, sock=20
02/14/2018 16:37:59;0100;Server@node2;Req;;Type 58 request received from Scheduler@node2.supernodexp.hpc, sock=20
02/14/2018 16:37:59;0100;Server@node2;Req;;Type 1 request received from ctminh@node2.supernodexp.hpc, sock=16
02/14/2018 16:37:59;0100;Server@node2;Req;;Type 20 request received from Scheduler@node2.supernodexp.hpc, sock=20
02/14/2018 16:37:59;0100;Server@node2;Req;;Type 3 request received from ctminh@node2.supernodexp.hpc, sock=16
02/14/2018 16:37:59;0100;Server@node2;Req;;Type 51 request received from Scheduler@node2.supernodexp.hpc, sock=20
02/14/2018 16:37:59;0100;Server@node2;Req;;Type 5 request received from ctminh@node2.supernodexp.hpc, sock=16
02/14/2018 16:37:59;0100;Server@node2;Job;1259.node2.supernodexp.hpc;enqueuing into workq, state 1 hop 1
02/14/2018 16:37:59;0008;Server@node2;Job;1259.node2.supernodexp.hpc;Job Queued at request of ctminh@node2.supernodexp.hpc, owner = ctminh@node2.supernodexp.hpc, job name = vectorization, queue = workq
02/14/2018 16:37:59;0100;Server@node2;Req;;Type 1 request received from ctminh@node2.supernodexp.hpc, sock=16
02/14/2018 16:37:59;0100;Server@node2;Req;;Type 11 request received from Scheduler@node2.supernodexp.hpc, sock=20
02/14/2018 16:37:59;0008;Server@node2;Job;1257.node2.supernodexp.hpc;Job Modified at request of Scheduler@node2.supernodexp.hpc
02/14/2018 16:37:59;0100;Server@node2;Req;;Type 3 request received from ctminh@node2.supernodexp.hpc, sock=16
02/14/2018 16:37:59;0100;Server@node2;Req;;Type 5 request received from ctminh@node2.supernodexp.hpc, sock=16
02/14/2018 16:37:59;0100;Server@node2;Job;1260.node2.supernodexp.hpc;enqueuing into workq, state 1 hop 1
02/14/2018 16:37:59;0008;Server@node2;Job;1260.node2.supernodexp.hpc;Job Queued at request of ctminh@node2.supernodexp.hpc, owner = ctminh@node2.supernodexp.hpc, job name = thread-affinity, queue = workq
02/14/2018 16:37:59;0100;Server@node2;Req;;Type 11 request received from Scheduler@node2.supernodexp.hpc, sock=20
02/14/2018 16:37:59;0008;Server@node2;Job;1258.node2.supernodexp.hpc;Job Modified at request of Scheduler@node2.supernodexp.hpc
02/14/2018 16:37:59;0040;Server@node2;Svr;node2.supernodexp.hpc;Scheduler sent command 1
02/14/2018 16:37:59;0040;Server@node2;Svr;node2.supernodexp.hpc;Scheduler sent command 0
02/14/2018 16:37:59;0100;Server@node2;Req;;Type 21 request received from Scheduler@node2.supernodexp.hpc, sock=20
02/14/2018 16:37:59;0100;Server@node2;Req;;Type 81 request received from Scheduler@node2.supernodexp.hpc, sock=20
02/14/2018 16:37:59;0100;Server@node2;Req;;Type 71 request received from Scheduler@node2.supernodexp.hpc, sock=20
02/14/2018 16:37:59;0100;Server@node2;Req;;Type 58 request received from Scheduler@node2.supernodexp.hpc, sock=20
02/14/2018 16:37:59;0100;Server@node2;Req;;Type 1 request received from ctminh@node2.supernodexp.hpc, sock=16
02/14/2018 16:37:59;0100;Server@node2;Req;;Type 20 request received from Scheduler@node2.supernodexp.hpc, sock=20
02/14/2018 16:37:59;0100;Server@node2;Req;;Type 3 request received from ctminh@node2.supernodexp.hpc, sock=16
02/14/2018 16:37:59;0100;Server@node2;Req;;Type 51 request received from Scheduler@node2.supernodexp.hpc, sock=20
02/14/2018 16:37:59;0100;Server@node2;Req;;Type 5 request received from ctminh@node2.supernodexp.hpc, sock=16
02/14/2018 16:37:59;0100;Server@node2;Job;1261.node2.supernodexp.hpc;enqueuing into workq, state 1 hop 1
02/14/2018 16:37:59;0008;Server@node2;Job;1261.node2.supernodexp.hpc;Job Queued at request of ctminh@node2.supernodexp.hpc, owner = ctminh@node2.supernodexp.hpc, job name = matrix-x-vector, queue = workq
02/14/2018 16:37:59;0100;Server@node2;Req;;Type 1 request received from ctminh@node2.supernodexp.hpc, sock=16
02/14/2018 16:37:59;0100;Server@node2;Req;;Type 11 request received from Scheduler@node2.supernodexp.hpc, sock=20
02/14/2018 16:37:59;0008;Server@node2;Job;1259.node2.supernodexp.hpc;Job Modified at request of Scheduler@node2.supernodexp.hpc
02/14/2018 16:37:59;0100;Server@node2;Req;;Type 3 request received from ctminh@node2.supernodexp.hpc, sock=16
02/14/2018 16:37:59;0100;Server@node2;Req;;Type 11 request received from Scheduler@node2.supernodexp.hpc, sock=20
02/14/2018 16:37:59;0008;Server@node2;Job;1260.node2.supernodexp.hpc;Job Modified at request of Scheduler@node2.supernodexp.hpc
02/14/2018 16:37:59;0100;Server@node2;Req;;Type 5 request received from ctminh@node2.supernodexp.hpc, sock=16
02/14/2018 16:37:59;0100;Server@node2;Job;1262.node2.supernodexp.hpc;enqueuing into workq, state 1 hop 1
02/14/2018 16:37:59;0008;Server@node2;Job;1262.node2.supernodexp.hpc;Job Queued at request of ctminh@node2.supernodexp.hpc, owner = ctminh@node2.supernodexp.hpc, job name = sweep, queue = workq
02/14/2018 16:37:59;0040;Server@node2;Svr;node2.supernodexp.hpc;Scheduler sent command 1
02/14/2018 16:37:59;0040;Server@node2;Svr;node2.supernodexp.hpc;Scheduler sent command 0
02/14/2018 16:37:59;0100;Server@node2;Req;;Type 21 request received from Scheduler@node2.supernodexp.hpc, sock=20
02/14/2018 16:37:59;0100;Server@node2;Req;;Type 81 request received from Scheduler@node2.supernodexp.hpc, sock=20
02/14/2018 16:37:59;0100;Server@node2;Req;;Type 71 request received from Scheduler@node2.supernodexp.hpc, sock=20
02/14/2018 16:37:59;0100;Server@node2;Req;;Type 58 request received from Scheduler@node2.supernodexp.hpc, sock=20
02/14/2018 16:37:59;0100;Server@node2;Req;;Type 1 request received from ctminh@node2.supernodexp.hpc, sock=16
02/14/2018 16:37:59;0100;Server@node2;Req;;Type 3 request received from ctminh@node2.supernodexp.hpc, sock=16
02/14/2018 16:37:59;0100;Server@node2;Req;;Type 5 request received from ctminh@node2.supernodexp.hpc, sock=16
02/14/2018 16:37:59;0100;Server@node2;Job;1263.node2.supernodexp.hpc;enqueuing into workq, state 1 hop 1
02/14/2018 16:37:59;0008;Server@node2;Job;1263.node2.supernodexp.hpc;Job Queued at request of ctminh@node2.supernodexp.hpc, owner = ctminh@node2.supernodexp.hpc, job name = histogram, queue = workq
02/14/2018 16:37:59;0100;Server@node2;Req;;Type 20 request received from Scheduler@node2.supernodexp.hpc, sock=20
02/14/2018 16:37:59;0100;Server@node2;Req;;Type 51 request received from Scheduler@node2.supernodexp.hpc, sock=20
02/14/2018 16:37:59;0100;Server@node2;Req;;Type 1 request received from ctminh@node2.supernodexp.hpc, sock=16
02/14/2018 16:37:59;0100;Server@node2;Req;;Type 3 request received from ctminh@node2.supernodexp.hpc, sock=16
02/14/2018 16:37:59;0100;Server@node2;Req;;Type 5 request received from ctminh@node2.supernodexp.hpc, sock=16
02/14/2018 16:37:59;0100;Server@node2;Job;1264.node2.supernodexp.hpc;enqueuing into workq, state 1 hop 1
02/14/2018 16:37:59;0008;Server@node2;Job;1264.node2.supernodexp.hpc;Job Queued at request of ctminh@node2.supernodexp.hpc, owner = ctminh@node2.supernodexp.hpc, job name = vectorization, queue = workq
02/14/2018 16:37:59;0100;Server@node2;Req;;Type 11 request received from Scheduler@node2.supernodexp.hpc, sock=20
02/14/2018 16:37:59;0008;Server@node2;Job;1261.node2.supernodexp.hpc;Job Modified at request of Scheduler@node2.supernodexp.hpc
02/14/2018 16:37:59;0100;Server@node2;Req;;Type 11 request received from Scheduler@node2.supernodexp.hpc, sock=20
02/14/2018 16:37:59;0008;Server@node2;Job;1262.node2.supernodexp.hpc;Job Modified at request of Scheduler@node2.supernodexp.hpc
02/14/2018 16:37:59;0100;Server@node2;Req;;Type 11 request received from Scheduler@node2.supernodexp.hpc, sock=20
02/14/2018 16:37:59;0008;Server@node2;Job;1263.node2.supernodexp.hpc;Job Modified at request of Scheduler@node2.supernodexp.hpc
02/14/2018 16:37:59;0040;Server@node2;Svr;node2.supernodexp.hpc;Scheduler sent command 1
02/14/2018 16:37:59;0040;Server@node2;Svr;node2.supernodexp.hpc;Scheduler sent command 0
02/14/2018 16:37:59;0100;Server@node2;Req;;Type 21 request received from Scheduler@node2.supernodexp.hpc, sock=20
02/14/2018 16:37:59;0100;Server@node2;Req;;Type 81 request received from Scheduler@node2.supernodexp.hpc, sock=20
02/14/2018 16:37:59;0100;Server@node2;Req;;Type 71 request received from Scheduler@node2.supernodexp.hpc, sock=20
02/14/2018 16:37:59;0100;Server@node2;Req;;Type 58 request received from Scheduler@node2.supernodexp.hpc, sock=20
02/14/2018 16:37:59;0100;Server@node2;Req;;Type 1 request received from ctminh@node2.supernodexp.hpc, sock=16
02/14/2018 16:37:59;0100;Server@node2;Req;;Type 3 request received from ctminh@node2.supernodexp.hpc, sock=16
02/14/2018 16:37:59;0100;Server@node2;Req;;Type 5 request received from ctminh@node2.supernodexp.hpc, sock=16
02/14/2018 16:37:59;0100;Server@node2;Job;1265.node2.supernodexp.hpc;enqueuing into workq, state 1 hop 1
02/14/2018 16:37:59;0008;Server@node2;Job;1265.node2.supernodexp.hpc;Job Queued at request of ctminh@node2.supernodexp.hpc, owner = ctminh@node2.supernodexp.hpc, job name = jacobi, queue = workq
02/14/2018 16:37:59;0100;Server@node2;Req;;Type 20 request received from Scheduler@node2.supernodexp.hpc, sock=20
02/14/2018 16:37:59;0100;Server@node2;Req;;Type 51 request received from Scheduler@node2.supernodexp.hpc, sock=20
02/14/2018 16:37:59;0100;Server@node2;Req;;Type 1 request received from ctminh@node2.supernodexp.hpc, sock=16
02/14/2018 16:37:59;0100;Server@node2;Req;;Type 3 request received from ctminh@node2.supernodexp.hpc, sock=16
02/14/2018 16:37:59;0100;Server@node2;Req;;Type 5 request received from ctminh@node2.supernodexp.hpc, sock=16
02/14/2018 16:37:59;0100;Server@node2;Job;1266.node2.supernodexp.hpc;enqueuing into workq, state 1 hop 1
02/14/2018 16:37:59;0008;Server@node2;Job;1266.node2.supernodexp.hpc;Job Queued at request of ctminh@node2.supernodexp.hpc, owner = ctminh@node2.supernodexp.hpc, job name = thread-affinity, queue = workq
02/14/2018 16:37:59;0100;Server@node2;Req;;Type 11 request received from Scheduler@node2.supernodexp.hpc, sock=20
02/14/2018 16:37:59;0008;Server@node2;Job;1264.node2.supernodexp.hpc;Job Modified at request of Scheduler@node2.supernodexp.hpc
02/14/2018 16:37:59;0100;Server@node2;Req;;Type 11 request received from Scheduler@node2.supernodexp.hpc, sock=20
02/14/2018 16:37:59;0008;Server@node2;Job;1265.node2.supernodexp.hpc;Job Modified at request of Scheduler@node2.supernodexp.hpc
02/14/2018 16:37:59;0040;Server@node2;Svr;node2.supernodexp.hpc;Scheduler sent command 1
02/14/2018 16:37:59;0040;Server@node2;Svr;node2.supernodexp.hpc;Scheduler sent command 0
02/14/2018 16:37:59;0100;Server@node2;Req;;Type 21 request received from Scheduler@node2.supernodexp.hpc, sock=20
02/14/2018 16:37:59;0100;Server@node2;Req;;Type 81 request received from Scheduler@node2.supernodexp.hpc, sock=20
02/14/2018 16:37:59;0100;Server@node2;Req;;Type 71 request received from Scheduler@node2.supernodexp.hpc, sock=20
02/14/2018 16:37:59;0100;Server@node2;Req;;Type 58 request received from Scheduler@node2.supernodexp.hpc, sock=20
02/14/2018 16:37:59;0100;Server@node2;Req;;Type 1 request received from ctminh@node2.supernodexp.hpc, sock=16
02/14/2018 16:37:59;0100;Server@node2;Req;;Type 3 request received from ctminh@node2.supernodexp.hpc, sock=16
02/14/2018 16:37:59;0100;Server@node2;Req;;Type 5 request received from ctminh@node2.supernodexp.hpc, sock=16
02/14/2018 16:37:59;0100;Server@node2;Job;1267.node2.supernodexp.hpc;enqueuing into workq, state 1 hop 1
02/14/2018 16:37:59;0008;Server@node2;Job;1267.node2.supernodexp.hpc;Job Queued at request of ctminh@node2.supernodexp.hpc, owner = ctminh@node2.supernodexp.hpc, job name = qe_mic_test, queue = workq
02/14/2018 16:37:59;0100;Server@node2;Req;;Type 1 request received from ctminh@node2.supernodexp.hpc, sock=16
02/14/2018 16:37:59;0100;Server@node2;Req;;Type 20 request received from Scheduler@node2.supernodexp.hpc, sock=20
02/14/2018 16:37:59;0100;Server@node2;Req;;Type 3 request received from ctminh@node2.supernodexp.hpc, sock=16
02/14/2018 16:37:59;0100;Server@node2;Req;;Type 51 request received from Scheduler@node2.supernodexp.hpc, sock=20
02/14/2018 16:37:59;0100;Server@node2;Req;;Type 5 request received from ctminh@node2.supernodexp.hpc, sock=16
02/14/2018 16:37:59;0100;Server@node2;Job;1268.node2.supernodexp.hpc;enqueuing into workq, state 1 hop 1
02/14/2018 16:37:59;0008;Server@node2;Job;1268.node2.supernodexp.hpc;Job Queued at request of ctminh@node2.supernodexp.hpc, owner = ctminh@node2.supernodexp.hpc, job name = jacobi, queue = workq
02/14/2018 16:37:59;0100;Server@node2;Req;;Type 1 request received from ctminh@node2.supernodexp.hpc, sock=16
02/14/2018 16:37:59;0100;Server@node2;Req;;Type 3 request received from ctminh@node2.supernodexp.hpc, sock=16
02/14/2018 16:37:59;0100;Server@node2;Req;;Type 5 request received from ctminh@node2.supernodexp.hpc, sock=16
02/14/2018 16:37:59;0100;Server@node2;Job;1269.node2.supernodexp.hpc;enqueuing into workq, state 1 hop 1
02/14/2018 16:37:59;0008;Server@node2;Job;1269.node2.supernodexp.hpc;Job Queued at request of ctminh@node2.supernodexp.hpc, owner = ctminh@node2.supernodexp.hpc, job name = vast1, queue = workq
02/14/2018 16:37:59;0100;Server@node2;Req;;Type 11 request received from Scheduler@node2.supernodexp.hpc, sock=20
02/14/2018 16:37:59;0008;Server@node2;Job;1266.node2.supernodexp.hpc;Job Modified at request of Scheduler@node2.supernodexp.hpc
02/14/2018 16:37:59;0100;Server@node2;Req;;Type 11 request received from Scheduler@node2.supernodexp.hpc, sock=20
02/14/2018 16:37:59;0008;Server@node2;Job;1267.node2.supernodexp.hpc;Job Modified at request of Scheduler@node2.supernodexp.hpc
02/14/2018 16:37:59;0040;Server@node2;Svr;node2.supernodexp.hpc;Scheduler sent command 1
02/14/2018 16:37:59;0040;Server@node2;Svr;node2.supernodexp.hpc;Scheduler sent command 0
02/14/2018 16:37:59;0100;Server@node2;Req;;Type 21 request received from Scheduler@node2.supernodexp.hpc, sock=20
02/14/2018 16:37:59;0100;Server@node2;Req;;Type 81 request received from Scheduler@node2.supernodexp.hpc, sock=20
02/14/2018 16:37:59;0100;Server@node2;Req;;Type 71 request received from Scheduler@node2.supernodexp.hpc, sock=20
02/14/2018 16:37:59;0100;Server@node2;Req;;Type 58 request received from Scheduler@node2.supernodexp.hpc, sock=20
02/14/2018 16:37:59;0100;Server@node2;Req;;Type 1 request received from ctminh@node2.supernodexp.hpc, sock=16
02/14/2018 16:37:59;0100;Server@node2;Req;;Type 3 request received from ctminh@node2.supernodexp.hpc, sock=16
02/14/2018 16:37:59;0100;Server@node2;Req;;Type 5 request received from ctminh@node2.supernodexp.hpc, sock=16
02/14/2018 16:37:59;0100;Server@node2;Job;1270.node2.supernodexp.hpc;enqueuing into workq, state 1 hop 1
02/14/2018 16:37:59;0008;Server@node2;Job;1270.node2.supernodexp.hpc;Job Queued at request of ctminh@node2.supernodexp.hpc, owner = ctminh@node2.supernodexp.hpc, job name = matrix-x-vector, queue = workq
02/14/2018 16:37:59;0100;Server@node2;Req;;Type 20 request received from Scheduler@node2.supernodexp.hpc, sock=20
02/14/2018 16:37:59;0100;Server@node2;Req;;Type 51 request received from Scheduler@node2.supernodexp.hpc, sock=20
02/14/2018 16:37:59;0100;Server@node2;Req;;Type 1 request received from ctminh@node2.supernodexp.hpc, sock=16
02/14/2018 16:37:59;0100;Server@node2;Req;;Type 3 request received from ctminh@node2.supernodexp.hpc, sock=16
02/14/2018 16:37:59;0100;Server@node2;Req;;Type 5 request received from ctminh@node2.supernodexp.hpc, sock=16
02/14/2018 16:37:59;0100;Server@node2;Job;1271.node2.supernodexp.hpc;enqueuing into workq, state 1 hop 1
02/14/2018 16:37:59;0008;Server@node2;Job;1271.node2.supernodexp.hpc;Job Queued at request of ctminh@node2.supernodexp.hpc, owner = ctminh@node2.supernodexp.hpc, job name = sweep, queue = workq
02/14/2018 16:37:59;0100;Server@node2;Req;;Type 1 request received from ctminh@node2.supernodexp.hpc, sock=16
02/14/2018 16:37:59;0100;Server@node2;Req;;Type 11 request received from Scheduler@node2.supernodexp.hpc, sock=20
02/14/2018 16:37:59;0008;Server@node2;Job;1268.node2.supernodexp.hpc;Job Modified at request of Scheduler@node2.supernodexp.hpc
02/14/2018 16:37:59;0100;Server@node2;Req;;Type 3 request received from ctminh@node2.supernodexp.hpc, sock=16
02/14/2018 16:37:59;0100;Server@node2;Req;;Type 11 request received from Scheduler@node2.supernodexp.hpc, sock=20
02/14/2018 16:37:59;0008;Server@node2;Job;1269.node2.supernodexp.hpc;Job Modified at request of Scheduler@node2.supernodexp.hpc
02/14/2018 16:37:59;0100;Server@node2;Req;;Type 5 request received from ctminh@node2.supernodexp.hpc, sock=16
02/14/2018 16:37:59;0100;Server@node2;Job;1272.node2.supernodexp.hpc;enqueuing into workq, state 1 hop 1
02/14/2018 16:37:59;0008;Server@node2;Job;1272.node2.supernodexp.hpc;Job Queued at request of ctminh@node2.supernodexp.hpc, owner = ctminh@node2.supernodexp.hpc, job name = nbody, queue = workq
02/14/2018 16:37:59;0100;Server@node2;Req;;Type 11 request received from Scheduler@node2.supernodexp.hpc, sock=20
02/14/2018 16:37:59;0008;Server@node2;Job;1270.node2.supernodexp.hpc;Job Modified at request of Scheduler@node2.supernodexp.hpc
02/14/2018 16:37:59;0040;Server@node2;Svr;node2.supernodexp.hpc;Scheduler sent command 1
02/14/2018 16:37:59;0040;Server@node2;Svr;node2.supernodexp.hpc;Scheduler sent command 0
02/14/2018 16:37:59;0100;Server@node2;Req;;Type 21 request received from Scheduler@node2.supernodexp.hpc, sock=20
02/14/2018 16:37:59;0100;Server@node2;Req;;Type 81 request received from Scheduler@node2.supernodexp.hpc, sock=20
02/14/2018 16:37:59;0100;Server@node2;Req;;Type 71 request received from Scheduler@node2.supernodexp.hpc, sock=20
02/14/2018 16:37:59;0100;Server@node2;Req;;Type 58 request received from Scheduler@node2.supernodexp.hpc, sock=20
02/14/2018 16:37:59;0100;Server@node2;Req;;Type 1 request received from ctminh@node2.supernodexp.hpc, sock=16
02/14/2018 16:37:59;0100;Server@node2;Req;;Type 3 request received from ctminh@node2.supernodexp.hpc, sock=16
02/14/2018 16:37:59;0100;Server@node2;Req;;Type 5 request received from ctminh@node2.supernodexp.hpc, sock=16
02/14/2018 16:37:59;0100;Server@node2;Job;1273.node2.supernodexp.hpc;enqueuing into workq, state 1 hop 1
02/14/2018 16:37:59;0008;Server@node2;Job;1273.node2.supernodexp.hpc;Job Queued at request of ctminh@node2.supernodexp.hpc, owner = ctminh@node2.supernodexp.hpc, job name = matrix-x-vector, queue = workq
02/14/2018 16:37:59;0100;Server@node2;Req;;Type 20 request received from Scheduler@node2.supernodexp.hpc, sock=20
02/14/2018 16:37:59;0100;Server@node2;Req;;Type 51 request received from Scheduler@node2.supernodexp.hpc, sock=20
02/14/2018 16:37:59;0100;Server@node2;Req;;Type 1 request received from ctminh@node2.supernodexp.hpc, sock=16
02/14/2018 16:37:59;0100;Server@node2;Req;;Type 3 request received from ctminh@node2.supernodexp.hpc, sock=16
02/14/2018 16:37:59;0100;Server@node2;Req;;Type 5 request received from ctminh@node2.supernodexp.hpc, sock=16
02/14/2018 16:37:59;0100;Server@node2;Job;1274.node2.supernodexp.hpc;enqueuing into workq, state 1 hop 1
02/14/2018 16:37:59;0008;Server@node2;Job;1274.node2.supernodexp.hpc;Job Queued at request of ctminh@node2.supernodexp.hpc, owner = ctminh@node2.supernodexp.hpc, job name = telemac3, queue = workq
02/14/2018 16:37:59;0100;Server@node2;Req;;Type 11 request received from Scheduler@node2.supernodexp.hpc, sock=20
02/14/2018 16:37:59;0008;Server@node2;Job;1271.node2.supernodexp.hpc;Job Modified at request of Scheduler@node2.supernodexp.hpc
02/14/2018 16:37:59;0100;Server@node2;Req;;Type 11 request received from Scheduler@node2.supernodexp.hpc, sock=20
02/14/2018 16:37:59;0008;Server@node2;Job;1272.node2.supernodexp.hpc;Job Modified at request of Scheduler@node2.supernodexp.hpc
02/14/2018 16:37:59;0100;Server@node2;Req;;Type 11 request received from Scheduler@node2.supernodexp.hpc, sock=20
02/14/2018 16:37:59;0008;Server@node2;Job;1273.node2.supernodexp.hpc;Job Modified at request of Scheduler@node2.supernodexp.hpc
02/14/2018 16:37:59;0040;Server@node2;Svr;node2.supernodexp.hpc;Scheduler sent command 1
02/14/2018 16:37:59;0040;Server@node2;Svr;node2.supernodexp.hpc;Scheduler sent command 0
02/14/2018 16:37:59;0100;Server@node2;Req;;Type 21 request received from Scheduler@node2.supernodexp.hpc, sock=20
02/14/2018 16:37:59;0100;Server@node2;Req;;Type 81 request received from Scheduler@node2.supernodexp.hpc, sock=20
02/14/2018 16:37:59;0100;Server@node2;Req;;Type 71 request received from Scheduler@node2.supernodexp.hpc, sock=20
02/14/2018 16:37:59;0100;Server@node2;Req;;Type 58 request received from Scheduler@node2.supernodexp.hpc, sock=20
02/14/2018 16:37:59;0100;Server@node2;Req;;Type 20 request received from Scheduler@node2.supernodexp.hpc, sock=20
02/14/2018 16:37:59;0100;Server@node2;Req;;Type 51 request received from Scheduler@node2.supernodexp.hpc, sock=20
02/14/2018 16:37:59;0100;Server@node2;Req;;Type 11 request received from Scheduler@node2.supernodexp.hpc, sock=20
02/14/2018 16:37:59;0008;Server@node2;Job;1274.node2.supernodexp.hpc;Job Modified at request of Scheduler@node2.supernodexp.hpc
02/14/2018 16:37:59;0100;Server@node2;Req;;Type 1 request received from ctminh@node2.supernodexp.hpc, sock=16
02/14/2018 16:37:59;0100;Server@node2;Req;;Type 3 request received from ctminh@node2.supernodexp.hpc, sock=16
02/14/2018 16:37:59;0100;Server@node2;Req;;Type 5 request received from ctminh@node2.supernodexp.hpc, sock=16
02/14/2018 16:37:59;0100;Server@node2;Job;1275.node2.supernodexp.hpc;enqueuing into workq, state 1 hop 1
02/14/2018 16:37:59;0008;Server@node2;Job;1275.node2.supernodexp.hpc;Job Queued at request of ctminh@node2.supernodexp.hpc, owner = ctminh@node2.supernodexp.hpc, job name = sweep, queue = workq
02/14/2018 16:37:59;0040;Server@node2;Svr;node2.supernodexp.hpc;Scheduler sent command 1
02/14/2018 16:37:59;0040;Server@node2;Svr;node2.supernodexp.hpc;Scheduler sent command 0
02/14/2018 16:37:59;0100;Server@node2;Req;;Type 21 request received from Scheduler@node2.supernodexp.hpc, sock=20
02/14/2018 16:37:59;0100;Server@node2;Req;;Type 81 request received from Scheduler@node2.supernodexp.hpc, sock=20
02/14/2018 16:37:59;0100;Server@node2;Req;;Type 71 request received from Scheduler@node2.supernodexp.hpc, sock=20
02/14/2018 16:37:59;0100;Server@node2;Req;;Type 58 request received from Scheduler@node2.supernodexp.hpc, sock=20
02/14/2018 16:37:59;0100;Server@node2;Req;;Type 1 request received from ctminh@node2.supernodexp.hpc, sock=16
02/14/2018 16:37:59;0100;Server@node2;Req;;Type 3 request received from ctminh@node2.supernodexp.hpc, sock=16
02/14/2018 16:37:59;0100;Server@node2;Req;;Type 5 request received from ctminh@node2.supernodexp.hpc, sock=16
02/14/2018 16:37:59;0100;Server@node2;Job;1276.node2.supernodexp.hpc;enqueuing into workq, state 1 hop 1
02/14/2018 16:37:59;0008;Server@node2;Job;1276.node2.supernodexp.hpc;Job Queued at request of ctminh@node2.supernodexp.hpc, owner = ctminh@node2.supernodexp.hpc, job name = telemac2, queue = workq
02/14/2018 16:37:59;0100;Server@node2;Req;;Type 1 request received from ctminh@node2.supernodexp.hpc, sock=16
02/14/2018 16:37:59;0100;Server@node2;Req;;Type 20 request received from Scheduler@node2.supernodexp.hpc, sock=20
02/14/2018 16:37:59;0100;Server@node2;Req;;Type 3 request received from ctminh@node2.supernodexp.hpc, sock=16
02/14/2018 16:37:59;0100;Server@node2;Req;;Type 51 request received from Scheduler@node2.supernodexp.hpc, sock=20
02/14/2018 16:37:59;0100;Server@node2;Req;;Type 5 request received from ctminh@node2.supernodexp.hpc, sock=16
02/14/2018 16:37:59;0100;Server@node2;Job;1277.node2.supernodexp.hpc;enqueuing into workq, state 1 hop 1
02/14/2018 16:37:59;0008;Server@node2;Job;1277.node2.supernodexp.hpc;Job Queued at request of ctminh@node2.supernodexp.hpc, owner = ctminh@node2.supernodexp.hpc, job name = sweep, queue = workq
02/14/2018 16:37:59;0100;Server@node2;Req;;Type 11 request received from Scheduler@node2.supernodexp.hpc, sock=20
02/14/2018 16:37:59;0008;Server@node2;Job;1275.node2.supernodexp.hpc;Job Modified at request of Scheduler@node2.supernodexp.hpc
02/14/2018 16:37:59;0100;Server@node2;Req;;Type 11 request received from Scheduler@node2.supernodexp.hpc, sock=20
02/14/2018 16:37:59;0008;Server@node2;Job;1276.node2.supernodexp.hpc;Job Modified at request of Scheduler@node2.supernodexp.hpc
02/14/2018 16:37:59;0040;Server@node2;Svr;node2.supernodexp.hpc;Scheduler sent command 1
02/14/2018 16:37:59;0040;Server@node2;Svr;node2.supernodexp.hpc;Scheduler sent command 0
02/14/2018 16:37:59;0100;Server@node2;Req;;Type 21 request received from Scheduler@node2.supernodexp.hpc, sock=20
02/14/2018 16:37:59;0100;Server@node2;Req;;Type 81 request received from Scheduler@node2.supernodexp.hpc, sock=20
02/14/2018 16:37:59;0100;Server@node2;Req;;Type 71 request received from Scheduler@node2.supernodexp.hpc, sock=20
02/14/2018 16:37:59;0100;Server@node2;Req;;Type 58 request received from Scheduler@node2.supernodexp.hpc, sock=20
02/14/2018 16:37:59;0100;Server@node2;Req;;Type 1 request received from ctminh@node2.supernodexp.hpc, sock=16
02/14/2018 16:37:59;0100;Server@node2;Req;;Type 3 request received from ctminh@node2.supernodexp.hpc, sock=16
02/14/2018 16:37:59;0100;Server@node2;Req;;Type 5 request received from ctminh@node2.supernodexp.hpc, sock=16
02/14/2018 16:37:59;0100;Server@node2;Job;1278.node2.supernodexp.hpc;enqueuing into workq, state 1 hop 1
02/14/2018 16:37:59;0008;Server@node2;Job;1278.node2.supernodexp.hpc;Job Queued at request of ctminh@node2.supernodexp.hpc, owner = ctminh@node2.supernodexp.hpc, job name = histogram, queue = workq
02/14/2018 16:37:59;0100;Server@node2;Req;;Type 1 request received from ctminh@node2.supernodexp.hpc, sock=16
02/14/2018 16:38:00;0100;Server@node2;Req;;Type 20 request received from Scheduler@node2.supernodexp.hpc, sock=20
02/14/2018 16:38:00;0100;Server@node2;Req;;Type 3 request received from ctminh@node2.supernodexp.hpc, sock=16
02/14/2018 16:38:00;0100;Server@node2;Req;;Type 51 request received from Scheduler@node2.supernodexp.hpc, sock=20
02/14/2018 16:38:00;0100;Server@node2;Req;;Type 5 request received from ctminh@node2.supernodexp.hpc, sock=16
02/14/2018 16:38:00;0100;Server@node2;Job;1279.node2.supernodexp.hpc;enqueuing into workq, state 1 hop 1
02/14/2018 16:38:00;0008;Server@node2;Job;1279.node2.supernodexp.hpc;Job Queued at request of ctminh@node2.supernodexp.hpc, owner = ctminh@node2.supernodexp.hpc, job name = nbody, queue = workq
02/14/2018 16:38:00;0100;Server@node2;Req;;Type 1 request received from ctminh@node2.supernodexp.hpc, sock=16
02/14/2018 16:38:00;0100;Server@node2;Req;;Type 3 request received from ctminh@node2.supernodexp.hpc, sock=16
02/14/2018 16:38:00;0100;Server@node2;Req;;Type 5 request received from ctminh@node2.supernodexp.hpc, sock=16
02/14/2018 16:38:00;0100;Server@node2;Job;1280.node2.supernodexp.hpc;enqueuing into workq, state 1 hop 1
02/14/2018 16:38:00;0008;Server@node2;Job;1280.node2.supernodexp.hpc;Job Queued at request of ctminh@node2.supernodexp.hpc, owner = ctminh@node2.supernodexp.hpc, job name = telemac2, queue = workq
02/14/2018 16:38:00;0100;Server@node2;Req;;Type 1 request received from ctminh@node2.supernodexp.hpc, sock=16
02/14/2018 16:38:00;0100;Server@node2;Req;;Type 11 request received from Scheduler@node2.supernodexp.hpc, sock=20
02/14/2018 16:38:00;0008;Server@node2;Job;1277.node2.supernodexp.hpc;Job Modified at request of Scheduler@node2.supernodexp.hpc
02/14/2018 16:38:00;0100;Server@node2;Req;;Type 3 request received from ctminh@node2.supernodexp.hpc, sock=16
02/14/2018 16:38:00;0100;Server@node2;Req;;Type 11 request received from Scheduler@node2.supernodexp.hpc, sock=20
02/14/2018 16:38:00;0008;Server@node2;Job;1278.node2.supernodexp.hpc;Job Modified at request of Scheduler@node2.supernodexp.hpc
02/14/2018 16:38:00;0100;Server@node2;Req;;Type 5 request received from ctminh@node2.supernodexp.hpc, sock=16
02/14/2018 16:38:00;0100;Server@node2;Job;1281.node2.supernodexp.hpc;enqueuing into workq, state 1 hop 1
02/14/2018 16:38:00;0008;Server@node2;Job;1281.node2.supernodexp.hpc;Job Queued at request of ctminh@node2.supernodexp.hpc, owner = ctminh@node2.supernodexp.hpc, job name = matrix-x-vector, queue = workq
02/14/2018 16:38:00;0040;Server@node2;Svr;node2.supernodexp.hpc;Scheduler sent command 1
02/14/2018 16:38:00;0040;Server@node2;Svr;node2.supernodexp.hpc;Scheduler sent command 0
02/14/2018 16:38:00;0100;Server@node2;Req;;Type 21 request received from Scheduler@node2.supernodexp.hpc, sock=20
02/14/2018 16:38:00;0100;Server@node2;Req;;Type 81 request received from Scheduler@node2.supernodexp.hpc, sock=20
02/14/2018 16:38:00;0100;Server@node2;Req;;Type 71 request received from Scheduler@node2.supernodexp.hpc, sock=20
02/14/2018 16:38:00;0100;Server@node2;Req;;Type 58 request received from Scheduler@node2.supernodexp.hpc, sock=20
02/14/2018 16:38:00;0100;Server@node2;Req;;Type 1 request received from ctminh@node2.supernodexp.hpc, sock=16
02/14/2018 16:38:00;0100;Server@node2;Req;;Type 3 request received from ctminh@node2.supernodexp.hpc, sock=16
02/14/2018 16:38:00;0100;Server@node2;Req;;Type 5 request received from ctminh@node2.supernodexp.hpc, sock=16
02/14/2018 16:38:00;0100;Server@node2;Job;1282.node2.supernodexp.hpc;enqueuing into workq, state 1 hop 1
02/14/2018 16:38:00;0008;Server@node2;Job;1282.node2.supernodexp.hpc;Job Queued at request of ctminh@node2.supernodexp.hpc, owner = ctminh@node2.supernodexp.hpc, job name = telemac1, queue = workq
02/14/2018 16:38:00;0100;Server@node2;Req;;Type 20 request received from Scheduler@node2.supernodexp.hpc, sock=20
02/14/2018 16:38:00;0100;Server@node2;Req;;Type 51 request received from Scheduler@node2.supernodexp.hpc, sock=20
02/14/2018 16:38:00;0100;Server@node2;Req;;Type 11 request received from Scheduler@node2.supernodexp.hpc, sock=20
02/14/2018 16:38:00;0008;Server@node2;Job;1279.node2.supernodexp.hpc;Job Modified at request of Scheduler@node2.supernodexp.hpc
02/14/2018 16:38:00;0100;Server@node2;Req;;Type 11 request received from Scheduler@node2.supernodexp.hpc, sock=20
02/14/2018 16:38:00;0008;Server@node2;Job;1280.node2.supernodexp.hpc;Job Modified at request of Scheduler@node2.supernodexp.hpc
02/14/2018 16:38:00;0100;Server@node2;Req;;Type 11 request received from Scheduler@node2.supernodexp.hpc, sock=20
02/14/2018 16:38:00;0008;Server@node2;Job;1281.node2.supernodexp.hpc;Job Modified at request of Scheduler@node2.supernodexp.hpc
02/14/2018 16:38:00;0100;Server@node2;Req;;Type 11 request received from Scheduler@node2.supernodexp.hpc, sock=20
02/14/2018 16:38:00;0008;Server@node2;Job;1282.node2.supernodexp.hpc;Job Modified at request of Scheduler@node2.supernodexp.hpc
02/14/2018 16:38:00;0040;Server@node2;Svr;node2.supernodexp.hpc;Scheduler sent command 1
02/14/2018 16:38:00;0040;Server@node2;Svr;node2.supernodexp.hpc;Scheduler sent command 0
02/14/2018 16:38:00;0100;Server@node2;Req;;Type 21 request received from Scheduler@node2.supernodexp.hpc, sock=20
02/14/2018 16:38:00;0100;Server@node2;Req;;Type 81 request received from Scheduler@node2.supernodexp.hpc, sock=20
02/14/2018 16:38:00;0100;Server@node2;Req;;Type 71 request received from Scheduler@node2.supernodexp.hpc, sock=20
02/14/2018 16:38:00;0100;Server@node2;Req;;Type 58 request received from Scheduler@node2.supernodexp.hpc, sock=20
02/14/2018 16:38:00;0100;Server@node2;Req;;Type 20 request received from Scheduler@node2.supernodexp.hpc, sock=20
02/14/2018 16:38:00;0100;Server@node2;Req;;Type 51 request received from Scheduler@node2.supernodexp.hpc, sock=20
02/14/2018 16:38:35;0100;Server@node2;Req;;Type 1 request received from ctminh@node2.supernodexp.hpc, sock=16
02/14/2018 16:38:35;0100;Server@node2;Req;;Type 3 request received from ctminh@node2.supernodexp.hpc, sock=16
02/14/2018 16:38:35;0100;Server@node2;Req;;Type 5 request received from ctminh@node2.supernodexp.hpc, sock=16
02/14/2018 16:38:35;0100;Server@node2;Job;1283.node2.supernodexp.hpc;enqueuing into workq, state 1 hop 1
02/14/2018 16:38:35;0008;Server@node2;Job;1283.node2.supernodexp.hpc;Job Queued at request of ctminh@node2.supernodexp.hpc, owner = ctminh@node2.supernodexp.hpc, job name = matrix-x-vector, queue = workq
02/14/2018 16:38:35;0040;Server@node2;Svr;node2.supernodexp.hpc;Scheduler sent command 1
02/14/2018 16:38:35;0040;Server@node2;Svr;node2.supernodexp.hpc;Scheduler sent command 0
02/14/2018 16:38:35;0100;Server@node2;Req;;Type 21 request received from Scheduler@node2.supernodexp.hpc, sock=20
02/14/2018 16:38:35;0100;Server@node2;Req;;Type 81 request received from Scheduler@node2.supernodexp.hpc, sock=20
02/14/2018 16:38:35;0100;Server@node2;Req;;Type 71 request received from Scheduler@node2.supernodexp.hpc, sock=20
02/14/2018 16:38:35;0100;Server@node2;Req;;Type 58 request received from Scheduler@node2.supernodexp.hpc, sock=20
02/14/2018 16:38:35;0100;Server@node2;Req;;Type 1 request received from ctminh@node2.supernodexp.hpc, sock=16
02/14/2018 16:38:35;0100;Server@node2;Req;;Type 3 request received from ctminh@node2.supernodexp.hpc, sock=16
02/14/2018 16:38:35;0100;Server@node2;Req;;Type 5 request received from ctminh@node2.supernodexp.hpc, sock=16
02/14/2018 16:38:35;0100;Server@node2;Job;1284.node2.supernodexp.hpc;enqueuing into workq, state 1 hop 1
02/14/2018 16:38:35;0008;Server@node2;Job;1284.node2.supernodexp.hpc;Job Queued at request of ctminh@node2.supernodexp.hpc, owner = ctminh@node2.supernodexp.hpc, job name = histogram, queue = workq
02/14/2018 16:38:35;0100;Server@node2;Req;;Type 20 request received from Scheduler@node2.supernodexp.hpc, sock=20
02/14/2018 16:38:35;0100;Server@node2;Req;;Type 51 request received from Scheduler@node2.supernodexp.hpc, sock=20
02/14/2018 16:38:35;0100;Server@node2;Req;;Type 1 request received from ctminh@node2.supernodexp.hpc, sock=16
02/14/2018 16:38:35;0100;Server@node2;Req;;Type 3 request received from ctminh@node2.supernodexp.hpc, sock=16
02/14/2018 16:38:35;0100;Server@node2;Req;;Type 5 request received from ctminh@node2.supernodexp.hpc, sock=16
02/14/2018 16:38:35;0100;Server@node2;Job;1285.node2.supernodexp.hpc;enqueuing into workq, state 1 hop 1
02/14/2018 16:38:35;0008;Server@node2;Job;1285.node2.supernodexp.hpc;Job Queued at request of ctminh@node2.supernodexp.hpc, owner = ctminh@node2.supernodexp.hpc, job name = qe_mic_test, queue = workq
02/14/2018 16:38:35;0100;Server@node2;Req;;Type 1 request received from ctminh@node2.supernodexp.hpc, sock=16
02/14/2018 16:38:35;0100;Server@node2;Req;;Type 11 request received from Scheduler@node2.supernodexp.hpc, sock=20
02/14/2018 16:38:35;0008;Server@node2;Job;1283.node2.supernodexp.hpc;Job Modified at request of Scheduler@node2.supernodexp.hpc
02/14/2018 16:38:35;0100;Server@node2;Req;;Type 3 request received from ctminh@node2.supernodexp.hpc, sock=16
02/14/2018 16:38:35;0100;Server@node2;Req;;Type 11 request received from Scheduler@node2.supernodexp.hpc, sock=20
02/14/2018 16:38:35;0008;Server@node2;Job;1284.node2.supernodexp.hpc;Job Modified at request of Scheduler@node2.supernodexp.hpc
02/14/2018 16:38:35;0100;Server@node2;Req;;Type 5 request received from ctminh@node2.supernodexp.hpc, sock=16
02/14/2018 16:38:35;0100;Server@node2;Job;1286.node2.supernodexp.hpc;enqueuing into workq, state 1 hop 1
02/14/2018 16:38:35;0008;Server@node2;Job;1286.node2.supernodexp.hpc;Job Queued at request of ctminh@node2.supernodexp.hpc, owner = ctminh@node2.supernodexp.hpc, job name = nbody, queue = workq
02/14/2018 16:38:35;0040;Server@node2;Svr;node2.supernodexp.hpc;Scheduler sent command 1
02/14/2018 16:38:35;0040;Server@node2;Svr;node2.supernodexp.hpc;Scheduler sent command 0
02/14/2018 16:38:35;0100;Server@node2;Req;;Type 21 request received from Scheduler@node2.supernodexp.hpc, sock=20
02/14/2018 16:38:35;0100;Server@node2;Req;;Type 81 request received from Scheduler@node2.supernodexp.hpc, sock=20
02/14/2018 16:38:35;0100;Server@node2;Req;;Type 71 request received from Scheduler@node2.supernodexp.hpc, sock=20
02/14/2018 16:38:35;0100;Server@node2;Req;;Type 58 request received from Scheduler@node2.supernodexp.hpc, sock=20
02/14/2018 16:38:35;0100;Server@node2;Req;;Type 1 request received from ctminh@node2.supernodexp.hpc, sock=16
02/14/2018 16:38:35;0100;Server@node2;Req;;Type 3 request received from ctminh@node2.supernodexp.hpc, sock=16
02/14/2018 16:38:35;0100;Server@node2;Req;;Type 5 request received from ctminh@node2.supernodexp.hpc, sock=16
02/14/2018 16:38:35;0100;Server@node2;Job;1287.node2.supernodexp.hpc;enqueuing into workq, state 1 hop 1
02/14/2018 16:38:35;0008;Server@node2;Job;1287.node2.supernodexp.hpc;Job Queued at request of ctminh@node2.supernodexp.hpc, owner = ctminh@node2.supernodexp.hpc, job name = telemac2, queue = workq
02/14/2018 16:38:35;0100;Server@node2;Req;;Type 1 request received from ctminh@node2.supernodexp.hpc, sock=16
02/14/2018 16:38:35;0100;Server@node2;Req;;Type 20 request received from Scheduler@node2.supernodexp.hpc, sock=20
02/14/2018 16:38:35;0100;Server@node2;Req;;Type 3 request received from ctminh@node2.supernodexp.hpc, sock=16
02/14/2018 16:38:35;0100;Server@node2;Req;;Type 51 request received from Scheduler@node2.supernodexp.hpc, sock=20
02/14/2018 16:38:35;0100;Server@node2;Req;;Type 5 request received from ctminh@node2.supernodexp.hpc, sock=16
02/14/2018 16:38:35;0100;Server@node2;Job;1288.node2.supernodexp.hpc;enqueuing into workq, state 1 hop 1
02/14/2018 16:38:35;0008;Server@node2;Job;1288.node2.supernodexp.hpc;Job Queued at request of ctminh@node2.supernodexp.hpc, owner = ctminh@node2.supernodexp.hpc, job name = jacobi, queue = workq
02/14/2018 16:38:35;0100;Server@node2;Req;;Type 1 request received from ctminh@node2.supernodexp.hpc, sock=16
02/14/2018 16:38:35;0100;Server@node2;Req;;Type 3 request received from ctminh@node2.supernodexp.hpc, sock=16
02/14/2018 16:38:35;0100;Server@node2;Req;;Type 5 request received from ctminh@node2.supernodexp.hpc, sock=16
02/14/2018 16:38:35;0100;Server@node2;Job;1289.node2.supernodexp.hpc;enqueuing into workq, state 1 hop 1
02/14/2018 16:38:35;0008;Server@node2;Job;1289.node2.supernodexp.hpc;Job Queued at request of ctminh@node2.supernodexp.hpc, owner = ctminh@node2.supernodexp.hpc, job name = histogram, queue = workq
02/14/2018 16:38:35;0100;Server@node2;Req;;Type 1 request received from ctminh@node2.supernodexp.hpc, sock=16
02/14/2018 16:38:35;0100;Server@node2;Req;;Type 11 request received from Scheduler@node2.supernodexp.hpc, sock=20
02/14/2018 16:38:35;0008;Server@node2;Job;1285.node2.supernodexp.hpc;Job Modified at request of Scheduler@node2.supernodexp.hpc
02/14/2018 16:38:35;0100;Server@node2;Req;;Type 3 request received from ctminh@node2.supernodexp.hpc, sock=16
02/14/2018 16:38:35;0100;Server@node2;Req;;Type 5 request received from ctminh@node2.supernodexp.hpc, sock=16
02/14/2018 16:38:35;0100;Server@node2;Job;1290.node2.supernodexp.hpc;enqueuing into workq, state 1 hop 1
02/14/2018 16:38:35;0008;Server@node2;Job;1290.node2.supernodexp.hpc;Job Queued at request of ctminh@node2.supernodexp.hpc, owner = ctminh@node2.supernodexp.hpc, job name = telemac3, queue = workq
02/14/2018 16:38:35;0100;Server@node2;Req;;Type 11 request received from Scheduler@node2.supernodexp.hpc, sock=20
02/14/2018 16:38:35;0008;Server@node2;Job;1286.node2.supernodexp.hpc;Job Modified at request of Scheduler@node2.supernodexp.hpc
02/14/2018 16:38:35;0100;Server@node2;Req;;Type 11 request received from Scheduler@node2.supernodexp.hpc, sock=20
02/14/2018 16:38:35;0008;Server@node2;Job;1287.node2.supernodexp.hpc;Job Modified at request of Scheduler@node2.supernodexp.hpc
02/14/2018 16:38:35;0040;Server@node2;Svr;node2.supernodexp.hpc;Scheduler sent command 1
02/14/2018 16:38:35;0040;Server@node2;Svr;node2.supernodexp.hpc;Scheduler sent command 0
02/14/2018 16:38:35;0100;Server@node2;Req;;Type 21 request received from Scheduler@node2.supernodexp.hpc, sock=20
02/14/2018 16:38:35;0100;Server@node2;Req;;Type 81 request received from Scheduler@node2.supernodexp.hpc, sock=20
02/14/2018 16:38:35;0100;Server@node2;Req;;Type 71 request received from Scheduler@node2.supernodexp.hpc, sock=20
02/14/2018 16:38:35;0100;Server@node2;Req;;Type 58 request received from Scheduler@node2.supernodexp.hpc, sock=20
02/14/2018 16:38:35;0100;Server@node2;Req;;Type 1 request received from ctminh@node2.supernodexp.hpc, sock=16
02/14/2018 16:38:35;0100;Server@node2;Req;;Type 3 request received from ctminh@node2.supernodexp.hpc, sock=16
02/14/2018 16:38:35;0100;Server@node2;Req;;Type 5 request received from ctminh@node2.supernodexp.hpc, sock=16
02/14/2018 16:38:35;0100;Server@node2;Job;1291.node2.supernodexp.hpc;enqueuing into workq, state 1 hop 1
02/14/2018 16:38:35;0008;Server@node2;Job;1291.node2.supernodexp.hpc;Job Queued at request of ctminh@node2.supernodexp.hpc, owner = ctminh@node2.supernodexp.hpc, job name = telemac3, queue = workq
02/14/2018 16:38:35;0100;Server@node2;Req;;Type 1 request received from ctminh@node2.supernodexp.hpc, sock=16
02/14/2018 16:38:35;0100;Server@node2;Req;;Type 20 request received from Scheduler@node2.supernodexp.hpc, sock=20
02/14/2018 16:38:35;0100;Server@node2;Req;;Type 3 request received from ctminh@node2.supernodexp.hpc, sock=16
02/14/2018 16:38:35;0100;Server@node2;Req;;Type 51 request received from Scheduler@node2.supernodexp.hpc, sock=20
02/14/2018 16:38:35;0100;Server@node2;Req;;Type 5 request received from ctminh@node2.supernodexp.hpc, sock=16
02/14/2018 16:38:35;0100;Server@node2;Job;1292.node2.supernodexp.hpc;enqueuing into workq, state 1 hop 1
02/14/2018 16:38:35;0008;Server@node2;Job;1292.node2.supernodexp.hpc;Job Queued at request of ctminh@node2.supernodexp.hpc, owner = ctminh@node2.supernodexp.hpc, job name = nbody, queue = workq
02/14/2018 16:38:35;0100;Server@node2;Req;;Type 1 request received from ctminh@node2.supernodexp.hpc, sock=16
02/14/2018 16:38:35;0100;Server@node2;Req;;Type 3 request received from ctminh@node2.supernodexp.hpc, sock=16
02/14/2018 16:38:35;0100;Server@node2;Req;;Type 5 request received from ctminh@node2.supernodexp.hpc, sock=16
02/14/2018 16:38:35;0100;Server@node2;Job;1293.node2.supernodexp.hpc;enqueuing into workq, state 1 hop 1
02/14/2018 16:38:35;0008;Server@node2;Job;1293.node2.supernodexp.hpc;Job Queued at request of ctminh@node2.supernodexp.hpc, owner = ctminh@node2.supernodexp.hpc, job name = vectorization, queue = workq
02/14/2018 16:38:35;0100;Server@node2;Req;;Type 1 request received from ctminh@node2.supernodexp.hpc, sock=16
02/14/2018 16:38:35;0100;Server@node2;Req;;Type 11 request received from Scheduler@node2.supernodexp.hpc, sock=20
02/14/2018 16:38:35;0008;Server@node2;Job;1288.node2.supernodexp.hpc;Job Modified at request of Scheduler@node2.supernodexp.hpc
02/14/2018 16:38:35;0100;Server@node2;Req;;Type 3 request received from ctminh@node2.supernodexp.hpc, sock=16
02/14/2018 16:38:35;0100;Server@node2;Req;;Type 11 request received from Scheduler@node2.supernodexp.hpc, sock=20
02/14/2018 16:38:35;0008;Server@node2;Job;1289.node2.supernodexp.hpc;Job Modified at request of Scheduler@node2.supernodexp.hpc
02/14/2018 16:38:35;0100;Server@node2;Req;;Type 5 request received from ctminh@node2.supernodexp.hpc, sock=16
02/14/2018 16:38:35;0100;Server@node2;Job;1294.node2.supernodexp.hpc;enqueuing into workq, state 1 hop 1
02/14/2018 16:38:35;0008;Server@node2;Job;1294.node2.supernodexp.hpc;Job Queued at request of ctminh@node2.supernodexp.hpc, owner = ctminh@node2.supernodexp.hpc, job name = sweep, queue = workq
02/14/2018 16:38:35;0100;Server@node2;Req;;Type 11 request received from Scheduler@node2.supernodexp.hpc, sock=20
02/14/2018 16:38:35;0008;Server@node2;Job;1290.node2.supernodexp.hpc;Job Modified at request of Scheduler@node2.supernodexp.hpc
02/14/2018 16:38:35;0100;Server@node2;Req;;Type 11 request received from Scheduler@node2.supernodexp.hpc, sock=20
02/14/2018 16:38:35;0008;Server@node2;Job;1291.node2.supernodexp.hpc;Job Modified at request of Scheduler@node2.supernodexp.hpc
02/14/2018 16:38:35;0040;Server@node2;Svr;node2.supernodexp.hpc;Scheduler sent command 1
02/14/2018 16:38:35;0040;Server@node2;Svr;node2.supernodexp.hpc;Scheduler sent command 0
02/14/2018 16:38:35;0100;Server@node2;Req;;Type 21 request received from Scheduler@node2.supernodexp.hpc, sock=20
02/14/2018 16:38:35;0100;Server@node2;Req;;Type 81 request received from Scheduler@node2.supernodexp.hpc, sock=20
02/14/2018 16:38:35;0100;Server@node2;Req;;Type 71 request received from Scheduler@node2.supernodexp.hpc, sock=20
02/14/2018 16:38:35;0100;Server@node2;Req;;Type 58 request received from Scheduler@node2.supernodexp.hpc, sock=20
02/14/2018 16:38:35;0100;Server@node2;Req;;Type 1 request received from ctminh@node2.supernodexp.hpc, sock=16
02/14/2018 16:38:35;0100;Server@node2;Req;;Type 3 request received from ctminh@node2.supernodexp.hpc, sock=16
02/14/2018 16:38:35;0100;Server@node2;Req;;Type 5 request received from ctminh@node2.supernodexp.hpc, sock=16
02/14/2018 16:38:35;0100;Server@node2;Job;1295.node2.supernodexp.hpc;enqueuing into workq, state 1 hop 1
02/14/2018 16:38:35;0008;Server@node2;Job;1295.node2.supernodexp.hpc;Job Queued at request of ctminh@node2.supernodexp.hpc, owner = ctminh@node2.supernodexp.hpc, job name = vectorization, queue = workq
02/14/2018 16:38:35;0100;Server@node2;Req;;Type 1 request received from ctminh@node2.supernodexp.hpc, sock=16
02/14/2018 16:38:35;0100;Server@node2;Req;;Type 20 request received from Scheduler@node2.supernodexp.hpc, sock=20
02/14/2018 16:38:35;0100;Server@node2;Req;;Type 3 request received from ctminh@node2.supernodexp.hpc, sock=16
02/14/2018 16:38:35;0100;Server@node2;Req;;Type 51 request received from Scheduler@node2.supernodexp.hpc, sock=20
02/14/2018 16:38:35;0100;Server@node2;Req;;Type 5 request received from ctminh@node2.supernodexp.hpc, sock=16
02/14/2018 16:38:35;0100;Server@node2;Job;1296.node2.supernodexp.hpc;enqueuing into workq, state 1 hop 1
02/14/2018 16:38:35;0008;Server@node2;Job;1296.node2.supernodexp.hpc;Job Queued at request of ctminh@node2.supernodexp.hpc, owner = ctminh@node2.supernodexp.hpc, job name = telemac3, queue = workq
02/14/2018 16:38:35;0100;Server@node2;Req;;Type 1 request received from ctminh@node2.supernodexp.hpc, sock=16
02/14/2018 16:38:35;0100;Server@node2;Req;;Type 3 request received from ctminh@node2.supernodexp.hpc, sock=16
02/14/2018 16:38:35;0100;Server@node2;Req;;Type 5 request received from ctminh@node2.supernodexp.hpc, sock=16
02/14/2018 16:38:35;0100;Server@node2;Job;1297.node2.supernodexp.hpc;enqueuing into workq, state 1 hop 1
02/14/2018 16:38:35;0008;Server@node2;Job;1297.node2.supernodexp.hpc;Job Queued at request of ctminh@node2.supernodexp.hpc, owner = ctminh@node2.supernodexp.hpc, job name = sweep, queue = workq
02/14/2018 16:38:35;0100;Server@node2;Req;;Type 1 request received from ctminh@node2.supernodexp.hpc, sock=16
02/14/2018 16:38:35;0100;Server@node2;Req;;Type 11 request received from Scheduler@node2.supernodexp.hpc, sock=20
02/14/2018 16:38:35;0008;Server@node2;Job;1292.node2.supernodexp.hpc;Job Modified at request of Scheduler@node2.supernodexp.hpc
02/14/2018 16:38:35;0100;Server@node2;Req;;Type 3 request received from ctminh@node2.supernodexp.hpc, sock=16
02/14/2018 16:38:35;0100;Server@node2;Req;;Type 5 request received from ctminh@node2.supernodexp.hpc, sock=16
02/14/2018 16:38:35;0100;Server@node2;Job;1298.node2.supernodexp.hpc;enqueuing into workq, state 1 hop 1
02/14/2018 16:38:35;0008;Server@node2;Job;1298.node2.supernodexp.hpc;Job Queued at request of ctminh@node2.supernodexp.hpc, owner = ctminh@node2.supernodexp.hpc, job name = histogram, queue = workq
02/14/2018 16:38:35;0100;Server@node2;Req;;Type 11 request received from Scheduler@node2.supernodexp.hpc, sock=20
02/14/2018 16:38:35;0008;Server@node2;Job;1293.node2.supernodexp.hpc;Job Modified at request of Scheduler@node2.supernodexp.hpc
02/14/2018 16:38:35;0100;Server@node2;Req;;Type 11 request received from Scheduler@node2.supernodexp.hpc, sock=20
02/14/2018 16:38:35;0008;Server@node2;Job;1294.node2.supernodexp.hpc;Job Modified at request of Scheduler@node2.supernodexp.hpc
02/14/2018 16:38:35;0100;Server@node2;Req;;Type 11 request received from Scheduler@node2.supernodexp.hpc, sock=20
02/14/2018 16:38:35;0008;Server@node2;Job;1295.node2.supernodexp.hpc;Job Modified at request of Scheduler@node2.supernodexp.hpc
02/14/2018 16:38:35;0040;Server@node2;Svr;node2.supernodexp.hpc;Scheduler sent command 1
02/14/2018 16:38:35;0040;Server@node2;Svr;node2.supernodexp.hpc;Scheduler sent command 0
02/14/2018 16:38:35;0100;Server@node2;Req;;Type 21 request received from Scheduler@node2.supernodexp.hpc, sock=20
02/14/2018 16:38:35;0100;Server@node2;Req;;Type 81 request received from Scheduler@node2.supernodexp.hpc, sock=20
02/14/2018 16:38:35;0100;Server@node2;Req;;Type 71 request received from Scheduler@node2.supernodexp.hpc, sock=20
02/14/2018 16:38:35;0100;Server@node2;Req;;Type 58 request received from Scheduler@node2.supernodexp.hpc, sock=20
02/14/2018 16:38:35;0100;Server@node2;Req;;Type 1 request received from ctminh@node2.supernodexp.hpc, sock=16
02/14/2018 16:38:35;0100;Server@node2;Req;;Type 3 request received from ctminh@node2.supernodexp.hpc, sock=16
02/14/2018 16:38:35;0100;Server@node2;Req;;Type 5 request received from ctminh@node2.supernodexp.hpc, sock=16
02/14/2018 16:38:35;0100;Server@node2;Job;1299.node2.supernodexp.hpc;enqueuing into workq, state 1 hop 1
02/14/2018 16:38:35;0008;Server@node2;Job;1299.node2.supernodexp.hpc;Job Queued at request of ctminh@node2.supernodexp.hpc, owner = ctminh@node2.supernodexp.hpc, job name = telemac1, queue = workq
02/14/2018 16:38:35;0100;Server@node2;Req;;Type 1 request received from ctminh@node2.supernodexp.hpc, sock=16
02/14/2018 16:38:35;0100;Server@node2;Hook;_pbs_python_event_set;Restarting Python interpreter to reduce mem usage
02/14/2018 16:38:35;0100;Server@node2;Svr;Server@node2;--> Stopping Python interpreter <--
02/14/2018 16:38:35;0100;Server@node2;Svr;Server@node2;--> Python Interpreter started, compiled with version:'2.7.5' <--
02/14/2018 16:38:35;0100;Server@node2;Svr;Server@node2;sys.modules= {'pbs.v1._svr_types': <module 'pbs.v1._svr_types' from '/opt/pbs/lib/python/altair/pbs/v1/_svr_types.pyo'>, 'copy_reg': <module 'copy_reg' from '/usr/lib64/python2.7/copy_reg.pyo'>, 'pbs.v1._pbs_v1': None, '__main__': <module '__main__' (built-in)>, '__builtin__': <module '__builtin__' (built-in)>, '_pbs_v1.svr_types': <module '_pbs_v1.svr_types' (built-in)>, 'encodings': <module 'encodings' from '/usr/lib64/python2.7/encodings/__init__.pyo'>, 'encodings.encodings': None, 'abc': <module 'abc' from '/usr/lib64/python2.7/abc.pyo'>, 'pbs._pbs_v1': None, 'posixpath': <module 'posixpath' from '/usr/lib64/python2.7/posixpath.pyo'>, '_weakrefset': <module '_weakrefset' from '/usr/lib64/python2.7/_weakrefset.pyo'>, 'pbs.v1': <module 'pbs.v1' from '/opt/pbs/lib/python/altair/pbs/v1/__init__.pyo'>, 'errno': <module 'errno' (built-in)>, 'encodings.codecs': None, 'pbs.v1._export_types': <module 'pbs.v1._export_types' from '/opt/pbs/lib/python/altair/pbs/v1/_export_types.pyo'>, 'pbs.v1.os': None, '_abcoll': <module '_abcoll' from '/usr/lib64/python2.7/_abcoll.pyo'>, 'os.path': <module 'posixpath' from '/usr/lib64/python2.7/posixpath.pyo'>, 'UserDict': <module 'UserDict' from '/usr/lib64/python2.7/UserDict.pyo'>, '_warnings': <module '_warnings' (built-in)>, 'genericpath': <module 'genericpath' from '/usr/lib64/python2.7/genericpath.pyo'>, 'stat': <module 'stat' from '/usr/lib64/python2.7/stat.pyo'>, 'zipimport': <module 'zipimport' (built-in)>, 'encodings.__builtin__': None, 'pbs.pbs': None, 'warnings': <module 'warnings' from '/usr/lib64/python2.7/warnings.pyo'>, '_codecs': <module '_codecs' (built-in)>, 'encodings.ascii': <module 'encodings.ascii' from '/usr/lib64/python2.7/encodings/ascii.pyo'>, 'sys': <module 'sys' (built-in)>, 'pbs.v1._base_types': <module 'pbs.v1._base_types' from '/opt/pbs/lib/python/altair/pbs/v1/_base_types.pyo'>, 'pbs.v1.sys': None, 'codecs': <module 'codecs' from '/usr/lib64/python2.7/codecs.pyo'>, 'types': <module 'types' from '/usr/lib64/python2.7/types.pyo'>, 'pbs': <module 'pbs' from '/opt/pbs/lib/python/altair/pbs/__init__.pyo'>, 'os': <module 'os' from '/usr/lib64/python2.7/os.pyo'>, 'signal': <module 'signal' (built-in)>, 'linecache': <module 'linecache' from '/usr/lib64/python2.7/linecache.pyo'>, '_pbs_v1': <module '_pbs_v1' (built-in)>, 'posix': <module 'posix' (built-in)>, 'encodings.aliases': <module 'encodings.aliases' from '/usr/lib64/python2.7/encodings/aliases.pyo'>, 'exceptions': <module 'exceptions' (built-in)>, 'pbs.v1._exc_types': <module 'pbs.v1._exc_types' from '/opt/pbs/lib/python/altair/pbs/v1/_exc_types.pyo'>, '_weakref': <module '_weakref' (built-in)>}
02/14/2018 16:38:35;0106;Server@node2;Svr;Server@node2;BEGIN setting up all resource attributes 
02/14/2018 16:38:35;0106;Server@node2;Svr;Server@node2;DONE setting up all resource attributes, number set <51>
02/14/2018 16:38:35;0106;Server@node2;Svr;Server@node2;BEGIN setting up all queue attributes 
02/14/2018 16:38:35;0106;Server@node2;Svr;Server@node2;DONE setting up all queue attributes, number set <55>
02/14/2018 16:38:35;0106;Server@node2;Svr;Server@node2;BEGIN setting up all job attributes 
02/14/2018 16:38:35;0106;Server@node2;Svr;Server@node2;DONE setting up all job attributes, number set <94>
02/14/2018 16:38:35;0106;Server@node2;Svr;Server@node2;BEGIN setting up all server attributes 
02/14/2018 16:38:35;0106;Server@node2;Svr;Server@node2;DONE setting up all server attributes, number set <88>
02/14/2018 16:38:35;0106;Server@node2;Svr;Server@node2;BEGIN setting up all reservation attributes 
02/14/2018 16:38:35;0106;Server@node2;Svr;Server@node2;DONE setting up all reservation attributes, number set <43>
02/14/2018 16:38:35;0106;Server@node2;Svr;Server@node2;BEGIN setting up all vnode attributes 
02/14/2018 16:38:35;0106;Server@node2;Svr;Server@node2;DONE setting up all vnode attributes, number set <28>
02/14/2018 16:38:35;0100;Server@node2;Hook;_pbs_python_event_set;Current memory usage: VmSize=319648kB, VmRSS=13084kB
02/14/2018 16:38:35;0100;Server@node2;Req;;Type 20 request received from Scheduler@node2.supernodexp.hpc, sock=20
02/14/2018 16:38:35;0100;Server@node2;Req;;Type 3 request received from ctminh@node2.supernodexp.hpc, sock=16
02/14/2018 16:38:35;0100;Server@node2;Req;;Type 51 request received from Scheduler@node2.supernodexp.hpc, sock=20
02/14/2018 16:38:35;0100;Server@node2;Req;;Type 5 request received from ctminh@node2.supernodexp.hpc, sock=16
02/14/2018 16:38:35;0100;Server@node2;Job;1300.node2.supernodexp.hpc;enqueuing into workq, state 1 hop 1
02/14/2018 16:38:35;0008;Server@node2;Job;1300.node2.supernodexp.hpc;Job Queued at request of ctminh@node2.supernodexp.hpc, owner = ctminh@node2.supernodexp.hpc, job name = nbody, queue = workq
02/14/2018 16:38:35;0100;Server@node2;Req;;Type 1 request received from ctminh@node2.supernodexp.hpc, sock=16
02/14/2018 16:38:35;0100;Server@node2;Req;;Type 3 request received from ctminh@node2.supernodexp.hpc, sock=16
02/14/2018 16:38:35;0100;Server@node2;Req;;Type 5 request received from ctminh@node2.supernodexp.hpc, sock=16
02/14/2018 16:38:35;0100;Server@node2;Job;1301.node2.supernodexp.hpc;enqueuing into workq, state 1 hop 1
02/14/2018 16:38:35;0008;Server@node2;Job;1301.node2.supernodexp.hpc;Job Queued at request of ctminh@node2.supernodexp.hpc, owner = ctminh@node2.supernodexp.hpc, job name = qe_mic_test, queue = workq
02/14/2018 16:38:35;0100;Server@node2;Req;;Type 11 request received from Scheduler@node2.supernodexp.hpc, sock=20
02/14/2018 16:38:35;0008;Server@node2;Job;1296.node2.supernodexp.hpc;Job Modified at request of Scheduler@node2.supernodexp.hpc
02/14/2018 16:38:35;0100;Server@node2;Req;;Type 11 request received from Scheduler@node2.supernodexp.hpc, sock=20
02/14/2018 16:38:35;0008;Server@node2;Job;1297.node2.supernodexp.hpc;Job Modified at request of Scheduler@node2.supernodexp.hpc
02/14/2018 16:38:35;0100;Server@node2;Req;;Type 11 request received from Scheduler@node2.supernodexp.hpc, sock=20
02/14/2018 16:38:35;0008;Server@node2;Job;1298.node2.supernodexp.hpc;Job Modified at request of Scheduler@node2.supernodexp.hpc
02/14/2018 16:38:35;0100;Server@node2;Req;;Type 11 request received from Scheduler@node2.supernodexp.hpc, sock=20
02/14/2018 16:38:35;0008;Server@node2;Job;1299.node2.supernodexp.hpc;Job Modified at request of Scheduler@node2.supernodexp.hpc
02/14/2018 16:38:35;0040;Server@node2;Svr;node2.supernodexp.hpc;Scheduler sent command 1
02/14/2018 16:38:35;0040;Server@node2;Svr;node2.supernodexp.hpc;Scheduler sent command 0
02/14/2018 16:38:35;0100;Server@node2;Req;;Type 21 request received from Scheduler@node2.supernodexp.hpc, sock=20
02/14/2018 16:38:35;0100;Server@node2;Req;;Type 81 request received from Scheduler@node2.supernodexp.hpc, sock=20
02/14/2018 16:38:35;0100;Server@node2;Req;;Type 71 request received from Scheduler@node2.supernodexp.hpc, sock=20
02/14/2018 16:38:35;0100;Server@node2;Req;;Type 58 request received from Scheduler@node2.supernodexp.hpc, sock=20
02/14/2018 16:38:35;0100;Server@node2;Req;;Type 1 request received from ctminh@node2.supernodexp.hpc, sock=16
02/14/2018 16:38:35;0100;Server@node2;Req;;Type 3 request received from ctminh@node2.supernodexp.hpc, sock=16
02/14/2018 16:38:35;0100;Server@node2;Req;;Type 5 request received from ctminh@node2.supernodexp.hpc, sock=16
02/14/2018 16:38:35;0100;Server@node2;Job;1302.node2.supernodexp.hpc;enqueuing into workq, state 1 hop 1
02/14/2018 16:38:35;0008;Server@node2;Job;1302.node2.supernodexp.hpc;Job Queued at request of ctminh@node2.supernodexp.hpc, owner = ctminh@node2.supernodexp.hpc, job name = jacobi, queue = workq
02/14/2018 16:38:35;0100;Server@node2;Req;;Type 1 request received from ctminh@node2.supernodexp.hpc, sock=16
02/14/2018 16:38:35;0100;Server@node2;Req;;Type 3 request received from ctminh@node2.supernodexp.hpc, sock=16
02/14/2018 16:38:35;0100;Server@node2;Req;;Type 5 request received from ctminh@node2.supernodexp.hpc, sock=16
02/14/2018 16:38:35;0100;Server@node2;Job;1303.node2.supernodexp.hpc;enqueuing into workq, state 1 hop 1
02/14/2018 16:38:35;0008;Server@node2;Job;1303.node2.supernodexp.hpc;Job Queued at request of ctminh@node2.supernodexp.hpc, owner = ctminh@node2.supernodexp.hpc, job name = histogram, queue = workq
02/14/2018 16:38:35;0100;Server@node2;Req;;Type 20 request received from Scheduler@node2.supernodexp.hpc, sock=20
02/14/2018 16:38:35;0100;Server@node2;Req;;Type 51 request received from Scheduler@node2.supernodexp.hpc, sock=20
02/14/2018 16:38:35;0100;Server@node2;Req;;Type 1 request received from ctminh@node2.supernodexp.hpc, sock=16
02/14/2018 16:38:35;0100;Server@node2;Req;;Type 3 request received from ctminh@node2.supernodexp.hpc, sock=16
02/14/2018 16:38:35;0100;Server@node2;Req;;Type 5 request received from ctminh@node2.supernodexp.hpc, sock=16
02/14/2018 16:38:35;0100;Server@node2;Job;1304.node2.supernodexp.hpc;enqueuing into workq, state 1 hop 1
02/14/2018 16:38:35;0008;Server@node2;Job;1304.node2.supernodexp.hpc;Job Queued at request of ctminh@node2.supernodexp.hpc, owner = ctminh@node2.supernodexp.hpc, job name = vast1, queue = workq
02/14/2018 16:38:35;0100;Server@node2;Req;;Type 1 request received from ctminh@node2.supernodexp.hpc, sock=16
02/14/2018 16:38:35;0100;Server@node2;Req;;Type 3 request received from ctminh@node2.supernodexp.hpc, sock=16
02/14/2018 16:38:35;0100;Server@node2;Req;;Type 5 request received from ctminh@node2.supernodexp.hpc, sock=16
02/14/2018 16:38:35;0100;Server@node2;Job;1305.node2.supernodexp.hpc;enqueuing into workq, state 1 hop 1
02/14/2018 16:38:35;0008;Server@node2;Job;1305.node2.supernodexp.hpc;Job Queued at request of ctminh@node2.supernodexp.hpc, owner = ctminh@node2.supernodexp.hpc, job name = nbody, queue = workq
02/14/2018 16:38:35;0100;Server@node2;Req;;Type 11 request received from Scheduler@node2.supernodexp.hpc, sock=20
02/14/2018 16:38:35;0008;Server@node2;Job;1300.node2.supernodexp.hpc;Job Modified at request of Scheduler@node2.supernodexp.hpc
02/14/2018 16:38:35;0100;Server@node2;Req;;Type 11 request received from Scheduler@node2.supernodexp.hpc, sock=20
02/14/2018 16:38:35;0008;Server@node2;Job;1301.node2.supernodexp.hpc;Job Modified at request of Scheduler@node2.supernodexp.hpc
02/14/2018 16:38:35;0100;Server@node2;Req;;Type 11 request received from Scheduler@node2.supernodexp.hpc, sock=20
02/14/2018 16:38:35;0008;Server@node2;Job;1302.node2.supernodexp.hpc;Job Modified at request of Scheduler@node2.supernodexp.hpc
02/14/2018 16:38:35;0100;Server@node2;Req;;Type 11 request received from Scheduler@node2.supernodexp.hpc, sock=20
02/14/2018 16:38:35;0008;Server@node2;Job;1303.node2.supernodexp.hpc;Job Modified at request of Scheduler@node2.supernodexp.hpc
02/14/2018 16:38:35;0040;Server@node2;Svr;node2.supernodexp.hpc;Scheduler sent command 1
02/14/2018 16:38:35;0040;Server@node2;Svr;node2.supernodexp.hpc;Scheduler sent command 0
02/14/2018 16:38:35;0100;Server@node2;Req;;Type 21 request received from Scheduler@node2.supernodexp.hpc, sock=20
02/14/2018 16:38:35;0100;Server@node2;Req;;Type 81 request received from Scheduler@node2.supernodexp.hpc, sock=20
02/14/2018 16:38:35;0100;Server@node2;Req;;Type 71 request received from Scheduler@node2.supernodexp.hpc, sock=20
02/14/2018 16:38:35;0100;Server@node2;Req;;Type 58 request received from Scheduler@node2.supernodexp.hpc, sock=20
02/14/2018 16:38:35;0100;Server@node2;Req;;Type 1 request received from ctminh@node2.supernodexp.hpc, sock=16
02/14/2018 16:38:35;0100;Server@node2;Req;;Type 3 request received from ctminh@node2.supernodexp.hpc, sock=16
02/14/2018 16:38:35;0100;Server@node2;Req;;Type 5 request received from ctminh@node2.supernodexp.hpc, sock=16
02/14/2018 16:38:35;0100;Server@node2;Job;1306.node2.supernodexp.hpc;enqueuing into workq, state 1 hop 1
02/14/2018 16:38:35;0008;Server@node2;Job;1306.node2.supernodexp.hpc;Job Queued at request of ctminh@node2.supernodexp.hpc, owner = ctminh@node2.supernodexp.hpc, job name = sweep, queue = workq
02/14/2018 16:38:35;0100;Server@node2;Req;;Type 1 request received from ctminh@node2.supernodexp.hpc, sock=16
02/14/2018 16:38:35;0100;Server@node2;Req;;Type 3 request received from ctminh@node2.supernodexp.hpc, sock=16
02/14/2018 16:38:35;0100;Server@node2;Req;;Type 5 request received from ctminh@node2.supernodexp.hpc, sock=16
02/14/2018 16:38:35;0100;Server@node2;Job;1307.node2.supernodexp.hpc;enqueuing into workq, state 1 hop 1
02/14/2018 16:38:35;0008;Server@node2;Job;1307.node2.supernodexp.hpc;Job Queued at request of ctminh@node2.supernodexp.hpc, owner = ctminh@node2.supernodexp.hpc, job name = jacobi, queue = workq
02/14/2018 16:38:35;0100;Server@node2;Req;;Type 20 request received from Scheduler@node2.supernodexp.hpc, sock=20
02/14/2018 16:38:35;0100;Server@node2;Req;;Type 51 request received from Scheduler@node2.supernodexp.hpc, sock=20
02/14/2018 16:38:35;0100;Server@node2;Req;;Type 1 request received from ctminh@node2.supernodexp.hpc, sock=16
02/14/2018 16:38:35;0100;Server@node2;Req;;Type 3 request received from ctminh@node2.supernodexp.hpc, sock=16
02/14/2018 16:38:35;0100;Server@node2;Req;;Type 5 request received from ctminh@node2.supernodexp.hpc, sock=16
02/14/2018 16:38:35;0100;Server@node2;Job;1308.node2.supernodexp.hpc;enqueuing into workq, state 1 hop 1
02/14/2018 16:38:35;0008;Server@node2;Job;1308.node2.supernodexp.hpc;Job Queued at request of ctminh@node2.supernodexp.hpc, owner = ctminh@node2.supernodexp.hpc, job name = qe_mic_test, queue = workq
02/14/2018 16:38:35;0100;Server@node2;Req;;Type 1 request received from ctminh@node2.supernodexp.hpc, sock=16
02/14/2018 16:38:35;0100;Server@node2;Req;;Type 3 request received from ctminh@node2.supernodexp.hpc, sock=16
02/14/2018 16:38:35;0100;Server@node2;Req;;Type 5 request received from ctminh@node2.supernodexp.hpc, sock=16
02/14/2018 16:38:35;0100;Server@node2;Job;1309.node2.supernodexp.hpc;enqueuing into workq, state 1 hop 1
02/14/2018 16:38:35;0008;Server@node2;Job;1309.node2.supernodexp.hpc;Job Queued at request of ctminh@node2.supernodexp.hpc, owner = ctminh@node2.supernodexp.hpc, job name = jacobi, queue = workq
02/14/2018 16:38:35;0100;Server@node2;Req;;Type 11 request received from Scheduler@node2.supernodexp.hpc, sock=20
02/14/2018 16:38:35;0008;Server@node2;Job;1304.node2.supernodexp.hpc;Job Modified at request of Scheduler@node2.supernodexp.hpc
02/14/2018 16:38:35;0100;Server@node2;Req;;Type 11 request received from Scheduler@node2.supernodexp.hpc, sock=20
02/14/2018 16:38:35;0008;Server@node2;Job;1305.node2.supernodexp.hpc;Job Modified at request of Scheduler@node2.supernodexp.hpc
02/14/2018 16:38:35;0100;Server@node2;Req;;Type 11 request received from Scheduler@node2.supernodexp.hpc, sock=20
02/14/2018 16:38:35;0008;Server@node2;Job;1306.node2.supernodexp.hpc;Job Modified at request of Scheduler@node2.supernodexp.hpc
02/14/2018 16:38:35;0100;Server@node2;Req;;Type 11 request received from Scheduler@node2.supernodexp.hpc, sock=20
02/14/2018 16:38:35;0008;Server@node2;Job;1307.node2.supernodexp.hpc;Job Modified at request of Scheduler@node2.supernodexp.hpc
02/14/2018 16:38:35;0040;Server@node2;Svr;node2.supernodexp.hpc;Scheduler sent command 1
02/14/2018 16:38:35;0040;Server@node2;Svr;node2.supernodexp.hpc;Scheduler sent command 0
02/14/2018 16:38:35;0100;Server@node2;Req;;Type 21 request received from Scheduler@node2.supernodexp.hpc, sock=20
02/14/2018 16:38:35;0100;Server@node2;Req;;Type 81 request received from Scheduler@node2.supernodexp.hpc, sock=20
02/14/2018 16:38:35;0100;Server@node2;Req;;Type 71 request received from Scheduler@node2.supernodexp.hpc, sock=20
02/14/2018 16:38:35;0100;Server@node2;Req;;Type 58 request received from Scheduler@node2.supernodexp.hpc, sock=20
02/14/2018 16:38:35;0100;Server@node2;Req;;Type 1 request received from ctminh@node2.supernodexp.hpc, sock=16
02/14/2018 16:38:35;0100;Server@node2;Req;;Type 3 request received from ctminh@node2.supernodexp.hpc, sock=16
02/14/2018 16:38:35;0100;Server@node2;Req;;Type 5 request received from ctminh@node2.supernodexp.hpc, sock=16
02/14/2018 16:38:35;0100;Server@node2;Job;1310.node2.supernodexp.hpc;enqueuing into workq, state 1 hop 1
02/14/2018 16:38:35;0008;Server@node2;Job;1310.node2.supernodexp.hpc;Job Queued at request of ctminh@node2.supernodexp.hpc, owner = ctminh@node2.supernodexp.hpc, job name = qe_mic_test, queue = workq
02/14/2018 16:38:35;0100;Server@node2;Req;;Type 1 request received from ctminh@node2.supernodexp.hpc, sock=16
02/14/2018 16:38:35;0100;Server@node2;Req;;Type 20 request received from Scheduler@node2.supernodexp.hpc, sock=20
02/14/2018 16:38:35;0100;Server@node2;Req;;Type 3 request received from ctminh@node2.supernodexp.hpc, sock=16
02/14/2018 16:38:35;0100;Server@node2;Req;;Type 51 request received from Scheduler@node2.supernodexp.hpc, sock=20
02/14/2018 16:38:35;0100;Server@node2;Req;;Type 5 request received from ctminh@node2.supernodexp.hpc, sock=16
02/14/2018 16:38:35;0100;Server@node2;Job;1311.node2.supernodexp.hpc;enqueuing into workq, state 1 hop 1
02/14/2018 16:38:35;0008;Server@node2;Job;1311.node2.supernodexp.hpc;Job Queued at request of ctminh@node2.supernodexp.hpc, owner = ctminh@node2.supernodexp.hpc, job name = lu-decomp, queue = workq
02/14/2018 16:38:35;0100;Server@node2;Req;;Type 1 request received from ctminh@node2.supernodexp.hpc, sock=16
02/14/2018 16:38:35;0100;Server@node2;Req;;Type 3 request received from ctminh@node2.supernodexp.hpc, sock=16
02/14/2018 16:38:35;0100;Server@node2;Req;;Type 5 request received from ctminh@node2.supernodexp.hpc, sock=16
02/14/2018 16:38:35;0100;Server@node2;Job;1312.node2.supernodexp.hpc;enqueuing into workq, state 1 hop 1
02/14/2018 16:38:35;0008;Server@node2;Job;1312.node2.supernodexp.hpc;Job Queued at request of ctminh@node2.supernodexp.hpc, owner = ctminh@node2.supernodexp.hpc, job name = telemac3, queue = workq
02/14/2018 16:38:36;0100;Server@node2;Req;;Type 11 request received from Scheduler@node2.supernodexp.hpc, sock=20
02/14/2018 16:38:36;0008;Server@node2;Job;1308.node2.supernodexp.hpc;Job Modified at request of Scheduler@node2.supernodexp.hpc
02/14/2018 16:38:36;0100;Server@node2;Req;;Type 11 request received from Scheduler@node2.supernodexp.hpc, sock=20
02/14/2018 16:38:36;0008;Server@node2;Job;1309.node2.supernodexp.hpc;Job Modified at request of Scheduler@node2.supernodexp.hpc
02/14/2018 16:38:36;0100;Server@node2;Req;;Type 11 request received from Scheduler@node2.supernodexp.hpc, sock=20
02/14/2018 16:38:36;0008;Server@node2;Job;1310.node2.supernodexp.hpc;Job Modified at request of Scheduler@node2.supernodexp.hpc
02/14/2018 16:38:36;0040;Server@node2;Svr;node2.supernodexp.hpc;Scheduler sent command 1
02/14/2018 16:38:36;0040;Server@node2;Svr;node2.supernodexp.hpc;Scheduler sent command 0
02/14/2018 16:38:36;0100;Server@node2;Req;;Type 21 request received from Scheduler@node2.supernodexp.hpc, sock=20
02/14/2018 16:38:36;0100;Server@node2;Req;;Type 81 request received from Scheduler@node2.supernodexp.hpc, sock=20
02/14/2018 16:38:36;0100;Server@node2;Req;;Type 71 request received from Scheduler@node2.supernodexp.hpc, sock=20
02/14/2018 16:38:36;0100;Server@node2;Req;;Type 58 request received from Scheduler@node2.supernodexp.hpc, sock=20
02/14/2018 16:38:36;0100;Server@node2;Req;;Type 1 request received from ctminh@node2.supernodexp.hpc, sock=16
02/14/2018 16:38:36;0100;Server@node2;Req;;Type 3 request received from ctminh@node2.supernodexp.hpc, sock=16
02/14/2018 16:38:36;0100;Server@node2;Req;;Type 5 request received from ctminh@node2.supernodexp.hpc, sock=16
02/14/2018 16:38:36;0100;Server@node2;Job;1313.node2.supernodexp.hpc;enqueuing into workq, state 1 hop 1
02/14/2018 16:38:36;0008;Server@node2;Job;1313.node2.supernodexp.hpc;Job Queued at request of ctminh@node2.supernodexp.hpc, owner = ctminh@node2.supernodexp.hpc, job name = lu-decomp, queue = workq
02/14/2018 16:38:36;0100;Server@node2;Req;;Type 1 request received from ctminh@node2.supernodexp.hpc, sock=16
02/14/2018 16:38:36;0100;Server@node2;Req;;Type 3 request received from ctminh@node2.supernodexp.hpc, sock=16
02/14/2018 16:38:36;0100;Server@node2;Req;;Type 5 request received from ctminh@node2.supernodexp.hpc, sock=16
02/14/2018 16:38:36;0100;Server@node2;Job;1314.node2.supernodexp.hpc;enqueuing into workq, state 1 hop 1
02/14/2018 16:38:36;0008;Server@node2;Job;1314.node2.supernodexp.hpc;Job Queued at request of ctminh@node2.supernodexp.hpc, owner = ctminh@node2.supernodexp.hpc, job name = telemac1, queue = workq
02/14/2018 16:38:36;0100;Server@node2;Req;;Type 20 request received from Scheduler@node2.supernodexp.hpc, sock=20
02/14/2018 16:38:36;0100;Server@node2;Req;;Type 51 request received from Scheduler@node2.supernodexp.hpc, sock=20
02/14/2018 16:38:36;0100;Server@node2;Req;;Type 1 request received from ctminh@node2.supernodexp.hpc, sock=16
02/14/2018 16:38:36;0100;Server@node2;Req;;Type 3 request received from ctminh@node2.supernodexp.hpc, sock=16
02/14/2018 16:38:36;0100;Server@node2;Req;;Type 5 request received from ctminh@node2.supernodexp.hpc, sock=16
02/14/2018 16:38:36;0100;Server@node2;Job;1315.node2.supernodexp.hpc;enqueuing into workq, state 1 hop 1
02/14/2018 16:38:36;0008;Server@node2;Job;1315.node2.supernodexp.hpc;Job Queued at request of ctminh@node2.supernodexp.hpc, owner = ctminh@node2.supernodexp.hpc, job name = telemac1, queue = workq
02/14/2018 16:38:36;0100;Server@node2;Req;;Type 1 request received from ctminh@node2.supernodexp.hpc, sock=16
02/14/2018 16:38:36;0100;Server@node2;Req;;Type 3 request received from ctminh@node2.supernodexp.hpc, sock=16
02/14/2018 16:38:36;0100;Server@node2;Req;;Type 5 request received from ctminh@node2.supernodexp.hpc, sock=16
02/14/2018 16:38:36;0100;Server@node2;Job;1316.node2.supernodexp.hpc;enqueuing into workq, state 1 hop 1
02/14/2018 16:38:36;0008;Server@node2;Job;1316.node2.supernodexp.hpc;Job Queued at request of ctminh@node2.supernodexp.hpc, owner = ctminh@node2.supernodexp.hpc, job name = nbody, queue = workq
02/14/2018 16:38:36;0100;Server@node2;Req;;Type 11 request received from Scheduler@node2.supernodexp.hpc, sock=20
02/14/2018 16:38:36;0008;Server@node2;Job;1311.node2.supernodexp.hpc;Job Modified at request of Scheduler@node2.supernodexp.hpc
02/14/2018 16:38:36;0100;Server@node2;Req;;Type 11 request received from Scheduler@node2.supernodexp.hpc, sock=20
02/14/2018 16:38:36;0008;Server@node2;Job;1312.node2.supernodexp.hpc;Job Modified at request of Scheduler@node2.supernodexp.hpc
02/14/2018 16:38:36;0100;Server@node2;Req;;Type 11 request received from Scheduler@node2.supernodexp.hpc, sock=20
02/14/2018 16:38:36;0008;Server@node2;Job;1313.node2.supernodexp.hpc;Job Modified at request of Scheduler@node2.supernodexp.hpc
02/14/2018 16:38:36;0100;Server@node2;Req;;Type 11 request received from Scheduler@node2.supernodexp.hpc, sock=20
02/14/2018 16:38:36;0008;Server@node2;Job;1314.node2.supernodexp.hpc;Job Modified at request of Scheduler@node2.supernodexp.hpc
02/14/2018 16:38:36;0040;Server@node2;Svr;node2.supernodexp.hpc;Scheduler sent command 1
02/14/2018 16:38:36;0040;Server@node2;Svr;node2.supernodexp.hpc;Scheduler sent command 0
02/14/2018 16:38:36;0100;Server@node2;Req;;Type 21 request received from Scheduler@node2.supernodexp.hpc, sock=20
02/14/2018 16:38:36;0100;Server@node2;Req;;Type 81 request received from Scheduler@node2.supernodexp.hpc, sock=20
02/14/2018 16:38:36;0100;Server@node2;Req;;Type 71 request received from Scheduler@node2.supernodexp.hpc, sock=20
02/14/2018 16:38:36;0100;Server@node2;Req;;Type 58 request received from Scheduler@node2.supernodexp.hpc, sock=20
02/14/2018 16:38:36;0100;Server@node2;Req;;Type 1 request received from ctminh@node2.supernodexp.hpc, sock=16
02/14/2018 16:38:36;0100;Server@node2;Req;;Type 3 request received from ctminh@node2.supernodexp.hpc, sock=16
02/14/2018 16:38:36;0100;Server@node2;Req;;Type 5 request received from ctminh@node2.supernodexp.hpc, sock=16
02/14/2018 16:38:36;0100;Server@node2;Job;1317.node2.supernodexp.hpc;enqueuing into workq, state 1 hop 1
02/14/2018 16:38:36;0008;Server@node2;Job;1317.node2.supernodexp.hpc;Job Queued at request of ctminh@node2.supernodexp.hpc, owner = ctminh@node2.supernodexp.hpc, job name = histogram, queue = workq
02/14/2018 16:38:36;0100;Server@node2;Req;;Type 1 request received from ctminh@node2.supernodexp.hpc, sock=16
02/14/2018 16:38:36;0100;Server@node2;Req;;Type 3 request received from ctminh@node2.supernodexp.hpc, sock=16
02/14/2018 16:38:36;0100;Server@node2;Req;;Type 5 request received from ctminh@node2.supernodexp.hpc, sock=16
02/14/2018 16:38:36;0100;Server@node2;Job;1318.node2.supernodexp.hpc;enqueuing into workq, state 1 hop 1
02/14/2018 16:38:36;0008;Server@node2;Job;1318.node2.supernodexp.hpc;Job Queued at request of ctminh@node2.supernodexp.hpc, owner = ctminh@node2.supernodexp.hpc, job name = vast1, queue = workq
02/14/2018 16:38:36;0100;Server@node2;Req;;Type 20 request received from Scheduler@node2.supernodexp.hpc, sock=20
02/14/2018 16:38:36;0100;Server@node2;Req;;Type 51 request received from Scheduler@node2.supernodexp.hpc, sock=20
02/14/2018 16:38:36;0100;Server@node2;Req;;Type 1 request received from ctminh@node2.supernodexp.hpc, sock=16
02/14/2018 16:38:36;0100;Server@node2;Req;;Type 3 request received from ctminh@node2.supernodexp.hpc, sock=16
02/14/2018 16:38:36;0100;Server@node2;Req;;Type 5 request received from ctminh@node2.supernodexp.hpc, sock=16
02/14/2018 16:38:36;0100;Server@node2;Job;1319.node2.supernodexp.hpc;enqueuing into workq, state 1 hop 1
02/14/2018 16:38:36;0008;Server@node2;Job;1319.node2.supernodexp.hpc;Job Queued at request of ctminh@node2.supernodexp.hpc, owner = ctminh@node2.supernodexp.hpc, job name = thread-affinity, queue = workq
02/14/2018 16:38:36;0100;Server@node2;Req;;Type 1 request received from ctminh@node2.supernodexp.hpc, sock=16
02/14/2018 16:38:36;0100;Server@node2;Req;;Type 3 request received from ctminh@node2.supernodexp.hpc, sock=16
02/14/2018 16:38:36;0100;Server@node2;Req;;Type 5 request received from ctminh@node2.supernodexp.hpc, sock=16
02/14/2018 16:38:36;0100;Server@node2;Job;1320.node2.supernodexp.hpc;enqueuing into workq, state 1 hop 1
02/14/2018 16:38:36;0008;Server@node2;Job;1320.node2.supernodexp.hpc;Job Queued at request of ctminh@node2.supernodexp.hpc, owner = ctminh@node2.supernodexp.hpc, job name = telemac3, queue = workq
02/14/2018 16:38:36;0100;Server@node2;Req;;Type 11 request received from Scheduler@node2.supernodexp.hpc, sock=20
02/14/2018 16:38:36;0008;Server@node2;Job;1315.node2.supernodexp.hpc;Job Modified at request of Scheduler@node2.supernodexp.hpc
02/14/2018 16:38:36;0100;Server@node2;Req;;Type 11 request received from Scheduler@node2.supernodexp.hpc, sock=20
02/14/2018 16:38:36;0008;Server@node2;Job;1316.node2.supernodexp.hpc;Job Modified at request of Scheduler@node2.supernodexp.hpc
02/14/2018 16:38:36;0100;Server@node2;Req;;Type 11 request received from Scheduler@node2.supernodexp.hpc, sock=20
02/14/2018 16:38:36;0008;Server@node2;Job;1317.node2.supernodexp.hpc;Job Modified at request of Scheduler@node2.supernodexp.hpc
02/14/2018 16:38:36;0100;Server@node2;Req;;Type 11 request received from Scheduler@node2.supernodexp.hpc, sock=20
02/14/2018 16:38:36;0008;Server@node2;Job;1318.node2.supernodexp.hpc;Job Modified at request of Scheduler@node2.supernodexp.hpc
02/14/2018 16:38:36;0040;Server@node2;Svr;node2.supernodexp.hpc;Scheduler sent command 1
02/14/2018 16:38:36;0040;Server@node2;Svr;node2.supernodexp.hpc;Scheduler sent command 0
02/14/2018 16:38:36;0100;Server@node2;Req;;Type 21 request received from Scheduler@node2.supernodexp.hpc, sock=20
02/14/2018 16:38:36;0100;Server@node2;Req;;Type 81 request received from Scheduler@node2.supernodexp.hpc, sock=20
02/14/2018 16:38:36;0100;Server@node2;Req;;Type 71 request received from Scheduler@node2.supernodexp.hpc, sock=20
02/14/2018 16:38:36;0100;Server@node2;Req;;Type 58 request received from Scheduler@node2.supernodexp.hpc, sock=20
02/14/2018 16:38:36;0100;Server@node2;Req;;Type 20 request received from Scheduler@node2.supernodexp.hpc, sock=20
02/14/2018 16:38:36;0100;Server@node2;Req;;Type 51 request received from Scheduler@node2.supernodexp.hpc, sock=20
02/14/2018 16:38:36;0100;Server@node2;Req;;Type 11 request received from Scheduler@node2.supernodexp.hpc, sock=20
02/14/2018 16:38:36;0008;Server@node2;Job;1319.node2.supernodexp.hpc;Job Modified at request of Scheduler@node2.supernodexp.hpc
02/14/2018 16:38:36;0100;Server@node2;Req;;Type 11 request received from Scheduler@node2.supernodexp.hpc, sock=20
02/14/2018 16:38:36;0008;Server@node2;Job;1320.node2.supernodexp.hpc;Job Modified at request of Scheduler@node2.supernodexp.hpc
02/14/2018 16:39:16;0080;Server@node2;Job;1207.node2.supernodexp.hpc;Obit received momhop:1 serverhop:1 state:4 substate:42
02/14/2018 16:39:18;0010;Server@node2;Job;1207.node2.supernodexp.hpc;Exit_status=0 resources_used.cpupercent=1405 resources_used.cput=01:01:03 resources_used.mem=1642172kb resources_used.ncpus=24 resources_used.vmem=15000240kb resources_used.walltime=00:02:41
02/14/2018 16:39:18;0100;Server@node2;Job;1207.node2.supernodexp.hpc;dequeuing from workq, state 5
02/14/2018 16:39:18;0040;Server@node2;Svr;node2.supernodexp.hpc;Scheduler sent command 2
02/14/2018 16:39:18;0040;Server@node2;Svr;node2.supernodexp.hpc;Scheduler sent command 0
02/14/2018 16:39:18;0100;Server@node2;Req;;Type 21 request received from Scheduler@node2.supernodexp.hpc, sock=20
02/14/2018 16:39:18;0100;Server@node2;Req;;Type 81 request received from Scheduler@node2.supernodexp.hpc, sock=20
02/14/2018 16:39:18;0100;Server@node2;Req;;Type 71 request received from Scheduler@node2.supernodexp.hpc, sock=20
02/14/2018 16:39:18;0100;Server@node2;Req;;Type 58 request received from Scheduler@node2.supernodexp.hpc, sock=20
02/14/2018 16:39:18;0100;Server@node2;Req;;Type 20 request received from Scheduler@node2.supernodexp.hpc, sock=20
02/14/2018 16:39:18;0100;Server@node2;Req;;Type 51 request received from Scheduler@node2.supernodexp.hpc, sock=20
02/14/2018 16:39:18;0100;Server@node2;Req;;Type 11 request received from Scheduler@node2.supernodexp.hpc, sock=20
02/14/2018 16:39:18;0008;Server@node2;Job;1209.node2.supernodexp.hpc;Job Modified at request of Scheduler@node2.supernodexp.hpc
02/14/2018 16:39:18;0100;Server@node2;Req;;Type 11 request received from Scheduler@node2.supernodexp.hpc, sock=20
02/14/2018 16:39:18;0008;Server@node2;Job;1211.node2.supernodexp.hpc;Job Modified at request of Scheduler@node2.supernodexp.hpc
02/14/2018 16:39:18;0100;Server@node2;Req;;Type 11 request received from Scheduler@node2.supernodexp.hpc, sock=20
02/14/2018 16:39:18;0008;Server@node2;Job;1212.node2.supernodexp.hpc;Job Modified at request of Scheduler@node2.supernodexp.hpc
02/14/2018 16:39:18;0100;Server@node2;Req;;Type 11 request received from Scheduler@node2.supernodexp.hpc, sock=20
02/14/2018 16:39:18;0008;Server@node2;Job;1213.node2.supernodexp.hpc;Job Modified at request of Scheduler@node2.supernodexp.hpc
02/14/2018 16:39:18;0100;Server@node2;Req;;Type 23 request received from Scheduler@node2.supernodexp.hpc, sock=20
02/14/2018 16:39:18;0008;Server@node2;Job;1214.node2.supernodexp.hpc;Job Run at request of Scheduler@node2.supernodexp.hpc on exec_vnode (node14:ncpus=24:mem=2097152kb)
02/14/2018 16:39:18;0001;Server@node2;Svr;Server@node2;Success (0) in req_runjob2, return value of svr_startjob is 0
02/14/2018 16:39:27;0100;Server@node2;Req;;Type 1 request received from ctminh@node2.supernodexp.hpc, sock=16
02/14/2018 16:39:27;0100;Server@node2;Req;;Type 3 request received from ctminh@node2.supernodexp.hpc, sock=16
02/14/2018 16:39:27;0100;Server@node2;Req;;Type 5 request received from ctminh@node2.supernodexp.hpc, sock=16
02/14/2018 16:39:27;0100;Server@node2;Job;1321.node2.supernodexp.hpc;enqueuing into workq, state 1 hop 1
02/14/2018 16:39:27;0008;Server@node2;Job;1321.node2.supernodexp.hpc;Job Queued at request of ctminh@node2.supernodexp.hpc, owner = ctminh@node2.supernodexp.hpc, job name = vectorization, queue = workq
02/14/2018 16:39:27;0040;Server@node2;Svr;node2.supernodexp.hpc;Scheduler sent command 1
02/14/2018 16:39:27;0040;Server@node2;Svr;node2.supernodexp.hpc;Scheduler sent command 0
02/14/2018 16:39:27;0100;Server@node2;Req;;Type 21 request received from Scheduler@node2.supernodexp.hpc, sock=20
02/14/2018 16:39:27;0100;Server@node2;Req;;Type 81 request received from Scheduler@node2.supernodexp.hpc, sock=20
02/14/2018 16:39:27;0100;Server@node2;Req;;Type 71 request received from Scheduler@node2.supernodexp.hpc, sock=20
02/14/2018 16:39:27;0100;Server@node2;Req;;Type 58 request received from Scheduler@node2.supernodexp.hpc, sock=20
02/14/2018 16:39:27;0100;Server@node2;Req;;Type 1 request received from ctminh@node2.supernodexp.hpc, sock=16
02/14/2018 16:39:27;0100;Server@node2;Req;;Type 3 request received from ctminh@node2.supernodexp.hpc, sock=16
02/14/2018 16:39:27;0100;Server@node2;Req;;Type 5 request received from ctminh@node2.supernodexp.hpc, sock=16
02/14/2018 16:39:27;0100;Server@node2;Job;1322.node2.supernodexp.hpc;enqueuing into workq, state 1 hop 1
02/14/2018 16:39:27;0008;Server@node2;Job;1322.node2.supernodexp.hpc;Job Queued at request of ctminh@node2.supernodexp.hpc, owner = ctminh@node2.supernodexp.hpc, job name = vectorization, queue = workq
02/14/2018 16:39:27;0100;Server@node2;Req;;Type 1 request received from ctminh@node2.supernodexp.hpc, sock=16
02/14/2018 16:39:27;0100;Server@node2;Req;;Type 20 request received from Scheduler@node2.supernodexp.hpc, sock=20
02/14/2018 16:39:27;0100;Server@node2;Req;;Type 3 request received from ctminh@node2.supernodexp.hpc, sock=16
02/14/2018 16:39:27;0100;Server@node2;Req;;Type 51 request received from Scheduler@node2.supernodexp.hpc, sock=20
02/14/2018 16:39:27;0100;Server@node2;Req;;Type 5 request received from ctminh@node2.supernodexp.hpc, sock=16
02/14/2018 16:39:27;0100;Server@node2;Job;1323.node2.supernodexp.hpc;enqueuing into workq, state 1 hop 1
02/14/2018 16:39:27;0008;Server@node2;Job;1323.node2.supernodexp.hpc;Job Queued at request of ctminh@node2.supernodexp.hpc, owner = ctminh@node2.supernodexp.hpc, job name = thread-affinity, queue = workq
02/14/2018 16:39:27;0100;Server@node2;Req;;Type 1 request received from ctminh@node2.supernodexp.hpc, sock=16
02/14/2018 16:39:27;0100;Server@node2;Req;;Type 3 request received from ctminh@node2.supernodexp.hpc, sock=16
02/14/2018 16:39:27;0100;Server@node2;Req;;Type 5 request received from ctminh@node2.supernodexp.hpc, sock=16
02/14/2018 16:39:27;0100;Server@node2;Job;1324.node2.supernodexp.hpc;enqueuing into workq, state 1 hop 1
02/14/2018 16:39:27;0008;Server@node2;Job;1324.node2.supernodexp.hpc;Job Queued at request of ctminh@node2.supernodexp.hpc, owner = ctminh@node2.supernodexp.hpc, job name = telemac3, queue = workq
02/14/2018 16:39:27;0100;Server@node2;Req;;Type 1 request received from ctminh@node2.supernodexp.hpc, sock=16
02/14/2018 16:39:27;0100;Server@node2;Req;;Type 11 request received from Scheduler@node2.supernodexp.hpc, sock=20
02/14/2018 16:39:27;0008;Server@node2;Job;1209.node2.supernodexp.hpc;Job Modified at request of Scheduler@node2.supernodexp.hpc
02/14/2018 16:39:27;0100;Server@node2;Req;;Type 3 request received from ctminh@node2.supernodexp.hpc, sock=16
02/14/2018 16:39:27;0100;Server@node2;Req;;Type 11 request received from Scheduler@node2.supernodexp.hpc, sock=20
02/14/2018 16:39:27;0008;Server@node2;Job;1211.node2.supernodexp.hpc;Job Modified at request of Scheduler@node2.supernodexp.hpc
02/14/2018 16:39:27;0100;Server@node2;Req;;Type 5 request received from ctminh@node2.supernodexp.hpc, sock=16
02/14/2018 16:39:27;0100;Server@node2;Job;1325.node2.supernodexp.hpc;enqueuing into workq, state 1 hop 1
02/14/2018 16:39:27;0008;Server@node2;Job;1325.node2.supernodexp.hpc;Job Queued at request of ctminh@node2.supernodexp.hpc, owner = ctminh@node2.supernodexp.hpc, job name = vectorization, queue = workq
02/14/2018 16:39:27;0100;Server@node2;Req;;Type 11 request received from Scheduler@node2.supernodexp.hpc, sock=20
02/14/2018 16:39:27;0008;Server@node2;Job;1212.node2.supernodexp.hpc;Job Modified at request of Scheduler@node2.supernodexp.hpc
02/14/2018 16:39:27;0100;Server@node2;Req;;Type 11 request received from Scheduler@node2.supernodexp.hpc, sock=20
02/14/2018 16:39:27;0008;Server@node2;Job;1213.node2.supernodexp.hpc;Job Modified at request of Scheduler@node2.supernodexp.hpc
02/14/2018 16:39:27;0100;Server@node2;Req;;Type 11 request received from Scheduler@node2.supernodexp.hpc, sock=20
02/14/2018 16:39:27;0008;Server@node2;Job;1321.node2.supernodexp.hpc;Job Modified at request of Scheduler@node2.supernodexp.hpc
02/14/2018 16:39:27;0100;Server@node2;Req;;Type 11 request received from Scheduler@node2.supernodexp.hpc, sock=20
02/14/2018 16:39:27;0008;Server@node2;Job;1322.node2.supernodexp.hpc;Job Modified at request of Scheduler@node2.supernodexp.hpc
02/14/2018 16:39:27;0040;Server@node2;Svr;node2.supernodexp.hpc;Scheduler sent command 1
02/14/2018 16:39:27;0040;Server@node2;Svr;node2.supernodexp.hpc;Scheduler sent command 0
02/14/2018 16:39:27;0100;Server@node2;Req;;Type 21 request received from Scheduler@node2.supernodexp.hpc, sock=20
02/14/2018 16:39:27;0100;Server@node2;Req;;Type 81 request received from Scheduler@node2.supernodexp.hpc, sock=20
02/14/2018 16:39:27;0100;Server@node2;Req;;Type 71 request received from Scheduler@node2.supernodexp.hpc, sock=20
02/14/2018 16:39:27;0100;Server@node2;Req;;Type 58 request received from Scheduler@node2.supernodexp.hpc, sock=20
02/14/2018 16:39:27;0100;Server@node2;Req;;Type 1 request received from ctminh@node2.supernodexp.hpc, sock=16
02/14/2018 16:39:27;0100;Server@node2;Req;;Type 3 request received from ctminh@node2.supernodexp.hpc, sock=16
02/14/2018 16:39:27;0100;Server@node2;Req;;Type 5 request received from ctminh@node2.supernodexp.hpc, sock=16
02/14/2018 16:39:27;0100;Server@node2;Job;1326.node2.supernodexp.hpc;enqueuing into workq, state 1 hop 1
02/14/2018 16:39:27;0008;Server@node2;Job;1326.node2.supernodexp.hpc;Job Queued at request of ctminh@node2.supernodexp.hpc, owner = ctminh@node2.supernodexp.hpc, job name = nbody, queue = workq
02/14/2018 16:39:27;0100;Server@node2;Req;;Type 1 request received from ctminh@node2.supernodexp.hpc, sock=16
02/14/2018 16:39:27;0100;Server@node2;Req;;Type 3 request received from ctminh@node2.supernodexp.hpc, sock=16
02/14/2018 16:39:27;0100;Server@node2;Req;;Type 5 request received from ctminh@node2.supernodexp.hpc, sock=16
02/14/2018 16:39:27;0100;Server@node2;Job;1327.node2.supernodexp.hpc;enqueuing into workq, state 1 hop 1
02/14/2018 16:39:27;0008;Server@node2;Job;1327.node2.supernodexp.hpc;Job Queued at request of ctminh@node2.supernodexp.hpc, owner = ctminh@node2.supernodexp.hpc, job name = nbody, queue = workq
02/14/2018 16:39:27;0100;Server@node2;Req;;Type 20 request received from Scheduler@node2.supernodexp.hpc, sock=20
02/14/2018 16:39:27;0100;Server@node2;Req;;Type 51 request received from Scheduler@node2.supernodexp.hpc, sock=20
02/14/2018 16:39:27;0100;Server@node2;Req;;Type 1 request received from ctminh@node2.supernodexp.hpc, sock=16
02/14/2018 16:39:27;0100;Server@node2;Req;;Type 3 request received from ctminh@node2.supernodexp.hpc, sock=16
02/14/2018 16:39:27;0100;Server@node2;Req;;Type 5 request received from ctminh@node2.supernodexp.hpc, sock=16
02/14/2018 16:39:27;0100;Server@node2;Job;1328.node2.supernodexp.hpc;enqueuing into workq, state 1 hop 1
02/14/2018 16:39:27;0008;Server@node2;Job;1328.node2.supernodexp.hpc;Job Queued at request of ctminh@node2.supernodexp.hpc, owner = ctminh@node2.supernodexp.hpc, job name = matrix-x-vector, queue = workq
02/14/2018 16:39:27;0100;Server@node2;Req;;Type 1 request received from ctminh@node2.supernodexp.hpc, sock=16
02/14/2018 16:39:27;0100;Server@node2;Req;;Type 3 request received from ctminh@node2.supernodexp.hpc, sock=16
02/14/2018 16:39:27;0100;Server@node2;Req;;Type 5 request received from ctminh@node2.supernodexp.hpc, sock=16
02/14/2018 16:39:27;0100;Server@node2;Job;1329.node2.supernodexp.hpc;enqueuing into workq, state 1 hop 1
02/14/2018 16:39:27;0008;Server@node2;Job;1329.node2.supernodexp.hpc;Job Queued at request of ctminh@node2.supernodexp.hpc, owner = ctminh@node2.supernodexp.hpc, job name = qe_mic_test, queue = workq
02/14/2018 16:39:27;0100;Server@node2;Req;;Type 11 request received from Scheduler@node2.supernodexp.hpc, sock=20
02/14/2018 16:39:27;0008;Server@node2;Job;1323.node2.supernodexp.hpc;Job Modified at request of Scheduler@node2.supernodexp.hpc
02/14/2018 16:39:27;0100;Server@node2;Req;;Type 11 request received from Scheduler@node2.supernodexp.hpc, sock=20
02/14/2018 16:39:27;0008;Server@node2;Job;1324.node2.supernodexp.hpc;Job Modified at request of Scheduler@node2.supernodexp.hpc
02/14/2018 16:39:27;0100;Server@node2;Req;;Type 11 request received from Scheduler@node2.supernodexp.hpc, sock=20
02/14/2018 16:39:27;0008;Server@node2;Job;1325.node2.supernodexp.hpc;Job Modified at request of Scheduler@node2.supernodexp.hpc
02/14/2018 16:39:27;0100;Server@node2;Req;;Type 11 request received from Scheduler@node2.supernodexp.hpc, sock=20
02/14/2018 16:39:27;0008;Server@node2;Job;1326.node2.supernodexp.hpc;Job Modified at request of Scheduler@node2.supernodexp.hpc
02/14/2018 16:39:27;0100;Server@node2;Req;;Type 11 request received from Scheduler@node2.supernodexp.hpc, sock=20
02/14/2018 16:39:27;0008;Server@node2;Job;1327.node2.supernodexp.hpc;Job Modified at request of Scheduler@node2.supernodexp.hpc
02/14/2018 16:39:27;0040;Server@node2;Svr;node2.supernodexp.hpc;Scheduler sent command 1
02/14/2018 16:39:27;0040;Server@node2;Svr;node2.supernodexp.hpc;Scheduler sent command 0
02/14/2018 16:39:27;0100;Server@node2;Req;;Type 21 request received from Scheduler@node2.supernodexp.hpc, sock=20
02/14/2018 16:39:27;0100;Server@node2;Req;;Type 81 request received from Scheduler@node2.supernodexp.hpc, sock=20
02/14/2018 16:39:27;0100;Server@node2;Req;;Type 71 request received from Scheduler@node2.supernodexp.hpc, sock=20
02/14/2018 16:39:27;0100;Server@node2;Req;;Type 58 request received from Scheduler@node2.supernodexp.hpc, sock=20
02/14/2018 16:39:27;0100;Server@node2;Req;;Type 1 request received from ctminh@node2.supernodexp.hpc, sock=16
02/14/2018 16:39:27;0100;Server@node2;Req;;Type 3 request received from ctminh@node2.supernodexp.hpc, sock=16
02/14/2018 16:39:27;0100;Server@node2;Req;;Type 5 request received from ctminh@node2.supernodexp.hpc, sock=16
02/14/2018 16:39:27;0100;Server@node2;Job;1330.node2.supernodexp.hpc;enqueuing into workq, state 1 hop 1
02/14/2018 16:39:27;0008;Server@node2;Job;1330.node2.supernodexp.hpc;Job Queued at request of ctminh@node2.supernodexp.hpc, owner = ctminh@node2.supernodexp.hpc, job name = telemac1, queue = workq
02/14/2018 16:39:27;0100;Server@node2;Req;;Type 1 request received from ctminh@node2.supernodexp.hpc, sock=16
02/14/2018 16:39:27;0100;Server@node2;Req;;Type 20 request received from Scheduler@node2.supernodexp.hpc, sock=20
02/14/2018 16:39:27;0100;Server@node2;Req;;Type 3 request received from ctminh@node2.supernodexp.hpc, sock=16
02/14/2018 16:39:27;0100;Server@node2;Req;;Type 51 request received from Scheduler@node2.supernodexp.hpc, sock=20
02/14/2018 16:39:27;0100;Server@node2;Req;;Type 5 request received from ctminh@node2.supernodexp.hpc, sock=16
02/14/2018 16:39:27;0100;Server@node2;Job;1331.node2.supernodexp.hpc;enqueuing into workq, state 1 hop 1
02/14/2018 16:39:27;0008;Server@node2;Job;1331.node2.supernodexp.hpc;Job Queued at request of ctminh@node2.supernodexp.hpc, owner = ctminh@node2.supernodexp.hpc, job name = sweep, queue = workq
02/14/2018 16:39:27;0100;Server@node2;Req;;Type 1 request received from ctminh@node2.supernodexp.hpc, sock=16
02/14/2018 16:39:27;0100;Server@node2;Req;;Type 3 request received from ctminh@node2.supernodexp.hpc, sock=16
02/14/2018 16:39:27;0100;Server@node2;Req;;Type 5 request received from ctminh@node2.supernodexp.hpc, sock=16
02/14/2018 16:39:27;0100;Server@node2;Job;1332.node2.supernodexp.hpc;enqueuing into workq, state 1 hop 1
02/14/2018 16:39:27;0008;Server@node2;Job;1332.node2.supernodexp.hpc;Job Queued at request of ctminh@node2.supernodexp.hpc, owner = ctminh@node2.supernodexp.hpc, job name = vectorization, queue = workq
02/14/2018 16:39:27;0100;Server@node2;Req;;Type 11 request received from Scheduler@node2.supernodexp.hpc, sock=20
02/14/2018 16:39:27;0008;Server@node2;Job;1328.node2.supernodexp.hpc;Job Modified at request of Scheduler@node2.supernodexp.hpc
02/14/2018 16:39:27;0100;Server@node2;Req;;Type 11 request received from Scheduler@node2.supernodexp.hpc, sock=20
02/14/2018 16:39:27;0008;Server@node2;Job;1329.node2.supernodexp.hpc;Job Modified at request of Scheduler@node2.supernodexp.hpc
02/14/2018 16:39:27;0100;Server@node2;Req;;Type 11 request received from Scheduler@node2.supernodexp.hpc, sock=20
02/14/2018 16:39:27;0008;Server@node2;Job;1330.node2.supernodexp.hpc;Job Modified at request of Scheduler@node2.supernodexp.hpc
02/14/2018 16:39:27;0040;Server@node2;Svr;node2.supernodexp.hpc;Scheduler sent command 1
02/14/2018 16:39:27;0040;Server@node2;Svr;node2.supernodexp.hpc;Scheduler sent command 0
02/14/2018 16:39:27;0100;Server@node2;Req;;Type 21 request received from Scheduler@node2.supernodexp.hpc, sock=20
02/14/2018 16:39:27;0100;Server@node2;Req;;Type 81 request received from Scheduler@node2.supernodexp.hpc, sock=20
02/14/2018 16:39:27;0100;Server@node2;Req;;Type 71 request received from Scheduler@node2.supernodexp.hpc, sock=20
02/14/2018 16:39:27;0100;Server@node2;Req;;Type 58 request received from Scheduler@node2.supernodexp.hpc, sock=20
02/14/2018 16:39:27;0100;Server@node2;Req;;Type 1 request received from ctminh@node2.supernodexp.hpc, sock=16
02/14/2018 16:39:27;0100;Server@node2;Req;;Type 3 request received from ctminh@node2.supernodexp.hpc, sock=16
02/14/2018 16:39:27;0100;Server@node2;Req;;Type 5 request received from ctminh@node2.supernodexp.hpc, sock=16
02/14/2018 16:39:27;0100;Server@node2;Job;1333.node2.supernodexp.hpc;enqueuing into workq, state 1 hop 1
02/14/2018 16:39:27;0008;Server@node2;Job;1333.node2.supernodexp.hpc;Job Queued at request of ctminh@node2.supernodexp.hpc, owner = ctminh@node2.supernodexp.hpc, job name = vast1, queue = workq
02/14/2018 16:39:27;0100;Server@node2;Req;;Type 1 request received from ctminh@node2.supernodexp.hpc, sock=16
02/14/2018 16:39:27;0100;Server@node2;Req;;Type 3 request received from ctminh@node2.supernodexp.hpc, sock=16
02/14/2018 16:39:27;0100;Server@node2;Req;;Type 5 request received from ctminh@node2.supernodexp.hpc, sock=16
02/14/2018 16:39:27;0100;Server@node2;Job;1334.node2.supernodexp.hpc;enqueuing into workq, state 1 hop 1
02/14/2018 16:39:27;0008;Server@node2;Job;1334.node2.supernodexp.hpc;Job Queued at request of ctminh@node2.supernodexp.hpc, owner = ctminh@node2.supernodexp.hpc, job name = sweep, queue = workq
02/14/2018 16:39:27;0100;Server@node2;Req;;Type 20 request received from Scheduler@node2.supernodexp.hpc, sock=20
02/14/2018 16:39:27;0100;Server@node2;Req;;Type 51 request received from Scheduler@node2.supernodexp.hpc, sock=20
02/14/2018 16:39:27;0100;Server@node2;Req;;Type 1 request received from ctminh@node2.supernodexp.hpc, sock=16
02/14/2018 16:39:27;0100;Server@node2;Req;;Type 3 request received from ctminh@node2.supernodexp.hpc, sock=16
02/14/2018 16:39:27;0100;Server@node2;Req;;Type 5 request received from ctminh@node2.supernodexp.hpc, sock=16
02/14/2018 16:39:27;0100;Server@node2;Job;1335.node2.supernodexp.hpc;enqueuing into workq, state 1 hop 1
02/14/2018 16:39:27;0008;Server@node2;Job;1335.node2.supernodexp.hpc;Job Queued at request of ctminh@node2.supernodexp.hpc, owner = ctminh@node2.supernodexp.hpc, job name = vectorization, queue = workq
02/14/2018 16:39:27;0100;Server@node2;Req;;Type 1 request received from ctminh@node2.supernodexp.hpc, sock=16
02/14/2018 16:39:27;0100;Server@node2;Req;;Type 3 request received from ctminh@node2.supernodexp.hpc, sock=16
02/14/2018 16:39:27;0100;Server@node2;Req;;Type 5 request received from ctminh@node2.supernodexp.hpc, sock=16
02/14/2018 16:39:27;0100;Server@node2;Job;1336.node2.supernodexp.hpc;enqueuing into workq, state 1 hop 1
02/14/2018 16:39:27;0008;Server@node2;Job;1336.node2.supernodexp.hpc;Job Queued at request of ctminh@node2.supernodexp.hpc, owner = ctminh@node2.supernodexp.hpc, job name = vectorization, queue = workq
02/14/2018 16:39:27;0100;Server@node2;Req;;Type 11 request received from Scheduler@node2.supernodexp.hpc, sock=20
02/14/2018 16:39:27;0008;Server@node2;Job;1331.node2.supernodexp.hpc;Job Modified at request of Scheduler@node2.supernodexp.hpc
02/14/2018 16:39:27;0100;Server@node2;Req;;Type 11 request received from Scheduler@node2.supernodexp.hpc, sock=20
02/14/2018 16:39:27;0008;Server@node2;Job;1332.node2.supernodexp.hpc;Job Modified at request of Scheduler@node2.supernodexp.hpc
02/14/2018 16:39:27;0100;Server@node2;Req;;Type 11 request received from Scheduler@node2.supernodexp.hpc, sock=20
02/14/2018 16:39:27;0008;Server@node2;Job;1333.node2.supernodexp.hpc;Job Modified at request of Scheduler@node2.supernodexp.hpc
02/14/2018 16:39:27;0100;Server@node2;Req;;Type 11 request received from Scheduler@node2.supernodexp.hpc, sock=20
02/14/2018 16:39:27;0008;Server@node2;Job;1334.node2.supernodexp.hpc;Job Modified at request of Scheduler@node2.supernodexp.hpc
02/14/2018 16:39:27;0040;Server@node2;Svr;node2.supernodexp.hpc;Scheduler sent command 1
02/14/2018 16:39:27;0040;Server@node2;Svr;node2.supernodexp.hpc;Scheduler sent command 0
02/14/2018 16:39:27;0100;Server@node2;Req;;Type 21 request received from Scheduler@node2.supernodexp.hpc, sock=20
02/14/2018 16:39:27;0100;Server@node2;Req;;Type 81 request received from Scheduler@node2.supernodexp.hpc, sock=20
02/14/2018 16:39:27;0100;Server@node2;Req;;Type 71 request received from Scheduler@node2.supernodexp.hpc, sock=20
02/14/2018 16:39:27;0100;Server@node2;Req;;Type 58 request received from Scheduler@node2.supernodexp.hpc, sock=20
02/14/2018 16:39:27;0100;Server@node2;Req;;Type 1 request received from ctminh@node2.supernodexp.hpc, sock=16
02/14/2018 16:39:27;0100;Server@node2;Req;;Type 3 request received from ctminh@node2.supernodexp.hpc, sock=16
02/14/2018 16:39:27;0100;Server@node2;Req;;Type 5 request received from ctminh@node2.supernodexp.hpc, sock=16
02/14/2018 16:39:27;0100;Server@node2;Job;1337.node2.supernodexp.hpc;enqueuing into workq, state 1 hop 1
02/14/2018 16:39:27;0008;Server@node2;Job;1337.node2.supernodexp.hpc;Job Queued at request of ctminh@node2.supernodexp.hpc, owner = ctminh@node2.supernodexp.hpc, job name = telemac2, queue = workq
02/14/2018 16:39:27;0100;Server@node2;Req;;Type 1 request received from ctminh@node2.supernodexp.hpc, sock=16
02/14/2018 16:39:27;0100;Server@node2;Req;;Type 3 request received from ctminh@node2.supernodexp.hpc, sock=16
02/14/2018 16:39:27;0100;Server@node2;Req;;Type 5 request received from ctminh@node2.supernodexp.hpc, sock=16
02/14/2018 16:39:27;0100;Server@node2;Job;1338.node2.supernodexp.hpc;enqueuing into workq, state 1 hop 1
02/14/2018 16:39:27;0008;Server@node2;Job;1338.node2.supernodexp.hpc;Job Queued at request of ctminh@node2.supernodexp.hpc, owner = ctminh@node2.supernodexp.hpc, job name = telemac3, queue = workq
02/14/2018 16:39:27;0100;Server@node2;Req;;Type 20 request received from Scheduler@node2.supernodexp.hpc, sock=20
02/14/2018 16:39:27;0100;Server@node2;Req;;Type 51 request received from Scheduler@node2.supernodexp.hpc, sock=20
02/14/2018 16:39:27;0100;Server@node2;Req;;Type 1 request received from ctminh@node2.supernodexp.hpc, sock=16
02/14/2018 16:39:27;0100;Server@node2;Req;;Type 3 request received from ctminh@node2.supernodexp.hpc, sock=16
02/14/2018 16:39:27;0100;Server@node2;Req;;Type 5 request received from ctminh@node2.supernodexp.hpc, sock=16
02/14/2018 16:39:27;0100;Server@node2;Job;1339.node2.supernodexp.hpc;enqueuing into workq, state 1 hop 1
02/14/2018 16:39:27;0008;Server@node2;Job;1339.node2.supernodexp.hpc;Job Queued at request of ctminh@node2.supernodexp.hpc, owner = ctminh@node2.supernodexp.hpc, job name = qe_mic_test, queue = workq
02/14/2018 16:39:27;0100;Server@node2;Req;;Type 1 request received from ctminh@node2.supernodexp.hpc, sock=16
02/14/2018 16:39:27;0100;Server@node2;Req;;Type 3 request received from ctminh@node2.supernodexp.hpc, sock=16
02/14/2018 16:39:27;0100;Server@node2;Req;;Type 5 request received from ctminh@node2.supernodexp.hpc, sock=16
02/14/2018 16:39:27;0100;Server@node2;Job;1340.node2.supernodexp.hpc;enqueuing into workq, state 1 hop 1
02/14/2018 16:39:27;0008;Server@node2;Job;1340.node2.supernodexp.hpc;Job Queued at request of ctminh@node2.supernodexp.hpc, owner = ctminh@node2.supernodexp.hpc, job name = matrix-x-vector, queue = workq
02/14/2018 16:39:27;0100;Server@node2;Req;;Type 11 request received from Scheduler@node2.supernodexp.hpc, sock=20
02/14/2018 16:39:27;0008;Server@node2;Job;1335.node2.supernodexp.hpc;Job Modified at request of Scheduler@node2.supernodexp.hpc
02/14/2018 16:39:27;0100;Server@node2;Req;;Type 11 request received from Scheduler@node2.supernodexp.hpc, sock=20
02/14/2018 16:39:27;0008;Server@node2;Job;1336.node2.supernodexp.hpc;Job Modified at request of Scheduler@node2.supernodexp.hpc
02/14/2018 16:39:27;0100;Server@node2;Req;;Type 11 request received from Scheduler@node2.supernodexp.hpc, sock=20
02/14/2018 16:39:27;0008;Server@node2;Job;1337.node2.supernodexp.hpc;Job Modified at request of Scheduler@node2.supernodexp.hpc
02/14/2018 16:39:27;0100;Server@node2;Req;;Type 11 request received from Scheduler@node2.supernodexp.hpc, sock=20
02/14/2018 16:39:27;0008;Server@node2;Job;1338.node2.supernodexp.hpc;Job Modified at request of Scheduler@node2.supernodexp.hpc
02/14/2018 16:39:27;0040;Server@node2;Svr;node2.supernodexp.hpc;Scheduler sent command 1
02/14/2018 16:39:27;0040;Server@node2;Svr;node2.supernodexp.hpc;Scheduler sent command 0
02/14/2018 16:39:27;0100;Server@node2;Req;;Type 21 request received from Scheduler@node2.supernodexp.hpc, sock=20
02/14/2018 16:39:27;0100;Server@node2;Req;;Type 81 request received from Scheduler@node2.supernodexp.hpc, sock=20
02/14/2018 16:39:27;0100;Server@node2;Req;;Type 71 request received from Scheduler@node2.supernodexp.hpc, sock=20
02/14/2018 16:39:27;0100;Server@node2;Req;;Type 58 request received from Scheduler@node2.supernodexp.hpc, sock=20
02/14/2018 16:39:27;0100;Server@node2;Req;;Type 1 request received from ctminh@node2.supernodexp.hpc, sock=16
02/14/2018 16:39:27;0100;Server@node2;Req;;Type 3 request received from ctminh@node2.supernodexp.hpc, sock=16
02/14/2018 16:39:27;0100;Server@node2;Req;;Type 5 request received from ctminh@node2.supernodexp.hpc, sock=16
02/14/2018 16:39:27;0100;Server@node2;Job;1341.node2.supernodexp.hpc;enqueuing into workq, state 1 hop 1
02/14/2018 16:39:27;0008;Server@node2;Job;1341.node2.supernodexp.hpc;Job Queued at request of ctminh@node2.supernodexp.hpc, owner = ctminh@node2.supernodexp.hpc, job name = matrix-x-vector, queue = workq
02/14/2018 16:39:27;0100;Server@node2;Req;;Type 1 request received from ctminh@node2.supernodexp.hpc, sock=16
02/14/2018 16:39:27;0100;Server@node2;Req;;Type 3 request received from ctminh@node2.supernodexp.hpc, sock=16
02/14/2018 16:39:27;0100;Server@node2;Req;;Type 20 request received from Scheduler@node2.supernodexp.hpc, sock=20
02/14/2018 16:39:27;0100;Server@node2;Req;;Type 5 request received from ctminh@node2.supernodexp.hpc, sock=16
02/14/2018 16:39:27;0100;Server@node2;Job;1342.node2.supernodexp.hpc;enqueuing into workq, state 1 hop 1
02/14/2018 16:39:27;0008;Server@node2;Job;1342.node2.supernodexp.hpc;Job Queued at request of ctminh@node2.supernodexp.hpc, owner = ctminh@node2.supernodexp.hpc, job name = sweep, queue = workq
02/14/2018 16:39:27;0100;Server@node2;Req;;Type 51 request received from Scheduler@node2.supernodexp.hpc, sock=20
02/14/2018 16:39:27;0100;Server@node2;Req;;Type 1 request received from ctminh@node2.supernodexp.hpc, sock=16
02/14/2018 16:39:27;0100;Server@node2;Req;;Type 3 request received from ctminh@node2.supernodexp.hpc, sock=16
02/14/2018 16:39:27;0100;Server@node2;Req;;Type 5 request received from ctminh@node2.supernodexp.hpc, sock=16
02/14/2018 16:39:27;0100;Server@node2;Job;1343.node2.supernodexp.hpc;enqueuing into workq, state 1 hop 1
02/14/2018 16:39:27;0008;Server@node2;Job;1343.node2.supernodexp.hpc;Job Queued at request of ctminh@node2.supernodexp.hpc, owner = ctminh@node2.supernodexp.hpc, job name = telemac3, queue = workq
02/14/2018 16:39:27;0100;Server@node2;Req;;Type 1 request received from ctminh@node2.supernodexp.hpc, sock=16
02/14/2018 16:39:27;0100;Server@node2;Req;;Type 3 request received from ctminh@node2.supernodexp.hpc, sock=16
02/14/2018 16:39:27;0100;Server@node2;Req;;Type 5 request received from ctminh@node2.supernodexp.hpc, sock=16
02/14/2018 16:39:27;0100;Server@node2;Job;1344.node2.supernodexp.hpc;enqueuing into workq, state 1 hop 1
02/14/2018 16:39:27;0008;Server@node2;Job;1344.node2.supernodexp.hpc;Job Queued at request of ctminh@node2.supernodexp.hpc, owner = ctminh@node2.supernodexp.hpc, job name = matrix-x-vector, queue = workq
02/14/2018 16:39:27;0100;Server@node2;Req;;Type 11 request received from Scheduler@node2.supernodexp.hpc, sock=20
02/14/2018 16:39:27;0008;Server@node2;Job;1339.node2.supernodexp.hpc;Job Modified at request of Scheduler@node2.supernodexp.hpc
02/14/2018 16:39:27;0100;Server@node2;Req;;Type 11 request received from Scheduler@node2.supernodexp.hpc, sock=20
02/14/2018 16:39:27;0008;Server@node2;Job;1340.node2.supernodexp.hpc;Job Modified at request of Scheduler@node2.supernodexp.hpc
02/14/2018 16:39:27;0100;Server@node2;Req;;Type 11 request received from Scheduler@node2.supernodexp.hpc, sock=20
02/14/2018 16:39:27;0008;Server@node2;Job;1341.node2.supernodexp.hpc;Job Modified at request of Scheduler@node2.supernodexp.hpc
02/14/2018 16:39:27;0100;Server@node2;Req;;Type 11 request received from Scheduler@node2.supernodexp.hpc, sock=20
02/14/2018 16:39:27;0008;Server@node2;Job;1342.node2.supernodexp.hpc;Job Modified at request of Scheduler@node2.supernodexp.hpc
02/14/2018 16:39:27;0040;Server@node2;Svr;node2.supernodexp.hpc;Scheduler sent command 1
02/14/2018 16:39:27;0040;Server@node2;Svr;node2.supernodexp.hpc;Scheduler sent command 0
02/14/2018 16:39:27;0100;Server@node2;Req;;Type 21 request received from Scheduler@node2.supernodexp.hpc, sock=20
02/14/2018 16:39:27;0100;Server@node2;Req;;Type 81 request received from Scheduler@node2.supernodexp.hpc, sock=20
02/14/2018 16:39:27;0100;Server@node2;Req;;Type 71 request received from Scheduler@node2.supernodexp.hpc, sock=20
02/14/2018 16:39:27;0100;Server@node2;Req;;Type 58 request received from Scheduler@node2.supernodexp.hpc, sock=20
02/14/2018 16:39:27;0100;Server@node2;Req;;Type 1 request received from ctminh@node2.supernodexp.hpc, sock=16
02/14/2018 16:39:27;0100;Server@node2;Req;;Type 3 request received from ctminh@node2.supernodexp.hpc, sock=16
02/14/2018 16:39:27;0100;Server@node2;Req;;Type 5 request received from ctminh@node2.supernodexp.hpc, sock=16
02/14/2018 16:39:27;0100;Server@node2;Job;1345.node2.supernodexp.hpc;enqueuing into workq, state 1 hop 1
02/14/2018 16:39:27;0008;Server@node2;Job;1345.node2.supernodexp.hpc;Job Queued at request of ctminh@node2.supernodexp.hpc, owner = ctminh@node2.supernodexp.hpc, job name = telemac2, queue = workq
02/14/2018 16:39:27;0100;Server@node2;Req;;Type 1 request received from ctminh@node2.supernodexp.hpc, sock=16
02/14/2018 16:39:27;0100;Server@node2;Req;;Type 3 request received from ctminh@node2.supernodexp.hpc, sock=16
02/14/2018 16:39:27;0100;Server@node2;Req;;Type 5 request received from ctminh@node2.supernodexp.hpc, sock=16
02/14/2018 16:39:27;0100;Server@node2;Job;1346.node2.supernodexp.hpc;enqueuing into workq, state 1 hop 1
02/14/2018 16:39:27;0008;Server@node2;Job;1346.node2.supernodexp.hpc;Job Queued at request of ctminh@node2.supernodexp.hpc, owner = ctminh@node2.supernodexp.hpc, job name = vectorization, queue = workq
02/14/2018 16:39:27;0100;Server@node2;Req;;Type 20 request received from Scheduler@node2.supernodexp.hpc, sock=20
02/14/2018 16:39:27;0100;Server@node2;Req;;Type 51 request received from Scheduler@node2.supernodexp.hpc, sock=20
02/14/2018 16:39:27;0100;Server@node2;Req;;Type 1 request received from ctminh@node2.supernodexp.hpc, sock=16
02/14/2018 16:39:27;0100;Server@node2;Req;;Type 3 request received from ctminh@node2.supernodexp.hpc, sock=16
02/14/2018 16:39:27;0100;Server@node2;Req;;Type 5 request received from ctminh@node2.supernodexp.hpc, sock=16
02/14/2018 16:39:27;0100;Server@node2;Job;1347.node2.supernodexp.hpc;enqueuing into workq, state 1 hop 1
02/14/2018 16:39:27;0008;Server@node2;Job;1347.node2.supernodexp.hpc;Job Queued at request of ctminh@node2.supernodexp.hpc, owner = ctminh@node2.supernodexp.hpc, job name = jacobi, queue = workq
02/14/2018 16:39:27;0100;Server@node2;Req;;Type 1 request received from ctminh@node2.supernodexp.hpc, sock=16
02/14/2018 16:39:27;0100;Server@node2;Req;;Type 3 request received from ctminh@node2.supernodexp.hpc, sock=16
02/14/2018 16:39:27;0100;Server@node2;Req;;Type 5 request received from ctminh@node2.supernodexp.hpc, sock=16
02/14/2018 16:39:27;0100;Server@node2;Job;1348.node2.supernodexp.hpc;enqueuing into workq, state 1 hop 1
02/14/2018 16:39:27;0008;Server@node2;Job;1348.node2.supernodexp.hpc;Job Queued at request of ctminh@node2.supernodexp.hpc, owner = ctminh@node2.supernodexp.hpc, job name = matrix-x-vector, queue = workq
02/14/2018 16:39:27;0100;Server@node2;Req;;Type 11 request received from Scheduler@node2.supernodexp.hpc, sock=20
02/14/2018 16:39:27;0008;Server@node2;Job;1343.node2.supernodexp.hpc;Job Modified at request of Scheduler@node2.supernodexp.hpc
02/14/2018 16:39:27;0100;Server@node2;Req;;Type 11 request received from Scheduler@node2.supernodexp.hpc, sock=20
02/14/2018 16:39:27;0008;Server@node2;Job;1344.node2.supernodexp.hpc;Job Modified at request of Scheduler@node2.supernodexp.hpc
02/14/2018 16:39:27;0100;Server@node2;Req;;Type 11 request received from Scheduler@node2.supernodexp.hpc, sock=20
02/14/2018 16:39:27;0008;Server@node2;Job;1345.node2.supernodexp.hpc;Job Modified at request of Scheduler@node2.supernodexp.hpc
02/14/2018 16:39:27;0100;Server@node2;Req;;Type 11 request received from Scheduler@node2.supernodexp.hpc, sock=20
02/14/2018 16:39:27;0008;Server@node2;Job;1346.node2.supernodexp.hpc;Job Modified at request of Scheduler@node2.supernodexp.hpc
02/14/2018 16:39:27;0040;Server@node2;Svr;node2.supernodexp.hpc;Scheduler sent command 1
02/14/2018 16:39:27;0040;Server@node2;Svr;node2.supernodexp.hpc;Scheduler sent command 0
02/14/2018 16:39:27;0100;Server@node2;Req;;Type 21 request received from Scheduler@node2.supernodexp.hpc, sock=20
02/14/2018 16:39:27;0100;Server@node2;Req;;Type 81 request received from Scheduler@node2.supernodexp.hpc, sock=20
02/14/2018 16:39:27;0100;Server@node2;Req;;Type 71 request received from Scheduler@node2.supernodexp.hpc, sock=20
02/14/2018 16:39:27;0100;Server@node2;Req;;Type 58 request received from Scheduler@node2.supernodexp.hpc, sock=20
02/14/2018 16:39:27;0100;Server@node2;Req;;Type 1 request received from ctminh@node2.supernodexp.hpc, sock=16
02/14/2018 16:39:27;0100;Server@node2;Req;;Type 3 request received from ctminh@node2.supernodexp.hpc, sock=16
02/14/2018 16:39:27;0100;Server@node2;Req;;Type 5 request received from ctminh@node2.supernodexp.hpc, sock=16
02/14/2018 16:39:27;0100;Server@node2;Job;1349.node2.supernodexp.hpc;enqueuing into workq, state 1 hop 1
02/14/2018 16:39:27;0008;Server@node2;Job;1349.node2.supernodexp.hpc;Job Queued at request of ctminh@node2.supernodexp.hpc, owner = ctminh@node2.supernodexp.hpc, job name = sweep, queue = workq
02/14/2018 16:39:27;0100;Server@node2;Req;;Type 1 request received from ctminh@node2.supernodexp.hpc, sock=16
02/14/2018 16:39:27;0100;Server@node2;Req;;Type 20 request received from Scheduler@node2.supernodexp.hpc, sock=20
02/14/2018 16:39:27;0100;Server@node2;Req;;Type 3 request received from ctminh@node2.supernodexp.hpc, sock=16
02/14/2018 16:39:27;0100;Server@node2;Req;;Type 51 request received from Scheduler@node2.supernodexp.hpc, sock=20
02/14/2018 16:39:27;0100;Server@node2;Req;;Type 5 request received from ctminh@node2.supernodexp.hpc, sock=16
02/14/2018 16:39:27;0100;Server@node2;Job;1350.node2.supernodexp.hpc;enqueuing into workq, state 1 hop 1
02/14/2018 16:39:27;0008;Server@node2;Job;1350.node2.supernodexp.hpc;Job Queued at request of ctminh@node2.supernodexp.hpc, owner = ctminh@node2.supernodexp.hpc, job name = thread-affinity, queue = workq
02/14/2018 16:39:28;0100;Server@node2;Req;;Type 11 request received from Scheduler@node2.supernodexp.hpc, sock=20
02/14/2018 16:39:28;0008;Server@node2;Job;1347.node2.supernodexp.hpc;Job Modified at request of Scheduler@node2.supernodexp.hpc
02/14/2018 16:39:28;0100;Server@node2;Req;;Type 11 request received from Scheduler@node2.supernodexp.hpc, sock=20
02/14/2018 16:39:28;0008;Server@node2;Job;1348.node2.supernodexp.hpc;Job Modified at request of Scheduler@node2.supernodexp.hpc
02/14/2018 16:39:28;0100;Server@node2;Req;;Type 11 request received from Scheduler@node2.supernodexp.hpc, sock=20
02/14/2018 16:39:28;0008;Server@node2;Job;1349.node2.supernodexp.hpc;Job Modified at request of Scheduler@node2.supernodexp.hpc
02/14/2018 16:39:28;0040;Server@node2;Svr;node2.supernodexp.hpc;Scheduler sent command 1
02/14/2018 16:39:28;0040;Server@node2;Svr;node2.supernodexp.hpc;Scheduler sent command 0
02/14/2018 16:39:28;0100;Server@node2;Req;;Type 21 request received from Scheduler@node2.supernodexp.hpc, sock=20
02/14/2018 16:39:28;0100;Server@node2;Req;;Type 81 request received from Scheduler@node2.supernodexp.hpc, sock=20
02/14/2018 16:39:28;0100;Server@node2;Req;;Type 71 request received from Scheduler@node2.supernodexp.hpc, sock=20
02/14/2018 16:39:28;0100;Server@node2;Req;;Type 58 request received from Scheduler@node2.supernodexp.hpc, sock=20
02/14/2018 16:39:28;0100;Server@node2;Req;;Type 20 request received from Scheduler@node2.supernodexp.hpc, sock=20
02/14/2018 16:39:28;0100;Server@node2;Req;;Type 51 request received from Scheduler@node2.supernodexp.hpc, sock=20
02/14/2018 16:39:28;0100;Server@node2;Req;;Type 11 request received from Scheduler@node2.supernodexp.hpc, sock=20
02/14/2018 16:39:28;0008;Server@node2;Job;1350.node2.supernodexp.hpc;Job Modified at request of Scheduler@node2.supernodexp.hpc
02/14/2018 16:39:43;0080;Server@node2;Job;1214.node2.supernodexp.hpc;Obit received momhop:1 serverhop:1 state:4 substate:42
02/14/2018 16:39:44;0010;Server@node2;Job;1214.node2.supernodexp.hpc;Exit_status=0 resources_used.cpupercent=2307 resources_used.cput=00:09:35 resources_used.mem=1535172kb resources_used.ncpus=24 resources_used.vmem=3509012kb resources_used.walltime=00:00:24
02/14/2018 16:39:44;0100;Server@node2;Job;1214.node2.supernodexp.hpc;dequeuing from workq, state 5
02/14/2018 16:39:44;0040;Server@node2;Svr;node2.supernodexp.hpc;Scheduler sent command 2
02/14/2018 16:39:44;0040;Server@node2;Svr;node2.supernodexp.hpc;Scheduler sent command 0
02/14/2018 16:39:44;0100;Server@node2;Req;;Type 21 request received from Scheduler@node2.supernodexp.hpc, sock=20
02/14/2018 16:39:44;0100;Server@node2;Req;;Type 81 request received from Scheduler@node2.supernodexp.hpc, sock=20
02/14/2018 16:39:44;0100;Server@node2;Req;;Type 71 request received from Scheduler@node2.supernodexp.hpc, sock=20
02/14/2018 16:39:44;0100;Server@node2;Req;;Type 58 request received from Scheduler@node2.supernodexp.hpc, sock=20
02/14/2018 16:39:44;0100;Server@node2;Req;;Type 20 request received from Scheduler@node2.supernodexp.hpc, sock=20
02/14/2018 16:39:44;0100;Server@node2;Req;;Type 51 request received from Scheduler@node2.supernodexp.hpc, sock=20
02/14/2018 16:39:44;0100;Server@node2;Req;;Type 11 request received from Scheduler@node2.supernodexp.hpc, sock=20
02/14/2018 16:39:44;0008;Server@node2;Job;1209.node2.supernodexp.hpc;Job Modified at request of Scheduler@node2.supernodexp.hpc
02/14/2018 16:39:44;0100;Server@node2;Req;;Type 11 request received from Scheduler@node2.supernodexp.hpc, sock=20
02/14/2018 16:39:44;0008;Server@node2;Job;1211.node2.supernodexp.hpc;Job Modified at request of Scheduler@node2.supernodexp.hpc
02/14/2018 16:39:44;0100;Server@node2;Req;;Type 11 request received from Scheduler@node2.supernodexp.hpc, sock=20
02/14/2018 16:39:44;0008;Server@node2;Job;1212.node2.supernodexp.hpc;Job Modified at request of Scheduler@node2.supernodexp.hpc
02/14/2018 16:39:44;0100;Server@node2;Req;;Type 11 request received from Scheduler@node2.supernodexp.hpc, sock=20
02/14/2018 16:39:44;0008;Server@node2;Job;1213.node2.supernodexp.hpc;Job Modified at request of Scheduler@node2.supernodexp.hpc
02/14/2018 16:39:44;0100;Server@node2;Req;;Type 23 request received from Scheduler@node2.supernodexp.hpc, sock=20
02/14/2018 16:39:44;0008;Server@node2;Job;1215.node2.supernodexp.hpc;Job Run at request of Scheduler@node2.supernodexp.hpc on exec_vnode (node14:ncpus=16:mem=2097152kb)
02/14/2018 16:39:44;0001;Server@node2;Svr;Server@node2;Success (0) in req_runjob2, return value of svr_startjob is 0
02/14/2018 16:39:44;0100;Server@node2;Req;;Type 11 request received from Scheduler@node2.supernodexp.hpc, sock=20
02/14/2018 16:39:44;0008;Server@node2;Job;1216.node2.supernodexp.hpc;Job Modified at request of Scheduler@node2.supernodexp.hpc
02/14/2018 16:39:44;0100;Server@node2;Req;;Type 11 request received from Scheduler@node2.supernodexp.hpc, sock=20
02/14/2018 16:39:44;0008;Server@node2;Job;1218.node2.supernodexp.hpc;Job Modified at request of Scheduler@node2.supernodexp.hpc
02/14/2018 16:39:44;0100;Server@node2;Req;;Type 11 request received from Scheduler@node2.supernodexp.hpc, sock=20
02/14/2018 16:39:44;0008;Server@node2;Job;1219.node2.supernodexp.hpc;Job Modified at request of Scheduler@node2.supernodexp.hpc
02/14/2018 16:39:44;0100;Server@node2;Req;;Type 11 request received from Scheduler@node2.supernodexp.hpc, sock=20
02/14/2018 16:39:44;0008;Server@node2;Job;1220.node2.supernodexp.hpc;Job Modified at request of Scheduler@node2.supernodexp.hpc
02/14/2018 16:39:44;0100;Server@node2;Req;;Type 11 request received from Scheduler@node2.supernodexp.hpc, sock=20
02/14/2018 16:39:44;0008;Server@node2;Job;1221.node2.supernodexp.hpc;Job Modified at request of Scheduler@node2.supernodexp.hpc
02/14/2018 16:39:44;0100;Server@node2;Req;;Type 11 request received from Scheduler@node2.supernodexp.hpc, sock=20
02/14/2018 16:39:44;0008;Server@node2;Job;1222.node2.supernodexp.hpc;Job Modified at request of Scheduler@node2.supernodexp.hpc
02/14/2018 16:39:44;0100;Server@node2;Req;;Type 11 request received from Scheduler@node2.supernodexp.hpc, sock=20
02/14/2018 16:39:44;0008;Server@node2;Job;1224.node2.supernodexp.hpc;Job Modified at request of Scheduler@node2.supernodexp.hpc
02/14/2018 16:39:44;0100;Server@node2;Req;;Type 11 request received from Scheduler@node2.supernodexp.hpc, sock=20
02/14/2018 16:39:44;0008;Server@node2;Job;1225.node2.supernodexp.hpc;Job Modified at request of Scheduler@node2.supernodexp.hpc
02/14/2018 16:39:44;0100;Server@node2;Req;;Type 11 request received from Scheduler@node2.supernodexp.hpc, sock=20
02/14/2018 16:39:44;0008;Server@node2;Job;1226.node2.supernodexp.hpc;Job Modified at request of Scheduler@node2.supernodexp.hpc
02/14/2018 16:39:44;0100;Server@node2;Req;;Type 11 request received from Scheduler@node2.supernodexp.hpc, sock=20
02/14/2018 16:39:44;0008;Server@node2;Job;1227.node2.supernodexp.hpc;Job Modified at request of Scheduler@node2.supernodexp.hpc
02/14/2018 16:39:44;0100;Server@node2;Req;;Type 11 request received from Scheduler@node2.supernodexp.hpc, sock=20
02/14/2018 16:39:44;0008;Server@node2;Job;1228.node2.supernodexp.hpc;Job Modified at request of Scheduler@node2.supernodexp.hpc
02/14/2018 16:39:44;0100;Server@node2;Req;;Type 11 request received from Scheduler@node2.supernodexp.hpc, sock=20
02/14/2018 16:39:44;0008;Server@node2;Job;1229.node2.supernodexp.hpc;Job Modified at request of Scheduler@node2.supernodexp.hpc
02/14/2018 16:39:44;0100;Server@node2;Req;;Type 11 request received from Scheduler@node2.supernodexp.hpc, sock=20
02/14/2018 16:39:44;0008;Server@node2;Job;1231.node2.supernodexp.hpc;Job Modified at request of Scheduler@node2.supernodexp.hpc
02/14/2018 16:39:44;0100;Server@node2;Req;;Type 11 request received from Scheduler@node2.supernodexp.hpc, sock=20
02/14/2018 16:39:44;0008;Server@node2;Job;1233.node2.supernodexp.hpc;Job Modified at request of Scheduler@node2.supernodexp.hpc
02/14/2018 16:39:44;0100;Server@node2;Req;;Type 11 request received from Scheduler@node2.supernodexp.hpc, sock=20
02/14/2018 16:39:44;0008;Server@node2;Job;1234.node2.supernodexp.hpc;Job Modified at request of Scheduler@node2.supernodexp.hpc
02/14/2018 16:39:44;0100;Server@node2;Req;;Type 11 request received from Scheduler@node2.supernodexp.hpc, sock=20
02/14/2018 16:39:44;0008;Server@node2;Job;1235.node2.supernodexp.hpc;Job Modified at request of Scheduler@node2.supernodexp.hpc
02/14/2018 16:39:44;0100;Server@node2;Req;;Type 11 request received from Scheduler@node2.supernodexp.hpc, sock=20
02/14/2018 16:39:44;0008;Server@node2;Job;1236.node2.supernodexp.hpc;Job Modified at request of Scheduler@node2.supernodexp.hpc
02/14/2018 16:39:44;0100;Server@node2;Req;;Type 11 request received from Scheduler@node2.supernodexp.hpc, sock=20
02/14/2018 16:39:44;0008;Server@node2;Job;1238.node2.supernodexp.hpc;Job Modified at request of Scheduler@node2.supernodexp.hpc
02/14/2018 16:39:44;0100;Server@node2;Req;;Type 11 request received from Scheduler@node2.supernodexp.hpc, sock=20
02/14/2018 16:39:44;0008;Server@node2;Job;1239.node2.supernodexp.hpc;Job Modified at request of Scheduler@node2.supernodexp.hpc
02/14/2018 16:39:44;0100;Server@node2;Req;;Type 11 request received from Scheduler@node2.supernodexp.hpc, sock=20
02/14/2018 16:39:44;0008;Server@node2;Job;1240.node2.supernodexp.hpc;Job Modified at request of Scheduler@node2.supernodexp.hpc
02/14/2018 16:39:44;0100;Server@node2;Req;;Type 11 request received from Scheduler@node2.supernodexp.hpc, sock=20
02/14/2018 16:39:44;0008;Server@node2;Job;1241.node2.supernodexp.hpc;Job Modified at request of Scheduler@node2.supernodexp.hpc
02/14/2018 16:39:44;0100;Server@node2;Req;;Type 11 request received from Scheduler@node2.supernodexp.hpc, sock=20
02/14/2018 16:39:44;0008;Server@node2;Job;1242.node2.supernodexp.hpc;Job Modified at request of Scheduler@node2.supernodexp.hpc
02/14/2018 16:39:44;0100;Server@node2;Req;;Type 11 request received from Scheduler@node2.supernodexp.hpc, sock=20
02/14/2018 16:39:44;0008;Server@node2;Job;1243.node2.supernodexp.hpc;Job Modified at request of Scheduler@node2.supernodexp.hpc
02/14/2018 16:39:44;0100;Server@node2;Req;;Type 11 request received from Scheduler@node2.supernodexp.hpc, sock=20
02/14/2018 16:39:44;0008;Server@node2;Job;1245.node2.supernodexp.hpc;Job Modified at request of Scheduler@node2.supernodexp.hpc
02/14/2018 16:39:44;0100;Server@node2;Req;;Type 11 request received from Scheduler@node2.supernodexp.hpc, sock=20
02/14/2018 16:39:44;0008;Server@node2;Job;1246.node2.supernodexp.hpc;Job Modified at request of Scheduler@node2.supernodexp.hpc
02/14/2018 16:39:44;0100;Server@node2;Req;;Type 23 request received from Scheduler@node2.supernodexp.hpc, sock=20
02/14/2018 16:39:44;0008;Server@node2;Job;1247.node2.supernodexp.hpc;Job Run at request of Scheduler@node2.supernodexp.hpc on exec_vnode (node14:ncpus=8:mem=3145728kb)
02/14/2018 16:39:44;0001;Server@node2;Svr;Server@node2;Success (0) in req_runjob2, return value of svr_startjob is 0
02/14/2018 16:39:46;0080;Server@node2;Job;1247.node2.supernodexp.hpc;Obit received momhop:1 serverhop:1 state:4 substate:42
02/14/2018 16:39:47;0010;Server@node2;Job;1247.node2.supernodexp.hpc;Exit_status=0 resources_used.cpupercent=498 resources_used.cput=00:00:10 resources_used.mem=0kb resources_used.ncpus=8 resources_used.vmem=0kb resources_used.walltime=00:00:02
02/14/2018 16:39:47;0100;Server@node2;Job;1247.node2.supernodexp.hpc;dequeuing from workq, state 5
02/14/2018 16:39:47;0040;Server@node2;Svr;node2.supernodexp.hpc;Scheduler sent command 2
02/14/2018 16:39:47;0040;Server@node2;Svr;node2.supernodexp.hpc;Scheduler sent command 0
02/14/2018 16:39:47;0100;Server@node2;Req;;Type 21 request received from Scheduler@node2.supernodexp.hpc, sock=20
02/14/2018 16:39:47;0100;Server@node2;Req;;Type 81 request received from Scheduler@node2.supernodexp.hpc, sock=20
02/14/2018 16:39:47;0100;Server@node2;Req;;Type 71 request received from Scheduler@node2.supernodexp.hpc, sock=20
02/14/2018 16:39:47;0100;Server@node2;Req;;Type 58 request received from Scheduler@node2.supernodexp.hpc, sock=20
02/14/2018 16:39:47;0100;Server@node2;Req;;Type 20 request received from Scheduler@node2.supernodexp.hpc, sock=20
02/14/2018 16:39:47;0100;Server@node2;Req;;Type 51 request received from Scheduler@node2.supernodexp.hpc, sock=20
02/14/2018 16:39:47;0100;Server@node2;Req;;Type 11 request received from Scheduler@node2.supernodexp.hpc, sock=20
02/14/2018 16:39:47;0008;Server@node2;Job;1209.node2.supernodexp.hpc;Job Modified at request of Scheduler@node2.supernodexp.hpc
02/14/2018 16:39:47;0100;Server@node2;Req;;Type 11 request received from Scheduler@node2.supernodexp.hpc, sock=20
02/14/2018 16:39:47;0008;Server@node2;Job;1211.node2.supernodexp.hpc;Job Modified at request of Scheduler@node2.supernodexp.hpc
02/14/2018 16:39:47;0100;Server@node2;Req;;Type 11 request received from Scheduler@node2.supernodexp.hpc, sock=20
02/14/2018 16:39:47;0008;Server@node2;Job;1212.node2.supernodexp.hpc;Job Modified at request of Scheduler@node2.supernodexp.hpc
02/14/2018 16:39:47;0100;Server@node2;Req;;Type 11 request received from Scheduler@node2.supernodexp.hpc, sock=20
02/14/2018 16:39:47;0008;Server@node2;Job;1213.node2.supernodexp.hpc;Job Modified at request of Scheduler@node2.supernodexp.hpc
02/14/2018 16:39:47;0100;Server@node2;Req;;Type 11 request received from Scheduler@node2.supernodexp.hpc, sock=20
02/14/2018 16:39:47;0008;Server@node2;Job;1248.node2.supernodexp.hpc;Job Modified at request of Scheduler@node2.supernodexp.hpc
02/14/2018 16:39:47;0100;Server@node2;Req;;Type 11 request received from Scheduler@node2.supernodexp.hpc, sock=20
02/14/2018 16:39:47;0008;Server@node2;Job;1249.node2.supernodexp.hpc;Job Modified at request of Scheduler@node2.supernodexp.hpc
02/14/2018 16:39:47;0100;Server@node2;Req;;Type 11 request received from Scheduler@node2.supernodexp.hpc, sock=20
02/14/2018 16:39:47;0008;Server@node2;Job;1250.node2.supernodexp.hpc;Job Modified at request of Scheduler@node2.supernodexp.hpc
02/14/2018 16:39:47;0100;Server@node2;Req;;Type 11 request received from Scheduler@node2.supernodexp.hpc, sock=20
02/14/2018 16:39:47;0008;Server@node2;Job;1251.node2.supernodexp.hpc;Job Modified at request of Scheduler@node2.supernodexp.hpc
02/14/2018 16:39:47;0100;Server@node2;Req;;Type 11 request received from Scheduler@node2.supernodexp.hpc, sock=20
02/14/2018 16:39:47;0008;Server@node2;Job;1252.node2.supernodexp.hpc;Job Modified at request of Scheduler@node2.supernodexp.hpc
02/14/2018 16:39:47;0100;Server@node2;Req;;Type 11 request received from Scheduler@node2.supernodexp.hpc, sock=20
02/14/2018 16:39:47;0008;Server@node2;Job;1253.node2.supernodexp.hpc;Job Modified at request of Scheduler@node2.supernodexp.hpc
02/14/2018 16:39:47;0100;Server@node2;Req;;Type 11 request received from Scheduler@node2.supernodexp.hpc, sock=20
02/14/2018 16:39:47;0008;Server@node2;Job;1254.node2.supernodexp.hpc;Job Modified at request of Scheduler@node2.supernodexp.hpc
02/14/2018 16:39:47;0100;Server@node2;Req;;Type 11 request received from Scheduler@node2.supernodexp.hpc, sock=20
02/14/2018 16:39:47;0008;Server@node2;Job;1255.node2.supernodexp.hpc;Job Modified at request of Scheduler@node2.supernodexp.hpc
02/14/2018 16:39:47;0100;Server@node2;Req;;Type 11 request received from Scheduler@node2.supernodexp.hpc, sock=20
02/14/2018 16:39:47;0008;Server@node2;Job;1256.node2.supernodexp.hpc;Job Modified at request of Scheduler@node2.supernodexp.hpc
02/14/2018 16:39:47;0100;Server@node2;Req;;Type 11 request received from Scheduler@node2.supernodexp.hpc, sock=20
02/14/2018 16:39:47;0008;Server@node2;Job;1257.node2.supernodexp.hpc;Job Modified at request of Scheduler@node2.supernodexp.hpc
02/14/2018 16:39:47;0100;Server@node2;Req;;Type 23 request received from Scheduler@node2.supernodexp.hpc, sock=20
02/14/2018 16:39:47;0008;Server@node2;Job;1258.node2.supernodexp.hpc;Job Run at request of Scheduler@node2.supernodexp.hpc on exec_vnode (node14:ncpus=8:mem=3145728kb)
02/14/2018 16:39:47;0001;Server@node2;Svr;Server@node2;Success (0) in req_runjob2, return value of svr_startjob is 0
02/14/2018 16:39:49;0080;Server@node2;Job;1258.node2.supernodexp.hpc;Obit received momhop:1 serverhop:1 state:4 substate:42
02/14/2018 16:39:50;0010;Server@node2;Job;1258.node2.supernodexp.hpc;Exit_status=0 resources_used.cpupercent=800 resources_used.cput=00:00:09 resources_used.mem=0kb resources_used.ncpus=8 resources_used.vmem=0kb resources_used.walltime=00:00:01
02/14/2018 16:39:50;0100;Server@node2;Job;1258.node2.supernodexp.hpc;dequeuing from workq, state 5
02/14/2018 16:39:50;0040;Server@node2;Svr;node2.supernodexp.hpc;Scheduler sent command 2
02/14/2018 16:39:50;0040;Server@node2;Svr;node2.supernodexp.hpc;Scheduler sent command 0
02/14/2018 16:39:50;0100;Server@node2;Req;;Type 21 request received from Scheduler@node2.supernodexp.hpc, sock=20
02/14/2018 16:39:50;0100;Server@node2;Req;;Type 81 request received from Scheduler@node2.supernodexp.hpc, sock=20
02/14/2018 16:39:50;0100;Server@node2;Req;;Type 71 request received from Scheduler@node2.supernodexp.hpc, sock=20
02/14/2018 16:39:50;0100;Server@node2;Req;;Type 58 request received from Scheduler@node2.supernodexp.hpc, sock=20
02/14/2018 16:39:50;0100;Server@node2;Req;;Type 20 request received from Scheduler@node2.supernodexp.hpc, sock=20
02/14/2018 16:39:50;0100;Server@node2;Req;;Type 51 request received from Scheduler@node2.supernodexp.hpc, sock=20
02/14/2018 16:39:50;0100;Server@node2;Req;;Type 11 request received from Scheduler@node2.supernodexp.hpc, sock=20
02/14/2018 16:39:50;0008;Server@node2;Job;1259.node2.supernodexp.hpc;Job Modified at request of Scheduler@node2.supernodexp.hpc
02/14/2018 16:39:50;0100;Server@node2;Req;;Type 11 request received from Scheduler@node2.supernodexp.hpc, sock=20
02/14/2018 16:39:50;0008;Server@node2;Job;1260.node2.supernodexp.hpc;Job Modified at request of Scheduler@node2.supernodexp.hpc
02/14/2018 16:39:50;0100;Server@node2;Req;;Type 11 request received from Scheduler@node2.supernodexp.hpc, sock=20
02/14/2018 16:39:50;0008;Server@node2;Job;1261.node2.supernodexp.hpc;Job Modified at request of Scheduler@node2.supernodexp.hpc
02/14/2018 16:39:50;0100;Server@node2;Req;;Type 23 request received from Scheduler@node2.supernodexp.hpc, sock=20
02/14/2018 16:39:50;0008;Server@node2;Job;1262.node2.supernodexp.hpc;Job Run at request of Scheduler@node2.supernodexp.hpc on exec_vnode (node14:ncpus=8:mem=3145728kb)
02/14/2018 16:39:50;0001;Server@node2;Svr;Server@node2;Success (0) in req_runjob2, return value of svr_startjob is 0
02/14/2018 16:39:52;0080;Server@node2;Job;1262.node2.supernodexp.hpc;Obit received momhop:1 serverhop:1 state:4 substate:42
02/14/2018 16:39:53;0010;Server@node2;Job;1262.node2.supernodexp.hpc;Exit_status=0 resources_used.cpupercent=498 resources_used.cput=00:00:10 resources_used.mem=0kb resources_used.ncpus=8 resources_used.vmem=0kb resources_used.walltime=00:00:02
02/14/2018 16:39:53;0100;Server@node2;Job;1262.node2.supernodexp.hpc;dequeuing from workq, state 5
02/14/2018 16:39:53;0040;Server@node2;Svr;node2.supernodexp.hpc;Scheduler sent command 2
02/14/2018 16:39:53;0040;Server@node2;Svr;node2.supernodexp.hpc;Scheduler sent command 0
02/14/2018 16:39:53;0100;Server@node2;Req;;Type 21 request received from Scheduler@node2.supernodexp.hpc, sock=20
02/14/2018 16:39:53;0100;Server@node2;Req;;Type 81 request received from Scheduler@node2.supernodexp.hpc, sock=20
02/14/2018 16:39:53;0100;Server@node2;Req;;Type 71 request received from Scheduler@node2.supernodexp.hpc, sock=20
02/14/2018 16:39:53;0100;Server@node2;Req;;Type 58 request received from Scheduler@node2.supernodexp.hpc, sock=20
02/14/2018 16:39:53;0100;Server@node2;Req;;Type 20 request received from Scheduler@node2.supernodexp.hpc, sock=20
02/14/2018 16:39:53;0100;Server@node2;Req;;Type 51 request received from Scheduler@node2.supernodexp.hpc, sock=20
02/14/2018 16:39:53;0100;Server@node2;Req;;Type 11 request received from Scheduler@node2.supernodexp.hpc, sock=20
02/14/2018 16:39:53;0008;Server@node2;Job;1263.node2.supernodexp.hpc;Job Modified at request of Scheduler@node2.supernodexp.hpc
02/14/2018 16:39:53;0100;Server@node2;Req;;Type 11 request received from Scheduler@node2.supernodexp.hpc, sock=20
02/14/2018 16:39:53;0008;Server@node2;Job;1264.node2.supernodexp.hpc;Job Modified at request of Scheduler@node2.supernodexp.hpc
02/14/2018 16:39:53;0100;Server@node2;Req;;Type 11 request received from Scheduler@node2.supernodexp.hpc, sock=20
02/14/2018 16:39:53;0008;Server@node2;Job;1265.node2.supernodexp.hpc;Job Modified at request of Scheduler@node2.supernodexp.hpc
02/14/2018 16:39:53;0100;Server@node2;Req;;Type 11 request received from Scheduler@node2.supernodexp.hpc, sock=20
02/14/2018 16:39:53;0008;Server@node2;Job;1266.node2.supernodexp.hpc;Job Modified at request of Scheduler@node2.supernodexp.hpc
02/14/2018 16:39:53;0100;Server@node2;Req;;Type 11 request received from Scheduler@node2.supernodexp.hpc, sock=20
02/14/2018 16:39:53;0008;Server@node2;Job;1267.node2.supernodexp.hpc;Job Modified at request of Scheduler@node2.supernodexp.hpc
02/14/2018 16:39:53;0100;Server@node2;Req;;Type 11 request received from Scheduler@node2.supernodexp.hpc, sock=20
02/14/2018 16:39:53;0008;Server@node2;Job;1268.node2.supernodexp.hpc;Job Modified at request of Scheduler@node2.supernodexp.hpc
02/14/2018 16:39:53;0100;Server@node2;Req;;Type 11 request received from Scheduler@node2.supernodexp.hpc, sock=20
02/14/2018 16:39:53;0008;Server@node2;Job;1269.node2.supernodexp.hpc;Job Modified at request of Scheduler@node2.supernodexp.hpc
02/14/2018 16:39:53;0100;Server@node2;Req;;Type 11 request received from Scheduler@node2.supernodexp.hpc, sock=20
02/14/2018 16:39:53;0008;Server@node2;Job;1270.node2.supernodexp.hpc;Job Modified at request of Scheduler@node2.supernodexp.hpc
02/14/2018 16:39:53;0100;Server@node2;Req;;Type 23 request received from Scheduler@node2.supernodexp.hpc, sock=20
02/14/2018 16:39:53;0008;Server@node2;Job;1271.node2.supernodexp.hpc;Job Run at request of Scheduler@node2.supernodexp.hpc on exec_vnode (node14:ncpus=8:mem=3145728kb)
02/14/2018 16:39:53;0001;Server@node2;Svr;Server@node2;Success (0) in req_runjob2, return value of svr_startjob is 0
02/14/2018 16:39:55;0080;Server@node2;Job;1271.node2.supernodexp.hpc;Obit received momhop:1 serverhop:1 state:4 substate:42
02/14/2018 16:39:56;0010;Server@node2;Job;1271.node2.supernodexp.hpc;Exit_status=0 resources_used.cpupercent=800 resources_used.cput=00:00:10 resources_used.mem=0kb resources_used.ncpus=8 resources_used.vmem=0kb resources_used.walltime=00:00:01
02/14/2018 16:39:56;0100;Server@node2;Job;1271.node2.supernodexp.hpc;dequeuing from workq, state 5
02/14/2018 16:39:56;0040;Server@node2;Svr;node2.supernodexp.hpc;Scheduler sent command 2
02/14/2018 16:39:56;0040;Server@node2;Svr;node2.supernodexp.hpc;Scheduler sent command 0
02/14/2018 16:39:56;0100;Server@node2;Req;;Type 21 request received from Scheduler@node2.supernodexp.hpc, sock=20
02/14/2018 16:39:56;0100;Server@node2;Req;;Type 81 request received from Scheduler@node2.supernodexp.hpc, sock=20
02/14/2018 16:39:56;0100;Server@node2;Req;;Type 71 request received from Scheduler@node2.supernodexp.hpc, sock=20
02/14/2018 16:39:56;0100;Server@node2;Req;;Type 58 request received from Scheduler@node2.supernodexp.hpc, sock=20
02/14/2018 16:39:56;0100;Server@node2;Req;;Type 20 request received from Scheduler@node2.supernodexp.hpc, sock=20
02/14/2018 16:39:56;0100;Server@node2;Req;;Type 51 request received from Scheduler@node2.supernodexp.hpc, sock=20
02/14/2018 16:39:56;0100;Server@node2;Req;;Type 11 request received from Scheduler@node2.supernodexp.hpc, sock=20
02/14/2018 16:39:56;0008;Server@node2;Job;1272.node2.supernodexp.hpc;Job Modified at request of Scheduler@node2.supernodexp.hpc
02/14/2018 16:39:56;0100;Server@node2;Req;;Type 11 request received from Scheduler@node2.supernodexp.hpc, sock=20
02/14/2018 16:39:56;0008;Server@node2;Job;1273.node2.supernodexp.hpc;Job Modified at request of Scheduler@node2.supernodexp.hpc
02/14/2018 16:39:56;0100;Server@node2;Req;;Type 11 request received from Scheduler@node2.supernodexp.hpc, sock=20
02/14/2018 16:39:56;0008;Server@node2;Job;1274.node2.supernodexp.hpc;Job Modified at request of Scheduler@node2.supernodexp.hpc
02/14/2018 16:39:56;0100;Server@node2;Req;;Type 23 request received from Scheduler@node2.supernodexp.hpc, sock=20
02/14/2018 16:39:56;0008;Server@node2;Job;1275.node2.supernodexp.hpc;Job Run at request of Scheduler@node2.supernodexp.hpc on exec_vnode (node14:ncpus=8:mem=3145728kb)
02/14/2018 16:39:56;0001;Server@node2;Svr;Server@node2;Success (0) in req_runjob2, return value of svr_startjob is 0
02/14/2018 16:39:58;0080;Server@node2;Job;1275.node2.supernodexp.hpc;Obit received momhop:1 serverhop:1 state:4 substate:42
02/14/2018 16:39:59;0010;Server@node2;Job;1275.node2.supernodexp.hpc;Exit_status=0 resources_used.cpupercent=548 resources_used.cput=00:00:11 resources_used.mem=0kb resources_used.ncpus=8 resources_used.vmem=0kb resources_used.walltime=00:00:02
02/14/2018 16:39:59;0100;Server@node2;Job;1275.node2.supernodexp.hpc;dequeuing from workq, state 5
02/14/2018 16:39:59;0040;Server@node2;Svr;node2.supernodexp.hpc;Scheduler sent command 2
02/14/2018 16:39:59;0040;Server@node2;Svr;node2.supernodexp.hpc;Scheduler sent command 0
02/14/2018 16:39:59;0100;Server@node2;Req;;Type 21 request received from Scheduler@node2.supernodexp.hpc, sock=20
02/14/2018 16:39:59;0100;Server@node2;Req;;Type 81 request received from Scheduler@node2.supernodexp.hpc, sock=20
02/14/2018 16:39:59;0100;Server@node2;Req;;Type 71 request received from Scheduler@node2.supernodexp.hpc, sock=20
02/14/2018 16:39:59;0100;Server@node2;Req;;Type 58 request received from Scheduler@node2.supernodexp.hpc, sock=20
02/14/2018 16:39:59;0100;Server@node2;Req;;Type 20 request received from Scheduler@node2.supernodexp.hpc, sock=20
02/14/2018 16:39:59;0100;Server@node2;Req;;Type 51 request received from Scheduler@node2.supernodexp.hpc, sock=20
02/14/2018 16:39:59;0100;Server@node2;Req;;Type 11 request received from Scheduler@node2.supernodexp.hpc, sock=20
02/14/2018 16:39:59;0008;Server@node2;Job;1276.node2.supernodexp.hpc;Job Modified at request of Scheduler@node2.supernodexp.hpc
02/14/2018 16:39:59;0100;Server@node2;Req;;Type 23 request received from Scheduler@node2.supernodexp.hpc, sock=20
02/14/2018 16:39:59;0008;Server@node2;Job;1277.node2.supernodexp.hpc;Job Run at request of Scheduler@node2.supernodexp.hpc on exec_vnode (node14:ncpus=8:mem=3145728kb)
02/14/2018 16:39:59;0001;Server@node2;Svr;Server@node2;Success (0) in req_runjob2, return value of svr_startjob is 0
02/14/2018 16:40:01;0080;Server@node2;Job;1277.node2.supernodexp.hpc;Obit received momhop:1 serverhop:1 state:4 substate:42
02/14/2018 16:40:02;0010;Server@node2;Job;1277.node2.supernodexp.hpc;Exit_status=0 resources_used.cpupercent=600 resources_used.cput=00:00:12 resources_used.mem=0kb resources_used.ncpus=8 resources_used.vmem=0kb resources_used.walltime=00:00:02
02/14/2018 16:40:02;0100;Server@node2;Job;1277.node2.supernodexp.hpc;dequeuing from workq, state 5
02/14/2018 16:40:02;0040;Server@node2;Svr;node2.supernodexp.hpc;Scheduler sent command 2
02/14/2018 16:40:02;0040;Server@node2;Svr;node2.supernodexp.hpc;Scheduler sent command 0
02/14/2018 16:40:02;0100;Server@node2;Req;;Type 21 request received from Scheduler@node2.supernodexp.hpc, sock=20
02/14/2018 16:40:02;0100;Server@node2;Req;;Type 81 request received from Scheduler@node2.supernodexp.hpc, sock=20
02/14/2018 16:40:02;0100;Server@node2;Req;;Type 71 request received from Scheduler@node2.supernodexp.hpc, sock=20
02/14/2018 16:40:02;0100;Server@node2;Req;;Type 58 request received from Scheduler@node2.supernodexp.hpc, sock=20
02/14/2018 16:40:03;0100;Server@node2;Req;;Type 20 request received from Scheduler@node2.supernodexp.hpc, sock=20
02/14/2018 16:40:03;0100;Server@node2;Req;;Type 51 request received from Scheduler@node2.supernodexp.hpc, sock=20
02/14/2018 16:40:03;0100;Server@node2;Req;;Type 11 request received from Scheduler@node2.supernodexp.hpc, sock=20
02/14/2018 16:40:03;0008;Server@node2;Job;1278.node2.supernodexp.hpc;Job Modified at request of Scheduler@node2.supernodexp.hpc
02/14/2018 16:40:03;0100;Server@node2;Req;;Type 11 request received from Scheduler@node2.supernodexp.hpc, sock=20
02/14/2018 16:40:03;0008;Server@node2;Job;1279.node2.supernodexp.hpc;Job Modified at request of Scheduler@node2.supernodexp.hpc
02/14/2018 16:40:03;0100;Server@node2;Req;;Type 11 request received from Scheduler@node2.supernodexp.hpc, sock=20
02/14/2018 16:40:03;0008;Server@node2;Job;1280.node2.supernodexp.hpc;Job Modified at request of Scheduler@node2.supernodexp.hpc
02/14/2018 16:40:03;0100;Server@node2;Req;;Type 11 request received from Scheduler@node2.supernodexp.hpc, sock=20
02/14/2018 16:40:03;0008;Server@node2;Job;1281.node2.supernodexp.hpc;Job Modified at request of Scheduler@node2.supernodexp.hpc
02/14/2018 16:40:03;0100;Server@node2;Req;;Type 11 request received from Scheduler@node2.supernodexp.hpc, sock=20
02/14/2018 16:40:03;0008;Server@node2;Job;1282.node2.supernodexp.hpc;Job Modified at request of Scheduler@node2.supernodexp.hpc
02/14/2018 16:40:03;0100;Server@node2;Req;;Type 11 request received from Scheduler@node2.supernodexp.hpc, sock=20
02/14/2018 16:40:03;0008;Server@node2;Job;1283.node2.supernodexp.hpc;Job Modified at request of Scheduler@node2.supernodexp.hpc
02/14/2018 16:40:03;0100;Server@node2;Req;;Type 11 request received from Scheduler@node2.supernodexp.hpc, sock=20
02/14/2018 16:40:03;0008;Server@node2;Job;1284.node2.supernodexp.hpc;Job Modified at request of Scheduler@node2.supernodexp.hpc
02/14/2018 16:40:03;0100;Server@node2;Req;;Type 11 request received from Scheduler@node2.supernodexp.hpc, sock=20
02/14/2018 16:40:03;0008;Server@node2;Job;1285.node2.supernodexp.hpc;Job Modified at request of Scheduler@node2.supernodexp.hpc
02/14/2018 16:40:03;0100;Server@node2;Req;;Type 11 request received from Scheduler@node2.supernodexp.hpc, sock=20
02/14/2018 16:40:03;0008;Server@node2;Job;1286.node2.supernodexp.hpc;Job Modified at request of Scheduler@node2.supernodexp.hpc
02/14/2018 16:40:03;0100;Server@node2;Req;;Type 11 request received from Scheduler@node2.supernodexp.hpc, sock=20
02/14/2018 16:40:03;0008;Server@node2;Job;1287.node2.supernodexp.hpc;Job Modified at request of Scheduler@node2.supernodexp.hpc
02/14/2018 16:40:03;0100;Server@node2;Req;;Type 11 request received from Scheduler@node2.supernodexp.hpc, sock=20
02/14/2018 16:40:03;0008;Server@node2;Job;1288.node2.supernodexp.hpc;Job Modified at request of Scheduler@node2.supernodexp.hpc
02/14/2018 16:40:03;0100;Server@node2;Req;;Type 11 request received from Scheduler@node2.supernodexp.hpc, sock=20
02/14/2018 16:40:03;0008;Server@node2;Job;1289.node2.supernodexp.hpc;Job Modified at request of Scheduler@node2.supernodexp.hpc
02/14/2018 16:40:03;0100;Server@node2;Req;;Type 11 request received from Scheduler@node2.supernodexp.hpc, sock=20
02/14/2018 16:40:03;0008;Server@node2;Job;1290.node2.supernodexp.hpc;Job Modified at request of Scheduler@node2.supernodexp.hpc
02/14/2018 16:40:03;0100;Server@node2;Req;;Type 11 request received from Scheduler@node2.supernodexp.hpc, sock=20
02/14/2018 16:40:03;0008;Server@node2;Job;1291.node2.supernodexp.hpc;Job Modified at request of Scheduler@node2.supernodexp.hpc
02/14/2018 16:40:03;0100;Server@node2;Req;;Type 11 request received from Scheduler@node2.supernodexp.hpc, sock=20
02/14/2018 16:40:03;0008;Server@node2;Job;1292.node2.supernodexp.hpc;Job Modified at request of Scheduler@node2.supernodexp.hpc
02/14/2018 16:40:03;0100;Server@node2;Req;;Type 11 request received from Scheduler@node2.supernodexp.hpc, sock=20
02/14/2018 16:40:03;0008;Server@node2;Job;1293.node2.supernodexp.hpc;Job Modified at request of Scheduler@node2.supernodexp.hpc
02/14/2018 16:40:03;0100;Server@node2;Req;;Type 23 request received from Scheduler@node2.supernodexp.hpc, sock=20
02/14/2018 16:40:03;0008;Server@node2;Job;1294.node2.supernodexp.hpc;Job Run at request of Scheduler@node2.supernodexp.hpc on exec_vnode (node14:ncpus=8:mem=3145728kb)
02/14/2018 16:40:03;0001;Server@node2;Svr;Server@node2;Success (0) in req_runjob2, return value of svr_startjob is 0
02/14/2018 16:40:04;0080;Server@node2;Job;1294.node2.supernodexp.hpc;Obit received momhop:1 serverhop:1 state:4 substate:42
02/14/2018 16:40:06;0010;Server@node2;Job;1294.node2.supernodexp.hpc;Exit_status=0 resources_used.cpupercent=548 resources_used.cput=00:00:11 resources_used.mem=0kb resources_used.ncpus=8 resources_used.vmem=0kb resources_used.walltime=00:00:02
02/14/2018 16:40:06;0100;Server@node2;Job;1294.node2.supernodexp.hpc;dequeuing from workq, state 5
02/14/2018 16:40:06;0040;Server@node2;Svr;node2.supernodexp.hpc;Scheduler sent command 2
02/14/2018 16:40:06;0040;Server@node2;Svr;node2.supernodexp.hpc;Scheduler sent command 0
02/14/2018 16:40:06;0100;Server@node2;Req;;Type 21 request received from Scheduler@node2.supernodexp.hpc, sock=20
02/14/2018 16:40:06;0100;Server@node2;Req;;Type 81 request received from Scheduler@node2.supernodexp.hpc, sock=20
02/14/2018 16:40:06;0100;Server@node2;Req;;Type 71 request received from Scheduler@node2.supernodexp.hpc, sock=20
02/14/2018 16:40:06;0100;Server@node2;Req;;Type 58 request received from Scheduler@node2.supernodexp.hpc, sock=20
02/14/2018 16:40:06;0100;Server@node2;Req;;Type 20 request received from Scheduler@node2.supernodexp.hpc, sock=20
02/14/2018 16:40:06;0100;Server@node2;Req;;Type 51 request received from Scheduler@node2.supernodexp.hpc, sock=20
02/14/2018 16:40:06;0100;Server@node2;Req;;Type 11 request received from Scheduler@node2.supernodexp.hpc, sock=20
02/14/2018 16:40:06;0008;Server@node2;Job;1295.node2.supernodexp.hpc;Job Modified at request of Scheduler@node2.supernodexp.hpc
02/14/2018 16:40:06;0100;Server@node2;Req;;Type 11 request received from Scheduler@node2.supernodexp.hpc, sock=20
02/14/2018 16:40:06;0008;Server@node2;Job;1296.node2.supernodexp.hpc;Job Modified at request of Scheduler@node2.supernodexp.hpc
02/14/2018 16:40:06;0100;Server@node2;Req;;Type 23 request received from Scheduler@node2.supernodexp.hpc, sock=20
02/14/2018 16:40:06;0008;Server@node2;Job;1297.node2.supernodexp.hpc;Job Run at request of Scheduler@node2.supernodexp.hpc on exec_vnode (node14:ncpus=8:mem=3145728kb)
02/14/2018 16:40:06;0001;Server@node2;Svr;Server@node2;Success (0) in req_runjob2, return value of svr_startjob is 0
02/14/2018 16:40:06;0100;Server@node2;Req;;Type 1 request received from ctminh@node2.supernodexp.hpc, sock=16
02/14/2018 16:40:07;0100;Server@node2;Req;;Type 3 request received from ctminh@node2.supernodexp.hpc, sock=16
02/14/2018 16:40:07;0100;Server@node2;Req;;Type 5 request received from ctminh@node2.supernodexp.hpc, sock=16
02/14/2018 16:40:07;0100;Server@node2;Job;1351.node2.supernodexp.hpc;enqueuing into workq, state 1 hop 1
02/14/2018 16:40:07;0008;Server@node2;Job;1351.node2.supernodexp.hpc;Job Queued at request of ctminh@node2.supernodexp.hpc, owner = ctminh@node2.supernodexp.hpc, job name = telemac2, queue = workq
02/14/2018 16:40:07;0040;Server@node2;Svr;node2.supernodexp.hpc;Scheduler sent command 1
02/14/2018 16:40:07;0040;Server@node2;Svr;node2.supernodexp.hpc;Scheduler sent command 0
02/14/2018 16:40:07;0100;Server@node2;Req;;Type 21 request received from Scheduler@node2.supernodexp.hpc, sock=20
02/14/2018 16:40:07;0100;Server@node2;Req;;Type 81 request received from Scheduler@node2.supernodexp.hpc, sock=20
02/14/2018 16:40:07;0100;Server@node2;Req;;Type 71 request received from Scheduler@node2.supernodexp.hpc, sock=20
02/14/2018 16:40:07;0100;Server@node2;Req;;Type 58 request received from Scheduler@node2.supernodexp.hpc, sock=20
02/14/2018 16:40:07;0100;Server@node2;Req;;Type 1 request received from ctminh@node2.supernodexp.hpc, sock=16
02/14/2018 16:40:07;0100;Server@node2;Req;;Type 3 request received from ctminh@node2.supernodexp.hpc, sock=16
02/14/2018 16:40:07;0100;Server@node2;Req;;Type 5 request received from ctminh@node2.supernodexp.hpc, sock=16
02/14/2018 16:40:07;0100;Server@node2;Job;1352.node2.supernodexp.hpc;enqueuing into workq, state 1 hop 1
02/14/2018 16:40:07;0008;Server@node2;Job;1352.node2.supernodexp.hpc;Job Queued at request of ctminh@node2.supernodexp.hpc, owner = ctminh@node2.supernodexp.hpc, job name = sweep, queue = workq
02/14/2018 16:40:07;0100;Server@node2;Req;;Type 20 request received from Scheduler@node2.supernodexp.hpc, sock=20
02/14/2018 16:40:07;0100;Server@node2;Req;;Type 51 request received from Scheduler@node2.supernodexp.hpc, sock=20
02/14/2018 16:40:07;0100;Server@node2;Req;;Type 1 request received from ctminh@node2.supernodexp.hpc, sock=16
02/14/2018 16:40:07;0100;Server@node2;Req;;Type 3 request received from ctminh@node2.supernodexp.hpc, sock=16
02/14/2018 16:40:07;0100;Server@node2;Req;;Type 5 request received from ctminh@node2.supernodexp.hpc, sock=16
02/14/2018 16:40:07;0100;Server@node2;Job;1353.node2.supernodexp.hpc;enqueuing into workq, state 1 hop 1
02/14/2018 16:40:07;0008;Server@node2;Job;1353.node2.supernodexp.hpc;Job Queued at request of ctminh@node2.supernodexp.hpc, owner = ctminh@node2.supernodexp.hpc, job name = telemac3, queue = workq
02/14/2018 16:40:07;0100;Server@node2;Req;;Type 1 request received from ctminh@node2.supernodexp.hpc, sock=16
02/14/2018 16:40:07;0100;Server@node2;Req;;Type 11 request received from Scheduler@node2.supernodexp.hpc, sock=20
02/14/2018 16:40:07;0008;Server@node2;Job;1209.node2.supernodexp.hpc;Job Modified at request of Scheduler@node2.supernodexp.hpc
02/14/2018 16:40:07;0100;Server@node2;Req;;Type 3 request received from ctminh@node2.supernodexp.hpc, sock=16
02/14/2018 16:40:07;0100;Server@node2;Req;;Type 5 request received from ctminh@node2.supernodexp.hpc, sock=16
02/14/2018 16:40:07;0100;Server@node2;Job;1354.node2.supernodexp.hpc;enqueuing into workq, state 1 hop 1
02/14/2018 16:40:07;0008;Server@node2;Job;1354.node2.supernodexp.hpc;Job Queued at request of ctminh@node2.supernodexp.hpc, owner = ctminh@node2.supernodexp.hpc, job name = vectorization, queue = workq
02/14/2018 16:40:07;0100;Server@node2;Req;;Type 11 request received from Scheduler@node2.supernodexp.hpc, sock=20
02/14/2018 16:40:07;0008;Server@node2;Job;1211.node2.supernodexp.hpc;Job Modified at request of Scheduler@node2.supernodexp.hpc
02/14/2018 16:40:07;0100;Server@node2;Req;;Type 11 request received from Scheduler@node2.supernodexp.hpc, sock=20
02/14/2018 16:40:07;0008;Server@node2;Job;1212.node2.supernodexp.hpc;Job Modified at request of Scheduler@node2.supernodexp.hpc
02/14/2018 16:40:07;0100;Server@node2;Req;;Type 11 request received from Scheduler@node2.supernodexp.hpc, sock=20
02/14/2018 16:40:07;0008;Server@node2;Job;1213.node2.supernodexp.hpc;Job Modified at request of Scheduler@node2.supernodexp.hpc
02/14/2018 16:40:07;0100;Server@node2;Req;;Type 11 request received from Scheduler@node2.supernodexp.hpc, sock=20
02/14/2018 16:40:07;0008;Server@node2;Job;1216.node2.supernodexp.hpc;Job Modified at request of Scheduler@node2.supernodexp.hpc
02/14/2018 16:40:07;0100;Server@node2;Req;;Type 11 request received from Scheduler@node2.supernodexp.hpc, sock=20
02/14/2018 16:40:07;0008;Server@node2;Job;1218.node2.supernodexp.hpc;Job Modified at request of Scheduler@node2.supernodexp.hpc
02/14/2018 16:40:07;0100;Server@node2;Req;;Type 11 request received from Scheduler@node2.supernodexp.hpc, sock=20
02/14/2018 16:40:07;0008;Server@node2;Job;1219.node2.supernodexp.hpc;Job Modified at request of Scheduler@node2.supernodexp.hpc
02/14/2018 16:40:07;0100;Server@node2;Req;;Type 11 request received from Scheduler@node2.supernodexp.hpc, sock=20
02/14/2018 16:40:07;0008;Server@node2;Job;1220.node2.supernodexp.hpc;Job Modified at request of Scheduler@node2.supernodexp.hpc
02/14/2018 16:40:07;0100;Server@node2;Req;;Type 11 request received from Scheduler@node2.supernodexp.hpc, sock=20
02/14/2018 16:40:07;0008;Server@node2;Job;1221.node2.supernodexp.hpc;Job Modified at request of Scheduler@node2.supernodexp.hpc
02/14/2018 16:40:07;0100;Server@node2;Req;;Type 11 request received from Scheduler@node2.supernodexp.hpc, sock=20
02/14/2018 16:40:07;0008;Server@node2;Job;1222.node2.supernodexp.hpc;Job Modified at request of Scheduler@node2.supernodexp.hpc
02/14/2018 16:40:07;0100;Server@node2;Req;;Type 11 request received from Scheduler@node2.supernodexp.hpc, sock=20
02/14/2018 16:40:07;0008;Server@node2;Job;1224.node2.supernodexp.hpc;Job Modified at request of Scheduler@node2.supernodexp.hpc
02/14/2018 16:40:07;0100;Server@node2;Req;;Type 11 request received from Scheduler@node2.supernodexp.hpc, sock=20
02/14/2018 16:40:07;0008;Server@node2;Job;1225.node2.supernodexp.hpc;Job Modified at request of Scheduler@node2.supernodexp.hpc
02/14/2018 16:40:07;0100;Server@node2;Req;;Type 11 request received from Scheduler@node2.supernodexp.hpc, sock=20
02/14/2018 16:40:07;0008;Server@node2;Job;1226.node2.supernodexp.hpc;Job Modified at request of Scheduler@node2.supernodexp.hpc
02/14/2018 16:40:07;0100;Server@node2;Req;;Type 11 request received from Scheduler@node2.supernodexp.hpc, sock=20
02/14/2018 16:40:07;0008;Server@node2;Job;1227.node2.supernodexp.hpc;Job Modified at request of Scheduler@node2.supernodexp.hpc
02/14/2018 16:40:07;0100;Server@node2;Req;;Type 11 request received from Scheduler@node2.supernodexp.hpc, sock=20
02/14/2018 16:40:07;0008;Server@node2;Job;1228.node2.supernodexp.hpc;Job Modified at request of Scheduler@node2.supernodexp.hpc
02/14/2018 16:40:07;0100;Server@node2;Req;;Type 11 request received from Scheduler@node2.supernodexp.hpc, sock=20
02/14/2018 16:40:07;0008;Server@node2;Job;1229.node2.supernodexp.hpc;Job Modified at request of Scheduler@node2.supernodexp.hpc
02/14/2018 16:40:07;0100;Server@node2;Req;;Type 11 request received from Scheduler@node2.supernodexp.hpc, sock=20
02/14/2018 16:40:07;0008;Server@node2;Job;1231.node2.supernodexp.hpc;Job Modified at request of Scheduler@node2.supernodexp.hpc
02/14/2018 16:40:07;0100;Server@node2;Req;;Type 11 request received from Scheduler@node2.supernodexp.hpc, sock=20
02/14/2018 16:40:07;0008;Server@node2;Job;1233.node2.supernodexp.hpc;Job Modified at request of Scheduler@node2.supernodexp.hpc
02/14/2018 16:40:07;0100;Server@node2;Req;;Type 11 request received from Scheduler@node2.supernodexp.hpc, sock=20
02/14/2018 16:40:07;0008;Server@node2;Job;1234.node2.supernodexp.hpc;Job Modified at request of Scheduler@node2.supernodexp.hpc
02/14/2018 16:40:07;0100;Server@node2;Req;;Type 11 request received from Scheduler@node2.supernodexp.hpc, sock=20
02/14/2018 16:40:07;0008;Server@node2;Job;1235.node2.supernodexp.hpc;Job Modified at request of Scheduler@node2.supernodexp.hpc
02/14/2018 16:40:07;0100;Server@node2;Req;;Type 11 request received from Scheduler@node2.supernodexp.hpc, sock=20
02/14/2018 16:40:07;0008;Server@node2;Job;1236.node2.supernodexp.hpc;Job Modified at request of Scheduler@node2.supernodexp.hpc
02/14/2018 16:40:07;0100;Server@node2;Req;;Type 11 request received from Scheduler@node2.supernodexp.hpc, sock=20
02/14/2018 16:40:07;0008;Server@node2;Job;1238.node2.supernodexp.hpc;Job Modified at request of Scheduler@node2.supernodexp.hpc
02/14/2018 16:40:07;0100;Server@node2;Req;;Type 11 request received from Scheduler@node2.supernodexp.hpc, sock=20
02/14/2018 16:40:07;0008;Server@node2;Job;1239.node2.supernodexp.hpc;Job Modified at request of Scheduler@node2.supernodexp.hpc
02/14/2018 16:40:07;0100;Server@node2;Req;;Type 11 request received from Scheduler@node2.supernodexp.hpc, sock=20
02/14/2018 16:40:07;0008;Server@node2;Job;1240.node2.supernodexp.hpc;Job Modified at request of Scheduler@node2.supernodexp.hpc
02/14/2018 16:40:07;0100;Server@node2;Req;;Type 11 request received from Scheduler@node2.supernodexp.hpc, sock=20
02/14/2018 16:40:07;0008;Server@node2;Job;1241.node2.supernodexp.hpc;Job Modified at request of Scheduler@node2.supernodexp.hpc
02/14/2018 16:40:07;0100;Server@node2;Req;;Type 11 request received from Scheduler@node2.supernodexp.hpc, sock=20
02/14/2018 16:40:07;0008;Server@node2;Job;1242.node2.supernodexp.hpc;Job Modified at request of Scheduler@node2.supernodexp.hpc
02/14/2018 16:40:07;0100;Server@node2;Req;;Type 11 request received from Scheduler@node2.supernodexp.hpc, sock=20
02/14/2018 16:40:07;0008;Server@node2;Job;1243.node2.supernodexp.hpc;Job Modified at request of Scheduler@node2.supernodexp.hpc
02/14/2018 16:40:07;0100;Server@node2;Req;;Type 11 request received from Scheduler@node2.supernodexp.hpc, sock=20
02/14/2018 16:40:07;0008;Server@node2;Job;1245.node2.supernodexp.hpc;Job Modified at request of Scheduler@node2.supernodexp.hpc
02/14/2018 16:40:07;0100;Server@node2;Req;;Type 11 request received from Scheduler@node2.supernodexp.hpc, sock=20
02/14/2018 16:40:07;0008;Server@node2;Job;1246.node2.supernodexp.hpc;Job Modified at request of Scheduler@node2.supernodexp.hpc
02/14/2018 16:40:07;0100;Server@node2;Req;;Type 11 request received from Scheduler@node2.supernodexp.hpc, sock=20
02/14/2018 16:40:07;0008;Server@node2;Job;1248.node2.supernodexp.hpc;Job Modified at request of Scheduler@node2.supernodexp.hpc
02/14/2018 16:40:07;0100;Server@node2;Req;;Type 11 request received from Scheduler@node2.supernodexp.hpc, sock=20
02/14/2018 16:40:07;0008;Server@node2;Job;1249.node2.supernodexp.hpc;Job Modified at request of Scheduler@node2.supernodexp.hpc
02/14/2018 16:40:07;0100;Server@node2;Req;;Type 11 request received from Scheduler@node2.supernodexp.hpc, sock=20
02/14/2018 16:40:07;0008;Server@node2;Job;1250.node2.supernodexp.hpc;Job Modified at request of Scheduler@node2.supernodexp.hpc
02/14/2018 16:40:07;0100;Server@node2;Req;;Type 11 request received from Scheduler@node2.supernodexp.hpc, sock=20
02/14/2018 16:40:07;0008;Server@node2;Job;1251.node2.supernodexp.hpc;Job Modified at request of Scheduler@node2.supernodexp.hpc
02/14/2018 16:40:07;0100;Server@node2;Req;;Type 11 request received from Scheduler@node2.supernodexp.hpc, sock=20
02/14/2018 16:40:07;0008;Server@node2;Job;1252.node2.supernodexp.hpc;Job Modified at request of Scheduler@node2.supernodexp.hpc
02/14/2018 16:40:07;0100;Server@node2;Req;;Type 11 request received from Scheduler@node2.supernodexp.hpc, sock=20
02/14/2018 16:40:07;0008;Server@node2;Job;1253.node2.supernodexp.hpc;Job Modified at request of Scheduler@node2.supernodexp.hpc
02/14/2018 16:40:07;0100;Server@node2;Req;;Type 11 request received from Scheduler@node2.supernodexp.hpc, sock=20
02/14/2018 16:40:07;0008;Server@node2;Job;1254.node2.supernodexp.hpc;Job Modified at request of Scheduler@node2.supernodexp.hpc
02/14/2018 16:40:07;0100;Server@node2;Req;;Type 11 request received from Scheduler@node2.supernodexp.hpc, sock=20
02/14/2018 16:40:07;0008;Server@node2;Job;1255.node2.supernodexp.hpc;Job Modified at request of Scheduler@node2.supernodexp.hpc
02/14/2018 16:40:07;0100;Server@node2;Req;;Type 11 request received from Scheduler@node2.supernodexp.hpc, sock=20
02/14/2018 16:40:07;0008;Server@node2;Job;1256.node2.supernodexp.hpc;Job Modified at request of Scheduler@node2.supernodexp.hpc
02/14/2018 16:40:07;0100;Server@node2;Req;;Type 11 request received from Scheduler@node2.supernodexp.hpc, sock=20
02/14/2018 16:40:07;0008;Server@node2;Job;1257.node2.supernodexp.hpc;Job Modified at request of Scheduler@node2.supernodexp.hpc
02/14/2018 16:40:07;0100;Server@node2;Req;;Type 11 request received from Scheduler@node2.supernodexp.hpc, sock=20
02/14/2018 16:40:07;0008;Server@node2;Job;1259.node2.supernodexp.hpc;Job Modified at request of Scheduler@node2.supernodexp.hpc
02/14/2018 16:40:07;0100;Server@node2;Req;;Type 11 request received from Scheduler@node2.supernodexp.hpc, sock=20
02/14/2018 16:40:07;0008;Server@node2;Job;1260.node2.supernodexp.hpc;Job Modified at request of Scheduler@node2.supernodexp.hpc
02/14/2018 16:40:07;0100;Server@node2;Req;;Type 11 request received from Scheduler@node2.supernodexp.hpc, sock=20
02/14/2018 16:40:07;0008;Server@node2;Job;1261.node2.supernodexp.hpc;Job Modified at request of Scheduler@node2.supernodexp.hpc
02/14/2018 16:40:07;0100;Server@node2;Req;;Type 11 request received from Scheduler@node2.supernodexp.hpc, sock=20
02/14/2018 16:40:07;0008;Server@node2;Job;1263.node2.supernodexp.hpc;Job Modified at request of Scheduler@node2.supernodexp.hpc
02/14/2018 16:40:07;0100;Server@node2;Req;;Type 11 request received from Scheduler@node2.supernodexp.hpc, sock=20
02/14/2018 16:40:07;0008;Server@node2;Job;1264.node2.supernodexp.hpc;Job Modified at request of Scheduler@node2.supernodexp.hpc
02/14/2018 16:40:07;0100;Server@node2;Req;;Type 11 request received from Scheduler@node2.supernodexp.hpc, sock=20
02/14/2018 16:40:07;0008;Server@node2;Job;1265.node2.supernodexp.hpc;Job Modified at request of Scheduler@node2.supernodexp.hpc
02/14/2018 16:40:07;0100;Server@node2;Req;;Type 11 request received from Scheduler@node2.supernodexp.hpc, sock=20
02/14/2018 16:40:07;0008;Server@node2;Job;1266.node2.supernodexp.hpc;Job Modified at request of Scheduler@node2.supernodexp.hpc
02/14/2018 16:40:07;0100;Server@node2;Req;;Type 11 request received from Scheduler@node2.supernodexp.hpc, sock=20
02/14/2018 16:40:07;0008;Server@node2;Job;1267.node2.supernodexp.hpc;Job Modified at request of Scheduler@node2.supernodexp.hpc
02/14/2018 16:40:07;0100;Server@node2;Req;;Type 11 request received from Scheduler@node2.supernodexp.hpc, sock=20
02/14/2018 16:40:07;0008;Server@node2;Job;1268.node2.supernodexp.hpc;Job Modified at request of Scheduler@node2.supernodexp.hpc
02/14/2018 16:40:07;0100;Server@node2;Req;;Type 11 request received from Scheduler@node2.supernodexp.hpc, sock=20
02/14/2018 16:40:07;0008;Server@node2;Job;1269.node2.supernodexp.hpc;Job Modified at request of Scheduler@node2.supernodexp.hpc
02/14/2018 16:40:07;0100;Server@node2;Req;;Type 11 request received from Scheduler@node2.supernodexp.hpc, sock=20
02/14/2018 16:40:07;0008;Server@node2;Job;1270.node2.supernodexp.hpc;Job Modified at request of Scheduler@node2.supernodexp.hpc
02/14/2018 16:40:07;0100;Server@node2;Req;;Type 11 request received from Scheduler@node2.supernodexp.hpc, sock=20
02/14/2018 16:40:07;0008;Server@node2;Job;1272.node2.supernodexp.hpc;Job Modified at request of Scheduler@node2.supernodexp.hpc
02/14/2018 16:40:07;0100;Server@node2;Req;;Type 11 request received from Scheduler@node2.supernodexp.hpc, sock=20
02/14/2018 16:40:07;0008;Server@node2;Job;1273.node2.supernodexp.hpc;Job Modified at request of Scheduler@node2.supernodexp.hpc
02/14/2018 16:40:07;0100;Server@node2;Req;;Type 11 request received from Scheduler@node2.supernodexp.hpc, sock=20
02/14/2018 16:40:07;0008;Server@node2;Job;1274.node2.supernodexp.hpc;Job Modified at request of Scheduler@node2.supernodexp.hpc
02/14/2018 16:40:07;0100;Server@node2;Req;;Type 11 request received from Scheduler@node2.supernodexp.hpc, sock=20
02/14/2018 16:40:07;0008;Server@node2;Job;1276.node2.supernodexp.hpc;Job Modified at request of Scheduler@node2.supernodexp.hpc
02/14/2018 16:40:07;0100;Server@node2;Req;;Type 11 request received from Scheduler@node2.supernodexp.hpc, sock=20
02/14/2018 16:40:07;0008;Server@node2;Job;1278.node2.supernodexp.hpc;Job Modified at request of Scheduler@node2.supernodexp.hpc
02/14/2018 16:40:07;0100;Server@node2;Req;;Type 11 request received from Scheduler@node2.supernodexp.hpc, sock=20
02/14/2018 16:40:07;0008;Server@node2;Job;1279.node2.supernodexp.hpc;Job Modified at request of Scheduler@node2.supernodexp.hpc
02/14/2018 16:40:07;0100;Server@node2;Req;;Type 11 request received from Scheduler@node2.supernodexp.hpc, sock=20
02/14/2018 16:40:07;0008;Server@node2;Job;1280.node2.supernodexp.hpc;Job Modified at request of Scheduler@node2.supernodexp.hpc
02/14/2018 16:40:07;0100;Server@node2;Req;;Type 11 request received from Scheduler@node2.supernodexp.hpc, sock=20
02/14/2018 16:40:07;0008;Server@node2;Job;1281.node2.supernodexp.hpc;Job Modified at request of Scheduler@node2.supernodexp.hpc
02/14/2018 16:40:07;0100;Server@node2;Req;;Type 11 request received from Scheduler@node2.supernodexp.hpc, sock=20
02/14/2018 16:40:07;0008;Server@node2;Job;1282.node2.supernodexp.hpc;Job Modified at request of Scheduler@node2.supernodexp.hpc
02/14/2018 16:40:07;0100;Server@node2;Req;;Type 11 request received from Scheduler@node2.supernodexp.hpc, sock=20
02/14/2018 16:40:07;0008;Server@node2;Job;1283.node2.supernodexp.hpc;Job Modified at request of Scheduler@node2.supernodexp.hpc
02/14/2018 16:40:07;0100;Server@node2;Req;;Type 11 request received from Scheduler@node2.supernodexp.hpc, sock=20
02/14/2018 16:40:07;0008;Server@node2;Job;1284.node2.supernodexp.hpc;Job Modified at request of Scheduler@node2.supernodexp.hpc
02/14/2018 16:40:07;0100;Server@node2;Req;;Type 11 request received from Scheduler@node2.supernodexp.hpc, sock=20
02/14/2018 16:40:07;0008;Server@node2;Job;1285.node2.supernodexp.hpc;Job Modified at request of Scheduler@node2.supernodexp.hpc
02/14/2018 16:40:07;0100;Server@node2;Req;;Type 11 request received from Scheduler@node2.supernodexp.hpc, sock=20
02/14/2018 16:40:07;0008;Server@node2;Job;1286.node2.supernodexp.hpc;Job Modified at request of Scheduler@node2.supernodexp.hpc
02/14/2018 16:40:07;0100;Server@node2;Req;;Type 11 request received from Scheduler@node2.supernodexp.hpc, sock=20
02/14/2018 16:40:07;0008;Server@node2;Job;1287.node2.supernodexp.hpc;Job Modified at request of Scheduler@node2.supernodexp.hpc
02/14/2018 16:40:07;0100;Server@node2;Req;;Type 11 request received from Scheduler@node2.supernodexp.hpc, sock=20
02/14/2018 16:40:07;0008;Server@node2;Job;1288.node2.supernodexp.hpc;Job Modified at request of Scheduler@node2.supernodexp.hpc
02/14/2018 16:40:07;0100;Server@node2;Req;;Type 11 request received from Scheduler@node2.supernodexp.hpc, sock=20
02/14/2018 16:40:07;0008;Server@node2;Job;1289.node2.supernodexp.hpc;Job Modified at request of Scheduler@node2.supernodexp.hpc
02/14/2018 16:40:07;0100;Server@node2;Req;;Type 11 request received from Scheduler@node2.supernodexp.hpc, sock=20
02/14/2018 16:40:07;0008;Server@node2;Job;1290.node2.supernodexp.hpc;Job Modified at request of Scheduler@node2.supernodexp.hpc
02/14/2018 16:40:07;0100;Server@node2;Req;;Type 11 request received from Scheduler@node2.supernodexp.hpc, sock=20
02/14/2018 16:40:07;0008;Server@node2;Job;1291.node2.supernodexp.hpc;Job Modified at request of Scheduler@node2.supernodexp.hpc
02/14/2018 16:40:07;0100;Server@node2;Req;;Type 11 request received from Scheduler@node2.supernodexp.hpc, sock=20
02/14/2018 16:40:07;0008;Server@node2;Job;1292.node2.supernodexp.hpc;Job Modified at request of Scheduler@node2.supernodexp.hpc
02/14/2018 16:40:07;0100;Server@node2;Req;;Type 11 request received from Scheduler@node2.supernodexp.hpc, sock=20
02/14/2018 16:40:07;0008;Server@node2;Job;1293.node2.supernodexp.hpc;Job Modified at request of Scheduler@node2.supernodexp.hpc
02/14/2018 16:40:07;0100;Server@node2;Req;;Type 11 request received from Scheduler@node2.supernodexp.hpc, sock=20
02/14/2018 16:40:07;0008;Server@node2;Job;1295.node2.supernodexp.hpc;Job Modified at request of Scheduler@node2.supernodexp.hpc
02/14/2018 16:40:07;0100;Server@node2;Req;;Type 11 request received from Scheduler@node2.supernodexp.hpc, sock=20
02/14/2018 16:40:07;0008;Server@node2;Job;1296.node2.supernodexp.hpc;Job Modified at request of Scheduler@node2.supernodexp.hpc
02/14/2018 16:40:07;0100;Server@node2;Req;;Type 11 request received from Scheduler@node2.supernodexp.hpc, sock=20
02/14/2018 16:40:07;0008;Server@node2;Job;1351.node2.supernodexp.hpc;Job Modified at request of Scheduler@node2.supernodexp.hpc
02/14/2018 16:40:07;0100;Server@node2;Req;;Type 11 request received from Scheduler@node2.supernodexp.hpc, sock=20
02/14/2018 16:40:07;0008;Server@node2;Job;1352.node2.supernodexp.hpc;Job Modified at request of Scheduler@node2.supernodexp.hpc
02/14/2018 16:40:07;0040;Server@node2;Svr;node2.supernodexp.hpc;Scheduler sent command 1
02/14/2018 16:40:07;0040;Server@node2;Svr;node2.supernodexp.hpc;Scheduler sent command 0
02/14/2018 16:40:07;0100;Server@node2;Req;;Type 21 request received from Scheduler@node2.supernodexp.hpc, sock=20
02/14/2018 16:40:07;0100;Server@node2;Req;;Type 81 request received from Scheduler@node2.supernodexp.hpc, sock=20
02/14/2018 16:40:07;0100;Server@node2;Req;;Type 71 request received from Scheduler@node2.supernodexp.hpc, sock=20
02/14/2018 16:40:07;0100;Server@node2;Req;;Type 58 request received from Scheduler@node2.supernodexp.hpc, sock=20
02/14/2018 16:40:07;0100;Server@node2;Req;;Type 1 request received from ctminh@node2.supernodexp.hpc, sock=16
02/14/2018 16:40:07;0100;Server@node2;Req;;Type 20 request received from Scheduler@node2.supernodexp.hpc, sock=20
02/14/2018 16:40:07;0100;Server@node2;Req;;Type 3 request received from ctminh@node2.supernodexp.hpc, sock=16
02/14/2018 16:40:07;0100;Server@node2;Req;;Type 51 request received from Scheduler@node2.supernodexp.hpc, sock=20
02/14/2018 16:40:07;0100;Server@node2;Req;;Type 5 request received from ctminh@node2.supernodexp.hpc, sock=16
02/14/2018 16:40:07;0100;Server@node2;Job;1355.node2.supernodexp.hpc;enqueuing into workq, state 1 hop 1
02/14/2018 16:40:07;0008;Server@node2;Job;1355.node2.supernodexp.hpc;Job Queued at request of ctminh@node2.supernodexp.hpc, owner = ctminh@node2.supernodexp.hpc, job name = lu-decomp, queue = workq
02/14/2018 16:40:07;0100;Server@node2;Req;;Type 1 request received from ctminh@node2.supernodexp.hpc, sock=16
02/14/2018 16:40:07;0100;Server@node2;Req;;Type 3 request received from ctminh@node2.supernodexp.hpc, sock=16
02/14/2018 16:40:07;0100;Server@node2;Req;;Type 5 request received from ctminh@node2.supernodexp.hpc, sock=16
02/14/2018 16:40:07;0100;Server@node2;Job;1356.node2.supernodexp.hpc;enqueuing into workq, state 1 hop 1
02/14/2018 16:40:07;0008;Server@node2;Job;1356.node2.supernodexp.hpc;Job Queued at request of ctminh@node2.supernodexp.hpc, owner = ctminh@node2.supernodexp.hpc, job name = thread-affinity, queue = workq
02/14/2018 16:40:07;0100;Server@node2;Req;;Type 11 request received from Scheduler@node2.supernodexp.hpc, sock=20
02/14/2018 16:40:07;0008;Server@node2;Job;1353.node2.supernodexp.hpc;Job Modified at request of Scheduler@node2.supernodexp.hpc
02/14/2018 16:40:07;0100;Server@node2;Req;;Type 11 request received from Scheduler@node2.supernodexp.hpc, sock=20
02/14/2018 16:40:07;0008;Server@node2;Job;1354.node2.supernodexp.hpc;Job Modified at request of Scheduler@node2.supernodexp.hpc
02/14/2018 16:40:07;0040;Server@node2;Svr;node2.supernodexp.hpc;Scheduler sent command 1
02/14/2018 16:40:07;0040;Server@node2;Svr;node2.supernodexp.hpc;Scheduler sent command 0
02/14/2018 16:40:07;0100;Server@node2;Req;;Type 21 request received from Scheduler@node2.supernodexp.hpc, sock=20
02/14/2018 16:40:07;0100;Server@node2;Req;;Type 81 request received from Scheduler@node2.supernodexp.hpc, sock=20
02/14/2018 16:40:07;0100;Server@node2;Req;;Type 71 request received from Scheduler@node2.supernodexp.hpc, sock=20
02/14/2018 16:40:07;0100;Server@node2;Req;;Type 58 request received from Scheduler@node2.supernodexp.hpc, sock=20
02/14/2018 16:40:07;0100;Server@node2;Req;;Type 1 request received from ctminh@node2.supernodexp.hpc, sock=16
02/14/2018 16:40:07;0100;Server@node2;Req;;Type 3 request received from ctminh@node2.supernodexp.hpc, sock=16
02/14/2018 16:40:07;0100;Server@node2;Req;;Type 5 request received from ctminh@node2.supernodexp.hpc, sock=16
02/14/2018 16:40:07;0100;Server@node2;Job;1357.node2.supernodexp.hpc;enqueuing into workq, state 1 hop 1
02/14/2018 16:40:07;0008;Server@node2;Job;1357.node2.supernodexp.hpc;Job Queued at request of ctminh@node2.supernodexp.hpc, owner = ctminh@node2.supernodexp.hpc, job name = vast1, queue = workq
02/14/2018 16:40:07;0100;Server@node2;Req;;Type 20 request received from Scheduler@node2.supernodexp.hpc, sock=20
02/14/2018 16:40:07;0100;Server@node2;Req;;Type 51 request received from Scheduler@node2.supernodexp.hpc, sock=20
02/14/2018 16:40:07;0100;Server@node2;Req;;Type 1 request received from ctminh@node2.supernodexp.hpc, sock=16
02/14/2018 16:40:07;0100;Server@node2;Req;;Type 3 request received from ctminh@node2.supernodexp.hpc, sock=16
02/14/2018 16:40:07;0100;Server@node2;Req;;Type 5 request received from ctminh@node2.supernodexp.hpc, sock=16
02/14/2018 16:40:07;0100;Server@node2;Job;1358.node2.supernodexp.hpc;enqueuing into workq, state 1 hop 1
02/14/2018 16:40:07;0008;Server@node2;Job;1358.node2.supernodexp.hpc;Job Queued at request of ctminh@node2.supernodexp.hpc, owner = ctminh@node2.supernodexp.hpc, job name = telemac2, queue = workq
02/14/2018 16:40:07;0100;Server@node2;Req;;Type 11 request received from Scheduler@node2.supernodexp.hpc, sock=20
02/14/2018 16:40:07;0008;Server@node2;Job;1355.node2.supernodexp.hpc;Job Modified at request of Scheduler@node2.supernodexp.hpc
02/14/2018 16:40:07;0100;Server@node2;Req;;Type 11 request received from Scheduler@node2.supernodexp.hpc, sock=20
02/14/2018 16:40:07;0008;Server@node2;Job;1356.node2.supernodexp.hpc;Job Modified at request of Scheduler@node2.supernodexp.hpc
02/14/2018 16:40:07;0100;Server@node2;Req;;Type 11 request received from Scheduler@node2.supernodexp.hpc, sock=20
02/14/2018 16:40:07;0008;Server@node2;Job;1357.node2.supernodexp.hpc;Job Modified at request of Scheduler@node2.supernodexp.hpc
02/14/2018 16:40:07;0040;Server@node2;Svr;node2.supernodexp.hpc;Scheduler sent command 1
02/14/2018 16:40:07;0040;Server@node2;Svr;node2.supernodexp.hpc;Scheduler sent command 0
02/14/2018 16:40:07;0100;Server@node2;Req;;Type 21 request received from Scheduler@node2.supernodexp.hpc, sock=20
02/14/2018 16:40:07;0100;Server@node2;Req;;Type 81 request received from Scheduler@node2.supernodexp.hpc, sock=20
02/14/2018 16:40:07;0100;Server@node2;Req;;Type 71 request received from Scheduler@node2.supernodexp.hpc, sock=20
02/14/2018 16:40:07;0100;Server@node2;Req;;Type 58 request received from Scheduler@node2.supernodexp.hpc, sock=20
02/14/2018 16:40:07;0100;Server@node2;Req;;Type 1 request received from ctminh@node2.supernodexp.hpc, sock=16
02/14/2018 16:40:07;0100;Server@node2;Req;;Type 20 request received from Scheduler@node2.supernodexp.hpc, sock=20
02/14/2018 16:40:07;0100;Server@node2;Req;;Type 3 request received from ctminh@node2.supernodexp.hpc, sock=16
02/14/2018 16:40:07;0100;Server@node2;Req;;Type 51 request received from Scheduler@node2.supernodexp.hpc, sock=20
02/14/2018 16:40:07;0100;Server@node2;Req;;Type 5 request received from ctminh@node2.supernodexp.hpc, sock=16
02/14/2018 16:40:07;0100;Server@node2;Job;1359.node2.supernodexp.hpc;enqueuing into workq, state 1 hop 1
02/14/2018 16:40:07;0008;Server@node2;Job;1359.node2.supernodexp.hpc;Job Queued at request of ctminh@node2.supernodexp.hpc, owner = ctminh@node2.supernodexp.hpc, job name = histogram, queue = workq
02/14/2018 16:40:07;0100;Server@node2;Req;;Type 1 request received from ctminh@node2.supernodexp.hpc, sock=16
02/14/2018 16:40:07;0100;Server@node2;Req;;Type 3 request received from ctminh@node2.supernodexp.hpc, sock=16
02/14/2018 16:40:07;0100;Server@node2;Req;;Type 5 request received from ctminh@node2.supernodexp.hpc, sock=16
02/14/2018 16:40:07;0100;Server@node2;Job;1360.node2.supernodexp.hpc;enqueuing into workq, state 1 hop 1
02/14/2018 16:40:07;0008;Server@node2;Job;1360.node2.supernodexp.hpc;Job Queued at request of ctminh@node2.supernodexp.hpc, owner = ctminh@node2.supernodexp.hpc, job name = vast1, queue = workq
02/14/2018 16:40:07;0100;Server@node2;Req;;Type 11 request received from Scheduler@node2.supernodexp.hpc, sock=20
02/14/2018 16:40:07;0008;Server@node2;Job;1358.node2.supernodexp.hpc;Job Modified at request of Scheduler@node2.supernodexp.hpc
02/14/2018 16:40:07;0040;Server@node2;Svr;node2.supernodexp.hpc;Scheduler sent command 1
02/14/2018 16:40:07;0040;Server@node2;Svr;node2.supernodexp.hpc;Scheduler sent command 0
02/14/2018 16:40:07;0100;Server@node2;Req;;Type 21 request received from Scheduler@node2.supernodexp.hpc, sock=20
02/14/2018 16:40:07;0100;Server@node2;Req;;Type 81 request received from Scheduler@node2.supernodexp.hpc, sock=20
02/14/2018 16:40:07;0100;Server@node2;Req;;Type 71 request received from Scheduler@node2.supernodexp.hpc, sock=20
02/14/2018 16:40:07;0100;Server@node2;Req;;Type 58 request received from Scheduler@node2.supernodexp.hpc, sock=20
02/14/2018 16:40:07;0100;Server@node2;Req;;Type 1 request received from ctminh@node2.supernodexp.hpc, sock=16
02/14/2018 16:40:07;0100;Server@node2;Req;;Type 3 request received from ctminh@node2.supernodexp.hpc, sock=16
02/14/2018 16:40:07;0100;Server@node2;Req;;Type 5 request received from ctminh@node2.supernodexp.hpc, sock=16
02/14/2018 16:40:07;0100;Server@node2;Job;1361.node2.supernodexp.hpc;enqueuing into workq, state 1 hop 1
02/14/2018 16:40:07;0008;Server@node2;Job;1361.node2.supernodexp.hpc;Job Queued at request of ctminh@node2.supernodexp.hpc, owner = ctminh@node2.supernodexp.hpc, job name = vectorization, queue = workq
02/14/2018 16:40:07;0100;Server@node2;Req;;Type 20 request received from Scheduler@node2.supernodexp.hpc, sock=20
02/14/2018 16:40:07;0100;Server@node2;Req;;Type 51 request received from Scheduler@node2.supernodexp.hpc, sock=20
02/14/2018 16:40:07;0100;Server@node2;Req;;Type 1 request received from ctminh@node2.supernodexp.hpc, sock=16
02/14/2018 16:40:07;0100;Server@node2;Req;;Type 3 request received from ctminh@node2.supernodexp.hpc, sock=16
02/14/2018 16:40:07;0100;Server@node2;Req;;Type 5 request received from ctminh@node2.supernodexp.hpc, sock=16
02/14/2018 16:40:07;0100;Server@node2;Job;1362.node2.supernodexp.hpc;enqueuing into workq, state 1 hop 1
02/14/2018 16:40:07;0008;Server@node2;Job;1362.node2.supernodexp.hpc;Job Queued at request of ctminh@node2.supernodexp.hpc, owner = ctminh@node2.supernodexp.hpc, job name = telemac2, queue = workq
02/14/2018 16:40:07;0100;Server@node2;Req;;Type 11 request received from Scheduler@node2.supernodexp.hpc, sock=20
02/14/2018 16:40:07;0008;Server@node2;Job;1359.node2.supernodexp.hpc;Job Modified at request of Scheduler@node2.supernodexp.hpc
02/14/2018 16:40:07;0100;Server@node2;Req;;Type 11 request received from Scheduler@node2.supernodexp.hpc, sock=20
02/14/2018 16:40:07;0008;Server@node2;Job;1360.node2.supernodexp.hpc;Job Modified at request of Scheduler@node2.supernodexp.hpc
02/14/2018 16:40:07;0100;Server@node2;Req;;Type 11 request received from Scheduler@node2.supernodexp.hpc, sock=20
02/14/2018 16:40:07;0008;Server@node2;Job;1361.node2.supernodexp.hpc;Job Modified at request of Scheduler@node2.supernodexp.hpc
02/14/2018 16:40:07;0040;Server@node2;Svr;node2.supernodexp.hpc;Scheduler sent command 1
02/14/2018 16:40:07;0040;Server@node2;Svr;node2.supernodexp.hpc;Scheduler sent command 0
02/14/2018 16:40:07;0100;Server@node2;Req;;Type 21 request received from Scheduler@node2.supernodexp.hpc, sock=20
02/14/2018 16:40:07;0100;Server@node2;Req;;Type 81 request received from Scheduler@node2.supernodexp.hpc, sock=20
02/14/2018 16:40:07;0100;Server@node2;Req;;Type 71 request received from Scheduler@node2.supernodexp.hpc, sock=20
02/14/2018 16:40:07;0100;Server@node2;Req;;Type 58 request received from Scheduler@node2.supernodexp.hpc, sock=20
02/14/2018 16:40:07;0100;Server@node2;Req;;Type 1 request received from ctminh@node2.supernodexp.hpc, sock=16
02/14/2018 16:40:07;0100;Server@node2;Req;;Type 3 request received from ctminh@node2.supernodexp.hpc, sock=16
02/14/2018 16:40:07;0100;Server@node2;Req;;Type 5 request received from ctminh@node2.supernodexp.hpc, sock=16
02/14/2018 16:40:07;0100;Server@node2;Job;1363.node2.supernodexp.hpc;enqueuing into workq, state 1 hop 1
02/14/2018 16:40:07;0008;Server@node2;Job;1363.node2.supernodexp.hpc;Job Queued at request of ctminh@node2.supernodexp.hpc, owner = ctminh@node2.supernodexp.hpc, job name = telemac2, queue = workq
02/14/2018 16:40:07;0100;Server@node2;Req;;Type 20 request received from Scheduler@node2.supernodexp.hpc, sock=20
02/14/2018 16:40:07;0100;Server@node2;Req;;Type 51 request received from Scheduler@node2.supernodexp.hpc, sock=20
02/14/2018 16:40:07;0100;Server@node2;Req;;Type 1 request received from ctminh@node2.supernodexp.hpc, sock=16
02/14/2018 16:40:07;0100;Server@node2;Req;;Type 3 request received from ctminh@node2.supernodexp.hpc, sock=16
02/14/2018 16:40:07;0100;Server@node2;Req;;Type 5 request received from ctminh@node2.supernodexp.hpc, sock=16
02/14/2018 16:40:07;0100;Server@node2;Job;1364.node2.supernodexp.hpc;enqueuing into workq, state 1 hop 1
02/14/2018 16:40:07;0008;Server@node2;Job;1364.node2.supernodexp.hpc;Job Queued at request of ctminh@node2.supernodexp.hpc, owner = ctminh@node2.supernodexp.hpc, job name = vectorization, queue = workq
02/14/2018 16:40:07;0100;Server@node2;Req;;Type 11 request received from Scheduler@node2.supernodexp.hpc, sock=20
02/14/2018 16:40:07;0008;Server@node2;Job;1362.node2.supernodexp.hpc;Job Modified at request of Scheduler@node2.supernodexp.hpc
02/14/2018 16:40:07;0100;Server@node2;Req;;Type 11 request received from Scheduler@node2.supernodexp.hpc, sock=20
02/14/2018 16:40:07;0008;Server@node2;Job;1363.node2.supernodexp.hpc;Job Modified at request of Scheduler@node2.supernodexp.hpc
02/14/2018 16:40:07;0040;Server@node2;Svr;node2.supernodexp.hpc;Scheduler sent command 1
02/14/2018 16:40:07;0040;Server@node2;Svr;node2.supernodexp.hpc;Scheduler sent command 0
02/14/2018 16:40:07;0100;Server@node2;Req;;Type 21 request received from Scheduler@node2.supernodexp.hpc, sock=20
02/14/2018 16:40:07;0100;Server@node2;Req;;Type 81 request received from Scheduler@node2.supernodexp.hpc, sock=20
02/14/2018 16:40:07;0100;Server@node2;Req;;Type 71 request received from Scheduler@node2.supernodexp.hpc, sock=20
02/14/2018 16:40:07;0100;Server@node2;Req;;Type 58 request received from Scheduler@node2.supernodexp.hpc, sock=20
02/14/2018 16:40:07;0100;Server@node2;Req;;Type 1 request received from ctminh@node2.supernodexp.hpc, sock=16
02/14/2018 16:40:07;0100;Server@node2;Req;;Type 3 request received from ctminh@node2.supernodexp.hpc, sock=16
02/14/2018 16:40:07;0100;Server@node2;Req;;Type 5 request received from ctminh@node2.supernodexp.hpc, sock=16
02/14/2018 16:40:07;0100;Server@node2;Job;1365.node2.supernodexp.hpc;enqueuing into workq, state 1 hop 1
02/14/2018 16:40:07;0008;Server@node2;Job;1365.node2.supernodexp.hpc;Job Queued at request of ctminh@node2.supernodexp.hpc, owner = ctminh@node2.supernodexp.hpc, job name = sweep, queue = workq
02/14/2018 16:40:07;0100;Server@node2;Req;;Type 20 request received from Scheduler@node2.supernodexp.hpc, sock=20
02/14/2018 16:40:07;0100;Server@node2;Req;;Type 51 request received from Scheduler@node2.supernodexp.hpc, sock=20
02/14/2018 16:40:07;0100;Server@node2;Req;;Type 1 request received from ctminh@node2.supernodexp.hpc, sock=16
02/14/2018 16:40:07;0100;Server@node2;Req;;Type 3 request received from ctminh@node2.supernodexp.hpc, sock=16
02/14/2018 16:40:07;0100;Server@node2;Req;;Type 5 request received from ctminh@node2.supernodexp.hpc, sock=16
02/14/2018 16:40:07;0100;Server@node2;Job;1366.node2.supernodexp.hpc;enqueuing into workq, state 1 hop 1
02/14/2018 16:40:07;0008;Server@node2;Job;1366.node2.supernodexp.hpc;Job Queued at request of ctminh@node2.supernodexp.hpc, owner = ctminh@node2.supernodexp.hpc, job name = telemac3, queue = workq
02/14/2018 16:40:07;0100;Server@node2;Req;;Type 11 request received from Scheduler@node2.supernodexp.hpc, sock=20
02/14/2018 16:40:07;0008;Server@node2;Job;1364.node2.supernodexp.hpc;Job Modified at request of Scheduler@node2.supernodexp.hpc
02/14/2018 16:40:07;0100;Server@node2;Req;;Type 11 request received from Scheduler@node2.supernodexp.hpc, sock=20
02/14/2018 16:40:07;0008;Server@node2;Job;1365.node2.supernodexp.hpc;Job Modified at request of Scheduler@node2.supernodexp.hpc
02/14/2018 16:40:07;0040;Server@node2;Svr;node2.supernodexp.hpc;Scheduler sent command 1
02/14/2018 16:40:07;0040;Server@node2;Svr;node2.supernodexp.hpc;Scheduler sent command 0
02/14/2018 16:40:07;0100;Server@node2;Req;;Type 21 request received from Scheduler@node2.supernodexp.hpc, sock=20
02/14/2018 16:40:07;0100;Server@node2;Req;;Type 81 request received from Scheduler@node2.supernodexp.hpc, sock=20
02/14/2018 16:40:07;0100;Server@node2;Req;;Type 71 request received from Scheduler@node2.supernodexp.hpc, sock=20
02/14/2018 16:40:07;0100;Server@node2;Req;;Type 58 request received from Scheduler@node2.supernodexp.hpc, sock=20
02/14/2018 16:40:07;0100;Server@node2;Req;;Type 1 request received from ctminh@node2.supernodexp.hpc, sock=16
02/14/2018 16:40:07;0100;Server@node2;Req;;Type 3 request received from ctminh@node2.supernodexp.hpc, sock=16
02/14/2018 16:40:07;0100;Server@node2;Req;;Type 5 request received from ctminh@node2.supernodexp.hpc, sock=16
02/14/2018 16:40:07;0100;Server@node2;Job;1367.node2.supernodexp.hpc;enqueuing into workq, state 1 hop 1
02/14/2018 16:40:07;0008;Server@node2;Job;1367.node2.supernodexp.hpc;Job Queued at request of ctminh@node2.supernodexp.hpc, owner = ctminh@node2.supernodexp.hpc, job name = qe_mic_test, queue = workq
02/14/2018 16:40:07;0100;Server@node2;Req;;Type 20 request received from Scheduler@node2.supernodexp.hpc, sock=20
02/14/2018 16:40:07;0100;Server@node2;Req;;Type 51 request received from Scheduler@node2.supernodexp.hpc, sock=20
02/14/2018 16:40:07;0100;Server@node2;Req;;Type 1 request received from ctminh@node2.supernodexp.hpc, sock=16
02/14/2018 16:40:07;0100;Server@node2;Req;;Type 3 request received from ctminh@node2.supernodexp.hpc, sock=16
02/14/2018 16:40:07;0100;Server@node2;Req;;Type 5 request received from ctminh@node2.supernodexp.hpc, sock=16
02/14/2018 16:40:07;0100;Server@node2;Job;1368.node2.supernodexp.hpc;enqueuing into workq, state 1 hop 1
02/14/2018 16:40:07;0008;Server@node2;Job;1368.node2.supernodexp.hpc;Job Queued at request of ctminh@node2.supernodexp.hpc, owner = ctminh@node2.supernodexp.hpc, job name = matrix-x-vector, queue = workq
02/14/2018 16:40:07;0100;Server@node2;Req;;Type 1 request received from ctminh@node2.supernodexp.hpc, sock=16
02/14/2018 16:40:07;0100;Server@node2;Req;;Type 11 request received from Scheduler@node2.supernodexp.hpc, sock=20
02/14/2018 16:40:07;0008;Server@node2;Job;1366.node2.supernodexp.hpc;Job Modified at request of Scheduler@node2.supernodexp.hpc
02/14/2018 16:40:07;0100;Server@node2;Req;;Type 3 request received from ctminh@node2.supernodexp.hpc, sock=16
02/14/2018 16:40:07;0100;Server@node2;Req;;Type 5 request received from ctminh@node2.supernodexp.hpc, sock=16
02/14/2018 16:40:07;0100;Server@node2;Job;1369.node2.supernodexp.hpc;enqueuing into workq, state 1 hop 1
02/14/2018 16:40:07;0008;Server@node2;Job;1369.node2.supernodexp.hpc;Job Queued at request of ctminh@node2.supernodexp.hpc, owner = ctminh@node2.supernodexp.hpc, job name = vast1, queue = workq
02/14/2018 16:40:07;0100;Server@node2;Req;;Type 11 request received from Scheduler@node2.supernodexp.hpc, sock=20
02/14/2018 16:40:07;0008;Server@node2;Job;1367.node2.supernodexp.hpc;Job Modified at request of Scheduler@node2.supernodexp.hpc
02/14/2018 16:40:07;0040;Server@node2;Svr;node2.supernodexp.hpc;Scheduler sent command 1
02/14/2018 16:40:07;0040;Server@node2;Svr;node2.supernodexp.hpc;Scheduler sent command 0
02/14/2018 16:40:07;0100;Server@node2;Req;;Type 21 request received from Scheduler@node2.supernodexp.hpc, sock=20
02/14/2018 16:40:07;0100;Server@node2;Req;;Type 81 request received from Scheduler@node2.supernodexp.hpc, sock=20
02/14/2018 16:40:07;0100;Server@node2;Req;;Type 71 request received from Scheduler@node2.supernodexp.hpc, sock=20
02/14/2018 16:40:07;0100;Server@node2;Req;;Type 58 request received from Scheduler@node2.supernodexp.hpc, sock=20
02/14/2018 16:40:07;0100;Server@node2;Req;;Type 20 request received from Scheduler@node2.supernodexp.hpc, sock=20
02/14/2018 16:40:07;0100;Server@node2;Req;;Type 51 request received from Scheduler@node2.supernodexp.hpc, sock=20
02/14/2018 16:40:07;0100;Server@node2;Req;;Type 1 request received from ctminh@node2.supernodexp.hpc, sock=16
02/14/2018 16:40:07;0100;Server@node2;Req;;Type 3 request received from ctminh@node2.supernodexp.hpc, sock=16
02/14/2018 16:40:07;0100;Server@node2;Req;;Type 5 request received from ctminh@node2.supernodexp.hpc, sock=16
02/14/2018 16:40:07;0100;Server@node2;Job;1370.node2.supernodexp.hpc;enqueuing into workq, state 1 hop 1
02/14/2018 16:40:07;0008;Server@node2;Job;1370.node2.supernodexp.hpc;Job Queued at request of ctminh@node2.supernodexp.hpc, owner = ctminh@node2.supernodexp.hpc, job name = histogram, queue = workq
02/14/2018 16:40:07;0100;Server@node2;Req;;Type 11 request received from Scheduler@node2.supernodexp.hpc, sock=20
02/14/2018 16:40:07;0008;Server@node2;Job;1368.node2.supernodexp.hpc;Job Modified at request of Scheduler@node2.supernodexp.hpc
02/14/2018 16:40:07;0100;Server@node2;Req;;Type 11 request received from Scheduler@node2.supernodexp.hpc, sock=20
02/14/2018 16:40:07;0008;Server@node2;Job;1369.node2.supernodexp.hpc;Job Modified at request of Scheduler@node2.supernodexp.hpc
02/14/2018 16:40:07;0040;Server@node2;Svr;node2.supernodexp.hpc;Scheduler sent command 1
02/14/2018 16:40:07;0040;Server@node2;Svr;node2.supernodexp.hpc;Scheduler sent command 0
02/14/2018 16:40:07;0100;Server@node2;Req;;Type 21 request received from Scheduler@node2.supernodexp.hpc, sock=20
02/14/2018 16:40:07;0100;Server@node2;Req;;Type 81 request received from Scheduler@node2.supernodexp.hpc, sock=20
02/14/2018 16:40:07;0100;Server@node2;Req;;Type 71 request received from Scheduler@node2.supernodexp.hpc, sock=20
02/14/2018 16:40:07;0100;Server@node2;Req;;Type 58 request received from Scheduler@node2.supernodexp.hpc, sock=20
02/14/2018 16:40:07;0100;Server@node2;Req;;Type 20 request received from Scheduler@node2.supernodexp.hpc, sock=20
02/14/2018 16:40:07;0100;Server@node2;Req;;Type 51 request received from Scheduler@node2.supernodexp.hpc, sock=20
02/14/2018 16:40:07;0080;Server@node2;Job;1297.node2.supernodexp.hpc;Obit received momhop:1 serverhop:1 state:4 substate:42
02/14/2018 16:40:07;0100;Server@node2;Req;;Type 11 request received from Scheduler@node2.supernodexp.hpc, sock=20
02/14/2018 16:40:07;0008;Server@node2;Job;1370.node2.supernodexp.hpc;Job Modified at request of Scheduler@node2.supernodexp.hpc
02/14/2018 16:40:09;0010;Server@node2;Job;1297.node2.supernodexp.hpc;Exit_status=0 resources_used.cpupercent=548 resources_used.cput=00:00:11 resources_used.mem=0kb resources_used.ncpus=8 resources_used.vmem=0kb resources_used.walltime=00:00:02
02/14/2018 16:40:09;0100;Server@node2;Job;1297.node2.supernodexp.hpc;dequeuing from workq, state 5
02/14/2018 16:40:09;0040;Server@node2;Svr;node2.supernodexp.hpc;Scheduler sent command 2
02/14/2018 16:40:09;0040;Server@node2;Svr;node2.supernodexp.hpc;Scheduler sent command 0
02/14/2018 16:40:09;0100;Server@node2;Req;;Type 21 request received from Scheduler@node2.supernodexp.hpc, sock=20
02/14/2018 16:40:09;0100;Server@node2;Req;;Type 81 request received from Scheduler@node2.supernodexp.hpc, sock=20
02/14/2018 16:40:09;0100;Server@node2;Req;;Type 71 request received from Scheduler@node2.supernodexp.hpc, sock=20
02/14/2018 16:40:09;0100;Server@node2;Req;;Type 58 request received from Scheduler@node2.supernodexp.hpc, sock=20
02/14/2018 16:40:09;0100;Server@node2;Req;;Type 20 request received from Scheduler@node2.supernodexp.hpc, sock=20
02/14/2018 16:40:09;0100;Server@node2;Req;;Type 51 request received from Scheduler@node2.supernodexp.hpc, sock=20
02/14/2018 16:40:09;0100;Server@node2;Req;;Type 11 request received from Scheduler@node2.supernodexp.hpc, sock=20
02/14/2018 16:40:09;0008;Server@node2;Job;1209.node2.supernodexp.hpc;Job Modified at request of Scheduler@node2.supernodexp.hpc
02/14/2018 16:40:09;0100;Server@node2;Req;;Type 11 request received from Scheduler@node2.supernodexp.hpc, sock=20
02/14/2018 16:40:09;0008;Server@node2;Job;1211.node2.supernodexp.hpc;Job Modified at request of Scheduler@node2.supernodexp.hpc
02/14/2018 16:40:09;0100;Server@node2;Req;;Type 11 request received from Scheduler@node2.supernodexp.hpc, sock=20
02/14/2018 16:40:09;0008;Server@node2;Job;1212.node2.supernodexp.hpc;Job Modified at request of Scheduler@node2.supernodexp.hpc
02/14/2018 16:40:09;0100;Server@node2;Req;;Type 11 request received from Scheduler@node2.supernodexp.hpc, sock=20
02/14/2018 16:40:09;0008;Server@node2;Job;1213.node2.supernodexp.hpc;Job Modified at request of Scheduler@node2.supernodexp.hpc
02/14/2018 16:40:09;0100;Server@node2;Req;;Type 11 request received from Scheduler@node2.supernodexp.hpc, sock=20
02/14/2018 16:40:09;0008;Server@node2;Job;1216.node2.supernodexp.hpc;Job Modified at request of Scheduler@node2.supernodexp.hpc
02/14/2018 16:40:09;0100;Server@node2;Req;;Type 11 request received from Scheduler@node2.supernodexp.hpc, sock=20
02/14/2018 16:40:09;0008;Server@node2;Job;1218.node2.supernodexp.hpc;Job Modified at request of Scheduler@node2.supernodexp.hpc
02/14/2018 16:40:09;0100;Server@node2;Req;;Type 11 request received from Scheduler@node2.supernodexp.hpc, sock=20
02/14/2018 16:40:09;0008;Server@node2;Job;1219.node2.supernodexp.hpc;Job Modified at request of Scheduler@node2.supernodexp.hpc
02/14/2018 16:40:09;0100;Server@node2;Req;;Type 11 request received from Scheduler@node2.supernodexp.hpc, sock=20
02/14/2018 16:40:09;0008;Server@node2;Job;1220.node2.supernodexp.hpc;Job Modified at request of Scheduler@node2.supernodexp.hpc
02/14/2018 16:40:09;0100;Server@node2;Req;;Type 11 request received from Scheduler@node2.supernodexp.hpc, sock=20
02/14/2018 16:40:09;0008;Server@node2;Job;1221.node2.supernodexp.hpc;Job Modified at request of Scheduler@node2.supernodexp.hpc
02/14/2018 16:40:09;0100;Server@node2;Req;;Type 11 request received from Scheduler@node2.supernodexp.hpc, sock=20
02/14/2018 16:40:09;0008;Server@node2;Job;1222.node2.supernodexp.hpc;Job Modified at request of Scheduler@node2.supernodexp.hpc
02/14/2018 16:40:09;0100;Server@node2;Req;;Type 11 request received from Scheduler@node2.supernodexp.hpc, sock=20
02/14/2018 16:40:09;0008;Server@node2;Job;1224.node2.supernodexp.hpc;Job Modified at request of Scheduler@node2.supernodexp.hpc
02/14/2018 16:40:09;0100;Server@node2;Req;;Type 11 request received from Scheduler@node2.supernodexp.hpc, sock=20
02/14/2018 16:40:09;0008;Server@node2;Job;1225.node2.supernodexp.hpc;Job Modified at request of Scheduler@node2.supernodexp.hpc
02/14/2018 16:40:09;0100;Server@node2;Req;;Type 11 request received from Scheduler@node2.supernodexp.hpc, sock=20
02/14/2018 16:40:09;0008;Server@node2;Job;1226.node2.supernodexp.hpc;Job Modified at request of Scheduler@node2.supernodexp.hpc
02/14/2018 16:40:09;0100;Server@node2;Req;;Type 11 request received from Scheduler@node2.supernodexp.hpc, sock=20
02/14/2018 16:40:09;0008;Server@node2;Job;1227.node2.supernodexp.hpc;Job Modified at request of Scheduler@node2.supernodexp.hpc
02/14/2018 16:40:09;0100;Server@node2;Req;;Type 11 request received from Scheduler@node2.supernodexp.hpc, sock=20
02/14/2018 16:40:09;0008;Server@node2;Job;1228.node2.supernodexp.hpc;Job Modified at request of Scheduler@node2.supernodexp.hpc
02/14/2018 16:40:09;0100;Server@node2;Req;;Type 11 request received from Scheduler@node2.supernodexp.hpc, sock=20
02/14/2018 16:40:09;0008;Server@node2;Job;1229.node2.supernodexp.hpc;Job Modified at request of Scheduler@node2.supernodexp.hpc
02/14/2018 16:40:09;0100;Server@node2;Req;;Type 11 request received from Scheduler@node2.supernodexp.hpc, sock=20
02/14/2018 16:40:09;0008;Server@node2;Job;1231.node2.supernodexp.hpc;Job Modified at request of Scheduler@node2.supernodexp.hpc
02/14/2018 16:40:09;0100;Server@node2;Req;;Type 11 request received from Scheduler@node2.supernodexp.hpc, sock=20
02/14/2018 16:40:09;0008;Server@node2;Job;1233.node2.supernodexp.hpc;Job Modified at request of Scheduler@node2.supernodexp.hpc
02/14/2018 16:40:09;0100;Server@node2;Req;;Type 11 request received from Scheduler@node2.supernodexp.hpc, sock=20
02/14/2018 16:40:09;0008;Server@node2;Job;1234.node2.supernodexp.hpc;Job Modified at request of Scheduler@node2.supernodexp.hpc
02/14/2018 16:40:09;0100;Server@node2;Req;;Type 11 request received from Scheduler@node2.supernodexp.hpc, sock=20
02/14/2018 16:40:09;0008;Server@node2;Job;1235.node2.supernodexp.hpc;Job Modified at request of Scheduler@node2.supernodexp.hpc
02/14/2018 16:40:09;0100;Server@node2;Req;;Type 11 request received from Scheduler@node2.supernodexp.hpc, sock=20
02/14/2018 16:40:09;0008;Server@node2;Job;1236.node2.supernodexp.hpc;Job Modified at request of Scheduler@node2.supernodexp.hpc
02/14/2018 16:40:09;0100;Server@node2;Req;;Type 11 request received from Scheduler@node2.supernodexp.hpc, sock=20
02/14/2018 16:40:09;0008;Server@node2;Job;1238.node2.supernodexp.hpc;Job Modified at request of Scheduler@node2.supernodexp.hpc
02/14/2018 16:40:09;0100;Server@node2;Req;;Type 11 request received from Scheduler@node2.supernodexp.hpc, sock=20
02/14/2018 16:40:09;0008;Server@node2;Job;1239.node2.supernodexp.hpc;Job Modified at request of Scheduler@node2.supernodexp.hpc
02/14/2018 16:40:09;0100;Server@node2;Req;;Type 11 request received from Scheduler@node2.supernodexp.hpc, sock=20
02/14/2018 16:40:09;0008;Server@node2;Job;1240.node2.supernodexp.hpc;Job Modified at request of Scheduler@node2.supernodexp.hpc
02/14/2018 16:40:09;0100;Server@node2;Req;;Type 11 request received from Scheduler@node2.supernodexp.hpc, sock=20
02/14/2018 16:40:09;0008;Server@node2;Job;1241.node2.supernodexp.hpc;Job Modified at request of Scheduler@node2.supernodexp.hpc
02/14/2018 16:40:09;0100;Server@node2;Req;;Type 11 request received from Scheduler@node2.supernodexp.hpc, sock=20
02/14/2018 16:40:09;0008;Server@node2;Job;1242.node2.supernodexp.hpc;Job Modified at request of Scheduler@node2.supernodexp.hpc
02/14/2018 16:40:09;0100;Server@node2;Req;;Type 11 request received from Scheduler@node2.supernodexp.hpc, sock=20
02/14/2018 16:40:09;0008;Server@node2;Job;1243.node2.supernodexp.hpc;Job Modified at request of Scheduler@node2.supernodexp.hpc
02/14/2018 16:40:09;0100;Server@node2;Req;;Type 11 request received from Scheduler@node2.supernodexp.hpc, sock=20
02/14/2018 16:40:09;0008;Server@node2;Job;1245.node2.supernodexp.hpc;Job Modified at request of Scheduler@node2.supernodexp.hpc
02/14/2018 16:40:09;0100;Server@node2;Req;;Type 11 request received from Scheduler@node2.supernodexp.hpc, sock=20
02/14/2018 16:40:09;0008;Server@node2;Job;1246.node2.supernodexp.hpc;Job Modified at request of Scheduler@node2.supernodexp.hpc
02/14/2018 16:40:09;0100;Server@node2;Req;;Type 11 request received from Scheduler@node2.supernodexp.hpc, sock=20
02/14/2018 16:40:09;0008;Server@node2;Job;1248.node2.supernodexp.hpc;Job Modified at request of Scheduler@node2.supernodexp.hpc
02/14/2018 16:40:09;0100;Server@node2;Req;;Type 11 request received from Scheduler@node2.supernodexp.hpc, sock=20
02/14/2018 16:40:09;0008;Server@node2;Job;1249.node2.supernodexp.hpc;Job Modified at request of Scheduler@node2.supernodexp.hpc
02/14/2018 16:40:09;0100;Server@node2;Req;;Type 11 request received from Scheduler@node2.supernodexp.hpc, sock=20
02/14/2018 16:40:09;0008;Server@node2;Job;1250.node2.supernodexp.hpc;Job Modified at request of Scheduler@node2.supernodexp.hpc
02/14/2018 16:40:09;0100;Server@node2;Req;;Type 11 request received from Scheduler@node2.supernodexp.hpc, sock=20
02/14/2018 16:40:09;0008;Server@node2;Job;1251.node2.supernodexp.hpc;Job Modified at request of Scheduler@node2.supernodexp.hpc
02/14/2018 16:40:09;0100;Server@node2;Req;;Type 11 request received from Scheduler@node2.supernodexp.hpc, sock=20
02/14/2018 16:40:09;0008;Server@node2;Job;1252.node2.supernodexp.hpc;Job Modified at request of Scheduler@node2.supernodexp.hpc
02/14/2018 16:40:09;0100;Server@node2;Req;;Type 11 request received from Scheduler@node2.supernodexp.hpc, sock=20
02/14/2018 16:40:09;0008;Server@node2;Job;1253.node2.supernodexp.hpc;Job Modified at request of Scheduler@node2.supernodexp.hpc
02/14/2018 16:40:09;0100;Server@node2;Req;;Type 11 request received from Scheduler@node2.supernodexp.hpc, sock=20
02/14/2018 16:40:09;0008;Server@node2;Job;1254.node2.supernodexp.hpc;Job Modified at request of Scheduler@node2.supernodexp.hpc
02/14/2018 16:40:09;0100;Server@node2;Req;;Type 11 request received from Scheduler@node2.supernodexp.hpc, sock=20
02/14/2018 16:40:09;0008;Server@node2;Job;1255.node2.supernodexp.hpc;Job Modified at request of Scheduler@node2.supernodexp.hpc
02/14/2018 16:40:09;0100;Server@node2;Req;;Type 11 request received from Scheduler@node2.supernodexp.hpc, sock=20
02/14/2018 16:40:09;0008;Server@node2;Job;1256.node2.supernodexp.hpc;Job Modified at request of Scheduler@node2.supernodexp.hpc
02/14/2018 16:40:09;0100;Server@node2;Req;;Type 11 request received from Scheduler@node2.supernodexp.hpc, sock=20
02/14/2018 16:40:09;0008;Server@node2;Job;1257.node2.supernodexp.hpc;Job Modified at request of Scheduler@node2.supernodexp.hpc
02/14/2018 16:40:09;0100;Server@node2;Req;;Type 11 request received from Scheduler@node2.supernodexp.hpc, sock=20
02/14/2018 16:40:09;0008;Server@node2;Job;1259.node2.supernodexp.hpc;Job Modified at request of Scheduler@node2.supernodexp.hpc
02/14/2018 16:40:09;0100;Server@node2;Req;;Type 11 request received from Scheduler@node2.supernodexp.hpc, sock=20
02/14/2018 16:40:09;0008;Server@node2;Job;1260.node2.supernodexp.hpc;Job Modified at request of Scheduler@node2.supernodexp.hpc
02/14/2018 16:40:09;0100;Server@node2;Req;;Type 11 request received from Scheduler@node2.supernodexp.hpc, sock=20
02/14/2018 16:40:09;0008;Server@node2;Job;1261.node2.supernodexp.hpc;Job Modified at request of Scheduler@node2.supernodexp.hpc
02/14/2018 16:40:09;0100;Server@node2;Req;;Type 11 request received from Scheduler@node2.supernodexp.hpc, sock=20
02/14/2018 16:40:09;0008;Server@node2;Job;1263.node2.supernodexp.hpc;Job Modified at request of Scheduler@node2.supernodexp.hpc
02/14/2018 16:40:09;0100;Server@node2;Req;;Type 11 request received from Scheduler@node2.supernodexp.hpc, sock=20
02/14/2018 16:40:09;0008;Server@node2;Job;1264.node2.supernodexp.hpc;Job Modified at request of Scheduler@node2.supernodexp.hpc
02/14/2018 16:40:09;0100;Server@node2;Req;;Type 11 request received from Scheduler@node2.supernodexp.hpc, sock=20
02/14/2018 16:40:09;0008;Server@node2;Job;1265.node2.supernodexp.hpc;Job Modified at request of Scheduler@node2.supernodexp.hpc
02/14/2018 16:40:09;0100;Server@node2;Req;;Type 11 request received from Scheduler@node2.supernodexp.hpc, sock=20
02/14/2018 16:40:09;0008;Server@node2;Job;1266.node2.supernodexp.hpc;Job Modified at request of Scheduler@node2.supernodexp.hpc
02/14/2018 16:40:09;0100;Server@node2;Req;;Type 11 request received from Scheduler@node2.supernodexp.hpc, sock=20
02/14/2018 16:40:09;0008;Server@node2;Job;1267.node2.supernodexp.hpc;Job Modified at request of Scheduler@node2.supernodexp.hpc
02/14/2018 16:40:09;0100;Server@node2;Req;;Type 11 request received from Scheduler@node2.supernodexp.hpc, sock=20
02/14/2018 16:40:09;0008;Server@node2;Job;1268.node2.supernodexp.hpc;Job Modified at request of Scheduler@node2.supernodexp.hpc
02/14/2018 16:40:09;0100;Server@node2;Req;;Type 11 request received from Scheduler@node2.supernodexp.hpc, sock=20
02/14/2018 16:40:09;0008;Server@node2;Job;1269.node2.supernodexp.hpc;Job Modified at request of Scheduler@node2.supernodexp.hpc
02/14/2018 16:40:09;0100;Server@node2;Req;;Type 11 request received from Scheduler@node2.supernodexp.hpc, sock=20
02/14/2018 16:40:09;0008;Server@node2;Job;1270.node2.supernodexp.hpc;Job Modified at request of Scheduler@node2.supernodexp.hpc
02/14/2018 16:40:09;0100;Server@node2;Req;;Type 11 request received from Scheduler@node2.supernodexp.hpc, sock=20
02/14/2018 16:40:09;0008;Server@node2;Job;1272.node2.supernodexp.hpc;Job Modified at request of Scheduler@node2.supernodexp.hpc
02/14/2018 16:40:09;0100;Server@node2;Req;;Type 11 request received from Scheduler@node2.supernodexp.hpc, sock=20
02/14/2018 16:40:09;0008;Server@node2;Job;1273.node2.supernodexp.hpc;Job Modified at request of Scheduler@node2.supernodexp.hpc
02/14/2018 16:40:09;0100;Server@node2;Req;;Type 11 request received from Scheduler@node2.supernodexp.hpc, sock=20
02/14/2018 16:40:09;0008;Server@node2;Job;1274.node2.supernodexp.hpc;Job Modified at request of Scheduler@node2.supernodexp.hpc
02/14/2018 16:40:09;0100;Server@node2;Req;;Type 11 request received from Scheduler@node2.supernodexp.hpc, sock=20
02/14/2018 16:40:09;0008;Server@node2;Job;1276.node2.supernodexp.hpc;Job Modified at request of Scheduler@node2.supernodexp.hpc
02/14/2018 16:40:09;0100;Server@node2;Req;;Type 11 request received from Scheduler@node2.supernodexp.hpc, sock=20
02/14/2018 16:40:09;0008;Server@node2;Job;1278.node2.supernodexp.hpc;Job Modified at request of Scheduler@node2.supernodexp.hpc
02/14/2018 16:40:09;0100;Server@node2;Req;;Type 11 request received from Scheduler@node2.supernodexp.hpc, sock=20
02/14/2018 16:40:09;0008;Server@node2;Job;1279.node2.supernodexp.hpc;Job Modified at request of Scheduler@node2.supernodexp.hpc
02/14/2018 16:40:09;0100;Server@node2;Req;;Type 11 request received from Scheduler@node2.supernodexp.hpc, sock=20
02/14/2018 16:40:09;0008;Server@node2;Job;1280.node2.supernodexp.hpc;Job Modified at request of Scheduler@node2.supernodexp.hpc
02/14/2018 16:40:09;0100;Server@node2;Req;;Type 11 request received from Scheduler@node2.supernodexp.hpc, sock=20
02/14/2018 16:40:09;0008;Server@node2;Job;1281.node2.supernodexp.hpc;Job Modified at request of Scheduler@node2.supernodexp.hpc
02/14/2018 16:40:09;0100;Server@node2;Req;;Type 11 request received from Scheduler@node2.supernodexp.hpc, sock=20
02/14/2018 16:40:09;0008;Server@node2;Job;1282.node2.supernodexp.hpc;Job Modified at request of Scheduler@node2.supernodexp.hpc
02/14/2018 16:40:09;0100;Server@node2;Req;;Type 11 request received from Scheduler@node2.supernodexp.hpc, sock=20
02/14/2018 16:40:09;0008;Server@node2;Job;1283.node2.supernodexp.hpc;Job Modified at request of Scheduler@node2.supernodexp.hpc
02/14/2018 16:40:09;0100;Server@node2;Req;;Type 11 request received from Scheduler@node2.supernodexp.hpc, sock=20
02/14/2018 16:40:09;0008;Server@node2;Job;1284.node2.supernodexp.hpc;Job Modified at request of Scheduler@node2.supernodexp.hpc
02/14/2018 16:40:09;0100;Server@node2;Req;;Type 11 request received from Scheduler@node2.supernodexp.hpc, sock=20
02/14/2018 16:40:09;0008;Server@node2;Job;1285.node2.supernodexp.hpc;Job Modified at request of Scheduler@node2.supernodexp.hpc
02/14/2018 16:40:09;0100;Server@node2;Req;;Type 11 request received from Scheduler@node2.supernodexp.hpc, sock=20
02/14/2018 16:40:09;0008;Server@node2;Job;1286.node2.supernodexp.hpc;Job Modified at request of Scheduler@node2.supernodexp.hpc
02/14/2018 16:40:09;0100;Server@node2;Req;;Type 11 request received from Scheduler@node2.supernodexp.hpc, sock=20
02/14/2018 16:40:09;0008;Server@node2;Job;1287.node2.supernodexp.hpc;Job Modified at request of Scheduler@node2.supernodexp.hpc
02/14/2018 16:40:09;0100;Server@node2;Req;;Type 11 request received from Scheduler@node2.supernodexp.hpc, sock=20
02/14/2018 16:40:09;0008;Server@node2;Job;1288.node2.supernodexp.hpc;Job Modified at request of Scheduler@node2.supernodexp.hpc
02/14/2018 16:40:09;0100;Server@node2;Req;;Type 11 request received from Scheduler@node2.supernodexp.hpc, sock=20
02/14/2018 16:40:09;0008;Server@node2;Job;1289.node2.supernodexp.hpc;Job Modified at request of Scheduler@node2.supernodexp.hpc
02/14/2018 16:40:09;0100;Server@node2;Req;;Type 11 request received from Scheduler@node2.supernodexp.hpc, sock=20
02/14/2018 16:40:09;0008;Server@node2;Job;1290.node2.supernodexp.hpc;Job Modified at request of Scheduler@node2.supernodexp.hpc
02/14/2018 16:40:09;0100;Server@node2;Req;;Type 11 request received from Scheduler@node2.supernodexp.hpc, sock=20
02/14/2018 16:40:09;0008;Server@node2;Job;1291.node2.supernodexp.hpc;Job Modified at request of Scheduler@node2.supernodexp.hpc
02/14/2018 16:40:09;0100;Server@node2;Req;;Type 11 request received from Scheduler@node2.supernodexp.hpc, sock=20
02/14/2018 16:40:09;0008;Server@node2;Job;1292.node2.supernodexp.hpc;Job Modified at request of Scheduler@node2.supernodexp.hpc
02/14/2018 16:40:09;0100;Server@node2;Req;;Type 11 request received from Scheduler@node2.supernodexp.hpc, sock=20
02/14/2018 16:40:09;0008;Server@node2;Job;1293.node2.supernodexp.hpc;Job Modified at request of Scheduler@node2.supernodexp.hpc
02/14/2018 16:40:09;0100;Server@node2;Req;;Type 11 request received from Scheduler@node2.supernodexp.hpc, sock=20
02/14/2018 16:40:09;0008;Server@node2;Job;1295.node2.supernodexp.hpc;Job Modified at request of Scheduler@node2.supernodexp.hpc
02/14/2018 16:40:09;0100;Server@node2;Req;;Type 11 request received from Scheduler@node2.supernodexp.hpc, sock=20
02/14/2018 16:40:09;0008;Server@node2;Job;1296.node2.supernodexp.hpc;Job Modified at request of Scheduler@node2.supernodexp.hpc
02/14/2018 16:40:09;0100;Server@node2;Req;;Type 11 request received from Scheduler@node2.supernodexp.hpc, sock=20
02/14/2018 16:40:09;0008;Server@node2;Job;1298.node2.supernodexp.hpc;Job Modified at request of Scheduler@node2.supernodexp.hpc
02/14/2018 16:40:09;0100;Server@node2;Req;;Type 11 request received from Scheduler@node2.supernodexp.hpc, sock=20
02/14/2018 16:40:09;0008;Server@node2;Job;1299.node2.supernodexp.hpc;Job Modified at request of Scheduler@node2.supernodexp.hpc
02/14/2018 16:40:09;0100;Server@node2;Req;;Type 11 request received from Scheduler@node2.supernodexp.hpc, sock=20
02/14/2018 16:40:09;0008;Server@node2;Job;1300.node2.supernodexp.hpc;Job Modified at request of Scheduler@node2.supernodexp.hpc
02/14/2018 16:40:09;0100;Server@node2;Req;;Type 11 request received from Scheduler@node2.supernodexp.hpc, sock=20
02/14/2018 16:40:09;0008;Server@node2;Job;1301.node2.supernodexp.hpc;Job Modified at request of Scheduler@node2.supernodexp.hpc
02/14/2018 16:40:09;0100;Server@node2;Req;;Type 11 request received from Scheduler@node2.supernodexp.hpc, sock=20
02/14/2018 16:40:09;0008;Server@node2;Job;1302.node2.supernodexp.hpc;Job Modified at request of Scheduler@node2.supernodexp.hpc
02/14/2018 16:40:09;0100;Server@node2;Req;;Type 11 request received from Scheduler@node2.supernodexp.hpc, sock=20
02/14/2018 16:40:09;0008;Server@node2;Job;1303.node2.supernodexp.hpc;Job Modified at request of Scheduler@node2.supernodexp.hpc
02/14/2018 16:40:09;0100;Server@node2;Req;;Type 11 request received from Scheduler@node2.supernodexp.hpc, sock=20
02/14/2018 16:40:09;0008;Server@node2;Job;1304.node2.supernodexp.hpc;Job Modified at request of Scheduler@node2.supernodexp.hpc
02/14/2018 16:40:09;0100;Server@node2;Req;;Type 11 request received from Scheduler@node2.supernodexp.hpc, sock=20
02/14/2018 16:40:09;0008;Server@node2;Job;1305.node2.supernodexp.hpc;Job Modified at request of Scheduler@node2.supernodexp.hpc
02/14/2018 16:40:09;0100;Server@node2;Req;;Type 23 request received from Scheduler@node2.supernodexp.hpc, sock=20
02/14/2018 16:40:09;0008;Server@node2;Job;1306.node2.supernodexp.hpc;Job Run at request of Scheduler@node2.supernodexp.hpc on exec_vnode (node14:ncpus=8:mem=3145728kb)
02/14/2018 16:40:09;0001;Server@node2;Svr;Server@node2;Success (0) in req_runjob2, return value of svr_startjob is 0
02/14/2018 16:40:10;0080;Server@node2;Job;1306.node2.supernodexp.hpc;Obit received momhop:1 serverhop:1 state:4 substate:42
02/14/2018 16:40:12;0010;Server@node2;Job;1306.node2.supernodexp.hpc;Exit_status=0 resources_used.cpupercent=800 resources_used.cput=00:00:09 resources_used.mem=0kb resources_used.ncpus=8 resources_used.vmem=0kb resources_used.walltime=00:00:02
02/14/2018 16:40:12;0100;Server@node2;Job;1306.node2.supernodexp.hpc;dequeuing from workq, state 5
02/14/2018 16:40:12;0040;Server@node2;Svr;node2.supernodexp.hpc;Scheduler sent command 2
02/14/2018 16:40:12;0040;Server@node2;Svr;node2.supernodexp.hpc;Scheduler sent command 0
02/14/2018 16:40:12;0100;Server@node2;Req;;Type 21 request received from Scheduler@node2.supernodexp.hpc, sock=20
02/14/2018 16:40:12;0100;Server@node2;Req;;Type 81 request received from Scheduler@node2.supernodexp.hpc, sock=20
02/14/2018 16:40:12;0100;Server@node2;Req;;Type 71 request received from Scheduler@node2.supernodexp.hpc, sock=20
02/14/2018 16:40:12;0100;Server@node2;Req;;Type 58 request received from Scheduler@node2.supernodexp.hpc, sock=20
02/14/2018 16:40:12;0100;Server@node2;Req;;Type 20 request received from Scheduler@node2.supernodexp.hpc, sock=20
02/14/2018 16:40:12;0100;Server@node2;Req;;Type 51 request received from Scheduler@node2.supernodexp.hpc, sock=20
02/14/2018 16:40:12;0100;Server@node2;Req;;Type 11 request received from Scheduler@node2.supernodexp.hpc, sock=20
02/14/2018 16:40:12;0008;Server@node2;Job;1307.node2.supernodexp.hpc;Job Modified at request of Scheduler@node2.supernodexp.hpc
02/14/2018 16:40:12;0100;Server@node2;Req;;Type 11 request received from Scheduler@node2.supernodexp.hpc, sock=20
02/14/2018 16:40:12;0008;Server@node2;Job;1308.node2.supernodexp.hpc;Job Modified at request of Scheduler@node2.supernodexp.hpc
02/14/2018 16:40:12;0100;Server@node2;Req;;Type 11 request received from Scheduler@node2.supernodexp.hpc, sock=20
02/14/2018 16:40:12;0008;Server@node2;Job;1309.node2.supernodexp.hpc;Job Modified at request of Scheduler@node2.supernodexp.hpc
02/14/2018 16:40:12;0100;Server@node2;Req;;Type 11 request received from Scheduler@node2.supernodexp.hpc, sock=20
02/14/2018 16:40:12;0008;Server@node2;Job;1310.node2.supernodexp.hpc;Job Modified at request of Scheduler@node2.supernodexp.hpc
02/14/2018 16:40:12;0100;Server@node2;Req;;Type 11 request received from Scheduler@node2.supernodexp.hpc, sock=20
02/14/2018 16:40:12;0008;Server@node2;Job;1311.node2.supernodexp.hpc;Job Modified at request of Scheduler@node2.supernodexp.hpc
02/14/2018 16:40:12;0100;Server@node2;Req;;Type 11 request received from Scheduler@node2.supernodexp.hpc, sock=20
02/14/2018 16:40:12;0008;Server@node2;Job;1312.node2.supernodexp.hpc;Job Modified at request of Scheduler@node2.supernodexp.hpc
02/14/2018 16:40:12;0100;Server@node2;Req;;Type 11 request received from Scheduler@node2.supernodexp.hpc, sock=20
02/14/2018 16:40:12;0008;Server@node2;Job;1313.node2.supernodexp.hpc;Job Modified at request of Scheduler@node2.supernodexp.hpc
02/14/2018 16:40:12;0100;Server@node2;Req;;Type 11 request received from Scheduler@node2.supernodexp.hpc, sock=20
02/14/2018 16:40:12;0008;Server@node2;Job;1314.node2.supernodexp.hpc;Job Modified at request of Scheduler@node2.supernodexp.hpc
02/14/2018 16:40:12;0100;Server@node2;Req;;Type 11 request received from Scheduler@node2.supernodexp.hpc, sock=20
02/14/2018 16:40:12;0008;Server@node2;Job;1315.node2.supernodexp.hpc;Job Modified at request of Scheduler@node2.supernodexp.hpc
02/14/2018 16:40:12;0100;Server@node2;Req;;Type 11 request received from Scheduler@node2.supernodexp.hpc, sock=20
02/14/2018 16:40:12;0008;Server@node2;Job;1316.node2.supernodexp.hpc;Job Modified at request of Scheduler@node2.supernodexp.hpc
02/14/2018 16:40:12;0100;Server@node2;Req;;Type 11 request received from Scheduler@node2.supernodexp.hpc, sock=20
02/14/2018 16:40:12;0008;Server@node2;Job;1317.node2.supernodexp.hpc;Job Modified at request of Scheduler@node2.supernodexp.hpc
02/14/2018 16:40:12;0100;Server@node2;Req;;Type 11 request received from Scheduler@node2.supernodexp.hpc, sock=20
02/14/2018 16:40:12;0008;Server@node2;Job;1318.node2.supernodexp.hpc;Job Modified at request of Scheduler@node2.supernodexp.hpc
02/14/2018 16:40:12;0100;Server@node2;Req;;Type 11 request received from Scheduler@node2.supernodexp.hpc, sock=20
02/14/2018 16:40:12;0008;Server@node2;Job;1319.node2.supernodexp.hpc;Job Modified at request of Scheduler@node2.supernodexp.hpc
02/14/2018 16:40:12;0100;Server@node2;Req;;Type 11 request received from Scheduler@node2.supernodexp.hpc, sock=20
02/14/2018 16:40:12;0008;Server@node2;Job;1320.node2.supernodexp.hpc;Job Modified at request of Scheduler@node2.supernodexp.hpc
02/14/2018 16:40:12;0100;Server@node2;Req;;Type 11 request received from Scheduler@node2.supernodexp.hpc, sock=20
02/14/2018 16:40:12;0008;Server@node2;Job;1321.node2.supernodexp.hpc;Job Modified at request of Scheduler@node2.supernodexp.hpc
02/14/2018 16:40:12;0100;Server@node2;Req;;Type 11 request received from Scheduler@node2.supernodexp.hpc, sock=20
02/14/2018 16:40:12;0008;Server@node2;Job;1322.node2.supernodexp.hpc;Job Modified at request of Scheduler@node2.supernodexp.hpc
02/14/2018 16:40:12;0100;Server@node2;Req;;Type 11 request received from Scheduler@node2.supernodexp.hpc, sock=20
02/14/2018 16:40:12;0008;Server@node2;Job;1323.node2.supernodexp.hpc;Job Modified at request of Scheduler@node2.supernodexp.hpc
02/14/2018 16:40:12;0100;Server@node2;Req;;Type 11 request received from Scheduler@node2.supernodexp.hpc, sock=20
02/14/2018 16:40:12;0008;Server@node2;Job;1324.node2.supernodexp.hpc;Job Modified at request of Scheduler@node2.supernodexp.hpc
02/14/2018 16:40:12;0100;Server@node2;Req;;Type 11 request received from Scheduler@node2.supernodexp.hpc, sock=20
02/14/2018 16:40:12;0008;Server@node2;Job;1325.node2.supernodexp.hpc;Job Modified at request of Scheduler@node2.supernodexp.hpc
02/14/2018 16:40:12;0100;Server@node2;Req;;Type 11 request received from Scheduler@node2.supernodexp.hpc, sock=20
02/14/2018 16:40:12;0008;Server@node2;Job;1326.node2.supernodexp.hpc;Job Modified at request of Scheduler@node2.supernodexp.hpc
02/14/2018 16:40:12;0100;Server@node2;Req;;Type 11 request received from Scheduler@node2.supernodexp.hpc, sock=20
02/14/2018 16:40:12;0008;Server@node2;Job;1327.node2.supernodexp.hpc;Job Modified at request of Scheduler@node2.supernodexp.hpc
02/14/2018 16:40:12;0100;Server@node2;Req;;Type 11 request received from Scheduler@node2.supernodexp.hpc, sock=20
02/14/2018 16:40:12;0008;Server@node2;Job;1328.node2.supernodexp.hpc;Job Modified at request of Scheduler@node2.supernodexp.hpc
02/14/2018 16:40:12;0100;Server@node2;Req;;Type 11 request received from Scheduler@node2.supernodexp.hpc, sock=20
02/14/2018 16:40:12;0008;Server@node2;Job;1329.node2.supernodexp.hpc;Job Modified at request of Scheduler@node2.supernodexp.hpc
02/14/2018 16:40:12;0100;Server@node2;Req;;Type 11 request received from Scheduler@node2.supernodexp.hpc, sock=20
02/14/2018 16:40:12;0008;Server@node2;Job;1330.node2.supernodexp.hpc;Job Modified at request of Scheduler@node2.supernodexp.hpc
02/14/2018 16:40:12;0100;Server@node2;Req;;Type 23 request received from Scheduler@node2.supernodexp.hpc, sock=20
02/14/2018 16:40:12;0008;Server@node2;Job;1331.node2.supernodexp.hpc;Job Run at request of Scheduler@node2.supernodexp.hpc on exec_vnode (node14:ncpus=8:mem=3145728kb)
02/14/2018 16:40:12;0001;Server@node2;Svr;Server@node2;Success (0) in req_runjob2, return value of svr_startjob is 0
02/14/2018 16:40:13;0080;Server@node2;Job;1331.node2.supernodexp.hpc;Obit received momhop:1 serverhop:1 state:4 substate:42
02/14/2018 16:40:15;0010;Server@node2;Job;1331.node2.supernodexp.hpc;Exit_status=0 resources_used.cpupercent=498 resources_used.cput=00:00:10 resources_used.mem=0kb resources_used.ncpus=8 resources_used.vmem=0kb resources_used.walltime=00:00:02
02/14/2018 16:40:15;0100;Server@node2;Job;1331.node2.supernodexp.hpc;dequeuing from workq, state 5
02/14/2018 16:40:15;0040;Server@node2;Svr;node2.supernodexp.hpc;Scheduler sent command 2
02/14/2018 16:40:15;0040;Server@node2;Svr;node2.supernodexp.hpc;Scheduler sent command 0
02/14/2018 16:40:15;0100;Server@node2;Req;;Type 21 request received from Scheduler@node2.supernodexp.hpc, sock=20
02/14/2018 16:40:15;0100;Server@node2;Req;;Type 81 request received from Scheduler@node2.supernodexp.hpc, sock=20
02/14/2018 16:40:15;0100;Server@node2;Req;;Type 71 request received from Scheduler@node2.supernodexp.hpc, sock=20
02/14/2018 16:40:15;0100;Server@node2;Req;;Type 58 request received from Scheduler@node2.supernodexp.hpc, sock=20
02/14/2018 16:40:15;0100;Server@node2;Req;;Type 20 request received from Scheduler@node2.supernodexp.hpc, sock=20
02/14/2018 16:40:15;0100;Server@node2;Req;;Type 51 request received from Scheduler@node2.supernodexp.hpc, sock=20
02/14/2018 16:40:15;0100;Server@node2;Req;;Type 11 request received from Scheduler@node2.supernodexp.hpc, sock=20
02/14/2018 16:40:15;0008;Server@node2;Job;1332.node2.supernodexp.hpc;Job Modified at request of Scheduler@node2.supernodexp.hpc
02/14/2018 16:40:15;0100;Server@node2;Req;;Type 11 request received from Scheduler@node2.supernodexp.hpc, sock=20
02/14/2018 16:40:15;0008;Server@node2;Job;1333.node2.supernodexp.hpc;Job Modified at request of Scheduler@node2.supernodexp.hpc
02/14/2018 16:40:15;0100;Server@node2;Req;;Type 23 request received from Scheduler@node2.supernodexp.hpc, sock=20
02/14/2018 16:40:15;0008;Server@node2;Job;1334.node2.supernodexp.hpc;Job Run at request of Scheduler@node2.supernodexp.hpc on exec_vnode (node14:ncpus=8:mem=3145728kb)
02/14/2018 16:40:15;0001;Server@node2;Svr;Server@node2;Success (0) in req_runjob2, return value of svr_startjob is 0
02/14/2018 16:40:16;0080;Server@node2;Job;1334.node2.supernodexp.hpc;Obit received momhop:1 serverhop:1 state:4 substate:42
02/14/2018 16:40:18;0010;Server@node2;Job;1334.node2.supernodexp.hpc;Exit_status=0 resources_used.cpupercent=800 resources_used.cput=00:00:10 resources_used.mem=0kb resources_used.ncpus=8 resources_used.vmem=0kb resources_used.walltime=00:00:02
02/14/2018 16:40:18;0100;Server@node2;Job;1334.node2.supernodexp.hpc;dequeuing from workq, state 5
02/14/2018 16:40:18;0040;Server@node2;Svr;node2.supernodexp.hpc;Scheduler sent command 2
02/14/2018 16:40:18;0040;Server@node2;Svr;node2.supernodexp.hpc;Scheduler sent command 0
02/14/2018 16:40:18;0100;Server@node2;Req;;Type 21 request received from Scheduler@node2.supernodexp.hpc, sock=20
02/14/2018 16:40:18;0100;Server@node2;Req;;Type 81 request received from Scheduler@node2.supernodexp.hpc, sock=20
02/14/2018 16:40:18;0100;Server@node2;Req;;Type 71 request received from Scheduler@node2.supernodexp.hpc, sock=20
02/14/2018 16:40:18;0100;Server@node2;Req;;Type 58 request received from Scheduler@node2.supernodexp.hpc, sock=20
02/14/2018 16:40:18;0100;Server@node2;Req;;Type 20 request received from Scheduler@node2.supernodexp.hpc, sock=20
02/14/2018 16:40:18;0100;Server@node2;Req;;Type 51 request received from Scheduler@node2.supernodexp.hpc, sock=20
02/14/2018 16:40:18;0100;Server@node2;Req;;Type 11 request received from Scheduler@node2.supernodexp.hpc, sock=20
02/14/2018 16:40:18;0008;Server@node2;Job;1335.node2.supernodexp.hpc;Job Modified at request of Scheduler@node2.supernodexp.hpc
02/14/2018 16:40:18;0100;Server@node2;Req;;Type 11 request received from Scheduler@node2.supernodexp.hpc, sock=20
02/14/2018 16:40:18;0008;Server@node2;Job;1336.node2.supernodexp.hpc;Job Modified at request of Scheduler@node2.supernodexp.hpc
02/14/2018 16:40:18;0100;Server@node2;Req;;Type 11 request received from Scheduler@node2.supernodexp.hpc, sock=20
02/14/2018 16:40:18;0008;Server@node2;Job;1337.node2.supernodexp.hpc;Job Modified at request of Scheduler@node2.supernodexp.hpc
02/14/2018 16:40:18;0100;Server@node2;Req;;Type 11 request received from Scheduler@node2.supernodexp.hpc, sock=20
02/14/2018 16:40:18;0008;Server@node2;Job;1338.node2.supernodexp.hpc;Job Modified at request of Scheduler@node2.supernodexp.hpc
02/14/2018 16:40:18;0100;Server@node2;Req;;Type 11 request received from Scheduler@node2.supernodexp.hpc, sock=20
02/14/2018 16:40:18;0008;Server@node2;Job;1339.node2.supernodexp.hpc;Job Modified at request of Scheduler@node2.supernodexp.hpc
02/14/2018 16:40:18;0100;Server@node2;Req;;Type 11 request received from Scheduler@node2.supernodexp.hpc, sock=20
02/14/2018 16:40:18;0008;Server@node2;Job;1340.node2.supernodexp.hpc;Job Modified at request of Scheduler@node2.supernodexp.hpc
02/14/2018 16:40:18;0100;Server@node2;Req;;Type 11 request received from Scheduler@node2.supernodexp.hpc, sock=20
02/14/2018 16:40:18;0008;Server@node2;Job;1341.node2.supernodexp.hpc;Job Modified at request of Scheduler@node2.supernodexp.hpc
02/14/2018 16:40:18;0100;Server@node2;Req;;Type 23 request received from Scheduler@node2.supernodexp.hpc, sock=20
02/14/2018 16:40:18;0008;Server@node2;Job;1342.node2.supernodexp.hpc;Job Run at request of Scheduler@node2.supernodexp.hpc on exec_vnode (node14:ncpus=8:mem=3145728kb)
02/14/2018 16:40:18;0001;Server@node2;Svr;Server@node2;Success (0) in req_runjob2, return value of svr_startjob is 0
02/14/2018 16:40:20;0080;Server@node2;Job;1342.node2.supernodexp.hpc;Obit received momhop:1 serverhop:1 state:4 substate:42
02/14/2018 16:40:21;0010;Server@node2;Job;1342.node2.supernodexp.hpc;Exit_status=0 resources_used.cpupercent=800 resources_used.cput=00:00:10 resources_used.mem=0kb resources_used.ncpus=8 resources_used.vmem=0kb resources_used.walltime=00:00:02
02/14/2018 16:40:21;0100;Server@node2;Job;1342.node2.supernodexp.hpc;dequeuing from workq, state 5
02/14/2018 16:40:21;0040;Server@node2;Svr;node2.supernodexp.hpc;Scheduler sent command 2
02/14/2018 16:40:21;0040;Server@node2;Svr;node2.supernodexp.hpc;Scheduler sent command 0
02/14/2018 16:40:21;0100;Server@node2;Req;;Type 21 request received from Scheduler@node2.supernodexp.hpc, sock=20
02/14/2018 16:40:21;0100;Server@node2;Req;;Type 81 request received from Scheduler@node2.supernodexp.hpc, sock=20
02/14/2018 16:40:21;0100;Server@node2;Req;;Type 71 request received from Scheduler@node2.supernodexp.hpc, sock=20
02/14/2018 16:40:21;0100;Server@node2;Req;;Type 58 request received from Scheduler@node2.supernodexp.hpc, sock=20
02/14/2018 16:40:21;0100;Server@node2;Req;;Type 20 request received from Scheduler@node2.supernodexp.hpc, sock=20
02/14/2018 16:40:21;0100;Server@node2;Req;;Type 51 request received from Scheduler@node2.supernodexp.hpc, sock=20
02/14/2018 16:40:21;0100;Server@node2;Req;;Type 11 request received from Scheduler@node2.supernodexp.hpc, sock=20
02/14/2018 16:40:21;0008;Server@node2;Job;1343.node2.supernodexp.hpc;Job Modified at request of Scheduler@node2.supernodexp.hpc
02/14/2018 16:40:21;0100;Server@node2;Req;;Type 11 request received from Scheduler@node2.supernodexp.hpc, sock=20
02/14/2018 16:40:21;0008;Server@node2;Job;1344.node2.supernodexp.hpc;Job Modified at request of Scheduler@node2.supernodexp.hpc
02/14/2018 16:40:21;0100;Server@node2;Req;;Type 11 request received from Scheduler@node2.supernodexp.hpc, sock=20
02/14/2018 16:40:21;0008;Server@node2;Job;1345.node2.supernodexp.hpc;Job Modified at request of Scheduler@node2.supernodexp.hpc
02/14/2018 16:40:21;0100;Server@node2;Req;;Type 11 request received from Scheduler@node2.supernodexp.hpc, sock=20
02/14/2018 16:40:21;0008;Server@node2;Job;1346.node2.supernodexp.hpc;Job Modified at request of Scheduler@node2.supernodexp.hpc
02/14/2018 16:40:21;0100;Server@node2;Req;;Type 11 request received from Scheduler@node2.supernodexp.hpc, sock=20
02/14/2018 16:40:21;0008;Server@node2;Job;1347.node2.supernodexp.hpc;Job Modified at request of Scheduler@node2.supernodexp.hpc
02/14/2018 16:40:21;0100;Server@node2;Req;;Type 11 request received from Scheduler@node2.supernodexp.hpc, sock=20
02/14/2018 16:40:21;0008;Server@node2;Job;1348.node2.supernodexp.hpc;Job Modified at request of Scheduler@node2.supernodexp.hpc
02/14/2018 16:40:21;0100;Server@node2;Req;;Type 23 request received from Scheduler@node2.supernodexp.hpc, sock=20
02/14/2018 16:40:21;0008;Server@node2;Job;1349.node2.supernodexp.hpc;Job Run at request of Scheduler@node2.supernodexp.hpc on exec_vnode (node14:ncpus=8:mem=3145728kb)
02/14/2018 16:40:21;0001;Server@node2;Svr;Server@node2;Success (0) in req_runjob2, return value of svr_startjob is 0
02/14/2018 16:40:23;0080;Server@node2;Job;1349.node2.supernodexp.hpc;Obit received momhop:1 serverhop:1 state:4 substate:42
02/14/2018 16:40:24;0010;Server@node2;Job;1349.node2.supernodexp.hpc;Exit_status=0 resources_used.cpupercent=801 resources_used.cput=00:00:11 resources_used.mem=0kb resources_used.ncpus=8 resources_used.vmem=0kb resources_used.walltime=00:00:01
02/14/2018 16:40:24;0100;Server@node2;Job;1349.node2.supernodexp.hpc;dequeuing from workq, state 5
02/14/2018 16:40:24;0040;Server@node2;Svr;node2.supernodexp.hpc;Scheduler sent command 2
02/14/2018 16:40:24;0040;Server@node2;Svr;node2.supernodexp.hpc;Scheduler sent command 0
02/14/2018 16:40:24;0100;Server@node2;Req;;Type 21 request received from Scheduler@node2.supernodexp.hpc, sock=20
02/14/2018 16:40:24;0100;Server@node2;Req;;Type 81 request received from Scheduler@node2.supernodexp.hpc, sock=20
02/14/2018 16:40:24;0100;Server@node2;Req;;Type 71 request received from Scheduler@node2.supernodexp.hpc, sock=20
02/14/2018 16:40:24;0100;Server@node2;Req;;Type 58 request received from Scheduler@node2.supernodexp.hpc, sock=20
02/14/2018 16:40:24;0100;Server@node2;Req;;Type 20 request received from Scheduler@node2.supernodexp.hpc, sock=20
02/14/2018 16:40:24;0100;Server@node2;Req;;Type 51 request received from Scheduler@node2.supernodexp.hpc, sock=20
02/14/2018 16:40:24;0100;Server@node2;Req;;Type 11 request received from Scheduler@node2.supernodexp.hpc, sock=20
02/14/2018 16:40:24;0008;Server@node2;Job;1350.node2.supernodexp.hpc;Job Modified at request of Scheduler@node2.supernodexp.hpc
02/14/2018 16:40:24;0100;Server@node2;Req;;Type 11 request received from Scheduler@node2.supernodexp.hpc, sock=20
02/14/2018 16:40:24;0008;Server@node2;Job;1351.node2.supernodexp.hpc;Job Modified at request of Scheduler@node2.supernodexp.hpc
02/14/2018 16:40:24;0100;Server@node2;Req;;Type 23 request received from Scheduler@node2.supernodexp.hpc, sock=20
02/14/2018 16:40:24;0008;Server@node2;Job;1352.node2.supernodexp.hpc;Job Run at request of Scheduler@node2.supernodexp.hpc on exec_vnode (node14:ncpus=8:mem=3145728kb)
02/14/2018 16:40:24;0001;Server@node2;Svr;Server@node2;Success (0) in req_runjob2, return value of svr_startjob is 0
02/14/2018 16:40:26;0080;Server@node2;Job;1352.node2.supernodexp.hpc;Obit received momhop:1 serverhop:1 state:4 substate:42
02/14/2018 16:40:27;0010;Server@node2;Job;1352.node2.supernodexp.hpc;Exit_status=0 resources_used.cpupercent=800 resources_used.cput=00:00:10 resources_used.mem=0kb resources_used.ncpus=8 resources_used.vmem=0kb resources_used.walltime=00:00:01
02/14/2018 16:40:27;0100;Server@node2;Job;1352.node2.supernodexp.hpc;dequeuing from workq, state 5
02/14/2018 16:40:27;0040;Server@node2;Svr;node2.supernodexp.hpc;Scheduler sent command 2
02/14/2018 16:40:27;0040;Server@node2;Svr;node2.supernodexp.hpc;Scheduler sent command 0
02/14/2018 16:40:27;0100;Server@node2;Req;;Type 21 request received from Scheduler@node2.supernodexp.hpc, sock=20
02/14/2018 16:40:27;0100;Server@node2;Req;;Type 81 request received from Scheduler@node2.supernodexp.hpc, sock=20
02/14/2018 16:40:27;0100;Server@node2;Req;;Type 71 request received from Scheduler@node2.supernodexp.hpc, sock=20
02/14/2018 16:40:27;0100;Server@node2;Req;;Type 58 request received from Scheduler@node2.supernodexp.hpc, sock=20
02/14/2018 16:40:27;0100;Server@node2;Req;;Type 20 request received from Scheduler@node2.supernodexp.hpc, sock=20
02/14/2018 16:40:27;0100;Server@node2;Req;;Type 51 request received from Scheduler@node2.supernodexp.hpc, sock=20
02/14/2018 16:40:27;0100;Server@node2;Req;;Type 11 request received from Scheduler@node2.supernodexp.hpc, sock=20
02/14/2018 16:40:27;0008;Server@node2;Job;1353.node2.supernodexp.hpc;Job Modified at request of Scheduler@node2.supernodexp.hpc
02/14/2018 16:40:27;0100;Server@node2;Req;;Type 11 request received from Scheduler@node2.supernodexp.hpc, sock=20
02/14/2018 16:40:27;0008;Server@node2;Job;1354.node2.supernodexp.hpc;Job Modified at request of Scheduler@node2.supernodexp.hpc
02/14/2018 16:40:27;0100;Server@node2;Req;;Type 11 request received from Scheduler@node2.supernodexp.hpc, sock=20
02/14/2018 16:40:27;0008;Server@node2;Job;1355.node2.supernodexp.hpc;Job Modified at request of Scheduler@node2.supernodexp.hpc
02/14/2018 16:40:27;0100;Server@node2;Req;;Type 11 request received from Scheduler@node2.supernodexp.hpc, sock=20
02/14/2018 16:40:27;0008;Server@node2;Job;1356.node2.supernodexp.hpc;Job Modified at request of Scheduler@node2.supernodexp.hpc
02/14/2018 16:40:27;0100;Server@node2;Req;;Type 11 request received from Scheduler@node2.supernodexp.hpc, sock=20
02/14/2018 16:40:27;0008;Server@node2;Job;1357.node2.supernodexp.hpc;Job Modified at request of Scheduler@node2.supernodexp.hpc
02/14/2018 16:40:27;0100;Server@node2;Req;;Type 11 request received from Scheduler@node2.supernodexp.hpc, sock=20
02/14/2018 16:40:27;0008;Server@node2;Job;1358.node2.supernodexp.hpc;Job Modified at request of Scheduler@node2.supernodexp.hpc
02/14/2018 16:40:27;0100;Server@node2;Req;;Type 11 request received from Scheduler@node2.supernodexp.hpc, sock=20
02/14/2018 16:40:27;0008;Server@node2;Job;1359.node2.supernodexp.hpc;Job Modified at request of Scheduler@node2.supernodexp.hpc
02/14/2018 16:40:27;0100;Server@node2;Req;;Type 11 request received from Scheduler@node2.supernodexp.hpc, sock=20
02/14/2018 16:40:27;0008;Server@node2;Job;1360.node2.supernodexp.hpc;Job Modified at request of Scheduler@node2.supernodexp.hpc
02/14/2018 16:40:27;0100;Server@node2;Req;;Type 11 request received from Scheduler@node2.supernodexp.hpc, sock=20
02/14/2018 16:40:27;0008;Server@node2;Job;1361.node2.supernodexp.hpc;Job Modified at request of Scheduler@node2.supernodexp.hpc
02/14/2018 16:40:27;0100;Server@node2;Req;;Type 11 request received from Scheduler@node2.supernodexp.hpc, sock=20
02/14/2018 16:40:27;0008;Server@node2;Job;1362.node2.supernodexp.hpc;Job Modified at request of Scheduler@node2.supernodexp.hpc
02/14/2018 16:40:27;0100;Server@node2;Req;;Type 11 request received from Scheduler@node2.supernodexp.hpc, sock=20
02/14/2018 16:40:27;0008;Server@node2;Job;1363.node2.supernodexp.hpc;Job Modified at request of Scheduler@node2.supernodexp.hpc
02/14/2018 16:40:27;0100;Server@node2;Req;;Type 11 request received from Scheduler@node2.supernodexp.hpc, sock=20
02/14/2018 16:40:27;0008;Server@node2;Job;1364.node2.supernodexp.hpc;Job Modified at request of Scheduler@node2.supernodexp.hpc
02/14/2018 16:40:27;0100;Server@node2;Req;;Type 23 request received from Scheduler@node2.supernodexp.hpc, sock=20
02/14/2018 16:40:27;0008;Server@node2;Job;1365.node2.supernodexp.hpc;Job Run at request of Scheduler@node2.supernodexp.hpc on exec_vnode (node14:ncpus=8:mem=3145728kb)
02/14/2018 16:40:27;0001;Server@node2;Svr;Server@node2;Success (0) in req_runjob2, return value of svr_startjob is 0
02/14/2018 16:40:29;0080;Server@node2;Job;1365.node2.supernodexp.hpc;Obit received momhop:1 serverhop:1 state:4 substate:42
02/14/2018 16:40:30;0010;Server@node2;Job;1365.node2.supernodexp.hpc;Exit_status=0 resources_used.cpupercent=800 resources_used.cput=00:00:10 resources_used.mem=0kb resources_used.ncpus=8 resources_used.vmem=0kb resources_used.walltime=00:00:02
02/14/2018 16:40:30;0100;Server@node2;Job;1365.node2.supernodexp.hpc;dequeuing from workq, state 5
02/14/2018 16:40:30;0040;Server@node2;Svr;node2.supernodexp.hpc;Scheduler sent command 2
02/14/2018 16:40:30;0040;Server@node2;Svr;node2.supernodexp.hpc;Scheduler sent command 0
02/14/2018 16:40:30;0100;Server@node2;Req;;Type 21 request received from Scheduler@node2.supernodexp.hpc, sock=20
02/14/2018 16:40:30;0100;Server@node2;Req;;Type 81 request received from Scheduler@node2.supernodexp.hpc, sock=20
02/14/2018 16:40:30;0100;Server@node2;Req;;Type 71 request received from Scheduler@node2.supernodexp.hpc, sock=20
02/14/2018 16:40:30;0100;Server@node2;Req;;Type 58 request received from Scheduler@node2.supernodexp.hpc, sock=20
02/14/2018 16:40:30;0100;Server@node2;Req;;Type 20 request received from Scheduler@node2.supernodexp.hpc, sock=20
02/14/2018 16:40:30;0100;Server@node2;Req;;Type 51 request received from Scheduler@node2.supernodexp.hpc, sock=20
02/14/2018 16:40:30;0100;Server@node2;Req;;Type 11 request received from Scheduler@node2.supernodexp.hpc, sock=20
02/14/2018 16:40:30;0008;Server@node2;Job;1366.node2.supernodexp.hpc;Job Modified at request of Scheduler@node2.supernodexp.hpc
02/14/2018 16:40:30;0100;Server@node2;Req;;Type 11 request received from Scheduler@node2.supernodexp.hpc, sock=20
02/14/2018 16:40:30;0008;Server@node2;Job;1367.node2.supernodexp.hpc;Job Modified at request of Scheduler@node2.supernodexp.hpc
02/14/2018 16:40:30;0100;Server@node2;Req;;Type 11 request received from Scheduler@node2.supernodexp.hpc, sock=20
02/14/2018 16:40:30;0008;Server@node2;Job;1368.node2.supernodexp.hpc;Job Modified at request of Scheduler@node2.supernodexp.hpc
02/14/2018 16:40:30;0100;Server@node2;Req;;Type 11 request received from Scheduler@node2.supernodexp.hpc, sock=20
02/14/2018 16:40:30;0008;Server@node2;Job;1369.node2.supernodexp.hpc;Job Modified at request of Scheduler@node2.supernodexp.hpc
02/14/2018 16:40:30;0100;Server@node2;Req;;Type 11 request received from Scheduler@node2.supernodexp.hpc, sock=20
02/14/2018 16:40:30;0008;Server@node2;Job;1370.node2.supernodexp.hpc;Job Modified at request of Scheduler@node2.supernodexp.hpc
02/14/2018 16:40:45;0080;Server@node2;Job;1215.node2.supernodexp.hpc;Obit received momhop:1 serverhop:1 state:4 substate:42
02/14/2018 16:40:46;0010;Server@node2;Job;1215.node2.supernodexp.hpc;Exit_status=0 resources_used.cpupercent=1002 resources_used.cput=00:15:22 resources_used.mem=97064kb resources_used.ncpus=16 resources_used.vmem=1468340kb resources_used.walltime=00:01:00
02/14/2018 16:40:46;0100;Server@node2;Job;1215.node2.supernodexp.hpc;dequeuing from workq, state 5
02/14/2018 16:40:46;0040;Server@node2;Svr;node2.supernodexp.hpc;Scheduler sent command 2
02/14/2018 16:40:46;0040;Server@node2;Svr;node2.supernodexp.hpc;Scheduler sent command 0
02/14/2018 16:40:46;0100;Server@node2;Req;;Type 21 request received from Scheduler@node2.supernodexp.hpc, sock=20
02/14/2018 16:40:46;0100;Server@node2;Req;;Type 81 request received from Scheduler@node2.supernodexp.hpc, sock=20
02/14/2018 16:40:46;0100;Server@node2;Req;;Type 71 request received from Scheduler@node2.supernodexp.hpc, sock=20
02/14/2018 16:40:46;0100;Server@node2;Req;;Type 58 request received from Scheduler@node2.supernodexp.hpc, sock=20
02/14/2018 16:40:46;0100;Server@node2;Req;;Type 20 request received from Scheduler@node2.supernodexp.hpc, sock=20
02/14/2018 16:40:46;0100;Server@node2;Req;;Type 51 request received from Scheduler@node2.supernodexp.hpc, sock=20
02/14/2018 16:40:46;0100;Server@node2;Req;;Type 11 request received from Scheduler@node2.supernodexp.hpc, sock=20
02/14/2018 16:40:46;0008;Server@node2;Job;1209.node2.supernodexp.hpc;Job Modified at request of Scheduler@node2.supernodexp.hpc
02/14/2018 16:40:46;0100;Server@node2;Req;;Type 11 request received from Scheduler@node2.supernodexp.hpc, sock=20
02/14/2018 16:40:46;0008;Server@node2;Job;1211.node2.supernodexp.hpc;Job Modified at request of Scheduler@node2.supernodexp.hpc
02/14/2018 16:40:46;0100;Server@node2;Req;;Type 11 request received from Scheduler@node2.supernodexp.hpc, sock=20
02/14/2018 16:40:46;0008;Server@node2;Job;1212.node2.supernodexp.hpc;Job Modified at request of Scheduler@node2.supernodexp.hpc
02/14/2018 16:40:46;0100;Server@node2;Req;;Type 11 request received from Scheduler@node2.supernodexp.hpc, sock=20
02/14/2018 16:40:46;0008;Server@node2;Job;1213.node2.supernodexp.hpc;Job Modified at request of Scheduler@node2.supernodexp.hpc
02/14/2018 16:40:46;0100;Server@node2;Req;;Type 11 request received from Scheduler@node2.supernodexp.hpc, sock=20
02/14/2018 16:40:46;0008;Server@node2;Job;1216.node2.supernodexp.hpc;Job Modified at request of Scheduler@node2.supernodexp.hpc
02/14/2018 16:40:46;0100;Server@node2;Req;;Type 11 request received from Scheduler@node2.supernodexp.hpc, sock=20
02/14/2018 16:40:46;0008;Server@node2;Job;1218.node2.supernodexp.hpc;Job Modified at request of Scheduler@node2.supernodexp.hpc
02/14/2018 16:40:46;0100;Server@node2;Req;;Type 23 request received from Scheduler@node2.supernodexp.hpc, sock=20
02/14/2018 16:40:46;0008;Server@node2;Job;1219.node2.supernodexp.hpc;Job Run at request of Scheduler@node2.supernodexp.hpc on exec_vnode (node14:ncpus=16:mem=2097152kb)
02/14/2018 16:40:46;0001;Server@node2;Svr;Server@node2;Success (0) in req_runjob2, return value of svr_startjob is 0
02/14/2018 16:40:47;0100;Server@node2;Req;;Type 1 request received from ctminh@node2.supernodexp.hpc, sock=16
02/14/2018 16:40:47;0100;Server@node2;Req;;Type 3 request received from ctminh@node2.supernodexp.hpc, sock=16
02/14/2018 16:40:47;0100;Server@node2;Req;;Type 5 request received from ctminh@node2.supernodexp.hpc, sock=16
02/14/2018 16:40:47;0100;Server@node2;Job;1371.node2.supernodexp.hpc;enqueuing into workq, state 1 hop 1
02/14/2018 16:40:47;0008;Server@node2;Job;1371.node2.supernodexp.hpc;Job Queued at request of ctminh@node2.supernodexp.hpc, owner = ctminh@node2.supernodexp.hpc, job name = jacobi, queue = workq
02/14/2018 16:40:47;0040;Server@node2;Svr;node2.supernodexp.hpc;Scheduler sent command 1
02/14/2018 16:40:47;0040;Server@node2;Svr;node2.supernodexp.hpc;Scheduler sent command 0
02/14/2018 16:40:47;0100;Server@node2;Req;;Type 21 request received from Scheduler@node2.supernodexp.hpc, sock=20
02/14/2018 16:40:47;0100;Server@node2;Req;;Type 81 request received from Scheduler@node2.supernodexp.hpc, sock=20
02/14/2018 16:40:47;0100;Server@node2;Req;;Type 71 request received from Scheduler@node2.supernodexp.hpc, sock=20
02/14/2018 16:40:47;0100;Server@node2;Req;;Type 58 request received from Scheduler@node2.supernodexp.hpc, sock=20
02/14/2018 16:40:48;0100;Server@node2;Req;;Type 1 request received from ctminh@node2.supernodexp.hpc, sock=16
02/14/2018 16:40:48;0100;Server@node2;Req;;Type 3 request received from ctminh@node2.supernodexp.hpc, sock=16
02/14/2018 16:40:48;0100;Server@node2;Req;;Type 5 request received from ctminh@node2.supernodexp.hpc, sock=16
02/14/2018 16:40:48;0100;Server@node2;Job;1372.node2.supernodexp.hpc;enqueuing into workq, state 1 hop 1
02/14/2018 16:40:48;0008;Server@node2;Job;1372.node2.supernodexp.hpc;Job Queued at request of ctminh@node2.supernodexp.hpc, owner = ctminh@node2.supernodexp.hpc, job name = thread-affinity, queue = workq
02/14/2018 16:40:48;0100;Server@node2;Req;;Type 20 request received from Scheduler@node2.supernodexp.hpc, sock=20
02/14/2018 16:40:48;0100;Server@node2;Req;;Type 51 request received from Scheduler@node2.supernodexp.hpc, sock=20
02/14/2018 16:40:48;0100;Server@node2;Req;;Type 1 request received from ctminh@node2.supernodexp.hpc, sock=16
02/14/2018 16:40:48;0100;Server@node2;Req;;Type 3 request received from ctminh@node2.supernodexp.hpc, sock=16
02/14/2018 16:40:48;0100;Server@node2;Req;;Type 5 request received from ctminh@node2.supernodexp.hpc, sock=16
02/14/2018 16:40:48;0100;Server@node2;Job;1373.node2.supernodexp.hpc;enqueuing into workq, state 1 hop 1
02/14/2018 16:40:48;0008;Server@node2;Job;1373.node2.supernodexp.hpc;Job Queued at request of ctminh@node2.supernodexp.hpc, owner = ctminh@node2.supernodexp.hpc, job name = sweep, queue = workq
02/14/2018 16:40:48;0100;Server@node2;Req;;Type 1 request received from ctminh@node2.supernodexp.hpc, sock=16
02/14/2018 16:40:48;0100;Server@node2;Req;;Type 3 request received from ctminh@node2.supernodexp.hpc, sock=16
02/14/2018 16:40:48;0100;Server@node2;Req;;Type 5 request received from ctminh@node2.supernodexp.hpc, sock=16
02/14/2018 16:40:48;0100;Server@node2;Job;1374.node2.supernodexp.hpc;enqueuing into workq, state 1 hop 1
02/14/2018 16:40:48;0008;Server@node2;Job;1374.node2.supernodexp.hpc;Job Queued at request of ctminh@node2.supernodexp.hpc, owner = ctminh@node2.supernodexp.hpc, job name = matrix-x-vector, queue = workq
02/14/2018 16:40:48;0100;Server@node2;Req;;Type 11 request received from Scheduler@node2.supernodexp.hpc, sock=20
02/14/2018 16:40:48;0008;Server@node2;Job;1209.node2.supernodexp.hpc;Job Modified at request of Scheduler@node2.supernodexp.hpc
02/14/2018 16:40:48;0100;Server@node2;Req;;Type 11 request received from Scheduler@node2.supernodexp.hpc, sock=20
02/14/2018 16:40:48;0008;Server@node2;Job;1211.node2.supernodexp.hpc;Job Modified at request of Scheduler@node2.supernodexp.hpc
02/14/2018 16:40:48;0100;Server@node2;Req;;Type 11 request received from Scheduler@node2.supernodexp.hpc, sock=20
02/14/2018 16:40:48;0008;Server@node2;Job;1212.node2.supernodexp.hpc;Job Modified at request of Scheduler@node2.supernodexp.hpc
02/14/2018 16:40:48;0100;Server@node2;Req;;Type 11 request received from Scheduler@node2.supernodexp.hpc, sock=20
02/14/2018 16:40:48;0008;Server@node2;Job;1213.node2.supernodexp.hpc;Job Modified at request of Scheduler@node2.supernodexp.hpc
02/14/2018 16:40:48;0100;Server@node2;Req;;Type 11 request received from Scheduler@node2.supernodexp.hpc, sock=20
02/14/2018 16:40:48;0008;Server@node2;Job;1216.node2.supernodexp.hpc;Job Modified at request of Scheduler@node2.supernodexp.hpc
02/14/2018 16:40:48;0100;Server@node2;Req;;Type 11 request received from Scheduler@node2.supernodexp.hpc, sock=20
02/14/2018 16:40:48;0008;Server@node2;Job;1218.node2.supernodexp.hpc;Job Modified at request of Scheduler@node2.supernodexp.hpc
02/14/2018 16:40:48;0100;Server@node2;Req;;Type 11 request received from Scheduler@node2.supernodexp.hpc, sock=20
02/14/2018 16:40:48;0008;Server@node2;Job;1371.node2.supernodexp.hpc;Job Modified at request of Scheduler@node2.supernodexp.hpc
02/14/2018 16:40:48;0100;Server@node2;Req;;Type 11 request received from Scheduler@node2.supernodexp.hpc, sock=20
02/14/2018 16:40:48;0008;Server@node2;Job;1372.node2.supernodexp.hpc;Job Modified at request of Scheduler@node2.supernodexp.hpc
02/14/2018 16:40:48;0040;Server@node2;Svr;node2.supernodexp.hpc;Scheduler sent command 1
02/14/2018 16:40:48;0040;Server@node2;Svr;node2.supernodexp.hpc;Scheduler sent command 0
02/14/2018 16:40:48;0100;Server@node2;Req;;Type 21 request received from Scheduler@node2.supernodexp.hpc, sock=20
02/14/2018 16:40:48;0100;Server@node2;Req;;Type 81 request received from Scheduler@node2.supernodexp.hpc, sock=20
02/14/2018 16:40:48;0100;Server@node2;Req;;Type 71 request received from Scheduler@node2.supernodexp.hpc, sock=20
02/14/2018 16:40:48;0100;Server@node2;Req;;Type 58 request received from Scheduler@node2.supernodexp.hpc, sock=20
02/14/2018 16:40:48;0100;Server@node2;Req;;Type 20 request received from Scheduler@node2.supernodexp.hpc, sock=20
02/14/2018 16:40:48;0100;Server@node2;Req;;Type 51 request received from Scheduler@node2.supernodexp.hpc, sock=20
02/14/2018 16:40:48;0100;Server@node2;Req;;Type 23 request received from Scheduler@node2.supernodexp.hpc, sock=20
02/14/2018 16:40:48;0008;Server@node2;Job;1373.node2.supernodexp.hpc;Job Run at request of Scheduler@node2.supernodexp.hpc on exec_vnode (node14:ncpus=8:mem=3145728kb)
02/14/2018 16:40:48;0001;Server@node2;Svr;Server@node2;Success (0) in req_runjob2, return value of svr_startjob is 0
02/14/2018 16:40:48;0100;Server@node2;Req;;Type 11 request received from Scheduler@node2.supernodexp.hpc, sock=20
02/14/2018 16:40:48;0008;Server@node2;Job;1374.node2.supernodexp.hpc;Job Modified at request of Scheduler@node2.supernodexp.hpc
02/14/2018 16:40:48;0100;Server@node2;Req;;Type 1 request received from ctminh@node2.supernodexp.hpc, sock=16
02/14/2018 16:40:48;0100;Server@node2;Req;;Type 3 request received from ctminh@node2.supernodexp.hpc, sock=16
02/14/2018 16:40:48;0100;Server@node2;Req;;Type 5 request received from ctminh@node2.supernodexp.hpc, sock=16
02/14/2018 16:40:48;0100;Server@node2;Job;1375.node2.supernodexp.hpc;enqueuing into workq, state 1 hop 1
02/14/2018 16:40:48;0008;Server@node2;Job;1375.node2.supernodexp.hpc;Job Queued at request of ctminh@node2.supernodexp.hpc, owner = ctminh@node2.supernodexp.hpc, job name = telemac2, queue = workq
02/14/2018 16:40:48;0040;Server@node2;Svr;node2.supernodexp.hpc;Scheduler sent command 1
02/14/2018 16:40:48;0040;Server@node2;Svr;node2.supernodexp.hpc;Scheduler sent command 0
02/14/2018 16:40:48;0100;Server@node2;Req;;Type 21 request received from Scheduler@node2.supernodexp.hpc, sock=20
02/14/2018 16:40:48;0100;Server@node2;Req;;Type 81 request received from Scheduler@node2.supernodexp.hpc, sock=20
02/14/2018 16:40:48;0100;Server@node2;Req;;Type 71 request received from Scheduler@node2.supernodexp.hpc, sock=20
02/14/2018 16:40:48;0100;Server@node2;Req;;Type 58 request received from Scheduler@node2.supernodexp.hpc, sock=20
02/14/2018 16:40:48;0100;Server@node2;Req;;Type 1 request received from ctminh@node2.supernodexp.hpc, sock=16
02/14/2018 16:40:48;0100;Server@node2;Req;;Type 3 request received from ctminh@node2.supernodexp.hpc, sock=16
02/14/2018 16:40:48;0100;Server@node2;Req;;Type 5 request received from ctminh@node2.supernodexp.hpc, sock=16
02/14/2018 16:40:48;0100;Server@node2;Job;1376.node2.supernodexp.hpc;enqueuing into workq, state 1 hop 1
02/14/2018 16:40:48;0008;Server@node2;Job;1376.node2.supernodexp.hpc;Job Queued at request of ctminh@node2.supernodexp.hpc, owner = ctminh@node2.supernodexp.hpc, job name = thread-affinity, queue = workq
02/14/2018 16:40:48;0100;Server@node2;Req;;Type 20 request received from Scheduler@node2.supernodexp.hpc, sock=20
02/14/2018 16:40:48;0100;Server@node2;Req;;Type 51 request received from Scheduler@node2.supernodexp.hpc, sock=20
02/14/2018 16:40:48;0100;Server@node2;Req;;Type 11 request received from Scheduler@node2.supernodexp.hpc, sock=20
02/14/2018 16:40:48;0008;Server@node2;Job;1209.node2.supernodexp.hpc;Job Modified at request of Scheduler@node2.supernodexp.hpc
02/14/2018 16:40:48;0100;Server@node2;Req;;Type 11 request received from Scheduler@node2.supernodexp.hpc, sock=20
02/14/2018 16:40:48;0008;Server@node2;Job;1211.node2.supernodexp.hpc;Job Modified at request of Scheduler@node2.supernodexp.hpc
02/14/2018 16:40:48;0100;Server@node2;Req;;Type 11 request received from Scheduler@node2.supernodexp.hpc, sock=20
02/14/2018 16:40:48;0008;Server@node2;Job;1212.node2.supernodexp.hpc;Job Modified at request of Scheduler@node2.supernodexp.hpc
02/14/2018 16:40:48;0100;Server@node2;Req;;Type 11 request received from Scheduler@node2.supernodexp.hpc, sock=20
02/14/2018 16:40:48;0008;Server@node2;Job;1213.node2.supernodexp.hpc;Job Modified at request of Scheduler@node2.supernodexp.hpc
02/14/2018 16:40:48;0100;Server@node2;Req;;Type 11 request received from Scheduler@node2.supernodexp.hpc, sock=20
02/14/2018 16:40:48;0008;Server@node2;Job;1216.node2.supernodexp.hpc;Job Modified at request of Scheduler@node2.supernodexp.hpc
02/14/2018 16:40:48;0100;Server@node2;Req;;Type 11 request received from Scheduler@node2.supernodexp.hpc, sock=20
02/14/2018 16:40:48;0008;Server@node2;Job;1218.node2.supernodexp.hpc;Job Modified at request of Scheduler@node2.supernodexp.hpc
02/14/2018 16:40:48;0100;Server@node2;Req;;Type 11 request received from Scheduler@node2.supernodexp.hpc, sock=20
02/14/2018 16:40:48;0008;Server@node2;Job;1220.node2.supernodexp.hpc;Job Modified at request of Scheduler@node2.supernodexp.hpc
02/14/2018 16:40:48;0100;Server@node2;Req;;Type 11 request received from Scheduler@node2.supernodexp.hpc, sock=20
02/14/2018 16:40:48;0008;Server@node2;Job;1221.node2.supernodexp.hpc;Job Modified at request of Scheduler@node2.supernodexp.hpc
02/14/2018 16:40:48;0100;Server@node2;Req;;Type 11 request received from Scheduler@node2.supernodexp.hpc, sock=20
02/14/2018 16:40:48;0008;Server@node2;Job;1222.node2.supernodexp.hpc;Job Modified at request of Scheduler@node2.supernodexp.hpc
02/14/2018 16:40:48;0100;Server@node2;Req;;Type 11 request received from Scheduler@node2.supernodexp.hpc, sock=20
02/14/2018 16:40:48;0008;Server@node2;Job;1224.node2.supernodexp.hpc;Job Modified at request of Scheduler@node2.supernodexp.hpc
02/14/2018 16:40:48;0100;Server@node2;Req;;Type 11 request received from Scheduler@node2.supernodexp.hpc, sock=20
02/14/2018 16:40:48;0008;Server@node2;Job;1225.node2.supernodexp.hpc;Job Modified at request of Scheduler@node2.supernodexp.hpc
02/14/2018 16:40:48;0100;Server@node2;Req;;Type 11 request received from Scheduler@node2.supernodexp.hpc, sock=20
02/14/2018 16:40:48;0008;Server@node2;Job;1226.node2.supernodexp.hpc;Job Modified at request of Scheduler@node2.supernodexp.hpc
02/14/2018 16:40:48;0100;Server@node2;Req;;Type 11 request received from Scheduler@node2.supernodexp.hpc, sock=20
02/14/2018 16:40:48;0008;Server@node2;Job;1227.node2.supernodexp.hpc;Job Modified at request of Scheduler@node2.supernodexp.hpc
02/14/2018 16:40:48;0100;Server@node2;Req;;Type 11 request received from Scheduler@node2.supernodexp.hpc, sock=20
02/14/2018 16:40:48;0008;Server@node2;Job;1228.node2.supernodexp.hpc;Job Modified at request of Scheduler@node2.supernodexp.hpc
02/14/2018 16:40:48;0100;Server@node2;Req;;Type 11 request received from Scheduler@node2.supernodexp.hpc, sock=20
02/14/2018 16:40:48;0008;Server@node2;Job;1229.node2.supernodexp.hpc;Job Modified at request of Scheduler@node2.supernodexp.hpc
02/14/2018 16:40:48;0100;Server@node2;Req;;Type 11 request received from Scheduler@node2.supernodexp.hpc, sock=20
02/14/2018 16:40:48;0008;Server@node2;Job;1231.node2.supernodexp.hpc;Job Modified at request of Scheduler@node2.supernodexp.hpc
02/14/2018 16:40:48;0100;Server@node2;Req;;Type 11 request received from Scheduler@node2.supernodexp.hpc, sock=20
02/14/2018 16:40:48;0008;Server@node2;Job;1233.node2.supernodexp.hpc;Job Modified at request of Scheduler@node2.supernodexp.hpc
02/14/2018 16:40:48;0100;Server@node2;Req;;Type 11 request received from Scheduler@node2.supernodexp.hpc, sock=20
02/14/2018 16:40:48;0008;Server@node2;Job;1234.node2.supernodexp.hpc;Job Modified at request of Scheduler@node2.supernodexp.hpc
02/14/2018 16:40:48;0100;Server@node2;Req;;Type 11 request received from Scheduler@node2.supernodexp.hpc, sock=20
02/14/2018 16:40:48;0008;Server@node2;Job;1235.node2.supernodexp.hpc;Job Modified at request of Scheduler@node2.supernodexp.hpc
02/14/2018 16:40:48;0100;Server@node2;Req;;Type 11 request received from Scheduler@node2.supernodexp.hpc, sock=20
02/14/2018 16:40:48;0008;Server@node2;Job;1236.node2.supernodexp.hpc;Job Modified at request of Scheduler@node2.supernodexp.hpc
02/14/2018 16:40:48;0100;Server@node2;Req;;Type 11 request received from Scheduler@node2.supernodexp.hpc, sock=20
02/14/2018 16:40:48;0008;Server@node2;Job;1238.node2.supernodexp.hpc;Job Modified at request of Scheduler@node2.supernodexp.hpc
02/14/2018 16:40:48;0100;Server@node2;Req;;Type 11 request received from Scheduler@node2.supernodexp.hpc, sock=20
02/14/2018 16:40:48;0008;Server@node2;Job;1239.node2.supernodexp.hpc;Job Modified at request of Scheduler@node2.supernodexp.hpc
02/14/2018 16:40:48;0100;Server@node2;Req;;Type 11 request received from Scheduler@node2.supernodexp.hpc, sock=20
02/14/2018 16:40:48;0008;Server@node2;Job;1240.node2.supernodexp.hpc;Job Modified at request of Scheduler@node2.supernodexp.hpc
02/14/2018 16:40:48;0100;Server@node2;Req;;Type 11 request received from Scheduler@node2.supernodexp.hpc, sock=20
02/14/2018 16:40:48;0008;Server@node2;Job;1241.node2.supernodexp.hpc;Job Modified at request of Scheduler@node2.supernodexp.hpc
02/14/2018 16:40:48;0100;Server@node2;Req;;Type 11 request received from Scheduler@node2.supernodexp.hpc, sock=20
02/14/2018 16:40:48;0008;Server@node2;Job;1242.node2.supernodexp.hpc;Job Modified at request of Scheduler@node2.supernodexp.hpc
02/14/2018 16:40:48;0100;Server@node2;Req;;Type 11 request received from Scheduler@node2.supernodexp.hpc, sock=20
02/14/2018 16:40:48;0008;Server@node2;Job;1243.node2.supernodexp.hpc;Job Modified at request of Scheduler@node2.supernodexp.hpc
02/14/2018 16:40:48;0100;Server@node2;Req;;Type 11 request received from Scheduler@node2.supernodexp.hpc, sock=20
02/14/2018 16:40:48;0008;Server@node2;Job;1245.node2.supernodexp.hpc;Job Modified at request of Scheduler@node2.supernodexp.hpc
02/14/2018 16:40:48;0100;Server@node2;Req;;Type 11 request received from Scheduler@node2.supernodexp.hpc, sock=20
02/14/2018 16:40:48;0008;Server@node2;Job;1246.node2.supernodexp.hpc;Job Modified at request of Scheduler@node2.supernodexp.hpc
02/14/2018 16:40:48;0100;Server@node2;Req;;Type 11 request received from Scheduler@node2.supernodexp.hpc, sock=20
02/14/2018 16:40:48;0008;Server@node2;Job;1248.node2.supernodexp.hpc;Job Modified at request of Scheduler@node2.supernodexp.hpc
02/14/2018 16:40:48;0100;Server@node2;Req;;Type 11 request received from Scheduler@node2.supernodexp.hpc, sock=20
02/14/2018 16:40:48;0008;Server@node2;Job;1249.node2.supernodexp.hpc;Job Modified at request of Scheduler@node2.supernodexp.hpc
02/14/2018 16:40:48;0100;Server@node2;Req;;Type 11 request received from Scheduler@node2.supernodexp.hpc, sock=20
02/14/2018 16:40:48;0008;Server@node2;Job;1250.node2.supernodexp.hpc;Job Modified at request of Scheduler@node2.supernodexp.hpc
02/14/2018 16:40:48;0100;Server@node2;Req;;Type 11 request received from Scheduler@node2.supernodexp.hpc, sock=20
02/14/2018 16:40:48;0008;Server@node2;Job;1251.node2.supernodexp.hpc;Job Modified at request of Scheduler@node2.supernodexp.hpc
02/14/2018 16:40:48;0100;Server@node2;Req;;Type 11 request received from Scheduler@node2.supernodexp.hpc, sock=20
02/14/2018 16:40:48;0008;Server@node2;Job;1252.node2.supernodexp.hpc;Job Modified at request of Scheduler@node2.supernodexp.hpc
02/14/2018 16:40:48;0100;Server@node2;Req;;Type 11 request received from Scheduler@node2.supernodexp.hpc, sock=20
02/14/2018 16:40:48;0008;Server@node2;Job;1253.node2.supernodexp.hpc;Job Modified at request of Scheduler@node2.supernodexp.hpc
02/14/2018 16:40:48;0100;Server@node2;Req;;Type 11 request received from Scheduler@node2.supernodexp.hpc, sock=20
02/14/2018 16:40:48;0008;Server@node2;Job;1254.node2.supernodexp.hpc;Job Modified at request of Scheduler@node2.supernodexp.hpc
02/14/2018 16:40:48;0100;Server@node2;Req;;Type 11 request received from Scheduler@node2.supernodexp.hpc, sock=20
02/14/2018 16:40:48;0008;Server@node2;Job;1255.node2.supernodexp.hpc;Job Modified at request of Scheduler@node2.supernodexp.hpc
02/14/2018 16:40:48;0100;Server@node2;Req;;Type 11 request received from Scheduler@node2.supernodexp.hpc, sock=20
02/14/2018 16:40:48;0008;Server@node2;Job;1256.node2.supernodexp.hpc;Job Modified at request of Scheduler@node2.supernodexp.hpc
02/14/2018 16:40:48;0100;Server@node2;Req;;Type 11 request received from Scheduler@node2.supernodexp.hpc, sock=20
02/14/2018 16:40:48;0008;Server@node2;Job;1257.node2.supernodexp.hpc;Job Modified at request of Scheduler@node2.supernodexp.hpc
02/14/2018 16:40:48;0100;Server@node2;Req;;Type 11 request received from Scheduler@node2.supernodexp.hpc, sock=20
02/14/2018 16:40:48;0008;Server@node2;Job;1259.node2.supernodexp.hpc;Job Modified at request of Scheduler@node2.supernodexp.hpc
02/14/2018 16:40:48;0100;Server@node2;Req;;Type 11 request received from Scheduler@node2.supernodexp.hpc, sock=20
02/14/2018 16:40:48;0008;Server@node2;Job;1260.node2.supernodexp.hpc;Job Modified at request of Scheduler@node2.supernodexp.hpc
02/14/2018 16:40:48;0100;Server@node2;Req;;Type 11 request received from Scheduler@node2.supernodexp.hpc, sock=20
02/14/2018 16:40:48;0008;Server@node2;Job;1261.node2.supernodexp.hpc;Job Modified at request of Scheduler@node2.supernodexp.hpc
02/14/2018 16:40:48;0100;Server@node2;Req;;Type 11 request received from Scheduler@node2.supernodexp.hpc, sock=20
02/14/2018 16:40:48;0008;Server@node2;Job;1263.node2.supernodexp.hpc;Job Modified at request of Scheduler@node2.supernodexp.hpc
02/14/2018 16:40:48;0100;Server@node2;Req;;Type 11 request received from Scheduler@node2.supernodexp.hpc, sock=20
02/14/2018 16:40:48;0008;Server@node2;Job;1264.node2.supernodexp.hpc;Job Modified at request of Scheduler@node2.supernodexp.hpc
02/14/2018 16:40:48;0100;Server@node2;Req;;Type 11 request received from Scheduler@node2.supernodexp.hpc, sock=20
02/14/2018 16:40:48;0008;Server@node2;Job;1265.node2.supernodexp.hpc;Job Modified at request of Scheduler@node2.supernodexp.hpc
02/14/2018 16:40:48;0100;Server@node2;Req;;Type 11 request received from Scheduler@node2.supernodexp.hpc, sock=20
02/14/2018 16:40:48;0008;Server@node2;Job;1266.node2.supernodexp.hpc;Job Modified at request of Scheduler@node2.supernodexp.hpc
02/14/2018 16:40:48;0100;Server@node2;Req;;Type 11 request received from Scheduler@node2.supernodexp.hpc, sock=20
02/14/2018 16:40:48;0008;Server@node2;Job;1267.node2.supernodexp.hpc;Job Modified at request of Scheduler@node2.supernodexp.hpc
02/14/2018 16:40:48;0100;Server@node2;Req;;Type 11 request received from Scheduler@node2.supernodexp.hpc, sock=20
02/14/2018 16:40:48;0008;Server@node2;Job;1268.node2.supernodexp.hpc;Job Modified at request of Scheduler@node2.supernodexp.hpc
02/14/2018 16:40:48;0100;Server@node2;Req;;Type 11 request received from Scheduler@node2.supernodexp.hpc, sock=20
02/14/2018 16:40:48;0008;Server@node2;Job;1269.node2.supernodexp.hpc;Job Modified at request of Scheduler@node2.supernodexp.hpc
02/14/2018 16:40:48;0100;Server@node2;Req;;Type 11 request received from Scheduler@node2.supernodexp.hpc, sock=20
02/14/2018 16:40:48;0008;Server@node2;Job;1270.node2.supernodexp.hpc;Job Modified at request of Scheduler@node2.supernodexp.hpc
02/14/2018 16:40:48;0100;Server@node2;Req;;Type 11 request received from Scheduler@node2.supernodexp.hpc, sock=20
02/14/2018 16:40:48;0008;Server@node2;Job;1272.node2.supernodexp.hpc;Job Modified at request of Scheduler@node2.supernodexp.hpc
02/14/2018 16:40:48;0100;Server@node2;Req;;Type 11 request received from Scheduler@node2.supernodexp.hpc, sock=20
02/14/2018 16:40:48;0008;Server@node2;Job;1273.node2.supernodexp.hpc;Job Modified at request of Scheduler@node2.supernodexp.hpc
02/14/2018 16:40:48;0100;Server@node2;Req;;Type 11 request received from Scheduler@node2.supernodexp.hpc, sock=20
02/14/2018 16:40:48;0008;Server@node2;Job;1274.node2.supernodexp.hpc;Job Modified at request of Scheduler@node2.supernodexp.hpc
02/14/2018 16:40:48;0100;Server@node2;Req;;Type 11 request received from Scheduler@node2.supernodexp.hpc, sock=20
02/14/2018 16:40:48;0008;Server@node2;Job;1276.node2.supernodexp.hpc;Job Modified at request of Scheduler@node2.supernodexp.hpc
02/14/2018 16:40:48;0100;Server@node2;Req;;Type 11 request received from Scheduler@node2.supernodexp.hpc, sock=20
02/14/2018 16:40:48;0008;Server@node2;Job;1278.node2.supernodexp.hpc;Job Modified at request of Scheduler@node2.supernodexp.hpc
02/14/2018 16:40:48;0100;Server@node2;Req;;Type 11 request received from Scheduler@node2.supernodexp.hpc, sock=20
02/14/2018 16:40:48;0008;Server@node2;Job;1279.node2.supernodexp.hpc;Job Modified at request of Scheduler@node2.supernodexp.hpc
02/14/2018 16:40:48;0100;Server@node2;Req;;Type 11 request received from Scheduler@node2.supernodexp.hpc, sock=20
02/14/2018 16:40:48;0008;Server@node2;Job;1280.node2.supernodexp.hpc;Job Modified at request of Scheduler@node2.supernodexp.hpc
02/14/2018 16:40:48;0100;Server@node2;Req;;Type 11 request received from Scheduler@node2.supernodexp.hpc, sock=20
02/14/2018 16:40:48;0008;Server@node2;Job;1281.node2.supernodexp.hpc;Job Modified at request of Scheduler@node2.supernodexp.hpc
02/14/2018 16:40:48;0100;Server@node2;Req;;Type 11 request received from Scheduler@node2.supernodexp.hpc, sock=20
02/14/2018 16:40:48;0008;Server@node2;Job;1282.node2.supernodexp.hpc;Job Modified at request of Scheduler@node2.supernodexp.hpc
02/14/2018 16:40:48;0100;Server@node2;Req;;Type 11 request received from Scheduler@node2.supernodexp.hpc, sock=20
02/14/2018 16:40:48;0008;Server@node2;Job;1283.node2.supernodexp.hpc;Job Modified at request of Scheduler@node2.supernodexp.hpc
02/14/2018 16:40:48;0100;Server@node2;Req;;Type 11 request received from Scheduler@node2.supernodexp.hpc, sock=20
02/14/2018 16:40:48;0008;Server@node2;Job;1284.node2.supernodexp.hpc;Job Modified at request of Scheduler@node2.supernodexp.hpc
02/14/2018 16:40:48;0100;Server@node2;Req;;Type 11 request received from Scheduler@node2.supernodexp.hpc, sock=20
02/14/2018 16:40:48;0008;Server@node2;Job;1285.node2.supernodexp.hpc;Job Modified at request of Scheduler@node2.supernodexp.hpc
02/14/2018 16:40:48;0100;Server@node2;Req;;Type 11 request received from Scheduler@node2.supernodexp.hpc, sock=20
02/14/2018 16:40:48;0008;Server@node2;Job;1286.node2.supernodexp.hpc;Job Modified at request of Scheduler@node2.supernodexp.hpc
02/14/2018 16:40:48;0100;Server@node2;Req;;Type 11 request received from Scheduler@node2.supernodexp.hpc, sock=20
02/14/2018 16:40:48;0008;Server@node2;Job;1287.node2.supernodexp.hpc;Job Modified at request of Scheduler@node2.supernodexp.hpc
02/14/2018 16:40:48;0100;Server@node2;Req;;Type 11 request received from Scheduler@node2.supernodexp.hpc, sock=20
02/14/2018 16:40:48;0008;Server@node2;Job;1288.node2.supernodexp.hpc;Job Modified at request of Scheduler@node2.supernodexp.hpc
02/14/2018 16:40:48;0100;Server@node2;Req;;Type 11 request received from Scheduler@node2.supernodexp.hpc, sock=20
02/14/2018 16:40:48;0008;Server@node2;Job;1289.node2.supernodexp.hpc;Job Modified at request of Scheduler@node2.supernodexp.hpc
02/14/2018 16:40:48;0100;Server@node2;Req;;Type 11 request received from Scheduler@node2.supernodexp.hpc, sock=20
02/14/2018 16:40:48;0008;Server@node2;Job;1290.node2.supernodexp.hpc;Job Modified at request of Scheduler@node2.supernodexp.hpc
02/14/2018 16:40:48;0100;Server@node2;Req;;Type 11 request received from Scheduler@node2.supernodexp.hpc, sock=20
02/14/2018 16:40:48;0008;Server@node2;Job;1291.node2.supernodexp.hpc;Job Modified at request of Scheduler@node2.supernodexp.hpc
02/14/2018 16:40:48;0100;Server@node2;Req;;Type 11 request received from Scheduler@node2.supernodexp.hpc, sock=20
02/14/2018 16:40:48;0008;Server@node2;Job;1292.node2.supernodexp.hpc;Job Modified at request of Scheduler@node2.supernodexp.hpc
02/14/2018 16:40:48;0100;Server@node2;Req;;Type 11 request received from Scheduler@node2.supernodexp.hpc, sock=20
02/14/2018 16:40:48;0008;Server@node2;Job;1293.node2.supernodexp.hpc;Job Modified at request of Scheduler@node2.supernodexp.hpc
02/14/2018 16:40:48;0100;Server@node2;Req;;Type 11 request received from Scheduler@node2.supernodexp.hpc, sock=20
02/14/2018 16:40:48;0008;Server@node2;Job;1295.node2.supernodexp.hpc;Job Modified at request of Scheduler@node2.supernodexp.hpc
02/14/2018 16:40:48;0100;Server@node2;Req;;Type 11 request received from Scheduler@node2.supernodexp.hpc, sock=20
02/14/2018 16:40:48;0008;Server@node2;Job;1296.node2.supernodexp.hpc;Job Modified at request of Scheduler@node2.supernodexp.hpc
02/14/2018 16:40:48;0100;Server@node2;Req;;Type 11 request received from Scheduler@node2.supernodexp.hpc, sock=20
02/14/2018 16:40:48;0008;Server@node2;Job;1298.node2.supernodexp.hpc;Job Modified at request of Scheduler@node2.supernodexp.hpc
02/14/2018 16:40:48;0100;Server@node2;Req;;Type 11 request received from Scheduler@node2.supernodexp.hpc, sock=20
02/14/2018 16:40:48;0008;Server@node2;Job;1299.node2.supernodexp.hpc;Job Modified at request of Scheduler@node2.supernodexp.hpc
02/14/2018 16:40:48;0100;Server@node2;Req;;Type 11 request received from Scheduler@node2.supernodexp.hpc, sock=20
02/14/2018 16:40:48;0008;Server@node2;Job;1300.node2.supernodexp.hpc;Job Modified at request of Scheduler@node2.supernodexp.hpc
02/14/2018 16:40:48;0100;Server@node2;Req;;Type 11 request received from Scheduler@node2.supernodexp.hpc, sock=20
02/14/2018 16:40:48;0008;Server@node2;Job;1301.node2.supernodexp.hpc;Job Modified at request of Scheduler@node2.supernodexp.hpc
02/14/2018 16:40:48;0100;Server@node2;Req;;Type 11 request received from Scheduler@node2.supernodexp.hpc, sock=20
02/14/2018 16:40:48;0008;Server@node2;Job;1302.node2.supernodexp.hpc;Job Modified at request of Scheduler@node2.supernodexp.hpc
02/14/2018 16:40:48;0100;Server@node2;Req;;Type 11 request received from Scheduler@node2.supernodexp.hpc, sock=20
02/14/2018 16:40:48;0008;Server@node2;Job;1303.node2.supernodexp.hpc;Job Modified at request of Scheduler@node2.supernodexp.hpc
02/14/2018 16:40:48;0100;Server@node2;Req;;Type 11 request received from Scheduler@node2.supernodexp.hpc, sock=20
02/14/2018 16:40:48;0008;Server@node2;Job;1304.node2.supernodexp.hpc;Job Modified at request of Scheduler@node2.supernodexp.hpc
02/14/2018 16:40:48;0100;Server@node2;Req;;Type 11 request received from Scheduler@node2.supernodexp.hpc, sock=20
02/14/2018 16:40:48;0008;Server@node2;Job;1305.node2.supernodexp.hpc;Job Modified at request of Scheduler@node2.supernodexp.hpc
02/14/2018 16:40:48;0100;Server@node2;Req;;Type 11 request received from Scheduler@node2.supernodexp.hpc, sock=20
02/14/2018 16:40:48;0008;Server@node2;Job;1307.node2.supernodexp.hpc;Job Modified at request of Scheduler@node2.supernodexp.hpc
02/14/2018 16:40:48;0100;Server@node2;Req;;Type 11 request received from Scheduler@node2.supernodexp.hpc, sock=20
02/14/2018 16:40:48;0008;Server@node2;Job;1308.node2.supernodexp.hpc;Job Modified at request of Scheduler@node2.supernodexp.hpc
02/14/2018 16:40:48;0100;Server@node2;Req;;Type 11 request received from Scheduler@node2.supernodexp.hpc, sock=20
02/14/2018 16:40:48;0008;Server@node2;Job;1309.node2.supernodexp.hpc;Job Modified at request of Scheduler@node2.supernodexp.hpc
02/14/2018 16:40:48;0100;Server@node2;Req;;Type 11 request received from Scheduler@node2.supernodexp.hpc, sock=20
02/14/2018 16:40:48;0008;Server@node2;Job;1310.node2.supernodexp.hpc;Job Modified at request of Scheduler@node2.supernodexp.hpc
02/14/2018 16:40:48;0100;Server@node2;Req;;Type 11 request received from Scheduler@node2.supernodexp.hpc, sock=20
02/14/2018 16:40:48;0008;Server@node2;Job;1311.node2.supernodexp.hpc;Job Modified at request of Scheduler@node2.supernodexp.hpc
02/14/2018 16:40:48;0100;Server@node2;Req;;Type 11 request received from Scheduler@node2.supernodexp.hpc, sock=20
02/14/2018 16:40:48;0008;Server@node2;Job;1312.node2.supernodexp.hpc;Job Modified at request of Scheduler@node2.supernodexp.hpc
02/14/2018 16:40:48;0100;Server@node2;Req;;Type 11 request received from Scheduler@node2.supernodexp.hpc, sock=20
02/14/2018 16:40:48;0008;Server@node2;Job;1313.node2.supernodexp.hpc;Job Modified at request of Scheduler@node2.supernodexp.hpc
02/14/2018 16:40:48;0100;Server@node2;Req;;Type 11 request received from Scheduler@node2.supernodexp.hpc, sock=20
02/14/2018 16:40:48;0008;Server@node2;Job;1314.node2.supernodexp.hpc;Job Modified at request of Scheduler@node2.supernodexp.hpc
02/14/2018 16:40:48;0100;Server@node2;Req;;Type 11 request received from Scheduler@node2.supernodexp.hpc, sock=20
02/14/2018 16:40:48;0008;Server@node2;Job;1315.node2.supernodexp.hpc;Job Modified at request of Scheduler@node2.supernodexp.hpc
02/14/2018 16:40:48;0100;Server@node2;Req;;Type 11 request received from Scheduler@node2.supernodexp.hpc, sock=20
02/14/2018 16:40:48;0008;Server@node2;Job;1316.node2.supernodexp.hpc;Job Modified at request of Scheduler@node2.supernodexp.hpc
02/14/2018 16:40:48;0100;Server@node2;Req;;Type 11 request received from Scheduler@node2.supernodexp.hpc, sock=20
02/14/2018 16:40:48;0008;Server@node2;Job;1317.node2.supernodexp.hpc;Job Modified at request of Scheduler@node2.supernodexp.hpc
02/14/2018 16:40:48;0100;Server@node2;Req;;Type 11 request received from Scheduler@node2.supernodexp.hpc, sock=20
02/14/2018 16:40:48;0008;Server@node2;Job;1318.node2.supernodexp.hpc;Job Modified at request of Scheduler@node2.supernodexp.hpc
02/14/2018 16:40:48;0100;Server@node2;Req;;Type 11 request received from Scheduler@node2.supernodexp.hpc, sock=20
02/14/2018 16:40:48;0008;Server@node2;Job;1319.node2.supernodexp.hpc;Job Modified at request of Scheduler@node2.supernodexp.hpc
02/14/2018 16:40:48;0100;Server@node2;Req;;Type 11 request received from Scheduler@node2.supernodexp.hpc, sock=20
02/14/2018 16:40:48;0008;Server@node2;Job;1320.node2.supernodexp.hpc;Job Modified at request of Scheduler@node2.supernodexp.hpc
02/14/2018 16:40:48;0100;Server@node2;Req;;Type 11 request received from Scheduler@node2.supernodexp.hpc, sock=20
02/14/2018 16:40:48;0008;Server@node2;Job;1321.node2.supernodexp.hpc;Job Modified at request of Scheduler@node2.supernodexp.hpc
02/14/2018 16:40:48;0100;Server@node2;Req;;Type 11 request received from Scheduler@node2.supernodexp.hpc, sock=20
02/14/2018 16:40:48;0008;Server@node2;Job;1322.node2.supernodexp.hpc;Job Modified at request of Scheduler@node2.supernodexp.hpc
02/14/2018 16:40:48;0100;Server@node2;Req;;Type 11 request received from Scheduler@node2.supernodexp.hpc, sock=20
02/14/2018 16:40:48;0008;Server@node2;Job;1323.node2.supernodexp.hpc;Job Modified at request of Scheduler@node2.supernodexp.hpc
02/14/2018 16:40:48;0100;Server@node2;Req;;Type 11 request received from Scheduler@node2.supernodexp.hpc, sock=20
02/14/2018 16:40:48;0008;Server@node2;Job;1324.node2.supernodexp.hpc;Job Modified at request of Scheduler@node2.supernodexp.hpc
02/14/2018 16:40:48;0100;Server@node2;Req;;Type 11 request received from Scheduler@node2.supernodexp.hpc, sock=20
02/14/2018 16:40:48;0008;Server@node2;Job;1325.node2.supernodexp.hpc;Job Modified at request of Scheduler@node2.supernodexp.hpc
02/14/2018 16:40:48;0100;Server@node2;Req;;Type 11 request received from Scheduler@node2.supernodexp.hpc, sock=20
02/14/2018 16:40:48;0008;Server@node2;Job;1326.node2.supernodexp.hpc;Job Modified at request of Scheduler@node2.supernodexp.hpc
02/14/2018 16:40:48;0100;Server@node2;Req;;Type 11 request received from Scheduler@node2.supernodexp.hpc, sock=20
02/14/2018 16:40:48;0008;Server@node2;Job;1327.node2.supernodexp.hpc;Job Modified at request of Scheduler@node2.supernodexp.hpc
02/14/2018 16:40:48;0100;Server@node2;Req;;Type 11 request received from Scheduler@node2.supernodexp.hpc, sock=20
02/14/2018 16:40:48;0008;Server@node2;Job;1328.node2.supernodexp.hpc;Job Modified at request of Scheduler@node2.supernodexp.hpc
02/14/2018 16:40:48;0100;Server@node2;Req;;Type 11 request received from Scheduler@node2.supernodexp.hpc, sock=20
02/14/2018 16:40:48;0008;Server@node2;Job;1329.node2.supernodexp.hpc;Job Modified at request of Scheduler@node2.supernodexp.hpc
02/14/2018 16:40:48;0100;Server@node2;Req;;Type 11 request received from Scheduler@node2.supernodexp.hpc, sock=20
02/14/2018 16:40:48;0008;Server@node2;Job;1330.node2.supernodexp.hpc;Job Modified at request of Scheduler@node2.supernodexp.hpc
02/14/2018 16:40:48;0100;Server@node2;Req;;Type 11 request received from Scheduler@node2.supernodexp.hpc, sock=20
02/14/2018 16:40:48;0008;Server@node2;Job;1332.node2.supernodexp.hpc;Job Modified at request of Scheduler@node2.supernodexp.hpc
02/14/2018 16:40:48;0100;Server@node2;Req;;Type 11 request received from Scheduler@node2.supernodexp.hpc, sock=20
02/14/2018 16:40:48;0008;Server@node2;Job;1333.node2.supernodexp.hpc;Job Modified at request of Scheduler@node2.supernodexp.hpc
02/14/2018 16:40:48;0100;Server@node2;Req;;Type 11 request received from Scheduler@node2.supernodexp.hpc, sock=20
02/14/2018 16:40:48;0008;Server@node2;Job;1335.node2.supernodexp.hpc;Job Modified at request of Scheduler@node2.supernodexp.hpc
02/14/2018 16:40:48;0100;Server@node2;Req;;Type 11 request received from Scheduler@node2.supernodexp.hpc, sock=20
