02/14/2018 00:00:00;0002;Server@node2;Svr;Log;Log opened
02/14/2018 00:00:00;0002;Server@node2;Svr;Server@node2;pbs_version=14.0.1
02/14/2018 00:00:00;0002;Server@node2;Svr;Server@node2;pbs_build=mach=N/A:security=N/A:configure_args=N/A
02/14/2018 00:00:00;0002;Server@node2;Svr;Server@node2;hostname=node2.supernodexp.hpc;pbs_leaf_name=N/A;pbs_mom_node_name=N/A
02/14/2018 00:00:00;0002;Server@node2;Svr;Server@node2;ipv4 interface lo: localhost localhost.localdomain localhost4 localhost4.localdomain4 
02/14/2018 00:00:00;0002;Server@node2;Svr;Server@node2;ipv4 interface br0: node2.supernodexp.hpc node2 supernodexp-cn02 
02/14/2018 00:00:00;0002;Server@node2;Svr;Server@node2;ipv4 interface ib0: node2.supernodexp.hpc 
02/14/2018 00:00:00;0002;Server@node2;Svr;Server@node2;ipv4 interface docker0: node2.supernodexp.hpc 
02/14/2018 00:00:00;0002;Server@node2;Svr;Server@node2;ipv4 interface virbr0: node2.supernodexp.hpc 
02/14/2018 00:00:00;0002;Server@node2;Svr;Server@node2;ipv6 interface lo: localhost localhost.localdomain localhost6 localhost6.localdomain6 
02/14/2018 00:00:00;0002;Server@node2;Svr;Server@node2;ipv6 interface eno49: node2.supernodexp.hpc 
02/14/2018 00:00:00;0002;Server@node2;Svr;Server@node2;ipv6 interface br0: node2.supernodexp.hpc 
02/14/2018 00:00:00;0002;Server@node2;Svr;Server@node2;ipv6 interface ib0: node2.supernodexp.hpc 
02/14/2018 00:00:00;0002;Server@node2;Svr;Server@node2;ipv6 interface veth1pl7177: node2.supernodexp.hpc 
02/14/2018 00:00:00;0002;Server@node2;Svr;Act;Account file /var/spool/pbs/server_priv/accounting/20180214 opened
02/14/2018 00:03:49;0040;Server@node2;Svr;node2.supernodexp.hpc;Scheduler sent command 3
02/14/2018 00:03:49;0040;Server@node2;Svr;node2.supernodexp.hpc;Scheduler sent command 0
02/14/2018 00:03:49;0100;Server@node2;Req;;Type 21 request received from Scheduler@node2.supernodexp.hpc, sock=16
02/14/2018 00:03:49;0100;Server@node2;Req;;Type 81 request received from Scheduler@node2.supernodexp.hpc, sock=16
02/14/2018 00:03:49;0100;Server@node2;Req;;Type 71 request received from Scheduler@node2.supernodexp.hpc, sock=16
02/14/2018 00:03:49;0100;Server@node2;Req;;Type 58 request received from Scheduler@node2.supernodexp.hpc, sock=16
02/14/2018 00:03:49;0100;Server@node2;Req;;Type 20 request received from Scheduler@node2.supernodexp.hpc, sock=16
02/14/2018 00:03:49;0100;Server@node2;Req;;Type 51 request received from Scheduler@node2.supernodexp.hpc, sock=16
02/14/2018 00:13:49;0040;Server@node2;Svr;node2.supernodexp.hpc;Scheduler sent command 3
02/14/2018 00:13:49;0040;Server@node2;Svr;node2.supernodexp.hpc;Scheduler sent command 0
02/14/2018 00:13:49;0100;Server@node2;Req;;Type 21 request received from Scheduler@node2.supernodexp.hpc, sock=16
02/14/2018 00:13:49;0100;Server@node2;Req;;Type 81 request received from Scheduler@node2.supernodexp.hpc, sock=16
02/14/2018 00:13:49;0100;Server@node2;Req;;Type 71 request received from Scheduler@node2.supernodexp.hpc, sock=16
02/14/2018 00:13:49;0100;Server@node2;Req;;Type 58 request received from Scheduler@node2.supernodexp.hpc, sock=16
02/14/2018 00:13:49;0100;Server@node2;Req;;Type 20 request received from Scheduler@node2.supernodexp.hpc, sock=16
02/14/2018 00:13:49;0100;Server@node2;Req;;Type 51 request received from Scheduler@node2.supernodexp.hpc, sock=16
02/14/2018 00:23:49;0040;Server@node2;Svr;node2.supernodexp.hpc;Scheduler sent command 3
02/14/2018 00:23:49;0040;Server@node2;Svr;node2.supernodexp.hpc;Scheduler sent command 0
02/14/2018 00:23:49;0100;Server@node2;Req;;Type 21 request received from Scheduler@node2.supernodexp.hpc, sock=16
02/14/2018 00:23:49;0100;Server@node2;Req;;Type 81 request received from Scheduler@node2.supernodexp.hpc, sock=16
02/14/2018 00:23:49;0100;Server@node2;Req;;Type 71 request received from Scheduler@node2.supernodexp.hpc, sock=16
02/14/2018 00:23:49;0100;Server@node2;Req;;Type 58 request received from Scheduler@node2.supernodexp.hpc, sock=16
02/14/2018 00:23:49;0100;Server@node2;Req;;Type 20 request received from Scheduler@node2.supernodexp.hpc, sock=16
02/14/2018 00:23:49;0100;Server@node2;Req;;Type 51 request received from Scheduler@node2.supernodexp.hpc, sock=16
02/14/2018 00:33:49;0040;Server@node2;Svr;node2.supernodexp.hpc;Scheduler sent command 3
02/14/2018 00:33:49;0040;Server@node2;Svr;node2.supernodexp.hpc;Scheduler sent command 0
02/14/2018 00:33:49;0100;Server@node2;Req;;Type 21 request received from Scheduler@node2.supernodexp.hpc, sock=16
02/14/2018 00:33:49;0100;Server@node2;Req;;Type 81 request received from Scheduler@node2.supernodexp.hpc, sock=16
02/14/2018 00:33:49;0100;Server@node2;Req;;Type 71 request received from Scheduler@node2.supernodexp.hpc, sock=16
02/14/2018 00:33:49;0100;Server@node2;Req;;Type 58 request received from Scheduler@node2.supernodexp.hpc, sock=16
02/14/2018 00:33:49;0100;Server@node2;Req;;Type 20 request received from Scheduler@node2.supernodexp.hpc, sock=16
02/14/2018 00:33:49;0100;Server@node2;Req;;Type 51 request received from Scheduler@node2.supernodexp.hpc, sock=16
02/14/2018 00:43:49;0040;Server@node2;Svr;node2.supernodexp.hpc;Scheduler sent command 3
02/14/2018 00:43:49;0040;Server@node2;Svr;node2.supernodexp.hpc;Scheduler sent command 0
02/14/2018 00:43:49;0100;Server@node2;Req;;Type 21 request received from Scheduler@node2.supernodexp.hpc, sock=16
02/14/2018 00:43:49;0100;Server@node2;Req;;Type 81 request received from Scheduler@node2.supernodexp.hpc, sock=16
02/14/2018 00:43:49;0100;Server@node2;Req;;Type 71 request received from Scheduler@node2.supernodexp.hpc, sock=16
02/14/2018 00:43:49;0100;Server@node2;Req;;Type 58 request received from Scheduler@node2.supernodexp.hpc, sock=16
02/14/2018 00:43:49;0100;Server@node2;Req;;Type 20 request received from Scheduler@node2.supernodexp.hpc, sock=16
02/14/2018 00:43:49;0100;Server@node2;Req;;Type 51 request received from Scheduler@node2.supernodexp.hpc, sock=16
02/14/2018 00:53:49;0040;Server@node2;Svr;node2.supernodexp.hpc;Scheduler sent command 3
02/14/2018 00:53:49;0040;Server@node2;Svr;node2.supernodexp.hpc;Scheduler sent command 0
02/14/2018 00:53:49;0100;Server@node2;Req;;Type 21 request received from Scheduler@node2.supernodexp.hpc, sock=16
02/14/2018 00:53:49;0100;Server@node2;Req;;Type 81 request received from Scheduler@node2.supernodexp.hpc, sock=16
02/14/2018 00:53:49;0100;Server@node2;Req;;Type 71 request received from Scheduler@node2.supernodexp.hpc, sock=16
02/14/2018 00:53:49;0100;Server@node2;Req;;Type 58 request received from Scheduler@node2.supernodexp.hpc, sock=16
02/14/2018 00:53:49;0100;Server@node2;Req;;Type 20 request received from Scheduler@node2.supernodexp.hpc, sock=16
02/14/2018 00:53:49;0100;Server@node2;Req;;Type 51 request received from Scheduler@node2.supernodexp.hpc, sock=16
02/14/2018 01:03:49;0040;Server@node2;Svr;node2.supernodexp.hpc;Scheduler sent command 3
02/14/2018 01:03:49;0040;Server@node2;Svr;node2.supernodexp.hpc;Scheduler sent command 0
02/14/2018 01:03:49;0100;Server@node2;Req;;Type 21 request received from Scheduler@node2.supernodexp.hpc, sock=16
02/14/2018 01:03:49;0100;Server@node2;Req;;Type 81 request received from Scheduler@node2.supernodexp.hpc, sock=16
02/14/2018 01:03:49;0100;Server@node2;Req;;Type 71 request received from Scheduler@node2.supernodexp.hpc, sock=16
02/14/2018 01:03:49;0100;Server@node2;Req;;Type 58 request received from Scheduler@node2.supernodexp.hpc, sock=16
02/14/2018 01:03:49;0100;Server@node2;Req;;Type 20 request received from Scheduler@node2.supernodexp.hpc, sock=16
02/14/2018 01:03:49;0100;Server@node2;Req;;Type 51 request received from Scheduler@node2.supernodexp.hpc, sock=16
02/14/2018 01:13:49;0040;Server@node2;Svr;node2.supernodexp.hpc;Scheduler sent command 3
02/14/2018 01:13:49;0040;Server@node2;Svr;node2.supernodexp.hpc;Scheduler sent command 0
02/14/2018 01:13:49;0100;Server@node2;Req;;Type 21 request received from Scheduler@node2.supernodexp.hpc, sock=16
02/14/2018 01:13:49;0100;Server@node2;Req;;Type 81 request received from Scheduler@node2.supernodexp.hpc, sock=16
02/14/2018 01:13:49;0100;Server@node2;Req;;Type 71 request received from Scheduler@node2.supernodexp.hpc, sock=16
02/14/2018 01:13:49;0100;Server@node2;Req;;Type 58 request received from Scheduler@node2.supernodexp.hpc, sock=16
02/14/2018 01:13:49;0100;Server@node2;Req;;Type 20 request received from Scheduler@node2.supernodexp.hpc, sock=16
02/14/2018 01:13:49;0100;Server@node2;Req;;Type 51 request received from Scheduler@node2.supernodexp.hpc, sock=16
02/14/2018 01:23:49;0040;Server@node2;Svr;node2.supernodexp.hpc;Scheduler sent command 3
02/14/2018 01:23:49;0040;Server@node2;Svr;node2.supernodexp.hpc;Scheduler sent command 0
02/14/2018 01:23:49;0100;Server@node2;Req;;Type 21 request received from Scheduler@node2.supernodexp.hpc, sock=16
02/14/2018 01:23:49;0100;Server@node2;Req;;Type 81 request received from Scheduler@node2.supernodexp.hpc, sock=16
02/14/2018 01:23:49;0100;Server@node2;Req;;Type 71 request received from Scheduler@node2.supernodexp.hpc, sock=16
02/14/2018 01:23:49;0100;Server@node2;Req;;Type 58 request received from Scheduler@node2.supernodexp.hpc, sock=16
02/14/2018 01:23:49;0100;Server@node2;Req;;Type 20 request received from Scheduler@node2.supernodexp.hpc, sock=16
02/14/2018 01:23:49;0100;Server@node2;Req;;Type 51 request received from Scheduler@node2.supernodexp.hpc, sock=16
02/14/2018 01:33:49;0040;Server@node2;Svr;node2.supernodexp.hpc;Scheduler sent command 3
02/14/2018 01:33:49;0040;Server@node2;Svr;node2.supernodexp.hpc;Scheduler sent command 0
02/14/2018 01:33:49;0100;Server@node2;Req;;Type 21 request received from Scheduler@node2.supernodexp.hpc, sock=16
02/14/2018 01:33:49;0100;Server@node2;Req;;Type 81 request received from Scheduler@node2.supernodexp.hpc, sock=16
02/14/2018 01:33:49;0100;Server@node2;Req;;Type 71 request received from Scheduler@node2.supernodexp.hpc, sock=16
02/14/2018 01:33:49;0100;Server@node2;Req;;Type 58 request received from Scheduler@node2.supernodexp.hpc, sock=16
02/14/2018 01:33:49;0100;Server@node2;Req;;Type 20 request received from Scheduler@node2.supernodexp.hpc, sock=16
02/14/2018 01:33:49;0100;Server@node2;Req;;Type 51 request received from Scheduler@node2.supernodexp.hpc, sock=16
02/14/2018 01:43:49;0040;Server@node2;Svr;node2.supernodexp.hpc;Scheduler sent command 3
02/14/2018 01:43:49;0040;Server@node2;Svr;node2.supernodexp.hpc;Scheduler sent command 0
02/14/2018 01:43:49;0100;Server@node2;Req;;Type 21 request received from Scheduler@node2.supernodexp.hpc, sock=16
02/14/2018 01:43:49;0100;Server@node2;Req;;Type 81 request received from Scheduler@node2.supernodexp.hpc, sock=16
02/14/2018 01:43:49;0100;Server@node2;Req;;Type 71 request received from Scheduler@node2.supernodexp.hpc, sock=16
02/14/2018 01:43:49;0100;Server@node2;Req;;Type 58 request received from Scheduler@node2.supernodexp.hpc, sock=16
02/14/2018 01:43:49;0100;Server@node2;Req;;Type 20 request received from Scheduler@node2.supernodexp.hpc, sock=16
02/14/2018 01:43:49;0100;Server@node2;Req;;Type 51 request received from Scheduler@node2.supernodexp.hpc, sock=16
02/14/2018 01:53:49;0040;Server@node2;Svr;node2.supernodexp.hpc;Scheduler sent command 3
02/14/2018 01:53:49;0040;Server@node2;Svr;node2.supernodexp.hpc;Scheduler sent command 0
02/14/2018 01:53:49;0100;Server@node2;Req;;Type 21 request received from Scheduler@node2.supernodexp.hpc, sock=16
02/14/2018 01:53:49;0100;Server@node2;Req;;Type 81 request received from Scheduler@node2.supernodexp.hpc, sock=16
02/14/2018 01:53:49;0100;Server@node2;Req;;Type 71 request received from Scheduler@node2.supernodexp.hpc, sock=16
02/14/2018 01:53:49;0100;Server@node2;Req;;Type 58 request received from Scheduler@node2.supernodexp.hpc, sock=16
02/14/2018 01:53:49;0100;Server@node2;Req;;Type 20 request received from Scheduler@node2.supernodexp.hpc, sock=16
02/14/2018 01:53:49;0100;Server@node2;Req;;Type 51 request received from Scheduler@node2.supernodexp.hpc, sock=16
02/14/2018 02:03:49;0040;Server@node2;Svr;node2.supernodexp.hpc;Scheduler sent command 3
02/14/2018 02:03:49;0040;Server@node2;Svr;node2.supernodexp.hpc;Scheduler sent command 0
02/14/2018 02:03:49;0100;Server@node2;Req;;Type 21 request received from Scheduler@node2.supernodexp.hpc, sock=16
02/14/2018 02:03:49;0100;Server@node2;Req;;Type 81 request received from Scheduler@node2.supernodexp.hpc, sock=16
02/14/2018 02:03:49;0100;Server@node2;Req;;Type 71 request received from Scheduler@node2.supernodexp.hpc, sock=16
02/14/2018 02:03:49;0100;Server@node2;Req;;Type 58 request received from Scheduler@node2.supernodexp.hpc, sock=16
02/14/2018 02:03:49;0100;Server@node2;Req;;Type 20 request received from Scheduler@node2.supernodexp.hpc, sock=16
02/14/2018 02:03:49;0100;Server@node2;Req;;Type 51 request received from Scheduler@node2.supernodexp.hpc, sock=16
02/14/2018 02:13:49;0040;Server@node2;Svr;node2.supernodexp.hpc;Scheduler sent command 3
02/14/2018 02:13:49;0040;Server@node2;Svr;node2.supernodexp.hpc;Scheduler sent command 0
02/14/2018 02:13:49;0100;Server@node2;Req;;Type 21 request received from Scheduler@node2.supernodexp.hpc, sock=16
02/14/2018 02:13:49;0100;Server@node2;Req;;Type 81 request received from Scheduler@node2.supernodexp.hpc, sock=16
02/14/2018 02:13:49;0100;Server@node2;Req;;Type 71 request received from Scheduler@node2.supernodexp.hpc, sock=16
02/14/2018 02:13:49;0100;Server@node2;Req;;Type 58 request received from Scheduler@node2.supernodexp.hpc, sock=16
02/14/2018 02:13:49;0100;Server@node2;Req;;Type 20 request received from Scheduler@node2.supernodexp.hpc, sock=16
02/14/2018 02:13:49;0100;Server@node2;Req;;Type 51 request received from Scheduler@node2.supernodexp.hpc, sock=16
02/14/2018 02:23:49;0040;Server@node2;Svr;node2.supernodexp.hpc;Scheduler sent command 3
02/14/2018 02:23:49;0040;Server@node2;Svr;node2.supernodexp.hpc;Scheduler sent command 0
02/14/2018 02:23:49;0100;Server@node2;Req;;Type 21 request received from Scheduler@node2.supernodexp.hpc, sock=16
02/14/2018 02:23:49;0100;Server@node2;Req;;Type 81 request received from Scheduler@node2.supernodexp.hpc, sock=16
02/14/2018 02:23:49;0100;Server@node2;Req;;Type 71 request received from Scheduler@node2.supernodexp.hpc, sock=16
02/14/2018 02:23:49;0100;Server@node2;Req;;Type 58 request received from Scheduler@node2.supernodexp.hpc, sock=16
02/14/2018 02:23:49;0100;Server@node2;Req;;Type 20 request received from Scheduler@node2.supernodexp.hpc, sock=16
02/14/2018 02:23:49;0100;Server@node2;Req;;Type 51 request received from Scheduler@node2.supernodexp.hpc, sock=16
02/14/2018 02:33:49;0040;Server@node2;Svr;node2.supernodexp.hpc;Scheduler sent command 3
02/14/2018 02:33:49;0040;Server@node2;Svr;node2.supernodexp.hpc;Scheduler sent command 0
02/14/2018 02:33:49;0100;Server@node2;Req;;Type 21 request received from Scheduler@node2.supernodexp.hpc, sock=16
02/14/2018 02:33:49;0100;Server@node2;Req;;Type 81 request received from Scheduler@node2.supernodexp.hpc, sock=16
02/14/2018 02:33:49;0100;Server@node2;Req;;Type 71 request received from Scheduler@node2.supernodexp.hpc, sock=16
02/14/2018 02:33:49;0100;Server@node2;Req;;Type 58 request received from Scheduler@node2.supernodexp.hpc, sock=16
02/14/2018 02:33:49;0100;Server@node2;Req;;Type 20 request received from Scheduler@node2.supernodexp.hpc, sock=16
02/14/2018 02:33:49;0100;Server@node2;Req;;Type 51 request received from Scheduler@node2.supernodexp.hpc, sock=16
02/14/2018 02:43:49;0040;Server@node2;Svr;node2.supernodexp.hpc;Scheduler sent command 3
02/14/2018 02:43:49;0040;Server@node2;Svr;node2.supernodexp.hpc;Scheduler sent command 0
02/14/2018 02:43:49;0100;Server@node2;Req;;Type 21 request received from Scheduler@node2.supernodexp.hpc, sock=16
02/14/2018 02:43:49;0100;Server@node2;Req;;Type 81 request received from Scheduler@node2.supernodexp.hpc, sock=16
02/14/2018 02:43:49;0100;Server@node2;Req;;Type 71 request received from Scheduler@node2.supernodexp.hpc, sock=16
02/14/2018 02:43:49;0100;Server@node2;Req;;Type 58 request received from Scheduler@node2.supernodexp.hpc, sock=16
02/14/2018 02:43:49;0100;Server@node2;Req;;Type 20 request received from Scheduler@node2.supernodexp.hpc, sock=16
02/14/2018 02:43:49;0100;Server@node2;Req;;Type 51 request received from Scheduler@node2.supernodexp.hpc, sock=16
02/14/2018 02:53:49;0040;Server@node2;Svr;node2.supernodexp.hpc;Scheduler sent command 3
02/14/2018 02:53:49;0040;Server@node2;Svr;node2.supernodexp.hpc;Scheduler sent command 0
02/14/2018 02:53:49;0100;Server@node2;Req;;Type 21 request received from Scheduler@node2.supernodexp.hpc, sock=16
02/14/2018 02:53:49;0100;Server@node2;Req;;Type 81 request received from Scheduler@node2.supernodexp.hpc, sock=16
02/14/2018 02:53:49;0100;Server@node2;Req;;Type 71 request received from Scheduler@node2.supernodexp.hpc, sock=16
02/14/2018 02:53:49;0100;Server@node2;Req;;Type 58 request received from Scheduler@node2.supernodexp.hpc, sock=16
02/14/2018 02:53:49;0100;Server@node2;Req;;Type 20 request received from Scheduler@node2.supernodexp.hpc, sock=16
02/14/2018 02:53:49;0100;Server@node2;Req;;Type 51 request received from Scheduler@node2.supernodexp.hpc, sock=16
02/14/2018 03:03:49;0040;Server@node2;Svr;node2.supernodexp.hpc;Scheduler sent command 3
02/14/2018 03:03:49;0040;Server@node2;Svr;node2.supernodexp.hpc;Scheduler sent command 0
02/14/2018 03:03:49;0100;Server@node2;Req;;Type 21 request received from Scheduler@node2.supernodexp.hpc, sock=16
02/14/2018 03:03:49;0100;Server@node2;Req;;Type 81 request received from Scheduler@node2.supernodexp.hpc, sock=16
02/14/2018 03:03:49;0100;Server@node2;Req;;Type 71 request received from Scheduler@node2.supernodexp.hpc, sock=16
02/14/2018 03:03:49;0100;Server@node2;Req;;Type 58 request received from Scheduler@node2.supernodexp.hpc, sock=16
02/14/2018 03:03:49;0100;Server@node2;Req;;Type 20 request received from Scheduler@node2.supernodexp.hpc, sock=16
02/14/2018 03:03:49;0100;Server@node2;Req;;Type 51 request received from Scheduler@node2.supernodexp.hpc, sock=16
02/14/2018 03:13:49;0040;Server@node2;Svr;node2.supernodexp.hpc;Scheduler sent command 3
02/14/2018 03:13:49;0040;Server@node2;Svr;node2.supernodexp.hpc;Scheduler sent command 0
02/14/2018 03:13:49;0100;Server@node2;Req;;Type 21 request received from Scheduler@node2.supernodexp.hpc, sock=16
02/14/2018 03:13:49;0100;Server@node2;Req;;Type 81 request received from Scheduler@node2.supernodexp.hpc, sock=16
02/14/2018 03:13:49;0100;Server@node2;Req;;Type 71 request received from Scheduler@node2.supernodexp.hpc, sock=16
02/14/2018 03:13:49;0100;Server@node2;Req;;Type 58 request received from Scheduler@node2.supernodexp.hpc, sock=16
02/14/2018 03:13:49;0100;Server@node2;Req;;Type 20 request received from Scheduler@node2.supernodexp.hpc, sock=16
02/14/2018 03:13:49;0100;Server@node2;Req;;Type 51 request received from Scheduler@node2.supernodexp.hpc, sock=16
02/14/2018 03:23:49;0040;Server@node2;Svr;node2.supernodexp.hpc;Scheduler sent command 3
02/14/2018 03:23:49;0040;Server@node2;Svr;node2.supernodexp.hpc;Scheduler sent command 0
02/14/2018 03:23:49;0100;Server@node2;Req;;Type 21 request received from Scheduler@node2.supernodexp.hpc, sock=16
02/14/2018 03:23:49;0100;Server@node2;Req;;Type 81 request received from Scheduler@node2.supernodexp.hpc, sock=16
02/14/2018 03:23:49;0100;Server@node2;Req;;Type 71 request received from Scheduler@node2.supernodexp.hpc, sock=16
02/14/2018 03:23:49;0100;Server@node2;Req;;Type 58 request received from Scheduler@node2.supernodexp.hpc, sock=16
02/14/2018 03:23:49;0100;Server@node2;Req;;Type 20 request received from Scheduler@node2.supernodexp.hpc, sock=16
02/14/2018 03:23:49;0100;Server@node2;Req;;Type 51 request received from Scheduler@node2.supernodexp.hpc, sock=16
02/14/2018 03:33:49;0040;Server@node2;Svr;node2.supernodexp.hpc;Scheduler sent command 3
02/14/2018 03:33:49;0040;Server@node2;Svr;node2.supernodexp.hpc;Scheduler sent command 0
02/14/2018 03:33:49;0100;Server@node2;Req;;Type 21 request received from Scheduler@node2.supernodexp.hpc, sock=16
02/14/2018 03:33:49;0100;Server@node2;Req;;Type 81 request received from Scheduler@node2.supernodexp.hpc, sock=16
02/14/2018 03:33:49;0100;Server@node2;Req;;Type 71 request received from Scheduler@node2.supernodexp.hpc, sock=16
02/14/2018 03:33:49;0100;Server@node2;Req;;Type 58 request received from Scheduler@node2.supernodexp.hpc, sock=16
02/14/2018 03:33:49;0100;Server@node2;Req;;Type 20 request received from Scheduler@node2.supernodexp.hpc, sock=16
02/14/2018 03:33:49;0100;Server@node2;Req;;Type 51 request received from Scheduler@node2.supernodexp.hpc, sock=16
02/14/2018 03:43:49;0040;Server@node2;Svr;node2.supernodexp.hpc;Scheduler sent command 3
02/14/2018 03:43:49;0040;Server@node2;Svr;node2.supernodexp.hpc;Scheduler sent command 0
02/14/2018 03:43:49;0100;Server@node2;Req;;Type 21 request received from Scheduler@node2.supernodexp.hpc, sock=16
02/14/2018 03:43:49;0100;Server@node2;Req;;Type 81 request received from Scheduler@node2.supernodexp.hpc, sock=16
02/14/2018 03:43:49;0100;Server@node2;Req;;Type 71 request received from Scheduler@node2.supernodexp.hpc, sock=16
02/14/2018 03:43:49;0100;Server@node2;Req;;Type 58 request received from Scheduler@node2.supernodexp.hpc, sock=16
02/14/2018 03:43:49;0100;Server@node2;Req;;Type 20 request received from Scheduler@node2.supernodexp.hpc, sock=16
02/14/2018 03:43:49;0100;Server@node2;Req;;Type 51 request received from Scheduler@node2.supernodexp.hpc, sock=16
02/14/2018 03:53:49;0040;Server@node2;Svr;node2.supernodexp.hpc;Scheduler sent command 3
02/14/2018 03:53:49;0040;Server@node2;Svr;node2.supernodexp.hpc;Scheduler sent command 0
02/14/2018 03:53:49;0100;Server@node2;Req;;Type 21 request received from Scheduler@node2.supernodexp.hpc, sock=16
02/14/2018 03:53:49;0100;Server@node2;Req;;Type 81 request received from Scheduler@node2.supernodexp.hpc, sock=16
02/14/2018 03:53:49;0100;Server@node2;Req;;Type 71 request received from Scheduler@node2.supernodexp.hpc, sock=16
02/14/2018 03:53:49;0100;Server@node2;Req;;Type 58 request received from Scheduler@node2.supernodexp.hpc, sock=16
02/14/2018 03:53:49;0100;Server@node2;Req;;Type 20 request received from Scheduler@node2.supernodexp.hpc, sock=16
02/14/2018 03:53:49;0100;Server@node2;Req;;Type 51 request received from Scheduler@node2.supernodexp.hpc, sock=16
02/14/2018 04:03:49;0040;Server@node2;Svr;node2.supernodexp.hpc;Scheduler sent command 3
02/14/2018 04:03:49;0040;Server@node2;Svr;node2.supernodexp.hpc;Scheduler sent command 0
02/14/2018 04:03:49;0100;Server@node2;Req;;Type 21 request received from Scheduler@node2.supernodexp.hpc, sock=16
02/14/2018 04:03:49;0100;Server@node2;Req;;Type 81 request received from Scheduler@node2.supernodexp.hpc, sock=16
02/14/2018 04:03:49;0100;Server@node2;Req;;Type 71 request received from Scheduler@node2.supernodexp.hpc, sock=16
02/14/2018 04:03:49;0100;Server@node2;Req;;Type 58 request received from Scheduler@node2.supernodexp.hpc, sock=16
02/14/2018 04:03:49;0100;Server@node2;Req;;Type 20 request received from Scheduler@node2.supernodexp.hpc, sock=16
02/14/2018 04:03:49;0100;Server@node2;Req;;Type 51 request received from Scheduler@node2.supernodexp.hpc, sock=16
02/14/2018 04:07:00;0100;Server@node2;Req;;Type 0 request received from root@node2.supernodexp.hpc, sock=16
02/14/2018 04:07:00;0100;Server@node2;Req;;Type 49 request received from root@node2.supernodexp.hpc, sock=20
02/14/2018 04:07:06;0100;Server@node2;Req;;Type 82 request received from root@node2.supernodexp.hpc, sock=16
02/14/2018 04:07:06;0100;Server@node2;Req;;Type 20 request received from root@node2.supernodexp.hpc, sock=16
02/14/2018 04:07:06;0100;Server@node2;Req;;Type 71 request received from root@node2.supernodexp.hpc, sock=16
02/14/2018 04:07:06;0100;Server@node2;Req;;Type 21 request received from root@node2.supernodexp.hpc, sock=16
02/14/2018 04:07:26;0100;Server@node2;Req;;Type 9 request received from root@node2.supernodexp.hpc, sock=16
02/14/2018 04:07:26;0004;Server@node2;Svr;Server@node2;attributes set:  at request of root@node2.supernodexp.hpc
02/14/2018 04:07:26;0004;Server@node2;Svr;Server@node2;attributes set: job_sort_formula = walltime
02/14/2018 04:07:40;0100;Server@node2;Req;;Type 0 request received from root@node2.supernodexp.hpc, sock=16
02/14/2018 04:07:40;0100;Server@node2;Req;;Type 49 request received from root@node2.supernodexp.hpc, sock=20
02/14/2018 04:07:40;0100;Server@node2;Req;;Type 21 request received from root@node2.supernodexp.hpc, sock=16
02/14/2018 04:07:40;0100;Server@node2;Req;;Type 0 request received from root@node2.supernodexp.hpc, sock=16
02/14/2018 04:07:40;0100;Server@node2;Req;;Type 49 request received from root@node2.supernodexp.hpc, sock=20
02/14/2018 04:07:40;0100;Server@node2;Req;;Type 17 request received from root@node2.supernodexp.hpc, sock=16
02/14/2018 04:07:40;0086;Server@node2;Svr;Server@node2;Shutdown request from root@node2.supernodexp.hpc 
02/14/2018 04:07:40;0086;Server@node2;Svr;Server@node2;Starting to shutdown the server, type is Quick
02/14/2018 04:07:40;0002;Server@node2;Svr;Server@node2;Stopping PBS dataservice
02/14/2018 04:07:44;0100;Server@node2;Svr;Server@node2;--> Stopping Python interpreter <--
02/14/2018 04:07:44;0d80;Server@node2;TPP;Server@node2(Main Thread);Shutting down TPP transport Layer
02/14/2018 04:07:44;0d80;Server@node2;TPP;Server@node2(Thread 0);Thrd exiting, had 1 connections
02/14/2018 04:07:44;0002;Server@node2;Svr;Server@node2;Server shutdown completed
02/14/2018 04:07:44;0002;Server@node2;Svr;Log;Log closed
02/14/2018 04:07:46;0002;Server@node2;Svr;Log;Log opened
02/14/2018 04:07:46;0002;Server@node2;Svr;Server@node2;pbs_version=14.0.1
02/14/2018 04:07:46;0002;Server@node2;Svr;Server@node2;pbs_build=mach=N/A:security=N/A:configure_args=N/A
02/14/2018 04:07:46;0002;Server@node2;Svr;Server@node2;hostname=node2.supernodexp.hpc;pbs_leaf_name=N/A;pbs_mom_node_name=N/A
02/14/2018 04:07:46;0002;Server@node2;Svr;Server@node2;ipv4 interface lo: localhost localhost.localdomain localhost4 localhost4.localdomain4 
02/14/2018 04:07:46;0002;Server@node2;Svr;Server@node2;ipv4 interface br0: node2.supernodexp.hpc node2 supernodexp-cn02 
02/14/2018 04:07:46;0002;Server@node2;Svr;Server@node2;ipv4 interface ib0: node2.supernodexp.hpc 
02/14/2018 04:07:46;0002;Server@node2;Svr;Server@node2;ipv4 interface docker0: node2.supernodexp.hpc 
02/14/2018 04:07:46;0002;Server@node2;Svr;Server@node2;ipv4 interface virbr0: node2.supernodexp.hpc 
02/14/2018 04:07:46;0002;Server@node2;Svr;Server@node2;ipv6 interface lo: localhost localhost.localdomain localhost6 localhost6.localdomain6 
02/14/2018 04:07:46;0002;Server@node2;Svr;Server@node2;ipv6 interface eno49: node2.supernodexp.hpc 
02/14/2018 04:07:46;0002;Server@node2;Svr;Server@node2;ipv6 interface br0: node2.supernodexp.hpc 
02/14/2018 04:07:46;0002;Server@node2;Svr;Server@node2;ipv6 interface ib0: node2.supernodexp.hpc 
02/14/2018 04:07:46;0002;Server@node2;Svr;Server@node2;ipv6 interface veth1pl7177: node2.supernodexp.hpc 
02/14/2018 04:07:46;0006;Server@node2;Fil;Server@node2;Version 14.0.1, started, initialization type = 1
02/14/2018 04:07:47;0002;Server@node2;Svr;Server@node2;Starting PBS dataservice
02/14/2018 04:07:52;0002;Server@node2;Svr;Server@node2;connected to PBS dataservice@node2.supernodexp.hpc
02/14/2018 04:07:52;0086;Server@node2;Svr;pbs_python_ext_quick_start_interpreter;--> Python Interpreter quick started, compiled with version:'2.7.5' <--
02/14/2018 04:07:52;0086;Server@node2;Svr;pbs_python_ext_quick_start_interpreter;--> Inserted Altair PBS Python modules dir '/opt/pbs/lib/python/altair' <--
02/14/2018 04:07:52;0002;Server@node2;Fil;Server@node2;PBS Server hostname is node2.supernodexp.hpc, Server-id is 1
02/14/2018 04:07:52;0002;Server@node2;n/a;setup_env;read environment from /var/spool/pbs/pbs_environment
02/14/2018 04:07:52;0004;Server@node2;Svr;Server@node2;node_fail_requeue value changed to 310
02/14/2018 04:07:52;0004;Server@node2;Svr;Server@node2;Licenses valid for 10000000 Floating hosts
02/14/2018 04:07:52;0002;Server@node2;Svr;Act;Account file /var/spool/pbs/server_priv/accounting/20180214 opened
02/14/2018 04:07:52;0086;Server@node2;Svr;Server@node2;Recovered queue workq
02/14/2018 04:07:52;0002;Server@node2;Svr;Server@node2;Expected 1, recovered 1 queues
02/14/2018 04:07:52;0080;Server@node2;Svr;Server@node2;No jobs to open
02/14/2018 04:07:52;0086;Server@node2;Svr;Server@node2;Found hook PBS_translate_mpp type=pbs
02/14/2018 04:07:52;0086;Server@node2;Svr;Server@node2;Found hook stop_docker type=site
02/14/2018 04:07:52;0086;Server@node2;Svr;Server@node2;Found hook launch_docker type=site
02/14/2018 04:07:52;0086;Server@node2;Svr;Server@node2;Found hook evaluation type=site
02/14/2018 04:07:52;0080;Server@node2;Hook;print_hook;ALLHOOKS hook[0] = {PBS_translate_mpp, order=1000, type=1, enabled=0 user=0, debug=(0) fail_action=(1), event=(queuejob,resvsub), alarm=90, freq=120}
02/14/2018 04:07:52;0080;Server@node2;Hook;print_hook;ALLHOOKS hook[1] = {stop_docker, order=1, type=0, enabled=1 user=0, debug=(0) fail_action=(1), event=(execjob_end), alarm=30, freq=120}
02/14/2018 04:07:52;0080;Server@node2;Hook;print_hook;ALLHOOKS hook[2] = {launch_docker, order=1, type=0, enabled=1 user=0, debug=(0) fail_action=(1), event=(execjob_launch), alarm=30, freq=120}
02/14/2018 04:07:52;0080;Server@node2;Hook;print_hook;ALLHOOKS hook[3] = {evaluation, order=1, type=0, enabled=1 user=0, debug=(0) fail_action=(1), event=(queuejob), alarm=30, freq=120}
02/14/2018 04:07:52;0080;Server@node2;Hook;print_hook;queuejob hook[0] = {evaluation, order=1, type=0, enabled=1 user=0, debug=(0) fail_action=(1), event=(queuejob), alarm=30, freq=120}
02/14/2018 04:07:52;0080;Server@node2;Hook;print_hook;queuejob hook[1] = {PBS_translate_mpp, order=1000, type=1, enabled=0 user=0, debug=(0) fail_action=(1), event=(queuejob,resvsub), alarm=90, freq=120}
02/14/2018 04:07:52;0080;Server@node2;Hook;print_hook;resvsub hook[0] = {PBS_translate_mpp, order=1000, type=1, enabled=0 user=0, debug=(0) fail_action=(1), event=(queuejob,resvsub), alarm=90, freq=120}
02/14/2018 04:07:52;0086;Server@node2;Svr;pbs_python_ext_quick_shutdown_interpreter;--> Stopping Python interpreter <--
02/14/2018 04:07:52;0d80;Server@node2;TPP;Server@node2(Main Thread);TPP set to use reserved port authentication
02/14/2018 04:07:52;0d80;Server@node2;TPP;Server@node2(Main Thread);Initializing TPP transport Layer
02/14/2018 04:07:52;0d80;Server@node2;TPP;Server@node2(Main Thread);Max files allowed = 1024
02/14/2018 04:07:52;0c06;Server@node2;TPP;Server@node2(Main Thread);Max files too low - you may want to increase it.
02/14/2018 04:07:52;0d80;Server@node2;TPP;Server@node2(Main Thread);TPP initialization done
02/14/2018 04:07:52;0c06;Server@node2;TPP;Server@node2(Main Thread);Single pbs_comm configured, TPP Fault tolerant mode disabled
02/14/2018 04:07:52;0d80;Server@node2;TPP;Server@node2(Main Thread);Connecting to pbs_comm node2.supernodexp.hpc
02/14/2018 04:07:52;0002;Server@node2;Svr;Server@node2;Server pid = 35659 ready;  using ports Server:15001 Scheduler:15004 MOM:15002 RM:15003
02/14/2018 04:07:52;0c06;Server@node2;TPP;Server@node2(Thread 0);Registering address 10.1.1.4:15001 to pbs_comm
02/14/2018 04:07:52;0c06;Server@node2;TPP;Server@node2(Thread 0);Connected to pbs_comm node2.supernodexp.hpc
02/14/2018 04:07:52;0100;Server@node2;Svr;Server@node2;--> Python Interpreter started, compiled with version:'2.7.5' <--
02/14/2018 04:07:52;0100;Server@node2;Svr;Server@node2;sys.modules= {'pbs.v1._svr_types': <module 'pbs.v1._svr_types' from '/opt/pbs/lib/python/altair/pbs/v1/_svr_types.pyo'>, 'copy_reg': <module 'copy_reg' from '/usr/lib64/python2.7/copy_reg.pyo'>, 'pbs.v1._pbs_v1': None, '__main__': <module '__main__' (built-in)>, '__builtin__': <module '__builtin__' (built-in)>, '_pbs_v1.svr_types': <module '_pbs_v1.svr_types' (built-in)>, 'encodings': <module 'encodings' from '/usr/lib64/python2.7/encodings/__init__.pyo'>, 'encodings.encodings': None, 'abc': <module 'abc' from '/usr/lib64/python2.7/abc.pyo'>, 'pbs._pbs_v1': None, 'posixpath': <module 'posixpath' from '/usr/lib64/python2.7/posixpath.pyo'>, '_weakrefset': <module '_weakrefset' from '/usr/lib64/python2.7/_weakrefset.pyo'>, 'pbs.v1': <module 'pbs.v1' from '/opt/pbs/lib/python/altair/pbs/v1/__init__.pyo'>, 'errno': <module 'errno' (built-in)>, 'encodings.codecs': None, 'pbs.v1._export_types': <module 'pbs.v1._export_types' from '/opt/pbs/lib/python/altair/pbs/v1/_export_types.pyo'>, 'pbs.v1.os': None, '_abcoll': <module '_abcoll' from '/usr/lib64/python2.7/_abcoll.pyo'>, 'os.path': <module 'posixpath' from '/usr/lib64/python2.7/posixpath.pyo'>, 'UserDict': <module 'UserDict' from '/usr/lib64/python2.7/UserDict.pyo'>, '_warnings': <module '_warnings' (built-in)>, 'genericpath': <module 'genericpath' from '/usr/lib64/python2.7/genericpath.pyo'>, 'stat': <module 'stat' from '/usr/lib64/python2.7/stat.pyo'>, 'zipimport': <module 'zipimport' (built-in)>, 'encodings.__builtin__': None, 'pbs.pbs': None, 'warnings': <module 'warnings' from '/usr/lib64/python2.7/warnings.pyo'>, '_codecs': <module '_codecs' (built-in)>, 'encodings.ascii': <module 'encodings.ascii' from '/usr/lib64/python2.7/encodings/ascii.pyo'>, 'sys': <module 'sys' (built-in)>, 'pbs.v1._base_types': <module 'pbs.v1._base_types' from '/opt/pbs/lib/python/altair/pbs/v1/_base_types.pyo'>, 'pbs.v1.sys': None, 'codecs': <module 'codecs' from '/usr/lib64/python2.7/codecs.pyo'>, 'types': <module 'types' from '/usr/lib64/python2.7/types.pyo'>, 'pbs': <module 'pbs' from '/opt/pbs/lib/python/altair/pbs/__init__.pyo'>, 'os': <module 'os' from '/usr/lib64/python2.7/os.pyo'>, 'signal': <module 'signal' (built-in)>, 'linecache': <module 'linecache' from '/usr/lib64/python2.7/linecache.pyo'>, '_pbs_v1': <module '_pbs_v1' (built-in)>, 'posix': <module 'posix' (built-in)>, 'encodings.aliases': <module 'encodings.aliases' from '/usr/lib64/python2.7/encodings/aliases.pyo'>, 'exceptions': <module 'exceptions' (built-in)>, 'pbs.v1._exc_types': <module 'pbs.v1._exc_types' from '/opt/pbs/lib/python/altair/pbs/v1/_exc_types.pyo'>, '_weakref': <module '_weakref' (built-in)>}
02/14/2018 04:07:52;0106;Server@node2;Svr;Server@node2;BEGIN setting up all resource attributes 
02/14/2018 04:07:52;0106;Server@node2;Svr;Server@node2;DONE setting up all resource attributes, number set <51>
02/14/2018 04:07:52;0106;Server@node2;Svr;Server@node2;BEGIN setting up all queue attributes 
02/14/2018 04:07:52;0106;Server@node2;Svr;Server@node2;DONE setting up all queue attributes, number set <55>
02/14/2018 04:07:52;0106;Server@node2;Svr;Server@node2;BEGIN setting up all job attributes 
02/14/2018 04:07:52;0106;Server@node2;Svr;Server@node2;DONE setting up all job attributes, number set <94>
02/14/2018 04:07:52;0106;Server@node2;Svr;Server@node2;BEGIN setting up all server attributes 
02/14/2018 04:07:52;0106;Server@node2;Svr;Server@node2;DONE setting up all server attributes, number set <88>
02/14/2018 04:07:52;0106;Server@node2;Svr;Server@node2;BEGIN setting up all reservation attributes 
02/14/2018 04:07:52;0106;Server@node2;Svr;Server@node2;DONE setting up all reservation attributes, number set <43>
02/14/2018 04:07:52;0106;Server@node2;Svr;Server@node2;BEGIN setting up all vnode attributes 
02/14/2018 04:07:52;0106;Server@node2;Svr;Server@node2;DONE setting up all vnode attributes, number set <28>
02/14/2018 04:07:52;0040;Server@node2;Svr;node2.supernodexp.hpc;Scheduler sent command 10
02/14/2018 04:07:52;0040;Server@node2;Svr;node2.supernodexp.hpc;Scheduler sent command 0
02/14/2018 04:07:52;0d80;Server@node2;TPP;Server@node2(Main Thread);net restore handler called
02/14/2018 04:07:52;0100;Server@node2;Req;;Type 9 request received from Scheduler@node2.supernodexp.hpc, sock=16
02/14/2018 04:07:52;0004;Server@node2;Sched;Server@node2;attributes set:  at request of Scheduler@node2.supernodexp.hpc
02/14/2018 04:07:52;0004;Server@node2;Sched;Server@node2;attributes set: sched_host = node2.supernodexp.hpc
02/14/2018 04:07:52;0004;Server@node2;Sched;Server@node2;attributes set: pbs_version = 14.0.1
02/14/2018 04:07:52;0100;Server@node2;Req;;Type 82 request received from Scheduler@node2.supernodexp.hpc, sock=16
02/14/2018 04:07:52;0100;Server@node2;Req;;Type 21 request received from Scheduler@node2.supernodexp.hpc, sock=16
02/14/2018 04:07:52;0100;Server@node2;Req;;Type 81 request received from Scheduler@node2.supernodexp.hpc, sock=16
02/14/2018 04:07:52;0100;Server@node2;Req;;Type 71 request received from Scheduler@node2.supernodexp.hpc, sock=16
02/14/2018 04:07:52;0100;Server@node2;Req;;Type 58 request received from Scheduler@node2.supernodexp.hpc, sock=16
02/14/2018 04:07:52;0100;Server@node2;Req;;Type 20 request received from Scheduler@node2.supernodexp.hpc, sock=16
02/14/2018 04:07:52;0100;Server@node2;Req;;Type 51 request received from Scheduler@node2.supernodexp.hpc, sock=16
02/14/2018 04:07:55;0d80;Server@node2;TPP;handle_incoming_data(Thread 0);Increased scratch size for tfd=15 to 16384
02/14/2018 04:07:55;0d80;Server@node2;TPP;handle_incoming_data(Thread 0);Increased scratch size for tfd=15 to 24576
02/14/2018 04:07:55;0d80;Server@node2;TPP;handle_incoming_data(Thread 0);Increased scratch size for tfd=15 to 32768
02/14/2018 04:07:55;0d80;Server@node2;TPP;handle_incoming_data(Thread 0);Increased scratch size for tfd=15 to 40960
02/14/2018 04:07:55;0d80;Server@node2;TPP;handle_incoming_data(Thread 0);Increased scratch size for tfd=15 to 49152
02/14/2018 04:07:55;0002;Server@node2;Node;10.1.1.15;update2 state:0 ncpus:48
02/14/2018 04:07:55;0002;Server@node2;Node;10.1.1.15;Mom reporting 1 vnodes as of Tue Feb 13 23:16:29 2018
02/14/2018 04:07:55;0002;Server@node2;Node;10.1.1.15;node up
02/14/2018 04:07:55;0002;Server@node2;Node;node14.supernodexp.hpc;update2 state:0 ncpus:48
02/14/2018 04:07:55;0002;Server@node2;Node;node14.supernodexp.hpc;Mom reporting 1 vnodes as of Tue Feb 13 16:16:45 2018
02/14/2018 04:07:56;0002;Server@node2;Node;node14.supernodexp.hpc;node up
02/14/2018 04:08:38;0100;Server@node2;Req;;Type 0 request received from ctminh@node2.supernodexp.hpc, sock=16
02/14/2018 04:08:38;0100;Server@node2;Req;;Type 49 request received from ctminh@node2.supernodexp.hpc, sock=17
02/14/2018 04:08:38;0100;Server@node2;Req;;Type 21 request received from ctminh@node2.supernodexp.hpc, sock=16
02/14/2018 04:08:38;0100;Server@node2;Req;;Type 1 request received from ctminh@node2.supernodexp.hpc, sock=16
02/14/2018 04:08:38;0086;Server@node2;Svr;Server@node2;Compiling script file: </var/spool/pbs/server_priv/hooks/evaluation.PY>
02/14/2018 04:08:38;0100;Server@node2;Req;;Type 3 request received from ctminh@node2.supernodexp.hpc, sock=16
02/14/2018 04:08:38;0100;Server@node2;Req;;Type 5 request received from ctminh@node2.supernodexp.hpc, sock=16
02/14/2018 04:08:38;0100;Server@node2;Job;1001.node2.supernodexp.hpc;enqueuing into workq, state 1 hop 1
02/14/2018 04:08:38;0008;Server@node2;Job;1001.node2.supernodexp.hpc;Job Queued at request of ctminh@node2.supernodexp.hpc, owner = ctminh@node2.supernodexp.hpc, job name = nbody, queue = workq
02/14/2018 04:08:38;0040;Server@node2;Svr;node2.supernodexp.hpc;Scheduler sent command 1
02/14/2018 04:08:38;0040;Server@node2;Svr;node2.supernodexp.hpc;Scheduler sent command 0
02/14/2018 04:08:38;0100;Server@node2;Req;;Type 21 request received from Scheduler@node2.supernodexp.hpc, sock=20
02/14/2018 04:08:38;0100;Server@node2;Req;;Type 1 request received from ctminh@node2.supernodexp.hpc, sock=16
02/14/2018 04:08:38;0100;Server@node2;Req;;Type 3 request received from ctminh@node2.supernodexp.hpc, sock=16
02/14/2018 04:08:38;0100;Server@node2;Req;;Type 5 request received from ctminh@node2.supernodexp.hpc, sock=16
02/14/2018 04:08:38;0100;Server@node2;Job;1002.node2.supernodexp.hpc;enqueuing into workq, state 1 hop 1
02/14/2018 04:08:38;0008;Server@node2;Job;1002.node2.supernodexp.hpc;Job Queued at request of ctminh@node2.supernodexp.hpc, owner = ctminh@node2.supernodexp.hpc, job name = telemac3, queue = workq
02/14/2018 04:08:38;0100;Server@node2;Req;;Type 81 request received from Scheduler@node2.supernodexp.hpc, sock=20
02/14/2018 04:08:38;0100;Server@node2;Req;;Type 71 request received from Scheduler@node2.supernodexp.hpc, sock=20
02/14/2018 04:08:38;0100;Server@node2;Req;;Type 58 request received from Scheduler@node2.supernodexp.hpc, sock=20
02/14/2018 04:08:38;0100;Server@node2;Req;;Type 20 request received from Scheduler@node2.supernodexp.hpc, sock=20
02/14/2018 04:08:38;0100;Server@node2;Req;;Type 51 request received from Scheduler@node2.supernodexp.hpc, sock=20
02/14/2018 04:08:38;0100;Server@node2;Req;;Type 23 request received from Scheduler@node2.supernodexp.hpc, sock=20
02/14/2018 04:08:38;0008;Server@node2;Job;1002.node2.supernodexp.hpc;Job Run at request of Scheduler@node2.supernodexp.hpc on exec_vnode (node13:ncpus=24:mem=4194304kb)+(node13:ncpus=24:mem=4194304kb)
02/14/2018 04:08:38;0001;Server@node2;Svr;Server@node2;Success (0) in req_runjob2, return value of svr_startjob is 0
02/14/2018 04:08:38;0100;Server@node2;Req;;Type 23 request received from Scheduler@node2.supernodexp.hpc, sock=20
02/14/2018 04:08:38;0008;Server@node2;Job;1001.node2.supernodexp.hpc;Job Run at request of Scheduler@node2.supernodexp.hpc on exec_vnode (node14:ncpus=12:mem=1048576kb)
02/14/2018 04:08:38;0001;Server@node2;Svr;Server@node2;Success (0) in req_runjob2, return value of svr_startjob is 0
02/14/2018 04:08:38;0040;Server@node2;Svr;node2.supernodexp.hpc;Scheduler sent command 1
02/14/2018 04:08:38;0040;Server@node2;Svr;node2.supernodexp.hpc;Scheduler sent command 0
02/14/2018 04:08:38;0100;Server@node2;Req;;Type 21 request received from Scheduler@node2.supernodexp.hpc, sock=20
02/14/2018 04:08:38;0100;Server@node2;Req;;Type 81 request received from Scheduler@node2.supernodexp.hpc, sock=20
02/14/2018 04:08:38;0100;Server@node2;Req;;Type 71 request received from Scheduler@node2.supernodexp.hpc, sock=20
02/14/2018 04:08:38;0100;Server@node2;Req;;Type 58 request received from Scheduler@node2.supernodexp.hpc, sock=20
02/14/2018 04:08:38;0100;Server@node2;Req;;Type 20 request received from Scheduler@node2.supernodexp.hpc, sock=20
02/14/2018 04:08:38;0100;Server@node2;Req;;Type 51 request received from Scheduler@node2.supernodexp.hpc, sock=20
02/14/2018 04:08:47;0080;Server@node2;Job;1001.node2.supernodexp.hpc;Obit received momhop:1 serverhop:1 state:4 substate:42
02/14/2018 04:08:48;0010;Server@node2;Job;1001.node2.supernodexp.hpc;Exit_status=0 resources_used.cpupercent=88 resources_used.cput=00:00:08 resources_used.mem=0kb resources_used.ncpus=12 resources_used.vmem=0kb resources_used.walltime=00:00:09
02/14/2018 04:08:48;0100;Server@node2;Job;1001.node2.supernodexp.hpc;dequeuing from workq, state 5
02/14/2018 04:08:48;0040;Server@node2;Svr;node2.supernodexp.hpc;Scheduler sent command 2
02/14/2018 04:08:48;0040;Server@node2;Svr;node2.supernodexp.hpc;Scheduler sent command 0
02/14/2018 04:08:48;0100;Server@node2;Req;;Type 21 request received from Scheduler@node2.supernodexp.hpc, sock=20
02/14/2018 04:08:48;0100;Server@node2;Req;;Type 81 request received from Scheduler@node2.supernodexp.hpc, sock=20
02/14/2018 04:08:48;0100;Server@node2;Req;;Type 71 request received from Scheduler@node2.supernodexp.hpc, sock=20
02/14/2018 04:08:48;0100;Server@node2;Req;;Type 58 request received from Scheduler@node2.supernodexp.hpc, sock=20
02/14/2018 04:08:48;0100;Server@node2;Req;;Type 20 request received from Scheduler@node2.supernodexp.hpc, sock=20
02/14/2018 04:08:48;0100;Server@node2;Req;;Type 51 request received from Scheduler@node2.supernodexp.hpc, sock=20
02/14/2018 04:09:18;0100;Server@node2;Req;;Type 1 request received from ctminh@node2.supernodexp.hpc, sock=16
02/14/2018 04:09:18;0100;Server@node2;Req;;Type 3 request received from ctminh@node2.supernodexp.hpc, sock=16
02/14/2018 04:09:18;0100;Server@node2;Req;;Type 5 request received from ctminh@node2.supernodexp.hpc, sock=16
02/14/2018 04:09:18;0100;Server@node2;Job;1003.node2.supernodexp.hpc;enqueuing into workq, state 1 hop 1
02/14/2018 04:09:18;0008;Server@node2;Job;1003.node2.supernodexp.hpc;Job Queued at request of ctminh@node2.supernodexp.hpc, owner = ctminh@node2.supernodexp.hpc, job name = histogram, queue = workq
02/14/2018 04:09:18;0040;Server@node2;Svr;node2.supernodexp.hpc;Scheduler sent command 1
02/14/2018 04:09:18;0040;Server@node2;Svr;node2.supernodexp.hpc;Scheduler sent command 0
02/14/2018 04:09:18;0100;Server@node2;Req;;Type 21 request received from Scheduler@node2.supernodexp.hpc, sock=20
02/14/2018 04:09:18;0100;Server@node2;Req;;Type 81 request received from Scheduler@node2.supernodexp.hpc, sock=20
02/14/2018 04:09:18;0100;Server@node2;Req;;Type 71 request received from Scheduler@node2.supernodexp.hpc, sock=20
02/14/2018 04:09:18;0100;Server@node2;Req;;Type 58 request received from Scheduler@node2.supernodexp.hpc, sock=20
02/14/2018 04:09:18;0100;Server@node2;Req;;Type 1 request received from ctminh@node2.supernodexp.hpc, sock=16
02/14/2018 04:09:18;0100;Server@node2;Req;;Type 3 request received from ctminh@node2.supernodexp.hpc, sock=16
02/14/2018 04:09:18;0100;Server@node2;Req;;Type 5 request received from ctminh@node2.supernodexp.hpc, sock=16
02/14/2018 04:09:18;0100;Server@node2;Job;1004.node2.supernodexp.hpc;enqueuing into workq, state 1 hop 1
02/14/2018 04:09:18;0008;Server@node2;Job;1004.node2.supernodexp.hpc;Job Queued at request of ctminh@node2.supernodexp.hpc, owner = ctminh@node2.supernodexp.hpc, job name = sweep, queue = workq
02/14/2018 04:09:18;0100;Server@node2;Req;;Type 20 request received from Scheduler@node2.supernodexp.hpc, sock=20
02/14/2018 04:09:18;0100;Server@node2;Req;;Type 51 request received from Scheduler@node2.supernodexp.hpc, sock=20
02/14/2018 04:09:18;0100;Server@node2;Req;;Type 1 request received from ctminh@node2.supernodexp.hpc, sock=16
02/14/2018 04:09:18;0100;Server@node2;Req;;Type 3 request received from ctminh@node2.supernodexp.hpc, sock=16
02/14/2018 04:09:18;0100;Server@node2;Req;;Type 5 request received from ctminh@node2.supernodexp.hpc, sock=16
02/14/2018 04:09:18;0100;Server@node2;Job;1005.node2.supernodexp.hpc;enqueuing into workq, state 1 hop 1
02/14/2018 04:09:18;0008;Server@node2;Job;1005.node2.supernodexp.hpc;Job Queued at request of ctminh@node2.supernodexp.hpc, owner = ctminh@node2.supernodexp.hpc, job name = matrix-x-vector, queue = workq
02/14/2018 04:09:18;0100;Server@node2;Req;;Type 23 request received from Scheduler@node2.supernodexp.hpc, sock=20
02/14/2018 04:09:18;0008;Server@node2;Job;1003.node2.supernodexp.hpc;Job Run at request of Scheduler@node2.supernodexp.hpc on exec_vnode (node14:ncpus=32:mem=2097152kb)
02/14/2018 04:09:18;0001;Server@node2;Svr;Server@node2;Success (0) in req_runjob2, return value of svr_startjob is 0
02/14/2018 04:09:18;0100;Server@node2;Req;;Type 1 request received from ctminh@node2.supernodexp.hpc, sock=16
02/14/2018 04:09:18;0100;Server@node2;Req;;Type 23 request received from Scheduler@node2.supernodexp.hpc, sock=20
02/14/2018 04:09:18;0008;Server@node2;Job;1004.node2.supernodexp.hpc;Job Run at request of Scheduler@node2.supernodexp.hpc on exec_vnode (node14:ncpus=8:mem=3145728kb)
02/14/2018 04:09:18;0001;Server@node2;Svr;Server@node2;Success (0) in req_runjob2, return value of svr_startjob is 0
02/14/2018 04:09:18;0100;Server@node2;Req;;Type 3 request received from ctminh@node2.supernodexp.hpc, sock=16
02/14/2018 04:09:18;0040;Server@node2;Svr;node2.supernodexp.hpc;Scheduler sent command 1
02/14/2018 04:09:18;0040;Server@node2;Svr;node2.supernodexp.hpc;Scheduler sent command 0
02/14/2018 04:09:18;0100;Server@node2;Req;;Type 5 request received from ctminh@node2.supernodexp.hpc, sock=16
02/14/2018 04:09:18;0100;Server@node2;Job;1006.node2.supernodexp.hpc;enqueuing into workq, state 1 hop 1
02/14/2018 04:09:18;0008;Server@node2;Job;1006.node2.supernodexp.hpc;Job Queued at request of ctminh@node2.supernodexp.hpc, owner = ctminh@node2.supernodexp.hpc, job name = telemac3, queue = workq
02/14/2018 04:09:18;0100;Server@node2;Req;;Type 21 request received from Scheduler@node2.supernodexp.hpc, sock=20
02/14/2018 04:09:18;0100;Server@node2;Req;;Type 81 request received from Scheduler@node2.supernodexp.hpc, sock=20
02/14/2018 04:09:18;0100;Server@node2;Req;;Type 71 request received from Scheduler@node2.supernodexp.hpc, sock=20
02/14/2018 04:09:18;0100;Server@node2;Req;;Type 58 request received from Scheduler@node2.supernodexp.hpc, sock=20
02/14/2018 04:09:18;0100;Server@node2;Req;;Type 1 request received from ctminh@node2.supernodexp.hpc, sock=16
02/14/2018 04:09:18;0100;Server@node2;Req;;Type 3 request received from ctminh@node2.supernodexp.hpc, sock=16
02/14/2018 04:09:18;0100;Server@node2;Req;;Type 5 request received from ctminh@node2.supernodexp.hpc, sock=16
02/14/2018 04:09:18;0100;Server@node2;Job;1007.node2.supernodexp.hpc;enqueuing into workq, state 1 hop 1
02/14/2018 04:09:18;0008;Server@node2;Job;1007.node2.supernodexp.hpc;Job Queued at request of ctminh@node2.supernodexp.hpc, owner = ctminh@node2.supernodexp.hpc, job name = matrix-x-vector, queue = workq
02/14/2018 04:09:18;0100;Server@node2;Req;;Type 1 request received from ctminh@node2.supernodexp.hpc, sock=16
02/14/2018 04:09:18;0100;Server@node2;Req;;Type 3 request received from ctminh@node2.supernodexp.hpc, sock=16
02/14/2018 04:09:18;0100;Server@node2;Req;;Type 5 request received from ctminh@node2.supernodexp.hpc, sock=16
02/14/2018 04:09:18;0100;Server@node2;Job;1008.node2.supernodexp.hpc;enqueuing into workq, state 1 hop 1
02/14/2018 04:09:18;0008;Server@node2;Job;1008.node2.supernodexp.hpc;Job Queued at request of ctminh@node2.supernodexp.hpc, owner = ctminh@node2.supernodexp.hpc, job name = telemac3, queue = workq
02/14/2018 04:09:18;0100;Server@node2;Req;;Type 1 request received from ctminh@node2.supernodexp.hpc, sock=16
02/14/2018 04:09:18;0100;Server@node2;Req;;Type 20 request received from Scheduler@node2.supernodexp.hpc, sock=20
02/14/2018 04:09:18;0100;Server@node2;Req;;Type 3 request received from ctminh@node2.supernodexp.hpc, sock=16
02/14/2018 04:09:18;0100;Server@node2;Req;;Type 51 request received from Scheduler@node2.supernodexp.hpc, sock=20
02/14/2018 04:09:18;0100;Server@node2;Req;;Type 5 request received from ctminh@node2.supernodexp.hpc, sock=16
02/14/2018 04:09:18;0100;Server@node2;Job;1009.node2.supernodexp.hpc;enqueuing into workq, state 1 hop 1
02/14/2018 04:09:18;0008;Server@node2;Job;1009.node2.supernodexp.hpc;Job Queued at request of ctminh@node2.supernodexp.hpc, owner = ctminh@node2.supernodexp.hpc, job name = sweep, queue = workq
02/14/2018 04:09:18;0100;Server@node2;Req;;Type 1 request received from ctminh@node2.supernodexp.hpc, sock=16
02/14/2018 04:09:18;0100;Server@node2;Req;;Type 3 request received from ctminh@node2.supernodexp.hpc, sock=16
02/14/2018 04:09:18;0100;Server@node2;Req;;Type 11 request received from Scheduler@node2.supernodexp.hpc, sock=20
02/14/2018 04:09:18;0008;Server@node2;Job;1008.node2.supernodexp.hpc;Job Modified at request of Scheduler@node2.supernodexp.hpc
02/14/2018 04:09:18;0100;Server@node2;Req;;Type 5 request received from ctminh@node2.supernodexp.hpc, sock=16
02/14/2018 04:09:18;0100;Server@node2;Job;1010.node2.supernodexp.hpc;enqueuing into workq, state 1 hop 1
02/14/2018 04:09:18;0008;Server@node2;Job;1010.node2.supernodexp.hpc;Job Queued at request of ctminh@node2.supernodexp.hpc, owner = ctminh@node2.supernodexp.hpc, job name = telemac2, queue = workq
02/14/2018 04:09:18;0100;Server@node2;Req;;Type 11 request received from Scheduler@node2.supernodexp.hpc, sock=20
02/14/2018 04:09:18;0008;Server@node2;Job;1005.node2.supernodexp.hpc;Job Modified at request of Scheduler@node2.supernodexp.hpc
02/14/2018 04:09:18;0100;Server@node2;Req;;Type 11 request received from Scheduler@node2.supernodexp.hpc, sock=20
02/14/2018 04:09:18;0008;Server@node2;Job;1007.node2.supernodexp.hpc;Job Modified at request of Scheduler@node2.supernodexp.hpc
02/14/2018 04:09:18;0100;Server@node2;Req;;Type 11 request received from Scheduler@node2.supernodexp.hpc, sock=20
02/14/2018 04:09:18;0008;Server@node2;Job;1006.node2.supernodexp.hpc;Job Modified at request of Scheduler@node2.supernodexp.hpc
02/14/2018 04:09:18;0040;Server@node2;Svr;node2.supernodexp.hpc;Scheduler sent command 1
02/14/2018 04:09:18;0040;Server@node2;Svr;node2.supernodexp.hpc;Scheduler sent command 0
02/14/2018 04:09:18;0100;Server@node2;Req;;Type 21 request received from Scheduler@node2.supernodexp.hpc, sock=20
02/14/2018 04:09:18;0100;Server@node2;Req;;Type 81 request received from Scheduler@node2.supernodexp.hpc, sock=20
02/14/2018 04:09:18;0100;Server@node2;Req;;Type 71 request received from Scheduler@node2.supernodexp.hpc, sock=20
02/14/2018 04:09:18;0100;Server@node2;Req;;Type 58 request received from Scheduler@node2.supernodexp.hpc, sock=20
02/14/2018 04:09:18;0100;Server@node2;Req;;Type 1 request received from ctminh@node2.supernodexp.hpc, sock=16
02/14/2018 04:09:18;0100;Server@node2;Req;;Type 3 request received from ctminh@node2.supernodexp.hpc, sock=16
02/14/2018 04:09:18;0100;Server@node2;Req;;Type 5 request received from ctminh@node2.supernodexp.hpc, sock=16
02/14/2018 04:09:18;0100;Server@node2;Job;1011.node2.supernodexp.hpc;enqueuing into workq, state 1 hop 1
02/14/2018 04:09:18;0008;Server@node2;Job;1011.node2.supernodexp.hpc;Job Queued at request of ctminh@node2.supernodexp.hpc, owner = ctminh@node2.supernodexp.hpc, job name = telemac1, queue = workq
02/14/2018 04:09:18;0100;Server@node2;Req;;Type 1 request received from ctminh@node2.supernodexp.hpc, sock=16
02/14/2018 04:09:18;0100;Server@node2;Req;;Type 20 request received from Scheduler@node2.supernodexp.hpc, sock=20
02/14/2018 04:09:18;0100;Server@node2;Req;;Type 3 request received from ctminh@node2.supernodexp.hpc, sock=16
02/14/2018 04:09:18;0100;Server@node2;Req;;Type 5 request received from ctminh@node2.supernodexp.hpc, sock=16
02/14/2018 04:09:18;0100;Server@node2;Job;1012.node2.supernodexp.hpc;enqueuing into workq, state 1 hop 1
02/14/2018 04:09:18;0008;Server@node2;Job;1012.node2.supernodexp.hpc;Job Queued at request of ctminh@node2.supernodexp.hpc, owner = ctminh@node2.supernodexp.hpc, job name = telemac2, queue = workq
02/14/2018 04:09:18;0100;Server@node2;Req;;Type 51 request received from Scheduler@node2.supernodexp.hpc, sock=20
02/14/2018 04:09:18;0100;Server@node2;Req;;Type 1 request received from ctminh@node2.supernodexp.hpc, sock=16
02/14/2018 04:09:18;0100;Server@node2;Req;;Type 3 request received from ctminh@node2.supernodexp.hpc, sock=16
02/14/2018 04:09:18;0100;Server@node2;Req;;Type 5 request received from ctminh@node2.supernodexp.hpc, sock=16
02/14/2018 04:09:18;0100;Server@node2;Job;1013.node2.supernodexp.hpc;enqueuing into workq, state 1 hop 1
02/14/2018 04:09:18;0008;Server@node2;Job;1013.node2.supernodexp.hpc;Job Queued at request of ctminh@node2.supernodexp.hpc, owner = ctminh@node2.supernodexp.hpc, job name = qe_mic_test, queue = workq
02/14/2018 04:09:18;0100;Server@node2;Req;;Type 11 request received from Scheduler@node2.supernodexp.hpc, sock=20
02/14/2018 04:09:18;0008;Server@node2;Job;1012.node2.supernodexp.hpc;Job Modified at request of Scheduler@node2.supernodexp.hpc
02/14/2018 04:09:18;0100;Server@node2;Req;;Type 11 request received from Scheduler@node2.supernodexp.hpc, sock=20
02/14/2018 04:09:18;0008;Server@node2;Job;1011.node2.supernodexp.hpc;Job Modified at request of Scheduler@node2.supernodexp.hpc
02/14/2018 04:09:18;0100;Server@node2;Req;;Type 11 request received from Scheduler@node2.supernodexp.hpc, sock=20
02/14/2018 04:09:18;0008;Server@node2;Job;1006.node2.supernodexp.hpc;Job Modified at request of Scheduler@node2.supernodexp.hpc
02/14/2018 04:09:18;0100;Server@node2;Req;;Type 11 request received from Scheduler@node2.supernodexp.hpc, sock=20
02/14/2018 04:09:18;0008;Server@node2;Job;1009.node2.supernodexp.hpc;Job Modified at request of Scheduler@node2.supernodexp.hpc
02/14/2018 04:09:18;0100;Server@node2;Req;;Type 11 request received from Scheduler@node2.supernodexp.hpc, sock=20
02/14/2018 04:09:18;0008;Server@node2;Job;1010.node2.supernodexp.hpc;Job Modified at request of Scheduler@node2.supernodexp.hpc
02/14/2018 04:09:18;0040;Server@node2;Svr;node2.supernodexp.hpc;Scheduler sent command 1
02/14/2018 04:09:18;0040;Server@node2;Svr;node2.supernodexp.hpc;Scheduler sent command 0
02/14/2018 04:09:18;0100;Server@node2;Req;;Type 1 request received from ctminh@node2.supernodexp.hpc, sock=16
02/14/2018 04:09:18;0100;Server@node2;Req;;Type 21 request received from Scheduler@node2.supernodexp.hpc, sock=20
02/14/2018 04:09:18;0100;Server@node2;Req;;Type 3 request received from ctminh@node2.supernodexp.hpc, sock=16
02/14/2018 04:09:18;0100;Server@node2;Req;;Type 5 request received from ctminh@node2.supernodexp.hpc, sock=16
02/14/2018 04:09:18;0100;Server@node2;Job;1014.node2.supernodexp.hpc;enqueuing into workq, state 1 hop 1
02/14/2018 04:09:18;0008;Server@node2;Job;1014.node2.supernodexp.hpc;Job Queued at request of ctminh@node2.supernodexp.hpc, owner = ctminh@node2.supernodexp.hpc, job name = telemac1, queue = workq
02/14/2018 04:09:18;0100;Server@node2;Req;;Type 81 request received from Scheduler@node2.supernodexp.hpc, sock=20
02/14/2018 04:09:18;0100;Server@node2;Req;;Type 71 request received from Scheduler@node2.supernodexp.hpc, sock=20
02/14/2018 04:09:18;0100;Server@node2;Req;;Type 58 request received from Scheduler@node2.supernodexp.hpc, sock=20
02/14/2018 04:09:18;0100;Server@node2;Req;;Type 1 request received from ctminh@node2.supernodexp.hpc, sock=16
02/14/2018 04:09:18;0100;Server@node2;Req;;Type 3 request received from ctminh@node2.supernodexp.hpc, sock=16
02/14/2018 04:09:18;0100;Server@node2;Req;;Type 5 request received from ctminh@node2.supernodexp.hpc, sock=16
02/14/2018 04:09:18;0100;Server@node2;Job;1015.node2.supernodexp.hpc;enqueuing into workq, state 1 hop 1
02/14/2018 04:09:18;0008;Server@node2;Job;1015.node2.supernodexp.hpc;Job Queued at request of ctminh@node2.supernodexp.hpc, owner = ctminh@node2.supernodexp.hpc, job name = thread-affinity, queue = workq
02/14/2018 04:09:18;0100;Server@node2;Req;;Type 20 request received from Scheduler@node2.supernodexp.hpc, sock=20
02/14/2018 04:09:18;0100;Server@node2;Req;;Type 51 request received from Scheduler@node2.supernodexp.hpc, sock=20
02/14/2018 04:09:18;0100;Server@node2;Req;;Type 11 request received from Scheduler@node2.supernodexp.hpc, sock=20
02/14/2018 04:09:18;0008;Server@node2;Job;1010.node2.supernodexp.hpc;Job Modified at request of Scheduler@node2.supernodexp.hpc
02/14/2018 04:09:18;0100;Server@node2;Req;;Type 11 request received from Scheduler@node2.supernodexp.hpc, sock=20
02/14/2018 04:09:18;0008;Server@node2;Job;1014.node2.supernodexp.hpc;Job Modified at request of Scheduler@node2.supernodexp.hpc
02/14/2018 04:09:18;0100;Server@node2;Req;;Type 11 request received from Scheduler@node2.supernodexp.hpc, sock=20
02/14/2018 04:09:18;0008;Server@node2;Job;1015.node2.supernodexp.hpc;Job Modified at request of Scheduler@node2.supernodexp.hpc
02/14/2018 04:09:18;0100;Server@node2;Req;;Type 11 request received from Scheduler@node2.supernodexp.hpc, sock=20
02/14/2018 04:09:18;0008;Server@node2;Job;1013.node2.supernodexp.hpc;Job Modified at request of Scheduler@node2.supernodexp.hpc
02/14/2018 04:09:18;0040;Server@node2;Svr;node2.supernodexp.hpc;Scheduler sent command 1
02/14/2018 04:09:18;0040;Server@node2;Svr;node2.supernodexp.hpc;Scheduler sent command 0
02/14/2018 04:09:18;0100;Server@node2;Req;;Type 21 request received from Scheduler@node2.supernodexp.hpc, sock=20
02/14/2018 04:09:18;0100;Server@node2;Req;;Type 81 request received from Scheduler@node2.supernodexp.hpc, sock=20
02/14/2018 04:09:18;0100;Server@node2;Req;;Type 1 request received from ctminh@node2.supernodexp.hpc, sock=16
02/14/2018 04:09:18;0100;Server@node2;Req;;Type 71 request received from Scheduler@node2.supernodexp.hpc, sock=20
02/14/2018 04:09:18;0100;Server@node2;Req;;Type 3 request received from ctminh@node2.supernodexp.hpc, sock=16
02/14/2018 04:09:18;0100;Server@node2;Req;;Type 58 request received from Scheduler@node2.supernodexp.hpc, sock=20
02/14/2018 04:09:18;0100;Server@node2;Req;;Type 5 request received from ctminh@node2.supernodexp.hpc, sock=16
02/14/2018 04:09:18;0100;Server@node2;Job;1016.node2.supernodexp.hpc;enqueuing into workq, state 1 hop 1
02/14/2018 04:09:19;0008;Server@node2;Job;1016.node2.supernodexp.hpc;Job Queued at request of ctminh@node2.supernodexp.hpc, owner = ctminh@node2.supernodexp.hpc, job name = vast1, queue = workq
02/14/2018 04:09:19;0100;Server@node2;Req;;Type 20 request received from Scheduler@node2.supernodexp.hpc, sock=20
02/14/2018 04:09:19;0100;Server@node2;Req;;Type 51 request received from Scheduler@node2.supernodexp.hpc, sock=20
02/14/2018 04:09:19;0100;Server@node2;Req;;Type 11 request received from Scheduler@node2.supernodexp.hpc, sock=20
02/14/2018 04:09:19;0008;Server@node2;Job;1016.node2.supernodexp.hpc;Job Modified at request of Scheduler@node2.supernodexp.hpc
02/14/2018 04:09:19;0040;Server@node2;Svr;node2.supernodexp.hpc;Scheduler sent command 1
02/14/2018 04:09:19;0040;Server@node2;Svr;node2.supernodexp.hpc;Scheduler sent command 0
02/14/2018 04:09:19;0100;Server@node2;Req;;Type 21 request received from Scheduler@node2.supernodexp.hpc, sock=20
02/14/2018 04:09:19;0100;Server@node2;Req;;Type 81 request received from Scheduler@node2.supernodexp.hpc, sock=20
02/14/2018 04:09:19;0100;Server@node2;Req;;Type 71 request received from Scheduler@node2.supernodexp.hpc, sock=20
02/14/2018 04:09:19;0100;Server@node2;Req;;Type 58 request received from Scheduler@node2.supernodexp.hpc, sock=20
02/14/2018 04:09:19;0100;Server@node2;Req;;Type 20 request received from Scheduler@node2.supernodexp.hpc, sock=20
02/14/2018 04:09:19;0100;Server@node2;Req;;Type 51 request received from Scheduler@node2.supernodexp.hpc, sock=20
02/14/2018 04:09:20;0080;Server@node2;Job;1004.node2.supernodexp.hpc;Obit received momhop:1 serverhop:1 state:4 substate:42
02/14/2018 04:09:21;0010;Server@node2;Job;1004.node2.supernodexp.hpc;Exit_status=0 resources_used.cpupercent=800 resources_used.cput=00:00:08 resources_used.mem=0kb resources_used.ncpus=8 resources_used.vmem=0kb resources_used.walltime=00:00:01
02/14/2018 04:09:21;0100;Server@node2;Job;1004.node2.supernodexp.hpc;dequeuing from workq, state 5
02/14/2018 04:09:21;0040;Server@node2;Svr;node2.supernodexp.hpc;Scheduler sent command 2
02/14/2018 04:09:21;0040;Server@node2;Svr;node2.supernodexp.hpc;Scheduler sent command 0
02/14/2018 04:09:21;0100;Server@node2;Req;;Type 21 request received from Scheduler@node2.supernodexp.hpc, sock=20
02/14/2018 04:09:21;0100;Server@node2;Req;;Type 81 request received from Scheduler@node2.supernodexp.hpc, sock=20
02/14/2018 04:09:21;0100;Server@node2;Req;;Type 71 request received from Scheduler@node2.supernodexp.hpc, sock=20
02/14/2018 04:09:21;0100;Server@node2;Req;;Type 58 request received from Scheduler@node2.supernodexp.hpc, sock=20
02/14/2018 04:09:21;0100;Server@node2;Req;;Type 20 request received from Scheduler@node2.supernodexp.hpc, sock=20
02/14/2018 04:09:21;0100;Server@node2;Req;;Type 51 request received from Scheduler@node2.supernodexp.hpc, sock=20
02/14/2018 04:09:21;0100;Server@node2;Req;;Type 11 request received from Scheduler@node2.supernodexp.hpc, sock=20
02/14/2018 04:09:21;0008;Server@node2;Job;1013.node2.supernodexp.hpc;Job Modified at request of Scheduler@node2.supernodexp.hpc
02/14/2018 04:09:22;0080;Server@node2;Job;1003.node2.supernodexp.hpc;Obit received momhop:1 serverhop:1 state:4 substate:42
02/14/2018 04:09:29;0010;Server@node2;Job;1003.node2.supernodexp.hpc;Exit_status=0 resources_used.cpupercent=100 resources_used.cput=00:00:04 resources_used.mem=535860kb resources_used.ncpus=32 resources_used.vmem=867316kb resources_used.walltime=00:00:05
02/14/2018 04:09:29;0100;Server@node2;Job;1003.node2.supernodexp.hpc;dequeuing from workq, state 5
02/14/2018 04:09:29;0040;Server@node2;Svr;node2.supernodexp.hpc;Scheduler sent command 2
02/14/2018 04:09:29;0040;Server@node2;Svr;node2.supernodexp.hpc;Scheduler sent command 0
02/14/2018 04:09:29;0100;Server@node2;Req;;Type 21 request received from Scheduler@node2.supernodexp.hpc, sock=20
02/14/2018 04:09:29;0100;Server@node2;Req;;Type 81 request received from Scheduler@node2.supernodexp.hpc, sock=20
02/14/2018 04:09:29;0100;Server@node2;Req;;Type 71 request received from Scheduler@node2.supernodexp.hpc, sock=20
02/14/2018 04:09:29;0100;Server@node2;Req;;Type 58 request received from Scheduler@node2.supernodexp.hpc, sock=20
02/14/2018 04:09:29;0100;Server@node2;Req;;Type 20 request received from Scheduler@node2.supernodexp.hpc, sock=20
02/14/2018 04:09:29;0100;Server@node2;Req;;Type 51 request received from Scheduler@node2.supernodexp.hpc, sock=20
02/14/2018 04:09:30;0100;Server@node2;Req;;Type 23 request received from Scheduler@node2.supernodexp.hpc, sock=20
02/14/2018 04:09:30;0008;Server@node2;Job;1013.node2.supernodexp.hpc;Job Run at request of Scheduler@node2.supernodexp.hpc on exec_vnode (node14:ncpus=32:nmics=1:mem=16777216kb)
02/14/2018 04:09:30;0001;Server@node2;Svr;Server@node2;Success (0) in req_runjob2, return value of svr_startjob is 0
02/14/2018 04:09:30;0100;Server@node2;Req;;Type 11 request received from Scheduler@node2.supernodexp.hpc, sock=20
02/14/2018 04:09:30;0008;Server@node2;Job;1016.node2.supernodexp.hpc;Job Modified at request of Scheduler@node2.supernodexp.hpc
02/14/2018 04:09:53;0100;Server@node2;Req;;Type 1 request received from ctminh@node2.supernodexp.hpc, sock=16
02/14/2018 04:09:53;0100;Server@node2;Req;;Type 3 request received from ctminh@node2.supernodexp.hpc, sock=16
02/14/2018 04:09:53;0100;Server@node2;Req;;Type 5 request received from ctminh@node2.supernodexp.hpc, sock=16
02/14/2018 04:09:53;0100;Server@node2;Job;1017.node2.supernodexp.hpc;enqueuing into workq, state 1 hop 1
02/14/2018 04:09:53;0008;Server@node2;Job;1017.node2.supernodexp.hpc;Job Queued at request of ctminh@node2.supernodexp.hpc, owner = ctminh@node2.supernodexp.hpc, job name = vectorization, queue = workq
02/14/2018 04:09:53;0040;Server@node2;Svr;node2.supernodexp.hpc;Scheduler sent command 1
02/14/2018 04:09:53;0040;Server@node2;Svr;node2.supernodexp.hpc;Scheduler sent command 0
02/14/2018 04:09:53;0100;Server@node2;Req;;Type 21 request received from Scheduler@node2.supernodexp.hpc, sock=20
02/14/2018 04:09:53;0100;Server@node2;Req;;Type 81 request received from Scheduler@node2.supernodexp.hpc, sock=20
02/14/2018 04:09:53;0100;Server@node2;Req;;Type 71 request received from Scheduler@node2.supernodexp.hpc, sock=20
02/14/2018 04:09:53;0100;Server@node2;Req;;Type 58 request received from Scheduler@node2.supernodexp.hpc, sock=20
02/14/2018 04:09:53;0100;Server@node2;Req;;Type 1 request received from ctminh@node2.supernodexp.hpc, sock=16
02/14/2018 04:09:53;0100;Server@node2;Req;;Type 3 request received from ctminh@node2.supernodexp.hpc, sock=16
02/14/2018 04:09:53;0100;Server@node2;Req;;Type 5 request received from ctminh@node2.supernodexp.hpc, sock=16
02/14/2018 04:09:53;0100;Server@node2;Job;1018.node2.supernodexp.hpc;enqueuing into workq, state 1 hop 1
02/14/2018 04:09:53;0008;Server@node2;Job;1018.node2.supernodexp.hpc;Job Queued at request of ctminh@node2.supernodexp.hpc, owner = ctminh@node2.supernodexp.hpc, job name = telemac3, queue = workq
02/14/2018 04:09:53;0100;Server@node2;Req;;Type 1 request received from ctminh@node2.supernodexp.hpc, sock=16
02/14/2018 04:09:53;0100;Server@node2;Req;;Type 3 request received from ctminh@node2.supernodexp.hpc, sock=16
02/14/2018 04:09:53;0100;Server@node2;Req;;Type 5 request received from ctminh@node2.supernodexp.hpc, sock=16
02/14/2018 04:09:53;0100;Server@node2;Job;1019.node2.supernodexp.hpc;enqueuing into workq, state 1 hop 1
02/14/2018 04:09:53;0008;Server@node2;Job;1019.node2.supernodexp.hpc;Job Queued at request of ctminh@node2.supernodexp.hpc, owner = ctminh@node2.supernodexp.hpc, job name = vast1, queue = workq
02/14/2018 04:09:53;0100;Server@node2;Req;;Type 20 request received from Scheduler@node2.supernodexp.hpc, sock=20
02/14/2018 04:09:53;0100;Server@node2;Req;;Type 51 request received from Scheduler@node2.supernodexp.hpc, sock=20
02/14/2018 04:09:53;0100;Server@node2;Req;;Type 1 request received from ctminh@node2.supernodexp.hpc, sock=16
02/14/2018 04:09:53;0100;Server@node2;Req;;Type 3 request received from ctminh@node2.supernodexp.hpc, sock=16
02/14/2018 04:09:53;0100;Server@node2;Req;;Type 5 request received from ctminh@node2.supernodexp.hpc, sock=16
02/14/2018 04:09:53;0100;Server@node2;Job;1020.node2.supernodexp.hpc;enqueuing into workq, state 1 hop 1
02/14/2018 04:09:53;0008;Server@node2;Job;1020.node2.supernodexp.hpc;Job Queued at request of ctminh@node2.supernodexp.hpc, owner = ctminh@node2.supernodexp.hpc, job name = vectorization, queue = workq
02/14/2018 04:09:53;0100;Server@node2;Req;;Type 1 request received from ctminh@node2.supernodexp.hpc, sock=16
02/14/2018 04:09:53;0100;Server@node2;Req;;Type 3 request received from ctminh@node2.supernodexp.hpc, sock=16
02/14/2018 04:09:53;0100;Server@node2;Req;;Type 5 request received from ctminh@node2.supernodexp.hpc, sock=16
02/14/2018 04:09:53;0100;Server@node2;Job;1021.node2.supernodexp.hpc;enqueuing into workq, state 1 hop 1
02/14/2018 04:09:53;0008;Server@node2;Job;1021.node2.supernodexp.hpc;Job Queued at request of ctminh@node2.supernodexp.hpc, owner = ctminh@node2.supernodexp.hpc, job name = telemac3, queue = workq
02/14/2018 04:09:53;0100;Server@node2;Req;;Type 11 request received from Scheduler@node2.supernodexp.hpc, sock=20
02/14/2018 04:09:53;0008;Server@node2;Job;1019.node2.supernodexp.hpc;Job Modified at request of Scheduler@node2.supernodexp.hpc
02/14/2018 04:09:53;0100;Server@node2;Req;;Type 11 request received from Scheduler@node2.supernodexp.hpc, sock=20
02/14/2018 04:09:53;0008;Server@node2;Job;1018.node2.supernodexp.hpc;Job Modified at request of Scheduler@node2.supernodexp.hpc
02/14/2018 04:09:53;0100;Server@node2;Req;;Type 11 request received from Scheduler@node2.supernodexp.hpc, sock=20
02/14/2018 04:09:53;0008;Server@node2;Job;1017.node2.supernodexp.hpc;Job Modified at request of Scheduler@node2.supernodexp.hpc
02/14/2018 04:09:53;0040;Server@node2;Svr;node2.supernodexp.hpc;Scheduler sent command 1
02/14/2018 04:09:53;0040;Server@node2;Svr;node2.supernodexp.hpc;Scheduler sent command 0
02/14/2018 04:09:53;0100;Server@node2;Req;;Type 21 request received from Scheduler@node2.supernodexp.hpc, sock=20
02/14/2018 04:09:53;0100;Server@node2;Req;;Type 81 request received from Scheduler@node2.supernodexp.hpc, sock=20
02/14/2018 04:09:53;0100;Server@node2;Req;;Type 71 request received from Scheduler@node2.supernodexp.hpc, sock=20
02/14/2018 04:09:53;0100;Server@node2;Req;;Type 58 request received from Scheduler@node2.supernodexp.hpc, sock=20
02/14/2018 04:09:53;0100;Server@node2;Req;;Type 1 request received from ctminh@node2.supernodexp.hpc, sock=16
02/14/2018 04:09:53;0100;Server@node2;Req;;Type 3 request received from ctminh@node2.supernodexp.hpc, sock=16
02/14/2018 04:09:53;0100;Server@node2;Req;;Type 5 request received from ctminh@node2.supernodexp.hpc, sock=16
02/14/2018 04:09:53;0100;Server@node2;Job;1022.node2.supernodexp.hpc;enqueuing into workq, state 1 hop 1
02/14/2018 04:09:53;0008;Server@node2;Job;1022.node2.supernodexp.hpc;Job Queued at request of ctminh@node2.supernodexp.hpc, owner = ctminh@node2.supernodexp.hpc, job name = thread-affinity, queue = workq
02/14/2018 04:09:53;0100;Server@node2;Req;;Type 1 request received from ctminh@node2.supernodexp.hpc, sock=16
02/14/2018 04:09:53;0100;Server@node2;Req;;Type 3 request received from ctminh@node2.supernodexp.hpc, sock=16
02/14/2018 04:09:53;0100;Server@node2;Req;;Type 5 request received from ctminh@node2.supernodexp.hpc, sock=16
02/14/2018 04:09:53;0100;Server@node2;Job;1023.node2.supernodexp.hpc;enqueuing into workq, state 1 hop 1
02/14/2018 04:09:53;0008;Server@node2;Job;1023.node2.supernodexp.hpc;Job Queued at request of ctminh@node2.supernodexp.hpc, owner = ctminh@node2.supernodexp.hpc, job name = sweep, queue = workq
02/14/2018 04:09:53;0100;Server@node2;Req;;Type 20 request received from Scheduler@node2.supernodexp.hpc, sock=20
02/14/2018 04:09:53;0100;Server@node2;Req;;Type 51 request received from Scheduler@node2.supernodexp.hpc, sock=20
02/14/2018 04:09:53;0100;Server@node2;Req;;Type 1 request received from ctminh@node2.supernodexp.hpc, sock=16
02/14/2018 04:09:53;0100;Server@node2;Req;;Type 3 request received from ctminh@node2.supernodexp.hpc, sock=16
02/14/2018 04:09:53;0100;Server@node2;Req;;Type 5 request received from ctminh@node2.supernodexp.hpc, sock=16
02/14/2018 04:09:53;0100;Server@node2;Job;1024.node2.supernodexp.hpc;enqueuing into workq, state 1 hop 1
02/14/2018 04:09:53;0008;Server@node2;Job;1024.node2.supernodexp.hpc;Job Queued at request of ctminh@node2.supernodexp.hpc, owner = ctminh@node2.supernodexp.hpc, job name = qe_mic_test, queue = workq
02/14/2018 04:09:53;0100;Server@node2;Req;;Type 1 request received from ctminh@node2.supernodexp.hpc, sock=16
02/14/2018 04:09:53;0100;Server@node2;Req;;Type 3 request received from ctminh@node2.supernodexp.hpc, sock=16
02/14/2018 04:09:53;0100;Server@node2;Req;;Type 5 request received from ctminh@node2.supernodexp.hpc, sock=16
02/14/2018 04:09:53;0100;Server@node2;Job;1025.node2.supernodexp.hpc;enqueuing into workq, state 1 hop 1
02/14/2018 04:09:53;0008;Server@node2;Job;1025.node2.supernodexp.hpc;Job Queued at request of ctminh@node2.supernodexp.hpc, owner = ctminh@node2.supernodexp.hpc, job name = vast1, queue = workq
02/14/2018 04:09:53;0100;Server@node2;Req;;Type 1 request received from ctminh@node2.supernodexp.hpc, sock=16
02/14/2018 04:09:53;0100;Server@node2;Req;;Type 3 request received from ctminh@node2.supernodexp.hpc, sock=16
02/14/2018 04:09:53;0100;Server@node2;Req;;Type 5 request received from ctminh@node2.supernodexp.hpc, sock=16
02/14/2018 04:09:53;0100;Server@node2;Job;1026.node2.supernodexp.hpc;enqueuing into workq, state 1 hop 1
02/14/2018 04:09:53;0008;Server@node2;Job;1026.node2.supernodexp.hpc;Job Queued at request of ctminh@node2.supernodexp.hpc, owner = ctminh@node2.supernodexp.hpc, job name = thread-affinity, queue = workq
02/14/2018 04:09:53;0100;Server@node2;Req;;Type 11 request received from Scheduler@node2.supernodexp.hpc, sock=20
02/14/2018 04:09:53;0008;Server@node2;Job;1021.node2.supernodexp.hpc;Job Modified at request of Scheduler@node2.supernodexp.hpc
02/14/2018 04:09:53;0100;Server@node2;Req;;Type 11 request received from Scheduler@node2.supernodexp.hpc, sock=20
02/14/2018 04:09:53;0008;Server@node2;Job;1022.node2.supernodexp.hpc;Job Modified at request of Scheduler@node2.supernodexp.hpc
02/14/2018 04:09:53;0100;Server@node2;Req;;Type 11 request received from Scheduler@node2.supernodexp.hpc, sock=20
02/14/2018 04:09:53;0008;Server@node2;Job;1020.node2.supernodexp.hpc;Job Modified at request of Scheduler@node2.supernodexp.hpc
02/14/2018 04:09:53;0100;Server@node2;Req;;Type 11 request received from Scheduler@node2.supernodexp.hpc, sock=20
02/14/2018 04:09:53;0008;Server@node2;Job;1023.node2.supernodexp.hpc;Job Modified at request of Scheduler@node2.supernodexp.hpc
02/14/2018 04:09:53;0040;Server@node2;Svr;node2.supernodexp.hpc;Scheduler sent command 1
02/14/2018 04:09:53;0040;Server@node2;Svr;node2.supernodexp.hpc;Scheduler sent command 0
02/14/2018 04:09:53;0100;Server@node2;Req;;Type 21 request received from Scheduler@node2.supernodexp.hpc, sock=20
02/14/2018 04:09:53;0100;Server@node2;Req;;Type 81 request received from Scheduler@node2.supernodexp.hpc, sock=20
02/14/2018 04:09:53;0100;Server@node2;Req;;Type 71 request received from Scheduler@node2.supernodexp.hpc, sock=20
02/14/2018 04:09:53;0100;Server@node2;Req;;Type 58 request received from Scheduler@node2.supernodexp.hpc, sock=20
02/14/2018 04:09:53;0100;Server@node2;Req;;Type 1 request received from ctminh@node2.supernodexp.hpc, sock=16
02/14/2018 04:09:53;0100;Server@node2;Req;;Type 3 request received from ctminh@node2.supernodexp.hpc, sock=16
02/14/2018 04:09:53;0100;Server@node2;Req;;Type 5 request received from ctminh@node2.supernodexp.hpc, sock=16
02/14/2018 04:09:53;0100;Server@node2;Job;1027.node2.supernodexp.hpc;enqueuing into workq, state 1 hop 1
02/14/2018 04:09:53;0008;Server@node2;Job;1027.node2.supernodexp.hpc;Job Queued at request of ctminh@node2.supernodexp.hpc, owner = ctminh@node2.supernodexp.hpc, job name = sweep, queue = workq
02/14/2018 04:09:53;0100;Server@node2;Req;;Type 1 request received from ctminh@node2.supernodexp.hpc, sock=16
02/14/2018 04:09:53;0100;Server@node2;Req;;Type 3 request received from ctminh@node2.supernodexp.hpc, sock=16
02/14/2018 04:09:53;0100;Server@node2;Req;;Type 5 request received from ctminh@node2.supernodexp.hpc, sock=16
02/14/2018 04:09:53;0100;Server@node2;Job;1028.node2.supernodexp.hpc;enqueuing into workq, state 1 hop 1
02/14/2018 04:09:53;0008;Server@node2;Job;1028.node2.supernodexp.hpc;Job Queued at request of ctminh@node2.supernodexp.hpc, owner = ctminh@node2.supernodexp.hpc, job name = vectorization, queue = workq
02/14/2018 04:09:53;0100;Server@node2;Req;;Type 1 request received from ctminh@node2.supernodexp.hpc, sock=16
02/14/2018 04:09:53;0100;Server@node2;Req;;Type 20 request received from Scheduler@node2.supernodexp.hpc, sock=20
02/14/2018 04:09:53;0100;Server@node2;Req;;Type 3 request received from ctminh@node2.supernodexp.hpc, sock=16
02/14/2018 04:09:53;0100;Server@node2;Req;;Type 51 request received from Scheduler@node2.supernodexp.hpc, sock=20
02/14/2018 04:09:53;0100;Server@node2;Req;;Type 5 request received from ctminh@node2.supernodexp.hpc, sock=16
02/14/2018 04:09:53;0100;Server@node2;Job;1029.node2.supernodexp.hpc;enqueuing into workq, state 1 hop 1
02/14/2018 04:09:53;0008;Server@node2;Job;1029.node2.supernodexp.hpc;Job Queued at request of ctminh@node2.supernodexp.hpc, owner = ctminh@node2.supernodexp.hpc, job name = vectorization, queue = workq
02/14/2018 04:09:53;0100;Server@node2;Req;;Type 11 request received from Scheduler@node2.supernodexp.hpc, sock=20
02/14/2018 04:09:53;0008;Server@node2;Job;1016.node2.supernodexp.hpc;Job Modified at request of Scheduler@node2.supernodexp.hpc
02/14/2018 04:09:53;0100;Server@node2;Req;;Type 11 request received from Scheduler@node2.supernodexp.hpc, sock=20
02/14/2018 04:09:53;0008;Server@node2;Job;1025.node2.supernodexp.hpc;Job Modified at request of Scheduler@node2.supernodexp.hpc
02/14/2018 04:09:53;0100;Server@node2;Req;;Type 11 request received from Scheduler@node2.supernodexp.hpc, sock=20
02/14/2018 04:09:53;0008;Server@node2;Job;1026.node2.supernodexp.hpc;Job Modified at request of Scheduler@node2.supernodexp.hpc
02/14/2018 04:09:53;0100;Server@node2;Req;;Type 11 request received from Scheduler@node2.supernodexp.hpc, sock=20
02/14/2018 04:09:53;0008;Server@node2;Job;1027.node2.supernodexp.hpc;Job Modified at request of Scheduler@node2.supernodexp.hpc
02/14/2018 04:09:53;0100;Server@node2;Req;;Type 11 request received from Scheduler@node2.supernodexp.hpc, sock=20
02/14/2018 04:09:53;0008;Server@node2;Job;1028.node2.supernodexp.hpc;Job Modified at request of Scheduler@node2.supernodexp.hpc
02/14/2018 04:09:53;0100;Server@node2;Req;;Type 11 request received from Scheduler@node2.supernodexp.hpc, sock=20
02/14/2018 04:09:53;0008;Server@node2;Job;1024.node2.supernodexp.hpc;Job Modified at request of Scheduler@node2.supernodexp.hpc
02/14/2018 04:09:53;0040;Server@node2;Svr;node2.supernodexp.hpc;Scheduler sent command 1
02/14/2018 04:09:53;0040;Server@node2;Svr;node2.supernodexp.hpc;Scheduler sent command 0
02/14/2018 04:09:53;0100;Server@node2;Req;;Type 21 request received from Scheduler@node2.supernodexp.hpc, sock=20
02/14/2018 04:09:53;0100;Server@node2;Req;;Type 81 request received from Scheduler@node2.supernodexp.hpc, sock=20
02/14/2018 04:09:53;0100;Server@node2;Req;;Type 71 request received from Scheduler@node2.supernodexp.hpc, sock=20
02/14/2018 04:09:53;0100;Server@node2;Req;;Type 58 request received from Scheduler@node2.supernodexp.hpc, sock=20
02/14/2018 04:09:53;0100;Server@node2;Req;;Type 20 request received from Scheduler@node2.supernodexp.hpc, sock=20
02/14/2018 04:09:53;0100;Server@node2;Req;;Type 51 request received from Scheduler@node2.supernodexp.hpc, sock=20
02/14/2018 04:09:53;0100;Server@node2;Req;;Type 1 request received from ctminh@node2.supernodexp.hpc, sock=16
02/14/2018 04:09:53;0100;Server@node2;Req;;Type 3 request received from ctminh@node2.supernodexp.hpc, sock=16
02/14/2018 04:09:53;0100;Server@node2;Req;;Type 5 request received from ctminh@node2.supernodexp.hpc, sock=16
02/14/2018 04:09:53;0100;Server@node2;Job;1030.node2.supernodexp.hpc;enqueuing into workq, state 1 hop 1
02/14/2018 04:09:53;0008;Server@node2;Job;1030.node2.supernodexp.hpc;Job Queued at request of ctminh@node2.supernodexp.hpc, owner = ctminh@node2.supernodexp.hpc, job name = jacobi, queue = workq
02/14/2018 04:09:53;0100;Server@node2;Req;;Type 1 request received from ctminh@node2.supernodexp.hpc, sock=16
02/14/2018 04:09:53;0100;Server@node2;Req;;Type 3 request received from ctminh@node2.supernodexp.hpc, sock=16
02/14/2018 04:09:53;0100;Server@node2;Req;;Type 5 request received from ctminh@node2.supernodexp.hpc, sock=16
02/14/2018 04:09:53;0100;Server@node2;Job;1031.node2.supernodexp.hpc;enqueuing into workq, state 1 hop 1
02/14/2018 04:09:53;0008;Server@node2;Job;1031.node2.supernodexp.hpc;Job Queued at request of ctminh@node2.supernodexp.hpc, owner = ctminh@node2.supernodexp.hpc, job name = jacobi, queue = workq
02/14/2018 04:09:53;0100;Server@node2;Req;;Type 11 request received from Scheduler@node2.supernodexp.hpc, sock=20
02/14/2018 04:09:53;0008;Server@node2;Job;1029.node2.supernodexp.hpc;Job Modified at request of Scheduler@node2.supernodexp.hpc
02/14/2018 04:09:53;0040;Server@node2;Svr;node2.supernodexp.hpc;Scheduler sent command 1
02/14/2018 04:09:53;0040;Server@node2;Svr;node2.supernodexp.hpc;Scheduler sent command 0
02/14/2018 04:09:53;0100;Server@node2;Req;;Type 21 request received from Scheduler@node2.supernodexp.hpc, sock=20
02/14/2018 04:09:53;0100;Server@node2;Req;;Type 81 request received from Scheduler@node2.supernodexp.hpc, sock=20
02/14/2018 04:09:53;0100;Server@node2;Req;;Type 71 request received from Scheduler@node2.supernodexp.hpc, sock=20
02/14/2018 04:09:53;0100;Server@node2;Req;;Type 58 request received from Scheduler@node2.supernodexp.hpc, sock=20
02/14/2018 04:09:53;0100;Server@node2;Req;;Type 1 request received from ctminh@node2.supernodexp.hpc, sock=16
02/14/2018 04:09:53;0100;Server@node2;Req;;Type 3 request received from ctminh@node2.supernodexp.hpc, sock=16
02/14/2018 04:09:53;0100;Server@node2;Req;;Type 5 request received from ctminh@node2.supernodexp.hpc, sock=16
02/14/2018 04:09:53;0100;Server@node2;Job;1032.node2.supernodexp.hpc;enqueuing into workq, state 1 hop 1
02/14/2018 04:09:53;0008;Server@node2;Job;1032.node2.supernodexp.hpc;Job Queued at request of ctminh@node2.supernodexp.hpc, owner = ctminh@node2.supernodexp.hpc, job name = thread-affinity, queue = workq
02/14/2018 04:09:53;0100;Server@node2;Req;;Type 1 request received from ctminh@node2.supernodexp.hpc, sock=16
02/14/2018 04:09:53;0100;Server@node2;Req;;Type 3 request received from ctminh@node2.supernodexp.hpc, sock=16
02/14/2018 04:09:53;0100;Server@node2;Req;;Type 5 request received from ctminh@node2.supernodexp.hpc, sock=16
02/14/2018 04:09:53;0100;Server@node2;Job;1033.node2.supernodexp.hpc;enqueuing into workq, state 1 hop 1
02/14/2018 04:09:53;0008;Server@node2;Job;1033.node2.supernodexp.hpc;Job Queued at request of ctminh@node2.supernodexp.hpc, owner = ctminh@node2.supernodexp.hpc, job name = telemac2, queue = workq
02/14/2018 04:09:53;0100;Server@node2;Req;;Type 1 request received from ctminh@node2.supernodexp.hpc, sock=16
02/14/2018 04:09:53;0100;Server@node2;Req;;Type 20 request received from Scheduler@node2.supernodexp.hpc, sock=20
02/14/2018 04:09:53;0100;Server@node2;Req;;Type 3 request received from ctminh@node2.supernodexp.hpc, sock=16
02/14/2018 04:09:53;0100;Server@node2;Req;;Type 51 request received from Scheduler@node2.supernodexp.hpc, sock=20
02/14/2018 04:09:53;0100;Server@node2;Req;;Type 5 request received from ctminh@node2.supernodexp.hpc, sock=16
02/14/2018 04:09:53;0100;Server@node2;Job;1034.node2.supernodexp.hpc;enqueuing into workq, state 1 hop 1
02/14/2018 04:09:53;0008;Server@node2;Job;1034.node2.supernodexp.hpc;Job Queued at request of ctminh@node2.supernodexp.hpc, owner = ctminh@node2.supernodexp.hpc, job name = jacobi, queue = workq
02/14/2018 04:09:53;0100;Server@node2;Req;;Type 1 request received from ctminh@node2.supernodexp.hpc, sock=16
02/14/2018 04:09:53;0100;Server@node2;Req;;Type 3 request received from ctminh@node2.supernodexp.hpc, sock=16
02/14/2018 04:09:53;0100;Server@node2;Req;;Type 5 request received from ctminh@node2.supernodexp.hpc, sock=16
02/14/2018 04:09:53;0100;Server@node2;Job;1035.node2.supernodexp.hpc;enqueuing into workq, state 1 hop 1
02/14/2018 04:09:53;0008;Server@node2;Job;1035.node2.supernodexp.hpc;Job Queued at request of ctminh@node2.supernodexp.hpc, owner = ctminh@node2.supernodexp.hpc, job name = matrix-x-vector, queue = workq
02/14/2018 04:09:53;0100;Server@node2;Req;;Type 1 request received from ctminh@node2.supernodexp.hpc, sock=16
02/14/2018 04:09:53;0100;Server@node2;Req;;Type 3 request received from ctminh@node2.supernodexp.hpc, sock=16
02/14/2018 04:09:53;0100;Server@node2;Req;;Type 5 request received from ctminh@node2.supernodexp.hpc, sock=16
02/14/2018 04:09:53;0100;Server@node2;Job;1036.node2.supernodexp.hpc;enqueuing into workq, state 1 hop 1
02/14/2018 04:09:53;0008;Server@node2;Job;1036.node2.supernodexp.hpc;Job Queued at request of ctminh@node2.supernodexp.hpc, owner = ctminh@node2.supernodexp.hpc, job name = matrix-x-vector, queue = workq
02/14/2018 04:09:53;0100;Server@node2;Req;;Type 1 request received from ctminh@node2.supernodexp.hpc, sock=16
02/14/2018 04:09:53;0100;Server@node2;Req;;Type 11 request received from Scheduler@node2.supernodexp.hpc, sock=20
02/14/2018 04:09:53;0008;Server@node2;Job;1033.node2.supernodexp.hpc;Job Modified at request of Scheduler@node2.supernodexp.hpc
02/14/2018 04:09:53;0100;Server@node2;Req;;Type 3 request received from ctminh@node2.supernodexp.hpc, sock=16
02/14/2018 04:09:53;0100;Server@node2;Req;;Type 5 request received from ctminh@node2.supernodexp.hpc, sock=16
02/14/2018 04:09:53;0100;Server@node2;Job;1037.node2.supernodexp.hpc;enqueuing into workq, state 1 hop 1
02/14/2018 04:09:53;0008;Server@node2;Job;1037.node2.supernodexp.hpc;Job Queued at request of ctminh@node2.supernodexp.hpc, owner = ctminh@node2.supernodexp.hpc, job name = qe_mic_test, queue = workq
02/14/2018 04:09:53;0100;Server@node2;Req;;Type 11 request received from Scheduler@node2.supernodexp.hpc, sock=20
02/14/2018 04:09:53;0008;Server@node2;Job;1030.node2.supernodexp.hpc;Job Modified at request of Scheduler@node2.supernodexp.hpc
02/14/2018 04:09:53;0100;Server@node2;Req;;Type 11 request received from Scheduler@node2.supernodexp.hpc, sock=20
02/14/2018 04:09:53;0008;Server@node2;Job;1031.node2.supernodexp.hpc;Job Modified at request of Scheduler@node2.supernodexp.hpc
02/14/2018 04:09:53;0100;Server@node2;Req;;Type 11 request received from Scheduler@node2.supernodexp.hpc, sock=20
02/14/2018 04:09:53;0008;Server@node2;Job;1032.node2.supernodexp.hpc;Job Modified at request of Scheduler@node2.supernodexp.hpc
02/14/2018 04:09:53;0040;Server@node2;Svr;node2.supernodexp.hpc;Scheduler sent command 1
02/14/2018 04:09:53;0040;Server@node2;Svr;node2.supernodexp.hpc;Scheduler sent command 0
02/14/2018 04:09:53;0100;Server@node2;Req;;Type 21 request received from Scheduler@node2.supernodexp.hpc, sock=20
02/14/2018 04:09:53;0100;Server@node2;Req;;Type 81 request received from Scheduler@node2.supernodexp.hpc, sock=20
02/14/2018 04:09:53;0100;Server@node2;Req;;Type 71 request received from Scheduler@node2.supernodexp.hpc, sock=20
02/14/2018 04:09:53;0100;Server@node2;Req;;Type 58 request received from Scheduler@node2.supernodexp.hpc, sock=20
02/14/2018 04:09:53;0100;Server@node2;Req;;Type 1 request received from ctminh@node2.supernodexp.hpc, sock=16
02/14/2018 04:09:53;0100;Server@node2;Req;;Type 3 request received from ctminh@node2.supernodexp.hpc, sock=16
02/14/2018 04:09:53;0100;Server@node2;Req;;Type 5 request received from ctminh@node2.supernodexp.hpc, sock=16
02/14/2018 04:09:53;0100;Server@node2;Job;1038.node2.supernodexp.hpc;enqueuing into workq, state 1 hop 1
02/14/2018 04:09:53;0008;Server@node2;Job;1038.node2.supernodexp.hpc;Job Queued at request of ctminh@node2.supernodexp.hpc, owner = ctminh@node2.supernodexp.hpc, job name = vast1, queue = workq
02/14/2018 04:09:53;0100;Server@node2;Req;;Type 1 request received from ctminh@node2.supernodexp.hpc, sock=16
02/14/2018 04:09:53;0100;Server@node2;Req;;Type 3 request received from ctminh@node2.supernodexp.hpc, sock=16
02/14/2018 04:09:53;0100;Server@node2;Req;;Type 5 request received from ctminh@node2.supernodexp.hpc, sock=16
02/14/2018 04:09:53;0100;Server@node2;Job;1039.node2.supernodexp.hpc;enqueuing into workq, state 1 hop 1
02/14/2018 04:09:53;0008;Server@node2;Job;1039.node2.supernodexp.hpc;Job Queued at request of ctminh@node2.supernodexp.hpc, owner = ctminh@node2.supernodexp.hpc, job name = telemac1, queue = workq
02/14/2018 04:09:53;0100;Server@node2;Req;;Type 1 request received from ctminh@node2.supernodexp.hpc, sock=16
02/14/2018 04:09:53;0100;Server@node2;Req;;Type 20 request received from Scheduler@node2.supernodexp.hpc, sock=20
02/14/2018 04:09:53;0100;Server@node2;Req;;Type 3 request received from ctminh@node2.supernodexp.hpc, sock=16
02/14/2018 04:09:53;0100;Server@node2;Req;;Type 51 request received from Scheduler@node2.supernodexp.hpc, sock=20
02/14/2018 04:09:53;0100;Server@node2;Req;;Type 5 request received from ctminh@node2.supernodexp.hpc, sock=16
02/14/2018 04:09:53;0100;Server@node2;Job;1040.node2.supernodexp.hpc;enqueuing into workq, state 1 hop 1
02/14/2018 04:09:53;0008;Server@node2;Job;1040.node2.supernodexp.hpc;Job Queued at request of ctminh@node2.supernodexp.hpc, owner = ctminh@node2.supernodexp.hpc, job name = vast1, queue = workq
02/14/2018 04:09:53;0100;Server@node2;Req;;Type 1 request received from ctminh@node2.supernodexp.hpc, sock=16
02/14/2018 04:09:53;0100;Server@node2;Req;;Type 3 request received from ctminh@node2.supernodexp.hpc, sock=16
02/14/2018 04:09:53;0100;Server@node2;Req;;Type 5 request received from ctminh@node2.supernodexp.hpc, sock=16
02/14/2018 04:09:53;0100;Server@node2;Job;1041.node2.supernodexp.hpc;enqueuing into workq, state 1 hop 1
02/14/2018 04:09:53;0008;Server@node2;Job;1041.node2.supernodexp.hpc;Job Queued at request of ctminh@node2.supernodexp.hpc, owner = ctminh@node2.supernodexp.hpc, job name = sweep, queue = workq
02/14/2018 04:09:53;0100;Server@node2;Req;;Type 1 request received from ctminh@node2.supernodexp.hpc, sock=16
02/14/2018 04:09:53;0100;Server@node2;Req;;Type 3 request received from ctminh@node2.supernodexp.hpc, sock=16
02/14/2018 04:09:53;0100;Server@node2;Req;;Type 5 request received from ctminh@node2.supernodexp.hpc, sock=16
02/14/2018 04:09:53;0100;Server@node2;Job;1042.node2.supernodexp.hpc;enqueuing into workq, state 1 hop 1
02/14/2018 04:09:53;0008;Server@node2;Job;1042.node2.supernodexp.hpc;Job Queued at request of ctminh@node2.supernodexp.hpc, owner = ctminh@node2.supernodexp.hpc, job name = telemac2, queue = workq
02/14/2018 04:09:53;0100;Server@node2;Req;;Type 1 request received from ctminh@node2.supernodexp.hpc, sock=16
02/14/2018 04:09:53;0100;Server@node2;Req;;Type 11 request received from Scheduler@node2.supernodexp.hpc, sock=20
02/14/2018 04:09:53;0008;Server@node2;Job;1037.node2.supernodexp.hpc;Job Modified at request of Scheduler@node2.supernodexp.hpc
02/14/2018 04:09:53;0100;Server@node2;Req;;Type 3 request received from ctminh@node2.supernodexp.hpc, sock=16
02/14/2018 04:09:53;0100;Server@node2;Req;;Type 5 request received from ctminh@node2.supernodexp.hpc, sock=16
02/14/2018 04:09:53;0100;Server@node2;Job;1043.node2.supernodexp.hpc;enqueuing into workq, state 1 hop 1
02/14/2018 04:09:53;0008;Server@node2;Job;1043.node2.supernodexp.hpc;Job Queued at request of ctminh@node2.supernodexp.hpc, owner = ctminh@node2.supernodexp.hpc, job name = thread-affinity, queue = workq
02/14/2018 04:09:53;0100;Server@node2;Req;;Type 11 request received from Scheduler@node2.supernodexp.hpc, sock=20
02/14/2018 04:09:53;0008;Server@node2;Job;1038.node2.supernodexp.hpc;Job Modified at request of Scheduler@node2.supernodexp.hpc
02/14/2018 04:09:53;0100;Server@node2;Req;;Type 11 request received from Scheduler@node2.supernodexp.hpc, sock=20
02/14/2018 04:09:53;0008;Server@node2;Job;1039.node2.supernodexp.hpc;Job Modified at request of Scheduler@node2.supernodexp.hpc
02/14/2018 04:09:53;0100;Server@node2;Req;;Type 11 request received from Scheduler@node2.supernodexp.hpc, sock=20
02/14/2018 04:09:53;0008;Server@node2;Job;1034.node2.supernodexp.hpc;Job Modified at request of Scheduler@node2.supernodexp.hpc
02/14/2018 04:09:53;0100;Server@node2;Req;;Type 11 request received from Scheduler@node2.supernodexp.hpc, sock=20
02/14/2018 04:09:53;0008;Server@node2;Job;1035.node2.supernodexp.hpc;Job Modified at request of Scheduler@node2.supernodexp.hpc
02/14/2018 04:09:53;0100;Server@node2;Req;;Type 11 request received from Scheduler@node2.supernodexp.hpc, sock=20
02/14/2018 04:09:53;0008;Server@node2;Job;1036.node2.supernodexp.hpc;Job Modified at request of Scheduler@node2.supernodexp.hpc
02/14/2018 04:09:53;0040;Server@node2;Svr;node2.supernodexp.hpc;Scheduler sent command 1
02/14/2018 04:09:53;0040;Server@node2;Svr;node2.supernodexp.hpc;Scheduler sent command 0
02/14/2018 04:09:53;0100;Server@node2;Req;;Type 21 request received from Scheduler@node2.supernodexp.hpc, sock=20
02/14/2018 04:09:53;0100;Server@node2;Req;;Type 81 request received from Scheduler@node2.supernodexp.hpc, sock=20
02/14/2018 04:09:53;0100;Server@node2;Req;;Type 71 request received from Scheduler@node2.supernodexp.hpc, sock=20
02/14/2018 04:09:53;0100;Server@node2;Req;;Type 58 request received from Scheduler@node2.supernodexp.hpc, sock=20
02/14/2018 04:09:53;0100;Server@node2;Req;;Type 1 request received from ctminh@node2.supernodexp.hpc, sock=16
02/14/2018 04:09:53;0100;Server@node2;Req;;Type 3 request received from ctminh@node2.supernodexp.hpc, sock=16
02/14/2018 04:09:53;0100;Server@node2;Req;;Type 5 request received from ctminh@node2.supernodexp.hpc, sock=16
02/14/2018 04:09:53;0100;Server@node2;Job;1044.node2.supernodexp.hpc;enqueuing into workq, state 1 hop 1
02/14/2018 04:09:53;0008;Server@node2;Job;1044.node2.supernodexp.hpc;Job Queued at request of ctminh@node2.supernodexp.hpc, owner = ctminh@node2.supernodexp.hpc, job name = jacobi, queue = workq
02/14/2018 04:09:53;0100;Server@node2;Req;;Type 20 request received from Scheduler@node2.supernodexp.hpc, sock=20
02/14/2018 04:09:53;0100;Server@node2;Req;;Type 51 request received from Scheduler@node2.supernodexp.hpc, sock=20
02/14/2018 04:09:53;0100;Server@node2;Req;;Type 11 request received from Scheduler@node2.supernodexp.hpc, sock=20
02/14/2018 04:09:53;0008;Server@node2;Job;1040.node2.supernodexp.hpc;Job Modified at request of Scheduler@node2.supernodexp.hpc
02/14/2018 04:09:53;0100;Server@node2;Req;;Type 11 request received from Scheduler@node2.supernodexp.hpc, sock=20
02/14/2018 04:09:53;0008;Server@node2;Job;1042.node2.supernodexp.hpc;Job Modified at request of Scheduler@node2.supernodexp.hpc
02/14/2018 04:09:53;0100;Server@node2;Req;;Type 11 request received from Scheduler@node2.supernodexp.hpc, sock=20
02/14/2018 04:09:53;0008;Server@node2;Job;1044.node2.supernodexp.hpc;Job Modified at request of Scheduler@node2.supernodexp.hpc
02/14/2018 04:09:53;0100;Server@node2;Req;;Type 11 request received from Scheduler@node2.supernodexp.hpc, sock=20
02/14/2018 04:09:53;0008;Server@node2;Job;1043.node2.supernodexp.hpc;Job Modified at request of Scheduler@node2.supernodexp.hpc
02/14/2018 04:09:53;0100;Server@node2;Req;;Type 11 request received from Scheduler@node2.supernodexp.hpc, sock=20
02/14/2018 04:09:53;0008;Server@node2;Job;1041.node2.supernodexp.hpc;Job Modified at request of Scheduler@node2.supernodexp.hpc
02/14/2018 04:09:53;0040;Server@node2;Svr;node2.supernodexp.hpc;Scheduler sent command 1
02/14/2018 04:09:53;0040;Server@node2;Svr;node2.supernodexp.hpc;Scheduler sent command 0
02/14/2018 04:09:53;0100;Server@node2;Req;;Type 21 request received from Scheduler@node2.supernodexp.hpc, sock=20
02/14/2018 04:09:53;0100;Server@node2;Req;;Type 81 request received from Scheduler@node2.supernodexp.hpc, sock=20
02/14/2018 04:09:53;0100;Server@node2;Req;;Type 71 request received from Scheduler@node2.supernodexp.hpc, sock=20
02/14/2018 04:09:53;0100;Server@node2;Req;;Type 58 request received from Scheduler@node2.supernodexp.hpc, sock=20
02/14/2018 04:09:53;0100;Server@node2;Req;;Type 20 request received from Scheduler@node2.supernodexp.hpc, sock=20
02/14/2018 04:09:53;0100;Server@node2;Req;;Type 51 request received from Scheduler@node2.supernodexp.hpc, sock=20
02/14/2018 04:10:40;0100;Server@node2;Req;;Type 0 request received from root@node2.supernodexp.hpc, sock=20
02/14/2018 04:10:40;0100;Server@node2;Req;;Type 49 request received from root@node2.supernodexp.hpc, sock=21
02/14/2018 04:10:40;0100;Server@node2;Req;;Type 21 request received from root@node2.supernodexp.hpc, sock=20
02/14/2018 04:10:40;0100;Server@node2;Req;;Type 19 request received from root@node2.supernodexp.hpc, sock=20
02/14/2018 04:10:41;0100;Server@node2;Req;;Type 1 request received from ctminh@node2.supernodexp.hpc, sock=16
02/14/2018 04:10:41;0100;Server@node2;Req;;Type 3 request received from ctminh@node2.supernodexp.hpc, sock=16
02/14/2018 04:10:41;0100;Server@node2;Req;;Type 5 request received from ctminh@node2.supernodexp.hpc, sock=16
02/14/2018 04:10:41;0100;Server@node2;Job;1045.node2.supernodexp.hpc;enqueuing into workq, state 1 hop 1
02/14/2018 04:10:41;0008;Server@node2;Job;1045.node2.supernodexp.hpc;Job Queued at request of ctminh@node2.supernodexp.hpc, owner = ctminh@node2.supernodexp.hpc, job name = jacobi, queue = workq
02/14/2018 04:10:41;0040;Server@node2;Svr;node2.supernodexp.hpc;Scheduler sent command 1
02/14/2018 04:10:41;0040;Server@node2;Svr;node2.supernodexp.hpc;Scheduler sent command 0
02/14/2018 04:10:41;0100;Server@node2;Req;;Type 21 request received from Scheduler@node2.supernodexp.hpc, sock=20
02/14/2018 04:10:41;0100;Server@node2;Req;;Type 81 request received from Scheduler@node2.supernodexp.hpc, sock=20
02/14/2018 04:10:41;0100;Server@node2;Req;;Type 71 request received from Scheduler@node2.supernodexp.hpc, sock=20
02/14/2018 04:10:41;0100;Server@node2;Req;;Type 58 request received from Scheduler@node2.supernodexp.hpc, sock=20
02/14/2018 04:10:41;0100;Server@node2;Req;;Type 1 request received from ctminh@node2.supernodexp.hpc, sock=16
02/14/2018 04:10:41;0100;Server@node2;Req;;Type 3 request received from ctminh@node2.supernodexp.hpc, sock=16
02/14/2018 04:10:41;0100;Server@node2;Req;;Type 5 request received from ctminh@node2.supernodexp.hpc, sock=16
02/14/2018 04:10:41;0100;Server@node2;Job;1046.node2.supernodexp.hpc;enqueuing into workq, state 1 hop 1
02/14/2018 04:10:41;0008;Server@node2;Job;1046.node2.supernodexp.hpc;Job Queued at request of ctminh@node2.supernodexp.hpc, owner = ctminh@node2.supernodexp.hpc, job name = thread-affinity, queue = workq
02/14/2018 04:10:41;0100;Server@node2;Req;;Type 1 request received from ctminh@node2.supernodexp.hpc, sock=16
02/14/2018 04:10:41;0100;Server@node2;Req;;Type 20 request received from Scheduler@node2.supernodexp.hpc, sock=20
02/14/2018 04:10:41;0100;Server@node2;Req;;Type 3 request received from ctminh@node2.supernodexp.hpc, sock=16
02/14/2018 04:10:41;0100;Server@node2;Req;;Type 51 request received from Scheduler@node2.supernodexp.hpc, sock=20
02/14/2018 04:10:41;0100;Server@node2;Req;;Type 5 request received from ctminh@node2.supernodexp.hpc, sock=16
02/14/2018 04:10:41;0100;Server@node2;Job;1047.node2.supernodexp.hpc;enqueuing into workq, state 1 hop 1
02/14/2018 04:10:41;0008;Server@node2;Job;1047.node2.supernodexp.hpc;Job Queued at request of ctminh@node2.supernodexp.hpc, owner = ctminh@node2.supernodexp.hpc, job name = nbody, queue = workq
02/14/2018 04:10:41;0100;Server@node2;Req;;Type 1 request received from ctminh@node2.supernodexp.hpc, sock=16
02/14/2018 04:10:41;0100;Server@node2;Req;;Type 3 request received from ctminh@node2.supernodexp.hpc, sock=16
02/14/2018 04:10:41;0100;Server@node2;Req;;Type 5 request received from ctminh@node2.supernodexp.hpc, sock=16
02/14/2018 04:10:41;0100;Server@node2;Job;1048.node2.supernodexp.hpc;enqueuing into workq, state 1 hop 1
02/14/2018 04:10:41;0008;Server@node2;Job;1048.node2.supernodexp.hpc;Job Queued at request of ctminh@node2.supernodexp.hpc, owner = ctminh@node2.supernodexp.hpc, job name = sweep, queue = workq
02/14/2018 04:10:41;0100;Server@node2;Req;;Type 1 request received from ctminh@node2.supernodexp.hpc, sock=16
02/14/2018 04:10:41;0100;Server@node2;Req;;Type 3 request received from ctminh@node2.supernodexp.hpc, sock=16
02/14/2018 04:10:41;0100;Server@node2;Req;;Type 5 request received from ctminh@node2.supernodexp.hpc, sock=16
02/14/2018 04:10:41;0100;Server@node2;Job;1049.node2.supernodexp.hpc;enqueuing into workq, state 1 hop 1
02/14/2018 04:10:41;0008;Server@node2;Job;1049.node2.supernodexp.hpc;Job Queued at request of ctminh@node2.supernodexp.hpc, owner = ctminh@node2.supernodexp.hpc, job name = telemac1, queue = workq
02/14/2018 04:10:42;0100;Server@node2;Req;;Type 1 request received from ctminh@node2.supernodexp.hpc, sock=16
02/14/2018 04:10:42;0100;Server@node2;Req;;Type 11 request received from Scheduler@node2.supernodexp.hpc, sock=20
02/14/2018 04:10:42;0008;Server@node2;Job;1045.node2.supernodexp.hpc;Job Modified at request of Scheduler@node2.supernodexp.hpc
02/14/2018 04:10:42;0100;Server@node2;Req;;Type 3 request received from ctminh@node2.supernodexp.hpc, sock=16
02/14/2018 04:10:42;0100;Server@node2;Req;;Type 5 request received from ctminh@node2.supernodexp.hpc, sock=16
02/14/2018 04:10:42;0100;Server@node2;Job;1050.node2.supernodexp.hpc;enqueuing into workq, state 1 hop 1
02/14/2018 04:10:42;0008;Server@node2;Job;1050.node2.supernodexp.hpc;Job Queued at request of ctminh@node2.supernodexp.hpc, owner = ctminh@node2.supernodexp.hpc, job name = sweep, queue = workq
02/14/2018 04:10:42;0100;Server@node2;Req;;Type 11 request received from Scheduler@node2.supernodexp.hpc, sock=20
02/14/2018 04:10:42;0008;Server@node2;Job;1046.node2.supernodexp.hpc;Job Modified at request of Scheduler@node2.supernodexp.hpc
02/14/2018 04:10:42;0040;Server@node2;Svr;node2.supernodexp.hpc;Scheduler sent command 1
02/14/2018 04:10:42;0040;Server@node2;Svr;node2.supernodexp.hpc;Scheduler sent command 0
02/14/2018 04:10:42;0100;Server@node2;Req;;Type 21 request received from Scheduler@node2.supernodexp.hpc, sock=20
02/14/2018 04:10:42;0100;Server@node2;Req;;Type 81 request received from Scheduler@node2.supernodexp.hpc, sock=20
02/14/2018 04:10:42;0100;Server@node2;Req;;Type 71 request received from Scheduler@node2.supernodexp.hpc, sock=20
02/14/2018 04:10:42;0100;Server@node2;Req;;Type 58 request received from Scheduler@node2.supernodexp.hpc, sock=20
02/14/2018 04:10:42;0100;Server@node2;Req;;Type 1 request received from ctminh@node2.supernodexp.hpc, sock=16
02/14/2018 04:10:42;0100;Server@node2;Req;;Type 3 request received from ctminh@node2.supernodexp.hpc, sock=16
02/14/2018 04:10:42;0100;Server@node2;Req;;Type 5 request received from ctminh@node2.supernodexp.hpc, sock=16
02/14/2018 04:10:42;0100;Server@node2;Job;1051.node2.supernodexp.hpc;enqueuing into workq, state 1 hop 1
02/14/2018 04:10:42;0008;Server@node2;Job;1051.node2.supernodexp.hpc;Job Queued at request of ctminh@node2.supernodexp.hpc, owner = ctminh@node2.supernodexp.hpc, job name = lu-decomp, queue = workq
02/14/2018 04:10:42;0100;Server@node2;Req;;Type 20 request received from Scheduler@node2.supernodexp.hpc, sock=20
02/14/2018 04:10:42;0100;Server@node2;Req;;Type 51 request received from Scheduler@node2.supernodexp.hpc, sock=20
02/14/2018 04:10:42;0100;Server@node2;Req;;Type 1 request received from ctminh@node2.supernodexp.hpc, sock=16
02/14/2018 04:10:42;0100;Server@node2;Req;;Type 3 request received from ctminh@node2.supernodexp.hpc, sock=16
02/14/2018 04:10:42;0100;Server@node2;Req;;Type 5 request received from ctminh@node2.supernodexp.hpc, sock=16
02/14/2018 04:10:42;0100;Server@node2;Job;1052.node2.supernodexp.hpc;enqueuing into workq, state 1 hop 1
02/14/2018 04:10:42;0008;Server@node2;Job;1052.node2.supernodexp.hpc;Job Queued at request of ctminh@node2.supernodexp.hpc, owner = ctminh@node2.supernodexp.hpc, job name = matrix-x-vector, queue = workq
02/14/2018 04:10:42;0100;Server@node2;Req;;Type 1 request received from ctminh@node2.supernodexp.hpc, sock=16
02/14/2018 04:10:42;0100;Server@node2;Req;;Type 3 request received from ctminh@node2.supernodexp.hpc, sock=16
02/14/2018 04:10:42;0100;Server@node2;Req;;Type 5 request received from ctminh@node2.supernodexp.hpc, sock=16
02/14/2018 04:10:42;0100;Server@node2;Job;1053.node2.supernodexp.hpc;enqueuing into workq, state 1 hop 1
02/14/2018 04:10:42;0008;Server@node2;Job;1053.node2.supernodexp.hpc;Job Queued at request of ctminh@node2.supernodexp.hpc, owner = ctminh@node2.supernodexp.hpc, job name = vectorization, queue = workq
02/14/2018 04:10:42;0100;Server@node2;Req;;Type 1 request received from ctminh@node2.supernodexp.hpc, sock=16
02/14/2018 04:10:42;0100;Server@node2;Req;;Type 3 request received from ctminh@node2.supernodexp.hpc, sock=16
02/14/2018 04:10:42;0100;Server@node2;Req;;Type 5 request received from ctminh@node2.supernodexp.hpc, sock=16
02/14/2018 04:10:42;0100;Server@node2;Job;1054.node2.supernodexp.hpc;enqueuing into workq, state 1 hop 1
02/14/2018 04:10:42;0008;Server@node2;Job;1054.node2.supernodexp.hpc;Job Queued at request of ctminh@node2.supernodexp.hpc, owner = ctminh@node2.supernodexp.hpc, job name = jacobi, queue = workq
02/14/2018 04:10:42;0100;Server@node2;Req;;Type 11 request received from Scheduler@node2.supernodexp.hpc, sock=20
02/14/2018 04:10:42;0008;Server@node2;Job;1049.node2.supernodexp.hpc;Job Modified at request of Scheduler@node2.supernodexp.hpc
02/14/2018 04:10:42;0100;Server@node2;Req;;Type 11 request received from Scheduler@node2.supernodexp.hpc, sock=20
02/14/2018 04:10:42;0008;Server@node2;Job;1047.node2.supernodexp.hpc;Job Modified at request of Scheduler@node2.supernodexp.hpc
02/14/2018 04:10:42;0100;Server@node2;Req;;Type 11 request received from Scheduler@node2.supernodexp.hpc, sock=20
02/14/2018 04:10:42;0008;Server@node2;Job;1048.node2.supernodexp.hpc;Job Modified at request of Scheduler@node2.supernodexp.hpc
02/14/2018 04:10:42;0100;Server@node2;Req;;Type 1 request received from ctminh@node2.supernodexp.hpc, sock=16
02/14/2018 04:10:42;0100;Server@node2;Req;;Type 11 request received from Scheduler@node2.supernodexp.hpc, sock=20
02/14/2018 04:10:42;0008;Server@node2;Job;1050.node2.supernodexp.hpc;Job Modified at request of Scheduler@node2.supernodexp.hpc
02/14/2018 04:10:42;0100;Server@node2;Req;;Type 3 request received from ctminh@node2.supernodexp.hpc, sock=16
02/14/2018 04:10:42;0100;Server@node2;Req;;Type 5 request received from ctminh@node2.supernodexp.hpc, sock=16
02/14/2018 04:10:42;0100;Server@node2;Job;1055.node2.supernodexp.hpc;enqueuing into workq, state 1 hop 1
02/14/2018 04:10:42;0008;Server@node2;Job;1055.node2.supernodexp.hpc;Job Queued at request of ctminh@node2.supernodexp.hpc, owner = ctminh@node2.supernodexp.hpc, job name = thread-affinity, queue = workq
02/14/2018 04:10:42;0100;Server@node2;Req;;Type 11 request received from Scheduler@node2.supernodexp.hpc, sock=20
02/14/2018 04:10:42;0008;Server@node2;Job;1051.node2.supernodexp.hpc;Job Modified at request of Scheduler@node2.supernodexp.hpc
02/14/2018 04:10:42;0040;Server@node2;Svr;node2.supernodexp.hpc;Scheduler sent command 1
02/14/2018 04:10:42;0040;Server@node2;Svr;node2.supernodexp.hpc;Scheduler sent command 0
02/14/2018 04:10:42;0100;Server@node2;Req;;Type 21 request received from Scheduler@node2.supernodexp.hpc, sock=20
02/14/2018 04:10:42;0100;Server@node2;Req;;Type 81 request received from Scheduler@node2.supernodexp.hpc, sock=20
02/14/2018 04:10:42;0100;Server@node2;Req;;Type 71 request received from Scheduler@node2.supernodexp.hpc, sock=20
02/14/2018 04:10:42;0100;Server@node2;Req;;Type 58 request received from Scheduler@node2.supernodexp.hpc, sock=20
02/14/2018 04:10:42;0100;Server@node2;Req;;Type 1 request received from ctminh@node2.supernodexp.hpc, sock=16
02/14/2018 04:10:42;0100;Server@node2;Req;;Type 3 request received from ctminh@node2.supernodexp.hpc, sock=16
02/14/2018 04:10:42;0100;Server@node2;Req;;Type 5 request received from ctminh@node2.supernodexp.hpc, sock=16
02/14/2018 04:10:42;0100;Server@node2;Job;1056.node2.supernodexp.hpc;enqueuing into workq, state 1 hop 1
02/14/2018 04:10:42;0008;Server@node2;Job;1056.node2.supernodexp.hpc;Job Queued at request of ctminh@node2.supernodexp.hpc, owner = ctminh@node2.supernodexp.hpc, job name = qe_mic_test, queue = workq
02/14/2018 04:10:42;0100;Server@node2;Req;;Type 1 request received from ctminh@node2.supernodexp.hpc, sock=16
02/14/2018 04:10:42;0100;Server@node2;Req;;Type 3 request received from ctminh@node2.supernodexp.hpc, sock=16
02/14/2018 04:10:42;0100;Server@node2;Req;;Type 5 request received from ctminh@node2.supernodexp.hpc, sock=16
02/14/2018 04:10:42;0100;Server@node2;Job;1057.node2.supernodexp.hpc;enqueuing into workq, state 1 hop 1
02/14/2018 04:10:42;0008;Server@node2;Job;1057.node2.supernodexp.hpc;Job Queued at request of ctminh@node2.supernodexp.hpc, owner = ctminh@node2.supernodexp.hpc, job name = matrix-x-vector, queue = workq
02/14/2018 04:10:42;0100;Server@node2;Req;;Type 1 request received from ctminh@node2.supernodexp.hpc, sock=16
02/14/2018 04:10:42;0100;Server@node2;Req;;Type 20 request received from Scheduler@node2.supernodexp.hpc, sock=20
02/14/2018 04:10:42;0100;Server@node2;Req;;Type 3 request received from ctminh@node2.supernodexp.hpc, sock=16
02/14/2018 04:10:42;0100;Server@node2;Req;;Type 51 request received from Scheduler@node2.supernodexp.hpc, sock=20
02/14/2018 04:10:42;0100;Server@node2;Req;;Type 5 request received from ctminh@node2.supernodexp.hpc, sock=16
02/14/2018 04:10:42;0100;Server@node2;Job;1058.node2.supernodexp.hpc;enqueuing into workq, state 1 hop 1
02/14/2018 04:10:42;0008;Server@node2;Job;1058.node2.supernodexp.hpc;Job Queued at request of ctminh@node2.supernodexp.hpc, owner = ctminh@node2.supernodexp.hpc, job name = telemac3, queue = workq
02/14/2018 04:10:42;0100;Server@node2;Req;;Type 1 request received from ctminh@node2.supernodexp.hpc, sock=16
02/14/2018 04:10:42;0100;Server@node2;Req;;Type 3 request received from ctminh@node2.supernodexp.hpc, sock=16
02/14/2018 04:10:42;0100;Server@node2;Req;;Type 5 request received from ctminh@node2.supernodexp.hpc, sock=16
02/14/2018 04:10:42;0100;Server@node2;Job;1059.node2.supernodexp.hpc;enqueuing into workq, state 1 hop 1
02/14/2018 04:10:42;0008;Server@node2;Job;1059.node2.supernodexp.hpc;Job Queued at request of ctminh@node2.supernodexp.hpc, owner = ctminh@node2.supernodexp.hpc, job name = thread-affinity, queue = workq
02/14/2018 04:10:42;0100;Server@node2;Req;;Type 1 request received from ctminh@node2.supernodexp.hpc, sock=16
02/14/2018 04:10:42;0100;Server@node2;Req;;Type 3 request received from ctminh@node2.supernodexp.hpc, sock=16
02/14/2018 04:10:42;0100;Server@node2;Req;;Type 5 request received from ctminh@node2.supernodexp.hpc, sock=16
02/14/2018 04:10:42;0100;Server@node2;Job;1060.node2.supernodexp.hpc;enqueuing into workq, state 1 hop 1
02/14/2018 04:10:42;0008;Server@node2;Job;1060.node2.supernodexp.hpc;Job Queued at request of ctminh@node2.supernodexp.hpc, owner = ctminh@node2.supernodexp.hpc, job name = thread-affinity, queue = workq
02/14/2018 04:10:42;0100;Server@node2;Req;;Type 1 request received from ctminh@node2.supernodexp.hpc, sock=16
02/14/2018 04:10:42;0100;Server@node2;Req;;Type 3 request received from ctminh@node2.supernodexp.hpc, sock=16
02/14/2018 04:10:42;0100;Server@node2;Req;;Type 5 request received from ctminh@node2.supernodexp.hpc, sock=16
02/14/2018 04:10:42;0100;Server@node2;Job;1061.node2.supernodexp.hpc;enqueuing into workq, state 1 hop 1
02/14/2018 04:10:42;0008;Server@node2;Job;1061.node2.supernodexp.hpc;Job Queued at request of ctminh@node2.supernodexp.hpc, owner = ctminh@node2.supernodexp.hpc, job name = nbody, queue = workq
02/14/2018 04:10:42;0100;Server@node2;Req;;Type 11 request received from Scheduler@node2.supernodexp.hpc, sock=20
02/14/2018 04:10:42;0008;Server@node2;Job;1056.node2.supernodexp.hpc;Job Modified at request of Scheduler@node2.supernodexp.hpc
02/14/2018 04:10:42;0100;Server@node2;Req;;Type 11 request received from Scheduler@node2.supernodexp.hpc, sock=20
02/14/2018 04:10:42;0008;Server@node2;Job;1054.node2.supernodexp.hpc;Job Modified at request of Scheduler@node2.supernodexp.hpc
02/14/2018 04:10:42;0100;Server@node2;Req;;Type 11 request received from Scheduler@node2.supernodexp.hpc, sock=20
02/14/2018 04:10:42;0008;Server@node2;Job;1055.node2.supernodexp.hpc;Job Modified at request of Scheduler@node2.supernodexp.hpc
02/14/2018 04:10:42;0100;Server@node2;Req;;Type 11 request received from Scheduler@node2.supernodexp.hpc, sock=20
02/14/2018 04:10:42;0008;Server@node2;Job;1053.node2.supernodexp.hpc;Job Modified at request of Scheduler@node2.supernodexp.hpc
02/14/2018 04:10:42;0100;Server@node2;Req;;Type 11 request received from Scheduler@node2.supernodexp.hpc, sock=20
02/14/2018 04:10:42;0008;Server@node2;Job;1052.node2.supernodexp.hpc;Job Modified at request of Scheduler@node2.supernodexp.hpc
02/14/2018 04:10:42;0100;Server@node2;Req;;Type 11 request received from Scheduler@node2.supernodexp.hpc, sock=20
02/14/2018 04:10:42;0008;Server@node2;Job;1057.node2.supernodexp.hpc;Job Modified at request of Scheduler@node2.supernodexp.hpc
02/14/2018 04:10:42;0040;Server@node2;Svr;node2.supernodexp.hpc;Scheduler sent command 1
02/14/2018 04:10:42;0040;Server@node2;Svr;node2.supernodexp.hpc;Scheduler sent command 0
02/14/2018 04:10:42;0100;Server@node2;Req;;Type 21 request received from Scheduler@node2.supernodexp.hpc, sock=20
02/14/2018 04:10:42;0100;Server@node2;Req;;Type 81 request received from Scheduler@node2.supernodexp.hpc, sock=20
02/14/2018 04:10:42;0100;Server@node2;Req;;Type 71 request received from Scheduler@node2.supernodexp.hpc, sock=20
02/14/2018 04:10:42;0100;Server@node2;Req;;Type 58 request received from Scheduler@node2.supernodexp.hpc, sock=20
02/14/2018 04:10:42;0100;Server@node2;Req;;Type 1 request received from ctminh@node2.supernodexp.hpc, sock=16
02/14/2018 04:10:42;0100;Server@node2;Req;;Type 3 request received from ctminh@node2.supernodexp.hpc, sock=16
02/14/2018 04:10:42;0100;Server@node2;Req;;Type 5 request received from ctminh@node2.supernodexp.hpc, sock=16
02/14/2018 04:10:42;0100;Server@node2;Job;1062.node2.supernodexp.hpc;enqueuing into workq, state 1 hop 1
02/14/2018 04:10:42;0008;Server@node2;Job;1062.node2.supernodexp.hpc;Job Queued at request of ctminh@node2.supernodexp.hpc, owner = ctminh@node2.supernodexp.hpc, job name = histogram, queue = workq
02/14/2018 04:10:42;0100;Server@node2;Req;;Type 1 request received from ctminh@node2.supernodexp.hpc, sock=16
02/14/2018 04:10:42;0100;Server@node2;Req;;Type 3 request received from ctminh@node2.supernodexp.hpc, sock=16
02/14/2018 04:10:42;0100;Server@node2;Req;;Type 5 request received from ctminh@node2.supernodexp.hpc, sock=16
02/14/2018 04:10:42;0100;Server@node2;Job;1063.node2.supernodexp.hpc;enqueuing into workq, state 1 hop 1
02/14/2018 04:10:42;0008;Server@node2;Job;1063.node2.supernodexp.hpc;Job Queued at request of ctminh@node2.supernodexp.hpc, owner = ctminh@node2.supernodexp.hpc, job name = thread-affinity, queue = workq
02/14/2018 04:10:42;0100;Server@node2;Req;;Type 20 request received from Scheduler@node2.supernodexp.hpc, sock=20
02/14/2018 04:10:42;0100;Server@node2;Req;;Type 51 request received from Scheduler@node2.supernodexp.hpc, sock=20
02/14/2018 04:10:42;0100;Server@node2;Req;;Type 1 request received from ctminh@node2.supernodexp.hpc, sock=16
02/14/2018 04:10:42;0100;Server@node2;Req;;Type 3 request received from ctminh@node2.supernodexp.hpc, sock=16
02/14/2018 04:10:42;0100;Server@node2;Req;;Type 5 request received from ctminh@node2.supernodexp.hpc, sock=16
02/14/2018 04:10:42;0100;Server@node2;Job;1064.node2.supernodexp.hpc;enqueuing into workq, state 1 hop 1
02/14/2018 04:10:42;0008;Server@node2;Job;1064.node2.supernodexp.hpc;Job Queued at request of ctminh@node2.supernodexp.hpc, owner = ctminh@node2.supernodexp.hpc, job name = telemac2, queue = workq
02/14/2018 04:10:42;0100;Server@node2;Req;;Type 1 request received from ctminh@node2.supernodexp.hpc, sock=16
02/14/2018 04:10:42;0100;Server@node2;Req;;Type 3 request received from ctminh@node2.supernodexp.hpc, sock=16
02/14/2018 04:10:42;0100;Server@node2;Req;;Type 5 request received from ctminh@node2.supernodexp.hpc, sock=16
02/14/2018 04:10:42;0100;Server@node2;Job;1065.node2.supernodexp.hpc;enqueuing into workq, state 1 hop 1
02/14/2018 04:10:42;0008;Server@node2;Job;1065.node2.supernodexp.hpc;Job Queued at request of ctminh@node2.supernodexp.hpc, owner = ctminh@node2.supernodexp.hpc, job name = matrix-x-vector, queue = workq
02/14/2018 04:10:42;0100;Server@node2;Req;;Type 1 request received from ctminh@node2.supernodexp.hpc, sock=16
02/14/2018 04:10:42;0100;Server@node2;Req;;Type 3 request received from ctminh@node2.supernodexp.hpc, sock=16
02/14/2018 04:10:42;0100;Server@node2;Req;;Type 5 request received from ctminh@node2.supernodexp.hpc, sock=16
02/14/2018 04:10:42;0100;Server@node2;Job;1066.node2.supernodexp.hpc;enqueuing into workq, state 1 hop 1
02/14/2018 04:10:42;0008;Server@node2;Job;1066.node2.supernodexp.hpc;Job Queued at request of ctminh@node2.supernodexp.hpc, owner = ctminh@node2.supernodexp.hpc, job name = nbody, queue = workq
02/14/2018 04:10:42;0100;Server@node2;Req;;Type 1 request received from ctminh@node2.supernodexp.hpc, sock=16
02/14/2018 04:10:42;0100;Server@node2;Req;;Type 11 request received from Scheduler@node2.supernodexp.hpc, sock=20
02/14/2018 04:10:42;0008;Server@node2;Job;1058.node2.supernodexp.hpc;Job Modified at request of Scheduler@node2.supernodexp.hpc
02/14/2018 04:10:42;0100;Server@node2;Req;;Type 3 request received from ctminh@node2.supernodexp.hpc, sock=16
02/14/2018 04:10:42;0100;Server@node2;Req;;Type 5 request received from ctminh@node2.supernodexp.hpc, sock=16
02/14/2018 04:10:42;0100;Server@node2;Job;1067.node2.supernodexp.hpc;enqueuing into workq, state 1 hop 1
02/14/2018 04:10:42;0008;Server@node2;Job;1067.node2.supernodexp.hpc;Job Queued at request of ctminh@node2.supernodexp.hpc, owner = ctminh@node2.supernodexp.hpc, job name = telemac3, queue = workq
02/14/2018 04:10:42;0100;Server@node2;Req;;Type 11 request received from Scheduler@node2.supernodexp.hpc, sock=20
02/14/2018 04:10:42;0008;Server@node2;Job;1059.node2.supernodexp.hpc;Job Modified at request of Scheduler@node2.supernodexp.hpc
02/14/2018 04:10:42;0100;Server@node2;Req;;Type 11 request received from Scheduler@node2.supernodexp.hpc, sock=20
02/14/2018 04:10:42;0008;Server@node2;Job;1060.node2.supernodexp.hpc;Job Modified at request of Scheduler@node2.supernodexp.hpc
02/14/2018 04:10:42;0100;Server@node2;Req;;Type 11 request received from Scheduler@node2.supernodexp.hpc, sock=20
02/14/2018 04:10:42;0008;Server@node2;Job;1063.node2.supernodexp.hpc;Job Modified at request of Scheduler@node2.supernodexp.hpc
02/14/2018 04:10:42;0100;Server@node2;Req;;Type 11 request received from Scheduler@node2.supernodexp.hpc, sock=20
02/14/2018 04:10:42;0008;Server@node2;Job;1061.node2.supernodexp.hpc;Job Modified at request of Scheduler@node2.supernodexp.hpc
02/14/2018 04:10:42;0100;Server@node2;Req;;Type 11 request received from Scheduler@node2.supernodexp.hpc, sock=20
02/14/2018 04:10:42;0008;Server@node2;Job;1062.node2.supernodexp.hpc;Job Modified at request of Scheduler@node2.supernodexp.hpc
02/14/2018 04:10:42;0040;Server@node2;Svr;node2.supernodexp.hpc;Scheduler sent command 1
02/14/2018 04:10:42;0040;Server@node2;Svr;node2.supernodexp.hpc;Scheduler sent command 0
02/14/2018 04:10:42;0100;Server@node2;Req;;Type 21 request received from Scheduler@node2.supernodexp.hpc, sock=20
02/14/2018 04:10:42;0100;Server@node2;Req;;Type 81 request received from Scheduler@node2.supernodexp.hpc, sock=20
02/14/2018 04:10:42;0100;Server@node2;Req;;Type 71 request received from Scheduler@node2.supernodexp.hpc, sock=20
02/14/2018 04:10:42;0100;Server@node2;Req;;Type 58 request received from Scheduler@node2.supernodexp.hpc, sock=20
02/14/2018 04:10:42;0100;Server@node2;Req;;Type 1 request received from ctminh@node2.supernodexp.hpc, sock=16
02/14/2018 04:10:42;0100;Server@node2;Req;;Type 3 request received from ctminh@node2.supernodexp.hpc, sock=16
02/14/2018 04:10:42;0100;Server@node2;Req;;Type 5 request received from ctminh@node2.supernodexp.hpc, sock=16
02/14/2018 04:10:42;0100;Server@node2;Job;1068.node2.supernodexp.hpc;enqueuing into workq, state 1 hop 1
02/14/2018 04:10:42;0008;Server@node2;Job;1068.node2.supernodexp.hpc;Job Queued at request of ctminh@node2.supernodexp.hpc, owner = ctminh@node2.supernodexp.hpc, job name = telemac3, queue = workq
02/14/2018 04:10:42;0100;Server@node2;Req;;Type 1 request received from ctminh@node2.supernodexp.hpc, sock=16
02/14/2018 04:10:42;0100;Server@node2;Req;;Type 3 request received from ctminh@node2.supernodexp.hpc, sock=16
02/14/2018 04:10:42;0100;Server@node2;Req;;Type 5 request received from ctminh@node2.supernodexp.hpc, sock=16
02/14/2018 04:10:42;0100;Server@node2;Job;1069.node2.supernodexp.hpc;enqueuing into workq, state 1 hop 1
02/14/2018 04:10:42;0008;Server@node2;Job;1069.node2.supernodexp.hpc;Job Queued at request of ctminh@node2.supernodexp.hpc, owner = ctminh@node2.supernodexp.hpc, job name = nbody, queue = workq
02/14/2018 04:10:42;0100;Server@node2;Req;;Type 1 request received from ctminh@node2.supernodexp.hpc, sock=16
02/14/2018 04:10:42;0100;Server@node2;Req;;Type 3 request received from ctminh@node2.supernodexp.hpc, sock=16
02/14/2018 04:10:42;0100;Server@node2;Req;;Type 5 request received from ctminh@node2.supernodexp.hpc, sock=16
02/14/2018 04:10:42;0100;Server@node2;Job;1070.node2.supernodexp.hpc;enqueuing into workq, state 1 hop 1
02/14/2018 04:10:42;0008;Server@node2;Job;1070.node2.supernodexp.hpc;Job Queued at request of ctminh@node2.supernodexp.hpc, owner = ctminh@node2.supernodexp.hpc, job name = telemac2, queue = workq
02/14/2018 04:10:42;0100;Server@node2;Req;;Type 20 request received from Scheduler@node2.supernodexp.hpc, sock=20
02/14/2018 04:10:42;0100;Server@node2;Req;;Type 51 request received from Scheduler@node2.supernodexp.hpc, sock=20
02/14/2018 04:10:42;0100;Server@node2;Req;;Type 1 request received from ctminh@node2.supernodexp.hpc, sock=16
02/14/2018 04:10:42;0100;Server@node2;Req;;Type 3 request received from ctminh@node2.supernodexp.hpc, sock=16
02/14/2018 04:10:42;0100;Server@node2;Req;;Type 5 request received from ctminh@node2.supernodexp.hpc, sock=16
02/14/2018 04:10:42;0100;Server@node2;Job;1071.node2.supernodexp.hpc;enqueuing into workq, state 1 hop 1
02/14/2018 04:10:42;0008;Server@node2;Job;1071.node2.supernodexp.hpc;Job Queued at request of ctminh@node2.supernodexp.hpc, owner = ctminh@node2.supernodexp.hpc, job name = telemac1, queue = workq
02/14/2018 04:10:42;0100;Server@node2;Req;;Type 1 request received from ctminh@node2.supernodexp.hpc, sock=16
02/14/2018 04:10:42;0100;Server@node2;Req;;Type 3 request received from ctminh@node2.supernodexp.hpc, sock=16
02/14/2018 04:10:42;0100;Server@node2;Req;;Type 5 request received from ctminh@node2.supernodexp.hpc, sock=16
02/14/2018 04:10:42;0100;Server@node2;Job;1072.node2.supernodexp.hpc;enqueuing into workq, state 1 hop 1
02/14/2018 04:10:42;0008;Server@node2;Job;1072.node2.supernodexp.hpc;Job Queued at request of ctminh@node2.supernodexp.hpc, owner = ctminh@node2.supernodexp.hpc, job name = jacobi, queue = workq
02/14/2018 04:10:42;0100;Server@node2;Req;;Type 1 request received from ctminh@node2.supernodexp.hpc, sock=16
02/14/2018 04:10:42;0100;Server@node2;Req;;Type 3 request received from ctminh@node2.supernodexp.hpc, sock=16
02/14/2018 04:10:42;0100;Server@node2;Req;;Type 5 request received from ctminh@node2.supernodexp.hpc, sock=16
02/14/2018 04:10:42;0100;Server@node2;Job;1073.node2.supernodexp.hpc;enqueuing into workq, state 1 hop 1
02/14/2018 04:10:42;0008;Server@node2;Job;1073.node2.supernodexp.hpc;Job Queued at request of ctminh@node2.supernodexp.hpc, owner = ctminh@node2.supernodexp.hpc, job name = vectorization, queue = workq
02/14/2018 04:10:42;0100;Server@node2;Req;;Type 1 request received from ctminh@node2.supernodexp.hpc, sock=16
02/14/2018 04:10:42;0100;Server@node2;Req;;Type 11 request received from Scheduler@node2.supernodexp.hpc, sock=20
02/14/2018 04:10:42;0008;Server@node2;Job;1064.node2.supernodexp.hpc;Job Modified at request of Scheduler@node2.supernodexp.hpc
02/14/2018 04:10:42;0100;Server@node2;Req;;Type 3 request received from ctminh@node2.supernodexp.hpc, sock=16
02/14/2018 04:10:42;0100;Server@node2;Req;;Type 11 request received from Scheduler@node2.supernodexp.hpc, sock=20
02/14/2018 04:10:42;0008;Server@node2;Job;1070.node2.supernodexp.hpc;Job Modified at request of Scheduler@node2.supernodexp.hpc
02/14/2018 04:10:42;0100;Server@node2;Req;;Type 5 request received from ctminh@node2.supernodexp.hpc, sock=16
02/14/2018 04:10:42;0100;Server@node2;Job;1074.node2.supernodexp.hpc;enqueuing into workq, state 1 hop 1
02/14/2018 04:10:42;0008;Server@node2;Job;1074.node2.supernodexp.hpc;Job Queued at request of ctminh@node2.supernodexp.hpc, owner = ctminh@node2.supernodexp.hpc, job name = vectorization, queue = workq
02/14/2018 04:10:42;0100;Server@node2;Req;;Type 11 request received from Scheduler@node2.supernodexp.hpc, sock=20
02/14/2018 04:10:42;0008;Server@node2;Job;1067.node2.supernodexp.hpc;Job Modified at request of Scheduler@node2.supernodexp.hpc
02/14/2018 04:10:42;0100;Server@node2;Req;;Type 11 request received from Scheduler@node2.supernodexp.hpc, sock=20
02/14/2018 04:10:42;0008;Server@node2;Job;1068.node2.supernodexp.hpc;Job Modified at request of Scheduler@node2.supernodexp.hpc
02/14/2018 04:10:42;0100;Server@node2;Req;;Type 11 request received from Scheduler@node2.supernodexp.hpc, sock=20
02/14/2018 04:10:42;0008;Server@node2;Job;1066.node2.supernodexp.hpc;Job Modified at request of Scheduler@node2.supernodexp.hpc
02/14/2018 04:10:42;0100;Server@node2;Req;;Type 11 request received from Scheduler@node2.supernodexp.hpc, sock=20
02/14/2018 04:10:42;0008;Server@node2;Job;1069.node2.supernodexp.hpc;Job Modified at request of Scheduler@node2.supernodexp.hpc
02/14/2018 04:10:42;0100;Server@node2;Req;;Type 11 request received from Scheduler@node2.supernodexp.hpc, sock=20
02/14/2018 04:10:42;0008;Server@node2;Job;1065.node2.supernodexp.hpc;Job Modified at request of Scheduler@node2.supernodexp.hpc
02/14/2018 04:10:42;0040;Server@node2;Svr;node2.supernodexp.hpc;Scheduler sent command 1
02/14/2018 04:10:42;0040;Server@node2;Svr;node2.supernodexp.hpc;Scheduler sent command 0
02/14/2018 04:10:42;0100;Server@node2;Req;;Type 21 request received from Scheduler@node2.supernodexp.hpc, sock=20
02/14/2018 04:10:42;0100;Server@node2;Req;;Type 81 request received from Scheduler@node2.supernodexp.hpc, sock=20
02/14/2018 04:10:42;0100;Server@node2;Req;;Type 71 request received from Scheduler@node2.supernodexp.hpc, sock=20
02/14/2018 04:10:42;0100;Server@node2;Req;;Type 58 request received from Scheduler@node2.supernodexp.hpc, sock=20
02/14/2018 04:10:42;0100;Server@node2;Req;;Type 1 request received from ctminh@node2.supernodexp.hpc, sock=16
02/14/2018 04:10:42;0100;Server@node2;Req;;Type 3 request received from ctminh@node2.supernodexp.hpc, sock=16
02/14/2018 04:10:42;0100;Server@node2;Req;;Type 5 request received from ctminh@node2.supernodexp.hpc, sock=16
02/14/2018 04:10:42;0100;Server@node2;Job;1075.node2.supernodexp.hpc;enqueuing into workq, state 1 hop 1
02/14/2018 04:10:42;0008;Server@node2;Job;1075.node2.supernodexp.hpc;Job Queued at request of ctminh@node2.supernodexp.hpc, owner = ctminh@node2.supernodexp.hpc, job name = thread-affinity, queue = workq
02/14/2018 04:10:42;0100;Server@node2;Req;;Type 1 request received from ctminh@node2.supernodexp.hpc, sock=16
02/14/2018 04:10:42;0100;Server@node2;Req;;Type 3 request received from ctminh@node2.supernodexp.hpc, sock=16
02/14/2018 04:10:42;0100;Server@node2;Req;;Type 5 request received from ctminh@node2.supernodexp.hpc, sock=16
02/14/2018 04:10:42;0100;Server@node2;Job;1076.node2.supernodexp.hpc;enqueuing into workq, state 1 hop 1
02/14/2018 04:10:42;0008;Server@node2;Job;1076.node2.supernodexp.hpc;Job Queued at request of ctminh@node2.supernodexp.hpc, owner = ctminh@node2.supernodexp.hpc, job name = matrix-x-vector, queue = workq
02/14/2018 04:10:42;0100;Server@node2;Req;;Type 1 request received from ctminh@node2.supernodexp.hpc, sock=16
02/14/2018 04:10:42;0100;Server@node2;Req;;Type 20 request received from Scheduler@node2.supernodexp.hpc, sock=20
02/14/2018 04:10:42;0100;Server@node2;Req;;Type 3 request received from ctminh@node2.supernodexp.hpc, sock=16
02/14/2018 04:10:42;0100;Server@node2;Req;;Type 51 request received from Scheduler@node2.supernodexp.hpc, sock=20
02/14/2018 04:10:42;0100;Server@node2;Req;;Type 5 request received from ctminh@node2.supernodexp.hpc, sock=16
02/14/2018 04:10:42;0100;Server@node2;Job;1077.node2.supernodexp.hpc;enqueuing into workq, state 1 hop 1
02/14/2018 04:10:42;0008;Server@node2;Job;1077.node2.supernodexp.hpc;Job Queued at request of ctminh@node2.supernodexp.hpc, owner = ctminh@node2.supernodexp.hpc, job name = qe_mic_test, queue = workq
02/14/2018 04:10:42;0100;Server@node2;Req;;Type 1 request received from ctminh@node2.supernodexp.hpc, sock=16
02/14/2018 04:10:42;0100;Server@node2;Req;;Type 3 request received from ctminh@node2.supernodexp.hpc, sock=16
02/14/2018 04:10:42;0100;Server@node2;Req;;Type 5 request received from ctminh@node2.supernodexp.hpc, sock=16
02/14/2018 04:10:42;0100;Server@node2;Job;1078.node2.supernodexp.hpc;enqueuing into workq, state 1 hop 1
02/14/2018 04:10:42;0008;Server@node2;Job;1078.node2.supernodexp.hpc;Job Queued at request of ctminh@node2.supernodexp.hpc, owner = ctminh@node2.supernodexp.hpc, job name = lu-decomp, queue = workq
02/14/2018 04:10:42;0100;Server@node2;Req;;Type 1 request received from ctminh@node2.supernodexp.hpc, sock=16
02/14/2018 04:10:42;0100;Server@node2;Req;;Type 3 request received from ctminh@node2.supernodexp.hpc, sock=16
02/14/2018 04:10:42;0100;Server@node2;Req;;Type 5 request received from ctminh@node2.supernodexp.hpc, sock=16
02/14/2018 04:10:42;0100;Server@node2;Job;1079.node2.supernodexp.hpc;enqueuing into workq, state 1 hop 1
02/14/2018 04:10:42;0008;Server@node2;Job;1079.node2.supernodexp.hpc;Job Queued at request of ctminh@node2.supernodexp.hpc, owner = ctminh@node2.supernodexp.hpc, job name = lu-decomp, queue = workq
02/14/2018 04:10:42;0100;Server@node2;Req;;Type 1 request received from ctminh@node2.supernodexp.hpc, sock=16
02/14/2018 04:10:42;0100;Server@node2;Req;;Type 3 request received from ctminh@node2.supernodexp.hpc, sock=16
02/14/2018 04:10:42;0100;Server@node2;Req;;Type 5 request received from ctminh@node2.supernodexp.hpc, sock=16
02/14/2018 04:10:42;0100;Server@node2;Job;1080.node2.supernodexp.hpc;enqueuing into workq, state 1 hop 1
02/14/2018 04:10:42;0008;Server@node2;Job;1080.node2.supernodexp.hpc;Job Queued at request of ctminh@node2.supernodexp.hpc, owner = ctminh@node2.supernodexp.hpc, job name = telemac3, queue = workq
02/14/2018 04:10:42;0100;Server@node2;Req;;Type 11 request received from Scheduler@node2.supernodexp.hpc, sock=20
02/14/2018 04:10:42;0008;Server@node2;Job;1071.node2.supernodexp.hpc;Job Modified at request of Scheduler@node2.supernodexp.hpc
02/14/2018 04:10:42;0100;Server@node2;Req;;Type 11 request received from Scheduler@node2.supernodexp.hpc, sock=20
02/14/2018 04:10:42;0008;Server@node2;Job;1072.node2.supernodexp.hpc;Job Modified at request of Scheduler@node2.supernodexp.hpc
02/14/2018 04:10:42;0100;Server@node2;Req;;Type 11 request received from Scheduler@node2.supernodexp.hpc, sock=20
02/14/2018 04:10:42;0008;Server@node2;Job;1075.node2.supernodexp.hpc;Job Modified at request of Scheduler@node2.supernodexp.hpc
02/14/2018 04:10:42;0100;Server@node2;Req;;Type 11 request received from Scheduler@node2.supernodexp.hpc, sock=20
02/14/2018 04:10:42;0008;Server@node2;Job;1073.node2.supernodexp.hpc;Job Modified at request of Scheduler@node2.supernodexp.hpc
02/14/2018 04:10:42;0100;Server@node2;Req;;Type 11 request received from Scheduler@node2.supernodexp.hpc, sock=20
02/14/2018 04:10:42;0008;Server@node2;Job;1074.node2.supernodexp.hpc;Job Modified at request of Scheduler@node2.supernodexp.hpc
02/14/2018 04:10:42;0100;Server@node2;Req;;Type 11 request received from Scheduler@node2.supernodexp.hpc, sock=20
02/14/2018 04:10:42;0008;Server@node2;Job;1076.node2.supernodexp.hpc;Job Modified at request of Scheduler@node2.supernodexp.hpc
02/14/2018 04:10:42;0040;Server@node2;Svr;node2.supernodexp.hpc;Scheduler sent command 1
02/14/2018 04:10:42;0040;Server@node2;Svr;node2.supernodexp.hpc;Scheduler sent command 0
02/14/2018 04:10:42;0100;Server@node2;Req;;Type 21 request received from Scheduler@node2.supernodexp.hpc, sock=20
02/14/2018 04:10:42;0100;Server@node2;Req;;Type 81 request received from Scheduler@node2.supernodexp.hpc, sock=20
02/14/2018 04:10:42;0100;Server@node2;Req;;Type 71 request received from Scheduler@node2.supernodexp.hpc, sock=20
02/14/2018 04:10:42;0100;Server@node2;Req;;Type 58 request received from Scheduler@node2.supernodexp.hpc, sock=20
02/14/2018 04:10:42;0100;Server@node2;Req;;Type 1 request received from ctminh@node2.supernodexp.hpc, sock=16
02/14/2018 04:10:42;0100;Server@node2;Req;;Type 3 request received from ctminh@node2.supernodexp.hpc, sock=16
02/14/2018 04:10:42;0100;Server@node2;Req;;Type 5 request received from ctminh@node2.supernodexp.hpc, sock=16
02/14/2018 04:10:42;0100;Server@node2;Job;1081.node2.supernodexp.hpc;enqueuing into workq, state 1 hop 1
02/14/2018 04:10:42;0008;Server@node2;Job;1081.node2.supernodexp.hpc;Job Queued at request of ctminh@node2.supernodexp.hpc, owner = ctminh@node2.supernodexp.hpc, job name = telemac3, queue = workq
02/14/2018 04:10:42;0100;Server@node2;Req;;Type 1 request received from ctminh@node2.supernodexp.hpc, sock=16
02/14/2018 04:10:42;0100;Server@node2;Req;;Type 3 request received from ctminh@node2.supernodexp.hpc, sock=16
02/14/2018 04:10:42;0100;Server@node2;Req;;Type 5 request received from ctminh@node2.supernodexp.hpc, sock=16
02/14/2018 04:10:42;0100;Server@node2;Job;1082.node2.supernodexp.hpc;enqueuing into workq, state 1 hop 1
02/14/2018 04:10:42;0008;Server@node2;Job;1082.node2.supernodexp.hpc;Job Queued at request of ctminh@node2.supernodexp.hpc, owner = ctminh@node2.supernodexp.hpc, job name = histogram, queue = workq
02/14/2018 04:10:42;0100;Server@node2;Req;;Type 20 request received from Scheduler@node2.supernodexp.hpc, sock=20
02/14/2018 04:10:42;0100;Server@node2;Req;;Type 51 request received from Scheduler@node2.supernodexp.hpc, sock=20
02/14/2018 04:10:42;0100;Server@node2;Req;;Type 11 request received from Scheduler@node2.supernodexp.hpc, sock=20
02/14/2018 04:10:42;0008;Server@node2;Job;1077.node2.supernodexp.hpc;Job Modified at request of Scheduler@node2.supernodexp.hpc
02/14/2018 04:10:42;0100;Server@node2;Req;;Type 11 request received from Scheduler@node2.supernodexp.hpc, sock=20
02/14/2018 04:10:42;0008;Server@node2;Job;1080.node2.supernodexp.hpc;Job Modified at request of Scheduler@node2.supernodexp.hpc
02/14/2018 04:10:42;0100;Server@node2;Req;;Type 11 request received from Scheduler@node2.supernodexp.hpc, sock=20
02/14/2018 04:10:42;0008;Server@node2;Job;1081.node2.supernodexp.hpc;Job Modified at request of Scheduler@node2.supernodexp.hpc
02/14/2018 04:10:42;0100;Server@node2;Req;;Type 11 request received from Scheduler@node2.supernodexp.hpc, sock=20
02/14/2018 04:10:42;0008;Server@node2;Job;1082.node2.supernodexp.hpc;Job Modified at request of Scheduler@node2.supernodexp.hpc
02/14/2018 04:10:42;0100;Server@node2;Req;;Type 11 request received from Scheduler@node2.supernodexp.hpc, sock=20
02/14/2018 04:10:42;0008;Server@node2;Job;1078.node2.supernodexp.hpc;Job Modified at request of Scheduler@node2.supernodexp.hpc
02/14/2018 04:10:42;0100;Server@node2;Req;;Type 11 request received from Scheduler@node2.supernodexp.hpc, sock=20
02/14/2018 04:10:42;0008;Server@node2;Job;1079.node2.supernodexp.hpc;Job Modified at request of Scheduler@node2.supernodexp.hpc
02/14/2018 04:10:42;0040;Server@node2;Svr;node2.supernodexp.hpc;Scheduler sent command 1
02/14/2018 04:10:42;0040;Server@node2;Svr;node2.supernodexp.hpc;Scheduler sent command 0
02/14/2018 04:10:42;0100;Server@node2;Req;;Type 21 request received from Scheduler@node2.supernodexp.hpc, sock=20
02/14/2018 04:10:42;0100;Server@node2;Req;;Type 81 request received from Scheduler@node2.supernodexp.hpc, sock=20
02/14/2018 04:10:42;0100;Server@node2;Req;;Type 71 request received from Scheduler@node2.supernodexp.hpc, sock=20
02/14/2018 04:10:42;0100;Server@node2;Req;;Type 58 request received from Scheduler@node2.supernodexp.hpc, sock=20
02/14/2018 04:10:42;0100;Server@node2;Req;;Type 20 request received from Scheduler@node2.supernodexp.hpc, sock=20
02/14/2018 04:10:42;0100;Server@node2;Req;;Type 51 request received from Scheduler@node2.supernodexp.hpc, sock=20
02/14/2018 04:11:17;0080;Server@node2;Job;1002.node2.supernodexp.hpc;Obit received momhop:1 serverhop:1 state:4 substate:42
02/14/2018 04:11:18;0010;Server@node2;Job;1002.node2.supernodexp.hpc;Exit_status=0 resources_used.cpupercent=1819 resources_used.cput=01:49:00 resources_used.mem=3252512kb resources_used.ncpus=48 resources_used.vmem=33619812kb resources_used.walltime=00:02:39
02/14/2018 04:11:18;0100;Server@node2;Job;1002.node2.supernodexp.hpc;dequeuing from workq, state 5
02/14/2018 04:11:18;0040;Server@node2;Svr;node2.supernodexp.hpc;Scheduler sent command 2
02/14/2018 04:11:18;0040;Server@node2;Svr;node2.supernodexp.hpc;Scheduler sent command 0
02/14/2018 04:11:18;0100;Server@node2;Req;;Type 21 request received from Scheduler@node2.supernodexp.hpc, sock=20
02/14/2018 04:11:18;0100;Server@node2;Req;;Type 81 request received from Scheduler@node2.supernodexp.hpc, sock=20
02/14/2018 04:11:18;0100;Server@node2;Req;;Type 71 request received from Scheduler@node2.supernodexp.hpc, sock=20
02/14/2018 04:11:18;0100;Server@node2;Req;;Type 58 request received from Scheduler@node2.supernodexp.hpc, sock=20
02/14/2018 04:11:18;0100;Server@node2;Req;;Type 20 request received from Scheduler@node2.supernodexp.hpc, sock=20
02/14/2018 04:11:18;0100;Server@node2;Req;;Type 51 request received from Scheduler@node2.supernodexp.hpc, sock=20
02/14/2018 04:11:19;0100;Server@node2;Req;;Type 23 request received from Scheduler@node2.supernodexp.hpc, sock=20
02/14/2018 04:11:19;0008;Server@node2;Job;1024.node2.supernodexp.hpc;Job Run at request of Scheduler@node2.supernodexp.hpc on exec_vnode (node13:ncpus=32:nmics=1:mem=16777216kb)
02/14/2018 04:11:19;0001;Server@node2;Svr;Server@node2;Success (0) in req_runjob2, return value of svr_startjob is 0
02/14/2018 04:11:19;0100;Server@node2;Req;;Type 11 request received from Scheduler@node2.supernodexp.hpc, sock=20
02/14/2018 04:11:19;0008;Server@node2;Job;1037.node2.supernodexp.hpc;Job Modified at request of Scheduler@node2.supernodexp.hpc
02/14/2018 04:11:37;0100;Server@node2;Req;;Type 1 request received from ctminh@node2.supernodexp.hpc, sock=16
02/14/2018 04:11:37;0100;Server@node2;Req;;Type 3 request received from ctminh@node2.supernodexp.hpc, sock=16
02/14/2018 04:11:37;0100;Server@node2;Req;;Type 5 request received from ctminh@node2.supernodexp.hpc, sock=16
02/14/2018 04:11:37;0100;Server@node2;Job;1083.node2.supernodexp.hpc;enqueuing into workq, state 1 hop 1
02/14/2018 04:11:37;0008;Server@node2;Job;1083.node2.supernodexp.hpc;Job Queued at request of ctminh@node2.supernodexp.hpc, owner = ctminh@node2.supernodexp.hpc, job name = nbody, queue = workq
02/14/2018 04:11:37;0040;Server@node2;Svr;node2.supernodexp.hpc;Scheduler sent command 1
02/14/2018 04:11:37;0040;Server@node2;Svr;node2.supernodexp.hpc;Scheduler sent command 0
02/14/2018 04:11:37;0100;Server@node2;Req;;Type 21 request received from Scheduler@node2.supernodexp.hpc, sock=20
02/14/2018 04:11:37;0100;Server@node2;Req;;Type 81 request received from Scheduler@node2.supernodexp.hpc, sock=20
02/14/2018 04:11:37;0100;Server@node2;Req;;Type 71 request received from Scheduler@node2.supernodexp.hpc, sock=20
02/14/2018 04:11:37;0100;Server@node2;Req;;Type 58 request received from Scheduler@node2.supernodexp.hpc, sock=20
02/14/2018 04:11:37;0100;Server@node2;Req;;Type 1 request received from ctminh@node2.supernodexp.hpc, sock=16
02/14/2018 04:11:37;0100;Server@node2;Req;;Type 3 request received from ctminh@node2.supernodexp.hpc, sock=16
02/14/2018 04:11:37;0100;Server@node2;Req;;Type 5 request received from ctminh@node2.supernodexp.hpc, sock=16
02/14/2018 04:11:37;0100;Server@node2;Job;1084.node2.supernodexp.hpc;enqueuing into workq, state 1 hop 1
02/14/2018 04:11:37;0008;Server@node2;Job;1084.node2.supernodexp.hpc;Job Queued at request of ctminh@node2.supernodexp.hpc, owner = ctminh@node2.supernodexp.hpc, job name = sweep, queue = workq
02/14/2018 04:11:37;0100;Server@node2;Req;;Type 1 request received from ctminh@node2.supernodexp.hpc, sock=16
02/14/2018 04:11:37;0100;Server@node2;Req;;Type 20 request received from Scheduler@node2.supernodexp.hpc, sock=20
02/14/2018 04:11:37;0100;Server@node2;Req;;Type 3 request received from ctminh@node2.supernodexp.hpc, sock=16
02/14/2018 04:11:37;0100;Server@node2;Req;;Type 51 request received from Scheduler@node2.supernodexp.hpc, sock=20
02/14/2018 04:11:37;0100;Server@node2;Req;;Type 5 request received from ctminh@node2.supernodexp.hpc, sock=16
02/14/2018 04:11:37;0100;Server@node2;Job;1085.node2.supernodexp.hpc;enqueuing into workq, state 1 hop 1
02/14/2018 04:11:37;0008;Server@node2;Job;1085.node2.supernodexp.hpc;Job Queued at request of ctminh@node2.supernodexp.hpc, owner = ctminh@node2.supernodexp.hpc, job name = vectorization, queue = workq
02/14/2018 04:11:37;0100;Server@node2;Req;;Type 1 request received from ctminh@node2.supernodexp.hpc, sock=16
02/14/2018 04:11:37;0100;Server@node2;Req;;Type 3 request received from ctminh@node2.supernodexp.hpc, sock=16
02/14/2018 04:11:37;0100;Server@node2;Req;;Type 5 request received from ctminh@node2.supernodexp.hpc, sock=16
02/14/2018 04:11:37;0100;Server@node2;Job;1086.node2.supernodexp.hpc;enqueuing into workq, state 1 hop 1
02/14/2018 04:11:37;0008;Server@node2;Job;1086.node2.supernodexp.hpc;Job Queued at request of ctminh@node2.supernodexp.hpc, owner = ctminh@node2.supernodexp.hpc, job name = vast1, queue = workq
02/14/2018 04:11:37;0100;Server@node2;Req;;Type 11 request received from Scheduler@node2.supernodexp.hpc, sock=20
02/14/2018 04:11:37;0008;Server@node2;Job;1083.node2.supernodexp.hpc;Job Modified at request of Scheduler@node2.supernodexp.hpc
02/14/2018 04:11:37;0100;Server@node2;Req;;Type 11 request received from Scheduler@node2.supernodexp.hpc, sock=20
02/14/2018 04:11:37;0008;Server@node2;Job;1084.node2.supernodexp.hpc;Job Modified at request of Scheduler@node2.supernodexp.hpc
02/14/2018 04:11:37;0040;Server@node2;Svr;node2.supernodexp.hpc;Scheduler sent command 1
02/14/2018 04:11:37;0040;Server@node2;Svr;node2.supernodexp.hpc;Scheduler sent command 0
02/14/2018 04:11:37;0100;Server@node2;Req;;Type 21 request received from Scheduler@node2.supernodexp.hpc, sock=20
02/14/2018 04:11:37;0100;Server@node2;Req;;Type 81 request received from Scheduler@node2.supernodexp.hpc, sock=20
02/14/2018 04:11:37;0100;Server@node2;Req;;Type 71 request received from Scheduler@node2.supernodexp.hpc, sock=20
02/14/2018 04:11:37;0100;Server@node2;Req;;Type 58 request received from Scheduler@node2.supernodexp.hpc, sock=20
02/14/2018 04:11:37;0100;Server@node2;Req;;Type 1 request received from ctminh@node2.supernodexp.hpc, sock=16
02/14/2018 04:11:37;0100;Server@node2;Req;;Type 3 request received from ctminh@node2.supernodexp.hpc, sock=16
02/14/2018 04:11:37;0100;Server@node2;Req;;Type 5 request received from ctminh@node2.supernodexp.hpc, sock=16
02/14/2018 04:11:37;0100;Server@node2;Job;1087.node2.supernodexp.hpc;enqueuing into workq, state 1 hop 1
02/14/2018 04:11:37;0008;Server@node2;Job;1087.node2.supernodexp.hpc;Job Queued at request of ctminh@node2.supernodexp.hpc, owner = ctminh@node2.supernodexp.hpc, job name = matrix-x-vector, queue = workq
02/14/2018 04:11:37;0100;Server@node2;Req;;Type 1 request received from ctminh@node2.supernodexp.hpc, sock=16
02/14/2018 04:11:37;0100;Server@node2;Req;;Type 3 request received from ctminh@node2.supernodexp.hpc, sock=16
02/14/2018 04:11:37;0100;Server@node2;Req;;Type 5 request received from ctminh@node2.supernodexp.hpc, sock=16
02/14/2018 04:11:37;0100;Server@node2;Job;1088.node2.supernodexp.hpc;enqueuing into workq, state 1 hop 1
02/14/2018 04:11:37;0008;Server@node2;Job;1088.node2.supernodexp.hpc;Job Queued at request of ctminh@node2.supernodexp.hpc, owner = ctminh@node2.supernodexp.hpc, job name = lu-decomp, queue = workq
02/14/2018 04:11:37;0100;Server@node2;Req;;Type 1 request received from ctminh@node2.supernodexp.hpc, sock=16
02/14/2018 04:11:37;0100;Server@node2;Req;;Type 3 request received from ctminh@node2.supernodexp.hpc, sock=16
02/14/2018 04:11:37;0100;Server@node2;Req;;Type 5 request received from ctminh@node2.supernodexp.hpc, sock=16
02/14/2018 04:11:37;0100;Server@node2;Job;1089.node2.supernodexp.hpc;enqueuing into workq, state 1 hop 1
02/14/2018 04:11:37;0008;Server@node2;Job;1089.node2.supernodexp.hpc;Job Queued at request of ctminh@node2.supernodexp.hpc, owner = ctminh@node2.supernodexp.hpc, job name = telemac3, queue = workq
02/14/2018 04:11:37;0100;Server@node2;Req;;Type 20 request received from Scheduler@node2.supernodexp.hpc, sock=20
02/14/2018 04:11:37;0100;Server@node2;Req;;Type 51 request received from Scheduler@node2.supernodexp.hpc, sock=20
02/14/2018 04:11:37;0100;Server@node2;Req;;Type 1 request received from ctminh@node2.supernodexp.hpc, sock=16
02/14/2018 04:11:37;0100;Server@node2;Req;;Type 3 request received from ctminh@node2.supernodexp.hpc, sock=16
02/14/2018 04:11:37;0100;Server@node2;Req;;Type 5 request received from ctminh@node2.supernodexp.hpc, sock=16
02/14/2018 04:11:37;0100;Server@node2;Job;1090.node2.supernodexp.hpc;enqueuing into workq, state 1 hop 1
02/14/2018 04:11:37;0008;Server@node2;Job;1090.node2.supernodexp.hpc;Job Queued at request of ctminh@node2.supernodexp.hpc, owner = ctminh@node2.supernodexp.hpc, job name = vast1, queue = workq
02/14/2018 04:11:37;0100;Server@node2;Req;;Type 1 request received from ctminh@node2.supernodexp.hpc, sock=16
02/14/2018 04:11:37;0100;Server@node2;Req;;Type 3 request received from ctminh@node2.supernodexp.hpc, sock=16
02/14/2018 04:11:37;0100;Server@node2;Req;;Type 5 request received from ctminh@node2.supernodexp.hpc, sock=16
02/14/2018 04:11:37;0100;Server@node2;Job;1091.node2.supernodexp.hpc;enqueuing into workq, state 1 hop 1
02/14/2018 04:11:37;0008;Server@node2;Job;1091.node2.supernodexp.hpc;Job Queued at request of ctminh@node2.supernodexp.hpc, owner = ctminh@node2.supernodexp.hpc, job name = telemac1, queue = workq
02/14/2018 04:11:37;0100;Server@node2;Req;;Type 1 request received from ctminh@node2.supernodexp.hpc, sock=16
02/14/2018 04:11:37;0100;Server@node2;Req;;Type 3 request received from ctminh@node2.supernodexp.hpc, sock=16
02/14/2018 04:11:37;0100;Server@node2;Req;;Type 5 request received from ctminh@node2.supernodexp.hpc, sock=16
02/14/2018 04:11:37;0100;Server@node2;Job;1092.node2.supernodexp.hpc;enqueuing into workq, state 1 hop 1
02/14/2018 04:11:37;0008;Server@node2;Job;1092.node2.supernodexp.hpc;Job Queued at request of ctminh@node2.supernodexp.hpc, owner = ctminh@node2.supernodexp.hpc, job name = sweep, queue = workq
02/14/2018 04:11:37;0100;Server@node2;Req;;Type 1 request received from ctminh@node2.supernodexp.hpc, sock=16
02/14/2018 04:11:37;0100;Server@node2;Req;;Type 11 request received from Scheduler@node2.supernodexp.hpc, sock=20
02/14/2018 04:11:37;0008;Server@node2;Job;1086.node2.supernodexp.hpc;Job Modified at request of Scheduler@node2.supernodexp.hpc
02/14/2018 04:11:37;0100;Server@node2;Req;;Type 3 request received from ctminh@node2.supernodexp.hpc, sock=16
02/14/2018 04:11:37;0100;Server@node2;Req;;Type 5 request received from ctminh@node2.supernodexp.hpc, sock=16
02/14/2018 04:11:37;0100;Server@node2;Job;1093.node2.supernodexp.hpc;enqueuing into workq, state 1 hop 1
02/14/2018 04:11:37;0008;Server@node2;Job;1093.node2.supernodexp.hpc;Job Queued at request of ctminh@node2.supernodexp.hpc, owner = ctminh@node2.supernodexp.hpc, job name = vectorization, queue = workq
02/14/2018 04:11:37;0100;Server@node2;Req;;Type 11 request received from Scheduler@node2.supernodexp.hpc, sock=20
02/14/2018 04:11:37;0008;Server@node2;Job;1089.node2.supernodexp.hpc;Job Modified at request of Scheduler@node2.supernodexp.hpc
02/14/2018 04:11:37;0100;Server@node2;Req;;Type 11 request received from Scheduler@node2.supernodexp.hpc, sock=20
02/14/2018 04:11:37;0008;Server@node2;Job;1085.node2.supernodexp.hpc;Job Modified at request of Scheduler@node2.supernodexp.hpc
02/14/2018 04:11:37;0100;Server@node2;Req;;Type 11 request received from Scheduler@node2.supernodexp.hpc, sock=20
02/14/2018 04:11:37;0008;Server@node2;Job;1087.node2.supernodexp.hpc;Job Modified at request of Scheduler@node2.supernodexp.hpc
02/14/2018 04:11:37;0100;Server@node2;Req;;Type 11 request received from Scheduler@node2.supernodexp.hpc, sock=20
02/14/2018 04:11:37;0008;Server@node2;Job;1088.node2.supernodexp.hpc;Job Modified at request of Scheduler@node2.supernodexp.hpc
02/14/2018 04:11:37;0040;Server@node2;Svr;node2.supernodexp.hpc;Scheduler sent command 1
02/14/2018 04:11:37;0040;Server@node2;Svr;node2.supernodexp.hpc;Scheduler sent command 0
02/14/2018 04:11:37;0100;Server@node2;Req;;Type 21 request received from Scheduler@node2.supernodexp.hpc, sock=20
02/14/2018 04:11:37;0100;Server@node2;Req;;Type 81 request received from Scheduler@node2.supernodexp.hpc, sock=20
02/14/2018 04:11:37;0100;Server@node2;Req;;Type 71 request received from Scheduler@node2.supernodexp.hpc, sock=20
02/14/2018 04:11:37;0100;Server@node2;Req;;Type 58 request received from Scheduler@node2.supernodexp.hpc, sock=20
02/14/2018 04:11:37;0100;Server@node2;Req;;Type 1 request received from ctminh@node2.supernodexp.hpc, sock=16
02/14/2018 04:11:37;0100;Server@node2;Req;;Type 3 request received from ctminh@node2.supernodexp.hpc, sock=16
02/14/2018 04:11:37;0100;Server@node2;Req;;Type 5 request received from ctminh@node2.supernodexp.hpc, sock=16
02/14/2018 04:11:37;0100;Server@node2;Job;1094.node2.supernodexp.hpc;enqueuing into workq, state 1 hop 1
02/14/2018 04:11:37;0008;Server@node2;Job;1094.node2.supernodexp.hpc;Job Queued at request of ctminh@node2.supernodexp.hpc, owner = ctminh@node2.supernodexp.hpc, job name = histogram, queue = workq
02/14/2018 04:11:37;0100;Server@node2;Req;;Type 1 request received from ctminh@node2.supernodexp.hpc, sock=16
02/14/2018 04:11:37;0100;Server@node2;Req;;Type 3 request received from ctminh@node2.supernodexp.hpc, sock=16
02/14/2018 04:11:37;0100;Server@node2;Req;;Type 5 request received from ctminh@node2.supernodexp.hpc, sock=16
02/14/2018 04:11:37;0100;Server@node2;Job;1095.node2.supernodexp.hpc;enqueuing into workq, state 1 hop 1
02/14/2018 04:11:37;0008;Server@node2;Job;1095.node2.supernodexp.hpc;Job Queued at request of ctminh@node2.supernodexp.hpc, owner = ctminh@node2.supernodexp.hpc, job name = sweep, queue = workq
02/14/2018 04:11:37;0100;Server@node2;Req;;Type 20 request received from Scheduler@node2.supernodexp.hpc, sock=20
02/14/2018 04:11:37;0100;Server@node2;Req;;Type 51 request received from Scheduler@node2.supernodexp.hpc, sock=20
02/14/2018 04:11:37;0100;Server@node2;Req;;Type 1 request received from ctminh@node2.supernodexp.hpc, sock=16
02/14/2018 04:11:37;0100;Server@node2;Req;;Type 3 request received from ctminh@node2.supernodexp.hpc, sock=16
02/14/2018 04:11:37;0100;Server@node2;Req;;Type 5 request received from ctminh@node2.supernodexp.hpc, sock=16
02/14/2018 04:11:37;0100;Server@node2;Job;1096.node2.supernodexp.hpc;enqueuing into workq, state 1 hop 1
02/14/2018 04:11:37;0008;Server@node2;Job;1096.node2.supernodexp.hpc;Job Queued at request of ctminh@node2.supernodexp.hpc, owner = ctminh@node2.supernodexp.hpc, job name = telemac3, queue = workq
02/14/2018 04:11:37;0100;Server@node2;Req;;Type 1 request received from ctminh@node2.supernodexp.hpc, sock=16
02/14/2018 04:11:37;0100;Server@node2;Req;;Type 3 request received from ctminh@node2.supernodexp.hpc, sock=16
02/14/2018 04:11:37;0100;Server@node2;Req;;Type 5 request received from ctminh@node2.supernodexp.hpc, sock=16
02/14/2018 04:11:37;0100;Server@node2;Job;1097.node2.supernodexp.hpc;enqueuing into workq, state 1 hop 1
02/14/2018 04:11:37;0008;Server@node2;Job;1097.node2.supernodexp.hpc;Job Queued at request of ctminh@node2.supernodexp.hpc, owner = ctminh@node2.supernodexp.hpc, job name = thread-affinity, queue = workq
02/14/2018 04:11:37;0100;Server@node2;Req;;Type 1 request received from ctminh@node2.supernodexp.hpc, sock=16
02/14/2018 04:11:37;0100;Server@node2;Req;;Type 11 request received from Scheduler@node2.supernodexp.hpc, sock=20
02/14/2018 04:11:37;0008;Server@node2;Job;1090.node2.supernodexp.hpc;Job Modified at request of Scheduler@node2.supernodexp.hpc
02/14/2018 04:11:37;0100;Server@node2;Req;;Type 3 request received from ctminh@node2.supernodexp.hpc, sock=16
02/14/2018 04:11:37;0100;Server@node2;Req;;Type 5 request received from ctminh@node2.supernodexp.hpc, sock=16
02/14/2018 04:11:37;0100;Server@node2;Job;1098.node2.supernodexp.hpc;enqueuing into workq, state 1 hop 1
02/14/2018 04:11:38;0008;Server@node2;Job;1098.node2.supernodexp.hpc;Job Queued at request of ctminh@node2.supernodexp.hpc, owner = ctminh@node2.supernodexp.hpc, job name = qe_mic_test, queue = workq
02/14/2018 04:11:38;0100;Server@node2;Req;;Type 11 request received from Scheduler@node2.supernodexp.hpc, sock=20
02/14/2018 04:11:38;0008;Server@node2;Job;1091.node2.supernodexp.hpc;Job Modified at request of Scheduler@node2.supernodexp.hpc
02/14/2018 04:11:38;0100;Server@node2;Req;;Type 11 request received from Scheduler@node2.supernodexp.hpc, sock=20
02/14/2018 04:11:38;0008;Server@node2;Job;1092.node2.supernodexp.hpc;Job Modified at request of Scheduler@node2.supernodexp.hpc
02/14/2018 04:11:38;0100;Server@node2;Req;;Type 11 request received from Scheduler@node2.supernodexp.hpc, sock=20
02/14/2018 04:11:38;0008;Server@node2;Job;1093.node2.supernodexp.hpc;Job Modified at request of Scheduler@node2.supernodexp.hpc
02/14/2018 04:11:38;0100;Server@node2;Req;;Type 11 request received from Scheduler@node2.supernodexp.hpc, sock=20
02/14/2018 04:11:38;0008;Server@node2;Job;1094.node2.supernodexp.hpc;Job Modified at request of Scheduler@node2.supernodexp.hpc
02/14/2018 04:11:38;0100;Server@node2;Req;;Type 11 request received from Scheduler@node2.supernodexp.hpc, sock=20
02/14/2018 04:11:38;0008;Server@node2;Job;1095.node2.supernodexp.hpc;Job Modified at request of Scheduler@node2.supernodexp.hpc
02/14/2018 04:11:38;0040;Server@node2;Svr;node2.supernodexp.hpc;Scheduler sent command 1
02/14/2018 04:11:38;0040;Server@node2;Svr;node2.supernodexp.hpc;Scheduler sent command 0
02/14/2018 04:11:38;0100;Server@node2;Req;;Type 21 request received from Scheduler@node2.supernodexp.hpc, sock=20
02/14/2018 04:11:38;0100;Server@node2;Req;;Type 81 request received from Scheduler@node2.supernodexp.hpc, sock=20
02/14/2018 04:11:38;0100;Server@node2;Req;;Type 71 request received from Scheduler@node2.supernodexp.hpc, sock=20
02/14/2018 04:11:38;0100;Server@node2;Req;;Type 58 request received from Scheduler@node2.supernodexp.hpc, sock=20
02/14/2018 04:11:38;0100;Server@node2;Req;;Type 1 request received from ctminh@node2.supernodexp.hpc, sock=16
02/14/2018 04:11:38;0100;Server@node2;Req;;Type 3 request received from ctminh@node2.supernodexp.hpc, sock=16
02/14/2018 04:11:38;0100;Server@node2;Req;;Type 5 request received from ctminh@node2.supernodexp.hpc, sock=16
02/14/2018 04:11:38;0100;Server@node2;Job;1099.node2.supernodexp.hpc;enqueuing into workq, state 1 hop 1
02/14/2018 04:11:38;0008;Server@node2;Job;1099.node2.supernodexp.hpc;Job Queued at request of ctminh@node2.supernodexp.hpc, owner = ctminh@node2.supernodexp.hpc, job name = nbody, queue = workq
02/14/2018 04:11:38;0100;Server@node2;Req;;Type 1 request received from ctminh@node2.supernodexp.hpc, sock=16
02/14/2018 04:11:38;0100;Server@node2;Hook;_pbs_python_event_set;Restarting Python interpreter to reduce mem usage
02/14/2018 04:11:38;0100;Server@node2;Svr;Server@node2;--> Stopping Python interpreter <--
02/14/2018 04:11:38;0100;Server@node2;Svr;Server@node2;--> Python Interpreter started, compiled with version:'2.7.5' <--
02/14/2018 04:11:38;0100;Server@node2;Svr;Server@node2;sys.modules= {'pbs.v1._svr_types': <module 'pbs.v1._svr_types' from '/opt/pbs/lib/python/altair/pbs/v1/_svr_types.pyo'>, 'copy_reg': <module 'copy_reg' from '/usr/lib64/python2.7/copy_reg.pyo'>, 'pbs.v1._pbs_v1': None, '__main__': <module '__main__' (built-in)>, '__builtin__': <module '__builtin__' (built-in)>, '_pbs_v1.svr_types': <module '_pbs_v1.svr_types' (built-in)>, 'encodings': <module 'encodings' from '/usr/lib64/python2.7/encodings/__init__.pyo'>, 'encodings.encodings': None, 'abc': <module 'abc' from '/usr/lib64/python2.7/abc.pyo'>, 'pbs._pbs_v1': None, 'posixpath': <module 'posixpath' from '/usr/lib64/python2.7/posixpath.pyo'>, '_weakrefset': <module '_weakrefset' from '/usr/lib64/python2.7/_weakrefset.pyo'>, 'pbs.v1': <module 'pbs.v1' from '/opt/pbs/lib/python/altair/pbs/v1/__init__.pyo'>, 'errno': <module 'errno' (built-in)>, 'encodings.codecs': None, 'pbs.v1._export_types': <module 'pbs.v1._export_types' from '/opt/pbs/lib/python/altair/pbs/v1/_export_types.pyo'>, 'pbs.v1.os': None, '_abcoll': <module '_abcoll' from '/usr/lib64/python2.7/_abcoll.pyo'>, 'os.path': <module 'posixpath' from '/usr/lib64/python2.7/posixpath.pyo'>, 'UserDict': <module 'UserDict' from '/usr/lib64/python2.7/UserDict.pyo'>, '_warnings': <module '_warnings' (built-in)>, 'genericpath': <module 'genericpath' from '/usr/lib64/python2.7/genericpath.pyo'>, 'stat': <module 'stat' from '/usr/lib64/python2.7/stat.pyo'>, 'zipimport': <module 'zipimport' (built-in)>, 'encodings.__builtin__': None, 'pbs.pbs': None, 'warnings': <module 'warnings' from '/usr/lib64/python2.7/warnings.pyo'>, '_codecs': <module '_codecs' (built-in)>, 'encodings.ascii': <module 'encodings.ascii' from '/usr/lib64/python2.7/encodings/ascii.pyo'>, 'sys': <module 'sys' (built-in)>, 'pbs.v1._base_types': <module 'pbs.v1._base_types' from '/opt/pbs/lib/python/altair/pbs/v1/_base_types.pyo'>, 'pbs.v1.sys': None, 'codecs': <module 'codecs' from '/usr/lib64/python2.7/codecs.pyo'>, 'types': <module 'types' from '/usr/lib64/python2.7/types.pyo'>, 'pbs': <module 'pbs' from '/opt/pbs/lib/python/altair/pbs/__init__.pyo'>, 'os': <module 'os' from '/usr/lib64/python2.7/os.pyo'>, 'signal': <module 'signal' (built-in)>, 'linecache': <module 'linecache' from '/usr/lib64/python2.7/linecache.pyo'>, '_pbs_v1': <module '_pbs_v1' (built-in)>, 'posix': <module 'posix' (built-in)>, 'encodings.aliases': <module 'encodings.aliases' from '/usr/lib64/python2.7/encodings/aliases.pyo'>, 'exceptions': <module 'exceptions' (built-in)>, 'pbs.v1._exc_types': <module 'pbs.v1._exc_types' from '/opt/pbs/lib/python/altair/pbs/v1/_exc_types.pyo'>, '_weakref': <module '_weakref' (built-in)>}
02/14/2018 04:11:38;0106;Server@node2;Svr;Server@node2;BEGIN setting up all resource attributes 
02/14/2018 04:11:38;0106;Server@node2;Svr;Server@node2;DONE setting up all resource attributes, number set <51>
02/14/2018 04:11:38;0106;Server@node2;Svr;Server@node2;BEGIN setting up all queue attributes 
02/14/2018 04:11:38;0106;Server@node2;Svr;Server@node2;DONE setting up all queue attributes, number set <55>
02/14/2018 04:11:38;0106;Server@node2;Svr;Server@node2;BEGIN setting up all job attributes 
02/14/2018 04:11:38;0106;Server@node2;Svr;Server@node2;DONE setting up all job attributes, number set <94>
02/14/2018 04:11:38;0106;Server@node2;Svr;Server@node2;BEGIN setting up all server attributes 
02/14/2018 04:11:38;0106;Server@node2;Svr;Server@node2;DONE setting up all server attributes, number set <88>
02/14/2018 04:11:38;0106;Server@node2;Svr;Server@node2;BEGIN setting up all reservation attributes 
02/14/2018 04:11:38;0106;Server@node2;Svr;Server@node2;DONE setting up all reservation attributes, number set <43>
02/14/2018 04:11:38;0106;Server@node2;Svr;Server@node2;BEGIN setting up all vnode attributes 
02/14/2018 04:11:38;0106;Server@node2;Svr;Server@node2;DONE setting up all vnode attributes, number set <28>
02/14/2018 04:11:38;0100;Server@node2;Hook;_pbs_python_event_set;Current memory usage: VmSize=321836kB, VmRSS=13204kB
02/14/2018 04:11:38;0100;Server@node2;Req;;Type 20 request received from Scheduler@node2.supernodexp.hpc, sock=20
02/14/2018 04:11:38;0100;Server@node2;Req;;Type 3 request received from ctminh@node2.supernodexp.hpc, sock=16
02/14/2018 04:11:38;0100;Server@node2;Req;;Type 51 request received from Scheduler@node2.supernodexp.hpc, sock=20
02/14/2018 04:11:38;0100;Server@node2;Req;;Type 5 request received from ctminh@node2.supernodexp.hpc, sock=16
02/14/2018 04:11:38;0100;Server@node2;Job;1100.node2.supernodexp.hpc;enqueuing into workq, state 1 hop 1
02/14/2018 04:11:38;0008;Server@node2;Job;1100.node2.supernodexp.hpc;Job Queued at request of ctminh@node2.supernodexp.hpc, owner = ctminh@node2.supernodexp.hpc, job name = sweep, queue = workq
02/14/2018 04:11:38;0100;Server@node2;Req;;Type 1 request received from ctminh@node2.supernodexp.hpc, sock=16
02/14/2018 04:11:38;0100;Server@node2;Req;;Type 3 request received from ctminh@node2.supernodexp.hpc, sock=16
02/14/2018 04:11:38;0100;Server@node2;Req;;Type 5 request received from ctminh@node2.supernodexp.hpc, sock=16
02/14/2018 04:11:38;0100;Server@node2;Job;1101.node2.supernodexp.hpc;enqueuing into workq, state 1 hop 1
02/14/2018 04:11:38;0008;Server@node2;Job;1101.node2.supernodexp.hpc;Job Queued at request of ctminh@node2.supernodexp.hpc, owner = ctminh@node2.supernodexp.hpc, job name = sweep, queue = workq
02/14/2018 04:11:38;0100;Server@node2;Req;;Type 1 request received from ctminh@node2.supernodexp.hpc, sock=16
02/14/2018 04:11:38;0100;Server@node2;Req;;Type 3 request received from ctminh@node2.supernodexp.hpc, sock=16
02/14/2018 04:11:38;0100;Server@node2;Req;;Type 5 request received from ctminh@node2.supernodexp.hpc, sock=16
02/14/2018 04:11:38;0100;Server@node2;Job;1102.node2.supernodexp.hpc;enqueuing into workq, state 1 hop 1
02/14/2018 04:11:38;0008;Server@node2;Job;1102.node2.supernodexp.hpc;Job Queued at request of ctminh@node2.supernodexp.hpc, owner = ctminh@node2.supernodexp.hpc, job name = telemac3, queue = workq
02/14/2018 04:11:38;0100;Server@node2;Req;;Type 1 request received from ctminh@node2.supernodexp.hpc, sock=16
02/14/2018 04:11:38;0100;Server@node2;Req;;Type 11 request received from Scheduler@node2.supernodexp.hpc, sock=20
02/14/2018 04:11:38;0008;Server@node2;Job;1098.node2.supernodexp.hpc;Job Modified at request of Scheduler@node2.supernodexp.hpc
02/14/2018 04:11:38;0100;Server@node2;Req;;Type 3 request received from ctminh@node2.supernodexp.hpc, sock=16
02/14/2018 04:11:38;0100;Server@node2;Req;;Type 5 request received from ctminh@node2.supernodexp.hpc, sock=16
02/14/2018 04:11:38;0100;Server@node2;Job;1103.node2.supernodexp.hpc;enqueuing into workq, state 1 hop 1
02/14/2018 04:11:38;0008;Server@node2;Job;1103.node2.supernodexp.hpc;Job Queued at request of ctminh@node2.supernodexp.hpc, owner = ctminh@node2.supernodexp.hpc, job name = qe_mic_test, queue = workq
02/14/2018 04:11:38;0100;Server@node2;Req;;Type 11 request received from Scheduler@node2.supernodexp.hpc, sock=20
02/14/2018 04:11:38;0008;Server@node2;Job;1096.node2.supernodexp.hpc;Job Modified at request of Scheduler@node2.supernodexp.hpc
02/14/2018 04:11:38;0100;Server@node2;Req;;Type 11 request received from Scheduler@node2.supernodexp.hpc, sock=20
02/14/2018 04:11:38;0008;Server@node2;Job;1097.node2.supernodexp.hpc;Job Modified at request of Scheduler@node2.supernodexp.hpc
02/14/2018 04:11:38;0100;Server@node2;Req;;Type 11 request received from Scheduler@node2.supernodexp.hpc, sock=20
02/14/2018 04:11:38;0008;Server@node2;Job;1099.node2.supernodexp.hpc;Job Modified at request of Scheduler@node2.supernodexp.hpc
02/14/2018 04:11:38;0040;Server@node2;Svr;node2.supernodexp.hpc;Scheduler sent command 1
02/14/2018 04:11:38;0040;Server@node2;Svr;node2.supernodexp.hpc;Scheduler sent command 0
02/14/2018 04:11:38;0100;Server@node2;Req;;Type 21 request received from Scheduler@node2.supernodexp.hpc, sock=20
02/14/2018 04:11:38;0100;Server@node2;Req;;Type 81 request received from Scheduler@node2.supernodexp.hpc, sock=20
02/14/2018 04:11:38;0100;Server@node2;Req;;Type 71 request received from Scheduler@node2.supernodexp.hpc, sock=20
02/14/2018 04:11:38;0100;Server@node2;Req;;Type 58 request received from Scheduler@node2.supernodexp.hpc, sock=20
02/14/2018 04:11:38;0100;Server@node2;Req;;Type 1 request received from ctminh@node2.supernodexp.hpc, sock=16
02/14/2018 04:11:38;0100;Server@node2;Req;;Type 3 request received from ctminh@node2.supernodexp.hpc, sock=16
02/14/2018 04:11:38;0100;Server@node2;Req;;Type 5 request received from ctminh@node2.supernodexp.hpc, sock=16
02/14/2018 04:11:38;0100;Server@node2;Job;1104.node2.supernodexp.hpc;enqueuing into workq, state 1 hop 1
02/14/2018 04:11:38;0008;Server@node2;Job;1104.node2.supernodexp.hpc;Job Queued at request of ctminh@node2.supernodexp.hpc, owner = ctminh@node2.supernodexp.hpc, job name = telemac3, queue = workq
02/14/2018 04:11:38;0100;Server@node2;Req;;Type 1 request received from ctminh@node2.supernodexp.hpc, sock=16
02/14/2018 04:11:38;0100;Server@node2;Req;;Type 3 request received from ctminh@node2.supernodexp.hpc, sock=16
02/14/2018 04:11:38;0100;Server@node2;Req;;Type 5 request received from ctminh@node2.supernodexp.hpc, sock=16
02/14/2018 04:11:38;0100;Server@node2;Job;1105.node2.supernodexp.hpc;enqueuing into workq, state 1 hop 1
02/14/2018 04:11:38;0008;Server@node2;Job;1105.node2.supernodexp.hpc;Job Queued at request of ctminh@node2.supernodexp.hpc, owner = ctminh@node2.supernodexp.hpc, job name = nbody, queue = workq
02/14/2018 04:11:38;0100;Server@node2;Req;;Type 20 request received from Scheduler@node2.supernodexp.hpc, sock=20
02/14/2018 04:11:38;0100;Server@node2;Req;;Type 51 request received from Scheduler@node2.supernodexp.hpc, sock=20
02/14/2018 04:11:38;0100;Server@node2;Req;;Type 1 request received from ctminh@node2.supernodexp.hpc, sock=16
02/14/2018 04:11:38;0100;Server@node2;Req;;Type 3 request received from ctminh@node2.supernodexp.hpc, sock=16
02/14/2018 04:11:38;0100;Server@node2;Req;;Type 5 request received from ctminh@node2.supernodexp.hpc, sock=16
02/14/2018 04:11:38;0100;Server@node2;Job;1106.node2.supernodexp.hpc;enqueuing into workq, state 1 hop 1
02/14/2018 04:11:38;0008;Server@node2;Job;1106.node2.supernodexp.hpc;Job Queued at request of ctminh@node2.supernodexp.hpc, owner = ctminh@node2.supernodexp.hpc, job name = lu-decomp, queue = workq
02/14/2018 04:11:38;0100;Server@node2;Req;;Type 1 request received from ctminh@node2.supernodexp.hpc, sock=16
02/14/2018 04:11:38;0100;Server@node2;Req;;Type 3 request received from ctminh@node2.supernodexp.hpc, sock=16
02/14/2018 04:11:38;0100;Server@node2;Req;;Type 5 request received from ctminh@node2.supernodexp.hpc, sock=16
02/14/2018 04:11:38;0100;Server@node2;Job;1107.node2.supernodexp.hpc;enqueuing into workq, state 1 hop 1
02/14/2018 04:11:38;0008;Server@node2;Job;1107.node2.supernodexp.hpc;Job Queued at request of ctminh@node2.supernodexp.hpc, owner = ctminh@node2.supernodexp.hpc, job name = histogram, queue = workq
02/14/2018 04:11:38;0100;Server@node2;Req;;Type 11 request received from Scheduler@node2.supernodexp.hpc, sock=20
02/14/2018 04:11:38;0008;Server@node2;Job;1103.node2.supernodexp.hpc;Job Modified at request of Scheduler@node2.supernodexp.hpc
02/14/2018 04:11:38;0100;Server@node2;Req;;Type 1 request received from ctminh@node2.supernodexp.hpc, sock=16
02/14/2018 04:11:38;0100;Server@node2;Req;;Type 11 request received from Scheduler@node2.supernodexp.hpc, sock=20
02/14/2018 04:11:38;0008;Server@node2;Job;1102.node2.supernodexp.hpc;Job Modified at request of Scheduler@node2.supernodexp.hpc
02/14/2018 04:11:38;0100;Server@node2;Req;;Type 3 request received from ctminh@node2.supernodexp.hpc, sock=16
02/14/2018 04:11:38;0100;Server@node2;Req;;Type 11 request received from Scheduler@node2.supernodexp.hpc, sock=20
02/14/2018 04:11:38;0008;Server@node2;Job;1104.node2.supernodexp.hpc;Job Modified at request of Scheduler@node2.supernodexp.hpc
02/14/2018 04:11:38;0100;Server@node2;Req;;Type 5 request received from ctminh@node2.supernodexp.hpc, sock=16
02/14/2018 04:11:38;0100;Server@node2;Job;1108.node2.supernodexp.hpc;enqueuing into workq, state 1 hop 1
02/14/2018 04:11:38;0008;Server@node2;Job;1108.node2.supernodexp.hpc;Job Queued at request of ctminh@node2.supernodexp.hpc, owner = ctminh@node2.supernodexp.hpc, job name = jacobi, queue = workq
02/14/2018 04:11:38;0100;Server@node2;Req;;Type 11 request received from Scheduler@node2.supernodexp.hpc, sock=20
02/14/2018 04:11:38;0008;Server@node2;Job;1105.node2.supernodexp.hpc;Job Modified at request of Scheduler@node2.supernodexp.hpc
02/14/2018 04:11:38;0100;Server@node2;Req;;Type 11 request received from Scheduler@node2.supernodexp.hpc, sock=20
02/14/2018 04:11:38;0008;Server@node2;Job;1100.node2.supernodexp.hpc;Job Modified at request of Scheduler@node2.supernodexp.hpc
02/14/2018 04:11:38;0100;Server@node2;Req;;Type 11 request received from Scheduler@node2.supernodexp.hpc, sock=20
02/14/2018 04:11:38;0008;Server@node2;Job;1101.node2.supernodexp.hpc;Job Modified at request of Scheduler@node2.supernodexp.hpc
02/14/2018 04:11:38;0040;Server@node2;Svr;node2.supernodexp.hpc;Scheduler sent command 1
02/14/2018 04:11:38;0040;Server@node2;Svr;node2.supernodexp.hpc;Scheduler sent command 0
02/14/2018 04:11:38;0100;Server@node2;Req;;Type 21 request received from Scheduler@node2.supernodexp.hpc, sock=20
02/14/2018 04:11:38;0100;Server@node2;Req;;Type 81 request received from Scheduler@node2.supernodexp.hpc, sock=20
02/14/2018 04:11:38;0100;Server@node2;Req;;Type 71 request received from Scheduler@node2.supernodexp.hpc, sock=20
02/14/2018 04:11:38;0100;Server@node2;Req;;Type 58 request received from Scheduler@node2.supernodexp.hpc, sock=20
02/14/2018 04:11:38;0100;Server@node2;Req;;Type 1 request received from ctminh@node2.supernodexp.hpc, sock=16
02/14/2018 04:11:38;0100;Server@node2;Req;;Type 3 request received from ctminh@node2.supernodexp.hpc, sock=16
02/14/2018 04:11:38;0100;Server@node2;Req;;Type 5 request received from ctminh@node2.supernodexp.hpc, sock=16
02/14/2018 04:11:38;0100;Server@node2;Job;1109.node2.supernodexp.hpc;enqueuing into workq, state 1 hop 1
02/14/2018 04:11:38;0008;Server@node2;Job;1109.node2.supernodexp.hpc;Job Queued at request of ctminh@node2.supernodexp.hpc, owner = ctminh@node2.supernodexp.hpc, job name = sweep, queue = workq
02/14/2018 04:11:38;0100;Server@node2;Req;;Type 1 request received from ctminh@node2.supernodexp.hpc, sock=16
02/14/2018 04:11:38;0100;Server@node2;Req;;Type 3 request received from ctminh@node2.supernodexp.hpc, sock=16
02/14/2018 04:11:38;0100;Server@node2;Req;;Type 5 request received from ctminh@node2.supernodexp.hpc, sock=16
02/14/2018 04:11:38;0100;Server@node2;Job;1110.node2.supernodexp.hpc;enqueuing into workq, state 1 hop 1
02/14/2018 04:11:38;0008;Server@node2;Job;1110.node2.supernodexp.hpc;Job Queued at request of ctminh@node2.supernodexp.hpc, owner = ctminh@node2.supernodexp.hpc, job name = thread-affinity, queue = workq
02/14/2018 04:11:38;0100;Server@node2;Req;;Type 20 request received from Scheduler@node2.supernodexp.hpc, sock=20
02/14/2018 04:11:38;0100;Server@node2;Req;;Type 51 request received from Scheduler@node2.supernodexp.hpc, sock=20
02/14/2018 04:11:38;0100;Server@node2;Req;;Type 1 request received from ctminh@node2.supernodexp.hpc, sock=16
02/14/2018 04:11:38;0100;Server@node2;Req;;Type 3 request received from ctminh@node2.supernodexp.hpc, sock=16
02/14/2018 04:11:38;0100;Server@node2;Req;;Type 5 request received from ctminh@node2.supernodexp.hpc, sock=16
02/14/2018 04:11:38;0100;Server@node2;Job;1111.node2.supernodexp.hpc;enqueuing into workq, state 1 hop 1
02/14/2018 04:11:38;0008;Server@node2;Job;1111.node2.supernodexp.hpc;Job Queued at request of ctminh@node2.supernodexp.hpc, owner = ctminh@node2.supernodexp.hpc, job name = qe_mic_test, queue = workq
02/14/2018 04:11:38;0100;Server@node2;Req;;Type 1 request received from ctminh@node2.supernodexp.hpc, sock=16
02/14/2018 04:11:38;0100;Server@node2;Req;;Type 3 request received from ctminh@node2.supernodexp.hpc, sock=16
02/14/2018 04:11:38;0100;Server@node2;Req;;Type 5 request received from ctminh@node2.supernodexp.hpc, sock=16
02/14/2018 04:11:38;0100;Server@node2;Job;1112.node2.supernodexp.hpc;enqueuing into workq, state 1 hop 1
02/14/2018 04:11:38;0008;Server@node2;Job;1112.node2.supernodexp.hpc;Job Queued at request of ctminh@node2.supernodexp.hpc, owner = ctminh@node2.supernodexp.hpc, job name = matrix-x-vector, queue = workq
02/14/2018 04:11:38;0100;Server@node2;Req;;Type 1 request received from ctminh@node2.supernodexp.hpc, sock=16
02/14/2018 04:11:38;0100;Server@node2;Req;;Type 3 request received from ctminh@node2.supernodexp.hpc, sock=16
02/14/2018 04:11:38;0100;Server@node2;Req;;Type 5 request received from ctminh@node2.supernodexp.hpc, sock=16
02/14/2018 04:11:38;0100;Server@node2;Job;1113.node2.supernodexp.hpc;enqueuing into workq, state 1 hop 1
02/14/2018 04:11:38;0008;Server@node2;Job;1113.node2.supernodexp.hpc;Job Queued at request of ctminh@node2.supernodexp.hpc, owner = ctminh@node2.supernodexp.hpc, job name = vast1, queue = workq
02/14/2018 04:11:38;0100;Server@node2;Req;;Type 1 request received from ctminh@node2.supernodexp.hpc, sock=16
02/14/2018 04:11:38;0100;Server@node2;Req;;Type 3 request received from ctminh@node2.supernodexp.hpc, sock=16
02/14/2018 04:11:38;0100;Server@node2;Req;;Type 5 request received from ctminh@node2.supernodexp.hpc, sock=16
02/14/2018 04:11:38;0100;Server@node2;Job;1114.node2.supernodexp.hpc;enqueuing into workq, state 1 hop 1
02/14/2018 04:11:38;0008;Server@node2;Job;1114.node2.supernodexp.hpc;Job Queued at request of ctminh@node2.supernodexp.hpc, owner = ctminh@node2.supernodexp.hpc, job name = vast1, queue = workq
02/14/2018 04:11:38;0100;Server@node2;Req;;Type 11 request received from Scheduler@node2.supernodexp.hpc, sock=20
02/14/2018 04:11:38;0008;Server@node2;Job;1108.node2.supernodexp.hpc;Job Modified at request of Scheduler@node2.supernodexp.hpc
02/14/2018 04:11:38;0100;Server@node2;Req;;Type 11 request received from Scheduler@node2.supernodexp.hpc, sock=20
02/14/2018 04:11:38;0008;Server@node2;Job;1110.node2.supernodexp.hpc;Job Modified at request of Scheduler@node2.supernodexp.hpc
02/14/2018 04:11:38;0100;Server@node2;Req;;Type 11 request received from Scheduler@node2.supernodexp.hpc, sock=20
02/14/2018 04:11:38;0008;Server@node2;Job;1107.node2.supernodexp.hpc;Job Modified at request of Scheduler@node2.supernodexp.hpc
02/14/2018 04:11:38;0100;Server@node2;Req;;Type 11 request received from Scheduler@node2.supernodexp.hpc, sock=20
02/14/2018 04:11:38;0008;Server@node2;Job;1109.node2.supernodexp.hpc;Job Modified at request of Scheduler@node2.supernodexp.hpc
02/14/2018 04:11:38;0100;Server@node2;Req;;Type 11 request received from Scheduler@node2.supernodexp.hpc, sock=20
02/14/2018 04:11:38;0008;Server@node2;Job;1106.node2.supernodexp.hpc;Job Modified at request of Scheduler@node2.supernodexp.hpc
02/14/2018 04:11:38;0040;Server@node2;Svr;node2.supernodexp.hpc;Scheduler sent command 1
02/14/2018 04:11:38;0040;Server@node2;Svr;node2.supernodexp.hpc;Scheduler sent command 0
02/14/2018 04:11:38;0100;Server@node2;Req;;Type 21 request received from Scheduler@node2.supernodexp.hpc, sock=20
02/14/2018 04:11:38;0100;Server@node2;Req;;Type 81 request received from Scheduler@node2.supernodexp.hpc, sock=20
02/14/2018 04:11:38;0100;Server@node2;Req;;Type 71 request received from Scheduler@node2.supernodexp.hpc, sock=20
02/14/2018 04:11:38;0100;Server@node2;Req;;Type 58 request received from Scheduler@node2.supernodexp.hpc, sock=20
02/14/2018 04:11:38;0100;Server@node2;Req;;Type 1 request received from ctminh@node2.supernodexp.hpc, sock=16
02/14/2018 04:11:38;0100;Server@node2;Req;;Type 3 request received from ctminh@node2.supernodexp.hpc, sock=16
02/14/2018 04:11:38;0100;Server@node2;Req;;Type 5 request received from ctminh@node2.supernodexp.hpc, sock=16
02/14/2018 04:11:38;0100;Server@node2;Job;1115.node2.supernodexp.hpc;enqueuing into workq, state 1 hop 1
02/14/2018 04:11:38;0008;Server@node2;Job;1115.node2.supernodexp.hpc;Job Queued at request of ctminh@node2.supernodexp.hpc, owner = ctminh@node2.supernodexp.hpc, job name = telemac3, queue = workq
02/14/2018 04:11:38;0100;Server@node2;Req;;Type 1 request received from ctminh@node2.supernodexp.hpc, sock=16
02/14/2018 04:11:38;0100;Server@node2;Req;;Type 3 request received from ctminh@node2.supernodexp.hpc, sock=16
02/14/2018 04:11:38;0100;Server@node2;Req;;Type 5 request received from ctminh@node2.supernodexp.hpc, sock=16
02/14/2018 04:11:38;0100;Server@node2;Job;1116.node2.supernodexp.hpc;enqueuing into workq, state 1 hop 1
02/14/2018 04:11:38;0008;Server@node2;Job;1116.node2.supernodexp.hpc;Job Queued at request of ctminh@node2.supernodexp.hpc, owner = ctminh@node2.supernodexp.hpc, job name = histogram, queue = workq
02/14/2018 04:11:38;0100;Server@node2;Req;;Type 1 request received from ctminh@node2.supernodexp.hpc, sock=16
02/14/2018 04:11:38;0100;Server@node2;Req;;Type 20 request received from Scheduler@node2.supernodexp.hpc, sock=20
02/14/2018 04:11:38;0100;Server@node2;Req;;Type 3 request received from ctminh@node2.supernodexp.hpc, sock=16
02/14/2018 04:11:38;0100;Server@node2;Req;;Type 51 request received from Scheduler@node2.supernodexp.hpc, sock=20
02/14/2018 04:11:38;0100;Server@node2;Req;;Type 5 request received from ctminh@node2.supernodexp.hpc, sock=16
02/14/2018 04:11:38;0100;Server@node2;Job;1117.node2.supernodexp.hpc;enqueuing into workq, state 1 hop 1
02/14/2018 04:11:38;0008;Server@node2;Job;1117.node2.supernodexp.hpc;Job Queued at request of ctminh@node2.supernodexp.hpc, owner = ctminh@node2.supernodexp.hpc, job name = telemac2, queue = workq
02/14/2018 04:11:38;0100;Server@node2;Req;;Type 1 request received from ctminh@node2.supernodexp.hpc, sock=16
02/14/2018 04:11:38;0100;Server@node2;Req;;Type 3 request received from ctminh@node2.supernodexp.hpc, sock=16
02/14/2018 04:11:38;0100;Server@node2;Req;;Type 5 request received from ctminh@node2.supernodexp.hpc, sock=16
02/14/2018 04:11:38;0100;Server@node2;Job;1118.node2.supernodexp.hpc;enqueuing into workq, state 1 hop 1
02/14/2018 04:11:38;0008;Server@node2;Job;1118.node2.supernodexp.hpc;Job Queued at request of ctminh@node2.supernodexp.hpc, owner = ctminh@node2.supernodexp.hpc, job name = matrix-x-vector, queue = workq
02/14/2018 04:11:38;0100;Server@node2;Req;;Type 1 request received from ctminh@node2.supernodexp.hpc, sock=16
02/14/2018 04:11:38;0100;Server@node2;Req;;Type 3 request received from ctminh@node2.supernodexp.hpc, sock=16
02/14/2018 04:11:38;0100;Server@node2;Req;;Type 5 request received from ctminh@node2.supernodexp.hpc, sock=16
02/14/2018 04:11:38;0100;Server@node2;Job;1119.node2.supernodexp.hpc;enqueuing into workq, state 1 hop 1
02/14/2018 04:11:38;0008;Server@node2;Job;1119.node2.supernodexp.hpc;Job Queued at request of ctminh@node2.supernodexp.hpc, owner = ctminh@node2.supernodexp.hpc, job name = telemac2, queue = workq
02/14/2018 04:11:38;0100;Server@node2;Req;;Type 1 request received from ctminh@node2.supernodexp.hpc, sock=16
02/14/2018 04:11:38;0100;Server@node2;Req;;Type 3 request received from ctminh@node2.supernodexp.hpc, sock=16
02/14/2018 04:11:38;0100;Server@node2;Req;;Type 5 request received from ctminh@node2.supernodexp.hpc, sock=16
02/14/2018 04:11:38;0100;Server@node2;Job;1120.node2.supernodexp.hpc;enqueuing into workq, state 1 hop 1
02/14/2018 04:11:38;0008;Server@node2;Job;1120.node2.supernodexp.hpc;Job Queued at request of ctminh@node2.supernodexp.hpc, owner = ctminh@node2.supernodexp.hpc, job name = qe_mic_test, queue = workq
02/14/2018 04:11:38;0100;Server@node2;Req;;Type 11 request received from Scheduler@node2.supernodexp.hpc, sock=20
02/14/2018 04:11:38;0008;Server@node2;Job;1111.node2.supernodexp.hpc;Job Modified at request of Scheduler@node2.supernodexp.hpc
02/14/2018 04:11:38;0100;Server@node2;Req;;Type 11 request received from Scheduler@node2.supernodexp.hpc, sock=20
02/14/2018 04:11:38;0008;Server@node2;Job;1113.node2.supernodexp.hpc;Job Modified at request of Scheduler@node2.supernodexp.hpc
02/14/2018 04:11:38;0100;Server@node2;Req;;Type 11 request received from Scheduler@node2.supernodexp.hpc, sock=20
02/14/2018 04:11:38;0008;Server@node2;Job;1114.node2.supernodexp.hpc;Job Modified at request of Scheduler@node2.supernodexp.hpc
02/14/2018 04:11:38;0100;Server@node2;Req;;Type 11 request received from Scheduler@node2.supernodexp.hpc, sock=20
02/14/2018 04:11:38;0008;Server@node2;Job;1115.node2.supernodexp.hpc;Job Modified at request of Scheduler@node2.supernodexp.hpc
02/14/2018 04:11:38;0100;Server@node2;Req;;Type 11 request received from Scheduler@node2.supernodexp.hpc, sock=20
02/14/2018 04:11:38;0008;Server@node2;Job;1116.node2.supernodexp.hpc;Job Modified at request of Scheduler@node2.supernodexp.hpc
02/14/2018 04:11:38;0100;Server@node2;Req;;Type 11 request received from Scheduler@node2.supernodexp.hpc, sock=20
02/14/2018 04:11:38;0008;Server@node2;Job;1112.node2.supernodexp.hpc;Job Modified at request of Scheduler@node2.supernodexp.hpc
02/14/2018 04:11:38;0040;Server@node2;Svr;node2.supernodexp.hpc;Scheduler sent command 1
02/14/2018 04:11:38;0040;Server@node2;Svr;node2.supernodexp.hpc;Scheduler sent command 0
02/14/2018 04:11:38;0100;Server@node2;Req;;Type 21 request received from Scheduler@node2.supernodexp.hpc, sock=20
02/14/2018 04:11:38;0100;Server@node2;Req;;Type 81 request received from Scheduler@node2.supernodexp.hpc, sock=20
02/14/2018 04:11:38;0100;Server@node2;Req;;Type 71 request received from Scheduler@node2.supernodexp.hpc, sock=20
02/14/2018 04:11:38;0100;Server@node2;Req;;Type 58 request received from Scheduler@node2.supernodexp.hpc, sock=20
02/14/2018 04:11:38;0100;Server@node2;Req;;Type 20 request received from Scheduler@node2.supernodexp.hpc, sock=20
02/14/2018 04:11:38;0100;Server@node2;Req;;Type 51 request received from Scheduler@node2.supernodexp.hpc, sock=20
02/14/2018 04:11:38;0100;Server@node2;Req;;Type 11 request received from Scheduler@node2.supernodexp.hpc, sock=20
02/14/2018 04:11:38;0008;Server@node2;Job;1120.node2.supernodexp.hpc;Job Modified at request of Scheduler@node2.supernodexp.hpc
02/14/2018 04:11:38;0100;Server@node2;Req;;Type 11 request received from Scheduler@node2.supernodexp.hpc, sock=20
02/14/2018 04:11:38;0008;Server@node2;Job;1117.node2.supernodexp.hpc;Job Modified at request of Scheduler@node2.supernodexp.hpc
02/14/2018 04:11:38;0100;Server@node2;Req;;Type 11 request received from Scheduler@node2.supernodexp.hpc, sock=20
02/14/2018 04:11:38;0008;Server@node2;Job;1119.node2.supernodexp.hpc;Job Modified at request of Scheduler@node2.supernodexp.hpc
02/14/2018 04:11:38;0100;Server@node2;Req;;Type 11 request received from Scheduler@node2.supernodexp.hpc, sock=20
02/14/2018 04:11:38;0008;Server@node2;Job;1118.node2.supernodexp.hpc;Job Modified at request of Scheduler@node2.supernodexp.hpc
02/14/2018 04:12:18;0100;Server@node2;Req;;Type 1 request received from ctminh@node2.supernodexp.hpc, sock=16
02/14/2018 04:12:18;0100;Server@node2;Req;;Type 3 request received from ctminh@node2.supernodexp.hpc, sock=16
02/14/2018 04:12:18;0100;Server@node2;Req;;Type 5 request received from ctminh@node2.supernodexp.hpc, sock=16
02/14/2018 04:12:18;0100;Server@node2;Job;1121.node2.supernodexp.hpc;enqueuing into workq, state 1 hop 1
02/14/2018 04:12:18;0008;Server@node2;Job;1121.node2.supernodexp.hpc;Job Queued at request of ctminh@node2.supernodexp.hpc, owner = ctminh@node2.supernodexp.hpc, job name = telemac1, queue = workq
02/14/2018 04:12:18;0040;Server@node2;Svr;node2.supernodexp.hpc;Scheduler sent command 1
02/14/2018 04:12:18;0040;Server@node2;Svr;node2.supernodexp.hpc;Scheduler sent command 0
02/14/2018 04:12:18;0100;Server@node2;Req;;Type 21 request received from Scheduler@node2.supernodexp.hpc, sock=20
02/14/2018 04:12:18;0100;Server@node2;Req;;Type 81 request received from Scheduler@node2.supernodexp.hpc, sock=20
02/14/2018 04:12:18;0100;Server@node2;Req;;Type 71 request received from Scheduler@node2.supernodexp.hpc, sock=20
02/14/2018 04:12:18;0100;Server@node2;Req;;Type 58 request received from Scheduler@node2.supernodexp.hpc, sock=20
02/14/2018 04:12:18;0100;Server@node2;Req;;Type 1 request received from ctminh@node2.supernodexp.hpc, sock=16
02/14/2018 04:12:18;0100;Server@node2;Req;;Type 3 request received from ctminh@node2.supernodexp.hpc, sock=16
02/14/2018 04:12:18;0100;Server@node2;Req;;Type 5 request received from ctminh@node2.supernodexp.hpc, sock=16
02/14/2018 04:12:18;0100;Server@node2;Job;1122.node2.supernodexp.hpc;enqueuing into workq, state 1 hop 1
02/14/2018 04:12:18;0008;Server@node2;Job;1122.node2.supernodexp.hpc;Job Queued at request of ctminh@node2.supernodexp.hpc, owner = ctminh@node2.supernodexp.hpc, job name = matrix-x-vector, queue = workq
02/14/2018 04:12:18;0100;Server@node2;Req;;Type 1 request received from ctminh@node2.supernodexp.hpc, sock=16
02/14/2018 04:12:18;0100;Server@node2;Req;;Type 3 request received from ctminh@node2.supernodexp.hpc, sock=16
02/14/2018 04:12:18;0100;Server@node2;Req;;Type 5 request received from ctminh@node2.supernodexp.hpc, sock=16
02/14/2018 04:12:18;0100;Server@node2;Job;1123.node2.supernodexp.hpc;enqueuing into workq, state 1 hop 1
02/14/2018 04:12:18;0008;Server@node2;Job;1123.node2.supernodexp.hpc;Job Queued at request of ctminh@node2.supernodexp.hpc, owner = ctminh@node2.supernodexp.hpc, job name = vast1, queue = workq
02/14/2018 04:12:18;0100;Server@node2;Req;;Type 1 request received from ctminh@node2.supernodexp.hpc, sock=16
02/14/2018 04:12:18;0100;Server@node2;Req;;Type 20 request received from Scheduler@node2.supernodexp.hpc, sock=20
02/14/2018 04:12:18;0100;Server@node2;Req;;Type 3 request received from ctminh@node2.supernodexp.hpc, sock=16
02/14/2018 04:12:18;0100;Server@node2;Req;;Type 51 request received from Scheduler@node2.supernodexp.hpc, sock=20
02/14/2018 04:12:18;0100;Server@node2;Req;;Type 5 request received from ctminh@node2.supernodexp.hpc, sock=16
02/14/2018 04:12:18;0100;Server@node2;Job;1124.node2.supernodexp.hpc;enqueuing into workq, state 1 hop 1
02/14/2018 04:12:18;0008;Server@node2;Job;1124.node2.supernodexp.hpc;Job Queued at request of ctminh@node2.supernodexp.hpc, owner = ctminh@node2.supernodexp.hpc, job name = thread-affinity, queue = workq
02/14/2018 04:12:18;0100;Server@node2;Req;;Type 1 request received from ctminh@node2.supernodexp.hpc, sock=16
02/14/2018 04:12:18;0100;Server@node2;Req;;Type 3 request received from ctminh@node2.supernodexp.hpc, sock=16
02/14/2018 04:12:18;0100;Server@node2;Req;;Type 5 request received from ctminh@node2.supernodexp.hpc, sock=16
02/14/2018 04:12:18;0100;Server@node2;Job;1125.node2.supernodexp.hpc;enqueuing into workq, state 1 hop 1
02/14/2018 04:12:18;0008;Server@node2;Job;1125.node2.supernodexp.hpc;Job Queued at request of ctminh@node2.supernodexp.hpc, owner = ctminh@node2.supernodexp.hpc, job name = lu-decomp, queue = workq
02/14/2018 04:12:18;0100;Server@node2;Req;;Type 1 request received from ctminh@node2.supernodexp.hpc, sock=16
02/14/2018 04:12:18;0100;Server@node2;Req;;Type 3 request received from ctminh@node2.supernodexp.hpc, sock=16
02/14/2018 04:12:18;0100;Server@node2;Req;;Type 5 request received from ctminh@node2.supernodexp.hpc, sock=16
02/14/2018 04:12:18;0100;Server@node2;Job;1126.node2.supernodexp.hpc;enqueuing into workq, state 1 hop 1
02/14/2018 04:12:18;0008;Server@node2;Job;1126.node2.supernodexp.hpc;Job Queued at request of ctminh@node2.supernodexp.hpc, owner = ctminh@node2.supernodexp.hpc, job name = telemac1, queue = workq
02/14/2018 04:12:18;0100;Server@node2;Req;;Type 1 request received from ctminh@node2.supernodexp.hpc, sock=16
02/14/2018 04:12:18;0100;Server@node2;Req;;Type 3 request received from ctminh@node2.supernodexp.hpc, sock=16
02/14/2018 04:12:18;0100;Server@node2;Req;;Type 5 request received from ctminh@node2.supernodexp.hpc, sock=16
02/14/2018 04:12:18;0100;Server@node2;Job;1127.node2.supernodexp.hpc;enqueuing into workq, state 1 hop 1
02/14/2018 04:12:18;0008;Server@node2;Job;1127.node2.supernodexp.hpc;Job Queued at request of ctminh@node2.supernodexp.hpc, owner = ctminh@node2.supernodexp.hpc, job name = vectorization, queue = workq
02/14/2018 04:12:18;0100;Server@node2;Req;;Type 1 request received from ctminh@node2.supernodexp.hpc, sock=16
02/14/2018 04:12:18;0100;Server@node2;Req;;Type 11 request received from Scheduler@node2.supernodexp.hpc, sock=20
02/14/2018 04:12:18;0008;Server@node2;Job;1123.node2.supernodexp.hpc;Job Modified at request of Scheduler@node2.supernodexp.hpc
02/14/2018 04:12:18;0100;Server@node2;Req;;Type 3 request received from ctminh@node2.supernodexp.hpc, sock=16
02/14/2018 04:12:18;0100;Server@node2;Req;;Type 5 request received from ctminh@node2.supernodexp.hpc, sock=16
02/14/2018 04:12:18;0100;Server@node2;Job;1128.node2.supernodexp.hpc;enqueuing into workq, state 1 hop 1
02/14/2018 04:12:18;0008;Server@node2;Job;1128.node2.supernodexp.hpc;Job Queued at request of ctminh@node2.supernodexp.hpc, owner = ctminh@node2.supernodexp.hpc, job name = qe_mic_test, queue = workq
02/14/2018 04:12:18;0100;Server@node2;Req;;Type 11 request received from Scheduler@node2.supernodexp.hpc, sock=20
02/14/2018 04:12:18;0008;Server@node2;Job;1121.node2.supernodexp.hpc;Job Modified at request of Scheduler@node2.supernodexp.hpc
02/14/2018 04:12:18;0100;Server@node2;Req;;Type 11 request received from Scheduler@node2.supernodexp.hpc, sock=20
02/14/2018 04:12:18;0008;Server@node2;Job;1122.node2.supernodexp.hpc;Job Modified at request of Scheduler@node2.supernodexp.hpc
02/14/2018 04:12:18;0040;Server@node2;Svr;node2.supernodexp.hpc;Scheduler sent command 1
02/14/2018 04:12:18;0040;Server@node2;Svr;node2.supernodexp.hpc;Scheduler sent command 0
02/14/2018 04:12:18;0100;Server@node2;Req;;Type 21 request received from Scheduler@node2.supernodexp.hpc, sock=20
02/14/2018 04:12:18;0100;Server@node2;Req;;Type 81 request received from Scheduler@node2.supernodexp.hpc, sock=20
02/14/2018 04:12:18;0100;Server@node2;Req;;Type 71 request received from Scheduler@node2.supernodexp.hpc, sock=20
02/14/2018 04:12:18;0100;Server@node2;Req;;Type 58 request received from Scheduler@node2.supernodexp.hpc, sock=20
02/14/2018 04:12:18;0100;Server@node2;Req;;Type 1 request received from ctminh@node2.supernodexp.hpc, sock=16
02/14/2018 04:12:18;0100;Server@node2;Req;;Type 3 request received from ctminh@node2.supernodexp.hpc, sock=16
02/14/2018 04:12:18;0100;Server@node2;Req;;Type 5 request received from ctminh@node2.supernodexp.hpc, sock=16
02/14/2018 04:12:18;0100;Server@node2;Job;1129.node2.supernodexp.hpc;enqueuing into workq, state 1 hop 1
02/14/2018 04:12:18;0008;Server@node2;Job;1129.node2.supernodexp.hpc;Job Queued at request of ctminh@node2.supernodexp.hpc, owner = ctminh@node2.supernodexp.hpc, job name = lu-decomp, queue = workq
02/14/2018 04:12:18;0100;Server@node2;Req;;Type 1 request received from ctminh@node2.supernodexp.hpc, sock=16
02/14/2018 04:12:18;0100;Server@node2;Req;;Type 3 request received from ctminh@node2.supernodexp.hpc, sock=16
02/14/2018 04:12:18;0100;Server@node2;Req;;Type 5 request received from ctminh@node2.supernodexp.hpc, sock=16
02/14/2018 04:12:18;0100;Server@node2;Job;1130.node2.supernodexp.hpc;enqueuing into workq, state 1 hop 1
02/14/2018 04:12:18;0008;Server@node2;Job;1130.node2.supernodexp.hpc;Job Queued at request of ctminh@node2.supernodexp.hpc, owner = ctminh@node2.supernodexp.hpc, job name = telemac1, queue = workq
02/14/2018 04:12:18;0100;Server@node2;Req;;Type 1 request received from ctminh@node2.supernodexp.hpc, sock=16
02/14/2018 04:12:18;0100;Server@node2;Req;;Type 20 request received from Scheduler@node2.supernodexp.hpc, sock=20
02/14/2018 04:12:18;0100;Server@node2;Req;;Type 3 request received from ctminh@node2.supernodexp.hpc, sock=16
02/14/2018 04:12:18;0100;Server@node2;Req;;Type 51 request received from Scheduler@node2.supernodexp.hpc, sock=20
02/14/2018 04:12:18;0100;Server@node2;Req;;Type 5 request received from ctminh@node2.supernodexp.hpc, sock=16
02/14/2018 04:12:18;0100;Server@node2;Job;1131.node2.supernodexp.hpc;enqueuing into workq, state 1 hop 1
02/14/2018 04:12:18;0008;Server@node2;Job;1131.node2.supernodexp.hpc;Job Queued at request of ctminh@node2.supernodexp.hpc, owner = ctminh@node2.supernodexp.hpc, job name = lu-decomp, queue = workq
02/14/2018 04:12:18;0100;Server@node2;Req;;Type 1 request received from ctminh@node2.supernodexp.hpc, sock=16
02/14/2018 04:12:18;0100;Server@node2;Req;;Type 3 request received from ctminh@node2.supernodexp.hpc, sock=16
02/14/2018 04:12:18;0100;Server@node2;Req;;Type 5 request received from ctminh@node2.supernodexp.hpc, sock=16
02/14/2018 04:12:18;0100;Server@node2;Job;1132.node2.supernodexp.hpc;enqueuing into workq, state 1 hop 1
02/14/2018 04:12:18;0008;Server@node2;Job;1132.node2.supernodexp.hpc;Job Queued at request of ctminh@node2.supernodexp.hpc, owner = ctminh@node2.supernodexp.hpc, job name = nbody, queue = workq
02/14/2018 04:12:18;0100;Server@node2;Req;;Type 1 request received from ctminh@node2.supernodexp.hpc, sock=16
02/14/2018 04:12:18;0100;Server@node2;Req;;Type 3 request received from ctminh@node2.supernodexp.hpc, sock=16
02/14/2018 04:12:18;0100;Server@node2;Req;;Type 5 request received from ctminh@node2.supernodexp.hpc, sock=16
02/14/2018 04:12:18;0100;Server@node2;Job;1133.node2.supernodexp.hpc;enqueuing into workq, state 1 hop 1
02/14/2018 04:12:18;0008;Server@node2;Job;1133.node2.supernodexp.hpc;Job Queued at request of ctminh@node2.supernodexp.hpc, owner = ctminh@node2.supernodexp.hpc, job name = telemac3, queue = workq
02/14/2018 04:12:18;0100;Server@node2;Req;;Type 1 request received from ctminh@node2.supernodexp.hpc, sock=16
02/14/2018 04:12:18;0100;Server@node2;Req;;Type 3 request received from ctminh@node2.supernodexp.hpc, sock=16
02/14/2018 04:12:18;0100;Server@node2;Req;;Type 5 request received from ctminh@node2.supernodexp.hpc, sock=16
02/14/2018 04:12:18;0100;Server@node2;Job;1134.node2.supernodexp.hpc;enqueuing into workq, state 1 hop 1
02/14/2018 04:12:18;0008;Server@node2;Job;1134.node2.supernodexp.hpc;Job Queued at request of ctminh@node2.supernodexp.hpc, owner = ctminh@node2.supernodexp.hpc, job name = histogram, queue = workq
02/14/2018 04:12:18;0100;Server@node2;Req;;Type 1 request received from ctminh@node2.supernodexp.hpc, sock=16
02/14/2018 04:12:18;0100;Server@node2;Req;;Type 3 request received from ctminh@node2.supernodexp.hpc, sock=16
02/14/2018 04:12:18;0100;Server@node2;Req;;Type 5 request received from ctminh@node2.supernodexp.hpc, sock=16
02/14/2018 04:12:18;0100;Server@node2;Job;1135.node2.supernodexp.hpc;enqueuing into workq, state 1 hop 1
02/14/2018 04:12:18;0008;Server@node2;Job;1135.node2.supernodexp.hpc;Job Queued at request of ctminh@node2.supernodexp.hpc, owner = ctminh@node2.supernodexp.hpc, job name = telemac3, queue = workq
02/14/2018 04:12:18;0100;Server@node2;Req;;Type 11 request received from Scheduler@node2.supernodexp.hpc, sock=20
02/14/2018 04:12:18;0008;Server@node2;Job;1128.node2.supernodexp.hpc;Job Modified at request of Scheduler@node2.supernodexp.hpc
02/14/2018 04:12:18;0100;Server@node2;Req;;Type 11 request received from Scheduler@node2.supernodexp.hpc, sock=20
02/14/2018 04:12:18;0008;Server@node2;Job;1126.node2.supernodexp.hpc;Job Modified at request of Scheduler@node2.supernodexp.hpc
02/14/2018 04:12:18;0100;Server@node2;Req;;Type 11 request received from Scheduler@node2.supernodexp.hpc, sock=20
02/14/2018 04:12:18;0008;Server@node2;Job;1130.node2.supernodexp.hpc;Job Modified at request of Scheduler@node2.supernodexp.hpc
02/14/2018 04:12:18;0100;Server@node2;Req;;Type 11 request received from Scheduler@node2.supernodexp.hpc, sock=20
02/14/2018 04:12:18;0008;Server@node2;Job;1124.node2.supernodexp.hpc;Job Modified at request of Scheduler@node2.supernodexp.hpc
02/14/2018 04:12:18;0100;Server@node2;Req;;Type 11 request received from Scheduler@node2.supernodexp.hpc, sock=20
02/14/2018 04:12:18;0008;Server@node2;Job;1127.node2.supernodexp.hpc;Job Modified at request of Scheduler@node2.supernodexp.hpc
02/14/2018 04:12:18;0100;Server@node2;Req;;Type 11 request received from Scheduler@node2.supernodexp.hpc, sock=20
02/14/2018 04:12:18;0008;Server@node2;Job;1125.node2.supernodexp.hpc;Job Modified at request of Scheduler@node2.supernodexp.hpc
02/14/2018 04:12:18;0100;Server@node2;Req;;Type 11 request received from Scheduler@node2.supernodexp.hpc, sock=20
02/14/2018 04:12:18;0008;Server@node2;Job;1129.node2.supernodexp.hpc;Job Modified at request of Scheduler@node2.supernodexp.hpc
02/14/2018 04:12:18;0040;Server@node2;Svr;node2.supernodexp.hpc;Scheduler sent command 1
02/14/2018 04:12:18;0040;Server@node2;Svr;node2.supernodexp.hpc;Scheduler sent command 0
02/14/2018 04:12:18;0100;Server@node2;Req;;Type 21 request received from Scheduler@node2.supernodexp.hpc, sock=20
02/14/2018 04:12:18;0100;Server@node2;Req;;Type 81 request received from Scheduler@node2.supernodexp.hpc, sock=20
02/14/2018 04:12:18;0100;Server@node2;Req;;Type 71 request received from Scheduler@node2.supernodexp.hpc, sock=20
02/14/2018 04:12:18;0100;Server@node2;Req;;Type 58 request received from Scheduler@node2.supernodexp.hpc, sock=20
02/14/2018 04:12:18;0100;Server@node2;Req;;Type 1 request received from ctminh@node2.supernodexp.hpc, sock=16
02/14/2018 04:12:18;0100;Server@node2;Req;;Type 3 request received from ctminh@node2.supernodexp.hpc, sock=16
02/14/2018 04:12:18;0100;Server@node2;Req;;Type 5 request received from ctminh@node2.supernodexp.hpc, sock=16
02/14/2018 04:12:18;0100;Server@node2;Job;1136.node2.supernodexp.hpc;enqueuing into workq, state 1 hop 1
02/14/2018 04:12:18;0008;Server@node2;Job;1136.node2.supernodexp.hpc;Job Queued at request of ctminh@node2.supernodexp.hpc, owner = ctminh@node2.supernodexp.hpc, job name = jacobi, queue = workq
02/14/2018 04:12:18;0100;Server@node2;Req;;Type 1 request received from ctminh@node2.supernodexp.hpc, sock=16
02/14/2018 04:12:18;0100;Server@node2;Req;;Type 3 request received from ctminh@node2.supernodexp.hpc, sock=16
02/14/2018 04:12:18;0100;Server@node2;Req;;Type 5 request received from ctminh@node2.supernodexp.hpc, sock=16
02/14/2018 04:12:18;0100;Server@node2;Job;1137.node2.supernodexp.hpc;enqueuing into workq, state 1 hop 1
02/14/2018 04:12:18;0008;Server@node2;Job;1137.node2.supernodexp.hpc;Job Queued at request of ctminh@node2.supernodexp.hpc, owner = ctminh@node2.supernodexp.hpc, job name = vectorization, queue = workq
02/14/2018 04:12:18;0100;Server@node2;Req;;Type 1 request received from ctminh@node2.supernodexp.hpc, sock=16
02/14/2018 04:12:18;0100;Server@node2;Req;;Type 20 request received from Scheduler@node2.supernodexp.hpc, sock=20
02/14/2018 04:12:18;0100;Server@node2;Req;;Type 3 request received from ctminh@node2.supernodexp.hpc, sock=16
02/14/2018 04:12:18;0100;Server@node2;Req;;Type 51 request received from Scheduler@node2.supernodexp.hpc, sock=20
02/14/2018 04:12:18;0100;Server@node2;Req;;Type 5 request received from ctminh@node2.supernodexp.hpc, sock=16
02/14/2018 04:12:18;0100;Server@node2;Job;1138.node2.supernodexp.hpc;enqueuing into workq, state 1 hop 1
02/14/2018 04:12:18;0008;Server@node2;Job;1138.node2.supernodexp.hpc;Job Queued at request of ctminh@node2.supernodexp.hpc, owner = ctminh@node2.supernodexp.hpc, job name = sweep, queue = workq
02/14/2018 04:12:18;0100;Server@node2;Req;;Type 1 request received from ctminh@node2.supernodexp.hpc, sock=16
02/14/2018 04:12:18;0100;Server@node2;Req;;Type 3 request received from ctminh@node2.supernodexp.hpc, sock=16
02/14/2018 04:12:18;0100;Server@node2;Req;;Type 5 request received from ctminh@node2.supernodexp.hpc, sock=16
02/14/2018 04:12:18;0100;Server@node2;Job;1139.node2.supernodexp.hpc;enqueuing into workq, state 1 hop 1
02/14/2018 04:12:18;0008;Server@node2;Job;1139.node2.supernodexp.hpc;Job Queued at request of ctminh@node2.supernodexp.hpc, owner = ctminh@node2.supernodexp.hpc, job name = lu-decomp, queue = workq
02/14/2018 04:12:18;0100;Server@node2;Req;;Type 1 request received from ctminh@node2.supernodexp.hpc, sock=16
02/14/2018 04:12:18;0100;Server@node2;Req;;Type 3 request received from ctminh@node2.supernodexp.hpc, sock=16
02/14/2018 04:12:18;0100;Server@node2;Req;;Type 5 request received from ctminh@node2.supernodexp.hpc, sock=16
02/14/2018 04:12:18;0100;Server@node2;Job;1140.node2.supernodexp.hpc;enqueuing into workq, state 1 hop 1
02/14/2018 04:12:18;0008;Server@node2;Job;1140.node2.supernodexp.hpc;Job Queued at request of ctminh@node2.supernodexp.hpc, owner = ctminh@node2.supernodexp.hpc, job name = matrix-x-vector, queue = workq
02/14/2018 04:12:18;0100;Server@node2;Req;;Type 1 request received from ctminh@node2.supernodexp.hpc, sock=16
02/14/2018 04:12:18;0100;Server@node2;Req;;Type 3 request received from ctminh@node2.supernodexp.hpc, sock=16
02/14/2018 04:12:18;0100;Server@node2;Req;;Type 5 request received from ctminh@node2.supernodexp.hpc, sock=16
02/14/2018 04:12:18;0100;Server@node2;Job;1141.node2.supernodexp.hpc;enqueuing into workq, state 1 hop 1
02/14/2018 04:12:18;0008;Server@node2;Job;1141.node2.supernodexp.hpc;Job Queued at request of ctminh@node2.supernodexp.hpc, owner = ctminh@node2.supernodexp.hpc, job name = nbody, queue = workq
02/14/2018 04:12:18;0100;Server@node2;Req;;Type 1 request received from ctminh@node2.supernodexp.hpc, sock=16
02/14/2018 04:12:18;0100;Server@node2;Req;;Type 3 request received from ctminh@node2.supernodexp.hpc, sock=16
02/14/2018 04:12:18;0100;Server@node2;Req;;Type 5 request received from ctminh@node2.supernodexp.hpc, sock=16
02/14/2018 04:12:18;0100;Server@node2;Job;1142.node2.supernodexp.hpc;enqueuing into workq, state 1 hop 1
02/14/2018 04:12:18;0008;Server@node2;Job;1142.node2.supernodexp.hpc;Job Queued at request of ctminh@node2.supernodexp.hpc, owner = ctminh@node2.supernodexp.hpc, job name = sweep, queue = workq
02/14/2018 04:12:18;0100;Server@node2;Req;;Type 11 request received from Scheduler@node2.supernodexp.hpc, sock=20
02/14/2018 04:12:18;0008;Server@node2;Job;1133.node2.supernodexp.hpc;Job Modified at request of Scheduler@node2.supernodexp.hpc
02/14/2018 04:12:18;0100;Server@node2;Req;;Type 11 request received from Scheduler@node2.supernodexp.hpc, sock=20
02/14/2018 04:12:18;0008;Server@node2;Job;1135.node2.supernodexp.hpc;Job Modified at request of Scheduler@node2.supernodexp.hpc
02/14/2018 04:12:18;0100;Server@node2;Req;;Type 11 request received from Scheduler@node2.supernodexp.hpc, sock=20
02/14/2018 04:12:18;0008;Server@node2;Job;1136.node2.supernodexp.hpc;Job Modified at request of Scheduler@node2.supernodexp.hpc
02/14/2018 04:12:18;0100;Server@node2;Req;;Type 11 request received from Scheduler@node2.supernodexp.hpc, sock=20
02/14/2018 04:12:18;0008;Server@node2;Job;1132.node2.supernodexp.hpc;Job Modified at request of Scheduler@node2.supernodexp.hpc
02/14/2018 04:12:18;0100;Server@node2;Req;;Type 11 request received from Scheduler@node2.supernodexp.hpc, sock=20
02/14/2018 04:12:18;0008;Server@node2;Job;1134.node2.supernodexp.hpc;Job Modified at request of Scheduler@node2.supernodexp.hpc
02/14/2018 04:12:18;0100;Server@node2;Req;;Type 11 request received from Scheduler@node2.supernodexp.hpc, sock=20
02/14/2018 04:12:18;0008;Server@node2;Job;1137.node2.supernodexp.hpc;Job Modified at request of Scheduler@node2.supernodexp.hpc
02/14/2018 04:12:18;0100;Server@node2;Req;;Type 11 request received from Scheduler@node2.supernodexp.hpc, sock=20
02/14/2018 04:12:18;0008;Server@node2;Job;1131.node2.supernodexp.hpc;Job Modified at request of Scheduler@node2.supernodexp.hpc
02/14/2018 04:12:18;0040;Server@node2;Svr;node2.supernodexp.hpc;Scheduler sent command 1
02/14/2018 04:12:18;0040;Server@node2;Svr;node2.supernodexp.hpc;Scheduler sent command 0
02/14/2018 04:12:18;0100;Server@node2;Req;;Type 21 request received from Scheduler@node2.supernodexp.hpc, sock=20
02/14/2018 04:12:18;0100;Server@node2;Req;;Type 81 request received from Scheduler@node2.supernodexp.hpc, sock=20
02/14/2018 04:12:18;0100;Server@node2;Req;;Type 71 request received from Scheduler@node2.supernodexp.hpc, sock=20
02/14/2018 04:12:18;0100;Server@node2;Req;;Type 58 request received from Scheduler@node2.supernodexp.hpc, sock=20
02/14/2018 04:12:18;0100;Server@node2;Req;;Type 1 request received from ctminh@node2.supernodexp.hpc, sock=16
02/14/2018 04:12:18;0100;Server@node2;Req;;Type 3 request received from ctminh@node2.supernodexp.hpc, sock=16
02/14/2018 04:12:18;0100;Server@node2;Req;;Type 5 request received from ctminh@node2.supernodexp.hpc, sock=16
02/14/2018 04:12:18;0100;Server@node2;Job;1143.node2.supernodexp.hpc;enqueuing into workq, state 1 hop 1
02/14/2018 04:12:18;0008;Server@node2;Job;1143.node2.supernodexp.hpc;Job Queued at request of ctminh@node2.supernodexp.hpc, owner = ctminh@node2.supernodexp.hpc, job name = telemac1, queue = workq
02/14/2018 04:12:18;0100;Server@node2;Req;;Type 1 request received from ctminh@node2.supernodexp.hpc, sock=16
02/14/2018 04:12:18;0100;Server@node2;Req;;Type 3 request received from ctminh@node2.supernodexp.hpc, sock=16
02/14/2018 04:12:18;0100;Server@node2;Req;;Type 5 request received from ctminh@node2.supernodexp.hpc, sock=16
02/14/2018 04:12:18;0100;Server@node2;Job;1144.node2.supernodexp.hpc;enqueuing into workq, state 1 hop 1
02/14/2018 04:12:18;0008;Server@node2;Job;1144.node2.supernodexp.hpc;Job Queued at request of ctminh@node2.supernodexp.hpc, owner = ctminh@node2.supernodexp.hpc, job name = telemac1, queue = workq
02/14/2018 04:12:18;0100;Server@node2;Req;;Type 1 request received from ctminh@node2.supernodexp.hpc, sock=16
02/14/2018 04:12:19;0100;Server@node2;Req;;Type 3 request received from ctminh@node2.supernodexp.hpc, sock=16
02/14/2018 04:12:19;0100;Server@node2;Req;;Type 5 request received from ctminh@node2.supernodexp.hpc, sock=16
02/14/2018 04:12:19;0100;Server@node2;Job;1145.node2.supernodexp.hpc;enqueuing into workq, state 1 hop 1
02/14/2018 04:12:19;0008;Server@node2;Job;1145.node2.supernodexp.hpc;Job Queued at request of ctminh@node2.supernodexp.hpc, owner = ctminh@node2.supernodexp.hpc, job name = sweep, queue = workq
02/14/2018 04:12:19;0100;Server@node2;Req;;Type 20 request received from Scheduler@node2.supernodexp.hpc, sock=20
02/14/2018 04:12:19;0100;Server@node2;Req;;Type 51 request received from Scheduler@node2.supernodexp.hpc, sock=20
02/14/2018 04:12:19;0100;Server@node2;Req;;Type 1 request received from ctminh@node2.supernodexp.hpc, sock=16
02/14/2018 04:12:19;0100;Server@node2;Req;;Type 3 request received from ctminh@node2.supernodexp.hpc, sock=16
02/14/2018 04:12:19;0100;Server@node2;Req;;Type 5 request received from ctminh@node2.supernodexp.hpc, sock=16
02/14/2018 04:12:19;0100;Server@node2;Job;1146.node2.supernodexp.hpc;enqueuing into workq, state 1 hop 1
02/14/2018 04:12:19;0008;Server@node2;Job;1146.node2.supernodexp.hpc;Job Queued at request of ctminh@node2.supernodexp.hpc, owner = ctminh@node2.supernodexp.hpc, job name = sweep, queue = workq
02/14/2018 04:12:19;0100;Server@node2;Req;;Type 1 request received from ctminh@node2.supernodexp.hpc, sock=16
02/14/2018 04:12:19;0100;Server@node2;Req;;Type 3 request received from ctminh@node2.supernodexp.hpc, sock=16
02/14/2018 04:12:19;0100;Server@node2;Req;;Type 5 request received from ctminh@node2.supernodexp.hpc, sock=16
02/14/2018 04:12:19;0100;Server@node2;Job;1147.node2.supernodexp.hpc;enqueuing into workq, state 1 hop 1
02/14/2018 04:12:19;0008;Server@node2;Job;1147.node2.supernodexp.hpc;Job Queued at request of ctminh@node2.supernodexp.hpc, owner = ctminh@node2.supernodexp.hpc, job name = telemac2, queue = workq
02/14/2018 04:12:19;0100;Server@node2;Req;;Type 1 request received from ctminh@node2.supernodexp.hpc, sock=16
02/14/2018 04:12:19;0100;Server@node2;Req;;Type 3 request received from ctminh@node2.supernodexp.hpc, sock=16
02/14/2018 04:12:19;0100;Server@node2;Req;;Type 5 request received from ctminh@node2.supernodexp.hpc, sock=16
02/14/2018 04:12:19;0100;Server@node2;Job;1148.node2.supernodexp.hpc;enqueuing into workq, state 1 hop 1
02/14/2018 04:12:19;0008;Server@node2;Job;1148.node2.supernodexp.hpc;Job Queued at request of ctminh@node2.supernodexp.hpc, owner = ctminh@node2.supernodexp.hpc, job name = jacobi, queue = workq
02/14/2018 04:12:19;0100;Server@node2;Req;;Type 1 request received from ctminh@node2.supernodexp.hpc, sock=16
02/14/2018 04:12:19;0100;Server@node2;Req;;Type 3 request received from ctminh@node2.supernodexp.hpc, sock=16
02/14/2018 04:12:19;0100;Server@node2;Req;;Type 5 request received from ctminh@node2.supernodexp.hpc, sock=16
02/14/2018 04:12:19;0100;Server@node2;Job;1149.node2.supernodexp.hpc;enqueuing into workq, state 1 hop 1
02/14/2018 04:12:19;0008;Server@node2;Job;1149.node2.supernodexp.hpc;Job Queued at request of ctminh@node2.supernodexp.hpc, owner = ctminh@node2.supernodexp.hpc, job name = sweep, queue = workq
02/14/2018 04:12:19;0100;Server@node2;Req;;Type 1 request received from ctminh@node2.supernodexp.hpc, sock=16
02/14/2018 04:12:19;0100;Server@node2;Req;;Type 3 request received from ctminh@node2.supernodexp.hpc, sock=16
02/14/2018 04:12:19;0100;Server@node2;Req;;Type 11 request received from Scheduler@node2.supernodexp.hpc, sock=20
02/14/2018 04:12:19;0008;Server@node2;Job;1143.node2.supernodexp.hpc;Job Modified at request of Scheduler@node2.supernodexp.hpc
02/14/2018 04:12:19;0100;Server@node2;Req;;Type 5 request received from ctminh@node2.supernodexp.hpc, sock=16
02/14/2018 04:12:19;0100;Server@node2;Job;1150.node2.supernodexp.hpc;enqueuing into workq, state 1 hop 1
02/14/2018 04:12:19;0008;Server@node2;Job;1150.node2.supernodexp.hpc;Job Queued at request of ctminh@node2.supernodexp.hpc, owner = ctminh@node2.supernodexp.hpc, job name = histogram, queue = workq
02/14/2018 04:12:19;0100;Server@node2;Req;;Type 11 request received from Scheduler@node2.supernodexp.hpc, sock=20
02/14/2018 04:12:19;0008;Server@node2;Job;1144.node2.supernodexp.hpc;Job Modified at request of Scheduler@node2.supernodexp.hpc
02/14/2018 04:12:19;0100;Server@node2;Req;;Type 11 request received from Scheduler@node2.supernodexp.hpc, sock=20
02/14/2018 04:12:19;0008;Server@node2;Job;1141.node2.supernodexp.hpc;Job Modified at request of Scheduler@node2.supernodexp.hpc
02/14/2018 04:12:19;0100;Server@node2;Req;;Type 11 request received from Scheduler@node2.supernodexp.hpc, sock=20
02/14/2018 04:12:19;0008;Server@node2;Job;1138.node2.supernodexp.hpc;Job Modified at request of Scheduler@node2.supernodexp.hpc
02/14/2018 04:12:19;0100;Server@node2;Req;;Type 11 request received from Scheduler@node2.supernodexp.hpc, sock=20
02/14/2018 04:12:19;0008;Server@node2;Job;1142.node2.supernodexp.hpc;Job Modified at request of Scheduler@node2.supernodexp.hpc
02/14/2018 04:12:19;0100;Server@node2;Req;;Type 11 request received from Scheduler@node2.supernodexp.hpc, sock=20
02/14/2018 04:12:19;0008;Server@node2;Job;1145.node2.supernodexp.hpc;Job Modified at request of Scheduler@node2.supernodexp.hpc
02/14/2018 04:12:19;0100;Server@node2;Req;;Type 11 request received from Scheduler@node2.supernodexp.hpc, sock=20
02/14/2018 04:12:19;0008;Server@node2;Job;1139.node2.supernodexp.hpc;Job Modified at request of Scheduler@node2.supernodexp.hpc
02/14/2018 04:12:19;0100;Server@node2;Req;;Type 11 request received from Scheduler@node2.supernodexp.hpc, sock=20
02/14/2018 04:12:19;0008;Server@node2;Job;1140.node2.supernodexp.hpc;Job Modified at request of Scheduler@node2.supernodexp.hpc
02/14/2018 04:12:19;0040;Server@node2;Svr;node2.supernodexp.hpc;Scheduler sent command 1
02/14/2018 04:12:19;0040;Server@node2;Svr;node2.supernodexp.hpc;Scheduler sent command 0
02/14/2018 04:12:19;0100;Server@node2;Req;;Type 21 request received from Scheduler@node2.supernodexp.hpc, sock=20
02/14/2018 04:12:19;0100;Server@node2;Req;;Type 81 request received from Scheduler@node2.supernodexp.hpc, sock=20
02/14/2018 04:12:19;0100;Server@node2;Req;;Type 71 request received from Scheduler@node2.supernodexp.hpc, sock=20
02/14/2018 04:12:19;0100;Server@node2;Req;;Type 58 request received from Scheduler@node2.supernodexp.hpc, sock=20
02/14/2018 04:12:19;0100;Server@node2;Req;;Type 20 request received from Scheduler@node2.supernodexp.hpc, sock=20
02/14/2018 04:12:19;0100;Server@node2;Req;;Type 51 request received from Scheduler@node2.supernodexp.hpc, sock=20
02/14/2018 04:12:19;0100;Server@node2;Req;;Type 11 request received from Scheduler@node2.supernodexp.hpc, sock=20
02/14/2018 04:12:19;0008;Server@node2;Job;1147.node2.supernodexp.hpc;Job Modified at request of Scheduler@node2.supernodexp.hpc
02/14/2018 04:12:19;0100;Server@node2;Req;;Type 11 request received from Scheduler@node2.supernodexp.hpc, sock=20
02/14/2018 04:12:19;0008;Server@node2;Job;1148.node2.supernodexp.hpc;Job Modified at request of Scheduler@node2.supernodexp.hpc
02/14/2018 04:12:19;0100;Server@node2;Req;;Type 11 request received from Scheduler@node2.supernodexp.hpc, sock=20
02/14/2018 04:12:19;0008;Server@node2;Job;1146.node2.supernodexp.hpc;Job Modified at request of Scheduler@node2.supernodexp.hpc
02/14/2018 04:12:19;0100;Server@node2;Req;;Type 11 request received from Scheduler@node2.supernodexp.hpc, sock=20
02/14/2018 04:12:19;0008;Server@node2;Job;1149.node2.supernodexp.hpc;Job Modified at request of Scheduler@node2.supernodexp.hpc
02/14/2018 04:12:19;0100;Server@node2;Req;;Type 11 request received from Scheduler@node2.supernodexp.hpc, sock=20
02/14/2018 04:12:19;0008;Server@node2;Job;1150.node2.supernodexp.hpc;Job Modified at request of Scheduler@node2.supernodexp.hpc
02/14/2018 04:13:14;0100;Server@node2;Req;;Type 1 request received from ctminh@node2.supernodexp.hpc, sock=16
02/14/2018 04:13:14;0100;Server@node2;Req;;Type 3 request received from ctminh@node2.supernodexp.hpc, sock=16
02/14/2018 04:13:14;0100;Server@node2;Req;;Type 5 request received from ctminh@node2.supernodexp.hpc, sock=16
02/14/2018 04:13:14;0100;Server@node2;Job;1151.node2.supernodexp.hpc;enqueuing into workq, state 1 hop 1
02/14/2018 04:13:14;0008;Server@node2;Job;1151.node2.supernodexp.hpc;Job Queued at request of ctminh@node2.supernodexp.hpc, owner = ctminh@node2.supernodexp.hpc, job name = telemac3, queue = workq
02/14/2018 04:13:14;0040;Server@node2;Svr;node2.supernodexp.hpc;Scheduler sent command 1
02/14/2018 04:13:14;0040;Server@node2;Svr;node2.supernodexp.hpc;Scheduler sent command 0
02/14/2018 04:13:14;0100;Server@node2;Req;;Type 21 request received from Scheduler@node2.supernodexp.hpc, sock=20
02/14/2018 04:13:14;0100;Server@node2;Req;;Type 81 request received from Scheduler@node2.supernodexp.hpc, sock=20
02/14/2018 04:13:14;0100;Server@node2;Req;;Type 71 request received from Scheduler@node2.supernodexp.hpc, sock=20
02/14/2018 04:13:14;0100;Server@node2;Req;;Type 58 request received from Scheduler@node2.supernodexp.hpc, sock=20
02/14/2018 04:13:14;0100;Server@node2;Req;;Type 1 request received from ctminh@node2.supernodexp.hpc, sock=16
02/14/2018 04:13:14;0100;Server@node2;Req;;Type 3 request received from ctminh@node2.supernodexp.hpc, sock=16
02/14/2018 04:13:14;0100;Server@node2;Req;;Type 5 request received from ctminh@node2.supernodexp.hpc, sock=16
02/14/2018 04:13:14;0100;Server@node2;Job;1152.node2.supernodexp.hpc;enqueuing into workq, state 1 hop 1
02/14/2018 04:13:14;0008;Server@node2;Job;1152.node2.supernodexp.hpc;Job Queued at request of ctminh@node2.supernodexp.hpc, owner = ctminh@node2.supernodexp.hpc, job name = vast1, queue = workq
02/14/2018 04:13:14;0100;Server@node2;Req;;Type 1 request received from ctminh@node2.supernodexp.hpc, sock=16
02/14/2018 04:13:14;0100;Server@node2;Req;;Type 3 request received from ctminh@node2.supernodexp.hpc, sock=16
02/14/2018 04:13:14;0100;Server@node2;Req;;Type 5 request received from ctminh@node2.supernodexp.hpc, sock=16
02/14/2018 04:13:14;0100;Server@node2;Job;1153.node2.supernodexp.hpc;enqueuing into workq, state 1 hop 1
02/14/2018 04:13:14;0008;Server@node2;Job;1153.node2.supernodexp.hpc;Job Queued at request of ctminh@node2.supernodexp.hpc, owner = ctminh@node2.supernodexp.hpc, job name = telemac1, queue = workq
02/14/2018 04:13:14;0100;Server@node2;Req;;Type 20 request received from Scheduler@node2.supernodexp.hpc, sock=20
02/14/2018 04:13:14;0100;Server@node2;Req;;Type 51 request received from Scheduler@node2.supernodexp.hpc, sock=20
02/14/2018 04:13:14;0100;Server@node2;Req;;Type 1 request received from ctminh@node2.supernodexp.hpc, sock=16
02/14/2018 04:13:14;0100;Server@node2;Req;;Type 3 request received from ctminh@node2.supernodexp.hpc, sock=16
02/14/2018 04:13:14;0100;Server@node2;Req;;Type 5 request received from ctminh@node2.supernodexp.hpc, sock=16
02/14/2018 04:13:14;0100;Server@node2;Job;1154.node2.supernodexp.hpc;enqueuing into workq, state 1 hop 1
02/14/2018 04:13:14;0008;Server@node2;Job;1154.node2.supernodexp.hpc;Job Queued at request of ctminh@node2.supernodexp.hpc, owner = ctminh@node2.supernodexp.hpc, job name = qe_mic_test, queue = workq
02/14/2018 04:13:14;0100;Server@node2;Req;;Type 1 request received from ctminh@node2.supernodexp.hpc, sock=16
02/14/2018 04:13:14;0100;Server@node2;Req;;Type 3 request received from ctminh@node2.supernodexp.hpc, sock=16
02/14/2018 04:13:14;0100;Server@node2;Req;;Type 5 request received from ctminh@node2.supernodexp.hpc, sock=16
02/14/2018 04:13:14;0100;Server@node2;Job;1155.node2.supernodexp.hpc;enqueuing into workq, state 1 hop 1
02/14/2018 04:13:14;0008;Server@node2;Job;1155.node2.supernodexp.hpc;Job Queued at request of ctminh@node2.supernodexp.hpc, owner = ctminh@node2.supernodexp.hpc, job name = nbody, queue = workq
02/14/2018 04:13:14;0100;Server@node2;Req;;Type 1 request received from ctminh@node2.supernodexp.hpc, sock=16
02/14/2018 04:13:14;0100;Server@node2;Req;;Type 3 request received from ctminh@node2.supernodexp.hpc, sock=16
02/14/2018 04:13:14;0100;Server@node2;Req;;Type 5 request received from ctminh@node2.supernodexp.hpc, sock=16
02/14/2018 04:13:14;0100;Server@node2;Job;1156.node2.supernodexp.hpc;enqueuing into workq, state 1 hop 1
02/14/2018 04:13:14;0008;Server@node2;Job;1156.node2.supernodexp.hpc;Job Queued at request of ctminh@node2.supernodexp.hpc, owner = ctminh@node2.supernodexp.hpc, job name = histogram, queue = workq
02/14/2018 04:13:14;0100;Server@node2;Req;;Type 1 request received from ctminh@node2.supernodexp.hpc, sock=16
02/14/2018 04:13:14;0100;Server@node2;Req;;Type 3 request received from ctminh@node2.supernodexp.hpc, sock=16
02/14/2018 04:13:14;0100;Server@node2;Req;;Type 5 request received from ctminh@node2.supernodexp.hpc, sock=16
02/14/2018 04:13:14;0100;Server@node2;Job;1157.node2.supernodexp.hpc;enqueuing into workq, state 1 hop 1
02/14/2018 04:13:14;0008;Server@node2;Job;1157.node2.supernodexp.hpc;Job Queued at request of ctminh@node2.supernodexp.hpc, owner = ctminh@node2.supernodexp.hpc, job name = histogram, queue = workq
02/14/2018 04:13:14;0100;Server@node2;Req;;Type 1 request received from ctminh@node2.supernodexp.hpc, sock=16
02/14/2018 04:13:14;0100;Server@node2;Req;;Type 3 request received from ctminh@node2.supernodexp.hpc, sock=16
02/14/2018 04:13:14;0100;Server@node2;Req;;Type 5 request received from ctminh@node2.supernodexp.hpc, sock=16
02/14/2018 04:13:14;0100;Server@node2;Job;1158.node2.supernodexp.hpc;enqueuing into workq, state 1 hop 1
02/14/2018 04:13:14;0008;Server@node2;Job;1158.node2.supernodexp.hpc;Job Queued at request of ctminh@node2.supernodexp.hpc, owner = ctminh@node2.supernodexp.hpc, job name = telemac1, queue = workq
02/14/2018 04:13:14;0100;Server@node2;Req;;Type 11 request received from Scheduler@node2.supernodexp.hpc, sock=20
02/14/2018 04:13:14;0008;Server@node2;Job;1152.node2.supernodexp.hpc;Job Modified at request of Scheduler@node2.supernodexp.hpc
02/14/2018 04:13:14;0100;Server@node2;Req;;Type 11 request received from Scheduler@node2.supernodexp.hpc, sock=20
02/14/2018 04:13:14;0008;Server@node2;Job;1153.node2.supernodexp.hpc;Job Modified at request of Scheduler@node2.supernodexp.hpc
02/14/2018 04:13:14;0100;Server@node2;Req;;Type 11 request received from Scheduler@node2.supernodexp.hpc, sock=20
02/14/2018 04:13:14;0008;Server@node2;Job;1151.node2.supernodexp.hpc;Job Modified at request of Scheduler@node2.supernodexp.hpc
02/14/2018 04:13:14;0040;Server@node2;Svr;node2.supernodexp.hpc;Scheduler sent command 1
02/14/2018 04:13:14;0040;Server@node2;Svr;node2.supernodexp.hpc;Scheduler sent command 0
02/14/2018 04:13:14;0100;Server@node2;Req;;Type 21 request received from Scheduler@node2.supernodexp.hpc, sock=20
02/14/2018 04:13:14;0100;Server@node2;Req;;Type 81 request received from Scheduler@node2.supernodexp.hpc, sock=20
02/14/2018 04:13:14;0100;Server@node2;Req;;Type 71 request received from Scheduler@node2.supernodexp.hpc, sock=20
02/14/2018 04:13:14;0100;Server@node2;Req;;Type 58 request received from Scheduler@node2.supernodexp.hpc, sock=20
02/14/2018 04:13:14;0100;Server@node2;Req;;Type 1 request received from ctminh@node2.supernodexp.hpc, sock=16
02/14/2018 04:13:14;0100;Server@node2;Req;;Type 3 request received from ctminh@node2.supernodexp.hpc, sock=16
02/14/2018 04:13:14;0100;Server@node2;Req;;Type 5 request received from ctminh@node2.supernodexp.hpc, sock=16
02/14/2018 04:13:14;0100;Server@node2;Job;1159.node2.supernodexp.hpc;enqueuing into workq, state 1 hop 1
02/14/2018 04:13:14;0008;Server@node2;Job;1159.node2.supernodexp.hpc;Job Queued at request of ctminh@node2.supernodexp.hpc, owner = ctminh@node2.supernodexp.hpc, job name = thread-affinity, queue = workq
02/14/2018 04:13:14;0100;Server@node2;Req;;Type 1 request received from ctminh@node2.supernodexp.hpc, sock=16
02/14/2018 04:13:14;0100;Server@node2;Req;;Type 3 request received from ctminh@node2.supernodexp.hpc, sock=16
02/14/2018 04:13:14;0100;Server@node2;Req;;Type 5 request received from ctminh@node2.supernodexp.hpc, sock=16
02/14/2018 04:13:14;0100;Server@node2;Job;1160.node2.supernodexp.hpc;enqueuing into workq, state 1 hop 1
02/14/2018 04:13:14;0008;Server@node2;Job;1160.node2.supernodexp.hpc;Job Queued at request of ctminh@node2.supernodexp.hpc, owner = ctminh@node2.supernodexp.hpc, job name = jacobi, queue = workq
02/14/2018 04:13:14;0100;Server@node2;Req;;Type 1 request received from ctminh@node2.supernodexp.hpc, sock=16
02/14/2018 04:13:14;0100;Server@node2;Req;;Type 20 request received from Scheduler@node2.supernodexp.hpc, sock=20
02/14/2018 04:13:14;0100;Server@node2;Req;;Type 3 request received from ctminh@node2.supernodexp.hpc, sock=16
02/14/2018 04:13:14;0100;Server@node2;Req;;Type 51 request received from Scheduler@node2.supernodexp.hpc, sock=20
02/14/2018 04:13:14;0100;Server@node2;Req;;Type 5 request received from ctminh@node2.supernodexp.hpc, sock=16
02/14/2018 04:13:14;0100;Server@node2;Job;1161.node2.supernodexp.hpc;enqueuing into workq, state 1 hop 1
02/14/2018 04:13:14;0008;Server@node2;Job;1161.node2.supernodexp.hpc;Job Queued at request of ctminh@node2.supernodexp.hpc, owner = ctminh@node2.supernodexp.hpc, job name = vectorization, queue = workq
02/14/2018 04:13:14;0100;Server@node2;Req;;Type 1 request received from ctminh@node2.supernodexp.hpc, sock=16
02/14/2018 04:13:14;0100;Server@node2;Req;;Type 3 request received from ctminh@node2.supernodexp.hpc, sock=16
02/14/2018 04:13:14;0100;Server@node2;Req;;Type 5 request received from ctminh@node2.supernodexp.hpc, sock=16
02/14/2018 04:13:14;0100;Server@node2;Job;1162.node2.supernodexp.hpc;enqueuing into workq, state 1 hop 1
02/14/2018 04:13:14;0008;Server@node2;Job;1162.node2.supernodexp.hpc;Job Queued at request of ctminh@node2.supernodexp.hpc, owner = ctminh@node2.supernodexp.hpc, job name = histogram, queue = workq
02/14/2018 04:13:14;0100;Server@node2;Req;;Type 1 request received from ctminh@node2.supernodexp.hpc, sock=16
02/14/2018 04:13:14;0100;Server@node2;Req;;Type 3 request received from ctminh@node2.supernodexp.hpc, sock=16
02/14/2018 04:13:14;0100;Server@node2;Req;;Type 5 request received from ctminh@node2.supernodexp.hpc, sock=16
02/14/2018 04:13:14;0100;Server@node2;Job;1163.node2.supernodexp.hpc;enqueuing into workq, state 1 hop 1
02/14/2018 04:13:14;0008;Server@node2;Job;1163.node2.supernodexp.hpc;Job Queued at request of ctminh@node2.supernodexp.hpc, owner = ctminh@node2.supernodexp.hpc, job name = matrix-x-vector, queue = workq
02/14/2018 04:13:14;0100;Server@node2;Req;;Type 1 request received from ctminh@node2.supernodexp.hpc, sock=16
02/14/2018 04:13:14;0100;Server@node2;Req;;Type 3 request received from ctminh@node2.supernodexp.hpc, sock=16
02/14/2018 04:13:14;0100;Server@node2;Req;;Type 5 request received from ctminh@node2.supernodexp.hpc, sock=16
02/14/2018 04:13:14;0100;Server@node2;Job;1164.node2.supernodexp.hpc;enqueuing into workq, state 1 hop 1
02/14/2018 04:13:14;0008;Server@node2;Job;1164.node2.supernodexp.hpc;Job Queued at request of ctminh@node2.supernodexp.hpc, owner = ctminh@node2.supernodexp.hpc, job name = nbody, queue = workq
02/14/2018 04:13:14;0100;Server@node2;Req;;Type 1 request received from ctminh@node2.supernodexp.hpc, sock=16
02/14/2018 04:13:14;0100;Server@node2;Req;;Type 3 request received from ctminh@node2.supernodexp.hpc, sock=16
02/14/2018 04:13:14;0100;Server@node2;Req;;Type 5 request received from ctminh@node2.supernodexp.hpc, sock=16
02/14/2018 04:13:14;0100;Server@node2;Job;1165.node2.supernodexp.hpc;enqueuing into workq, state 1 hop 1
02/14/2018 04:13:14;0008;Server@node2;Job;1165.node2.supernodexp.hpc;Job Queued at request of ctminh@node2.supernodexp.hpc, owner = ctminh@node2.supernodexp.hpc, job name = telemac1, queue = workq
02/14/2018 04:13:14;0100;Server@node2;Req;;Type 1 request received from ctminh@node2.supernodexp.hpc, sock=16
02/14/2018 04:13:14;0100;Server@node2;Req;;Type 11 request received from Scheduler@node2.supernodexp.hpc, sock=20
02/14/2018 04:13:14;0008;Server@node2;Job;1154.node2.supernodexp.hpc;Job Modified at request of Scheduler@node2.supernodexp.hpc
02/14/2018 04:13:14;0100;Server@node2;Req;;Type 3 request received from ctminh@node2.supernodexp.hpc, sock=16
02/14/2018 04:13:14;0100;Server@node2;Req;;Type 5 request received from ctminh@node2.supernodexp.hpc, sock=16
02/14/2018 04:13:14;0100;Server@node2;Job;1166.node2.supernodexp.hpc;enqueuing into workq, state 1 hop 1
02/14/2018 04:13:14;0008;Server@node2;Job;1166.node2.supernodexp.hpc;Job Queued at request of ctminh@node2.supernodexp.hpc, owner = ctminh@node2.supernodexp.hpc, job name = telemac1, queue = workq
02/14/2018 04:13:14;0100;Server@node2;Req;;Type 11 request received from Scheduler@node2.supernodexp.hpc, sock=20
02/14/2018 04:13:14;0008;Server@node2;Job;1158.node2.supernodexp.hpc;Job Modified at request of Scheduler@node2.supernodexp.hpc
02/14/2018 04:13:14;0100;Server@node2;Req;;Type 11 request received from Scheduler@node2.supernodexp.hpc, sock=20
02/14/2018 04:13:14;0008;Server@node2;Job;1160.node2.supernodexp.hpc;Job Modified at request of Scheduler@node2.supernodexp.hpc
02/14/2018 04:13:14;0100;Server@node2;Req;;Type 11 request received from Scheduler@node2.supernodexp.hpc, sock=20
02/14/2018 04:13:14;0008;Server@node2;Job;1159.node2.supernodexp.hpc;Job Modified at request of Scheduler@node2.supernodexp.hpc
02/14/2018 04:13:14;0100;Server@node2;Req;;Type 11 request received from Scheduler@node2.supernodexp.hpc, sock=20
02/14/2018 04:13:14;0008;Server@node2;Job;1155.node2.supernodexp.hpc;Job Modified at request of Scheduler@node2.supernodexp.hpc
02/14/2018 04:13:14;0100;Server@node2;Req;;Type 11 request received from Scheduler@node2.supernodexp.hpc, sock=20
02/14/2018 04:13:14;0008;Server@node2;Job;1156.node2.supernodexp.hpc;Job Modified at request of Scheduler@node2.supernodexp.hpc
02/14/2018 04:13:14;0100;Server@node2;Req;;Type 11 request received from Scheduler@node2.supernodexp.hpc, sock=20
02/14/2018 04:13:14;0008;Server@node2;Job;1157.node2.supernodexp.hpc;Job Modified at request of Scheduler@node2.supernodexp.hpc
02/14/2018 04:13:14;0040;Server@node2;Svr;node2.supernodexp.hpc;Scheduler sent command 1
02/14/2018 04:13:14;0040;Server@node2;Svr;node2.supernodexp.hpc;Scheduler sent command 0
02/14/2018 04:13:14;0100;Server@node2;Req;;Type 21 request received from Scheduler@node2.supernodexp.hpc, sock=20
02/14/2018 04:13:14;0100;Server@node2;Req;;Type 81 request received from Scheduler@node2.supernodexp.hpc, sock=20
02/14/2018 04:13:14;0100;Server@node2;Req;;Type 71 request received from Scheduler@node2.supernodexp.hpc, sock=20
02/14/2018 04:13:14;0100;Server@node2;Req;;Type 58 request received from Scheduler@node2.supernodexp.hpc, sock=20
02/14/2018 04:13:14;0100;Server@node2;Req;;Type 1 request received from ctminh@node2.supernodexp.hpc, sock=16
02/14/2018 04:13:14;0100;Server@node2;Req;;Type 3 request received from ctminh@node2.supernodexp.hpc, sock=16
02/14/2018 04:13:14;0100;Server@node2;Req;;Type 5 request received from ctminh@node2.supernodexp.hpc, sock=16
02/14/2018 04:13:14;0100;Server@node2;Job;1167.node2.supernodexp.hpc;enqueuing into workq, state 1 hop 1
02/14/2018 04:13:14;0008;Server@node2;Job;1167.node2.supernodexp.hpc;Job Queued at request of ctminh@node2.supernodexp.hpc, owner = ctminh@node2.supernodexp.hpc, job name = vast1, queue = workq
02/14/2018 04:13:14;0100;Server@node2;Req;;Type 1 request received from ctminh@node2.supernodexp.hpc, sock=16
02/14/2018 04:13:14;0100;Server@node2;Req;;Type 3 request received from ctminh@node2.supernodexp.hpc, sock=16
02/14/2018 04:13:14;0100;Server@node2;Req;;Type 5 request received from ctminh@node2.supernodexp.hpc, sock=16
02/14/2018 04:13:14;0100;Server@node2;Job;1168.node2.supernodexp.hpc;enqueuing into workq, state 1 hop 1
02/14/2018 04:13:14;0008;Server@node2;Job;1168.node2.supernodexp.hpc;Job Queued at request of ctminh@node2.supernodexp.hpc, owner = ctminh@node2.supernodexp.hpc, job name = jacobi, queue = workq
02/14/2018 04:13:14;0100;Server@node2;Req;;Type 1 request received from ctminh@node2.supernodexp.hpc, sock=16
02/14/2018 04:13:14;0100;Server@node2;Req;;Type 3 request received from ctminh@node2.supernodexp.hpc, sock=16
02/14/2018 04:13:14;0100;Server@node2;Req;;Type 5 request received from ctminh@node2.supernodexp.hpc, sock=16
02/14/2018 04:13:14;0100;Server@node2;Job;1169.node2.supernodexp.hpc;enqueuing into workq, state 1 hop 1
02/14/2018 04:13:14;0008;Server@node2;Job;1169.node2.supernodexp.hpc;Job Queued at request of ctminh@node2.supernodexp.hpc, owner = ctminh@node2.supernodexp.hpc, job name = vectorization, queue = workq
02/14/2018 04:13:14;0100;Server@node2;Req;;Type 20 request received from Scheduler@node2.supernodexp.hpc, sock=20
02/14/2018 04:13:14;0100;Server@node2;Req;;Type 51 request received from Scheduler@node2.supernodexp.hpc, sock=20
02/14/2018 04:13:14;0100;Server@node2;Req;;Type 1 request received from ctminh@node2.supernodexp.hpc, sock=16
02/14/2018 04:13:14;0100;Server@node2;Req;;Type 3 request received from ctminh@node2.supernodexp.hpc, sock=16
02/14/2018 04:13:14;0100;Server@node2;Req;;Type 5 request received from ctminh@node2.supernodexp.hpc, sock=16
02/14/2018 04:13:14;0100;Server@node2;Job;1170.node2.supernodexp.hpc;enqueuing into workq, state 1 hop 1
02/14/2018 04:13:14;0008;Server@node2;Job;1170.node2.supernodexp.hpc;Job Queued at request of ctminh@node2.supernodexp.hpc, owner = ctminh@node2.supernodexp.hpc, job name = sweep, queue = workq
02/14/2018 04:13:14;0100;Server@node2;Req;;Type 11 request received from Scheduler@node2.supernodexp.hpc, sock=20
02/14/2018 04:13:14;0008;Server@node2;Job;1167.node2.supernodexp.hpc;Job Modified at request of Scheduler@node2.supernodexp.hpc
02/14/2018 04:13:14;0100;Server@node2;Req;;Type 11 request received from Scheduler@node2.supernodexp.hpc, sock=20
02/14/2018 04:13:14;0008;Server@node2;Job;1165.node2.supernodexp.hpc;Job Modified at request of Scheduler@node2.supernodexp.hpc
02/14/2018 04:13:14;0100;Server@node2;Req;;Type 11 request received from Scheduler@node2.supernodexp.hpc, sock=20
02/14/2018 04:13:14;0008;Server@node2;Job;1166.node2.supernodexp.hpc;Job Modified at request of Scheduler@node2.supernodexp.hpc
02/14/2018 04:13:14;0100;Server@node2;Req;;Type 11 request received from Scheduler@node2.supernodexp.hpc, sock=20
02/14/2018 04:13:14;0008;Server@node2;Job;1168.node2.supernodexp.hpc;Job Modified at request of Scheduler@node2.supernodexp.hpc
02/14/2018 04:13:14;0100;Server@node2;Req;;Type 11 request received from Scheduler@node2.supernodexp.hpc, sock=20
02/14/2018 04:13:14;0008;Server@node2;Job;1164.node2.supernodexp.hpc;Job Modified at request of Scheduler@node2.supernodexp.hpc
02/14/2018 04:13:14;0100;Server@node2;Req;;Type 11 request received from Scheduler@node2.supernodexp.hpc, sock=20
02/14/2018 04:13:14;0008;Server@node2;Job;1161.node2.supernodexp.hpc;Job Modified at request of Scheduler@node2.supernodexp.hpc
02/14/2018 04:13:14;0100;Server@node2;Req;;Type 11 request received from Scheduler@node2.supernodexp.hpc, sock=20
02/14/2018 04:13:14;0008;Server@node2;Job;1162.node2.supernodexp.hpc;Job Modified at request of Scheduler@node2.supernodexp.hpc
02/14/2018 04:13:14;0100;Server@node2;Req;;Type 11 request received from Scheduler@node2.supernodexp.hpc, sock=20
02/14/2018 04:13:14;0008;Server@node2;Job;1169.node2.supernodexp.hpc;Job Modified at request of Scheduler@node2.supernodexp.hpc
02/14/2018 04:13:14;0100;Server@node2;Req;;Type 11 request received from Scheduler@node2.supernodexp.hpc, sock=20
02/14/2018 04:13:14;0008;Server@node2;Job;1163.node2.supernodexp.hpc;Job Modified at request of Scheduler@node2.supernodexp.hpc
02/14/2018 04:13:14;0040;Server@node2;Svr;node2.supernodexp.hpc;Scheduler sent command 1
02/14/2018 04:13:14;0040;Server@node2;Svr;node2.supernodexp.hpc;Scheduler sent command 0
02/14/2018 04:13:14;0100;Server@node2;Req;;Type 21 request received from Scheduler@node2.supernodexp.hpc, sock=20
02/14/2018 04:13:14;0100;Server@node2;Req;;Type 81 request received from Scheduler@node2.supernodexp.hpc, sock=20
02/14/2018 04:13:14;0100;Server@node2;Req;;Type 71 request received from Scheduler@node2.supernodexp.hpc, sock=20
02/14/2018 04:13:14;0100;Server@node2;Req;;Type 58 request received from Scheduler@node2.supernodexp.hpc, sock=20
02/14/2018 04:13:14;0100;Server@node2;Req;;Type 20 request received from Scheduler@node2.supernodexp.hpc, sock=20
02/14/2018 04:13:14;0100;Server@node2;Req;;Type 51 request received from Scheduler@node2.supernodexp.hpc, sock=20
02/14/2018 04:13:14;0100;Server@node2;Req;;Type 11 request received from Scheduler@node2.supernodexp.hpc, sock=20
02/14/2018 04:13:14;0008;Server@node2;Job;1170.node2.supernodexp.hpc;Job Modified at request of Scheduler@node2.supernodexp.hpc
02/14/2018 04:14:04;0100;Server@node2;Req;;Type 1 request received from ctminh@node2.supernodexp.hpc, sock=16
02/14/2018 04:14:04;0100;Server@node2;Req;;Type 3 request received from ctminh@node2.supernodexp.hpc, sock=16
02/14/2018 04:14:04;0100;Server@node2;Req;;Type 5 request received from ctminh@node2.supernodexp.hpc, sock=16
02/14/2018 04:14:04;0100;Server@node2;Job;1171.node2.supernodexp.hpc;enqueuing into workq, state 1 hop 1
02/14/2018 04:14:04;0008;Server@node2;Job;1171.node2.supernodexp.hpc;Job Queued at request of ctminh@node2.supernodexp.hpc, owner = ctminh@node2.supernodexp.hpc, job name = telemac1, queue = workq
02/14/2018 04:14:04;0040;Server@node2;Svr;node2.supernodexp.hpc;Scheduler sent command 1
02/14/2018 04:14:04;0040;Server@node2;Svr;node2.supernodexp.hpc;Scheduler sent command 0
02/14/2018 04:14:04;0100;Server@node2;Req;;Type 21 request received from Scheduler@node2.supernodexp.hpc, sock=20
02/14/2018 04:14:04;0100;Server@node2;Req;;Type 81 request received from Scheduler@node2.supernodexp.hpc, sock=20
02/14/2018 04:14:04;0100;Server@node2;Req;;Type 71 request received from Scheduler@node2.supernodexp.hpc, sock=20
02/14/2018 04:14:04;0100;Server@node2;Req;;Type 58 request received from Scheduler@node2.supernodexp.hpc, sock=20
02/14/2018 04:14:04;0100;Server@node2;Req;;Type 1 request received from ctminh@node2.supernodexp.hpc, sock=16
02/14/2018 04:14:04;0100;Server@node2;Req;;Type 3 request received from ctminh@node2.supernodexp.hpc, sock=16
02/14/2018 04:14:04;0100;Server@node2;Req;;Type 5 request received from ctminh@node2.supernodexp.hpc, sock=16
02/14/2018 04:14:04;0100;Server@node2;Job;1172.node2.supernodexp.hpc;enqueuing into workq, state 1 hop 1
02/14/2018 04:14:04;0008;Server@node2;Job;1172.node2.supernodexp.hpc;Job Queued at request of ctminh@node2.supernodexp.hpc, owner = ctminh@node2.supernodexp.hpc, job name = telemac1, queue = workq
02/14/2018 04:14:04;0100;Server@node2;Req;;Type 1 request received from ctminh@node2.supernodexp.hpc, sock=16
02/14/2018 04:14:04;0100;Server@node2;Req;;Type 3 request received from ctminh@node2.supernodexp.hpc, sock=16
02/14/2018 04:14:04;0100;Server@node2;Req;;Type 5 request received from ctminh@node2.supernodexp.hpc, sock=16
02/14/2018 04:14:04;0100;Server@node2;Job;1173.node2.supernodexp.hpc;enqueuing into workq, state 1 hop 1
02/14/2018 04:14:04;0008;Server@node2;Job;1173.node2.supernodexp.hpc;Job Queued at request of ctminh@node2.supernodexp.hpc, owner = ctminh@node2.supernodexp.hpc, job name = telemac3, queue = workq
02/14/2018 04:14:04;0100;Server@node2;Req;;Type 20 request received from Scheduler@node2.supernodexp.hpc, sock=20
02/14/2018 04:14:04;0100;Server@node2;Req;;Type 51 request received from Scheduler@node2.supernodexp.hpc, sock=20
02/14/2018 04:14:04;0100;Server@node2;Req;;Type 1 request received from ctminh@node2.supernodexp.hpc, sock=16
02/14/2018 04:14:04;0100;Server@node2;Req;;Type 3 request received from ctminh@node2.supernodexp.hpc, sock=16
02/14/2018 04:14:04;0100;Server@node2;Req;;Type 5 request received from ctminh@node2.supernodexp.hpc, sock=16
02/14/2018 04:14:04;0100;Server@node2;Job;1174.node2.supernodexp.hpc;enqueuing into workq, state 1 hop 1
02/14/2018 04:14:04;0008;Server@node2;Job;1174.node2.supernodexp.hpc;Job Queued at request of ctminh@node2.supernodexp.hpc, owner = ctminh@node2.supernodexp.hpc, job name = lu-decomp, queue = workq
02/14/2018 04:14:04;0100;Server@node2;Req;;Type 1 request received from ctminh@node2.supernodexp.hpc, sock=16
02/14/2018 04:14:04;0100;Server@node2;Req;;Type 3 request received from ctminh@node2.supernodexp.hpc, sock=16
02/14/2018 04:14:04;0100;Server@node2;Req;;Type 5 request received from ctminh@node2.supernodexp.hpc, sock=16
02/14/2018 04:14:04;0100;Server@node2;Job;1175.node2.supernodexp.hpc;enqueuing into workq, state 1 hop 1
02/14/2018 04:14:04;0008;Server@node2;Job;1175.node2.supernodexp.hpc;Job Queued at request of ctminh@node2.supernodexp.hpc, owner = ctminh@node2.supernodexp.hpc, job name = nbody, queue = workq
02/14/2018 04:14:04;0100;Server@node2;Req;;Type 1 request received from ctminh@node2.supernodexp.hpc, sock=16
02/14/2018 04:14:04;0100;Server@node2;Req;;Type 3 request received from ctminh@node2.supernodexp.hpc, sock=16
02/14/2018 04:14:04;0100;Server@node2;Req;;Type 5 request received from ctminh@node2.supernodexp.hpc, sock=16
02/14/2018 04:14:04;0100;Server@node2;Job;1176.node2.supernodexp.hpc;enqueuing into workq, state 1 hop 1
02/14/2018 04:14:04;0008;Server@node2;Job;1176.node2.supernodexp.hpc;Job Queued at request of ctminh@node2.supernodexp.hpc, owner = ctminh@node2.supernodexp.hpc, job name = qe_mic_test, queue = workq
02/14/2018 04:14:04;0100;Server@node2;Req;;Type 1 request received from ctminh@node2.supernodexp.hpc, sock=16
02/14/2018 04:14:04;0100;Server@node2;Req;;Type 3 request received from ctminh@node2.supernodexp.hpc, sock=16
02/14/2018 04:14:04;0100;Server@node2;Req;;Type 5 request received from ctminh@node2.supernodexp.hpc, sock=16
02/14/2018 04:14:04;0100;Server@node2;Job;1177.node2.supernodexp.hpc;enqueuing into workq, state 1 hop 1
02/14/2018 04:14:04;0008;Server@node2;Job;1177.node2.supernodexp.hpc;Job Queued at request of ctminh@node2.supernodexp.hpc, owner = ctminh@node2.supernodexp.hpc, job name = jacobi, queue = workq
02/14/2018 04:14:04;0100;Server@node2;Req;;Type 1 request received from ctminh@node2.supernodexp.hpc, sock=16
02/14/2018 04:14:04;0100;Server@node2;Req;;Type 3 request received from ctminh@node2.supernodexp.hpc, sock=16
02/14/2018 04:14:04;0100;Server@node2;Req;;Type 5 request received from ctminh@node2.supernodexp.hpc, sock=16
02/14/2018 04:14:04;0100;Server@node2;Job;1178.node2.supernodexp.hpc;enqueuing into workq, state 1 hop 1
02/14/2018 04:14:04;0008;Server@node2;Job;1178.node2.supernodexp.hpc;Job Queued at request of ctminh@node2.supernodexp.hpc, owner = ctminh@node2.supernodexp.hpc, job name = nbody, queue = workq
02/14/2018 04:14:04;0100;Server@node2;Req;;Type 11 request received from Scheduler@node2.supernodexp.hpc, sock=20
02/14/2018 04:14:04;0008;Server@node2;Job;1171.node2.supernodexp.hpc;Job Modified at request of Scheduler@node2.supernodexp.hpc
02/14/2018 04:14:04;0100;Server@node2;Req;;Type 11 request received from Scheduler@node2.supernodexp.hpc, sock=20
02/14/2018 04:14:04;0008;Server@node2;Job;1172.node2.supernodexp.hpc;Job Modified at request of Scheduler@node2.supernodexp.hpc
02/14/2018 04:14:04;0100;Server@node2;Req;;Type 11 request received from Scheduler@node2.supernodexp.hpc, sock=20
02/14/2018 04:14:04;0008;Server@node2;Job;1173.node2.supernodexp.hpc;Job Modified at request of Scheduler@node2.supernodexp.hpc
02/14/2018 04:14:04;0040;Server@node2;Svr;node2.supernodexp.hpc;Scheduler sent command 1
02/14/2018 04:14:04;0040;Server@node2;Svr;node2.supernodexp.hpc;Scheduler sent command 0
02/14/2018 04:14:04;0100;Server@node2;Req;;Type 21 request received from Scheduler@node2.supernodexp.hpc, sock=20
02/14/2018 04:14:04;0100;Server@node2;Req;;Type 81 request received from Scheduler@node2.supernodexp.hpc, sock=20
02/14/2018 04:14:04;0100;Server@node2;Req;;Type 71 request received from Scheduler@node2.supernodexp.hpc, sock=20
02/14/2018 04:14:04;0100;Server@node2;Req;;Type 58 request received from Scheduler@node2.supernodexp.hpc, sock=20
02/14/2018 04:14:04;0100;Server@node2;Req;;Type 1 request received from ctminh@node2.supernodexp.hpc, sock=16
02/14/2018 04:14:04;0100;Server@node2;Req;;Type 3 request received from ctminh@node2.supernodexp.hpc, sock=16
02/14/2018 04:14:04;0100;Server@node2;Req;;Type 5 request received from ctminh@node2.supernodexp.hpc, sock=16
02/14/2018 04:14:04;0100;Server@node2;Job;1179.node2.supernodexp.hpc;enqueuing into workq, state 1 hop 1
02/14/2018 04:14:04;0008;Server@node2;Job;1179.node2.supernodexp.hpc;Job Queued at request of ctminh@node2.supernodexp.hpc, owner = ctminh@node2.supernodexp.hpc, job name = nbody, queue = workq
02/14/2018 04:14:04;0100;Server@node2;Req;;Type 1 request received from ctminh@node2.supernodexp.hpc, sock=16
02/14/2018 04:14:04;0100;Server@node2;Req;;Type 3 request received from ctminh@node2.supernodexp.hpc, sock=16
02/14/2018 04:14:04;0100;Server@node2;Req;;Type 5 request received from ctminh@node2.supernodexp.hpc, sock=16
02/14/2018 04:14:04;0100;Server@node2;Job;1180.node2.supernodexp.hpc;enqueuing into workq, state 1 hop 1
02/14/2018 04:14:04;0008;Server@node2;Job;1180.node2.supernodexp.hpc;Job Queued at request of ctminh@node2.supernodexp.hpc, owner = ctminh@node2.supernodexp.hpc, job name = histogram, queue = workq
02/14/2018 04:14:04;0100;Server@node2;Req;;Type 20 request received from Scheduler@node2.supernodexp.hpc, sock=20
02/14/2018 04:14:04;0100;Server@node2;Req;;Type 51 request received from Scheduler@node2.supernodexp.hpc, sock=20
02/14/2018 04:14:04;0100;Server@node2;Req;;Type 11 request received from Scheduler@node2.supernodexp.hpc, sock=20
02/14/2018 04:14:04;0008;Server@node2;Job;1176.node2.supernodexp.hpc;Job Modified at request of Scheduler@node2.supernodexp.hpc
02/14/2018 04:14:04;0100;Server@node2;Req;;Type 11 request received from Scheduler@node2.supernodexp.hpc, sock=20
02/14/2018 04:14:04;0008;Server@node2;Job;1177.node2.supernodexp.hpc;Job Modified at request of Scheduler@node2.supernodexp.hpc
02/14/2018 04:14:04;0100;Server@node2;Req;;Type 11 request received from Scheduler@node2.supernodexp.hpc, sock=20
02/14/2018 04:14:04;0008;Server@node2;Job;1175.node2.supernodexp.hpc;Job Modified at request of Scheduler@node2.supernodexp.hpc
02/14/2018 04:14:04;0100;Server@node2;Req;;Type 11 request received from Scheduler@node2.supernodexp.hpc, sock=20
02/14/2018 04:14:04;0008;Server@node2;Job;1178.node2.supernodexp.hpc;Job Modified at request of Scheduler@node2.supernodexp.hpc
02/14/2018 04:14:04;0100;Server@node2;Req;;Type 11 request received from Scheduler@node2.supernodexp.hpc, sock=20
02/14/2018 04:14:04;0008;Server@node2;Job;1179.node2.supernodexp.hpc;Job Modified at request of Scheduler@node2.supernodexp.hpc
02/14/2018 04:14:04;0100;Server@node2;Req;;Type 11 request received from Scheduler@node2.supernodexp.hpc, sock=20
02/14/2018 04:14:04;0008;Server@node2;Job;1180.node2.supernodexp.hpc;Job Modified at request of Scheduler@node2.supernodexp.hpc
02/14/2018 04:14:04;0100;Server@node2;Req;;Type 11 request received from Scheduler@node2.supernodexp.hpc, sock=20
02/14/2018 04:14:04;0008;Server@node2;Job;1174.node2.supernodexp.hpc;Job Modified at request of Scheduler@node2.supernodexp.hpc
02/14/2018 04:14:04;0040;Server@node2;Svr;node2.supernodexp.hpc;Scheduler sent command 1
02/14/2018 04:14:04;0040;Server@node2;Svr;node2.supernodexp.hpc;Scheduler sent command 0
02/14/2018 04:14:04;0100;Server@node2;Req;;Type 21 request received from Scheduler@node2.supernodexp.hpc, sock=20
02/14/2018 04:14:04;0100;Server@node2;Req;;Type 81 request received from Scheduler@node2.supernodexp.hpc, sock=20
02/14/2018 04:14:04;0100;Server@node2;Req;;Type 71 request received from Scheduler@node2.supernodexp.hpc, sock=20
02/14/2018 04:14:04;0100;Server@node2;Req;;Type 58 request received from Scheduler@node2.supernodexp.hpc, sock=20
02/14/2018 04:14:04;0100;Server@node2;Req;;Type 20 request received from Scheduler@node2.supernodexp.hpc, sock=20
02/14/2018 04:14:04;0100;Server@node2;Req;;Type 51 request received from Scheduler@node2.supernodexp.hpc, sock=20
02/14/2018 04:14:35;0100;Server@node2;Req;;Type 1 request received from ctminh@node2.supernodexp.hpc, sock=16
02/14/2018 04:14:35;0100;Server@node2;Req;;Type 3 request received from ctminh@node2.supernodexp.hpc, sock=16
02/14/2018 04:14:35;0100;Server@node2;Req;;Type 5 request received from ctminh@node2.supernodexp.hpc, sock=16
02/14/2018 04:14:35;0100;Server@node2;Job;1181.node2.supernodexp.hpc;enqueuing into workq, state 1 hop 1
02/14/2018 04:14:35;0008;Server@node2;Job;1181.node2.supernodexp.hpc;Job Queued at request of ctminh@node2.supernodexp.hpc, owner = ctminh@node2.supernodexp.hpc, job name = telemac2, queue = workq
02/14/2018 04:14:35;0040;Server@node2;Svr;node2.supernodexp.hpc;Scheduler sent command 1
02/14/2018 04:14:35;0040;Server@node2;Svr;node2.supernodexp.hpc;Scheduler sent command 0
02/14/2018 04:14:35;0100;Server@node2;Req;;Type 21 request received from Scheduler@node2.supernodexp.hpc, sock=20
02/14/2018 04:14:35;0100;Server@node2;Req;;Type 81 request received from Scheduler@node2.supernodexp.hpc, sock=20
02/14/2018 04:14:35;0100;Server@node2;Req;;Type 71 request received from Scheduler@node2.supernodexp.hpc, sock=20
02/14/2018 04:14:35;0100;Server@node2;Req;;Type 58 request received from Scheduler@node2.supernodexp.hpc, sock=20
02/14/2018 04:14:35;0100;Server@node2;Req;;Type 1 request received from ctminh@node2.supernodexp.hpc, sock=16
02/14/2018 04:14:35;0100;Server@node2;Req;;Type 3 request received from ctminh@node2.supernodexp.hpc, sock=16
02/14/2018 04:14:35;0100;Server@node2;Req;;Type 5 request received from ctminh@node2.supernodexp.hpc, sock=16
02/14/2018 04:14:35;0100;Server@node2;Job;1182.node2.supernodexp.hpc;enqueuing into workq, state 1 hop 1
02/14/2018 04:14:35;0008;Server@node2;Job;1182.node2.supernodexp.hpc;Job Queued at request of ctminh@node2.supernodexp.hpc, owner = ctminh@node2.supernodexp.hpc, job name = sweep, queue = workq
02/14/2018 04:14:35;0100;Server@node2;Req;;Type 1 request received from ctminh@node2.supernodexp.hpc, sock=16
02/14/2018 04:14:35;0100;Server@node2;Req;;Type 3 request received from ctminh@node2.supernodexp.hpc, sock=16
02/14/2018 04:14:35;0100;Server@node2;Req;;Type 5 request received from ctminh@node2.supernodexp.hpc, sock=16
02/14/2018 04:14:35;0100;Server@node2;Job;1183.node2.supernodexp.hpc;enqueuing into workq, state 1 hop 1
02/14/2018 04:14:35;0008;Server@node2;Job;1183.node2.supernodexp.hpc;Job Queued at request of ctminh@node2.supernodexp.hpc, owner = ctminh@node2.supernodexp.hpc, job name = telemac1, queue = workq
02/14/2018 04:14:35;0100;Server@node2;Req;;Type 20 request received from Scheduler@node2.supernodexp.hpc, sock=20
02/14/2018 04:14:35;0100;Server@node2;Req;;Type 51 request received from Scheduler@node2.supernodexp.hpc, sock=20
02/14/2018 04:14:35;0100;Server@node2;Req;;Type 1 request received from ctminh@node2.supernodexp.hpc, sock=16
02/14/2018 04:14:35;0100;Server@node2;Req;;Type 3 request received from ctminh@node2.supernodexp.hpc, sock=16
02/14/2018 04:14:35;0100;Server@node2;Req;;Type 5 request received from ctminh@node2.supernodexp.hpc, sock=16
02/14/2018 04:14:35;0100;Server@node2;Job;1184.node2.supernodexp.hpc;enqueuing into workq, state 1 hop 1
02/14/2018 04:14:35;0008;Server@node2;Job;1184.node2.supernodexp.hpc;Job Queued at request of ctminh@node2.supernodexp.hpc, owner = ctminh@node2.supernodexp.hpc, job name = thread-affinity, queue = workq
02/14/2018 04:14:36;0100;Server@node2;Req;;Type 11 request received from Scheduler@node2.supernodexp.hpc, sock=20
02/14/2018 04:14:36;0008;Server@node2;Job;1181.node2.supernodexp.hpc;Job Modified at request of Scheduler@node2.supernodexp.hpc
02/14/2018 04:14:36;0100;Server@node2;Req;;Type 11 request received from Scheduler@node2.supernodexp.hpc, sock=20
02/14/2018 04:14:36;0008;Server@node2;Job;1183.node2.supernodexp.hpc;Job Modified at request of Scheduler@node2.supernodexp.hpc
02/14/2018 04:14:36;0100;Server@node2;Req;;Type 11 request received from Scheduler@node2.supernodexp.hpc, sock=20
02/14/2018 04:14:36;0008;Server@node2;Job;1182.node2.supernodexp.hpc;Job Modified at request of Scheduler@node2.supernodexp.hpc
02/14/2018 04:14:36;0040;Server@node2;Svr;node2.supernodexp.hpc;Scheduler sent command 1
02/14/2018 04:14:36;0040;Server@node2;Svr;node2.supernodexp.hpc;Scheduler sent command 0
02/14/2018 04:14:36;0100;Server@node2;Req;;Type 21 request received from Scheduler@node2.supernodexp.hpc, sock=20
02/14/2018 04:14:36;0100;Server@node2;Req;;Type 81 request received from Scheduler@node2.supernodexp.hpc, sock=20
02/14/2018 04:14:36;0100;Server@node2;Req;;Type 71 request received from Scheduler@node2.supernodexp.hpc, sock=20
02/14/2018 04:14:36;0100;Server@node2;Req;;Type 58 request received from Scheduler@node2.supernodexp.hpc, sock=20
02/14/2018 04:14:36;0100;Server@node2;Req;;Type 20 request received from Scheduler@node2.supernodexp.hpc, sock=20
02/14/2018 04:14:36;0100;Server@node2;Req;;Type 51 request received from Scheduler@node2.supernodexp.hpc, sock=20
02/14/2018 04:14:36;0100;Server@node2;Req;;Type 11 request received from Scheduler@node2.supernodexp.hpc, sock=20
02/14/2018 04:14:36;0008;Server@node2;Job;1184.node2.supernodexp.hpc;Job Modified at request of Scheduler@node2.supernodexp.hpc
02/14/2018 04:15:30;0100;Server@node2;Req;;Type 1 request received from ctminh@node2.supernodexp.hpc, sock=16
02/14/2018 04:15:30;0100;Server@node2;Req;;Type 3 request received from ctminh@node2.supernodexp.hpc, sock=16
02/14/2018 04:15:30;0100;Server@node2;Req;;Type 5 request received from ctminh@node2.supernodexp.hpc, sock=16
02/14/2018 04:15:30;0100;Server@node2;Job;1185.node2.supernodexp.hpc;enqueuing into workq, state 1 hop 1
02/14/2018 04:15:30;0008;Server@node2;Job;1185.node2.supernodexp.hpc;Job Queued at request of ctminh@node2.supernodexp.hpc, owner = ctminh@node2.supernodexp.hpc, job name = thread-affinity, queue = workq
02/14/2018 04:15:30;0040;Server@node2;Svr;node2.supernodexp.hpc;Scheduler sent command 1
02/14/2018 04:15:30;0040;Server@node2;Svr;node2.supernodexp.hpc;Scheduler sent command 0
02/14/2018 04:15:30;0100;Server@node2;Req;;Type 21 request received from Scheduler@node2.supernodexp.hpc, sock=20
02/14/2018 04:15:30;0100;Server@node2;Req;;Type 81 request received from Scheduler@node2.supernodexp.hpc, sock=20
02/14/2018 04:15:30;0100;Server@node2;Req;;Type 71 request received from Scheduler@node2.supernodexp.hpc, sock=20
02/14/2018 04:15:30;0100;Server@node2;Req;;Type 58 request received from Scheduler@node2.supernodexp.hpc, sock=20
02/14/2018 04:15:30;0100;Server@node2;Req;;Type 1 request received from ctminh@node2.supernodexp.hpc, sock=16
02/14/2018 04:15:30;0100;Server@node2;Req;;Type 3 request received from ctminh@node2.supernodexp.hpc, sock=16
02/14/2018 04:15:30;0100;Server@node2;Req;;Type 5 request received from ctminh@node2.supernodexp.hpc, sock=16
02/14/2018 04:15:30;0100;Server@node2;Job;1186.node2.supernodexp.hpc;enqueuing into workq, state 1 hop 1
02/14/2018 04:15:30;0008;Server@node2;Job;1186.node2.supernodexp.hpc;Job Queued at request of ctminh@node2.supernodexp.hpc, owner = ctminh@node2.supernodexp.hpc, job name = matrix-x-vector, queue = workq
02/14/2018 04:15:30;0100;Server@node2;Req;;Type 1 request received from ctminh@node2.supernodexp.hpc, sock=16
02/14/2018 04:15:31;0100;Server@node2;Req;;Type 3 request received from ctminh@node2.supernodexp.hpc, sock=16
02/14/2018 04:15:31;0100;Server@node2;Req;;Type 5 request received from ctminh@node2.supernodexp.hpc, sock=16
02/14/2018 04:15:31;0100;Server@node2;Job;1187.node2.supernodexp.hpc;enqueuing into workq, state 1 hop 1
02/14/2018 04:15:31;0008;Server@node2;Job;1187.node2.supernodexp.hpc;Job Queued at request of ctminh@node2.supernodexp.hpc, owner = ctminh@node2.supernodexp.hpc, job name = telemac1, queue = workq
02/14/2018 04:15:31;0100;Server@node2;Req;;Type 1 request received from ctminh@node2.supernodexp.hpc, sock=16
02/14/2018 04:15:31;0100;Server@node2;Req;;Type 3 request received from ctminh@node2.supernodexp.hpc, sock=16
02/14/2018 04:15:31;0100;Server@node2;Req;;Type 5 request received from ctminh@node2.supernodexp.hpc, sock=16
02/14/2018 04:15:31;0100;Server@node2;Job;1188.node2.supernodexp.hpc;enqueuing into workq, state 1 hop 1
02/14/2018 04:15:31;0008;Server@node2;Job;1188.node2.supernodexp.hpc;Job Queued at request of ctminh@node2.supernodexp.hpc, owner = ctminh@node2.supernodexp.hpc, job name = lu-decomp, queue = workq
02/14/2018 04:15:31;0100;Server@node2;Req;;Type 20 request received from Scheduler@node2.supernodexp.hpc, sock=20
02/14/2018 04:15:31;0100;Server@node2;Req;;Type 51 request received from Scheduler@node2.supernodexp.hpc, sock=20
02/14/2018 04:15:31;0100;Server@node2;Req;;Type 11 request received from Scheduler@node2.supernodexp.hpc, sock=20
02/14/2018 04:15:31;0008;Server@node2;Job;1187.node2.supernodexp.hpc;Job Modified at request of Scheduler@node2.supernodexp.hpc
02/14/2018 04:15:31;0100;Server@node2;Req;;Type 11 request received from Scheduler@node2.supernodexp.hpc, sock=20
02/14/2018 04:15:31;0008;Server@node2;Job;1185.node2.supernodexp.hpc;Job Modified at request of Scheduler@node2.supernodexp.hpc
02/14/2018 04:15:31;0100;Server@node2;Req;;Type 11 request received from Scheduler@node2.supernodexp.hpc, sock=20
02/14/2018 04:15:31;0008;Server@node2;Job;1186.node2.supernodexp.hpc;Job Modified at request of Scheduler@node2.supernodexp.hpc
02/14/2018 04:15:31;0100;Server@node2;Req;;Type 11 request received from Scheduler@node2.supernodexp.hpc, sock=20
02/14/2018 04:15:31;0008;Server@node2;Job;1188.node2.supernodexp.hpc;Job Modified at request of Scheduler@node2.supernodexp.hpc
02/14/2018 04:15:31;0040;Server@node2;Svr;node2.supernodexp.hpc;Scheduler sent command 1
02/14/2018 04:15:31;0040;Server@node2;Svr;node2.supernodexp.hpc;Scheduler sent command 0
02/14/2018 04:15:31;0100;Server@node2;Req;;Type 21 request received from Scheduler@node2.supernodexp.hpc, sock=20
02/14/2018 04:15:31;0100;Server@node2;Req;;Type 81 request received from Scheduler@node2.supernodexp.hpc, sock=20
02/14/2018 04:15:31;0100;Server@node2;Req;;Type 71 request received from Scheduler@node2.supernodexp.hpc, sock=20
02/14/2018 04:15:31;0100;Server@node2;Req;;Type 58 request received from Scheduler@node2.supernodexp.hpc, sock=20
02/14/2018 04:15:31;0100;Server@node2;Req;;Type 20 request received from Scheduler@node2.supernodexp.hpc, sock=20
02/14/2018 04:15:31;0100;Server@node2;Req;;Type 51 request received from Scheduler@node2.supernodexp.hpc, sock=20
02/14/2018 04:16:13;0100;Server@node2;Req;;Type 1 request received from ctminh@node2.supernodexp.hpc, sock=16
02/14/2018 04:16:13;0100;Server@node2;Req;;Type 3 request received from ctminh@node2.supernodexp.hpc, sock=16
02/14/2018 04:16:13;0100;Server@node2;Req;;Type 5 request received from ctminh@node2.supernodexp.hpc, sock=16
02/14/2018 04:16:13;0100;Server@node2;Job;1189.node2.supernodexp.hpc;enqueuing into workq, state 1 hop 1
02/14/2018 04:16:13;0008;Server@node2;Job;1189.node2.supernodexp.hpc;Job Queued at request of ctminh@node2.supernodexp.hpc, owner = ctminh@node2.supernodexp.hpc, job name = vast1, queue = workq
02/14/2018 04:16:13;0040;Server@node2;Svr;node2.supernodexp.hpc;Scheduler sent command 1
02/14/2018 04:16:13;0040;Server@node2;Svr;node2.supernodexp.hpc;Scheduler sent command 0
02/14/2018 04:16:13;0100;Server@node2;Req;;Type 21 request received from Scheduler@node2.supernodexp.hpc, sock=20
02/14/2018 04:16:13;0100;Server@node2;Req;;Type 81 request received from Scheduler@node2.supernodexp.hpc, sock=20
02/14/2018 04:16:13;0100;Server@node2;Req;;Type 71 request received from Scheduler@node2.supernodexp.hpc, sock=20
02/14/2018 04:16:13;0100;Server@node2;Req;;Type 58 request received from Scheduler@node2.supernodexp.hpc, sock=20
02/14/2018 04:16:13;0100;Server@node2;Req;;Type 1 request received from ctminh@node2.supernodexp.hpc, sock=16
02/14/2018 04:16:13;0100;Server@node2;Req;;Type 3 request received from ctminh@node2.supernodexp.hpc, sock=16
02/14/2018 04:16:13;0100;Server@node2;Req;;Type 5 request received from ctminh@node2.supernodexp.hpc, sock=16
02/14/2018 04:16:13;0100;Server@node2;Job;1190.node2.supernodexp.hpc;enqueuing into workq, state 1 hop 1
02/14/2018 04:16:13;0008;Server@node2;Job;1190.node2.supernodexp.hpc;Job Queued at request of ctminh@node2.supernodexp.hpc, owner = ctminh@node2.supernodexp.hpc, job name = vectorization, queue = workq
02/14/2018 04:16:13;0100;Server@node2;Req;;Type 1 request received from ctminh@node2.supernodexp.hpc, sock=16
02/14/2018 04:16:13;0100;Server@node2;Req;;Type 3 request received from ctminh@node2.supernodexp.hpc, sock=16
02/14/2018 04:16:13;0100;Server@node2;Req;;Type 5 request received from ctminh@node2.supernodexp.hpc, sock=16
02/14/2018 04:16:13;0100;Server@node2;Job;1191.node2.supernodexp.hpc;enqueuing into workq, state 1 hop 1
02/14/2018 04:16:13;0008;Server@node2;Job;1191.node2.supernodexp.hpc;Job Queued at request of ctminh@node2.supernodexp.hpc, owner = ctminh@node2.supernodexp.hpc, job name = matrix-x-vector, queue = workq
02/14/2018 04:16:13;0100;Server@node2;Req;;Type 1 request received from ctminh@node2.supernodexp.hpc, sock=16
02/14/2018 04:16:13;0100;Server@node2;Req;;Type 3 request received from ctminh@node2.supernodexp.hpc, sock=16
02/14/2018 04:16:13;0100;Server@node2;Req;;Type 5 request received from ctminh@node2.supernodexp.hpc, sock=16
02/14/2018 04:16:13;0100;Server@node2;Job;1192.node2.supernodexp.hpc;enqueuing into workq, state 1 hop 1
02/14/2018 04:16:13;0008;Server@node2;Job;1192.node2.supernodexp.hpc;Job Queued at request of ctminh@node2.supernodexp.hpc, owner = ctminh@node2.supernodexp.hpc, job name = telemac2, queue = workq
02/14/2018 04:16:13;0100;Server@node2;Req;;Type 20 request received from Scheduler@node2.supernodexp.hpc, sock=20
02/14/2018 04:16:13;0100;Server@node2;Req;;Type 51 request received from Scheduler@node2.supernodexp.hpc, sock=20
02/14/2018 04:16:13;0100;Server@node2;Req;;Type 11 request received from Scheduler@node2.supernodexp.hpc, sock=20
02/14/2018 04:16:13;0008;Server@node2;Job;1189.node2.supernodexp.hpc;Job Modified at request of Scheduler@node2.supernodexp.hpc
02/14/2018 04:16:13;0100;Server@node2;Req;;Type 11 request received from Scheduler@node2.supernodexp.hpc, sock=20
02/14/2018 04:16:13;0008;Server@node2;Job;1192.node2.supernodexp.hpc;Job Modified at request of Scheduler@node2.supernodexp.hpc
02/14/2018 04:16:13;0100;Server@node2;Req;;Type 11 request received from Scheduler@node2.supernodexp.hpc, sock=20
02/14/2018 04:16:13;0008;Server@node2;Job;1190.node2.supernodexp.hpc;Job Modified at request of Scheduler@node2.supernodexp.hpc
02/14/2018 04:16:13;0100;Server@node2;Req;;Type 11 request received from Scheduler@node2.supernodexp.hpc, sock=20
02/14/2018 04:16:13;0008;Server@node2;Job;1191.node2.supernodexp.hpc;Job Modified at request of Scheduler@node2.supernodexp.hpc
02/14/2018 04:16:13;0040;Server@node2;Svr;node2.supernodexp.hpc;Scheduler sent command 1
02/14/2018 04:16:13;0040;Server@node2;Svr;node2.supernodexp.hpc;Scheduler sent command 0
02/14/2018 04:16:13;0100;Server@node2;Req;;Type 21 request received from Scheduler@node2.supernodexp.hpc, sock=20
02/14/2018 04:16:13;0100;Server@node2;Req;;Type 81 request received from Scheduler@node2.supernodexp.hpc, sock=20
02/14/2018 04:16:13;0100;Server@node2;Req;;Type 71 request received from Scheduler@node2.supernodexp.hpc, sock=20
02/14/2018 04:16:13;0100;Server@node2;Req;;Type 58 request received from Scheduler@node2.supernodexp.hpc, sock=20
02/14/2018 04:16:13;0100;Server@node2;Req;;Type 20 request received from Scheduler@node2.supernodexp.hpc, sock=20
02/14/2018 04:16:13;0100;Server@node2;Req;;Type 51 request received from Scheduler@node2.supernodexp.hpc, sock=20
02/14/2018 04:16:53;0100;Server@node2;Req;;Type 1 request received from ctminh@node2.supernodexp.hpc, sock=16
02/14/2018 04:16:53;0100;Server@node2;Req;;Type 3 request received from ctminh@node2.supernodexp.hpc, sock=16
02/14/2018 04:16:53;0100;Server@node2;Req;;Type 5 request received from ctminh@node2.supernodexp.hpc, sock=16
02/14/2018 04:16:53;0100;Server@node2;Job;1193.node2.supernodexp.hpc;enqueuing into workq, state 1 hop 1
02/14/2018 04:16:53;0008;Server@node2;Job;1193.node2.supernodexp.hpc;Job Queued at request of ctminh@node2.supernodexp.hpc, owner = ctminh@node2.supernodexp.hpc, job name = nbody, queue = workq
02/14/2018 04:16:53;0040;Server@node2;Svr;node2.supernodexp.hpc;Scheduler sent command 1
02/14/2018 04:16:53;0040;Server@node2;Svr;node2.supernodexp.hpc;Scheduler sent command 0
02/14/2018 04:16:53;0100;Server@node2;Req;;Type 21 request received from Scheduler@node2.supernodexp.hpc, sock=20
02/14/2018 04:16:53;0100;Server@node2;Req;;Type 81 request received from Scheduler@node2.supernodexp.hpc, sock=20
02/14/2018 04:16:53;0100;Server@node2;Req;;Type 71 request received from Scheduler@node2.supernodexp.hpc, sock=20
02/14/2018 04:16:53;0100;Server@node2;Req;;Type 58 request received from Scheduler@node2.supernodexp.hpc, sock=20
02/14/2018 04:16:53;0100;Server@node2;Req;;Type 1 request received from ctminh@node2.supernodexp.hpc, sock=16
02/14/2018 04:16:53;0100;Server@node2;Req;;Type 3 request received from ctminh@node2.supernodexp.hpc, sock=16
02/14/2018 04:16:53;0100;Server@node2;Req;;Type 5 request received from ctminh@node2.supernodexp.hpc, sock=16
02/14/2018 04:16:53;0100;Server@node2;Job;1194.node2.supernodexp.hpc;enqueuing into workq, state 1 hop 1
02/14/2018 04:16:53;0008;Server@node2;Job;1194.node2.supernodexp.hpc;Job Queued at request of ctminh@node2.supernodexp.hpc, owner = ctminh@node2.supernodexp.hpc, job name = matrix-x-vector, queue = workq
02/14/2018 04:16:53;0100;Server@node2;Req;;Type 1 request received from ctminh@node2.supernodexp.hpc, sock=16
02/14/2018 04:16:53;0100;Server@node2;Req;;Type 3 request received from ctminh@node2.supernodexp.hpc, sock=16
02/14/2018 04:16:53;0100;Server@node2;Req;;Type 5 request received from ctminh@node2.supernodexp.hpc, sock=16
02/14/2018 04:16:53;0100;Server@node2;Job;1195.node2.supernodexp.hpc;enqueuing into workq, state 1 hop 1
02/14/2018 04:16:53;0008;Server@node2;Job;1195.node2.supernodexp.hpc;Job Queued at request of ctminh@node2.supernodexp.hpc, owner = ctminh@node2.supernodexp.hpc, job name = vast1, queue = workq
02/14/2018 04:16:53;0100;Server@node2;Req;;Type 20 request received from Scheduler@node2.supernodexp.hpc, sock=20
02/14/2018 04:16:53;0100;Server@node2;Req;;Type 51 request received from Scheduler@node2.supernodexp.hpc, sock=20
02/14/2018 04:16:53;0100;Server@node2;Req;;Type 1 request received from ctminh@node2.supernodexp.hpc, sock=16
02/14/2018 04:16:53;0100;Server@node2;Req;;Type 3 request received from ctminh@node2.supernodexp.hpc, sock=16
02/14/2018 04:16:53;0100;Server@node2;Req;;Type 5 request received from ctminh@node2.supernodexp.hpc, sock=16
02/14/2018 04:16:53;0100;Server@node2;Job;1196.node2.supernodexp.hpc;enqueuing into workq, state 1 hop 1
02/14/2018 04:16:53;0008;Server@node2;Job;1196.node2.supernodexp.hpc;Job Queued at request of ctminh@node2.supernodexp.hpc, owner = ctminh@node2.supernodexp.hpc, job name = vast1, queue = workq
02/14/2018 04:16:53;0100;Server@node2;Req;;Type 11 request received from Scheduler@node2.supernodexp.hpc, sock=20
02/14/2018 04:16:53;0008;Server@node2;Job;1195.node2.supernodexp.hpc;Job Modified at request of Scheduler@node2.supernodexp.hpc
02/14/2018 04:16:53;0100;Server@node2;Req;;Type 11 request received from Scheduler@node2.supernodexp.hpc, sock=20
02/14/2018 04:16:53;0008;Server@node2;Job;1193.node2.supernodexp.hpc;Job Modified at request of Scheduler@node2.supernodexp.hpc
02/14/2018 04:16:53;0100;Server@node2;Req;;Type 11 request received from Scheduler@node2.supernodexp.hpc, sock=20
02/14/2018 04:16:53;0008;Server@node2;Job;1194.node2.supernodexp.hpc;Job Modified at request of Scheduler@node2.supernodexp.hpc
02/14/2018 04:16:53;0040;Server@node2;Svr;node2.supernodexp.hpc;Scheduler sent command 1
02/14/2018 04:16:53;0040;Server@node2;Svr;node2.supernodexp.hpc;Scheduler sent command 0
02/14/2018 04:16:53;0100;Server@node2;Req;;Type 21 request received from Scheduler@node2.supernodexp.hpc, sock=20
02/14/2018 04:16:53;0100;Server@node2;Req;;Type 81 request received from Scheduler@node2.supernodexp.hpc, sock=20
02/14/2018 04:16:53;0100;Server@node2;Req;;Type 71 request received from Scheduler@node2.supernodexp.hpc, sock=20
02/14/2018 04:16:53;0100;Server@node2;Req;;Type 58 request received from Scheduler@node2.supernodexp.hpc, sock=20
02/14/2018 04:16:53;0100;Server@node2;Req;;Type 20 request received from Scheduler@node2.supernodexp.hpc, sock=20
02/14/2018 04:16:53;0100;Server@node2;Req;;Type 51 request received from Scheduler@node2.supernodexp.hpc, sock=20
02/14/2018 04:16:53;0100;Server@node2;Req;;Type 11 request received from Scheduler@node2.supernodexp.hpc, sock=20
02/14/2018 04:16:53;0008;Server@node2;Job;1196.node2.supernodexp.hpc;Job Modified at request of Scheduler@node2.supernodexp.hpc
02/14/2018 04:17:23;0100;Server@node2;Req;;Type 1 request received from ctminh@node2.supernodexp.hpc, sock=16
02/14/2018 04:17:23;0100;Server@node2;Req;;Type 3 request received from ctminh@node2.supernodexp.hpc, sock=16
02/14/2018 04:17:23;0100;Server@node2;Req;;Type 5 request received from ctminh@node2.supernodexp.hpc, sock=16
02/14/2018 04:17:23;0100;Server@node2;Job;1197.node2.supernodexp.hpc;enqueuing into workq, state 1 hop 1
02/14/2018 04:17:23;0008;Server@node2;Job;1197.node2.supernodexp.hpc;Job Queued at request of ctminh@node2.supernodexp.hpc, owner = ctminh@node2.supernodexp.hpc, job name = telemac3, queue = workq
02/14/2018 04:17:23;0040;Server@node2;Svr;node2.supernodexp.hpc;Scheduler sent command 1
02/14/2018 04:17:23;0040;Server@node2;Svr;node2.supernodexp.hpc;Scheduler sent command 0
02/14/2018 04:17:23;0100;Server@node2;Req;;Type 21 request received from Scheduler@node2.supernodexp.hpc, sock=20
02/14/2018 04:17:23;0100;Server@node2;Req;;Type 81 request received from Scheduler@node2.supernodexp.hpc, sock=20
02/14/2018 04:17:23;0100;Server@node2;Req;;Type 71 request received from Scheduler@node2.supernodexp.hpc, sock=20
02/14/2018 04:17:23;0100;Server@node2;Req;;Type 58 request received from Scheduler@node2.supernodexp.hpc, sock=20
02/14/2018 04:17:23;0100;Server@node2;Req;;Type 1 request received from ctminh@node2.supernodexp.hpc, sock=16
02/14/2018 04:17:23;0100;Server@node2;Req;;Type 3 request received from ctminh@node2.supernodexp.hpc, sock=16
02/14/2018 04:17:23;0100;Server@node2;Req;;Type 5 request received from ctminh@node2.supernodexp.hpc, sock=16
02/14/2018 04:17:23;0100;Server@node2;Job;1198.node2.supernodexp.hpc;enqueuing into workq, state 1 hop 1
02/14/2018 04:17:23;0008;Server@node2;Job;1198.node2.supernodexp.hpc;Job Queued at request of ctminh@node2.supernodexp.hpc, owner = ctminh@node2.supernodexp.hpc, job name = qe_mic_test, queue = workq
02/14/2018 04:17:23;0100;Server@node2;Req;;Type 20 request received from Scheduler@node2.supernodexp.hpc, sock=20
02/14/2018 04:17:23;0100;Server@node2;Req;;Type 51 request received from Scheduler@node2.supernodexp.hpc, sock=20
02/14/2018 04:17:23;0100;Server@node2;Req;;Type 11 request received from Scheduler@node2.supernodexp.hpc, sock=20
02/14/2018 04:17:23;0008;Server@node2;Job;1198.node2.supernodexp.hpc;Job Modified at request of Scheduler@node2.supernodexp.hpc
02/14/2018 04:17:23;0100;Server@node2;Req;;Type 11 request received from Scheduler@node2.supernodexp.hpc, sock=20
02/14/2018 04:17:23;0008;Server@node2;Job;1197.node2.supernodexp.hpc;Job Modified at request of Scheduler@node2.supernodexp.hpc
02/14/2018 04:17:23;0040;Server@node2;Svr;node2.supernodexp.hpc;Scheduler sent command 1
02/14/2018 04:17:23;0040;Server@node2;Svr;node2.supernodexp.hpc;Scheduler sent command 0
02/14/2018 04:17:23;0100;Server@node2;Req;;Type 21 request received from Scheduler@node2.supernodexp.hpc, sock=20
02/14/2018 04:17:23;0100;Server@node2;Req;;Type 81 request received from Scheduler@node2.supernodexp.hpc, sock=20
02/14/2018 04:17:23;0100;Server@node2;Req;;Type 71 request received from Scheduler@node2.supernodexp.hpc, sock=20
02/14/2018 04:17:23;0100;Server@node2;Req;;Type 58 request received from Scheduler@node2.supernodexp.hpc, sock=20
02/14/2018 04:17:23;0100;Server@node2;Req;;Type 20 request received from Scheduler@node2.supernodexp.hpc, sock=20
02/14/2018 04:17:23;0100;Server@node2;Req;;Type 51 request received from Scheduler@node2.supernodexp.hpc, sock=20
02/14/2018 04:18:22;0100;Server@node2;Req;;Type 1 request received from ctminh@node2.supernodexp.hpc, sock=16
02/14/2018 04:18:22;0100;Server@node2;Req;;Type 3 request received from ctminh@node2.supernodexp.hpc, sock=16
02/14/2018 04:18:22;0100;Server@node2;Req;;Type 5 request received from ctminh@node2.supernodexp.hpc, sock=16
02/14/2018 04:18:22;0100;Server@node2;Job;1199.node2.supernodexp.hpc;enqueuing into workq, state 1 hop 1
02/14/2018 04:18:22;0008;Server@node2;Job;1199.node2.supernodexp.hpc;Job Queued at request of ctminh@node2.supernodexp.hpc, owner = ctminh@node2.supernodexp.hpc, job name = vectorization, queue = workq
02/14/2018 04:18:22;0040;Server@node2;Svr;node2.supernodexp.hpc;Scheduler sent command 1
02/14/2018 04:18:22;0040;Server@node2;Svr;node2.supernodexp.hpc;Scheduler sent command 0
02/14/2018 04:18:22;0100;Server@node2;Req;;Type 21 request received from Scheduler@node2.supernodexp.hpc, sock=20
02/14/2018 04:18:22;0100;Server@node2;Req;;Type 81 request received from Scheduler@node2.supernodexp.hpc, sock=20
02/14/2018 04:18:22;0100;Server@node2;Req;;Type 71 request received from Scheduler@node2.supernodexp.hpc, sock=20
02/14/2018 04:18:22;0100;Server@node2;Req;;Type 58 request received from Scheduler@node2.supernodexp.hpc, sock=20
02/14/2018 04:18:22;0100;Server@node2;Req;;Type 1 request received from ctminh@node2.supernodexp.hpc, sock=16
02/14/2018 04:18:22;0100;Server@node2;Hook;_pbs_python_event_set;Restarting Python interpreter to reduce mem usage
02/14/2018 04:18:22;0100;Server@node2;Svr;Server@node2;--> Stopping Python interpreter <--
02/14/2018 04:18:22;0100;Server@node2;Svr;Server@node2;--> Python Interpreter started, compiled with version:'2.7.5' <--
02/14/2018 04:18:22;0100;Server@node2;Svr;Server@node2;sys.modules= {'pbs.v1._svr_types': <module 'pbs.v1._svr_types' from '/opt/pbs/lib/python/altair/pbs/v1/_svr_types.pyo'>, 'copy_reg': <module 'copy_reg' from '/usr/lib64/python2.7/copy_reg.pyo'>, 'pbs.v1._pbs_v1': None, '__main__': <module '__main__' (built-in)>, '__builtin__': <module '__builtin__' (built-in)>, '_pbs_v1.svr_types': <module '_pbs_v1.svr_types' (built-in)>, 'encodings': <module 'encodings' from '/usr/lib64/python2.7/encodings/__init__.pyo'>, 'encodings.encodings': None, 'abc': <module 'abc' from '/usr/lib64/python2.7/abc.pyo'>, 'pbs._pbs_v1': None, 'posixpath': <module 'posixpath' from '/usr/lib64/python2.7/posixpath.pyo'>, '_weakrefset': <module '_weakrefset' from '/usr/lib64/python2.7/_weakrefset.pyo'>, 'pbs.v1': <module 'pbs.v1' from '/opt/pbs/lib/python/altair/pbs/v1/__init__.pyo'>, 'errno': <module 'errno' (built-in)>, 'encodings.codecs': None, 'pbs.v1._export_types': <module 'pbs.v1._export_types' from '/opt/pbs/lib/python/altair/pbs/v1/_export_types.pyo'>, 'pbs.v1.os': None, '_abcoll': <module '_abcoll' from '/usr/lib64/python2.7/_abcoll.pyo'>, 'os.path': <module 'posixpath' from '/usr/lib64/python2.7/posixpath.pyo'>, 'UserDict': <module 'UserDict' from '/usr/lib64/python2.7/UserDict.pyo'>, '_warnings': <module '_warnings' (built-in)>, 'genericpath': <module 'genericpath' from '/usr/lib64/python2.7/genericpath.pyo'>, 'stat': <module 'stat' from '/usr/lib64/python2.7/stat.pyo'>, 'zipimport': <module 'zipimport' (built-in)>, 'encodings.__builtin__': None, 'pbs.pbs': None, 'warnings': <module 'warnings' from '/usr/lib64/python2.7/warnings.pyo'>, '_codecs': <module '_codecs' (built-in)>, 'encodings.ascii': <module 'encodings.ascii' from '/usr/lib64/python2.7/encodings/ascii.pyo'>, 'sys': <module 'sys' (built-in)>, 'pbs.v1._base_types': <module 'pbs.v1._base_types' from '/opt/pbs/lib/python/altair/pbs/v1/_base_types.pyo'>, 'pbs.v1.sys': None, 'codecs': <module 'codecs' from '/usr/lib64/python2.7/codecs.pyo'>, 'types': <module 'types' from '/usr/lib64/python2.7/types.pyo'>, 'pbs': <module 'pbs' from '/opt/pbs/lib/python/altair/pbs/__init__.pyo'>, 'os': <module 'os' from '/usr/lib64/python2.7/os.pyo'>, 'signal': <module 'signal' (built-in)>, 'linecache': <module 'linecache' from '/usr/lib64/python2.7/linecache.pyo'>, '_pbs_v1': <module '_pbs_v1' (built-in)>, 'posix': <module 'posix' (built-in)>, 'encodings.aliases': <module 'encodings.aliases' from '/usr/lib64/python2.7/encodings/aliases.pyo'>, 'exceptions': <module 'exceptions' (built-in)>, 'pbs.v1._exc_types': <module 'pbs.v1._exc_types' from '/opt/pbs/lib/python/altair/pbs/v1/_exc_types.pyo'>, '_weakref': <module '_weakref' (built-in)>}
02/14/2018 04:18:22;0106;Server@node2;Svr;Server@node2;BEGIN setting up all resource attributes 
02/14/2018 04:18:22;0106;Server@node2;Svr;Server@node2;DONE setting up all resource attributes, number set <51>
02/14/2018 04:18:22;0106;Server@node2;Svr;Server@node2;BEGIN setting up all queue attributes 
02/14/2018 04:18:22;0106;Server@node2;Svr;Server@node2;DONE setting up all queue attributes, number set <55>
02/14/2018 04:18:22;0106;Server@node2;Svr;Server@node2;BEGIN setting up all job attributes 
02/14/2018 04:18:22;0106;Server@node2;Svr;Server@node2;DONE setting up all job attributes, number set <94>
02/14/2018 04:18:22;0106;Server@node2;Svr;Server@node2;BEGIN setting up all server attributes 
02/14/2018 04:18:22;0106;Server@node2;Svr;Server@node2;DONE setting up all server attributes, number set <88>
02/14/2018 04:18:22;0106;Server@node2;Svr;Server@node2;BEGIN setting up all reservation attributes 
02/14/2018 04:18:22;0106;Server@node2;Svr;Server@node2;DONE setting up all reservation attributes, number set <43>
02/14/2018 04:18:22;0106;Server@node2;Svr;Server@node2;BEGIN setting up all vnode attributes 
02/14/2018 04:18:22;0106;Server@node2;Svr;Server@node2;DONE setting up all vnode attributes, number set <28>
02/14/2018 04:18:22;0100;Server@node2;Hook;_pbs_python_event_set;Current memory usage: VmSize=326072kB, VmRSS=17712kB
02/14/2018 04:18:22;0100;Server@node2;Req;;Type 3 request received from ctminh@node2.supernodexp.hpc, sock=16
02/14/2018 04:18:22;0100;Server@node2;Req;;Type 5 request received from ctminh@node2.supernodexp.hpc, sock=16
02/14/2018 04:18:22;0100;Server@node2;Job;1200.node2.supernodexp.hpc;enqueuing into workq, state 1 hop 1
02/14/2018 04:18:22;0008;Server@node2;Job;1200.node2.supernodexp.hpc;Job Queued at request of ctminh@node2.supernodexp.hpc, owner = ctminh@node2.supernodexp.hpc, job name = qe_mic_test, queue = workq
02/14/2018 04:18:22;0100;Server@node2;Req;;Type 20 request received from Scheduler@node2.supernodexp.hpc, sock=20
02/14/2018 04:18:22;0100;Server@node2;Req;;Type 51 request received from Scheduler@node2.supernodexp.hpc, sock=20
02/14/2018 04:18:22;0100;Server@node2;Req;;Type 11 request received from Scheduler@node2.supernodexp.hpc, sock=20
02/14/2018 04:18:22;0008;Server@node2;Job;1200.node2.supernodexp.hpc;Job Modified at request of Scheduler@node2.supernodexp.hpc
02/14/2018 04:18:22;0100;Server@node2;Req;;Type 11 request received from Scheduler@node2.supernodexp.hpc, sock=20
02/14/2018 04:18:22;0008;Server@node2;Job;1199.node2.supernodexp.hpc;Job Modified at request of Scheduler@node2.supernodexp.hpc
02/14/2018 04:18:22;0040;Server@node2;Svr;node2.supernodexp.hpc;Scheduler sent command 1
02/14/2018 04:18:22;0040;Server@node2;Svr;node2.supernodexp.hpc;Scheduler sent command 0
02/14/2018 04:18:22;0100;Server@node2;Req;;Type 21 request received from Scheduler@node2.supernodexp.hpc, sock=20
02/14/2018 04:18:22;0100;Server@node2;Req;;Type 81 request received from Scheduler@node2.supernodexp.hpc, sock=20
02/14/2018 04:18:22;0100;Server@node2;Req;;Type 71 request received from Scheduler@node2.supernodexp.hpc, sock=20
02/14/2018 04:18:22;0100;Server@node2;Req;;Type 58 request received from Scheduler@node2.supernodexp.hpc, sock=20
02/14/2018 04:18:22;0100;Server@node2;Req;;Type 20 request received from Scheduler@node2.supernodexp.hpc, sock=20
02/14/2018 04:18:22;0100;Server@node2;Req;;Type 51 request received from Scheduler@node2.supernodexp.hpc, sock=20
02/14/2018 04:27:55;0080;Server@node2;Job;1013.node2.supernodexp.hpc;Obit received momhop:1 serverhop:1 state:4 substate:42
02/14/2018 04:27:56;0010;Server@node2;Job;1013.node2.supernodexp.hpc;Exit_status=2 resources_used.cpupercent=2090 resources_used.cput=06:10:00 resources_used.mem=22199084kb resources_used.ncpus=32 resources_used.vmem=24915664kb resources_used.walltime=00:18:26
02/14/2018 04:27:56;0100;Server@node2;Job;1013.node2.supernodexp.hpc;dequeuing from workq, state 5
02/14/2018 04:27:56;0040;Server@node2;Svr;node2.supernodexp.hpc;Scheduler sent command 2
02/14/2018 04:27:56;0040;Server@node2;Svr;node2.supernodexp.hpc;Scheduler sent command 0
02/14/2018 04:27:56;0100;Server@node2;Req;;Type 21 request received from Scheduler@node2.supernodexp.hpc, sock=16
02/14/2018 04:27:56;0100;Server@node2;Req;;Type 81 request received from Scheduler@node2.supernodexp.hpc, sock=16
02/14/2018 04:27:56;0100;Server@node2;Req;;Type 71 request received from Scheduler@node2.supernodexp.hpc, sock=16
02/14/2018 04:27:56;0100;Server@node2;Req;;Type 58 request received from Scheduler@node2.supernodexp.hpc, sock=16
02/14/2018 04:27:56;0100;Server@node2;Req;;Type 20 request received from Scheduler@node2.supernodexp.hpc, sock=16
02/14/2018 04:27:56;0100;Server@node2;Req;;Type 51 request received from Scheduler@node2.supernodexp.hpc, sock=16
02/14/2018 04:27:56;0100;Server@node2;Req;;Type 23 request received from Scheduler@node2.supernodexp.hpc, sock=16
02/14/2018 04:27:56;0008;Server@node2;Job;1037.node2.supernodexp.hpc;Job Run at request of Scheduler@node2.supernodexp.hpc on exec_vnode (node14:ncpus=32:nmics=1:mem=16777216kb)
02/14/2018 04:27:56;0001;Server@node2;Svr;Server@node2;Success (0) in req_runjob2, return value of svr_startjob is 0
02/14/2018 04:27:56;0100;Server@node2;Req;;Type 11 request received from Scheduler@node2.supernodexp.hpc, sock=16
02/14/2018 04:27:56;0008;Server@node2;Job;1056.node2.supernodexp.hpc;Job Modified at request of Scheduler@node2.supernodexp.hpc
02/14/2018 04:30:08;0080;Server@node2;Job;1024.node2.supernodexp.hpc;Obit received momhop:1 serverhop:1 state:4 substate:42
02/14/2018 04:30:10;0010;Server@node2;Job;1024.node2.supernodexp.hpc;Exit_status=2 resources_used.cpupercent=2227 resources_used.cput=06:37:30 resources_used.mem=21833368kb resources_used.ncpus=32 resources_used.vmem=24850772kb resources_used.walltime=00:18:50
02/14/2018 04:30:10;0100;Server@node2;Job;1024.node2.supernodexp.hpc;dequeuing from workq, state 5
02/14/2018 04:30:10;0040;Server@node2;Svr;node2.supernodexp.hpc;Scheduler sent command 2
02/14/2018 04:30:10;0040;Server@node2;Svr;node2.supernodexp.hpc;Scheduler sent command 0
02/14/2018 04:30:10;0100;Server@node2;Req;;Type 21 request received from Scheduler@node2.supernodexp.hpc, sock=16
02/14/2018 04:30:10;0100;Server@node2;Req;;Type 81 request received from Scheduler@node2.supernodexp.hpc, sock=16
02/14/2018 04:30:10;0100;Server@node2;Req;;Type 71 request received from Scheduler@node2.supernodexp.hpc, sock=16
02/14/2018 04:30:10;0100;Server@node2;Req;;Type 58 request received from Scheduler@node2.supernodexp.hpc, sock=16
02/14/2018 04:30:10;0100;Server@node2;Req;;Type 20 request received from Scheduler@node2.supernodexp.hpc, sock=16
02/14/2018 04:30:10;0100;Server@node2;Req;;Type 51 request received from Scheduler@node2.supernodexp.hpc, sock=16
02/14/2018 04:30:10;0100;Server@node2;Req;;Type 23 request received from Scheduler@node2.supernodexp.hpc, sock=16
02/14/2018 04:30:10;0008;Server@node2;Job;1056.node2.supernodexp.hpc;Job Run at request of Scheduler@node2.supernodexp.hpc on exec_vnode (node13:ncpus=32:nmics=1:mem=16777216kb)
02/14/2018 04:30:10;0001;Server@node2;Svr;Server@node2;Success (0) in req_runjob2, return value of svr_startjob is 0
02/14/2018 04:30:10;0100;Server@node2;Req;;Type 11 request received from Scheduler@node2.supernodexp.hpc, sock=16
02/14/2018 04:30:10;0008;Server@node2;Job;1077.node2.supernodexp.hpc;Job Modified at request of Scheduler@node2.supernodexp.hpc
02/14/2018 04:40:10;0040;Server@node2;Svr;node2.supernodexp.hpc;Scheduler sent command 3
02/14/2018 04:40:10;0040;Server@node2;Svr;node2.supernodexp.hpc;Scheduler sent command 0
02/14/2018 04:40:10;0100;Server@node2;Req;;Type 21 request received from Scheduler@node2.supernodexp.hpc, sock=16
02/14/2018 04:40:10;0100;Server@node2;Req;;Type 81 request received from Scheduler@node2.supernodexp.hpc, sock=16
02/14/2018 04:40:10;0100;Server@node2;Req;;Type 71 request received from Scheduler@node2.supernodexp.hpc, sock=16
02/14/2018 04:40:10;0100;Server@node2;Req;;Type 58 request received from Scheduler@node2.supernodexp.hpc, sock=16
02/14/2018 04:40:10;0100;Server@node2;Req;;Type 20 request received from Scheduler@node2.supernodexp.hpc, sock=16
02/14/2018 04:40:10;0100;Server@node2;Req;;Type 51 request received from Scheduler@node2.supernodexp.hpc, sock=16
02/14/2018 04:46:36;0080;Server@node2;Job;1037.node2.supernodexp.hpc;Obit received momhop:1 serverhop:1 state:4 substate:42
02/14/2018 04:46:38;0010;Server@node2;Job;1037.node2.supernodexp.hpc;Exit_status=2 resources_used.cpupercent=2071 resources_used.cput=06:10:54 resources_used.mem=22030784kb resources_used.ncpus=32 resources_used.vmem=24762876kb resources_used.walltime=00:18:40
02/14/2018 04:46:38;0100;Server@node2;Job;1037.node2.supernodexp.hpc;dequeuing from workq, state 5
02/14/2018 04:46:38;0040;Server@node2;Svr;node2.supernodexp.hpc;Scheduler sent command 2
02/14/2018 04:46:38;0040;Server@node2;Svr;node2.supernodexp.hpc;Scheduler sent command 0
02/14/2018 04:46:38;0100;Server@node2;Req;;Type 21 request received from Scheduler@node2.supernodexp.hpc, sock=16
02/14/2018 04:46:38;0100;Server@node2;Req;;Type 81 request received from Scheduler@node2.supernodexp.hpc, sock=16
02/14/2018 04:46:38;0100;Server@node2;Req;;Type 71 request received from Scheduler@node2.supernodexp.hpc, sock=16
02/14/2018 04:46:38;0100;Server@node2;Req;;Type 58 request received from Scheduler@node2.supernodexp.hpc, sock=16
02/14/2018 04:46:38;0100;Server@node2;Req;;Type 20 request received from Scheduler@node2.supernodexp.hpc, sock=16
02/14/2018 04:46:38;0100;Server@node2;Req;;Type 51 request received from Scheduler@node2.supernodexp.hpc, sock=16
02/14/2018 04:46:38;0100;Server@node2;Req;;Type 23 request received from Scheduler@node2.supernodexp.hpc, sock=16
02/14/2018 04:46:38;0008;Server@node2;Job;1077.node2.supernodexp.hpc;Job Run at request of Scheduler@node2.supernodexp.hpc on exec_vnode (node14:ncpus=32:nmics=1:mem=16777216kb)
02/14/2018 04:46:38;0001;Server@node2;Svr;Server@node2;Success (0) in req_runjob2, return value of svr_startjob is 0
02/14/2018 04:46:38;0100;Server@node2;Req;;Type 11 request received from Scheduler@node2.supernodexp.hpc, sock=16
02/14/2018 04:46:38;0008;Server@node2;Job;1098.node2.supernodexp.hpc;Job Modified at request of Scheduler@node2.supernodexp.hpc
02/14/2018 04:48:15;0080;Server@node2;Job;1056.node2.supernodexp.hpc;Obit received momhop:1 serverhop:1 state:4 substate:42
02/14/2018 04:48:16;0010;Server@node2;Job;1056.node2.supernodexp.hpc;Exit_status=2 resources_used.cpupercent=2163 resources_used.cput=06:26:12 resources_used.mem=21811480kb resources_used.ncpus=32 resources_used.vmem=24868252kb resources_used.walltime=00:18:05
02/14/2018 04:48:16;0100;Server@node2;Job;1056.node2.supernodexp.hpc;dequeuing from workq, state 5
02/14/2018 04:48:16;0040;Server@node2;Svr;node2.supernodexp.hpc;Scheduler sent command 2
02/14/2018 04:48:16;0040;Server@node2;Svr;node2.supernodexp.hpc;Scheduler sent command 0
02/14/2018 04:48:16;0100;Server@node2;Req;;Type 21 request received from Scheduler@node2.supernodexp.hpc, sock=16
02/14/2018 04:48:16;0100;Server@node2;Req;;Type 81 request received from Scheduler@node2.supernodexp.hpc, sock=16
02/14/2018 04:48:16;0100;Server@node2;Req;;Type 71 request received from Scheduler@node2.supernodexp.hpc, sock=16
02/14/2018 04:48:16;0100;Server@node2;Req;;Type 58 request received from Scheduler@node2.supernodexp.hpc, sock=16
02/14/2018 04:48:16;0100;Server@node2;Req;;Type 20 request received from Scheduler@node2.supernodexp.hpc, sock=16
02/14/2018 04:48:16;0100;Server@node2;Req;;Type 51 request received from Scheduler@node2.supernodexp.hpc, sock=16
02/14/2018 04:48:16;0100;Server@node2;Req;;Type 23 request received from Scheduler@node2.supernodexp.hpc, sock=16
02/14/2018 04:48:16;0008;Server@node2;Job;1098.node2.supernodexp.hpc;Job Run at request of Scheduler@node2.supernodexp.hpc on exec_vnode (node13:ncpus=32:nmics=1:mem=16777216kb)
02/14/2018 04:48:16;0001;Server@node2;Svr;Server@node2;Success (0) in req_runjob2, return value of svr_startjob is 0
02/14/2018 04:48:16;0100;Server@node2;Req;;Type 11 request received from Scheduler@node2.supernodexp.hpc, sock=16
02/14/2018 04:48:16;0008;Server@node2;Job;1103.node2.supernodexp.hpc;Job Modified at request of Scheduler@node2.supernodexp.hpc
02/14/2018 04:58:16;0040;Server@node2;Svr;node2.supernodexp.hpc;Scheduler sent command 3
02/14/2018 04:58:16;0040;Server@node2;Svr;node2.supernodexp.hpc;Scheduler sent command 0
02/14/2018 04:58:16;0100;Server@node2;Req;;Type 21 request received from Scheduler@node2.supernodexp.hpc, sock=16
02/14/2018 04:58:16;0100;Server@node2;Req;;Type 81 request received from Scheduler@node2.supernodexp.hpc, sock=16
02/14/2018 04:58:16;0100;Server@node2;Req;;Type 71 request received from Scheduler@node2.supernodexp.hpc, sock=16
02/14/2018 04:58:16;0100;Server@node2;Req;;Type 58 request received from Scheduler@node2.supernodexp.hpc, sock=16
02/14/2018 04:58:16;0100;Server@node2;Req;;Type 20 request received from Scheduler@node2.supernodexp.hpc, sock=16
02/14/2018 04:58:16;0100;Server@node2;Req;;Type 51 request received from Scheduler@node2.supernodexp.hpc, sock=16
02/14/2018 05:05:27;0080;Server@node2;Job;1077.node2.supernodexp.hpc;Obit received momhop:1 serverhop:1 state:4 substate:42
02/14/2018 05:05:34;0010;Server@node2;Job;1077.node2.supernodexp.hpc;Exit_status=2 resources_used.cpupercent=2076 resources_used.cput=06:12:16 resources_used.mem=22166928kb resources_used.ncpus=32 resources_used.vmem=24901832kb resources_used.walltime=00:18:49
02/14/2018 05:05:34;0100;Server@node2;Job;1077.node2.supernodexp.hpc;dequeuing from workq, state 5
02/14/2018 05:05:34;0040;Server@node2;Svr;node2.supernodexp.hpc;Scheduler sent command 2
02/14/2018 05:05:34;0040;Server@node2;Svr;node2.supernodexp.hpc;Scheduler sent command 0
02/14/2018 05:05:34;0100;Server@node2;Req;;Type 21 request received from Scheduler@node2.supernodexp.hpc, sock=16
02/14/2018 05:05:34;0100;Server@node2;Req;;Type 81 request received from Scheduler@node2.supernodexp.hpc, sock=16
02/14/2018 05:05:34;0100;Server@node2;Req;;Type 71 request received from Scheduler@node2.supernodexp.hpc, sock=16
02/14/2018 05:05:34;0100;Server@node2;Req;;Type 58 request received from Scheduler@node2.supernodexp.hpc, sock=16
02/14/2018 05:05:34;0100;Server@node2;Req;;Type 20 request received from Scheduler@node2.supernodexp.hpc, sock=16
02/14/2018 05:05:34;0100;Server@node2;Req;;Type 51 request received from Scheduler@node2.supernodexp.hpc, sock=16
02/14/2018 05:05:34;0100;Server@node2;Req;;Type 23 request received from Scheduler@node2.supernodexp.hpc, sock=16
02/14/2018 05:05:34;0008;Server@node2;Job;1103.node2.supernodexp.hpc;Job Run at request of Scheduler@node2.supernodexp.hpc on exec_vnode (node14:ncpus=32:nmics=1:mem=16777216kb)
02/14/2018 05:05:34;0001;Server@node2;Svr;Server@node2;Success (0) in req_runjob2, return value of svr_startjob is 0
02/14/2018 05:05:34;0100;Server@node2;Req;;Type 11 request received from Scheduler@node2.supernodexp.hpc, sock=16
02/14/2018 05:05:34;0008;Server@node2;Job;1111.node2.supernodexp.hpc;Job Modified at request of Scheduler@node2.supernodexp.hpc
02/14/2018 05:06:53;0080;Server@node2;Job;1098.node2.supernodexp.hpc;Obit received momhop:1 serverhop:1 state:4 substate:42
02/14/2018 05:06:55;0010;Server@node2;Job;1098.node2.supernodexp.hpc;Exit_status=2 resources_used.cpupercent=2217 resources_used.cput=06:35:38 resources_used.mem=21830564kb resources_used.ncpus=32 resources_used.vmem=24853412kb resources_used.walltime=00:18:37
02/14/2018 05:06:55;0100;Server@node2;Job;1098.node2.supernodexp.hpc;dequeuing from workq, state 5
02/14/2018 05:06:55;0040;Server@node2;Svr;node2.supernodexp.hpc;Scheduler sent command 2
02/14/2018 05:06:55;0040;Server@node2;Svr;node2.supernodexp.hpc;Scheduler sent command 0
02/14/2018 05:06:55;0100;Server@node2;Req;;Type 21 request received from Scheduler@node2.supernodexp.hpc, sock=16
02/14/2018 05:06:55;0100;Server@node2;Req;;Type 81 request received from Scheduler@node2.supernodexp.hpc, sock=16
02/14/2018 05:06:55;0100;Server@node2;Req;;Type 71 request received from Scheduler@node2.supernodexp.hpc, sock=16
02/14/2018 05:06:55;0100;Server@node2;Req;;Type 58 request received from Scheduler@node2.supernodexp.hpc, sock=16
02/14/2018 05:06:55;0100;Server@node2;Req;;Type 20 request received from Scheduler@node2.supernodexp.hpc, sock=16
02/14/2018 05:06:55;0100;Server@node2;Req;;Type 51 request received from Scheduler@node2.supernodexp.hpc, sock=16
02/14/2018 05:06:55;0100;Server@node2;Req;;Type 23 request received from Scheduler@node2.supernodexp.hpc, sock=16
02/14/2018 05:06:55;0008;Server@node2;Job;1111.node2.supernodexp.hpc;Job Run at request of Scheduler@node2.supernodexp.hpc on exec_vnode (node13:ncpus=32:nmics=1:mem=16777216kb)
02/14/2018 05:06:55;0001;Server@node2;Svr;Server@node2;Success (0) in req_runjob2, return value of svr_startjob is 0
02/14/2018 05:06:55;0100;Server@node2;Req;;Type 11 request received from Scheduler@node2.supernodexp.hpc, sock=16
02/14/2018 05:06:55;0008;Server@node2;Job;1120.node2.supernodexp.hpc;Job Modified at request of Scheduler@node2.supernodexp.hpc
02/14/2018 05:16:55;0040;Server@node2;Svr;node2.supernodexp.hpc;Scheduler sent command 3
02/14/2018 05:16:55;0040;Server@node2;Svr;node2.supernodexp.hpc;Scheduler sent command 0
02/14/2018 05:16:55;0100;Server@node2;Req;;Type 21 request received from Scheduler@node2.supernodexp.hpc, sock=16
02/14/2018 05:16:55;0100;Server@node2;Req;;Type 81 request received from Scheduler@node2.supernodexp.hpc, sock=16
02/14/2018 05:16:55;0100;Server@node2;Req;;Type 71 request received from Scheduler@node2.supernodexp.hpc, sock=16
02/14/2018 05:16:55;0100;Server@node2;Req;;Type 58 request received from Scheduler@node2.supernodexp.hpc, sock=16
02/14/2018 05:16:55;0100;Server@node2;Req;;Type 20 request received from Scheduler@node2.supernodexp.hpc, sock=16
02/14/2018 05:16:55;0100;Server@node2;Req;;Type 51 request received from Scheduler@node2.supernodexp.hpc, sock=16
02/14/2018 05:24:07;0080;Server@node2;Job;1103.node2.supernodexp.hpc;Obit received momhop:1 serverhop:1 state:4 substate:42
02/14/2018 05:24:08;0010;Server@node2;Job;1103.node2.supernodexp.hpc;Exit_status=2 resources_used.cpupercent=2082 resources_used.cput=06:11:58 resources_used.mem=22196004kb resources_used.ncpus=32 resources_used.vmem=24914456kb resources_used.walltime=00:18:34
02/14/2018 05:24:08;0100;Server@node2;Job;1103.node2.supernodexp.hpc;dequeuing from workq, state 5
02/14/2018 05:24:08;0040;Server@node2;Svr;node2.supernodexp.hpc;Scheduler sent command 2
02/14/2018 05:24:08;0040;Server@node2;Svr;node2.supernodexp.hpc;Scheduler sent command 0
02/14/2018 05:24:08;0100;Server@node2;Req;;Type 21 request received from Scheduler@node2.supernodexp.hpc, sock=16
02/14/2018 05:24:08;0100;Server@node2;Req;;Type 81 request received from Scheduler@node2.supernodexp.hpc, sock=16
02/14/2018 05:24:08;0100;Server@node2;Req;;Type 71 request received from Scheduler@node2.supernodexp.hpc, sock=16
02/14/2018 05:24:08;0100;Server@node2;Req;;Type 58 request received from Scheduler@node2.supernodexp.hpc, sock=16
02/14/2018 05:24:08;0100;Server@node2;Req;;Type 20 request received from Scheduler@node2.supernodexp.hpc, sock=16
02/14/2018 05:24:08;0100;Server@node2;Req;;Type 51 request received from Scheduler@node2.supernodexp.hpc, sock=16
02/14/2018 05:24:09;0100;Server@node2;Req;;Type 23 request received from Scheduler@node2.supernodexp.hpc, sock=16
02/14/2018 05:24:09;0008;Server@node2;Job;1120.node2.supernodexp.hpc;Job Run at request of Scheduler@node2.supernodexp.hpc on exec_vnode (node14:ncpus=32:nmics=1:mem=16777216kb)
02/14/2018 05:24:09;0001;Server@node2;Svr;Server@node2;Success (0) in req_runjob2, return value of svr_startjob is 0
02/14/2018 05:24:09;0100;Server@node2;Req;;Type 11 request received from Scheduler@node2.supernodexp.hpc, sock=16
02/14/2018 05:24:09;0008;Server@node2;Job;1128.node2.supernodexp.hpc;Job Modified at request of Scheduler@node2.supernodexp.hpc
02/14/2018 05:25:52;0080;Server@node2;Job;1111.node2.supernodexp.hpc;Obit received momhop:1 serverhop:1 state:4 substate:42
02/14/2018 05:25:54;0010;Server@node2;Job;1111.node2.supernodexp.hpc;Exit_status=2 resources_used.cpupercent=2211 resources_used.cput=06:36:00 resources_used.mem=21821940kb resources_used.ncpus=32 resources_used.vmem=25038136kb resources_used.walltime=00:18:57
02/14/2018 05:25:54;0100;Server@node2;Job;1111.node2.supernodexp.hpc;dequeuing from workq, state 5
02/14/2018 05:25:54;0040;Server@node2;Svr;node2.supernodexp.hpc;Scheduler sent command 2
02/14/2018 05:25:54;0040;Server@node2;Svr;node2.supernodexp.hpc;Scheduler sent command 0
02/14/2018 05:25:54;0100;Server@node2;Req;;Type 21 request received from Scheduler@node2.supernodexp.hpc, sock=16
02/14/2018 05:25:54;0100;Server@node2;Req;;Type 81 request received from Scheduler@node2.supernodexp.hpc, sock=16
02/14/2018 05:25:54;0100;Server@node2;Req;;Type 71 request received from Scheduler@node2.supernodexp.hpc, sock=16
02/14/2018 05:25:54;0100;Server@node2;Req;;Type 58 request received from Scheduler@node2.supernodexp.hpc, sock=16
02/14/2018 05:25:54;0100;Server@node2;Req;;Type 20 request received from Scheduler@node2.supernodexp.hpc, sock=16
02/14/2018 05:25:54;0100;Server@node2;Req;;Type 51 request received from Scheduler@node2.supernodexp.hpc, sock=16
02/14/2018 05:25:54;0100;Server@node2;Req;;Type 23 request received from Scheduler@node2.supernodexp.hpc, sock=16
02/14/2018 05:25:54;0008;Server@node2;Job;1128.node2.supernodexp.hpc;Job Run at request of Scheduler@node2.supernodexp.hpc on exec_vnode (node13:ncpus=32:nmics=1:mem=16777216kb)
02/14/2018 05:25:54;0001;Server@node2;Svr;Server@node2;Success (0) in req_runjob2, return value of svr_startjob is 0
02/14/2018 05:25:54;0100;Server@node2;Req;;Type 11 request received from Scheduler@node2.supernodexp.hpc, sock=16
02/14/2018 05:25:54;0008;Server@node2;Job;1154.node2.supernodexp.hpc;Job Modified at request of Scheduler@node2.supernodexp.hpc
02/14/2018 05:35:54;0040;Server@node2;Svr;node2.supernodexp.hpc;Scheduler sent command 3
02/14/2018 05:35:54;0040;Server@node2;Svr;node2.supernodexp.hpc;Scheduler sent command 0
02/14/2018 05:35:54;0100;Server@node2;Req;;Type 21 request received from Scheduler@node2.supernodexp.hpc, sock=16
02/14/2018 05:35:54;0100;Server@node2;Req;;Type 81 request received from Scheduler@node2.supernodexp.hpc, sock=16
02/14/2018 05:35:54;0100;Server@node2;Req;;Type 71 request received from Scheduler@node2.supernodexp.hpc, sock=16
02/14/2018 05:35:54;0100;Server@node2;Req;;Type 58 request received from Scheduler@node2.supernodexp.hpc, sock=16
02/14/2018 05:35:54;0100;Server@node2;Req;;Type 20 request received from Scheduler@node2.supernodexp.hpc, sock=16
02/14/2018 05:35:54;0100;Server@node2;Req;;Type 51 request received from Scheduler@node2.supernodexp.hpc, sock=16
02/14/2018 05:43:01;0080;Server@node2;Job;1120.node2.supernodexp.hpc;Obit received momhop:1 serverhop:1 state:4 substate:42
02/14/2018 05:43:02;0010;Server@node2;Job;1120.node2.supernodexp.hpc;Exit_status=2 resources_used.cpupercent=2070 resources_used.cput=06:11:55 resources_used.mem=22208124kb resources_used.ncpus=32 resources_used.vmem=24918016kb resources_used.walltime=00:18:52
02/14/2018 05:43:02;0100;Server@node2;Job;1120.node2.supernodexp.hpc;dequeuing from workq, state 5
02/14/2018 05:43:02;0040;Server@node2;Svr;node2.supernodexp.hpc;Scheduler sent command 2
02/14/2018 05:43:02;0040;Server@node2;Svr;node2.supernodexp.hpc;Scheduler sent command 0
02/14/2018 05:43:02;0100;Server@node2;Req;;Type 21 request received from Scheduler@node2.supernodexp.hpc, sock=16
02/14/2018 05:43:02;0100;Server@node2;Req;;Type 81 request received from Scheduler@node2.supernodexp.hpc, sock=16
02/14/2018 05:43:02;0100;Server@node2;Req;;Type 71 request received from Scheduler@node2.supernodexp.hpc, sock=16
02/14/2018 05:43:02;0100;Server@node2;Req;;Type 58 request received from Scheduler@node2.supernodexp.hpc, sock=16
02/14/2018 05:43:02;0100;Server@node2;Req;;Type 20 request received from Scheduler@node2.supernodexp.hpc, sock=16
02/14/2018 05:43:02;0100;Server@node2;Req;;Type 51 request received from Scheduler@node2.supernodexp.hpc, sock=16
02/14/2018 05:43:02;0100;Server@node2;Req;;Type 23 request received from Scheduler@node2.supernodexp.hpc, sock=16
02/14/2018 05:43:02;0008;Server@node2;Job;1154.node2.supernodexp.hpc;Job Run at request of Scheduler@node2.supernodexp.hpc on exec_vnode (node14:ncpus=32:nmics=1:mem=16777216kb)
02/14/2018 05:43:02;0001;Server@node2;Svr;Server@node2;Success (0) in req_runjob2, return value of svr_startjob is 0
02/14/2018 05:43:02;0100;Server@node2;Req;;Type 11 request received from Scheduler@node2.supernodexp.hpc, sock=16
02/14/2018 05:43:02;0008;Server@node2;Job;1176.node2.supernodexp.hpc;Job Modified at request of Scheduler@node2.supernodexp.hpc
02/14/2018 05:44:27;0080;Server@node2;Job;1128.node2.supernodexp.hpc;Obit received momhop:1 serverhop:1 state:4 substate:42
02/14/2018 05:44:29;0010;Server@node2;Job;1128.node2.supernodexp.hpc;Exit_status=2 resources_used.cpupercent=2258 resources_used.cput=06:36:24 resources_used.mem=21812872kb resources_used.ncpus=32 resources_used.vmem=24854700kb resources_used.walltime=00:18:34
02/14/2018 05:44:29;0100;Server@node2;Job;1128.node2.supernodexp.hpc;dequeuing from workq, state 5
02/14/2018 05:44:29;0040;Server@node2;Svr;node2.supernodexp.hpc;Scheduler sent command 2
02/14/2018 05:44:29;0040;Server@node2;Svr;node2.supernodexp.hpc;Scheduler sent command 0
02/14/2018 05:44:29;0100;Server@node2;Req;;Type 21 request received from Scheduler@node2.supernodexp.hpc, sock=16
02/14/2018 05:44:29;0100;Server@node2;Req;;Type 81 request received from Scheduler@node2.supernodexp.hpc, sock=16
02/14/2018 05:44:29;0100;Server@node2;Req;;Type 71 request received from Scheduler@node2.supernodexp.hpc, sock=16
02/14/2018 05:44:29;0100;Server@node2;Req;;Type 58 request received from Scheduler@node2.supernodexp.hpc, sock=16
02/14/2018 05:44:29;0100;Server@node2;Req;;Type 20 request received from Scheduler@node2.supernodexp.hpc, sock=16
02/14/2018 05:44:29;0100;Server@node2;Req;;Type 51 request received from Scheduler@node2.supernodexp.hpc, sock=16
02/14/2018 05:44:29;0100;Server@node2;Req;;Type 23 request received from Scheduler@node2.supernodexp.hpc, sock=16
02/14/2018 05:44:29;0008;Server@node2;Job;1176.node2.supernodexp.hpc;Job Run at request of Scheduler@node2.supernodexp.hpc on exec_vnode (node13:ncpus=32:nmics=1:mem=16777216kb)
02/14/2018 05:44:29;0001;Server@node2;Svr;Server@node2;Success (0) in req_runjob2, return value of svr_startjob is 0
02/14/2018 05:44:29;0100;Server@node2;Req;;Type 11 request received from Scheduler@node2.supernodexp.hpc, sock=16
02/14/2018 05:44:29;0008;Server@node2;Job;1198.node2.supernodexp.hpc;Job Modified at request of Scheduler@node2.supernodexp.hpc
02/14/2018 05:54:29;0040;Server@node2;Svr;node2.supernodexp.hpc;Scheduler sent command 3
02/14/2018 05:54:29;0040;Server@node2;Svr;node2.supernodexp.hpc;Scheduler sent command 0
02/14/2018 05:54:29;0100;Server@node2;Req;;Type 21 request received from Scheduler@node2.supernodexp.hpc, sock=16
02/14/2018 05:54:29;0100;Server@node2;Req;;Type 81 request received from Scheduler@node2.supernodexp.hpc, sock=16
02/14/2018 05:54:29;0100;Server@node2;Req;;Type 71 request received from Scheduler@node2.supernodexp.hpc, sock=16
02/14/2018 05:54:29;0100;Server@node2;Req;;Type 58 request received from Scheduler@node2.supernodexp.hpc, sock=16
02/14/2018 05:54:29;0100;Server@node2;Req;;Type 20 request received from Scheduler@node2.supernodexp.hpc, sock=16
02/14/2018 05:54:29;0100;Server@node2;Req;;Type 51 request received from Scheduler@node2.supernodexp.hpc, sock=16
02/14/2018 06:01:38;0080;Server@node2;Job;1154.node2.supernodexp.hpc;Obit received momhop:1 serverhop:1 state:4 substate:42
02/14/2018 06:01:40;0010;Server@node2;Job;1154.node2.supernodexp.hpc;Exit_status=2 resources_used.cpupercent=2164 resources_used.cput=06:16:16 resources_used.mem=22193868kb resources_used.ncpus=32 resources_used.vmem=24917160kb resources_used.walltime=00:18:36
02/14/2018 06:01:40;0100;Server@node2;Job;1154.node2.supernodexp.hpc;dequeuing from workq, state 5
02/14/2018 06:01:40;0040;Server@node2;Svr;node2.supernodexp.hpc;Scheduler sent command 2
02/14/2018 06:01:40;0040;Server@node2;Svr;node2.supernodexp.hpc;Scheduler sent command 0
02/14/2018 06:01:40;0100;Server@node2;Req;;Type 21 request received from Scheduler@node2.supernodexp.hpc, sock=16
02/14/2018 06:01:40;0100;Server@node2;Req;;Type 81 request received from Scheduler@node2.supernodexp.hpc, sock=16
02/14/2018 06:01:40;0100;Server@node2;Req;;Type 71 request received from Scheduler@node2.supernodexp.hpc, sock=16
02/14/2018 06:01:40;0100;Server@node2;Req;;Type 58 request received from Scheduler@node2.supernodexp.hpc, sock=16
02/14/2018 06:01:40;0100;Server@node2;Req;;Type 20 request received from Scheduler@node2.supernodexp.hpc, sock=16
02/14/2018 06:01:40;0100;Server@node2;Req;;Type 51 request received from Scheduler@node2.supernodexp.hpc, sock=16
02/14/2018 06:01:40;0100;Server@node2;Req;;Type 23 request received from Scheduler@node2.supernodexp.hpc, sock=16
02/14/2018 06:01:40;0008;Server@node2;Job;1198.node2.supernodexp.hpc;Job Run at request of Scheduler@node2.supernodexp.hpc on exec_vnode (node14:ncpus=32:nmics=1:mem=16777216kb)
02/14/2018 06:01:40;0001;Server@node2;Svr;Server@node2;Success (0) in req_runjob2, return value of svr_startjob is 0
02/14/2018 06:01:40;0100;Server@node2;Req;;Type 11 request received from Scheduler@node2.supernodexp.hpc, sock=16
02/14/2018 06:01:40;0008;Server@node2;Job;1200.node2.supernodexp.hpc;Job Modified at request of Scheduler@node2.supernodexp.hpc
02/14/2018 06:02:59;0080;Server@node2;Job;1176.node2.supernodexp.hpc;Obit received momhop:1 serverhop:1 state:4 substate:42
02/14/2018 06:03:00;0010;Server@node2;Job;1176.node2.supernodexp.hpc;Exit_status=2 resources_used.cpupercent=2234 resources_used.cput=06:37:30 resources_used.mem=21833708kb resources_used.ncpus=32 resources_used.vmem=24868264kb resources_used.walltime=00:18:30
02/14/2018 06:03:00;0100;Server@node2;Job;1176.node2.supernodexp.hpc;dequeuing from workq, state 5
02/14/2018 06:03:00;0040;Server@node2;Svr;node2.supernodexp.hpc;Scheduler sent command 2
02/14/2018 06:03:00;0040;Server@node2;Svr;node2.supernodexp.hpc;Scheduler sent command 0
02/14/2018 06:03:00;0100;Server@node2;Req;;Type 21 request received from Scheduler@node2.supernodexp.hpc, sock=16
02/14/2018 06:03:00;0100;Server@node2;Req;;Type 81 request received from Scheduler@node2.supernodexp.hpc, sock=16
02/14/2018 06:03:00;0100;Server@node2;Req;;Type 71 request received from Scheduler@node2.supernodexp.hpc, sock=16
02/14/2018 06:03:00;0100;Server@node2;Req;;Type 58 request received from Scheduler@node2.supernodexp.hpc, sock=16
02/14/2018 06:03:00;0100;Server@node2;Req;;Type 20 request received from Scheduler@node2.supernodexp.hpc, sock=16
02/14/2018 06:03:00;0100;Server@node2;Req;;Type 51 request received from Scheduler@node2.supernodexp.hpc, sock=16
02/14/2018 06:03:00;0100;Server@node2;Req;;Type 23 request received from Scheduler@node2.supernodexp.hpc, sock=16
02/14/2018 06:03:00;0008;Server@node2;Job;1200.node2.supernodexp.hpc;Job Run at request of Scheduler@node2.supernodexp.hpc on exec_vnode (node13:ncpus=32:nmics=1:mem=16777216kb)
02/14/2018 06:03:00;0001;Server@node2;Svr;Server@node2;Success (0) in req_runjob2, return value of svr_startjob is 0
02/14/2018 06:03:00;0100;Server@node2;Req;;Type 11 request received from Scheduler@node2.supernodexp.hpc, sock=16
02/14/2018 06:03:00;0008;Server@node2;Job;1016.node2.supernodexp.hpc;Job Modified at request of Scheduler@node2.supernodexp.hpc
02/14/2018 06:13:00;0040;Server@node2;Svr;node2.supernodexp.hpc;Scheduler sent command 3
02/14/2018 06:13:00;0040;Server@node2;Svr;node2.supernodexp.hpc;Scheduler sent command 0
02/14/2018 06:13:00;0100;Server@node2;Req;;Type 21 request received from Scheduler@node2.supernodexp.hpc, sock=16
02/14/2018 06:13:00;0100;Server@node2;Req;;Type 81 request received from Scheduler@node2.supernodexp.hpc, sock=16
02/14/2018 06:13:00;0100;Server@node2;Req;;Type 71 request received from Scheduler@node2.supernodexp.hpc, sock=16
02/14/2018 06:13:00;0100;Server@node2;Req;;Type 58 request received from Scheduler@node2.supernodexp.hpc, sock=16
02/14/2018 06:13:00;0100;Server@node2;Req;;Type 20 request received from Scheduler@node2.supernodexp.hpc, sock=16
02/14/2018 06:13:00;0100;Server@node2;Req;;Type 51 request received from Scheduler@node2.supernodexp.hpc, sock=16
02/14/2018 06:20:42;0080;Server@node2;Job;1198.node2.supernodexp.hpc;Obit received momhop:1 serverhop:1 state:4 substate:42
02/14/2018 06:20:45;0010;Server@node2;Job;1198.node2.supernodexp.hpc;Exit_status=2 resources_used.cpupercent=2143 resources_used.cput=06:18:33 resources_used.mem=22218588kb resources_used.ncpus=32 resources_used.vmem=24942256kb resources_used.walltime=00:19:03
02/14/2018 06:20:45;0100;Server@node2;Job;1198.node2.supernodexp.hpc;dequeuing from workq, state 5
02/14/2018 06:20:45;0040;Server@node2;Svr;node2.supernodexp.hpc;Scheduler sent command 2
02/14/2018 06:20:45;0040;Server@node2;Svr;node2.supernodexp.hpc;Scheduler sent command 0
02/14/2018 06:20:45;0100;Server@node2;Req;;Type 21 request received from Scheduler@node2.supernodexp.hpc, sock=16
02/14/2018 06:20:45;0100;Server@node2;Req;;Type 81 request received from Scheduler@node2.supernodexp.hpc, sock=16
02/14/2018 06:20:45;0100;Server@node2;Req;;Type 71 request received from Scheduler@node2.supernodexp.hpc, sock=16
02/14/2018 06:20:45;0100;Server@node2;Req;;Type 58 request received from Scheduler@node2.supernodexp.hpc, sock=16
02/14/2018 06:20:45;0100;Server@node2;Req;;Type 20 request received from Scheduler@node2.supernodexp.hpc, sock=16
02/14/2018 06:20:45;0100;Server@node2;Req;;Type 51 request received from Scheduler@node2.supernodexp.hpc, sock=16
02/14/2018 06:20:45;0100;Server@node2;Req;;Type 23 request received from Scheduler@node2.supernodexp.hpc, sock=16
02/14/2018 06:20:45;0008;Server@node2;Job;1016.node2.supernodexp.hpc;Job Run at request of Scheduler@node2.supernodexp.hpc on exec_vnode (node14:ncpus=48:mem=5242880kb)
02/14/2018 06:20:45;0001;Server@node2;Svr;Server@node2;Success (0) in req_runjob2, return value of svr_startjob is 0
02/14/2018 06:20:45;0100;Server@node2;Req;;Type 11 request received from Scheduler@node2.supernodexp.hpc, sock=16
02/14/2018 06:20:45;0008;Server@node2;Job;1019.node2.supernodexp.hpc;Job Modified at request of Scheduler@node2.supernodexp.hpc
02/14/2018 06:21:33;0080;Server@node2;Job;1200.node2.supernodexp.hpc;Obit received momhop:1 serverhop:1 state:4 substate:42
02/14/2018 06:21:35;0010;Server@node2;Job;1200.node2.supernodexp.hpc;Exit_status=2 resources_used.cpupercent=2230 resources_used.cput=06:38:36 resources_used.mem=21827424kb resources_used.ncpus=32 resources_used.vmem=24850764kb resources_used.walltime=00:18:33
02/14/2018 06:21:35;0100;Server@node2;Job;1200.node2.supernodexp.hpc;dequeuing from workq, state 5
02/14/2018 06:21:35;0040;Server@node2;Svr;node2.supernodexp.hpc;Scheduler sent command 2
02/14/2018 06:21:35;0040;Server@node2;Svr;node2.supernodexp.hpc;Scheduler sent command 0
02/14/2018 06:21:35;0100;Server@node2;Req;;Type 21 request received from Scheduler@node2.supernodexp.hpc, sock=16
02/14/2018 06:21:35;0100;Server@node2;Req;;Type 81 request received from Scheduler@node2.supernodexp.hpc, sock=16
02/14/2018 06:21:35;0100;Server@node2;Req;;Type 71 request received from Scheduler@node2.supernodexp.hpc, sock=16
02/14/2018 06:21:35;0100;Server@node2;Req;;Type 58 request received from Scheduler@node2.supernodexp.hpc, sock=16
02/14/2018 06:21:35;0100;Server@node2;Req;;Type 20 request received from Scheduler@node2.supernodexp.hpc, sock=16
02/14/2018 06:21:35;0100;Server@node2;Req;;Type 51 request received from Scheduler@node2.supernodexp.hpc, sock=16
02/14/2018 06:21:35;0100;Server@node2;Req;;Type 23 request received from Scheduler@node2.supernodexp.hpc, sock=16
02/14/2018 06:21:35;0008;Server@node2;Job;1019.node2.supernodexp.hpc;Job Run at request of Scheduler@node2.supernodexp.hpc on exec_vnode (node13:ncpus=48:mem=5242880kb)
02/14/2018 06:21:35;0001;Server@node2;Svr;Server@node2;Success (0) in req_runjob2, return value of svr_startjob is 0
02/14/2018 06:21:35;0100;Server@node2;Req;;Type 11 request received from Scheduler@node2.supernodexp.hpc, sock=16
02/14/2018 06:21:35;0008;Server@node2;Job;1025.node2.supernodexp.hpc;Job Modified at request of Scheduler@node2.supernodexp.hpc
02/14/2018 06:31:11;0080;Server@node2;Job;1016.node2.supernodexp.hpc;Obit received momhop:1 serverhop:1 state:4 substate:42
02/14/2018 06:31:12;0010;Server@node2;Job;1016.node2.supernodexp.hpc;Exit_status=0 resources_used.cpupercent=4744 resources_used.cput=08:08:42 resources_used.mem=7961780kb resources_used.ncpus=48 resources_used.vmem=47424400kb resources_used.walltime=00:10:26
02/14/2018 06:31:12;0100;Server@node2;Job;1016.node2.supernodexp.hpc;dequeuing from workq, state 5
02/14/2018 06:31:12;0040;Server@node2;Svr;node2.supernodexp.hpc;Scheduler sent command 2
02/14/2018 06:31:12;0040;Server@node2;Svr;node2.supernodexp.hpc;Scheduler sent command 0
02/14/2018 06:31:12;0100;Server@node2;Req;;Type 21 request received from Scheduler@node2.supernodexp.hpc, sock=16
02/14/2018 06:31:12;0100;Server@node2;Req;;Type 81 request received from Scheduler@node2.supernodexp.hpc, sock=16
02/14/2018 06:31:12;0100;Server@node2;Req;;Type 71 request received from Scheduler@node2.supernodexp.hpc, sock=16
02/14/2018 06:31:12;0100;Server@node2;Req;;Type 58 request received from Scheduler@node2.supernodexp.hpc, sock=16
02/14/2018 06:31:12;0100;Server@node2;Req;;Type 20 request received from Scheduler@node2.supernodexp.hpc, sock=16
02/14/2018 06:31:12;0100;Server@node2;Req;;Type 51 request received from Scheduler@node2.supernodexp.hpc, sock=16
02/14/2018 06:31:12;0100;Server@node2;Req;;Type 23 request received from Scheduler@node2.supernodexp.hpc, sock=16
02/14/2018 06:31:12;0008;Server@node2;Job;1025.node2.supernodexp.hpc;Job Run at request of Scheduler@node2.supernodexp.hpc on exec_vnode (node14:ncpus=48:mem=5242880kb)
02/14/2018 06:31:12;0001;Server@node2;Svr;Server@node2;Success (0) in req_runjob2, return value of svr_startjob is 0
02/14/2018 06:31:12;0100;Server@node2;Req;;Type 11 request received from Scheduler@node2.supernodexp.hpc, sock=16
02/14/2018 06:31:12;0008;Server@node2;Job;1038.node2.supernodexp.hpc;Job Modified at request of Scheduler@node2.supernodexp.hpc
02/14/2018 06:33:04;0080;Server@node2;Job;1019.node2.supernodexp.hpc;Obit received momhop:1 serverhop:1 state:4 substate:42
02/14/2018 06:33:06;0010;Server@node2;Job;1019.node2.supernodexp.hpc;Exit_status=0 resources_used.cpupercent=4679 resources_used.cput=08:52:40 resources_used.mem=7908428kb resources_used.ncpus=48 resources_used.vmem=47424632kb resources_used.walltime=00:11:30
02/14/2018 06:33:06;0100;Server@node2;Job;1019.node2.supernodexp.hpc;dequeuing from workq, state 5
02/14/2018 06:33:06;0040;Server@node2;Svr;node2.supernodexp.hpc;Scheduler sent command 2
02/14/2018 06:33:06;0040;Server@node2;Svr;node2.supernodexp.hpc;Scheduler sent command 0
02/14/2018 06:33:06;0100;Server@node2;Req;;Type 21 request received from Scheduler@node2.supernodexp.hpc, sock=16
02/14/2018 06:33:06;0100;Server@node2;Req;;Type 81 request received from Scheduler@node2.supernodexp.hpc, sock=16
02/14/2018 06:33:06;0100;Server@node2;Req;;Type 71 request received from Scheduler@node2.supernodexp.hpc, sock=16
02/14/2018 06:33:06;0100;Server@node2;Req;;Type 58 request received from Scheduler@node2.supernodexp.hpc, sock=16
02/14/2018 06:33:06;0100;Server@node2;Req;;Type 20 request received from Scheduler@node2.supernodexp.hpc, sock=16
02/14/2018 06:33:06;0100;Server@node2;Req;;Type 51 request received from Scheduler@node2.supernodexp.hpc, sock=16
02/14/2018 06:33:06;0100;Server@node2;Req;;Type 23 request received from Scheduler@node2.supernodexp.hpc, sock=16
02/14/2018 06:33:06;0008;Server@node2;Job;1038.node2.supernodexp.hpc;Job Run at request of Scheduler@node2.supernodexp.hpc on exec_vnode (node13:ncpus=48:mem=5242880kb)
02/14/2018 06:33:06;0001;Server@node2;Svr;Server@node2;Success (0) in req_runjob2, return value of svr_startjob is 0
02/14/2018 06:33:06;0100;Server@node2;Req;;Type 11 request received from Scheduler@node2.supernodexp.hpc, sock=16
02/14/2018 06:33:06;0008;Server@node2;Job;1040.node2.supernodexp.hpc;Job Modified at request of Scheduler@node2.supernodexp.hpc
02/14/2018 06:41:47;0080;Server@node2;Job;1025.node2.supernodexp.hpc;Obit received momhop:1 serverhop:1 state:4 substate:42
02/14/2018 06:41:49;0010;Server@node2;Job;1025.node2.supernodexp.hpc;Exit_status=0 resources_used.cpupercent=4738 resources_used.cput=08:15:29 resources_used.mem=7865888kb resources_used.ncpus=48 resources_used.vmem=47424832kb resources_used.walltime=00:10:35
02/14/2018 06:41:49;0100;Server@node2;Job;1025.node2.supernodexp.hpc;dequeuing from workq, state 5
02/14/2018 06:41:49;0040;Server@node2;Svr;node2.supernodexp.hpc;Scheduler sent command 2
02/14/2018 06:41:49;0040;Server@node2;Svr;node2.supernodexp.hpc;Scheduler sent command 0
02/14/2018 06:41:49;0100;Server@node2;Req;;Type 21 request received from Scheduler@node2.supernodexp.hpc, sock=16
02/14/2018 06:41:49;0100;Server@node2;Req;;Type 81 request received from Scheduler@node2.supernodexp.hpc, sock=16
02/14/2018 06:41:49;0100;Server@node2;Req;;Type 71 request received from Scheduler@node2.supernodexp.hpc, sock=16
02/14/2018 06:41:49;0100;Server@node2;Req;;Type 58 request received from Scheduler@node2.supernodexp.hpc, sock=16
02/14/2018 06:41:49;0100;Server@node2;Req;;Type 20 request received from Scheduler@node2.supernodexp.hpc, sock=16
02/14/2018 06:41:49;0100;Server@node2;Req;;Type 51 request received from Scheduler@node2.supernodexp.hpc, sock=16
02/14/2018 06:41:49;0100;Server@node2;Req;;Type 23 request received from Scheduler@node2.supernodexp.hpc, sock=16
02/14/2018 06:41:49;0008;Server@node2;Job;1040.node2.supernodexp.hpc;Job Run at request of Scheduler@node2.supernodexp.hpc on exec_vnode (node14:ncpus=48:mem=5242880kb)
02/14/2018 06:41:49;0001;Server@node2;Svr;Server@node2;Success (0) in req_runjob2, return value of svr_startjob is 0
02/14/2018 06:41:49;0100;Server@node2;Req;;Type 11 request received from Scheduler@node2.supernodexp.hpc, sock=16
02/14/2018 06:41:49;0008;Server@node2;Job;1086.node2.supernodexp.hpc;Job Modified at request of Scheduler@node2.supernodexp.hpc
02/14/2018 06:43:56;0080;Server@node2;Job;1038.node2.supernodexp.hpc;Obit received momhop:1 serverhop:1 state:4 substate:42
02/14/2018 06:43:58;0010;Server@node2;Job;1038.node2.supernodexp.hpc;Exit_status=0 resources_used.cpupercent=4732 resources_used.cput=08:23:53 resources_used.mem=7902912kb resources_used.ncpus=48 resources_used.vmem=47424324kb resources_used.walltime=00:10:50
02/14/2018 06:43:58;0100;Server@node2;Job;1038.node2.supernodexp.hpc;dequeuing from workq, state 5
02/14/2018 06:43:58;0040;Server@node2;Svr;node2.supernodexp.hpc;Scheduler sent command 2
02/14/2018 06:43:58;0040;Server@node2;Svr;node2.supernodexp.hpc;Scheduler sent command 0
02/14/2018 06:43:58;0100;Server@node2;Req;;Type 21 request received from Scheduler@node2.supernodexp.hpc, sock=16
02/14/2018 06:43:58;0100;Server@node2;Req;;Type 81 request received from Scheduler@node2.supernodexp.hpc, sock=16
02/14/2018 06:43:58;0100;Server@node2;Req;;Type 71 request received from Scheduler@node2.supernodexp.hpc, sock=16
02/14/2018 06:43:58;0100;Server@node2;Req;;Type 58 request received from Scheduler@node2.supernodexp.hpc, sock=16
02/14/2018 06:43:58;0100;Server@node2;Req;;Type 20 request received from Scheduler@node2.supernodexp.hpc, sock=16
02/14/2018 06:43:58;0100;Server@node2;Req;;Type 51 request received from Scheduler@node2.supernodexp.hpc, sock=16
02/14/2018 06:43:58;0100;Server@node2;Req;;Type 23 request received from Scheduler@node2.supernodexp.hpc, sock=16
02/14/2018 06:43:58;0008;Server@node2;Job;1086.node2.supernodexp.hpc;Job Run at request of Scheduler@node2.supernodexp.hpc on exec_vnode (node13:ncpus=48:mem=5242880kb)
02/14/2018 06:43:58;0001;Server@node2;Svr;Server@node2;Success (0) in req_runjob2, return value of svr_startjob is 0
02/14/2018 06:43:58;0100;Server@node2;Req;;Type 11 request received from Scheduler@node2.supernodexp.hpc, sock=16
02/14/2018 06:43:58;0008;Server@node2;Job;1090.node2.supernodexp.hpc;Job Modified at request of Scheduler@node2.supernodexp.hpc
02/14/2018 06:52:16;0080;Server@node2;Job;1040.node2.supernodexp.hpc;Obit received momhop:1 serverhop:1 state:4 substate:42
02/14/2018 06:52:17;0010;Server@node2;Job;1040.node2.supernodexp.hpc;Exit_status=0 resources_used.cpupercent=4751 resources_used.cput=08:11:56 resources_used.mem=7964588kb resources_used.ncpus=48 resources_used.vmem=47424828kb resources_used.walltime=00:10:28
02/14/2018 06:52:17;0100;Server@node2;Job;1040.node2.supernodexp.hpc;dequeuing from workq, state 5
02/14/2018 06:52:17;0040;Server@node2;Svr;node2.supernodexp.hpc;Scheduler sent command 2
02/14/2018 06:52:17;0040;Server@node2;Svr;node2.supernodexp.hpc;Scheduler sent command 0
02/14/2018 06:52:17;0100;Server@node2;Req;;Type 21 request received from Scheduler@node2.supernodexp.hpc, sock=16
02/14/2018 06:52:17;0100;Server@node2;Req;;Type 81 request received from Scheduler@node2.supernodexp.hpc, sock=16
02/14/2018 06:52:17;0100;Server@node2;Req;;Type 71 request received from Scheduler@node2.supernodexp.hpc, sock=16
02/14/2018 06:52:17;0100;Server@node2;Req;;Type 58 request received from Scheduler@node2.supernodexp.hpc, sock=16
02/14/2018 06:52:17;0100;Server@node2;Req;;Type 20 request received from Scheduler@node2.supernodexp.hpc, sock=16
02/14/2018 06:52:17;0100;Server@node2;Req;;Type 51 request received from Scheduler@node2.supernodexp.hpc, sock=16
02/14/2018 06:52:18;0100;Server@node2;Req;;Type 23 request received from Scheduler@node2.supernodexp.hpc, sock=16
02/14/2018 06:52:18;0008;Server@node2;Job;1090.node2.supernodexp.hpc;Job Run at request of Scheduler@node2.supernodexp.hpc on exec_vnode (node14:ncpus=48:mem=5242880kb)
02/14/2018 06:52:18;0001;Server@node2;Svr;Server@node2;Success (0) in req_runjob2, return value of svr_startjob is 0
02/14/2018 06:52:18;0100;Server@node2;Req;;Type 11 request received from Scheduler@node2.supernodexp.hpc, sock=16
02/14/2018 06:52:18;0008;Server@node2;Job;1113.node2.supernodexp.hpc;Job Modified at request of Scheduler@node2.supernodexp.hpc
02/14/2018 06:54:33;0080;Server@node2;Job;1086.node2.supernodexp.hpc;Obit received momhop:1 serverhop:1 state:4 substate:42
02/14/2018 06:54:34;0010;Server@node2;Job;1086.node2.supernodexp.hpc;Exit_status=0 resources_used.cpupercent=4747 resources_used.cput=08:17:17 resources_used.mem=7908708kb resources_used.ncpus=48 resources_used.vmem=47424620kb resources_used.walltime=00:10:35
02/14/2018 06:54:34;0100;Server@node2;Job;1086.node2.supernodexp.hpc;dequeuing from workq, state 5
02/14/2018 06:54:34;0040;Server@node2;Svr;node2.supernodexp.hpc;Scheduler sent command 2
02/14/2018 06:54:34;0040;Server@node2;Svr;node2.supernodexp.hpc;Scheduler sent command 0
02/14/2018 06:54:34;0100;Server@node2;Req;;Type 21 request received from Scheduler@node2.supernodexp.hpc, sock=16
02/14/2018 06:54:34;0100;Server@node2;Req;;Type 81 request received from Scheduler@node2.supernodexp.hpc, sock=16
02/14/2018 06:54:34;0100;Server@node2;Req;;Type 71 request received from Scheduler@node2.supernodexp.hpc, sock=16
02/14/2018 06:54:34;0100;Server@node2;Req;;Type 58 request received from Scheduler@node2.supernodexp.hpc, sock=16
02/14/2018 06:54:34;0100;Server@node2;Req;;Type 20 request received from Scheduler@node2.supernodexp.hpc, sock=16
02/14/2018 06:54:34;0100;Server@node2;Req;;Type 51 request received from Scheduler@node2.supernodexp.hpc, sock=16
02/14/2018 06:54:34;0100;Server@node2;Req;;Type 23 request received from Scheduler@node2.supernodexp.hpc, sock=16
02/14/2018 06:54:34;0008;Server@node2;Job;1113.node2.supernodexp.hpc;Job Run at request of Scheduler@node2.supernodexp.hpc on exec_vnode (node13:ncpus=48:mem=5242880kb)
02/14/2018 06:54:34;0001;Server@node2;Svr;Server@node2;Success (0) in req_runjob2, return value of svr_startjob is 0
02/14/2018 06:54:34;0100;Server@node2;Req;;Type 11 request received from Scheduler@node2.supernodexp.hpc, sock=16
02/14/2018 06:54:34;0008;Server@node2;Job;1114.node2.supernodexp.hpc;Job Modified at request of Scheduler@node2.supernodexp.hpc
02/14/2018 07:03:05;0080;Server@node2;Job;1090.node2.supernodexp.hpc;Obit received momhop:1 serverhop:1 state:4 substate:42
02/14/2018 07:03:07;0010;Server@node2;Job;1090.node2.supernodexp.hpc;Exit_status=0 resources_used.cpupercent=4774 resources_used.cput=08:18:31 resources_used.mem=7936308kb resources_used.ncpus=48 resources_used.vmem=47423772kb resources_used.walltime=00:10:48
02/14/2018 07:03:07;0100;Server@node2;Job;1090.node2.supernodexp.hpc;dequeuing from workq, state 5
02/14/2018 07:03:07;0040;Server@node2;Svr;node2.supernodexp.hpc;Scheduler sent command 2
02/14/2018 07:03:07;0040;Server@node2;Svr;node2.supernodexp.hpc;Scheduler sent command 0
02/14/2018 07:03:07;0100;Server@node2;Req;;Type 21 request received from Scheduler@node2.supernodexp.hpc, sock=16
02/14/2018 07:03:07;0100;Server@node2;Req;;Type 81 request received from Scheduler@node2.supernodexp.hpc, sock=16
02/14/2018 07:03:07;0100;Server@node2;Req;;Type 71 request received from Scheduler@node2.supernodexp.hpc, sock=16
02/14/2018 07:03:07;0100;Server@node2;Req;;Type 58 request received from Scheduler@node2.supernodexp.hpc, sock=16
02/14/2018 07:03:07;0100;Server@node2;Req;;Type 20 request received from Scheduler@node2.supernodexp.hpc, sock=16
02/14/2018 07:03:07;0100;Server@node2;Req;;Type 51 request received from Scheduler@node2.supernodexp.hpc, sock=16
02/14/2018 07:03:07;0100;Server@node2;Req;;Type 23 request received from Scheduler@node2.supernodexp.hpc, sock=16
02/14/2018 07:03:07;0008;Server@node2;Job;1114.node2.supernodexp.hpc;Job Run at request of Scheduler@node2.supernodexp.hpc on exec_vnode (node14:ncpus=48:mem=5242880kb)
02/14/2018 07:03:07;0001;Server@node2;Svr;Server@node2;Success (0) in req_runjob2, return value of svr_startjob is 0
02/14/2018 07:03:07;0100;Server@node2;Req;;Type 11 request received from Scheduler@node2.supernodexp.hpc, sock=16
02/14/2018 07:03:07;0008;Server@node2;Job;1123.node2.supernodexp.hpc;Job Modified at request of Scheduler@node2.supernodexp.hpc
02/14/2018 07:05:33;0080;Server@node2;Job;1113.node2.supernodexp.hpc;Obit received momhop:1 serverhop:1 state:4 substate:42
02/14/2018 07:05:34;0010;Server@node2;Job;1113.node2.supernodexp.hpc;Exit_status=0 resources_used.cpupercent=4784 resources_used.cput=08:24:13 resources_used.mem=7858376kb resources_used.ncpus=48 resources_used.vmem=47424636kb resources_used.walltime=00:10:58
02/14/2018 07:05:34;0100;Server@node2;Job;1113.node2.supernodexp.hpc;dequeuing from workq, state 5
02/14/2018 07:05:34;0040;Server@node2;Svr;node2.supernodexp.hpc;Scheduler sent command 2
02/14/2018 07:05:34;0040;Server@node2;Svr;node2.supernodexp.hpc;Scheduler sent command 0
02/14/2018 07:05:34;0100;Server@node2;Req;;Type 21 request received from Scheduler@node2.supernodexp.hpc, sock=16
02/14/2018 07:05:34;0100;Server@node2;Req;;Type 81 request received from Scheduler@node2.supernodexp.hpc, sock=16
02/14/2018 07:05:34;0100;Server@node2;Req;;Type 71 request received from Scheduler@node2.supernodexp.hpc, sock=16
02/14/2018 07:05:34;0100;Server@node2;Req;;Type 58 request received from Scheduler@node2.supernodexp.hpc, sock=16
02/14/2018 07:05:34;0100;Server@node2;Req;;Type 20 request received from Scheduler@node2.supernodexp.hpc, sock=16
02/14/2018 07:05:34;0100;Server@node2;Req;;Type 51 request received from Scheduler@node2.supernodexp.hpc, sock=16
02/14/2018 07:05:34;0100;Server@node2;Req;;Type 23 request received from Scheduler@node2.supernodexp.hpc, sock=16
02/14/2018 07:05:34;0008;Server@node2;Job;1123.node2.supernodexp.hpc;Job Run at request of Scheduler@node2.supernodexp.hpc on exec_vnode (node13:ncpus=48:mem=5242880kb)
02/14/2018 07:05:34;0001;Server@node2;Svr;Server@node2;Success (0) in req_runjob2, return value of svr_startjob is 0
02/14/2018 07:05:34;0100;Server@node2;Req;;Type 11 request received from Scheduler@node2.supernodexp.hpc, sock=16
02/14/2018 07:05:34;0008;Server@node2;Job;1152.node2.supernodexp.hpc;Job Modified at request of Scheduler@node2.supernodexp.hpc
02/14/2018 07:15:34;0040;Server@node2;Svr;node2.supernodexp.hpc;Scheduler sent command 3
02/14/2018 07:15:34;0040;Server@node2;Svr;node2.supernodexp.hpc;Scheduler sent command 0
02/14/2018 07:15:34;0100;Server@node2;Req;;Type 21 request received from Scheduler@node2.supernodexp.hpc, sock=16
02/14/2018 07:15:34;0100;Server@node2;Req;;Type 81 request received from Scheduler@node2.supernodexp.hpc, sock=16
02/14/2018 07:15:34;0100;Server@node2;Req;;Type 71 request received from Scheduler@node2.supernodexp.hpc, sock=16
02/14/2018 07:15:34;0100;Server@node2;Req;;Type 58 request received from Scheduler@node2.supernodexp.hpc, sock=16
02/14/2018 07:15:34;0100;Server@node2;Req;;Type 20 request received from Scheduler@node2.supernodexp.hpc, sock=16
02/14/2018 07:15:34;0100;Server@node2;Req;;Type 51 request received from Scheduler@node2.supernodexp.hpc, sock=16
02/14/2018 07:16:29;0080;Server@node2;Job;1123.node2.supernodexp.hpc;Obit received momhop:1 serverhop:1 state:4 substate:42
02/14/2018 07:16:31;0010;Server@node2;Job;1123.node2.supernodexp.hpc;Exit_status=0 resources_used.cpupercent=4702 resources_used.cput=08:26:11 resources_used.mem=7914428kb resources_used.ncpus=48 resources_used.vmem=47424636kb resources_used.walltime=00:10:56
02/14/2018 07:16:31;0100;Server@node2;Job;1123.node2.supernodexp.hpc;dequeuing from workq, state 5
02/14/2018 07:16:31;0040;Server@node2;Svr;node2.supernodexp.hpc;Scheduler sent command 2
02/14/2018 07:16:31;0040;Server@node2;Svr;node2.supernodexp.hpc;Scheduler sent command 0
02/14/2018 07:16:31;0100;Server@node2;Req;;Type 21 request received from Scheduler@node2.supernodexp.hpc, sock=16
02/14/2018 07:16:31;0100;Server@node2;Req;;Type 81 request received from Scheduler@node2.supernodexp.hpc, sock=16
02/14/2018 07:16:31;0100;Server@node2;Req;;Type 71 request received from Scheduler@node2.supernodexp.hpc, sock=16
02/14/2018 07:16:31;0100;Server@node2;Req;;Type 58 request received from Scheduler@node2.supernodexp.hpc, sock=16
02/14/2018 07:16:31;0100;Server@node2;Req;;Type 20 request received from Scheduler@node2.supernodexp.hpc, sock=16
02/14/2018 07:16:31;0100;Server@node2;Req;;Type 51 request received from Scheduler@node2.supernodexp.hpc, sock=16
02/14/2018 07:16:31;0100;Server@node2;Req;;Type 23 request received from Scheduler@node2.supernodexp.hpc, sock=16
02/14/2018 07:16:31;0008;Server@node2;Job;1152.node2.supernodexp.hpc;Job Run at request of Scheduler@node2.supernodexp.hpc on exec_vnode (node13:ncpus=48:mem=5242880kb)
02/14/2018 07:16:31;0001;Server@node2;Svr;Server@node2;Success (0) in req_runjob2, return value of svr_startjob is 0
02/14/2018 07:16:31;0100;Server@node2;Req;;Type 11 request received from Scheduler@node2.supernodexp.hpc, sock=16
02/14/2018 07:16:31;0008;Server@node2;Job;1167.node2.supernodexp.hpc;Job Modified at request of Scheduler@node2.supernodexp.hpc
02/14/2018 07:20:52;0080;Server@node2;Job;1114.node2.supernodexp.hpc;Obit received momhop:1 serverhop:1 state:4 substate:42
02/14/2018 07:20:54;0010;Server@node2;Job;1114.node2.supernodexp.hpc;Exit_status=0 resources_used.cpupercent=4764 resources_used.cput=13:44:58 resources_used.mem=7930260kb resources_used.ncpus=48 resources_used.vmem=47424568kb resources_used.walltime=00:17:46
02/14/2018 07:20:54;0100;Server@node2;Job;1114.node2.supernodexp.hpc;dequeuing from workq, state 5
02/14/2018 07:20:54;0040;Server@node2;Svr;node2.supernodexp.hpc;Scheduler sent command 2
02/14/2018 07:20:54;0040;Server@node2;Svr;node2.supernodexp.hpc;Scheduler sent command 0
02/14/2018 07:20:54;0100;Server@node2;Req;;Type 21 request received from Scheduler@node2.supernodexp.hpc, sock=16
02/14/2018 07:20:54;0100;Server@node2;Req;;Type 81 request received from Scheduler@node2.supernodexp.hpc, sock=16
02/14/2018 07:20:54;0100;Server@node2;Req;;Type 71 request received from Scheduler@node2.supernodexp.hpc, sock=16
02/14/2018 07:20:54;0100;Server@node2;Req;;Type 58 request received from Scheduler@node2.supernodexp.hpc, sock=16
02/14/2018 07:20:54;0100;Server@node2;Req;;Type 20 request received from Scheduler@node2.supernodexp.hpc, sock=16
02/14/2018 07:20:54;0100;Server@node2;Req;;Type 51 request received from Scheduler@node2.supernodexp.hpc, sock=16
02/14/2018 07:20:54;0100;Server@node2;Req;;Type 23 request received from Scheduler@node2.supernodexp.hpc, sock=16
02/14/2018 07:20:54;0008;Server@node2;Job;1167.node2.supernodexp.hpc;Job Run at request of Scheduler@node2.supernodexp.hpc on exec_vnode (node14:ncpus=48:mem=5242880kb)
02/14/2018 07:20:54;0001;Server@node2;Svr;Server@node2;Success (0) in req_runjob2, return value of svr_startjob is 0
02/14/2018 07:20:54;0100;Server@node2;Req;;Type 11 request received from Scheduler@node2.supernodexp.hpc, sock=16
02/14/2018 07:20:54;0008;Server@node2;Job;1189.node2.supernodexp.hpc;Job Modified at request of Scheduler@node2.supernodexp.hpc
02/14/2018 07:27:16;0080;Server@node2;Job;1152.node2.supernodexp.hpc;Obit received momhop:1 serverhop:1 state:4 substate:42
02/14/2018 07:27:17;0010;Server@node2;Job;1152.node2.supernodexp.hpc;Exit_status=0 resources_used.cpupercent=4736 resources_used.cput=08:15:54 resources_used.mem=7938676kb resources_used.ncpus=48 resources_used.vmem=47425224kb resources_used.walltime=00:10:45
02/14/2018 07:27:17;0100;Server@node2;Job;1152.node2.supernodexp.hpc;dequeuing from workq, state 5
02/14/2018 07:27:17;0040;Server@node2;Svr;node2.supernodexp.hpc;Scheduler sent command 2
02/14/2018 07:27:17;0040;Server@node2;Svr;node2.supernodexp.hpc;Scheduler sent command 0
02/14/2018 07:27:17;0100;Server@node2;Req;;Type 21 request received from Scheduler@node2.supernodexp.hpc, sock=16
02/14/2018 07:27:17;0100;Server@node2;Req;;Type 81 request received from Scheduler@node2.supernodexp.hpc, sock=16
02/14/2018 07:27:17;0100;Server@node2;Req;;Type 71 request received from Scheduler@node2.supernodexp.hpc, sock=16
02/14/2018 07:27:17;0100;Server@node2;Req;;Type 58 request received from Scheduler@node2.supernodexp.hpc, sock=16
02/14/2018 07:27:17;0100;Server@node2;Req;;Type 20 request received from Scheduler@node2.supernodexp.hpc, sock=16
02/14/2018 07:27:17;0100;Server@node2;Req;;Type 51 request received from Scheduler@node2.supernodexp.hpc, sock=16
02/14/2018 07:27:17;0100;Server@node2;Req;;Type 23 request received from Scheduler@node2.supernodexp.hpc, sock=16
02/14/2018 07:27:17;0008;Server@node2;Job;1189.node2.supernodexp.hpc;Job Run at request of Scheduler@node2.supernodexp.hpc on exec_vnode (node13:ncpus=48:mem=5242880kb)
02/14/2018 07:27:17;0001;Server@node2;Svr;Server@node2;Success (0) in req_runjob2, return value of svr_startjob is 0
02/14/2018 07:27:17;0100;Server@node2;Req;;Type 11 request received from Scheduler@node2.supernodexp.hpc, sock=16
02/14/2018 07:27:17;0008;Server@node2;Job;1195.node2.supernodexp.hpc;Job Modified at request of Scheduler@node2.supernodexp.hpc
02/14/2018 07:37:17;0040;Server@node2;Svr;node2.supernodexp.hpc;Scheduler sent command 3
02/14/2018 07:37:17;0040;Server@node2;Svr;node2.supernodexp.hpc;Scheduler sent command 0
02/14/2018 07:37:17;0100;Server@node2;Req;;Type 21 request received from Scheduler@node2.supernodexp.hpc, sock=16
02/14/2018 07:37:17;0100;Server@node2;Req;;Type 81 request received from Scheduler@node2.supernodexp.hpc, sock=16
02/14/2018 07:37:17;0100;Server@node2;Req;;Type 71 request received from Scheduler@node2.supernodexp.hpc, sock=16
02/14/2018 07:37:17;0100;Server@node2;Req;;Type 58 request received from Scheduler@node2.supernodexp.hpc, sock=16
02/14/2018 07:37:17;0100;Server@node2;Req;;Type 20 request received from Scheduler@node2.supernodexp.hpc, sock=16
02/14/2018 07:37:17;0100;Server@node2;Req;;Type 51 request received from Scheduler@node2.supernodexp.hpc, sock=16
02/14/2018 07:37:57;0080;Server@node2;Job;1189.node2.supernodexp.hpc;Obit received momhop:1 serverhop:1 state:4 substate:42
02/14/2018 07:37:58;0010;Server@node2;Job;1189.node2.supernodexp.hpc;Exit_status=0 resources_used.cpupercent=4732 resources_used.cput=08:14:29 resources_used.mem=7941580kb resources_used.ncpus=48 resources_used.vmem=47424936kb resources_used.walltime=00:10:39
02/14/2018 07:37:58;0100;Server@node2;Job;1189.node2.supernodexp.hpc;dequeuing from workq, state 5
02/14/2018 07:37:58;0040;Server@node2;Svr;node2.supernodexp.hpc;Scheduler sent command 2
02/14/2018 07:37:58;0040;Server@node2;Svr;node2.supernodexp.hpc;Scheduler sent command 0
02/14/2018 07:37:58;0100;Server@node2;Req;;Type 21 request received from Scheduler@node2.supernodexp.hpc, sock=16
02/14/2018 07:37:58;0100;Server@node2;Req;;Type 81 request received from Scheduler@node2.supernodexp.hpc, sock=16
02/14/2018 07:37:58;0100;Server@node2;Req;;Type 71 request received from Scheduler@node2.supernodexp.hpc, sock=16
02/14/2018 07:37:58;0100;Server@node2;Req;;Type 58 request received from Scheduler@node2.supernodexp.hpc, sock=16
02/14/2018 07:37:58;0100;Server@node2;Req;;Type 20 request received from Scheduler@node2.supernodexp.hpc, sock=16
02/14/2018 07:37:58;0100;Server@node2;Req;;Type 51 request received from Scheduler@node2.supernodexp.hpc, sock=16
02/14/2018 07:37:58;0100;Server@node2;Req;;Type 23 request received from Scheduler@node2.supernodexp.hpc, sock=16
02/14/2018 07:37:58;0008;Server@node2;Job;1195.node2.supernodexp.hpc;Job Run at request of Scheduler@node2.supernodexp.hpc on exec_vnode (node13:ncpus=48:mem=5242880kb)
02/14/2018 07:37:58;0001;Server@node2;Svr;Server@node2;Success (0) in req_runjob2, return value of svr_startjob is 0
02/14/2018 07:37:58;0100;Server@node2;Req;;Type 11 request received from Scheduler@node2.supernodexp.hpc, sock=16
02/14/2018 07:37:58;0008;Server@node2;Job;1196.node2.supernodexp.hpc;Job Modified at request of Scheduler@node2.supernodexp.hpc
02/14/2018 07:38:56;0080;Server@node2;Job;1167.node2.supernodexp.hpc;Obit received momhop:1 serverhop:1 state:4 substate:42
02/14/2018 07:38:57;0010;Server@node2;Job;1167.node2.supernodexp.hpc;Exit_status=0 resources_used.cpupercent=4714 resources_used.cput=13:55:56 resources_used.mem=7891828kb resources_used.ncpus=48 resources_used.vmem=47424548kb resources_used.walltime=00:18:03
02/14/2018 07:38:57;0100;Server@node2;Job;1167.node2.supernodexp.hpc;dequeuing from workq, state 5
02/14/2018 07:38:57;0040;Server@node2;Svr;node2.supernodexp.hpc;Scheduler sent command 2
02/14/2018 07:38:57;0040;Server@node2;Svr;node2.supernodexp.hpc;Scheduler sent command 0
02/14/2018 07:38:57;0100;Server@node2;Req;;Type 21 request received from Scheduler@node2.supernodexp.hpc, sock=16
02/14/2018 07:38:57;0100;Server@node2;Req;;Type 81 request received from Scheduler@node2.supernodexp.hpc, sock=16
02/14/2018 07:38:57;0100;Server@node2;Req;;Type 71 request received from Scheduler@node2.supernodexp.hpc, sock=16
02/14/2018 07:38:57;0100;Server@node2;Req;;Type 58 request received from Scheduler@node2.supernodexp.hpc, sock=16
02/14/2018 07:38:57;0100;Server@node2;Req;;Type 20 request received from Scheduler@node2.supernodexp.hpc, sock=16
02/14/2018 07:38:57;0100;Server@node2;Req;;Type 51 request received from Scheduler@node2.supernodexp.hpc, sock=16
02/14/2018 07:38:57;0100;Server@node2;Req;;Type 23 request received from Scheduler@node2.supernodexp.hpc, sock=16
02/14/2018 07:38:57;0008;Server@node2;Job;1196.node2.supernodexp.hpc;Job Run at request of Scheduler@node2.supernodexp.hpc on exec_vnode (node14:ncpus=48:mem=5242880kb)
02/14/2018 07:38:57;0001;Server@node2;Svr;Server@node2;Success (0) in req_runjob2, return value of svr_startjob is 0
02/14/2018 07:38:57;0100;Server@node2;Req;;Type 11 request received from Scheduler@node2.supernodexp.hpc, sock=16
02/14/2018 07:38:57;0008;Server@node2;Job;1010.node2.supernodexp.hpc;Job Modified at request of Scheduler@node2.supernodexp.hpc
02/14/2018 07:48:39;0080;Server@node2;Job;1195.node2.supernodexp.hpc;Obit received momhop:1 serverhop:1 state:4 substate:42
02/14/2018 07:48:41;0010;Server@node2;Job;1195.node2.supernodexp.hpc;Exit_status=0 resources_used.cpupercent=4748 resources_used.cput=08:17:54 resources_used.mem=7928156kb resources_used.ncpus=48 resources_used.vmem=47424328kb resources_used.walltime=00:10:41
02/14/2018 07:48:41;0100;Server@node2;Job;1195.node2.supernodexp.hpc;dequeuing from workq, state 5
02/14/2018 07:48:41;0040;Server@node2;Svr;node2.supernodexp.hpc;Scheduler sent command 2
02/14/2018 07:48:41;0040;Server@node2;Svr;node2.supernodexp.hpc;Scheduler sent command 0
02/14/2018 07:48:41;0100;Server@node2;Req;;Type 21 request received from Scheduler@node2.supernodexp.hpc, sock=16
02/14/2018 07:48:41;0100;Server@node2;Req;;Type 81 request received from Scheduler@node2.supernodexp.hpc, sock=16
02/14/2018 07:48:41;0100;Server@node2;Req;;Type 71 request received from Scheduler@node2.supernodexp.hpc, sock=16
02/14/2018 07:48:41;0100;Server@node2;Req;;Type 58 request received from Scheduler@node2.supernodexp.hpc, sock=16
02/14/2018 07:48:41;0100;Server@node2;Req;;Type 20 request received from Scheduler@node2.supernodexp.hpc, sock=16
02/14/2018 07:48:41;0100;Server@node2;Req;;Type 51 request received from Scheduler@node2.supernodexp.hpc, sock=16
02/14/2018 07:48:41;0100;Server@node2;Req;;Type 23 request received from Scheduler@node2.supernodexp.hpc, sock=16
02/14/2018 07:48:41;0008;Server@node2;Job;1010.node2.supernodexp.hpc;Job Run at request of Scheduler@node2.supernodexp.hpc on exec_vnode (node13:ncpus=16:mem=8388608kb)
02/14/2018 07:48:41;0001;Server@node2;Svr;Server@node2;Success (0) in req_runjob2, return value of svr_startjob is 0
02/14/2018 07:48:41;0100;Server@node2;Req;;Type 23 request received from Scheduler@node2.supernodexp.hpc, sock=16
02/14/2018 07:48:41;0008;Server@node2;Job;1012.node2.supernodexp.hpc;Job Run at request of Scheduler@node2.supernodexp.hpc on exec_vnode (node13:ncpus=16:mem=8388608kb)
02/14/2018 07:48:41;0001;Server@node2;Svr;Server@node2;Success (0) in req_runjob2, return value of svr_startjob is 0
02/14/2018 07:48:41;0100;Server@node2;Req;;Type 23 request received from Scheduler@node2.supernodexp.hpc, sock=16
02/14/2018 07:48:41;0008;Server@node2;Job;1033.node2.supernodexp.hpc;Job Run at request of Scheduler@node2.supernodexp.hpc on exec_vnode (node13:ncpus=16:mem=8388608kb)
02/14/2018 07:48:41;0001;Server@node2;Svr;Server@node2;Success (0) in req_runjob2, return value of svr_startjob is 0
02/14/2018 07:48:41;0100;Server@node2;Req;;Type 11 request received from Scheduler@node2.supernodexp.hpc, sock=16
02/14/2018 07:48:41;0008;Server@node2;Job;1042.node2.supernodexp.hpc;Job Modified at request of Scheduler@node2.supernodexp.hpc
02/14/2018 07:48:45;0080;Server@node2;Job;1010.node2.supernodexp.hpc;Obit received momhop:1 serverhop:1 state:4 substate:42
02/14/2018 07:48:46;0010;Server@node2;Job;1010.node2.supernodexp.hpc;Exit_status=1 resources_used.cpupercent=39 resources_used.cput=00:00:02 resources_used.mem=0kb resources_used.ncpus=16 resources_used.vmem=0kb resources_used.walltime=00:00:05
02/14/2018 07:48:46;0100;Server@node2;Job;1010.node2.supernodexp.hpc;dequeuing from workq, state 5
02/14/2018 07:48:46;0040;Server@node2;Svr;node2.supernodexp.hpc;Scheduler sent command 2
02/14/2018 07:48:46;0040;Server@node2;Svr;node2.supernodexp.hpc;Scheduler sent command 0
02/14/2018 07:48:46;0100;Server@node2;Req;;Type 21 request received from Scheduler@node2.supernodexp.hpc, sock=16
02/14/2018 07:48:46;0100;Server@node2;Req;;Type 81 request received from Scheduler@node2.supernodexp.hpc, sock=16
02/14/2018 07:48:46;0100;Server@node2;Req;;Type 71 request received from Scheduler@node2.supernodexp.hpc, sock=16
02/14/2018 07:48:46;0100;Server@node2;Req;;Type 58 request received from Scheduler@node2.supernodexp.hpc, sock=16
02/14/2018 07:48:46;0100;Server@node2;Req;;Type 20 request received from Scheduler@node2.supernodexp.hpc, sock=16
02/14/2018 07:48:46;0100;Server@node2;Req;;Type 51 request received from Scheduler@node2.supernodexp.hpc, sock=16
02/14/2018 07:48:47;0100;Server@node2;Req;;Type 23 request received from Scheduler@node2.supernodexp.hpc, sock=16
02/14/2018 07:48:47;0008;Server@node2;Job;1042.node2.supernodexp.hpc;Job Run at request of Scheduler@node2.supernodexp.hpc on exec_vnode (node13:ncpus=16:mem=8388608kb)
02/14/2018 07:48:47;0001;Server@node2;Svr;Server@node2;Success (0) in req_runjob2, return value of svr_startjob is 0
02/14/2018 07:48:47;0100;Server@node2;Req;;Type 11 request received from Scheduler@node2.supernodexp.hpc, sock=16
02/14/2018 07:48:47;0008;Server@node2;Job;1064.node2.supernodexp.hpc;Job Modified at request of Scheduler@node2.supernodexp.hpc
02/14/2018 07:48:58;0080;Server@node2;Job;1033.node2.supernodexp.hpc;Obit received momhop:1 serverhop:1 state:4 substate:42
02/14/2018 07:48:59;0010;Server@node2;Job;1033.node2.supernodexp.hpc;Exit_status=1 resources_used.cpupercent=39 resources_used.cput=00:00:03 resources_used.mem=82092kb resources_used.ncpus=16 resources_used.vmem=1073040kb resources_used.walltime=00:00:17
02/14/2018 07:48:59;0100;Server@node2;Job;1033.node2.supernodexp.hpc;dequeuing from workq, state 5
02/14/2018 07:48:59;0040;Server@node2;Svr;node2.supernodexp.hpc;Scheduler sent command 2
02/14/2018 07:48:59;0040;Server@node2;Svr;node2.supernodexp.hpc;Scheduler sent command 0
02/14/2018 07:48:59;0100;Server@node2;Req;;Type 21 request received from Scheduler@node2.supernodexp.hpc, sock=16
02/14/2018 07:48:59;0100;Server@node2;Req;;Type 81 request received from Scheduler@node2.supernodexp.hpc, sock=16
02/14/2018 07:48:59;0100;Server@node2;Req;;Type 71 request received from Scheduler@node2.supernodexp.hpc, sock=16
02/14/2018 07:48:59;0100;Server@node2;Req;;Type 58 request received from Scheduler@node2.supernodexp.hpc, sock=16
02/14/2018 07:48:59;0100;Server@node2;Req;;Type 20 request received from Scheduler@node2.supernodexp.hpc, sock=16
02/14/2018 07:48:59;0100;Server@node2;Req;;Type 51 request received from Scheduler@node2.supernodexp.hpc, sock=16
02/14/2018 07:48:59;0100;Server@node2;Req;;Type 23 request received from Scheduler@node2.supernodexp.hpc, sock=16
02/14/2018 07:48:59;0008;Server@node2;Job;1064.node2.supernodexp.hpc;Job Run at request of Scheduler@node2.supernodexp.hpc on exec_vnode (node13:ncpus=16:mem=8388608kb)
02/14/2018 07:48:59;0001;Server@node2;Svr;Server@node2;Success (0) in req_runjob2, return value of svr_startjob is 0
02/14/2018 07:48:59;0100;Server@node2;Req;;Type 11 request received from Scheduler@node2.supernodexp.hpc, sock=16
02/14/2018 07:48:59;0008;Server@node2;Job;1070.node2.supernodexp.hpc;Job Modified at request of Scheduler@node2.supernodexp.hpc
02/14/2018 07:52:19;0080;Server@node2;Job;1042.node2.supernodexp.hpc;Obit received momhop:1 serverhop:1 state:4 substate:42
02/14/2018 07:52:21;0010;Server@node2;Job;1042.node2.supernodexp.hpc;Exit_status=0 resources_used.cpupercent=1057 resources_used.cput=00:54:23 resources_used.mem=1116892kb resources_used.ncpus=16 resources_used.vmem=9776612kb resources_used.walltime=00:03:33
02/14/2018 07:52:21;0100;Server@node2;Job;1042.node2.supernodexp.hpc;dequeuing from workq, state 5
02/14/2018 07:52:21;0040;Server@node2;Svr;node2.supernodexp.hpc;Scheduler sent command 2
02/14/2018 07:52:21;0040;Server@node2;Svr;node2.supernodexp.hpc;Scheduler sent command 0
02/14/2018 07:52:21;0100;Server@node2;Req;;Type 21 request received from Scheduler@node2.supernodexp.hpc, sock=16
02/14/2018 07:52:21;0100;Server@node2;Req;;Type 81 request received from Scheduler@node2.supernodexp.hpc, sock=16
02/14/2018 07:52:21;0100;Server@node2;Req;;Type 71 request received from Scheduler@node2.supernodexp.hpc, sock=16
02/14/2018 07:52:21;0100;Server@node2;Req;;Type 58 request received from Scheduler@node2.supernodexp.hpc, sock=16
02/14/2018 07:52:21;0100;Server@node2;Req;;Type 20 request received from Scheduler@node2.supernodexp.hpc, sock=16
02/14/2018 07:52:21;0100;Server@node2;Req;;Type 51 request received from Scheduler@node2.supernodexp.hpc, sock=16
02/14/2018 07:52:21;0100;Server@node2;Req;;Type 23 request received from Scheduler@node2.supernodexp.hpc, sock=16
02/14/2018 07:52:21;0008;Server@node2;Job;1070.node2.supernodexp.hpc;Job Run at request of Scheduler@node2.supernodexp.hpc on exec_vnode (node13:ncpus=16:mem=8388608kb)
02/14/2018 07:52:21;0001;Server@node2;Svr;Server@node2;Success (0) in req_runjob2, return value of svr_startjob is 0
02/14/2018 07:52:21;0100;Server@node2;Req;;Type 11 request received from Scheduler@node2.supernodexp.hpc, sock=16
02/14/2018 07:52:21;0008;Server@node2;Job;1117.node2.supernodexp.hpc;Job Modified at request of Scheduler@node2.supernodexp.hpc
02/14/2018 07:52:33;0080;Server@node2;Job;1012.node2.supernodexp.hpc;Obit received momhop:1 serverhop:1 state:4 substate:42
02/14/2018 07:52:35;0010;Server@node2;Job;1012.node2.supernodexp.hpc;Exit_status=0 resources_used.cpupercent=848 resources_used.cput=00:56:21 resources_used.mem=1114812kb resources_used.ncpus=16 resources_used.vmem=9776660kb resources_used.walltime=00:03:53
02/14/2018 07:52:35;0100;Server@node2;Job;1012.node2.supernodexp.hpc;dequeuing from workq, state 5
02/14/2018 07:52:35;0040;Server@node2;Svr;node2.supernodexp.hpc;Scheduler sent command 2
02/14/2018 07:52:35;0040;Server@node2;Svr;node2.supernodexp.hpc;Scheduler sent command 0
02/14/2018 07:52:35;0100;Server@node2;Req;;Type 21 request received from Scheduler@node2.supernodexp.hpc, sock=16
02/14/2018 07:52:35;0100;Server@node2;Req;;Type 81 request received from Scheduler@node2.supernodexp.hpc, sock=16
02/14/2018 07:52:35;0100;Server@node2;Req;;Type 71 request received from Scheduler@node2.supernodexp.hpc, sock=16
02/14/2018 07:52:35;0100;Server@node2;Req;;Type 58 request received from Scheduler@node2.supernodexp.hpc, sock=16
02/14/2018 07:52:35;0100;Server@node2;Req;;Type 20 request received from Scheduler@node2.supernodexp.hpc, sock=16
02/14/2018 07:52:35;0100;Server@node2;Req;;Type 51 request received from Scheduler@node2.supernodexp.hpc, sock=16
02/14/2018 07:52:35;0100;Server@node2;Req;;Type 23 request received from Scheduler@node2.supernodexp.hpc, sock=16
02/14/2018 07:52:35;0008;Server@node2;Job;1117.node2.supernodexp.hpc;Job Run at request of Scheduler@node2.supernodexp.hpc on exec_vnode (node13:ncpus=16:mem=8388608kb)
02/14/2018 07:52:35;0001;Server@node2;Svr;Server@node2;Success (0) in req_runjob2, return value of svr_startjob is 0
02/14/2018 07:52:35;0100;Server@node2;Req;;Type 11 request received from Scheduler@node2.supernodexp.hpc, sock=16
02/14/2018 07:52:35;0008;Server@node2;Job;1119.node2.supernodexp.hpc;Job Modified at request of Scheduler@node2.supernodexp.hpc
02/14/2018 07:52:36;0080;Server@node2;Job;1064.node2.supernodexp.hpc;Obit received momhop:1 serverhop:1 state:4 substate:42
02/14/2018 07:52:37;0010;Server@node2;Job;1064.node2.supernodexp.hpc;Exit_status=0 resources_used.cpupercent=928 resources_used.cput=00:55:09 resources_used.mem=1115084kb resources_used.ncpus=16 resources_used.vmem=9776856kb resources_used.walltime=00:03:37
02/14/2018 07:52:37;0100;Server@node2;Job;1064.node2.supernodexp.hpc;dequeuing from workq, state 5
02/14/2018 07:52:37;0040;Server@node2;Svr;node2.supernodexp.hpc;Scheduler sent command 2
02/14/2018 07:52:37;0040;Server@node2;Svr;node2.supernodexp.hpc;Scheduler sent command 0
02/14/2018 07:52:37;0100;Server@node2;Req;;Type 21 request received from Scheduler@node2.supernodexp.hpc, sock=16
02/14/2018 07:52:37;0100;Server@node2;Req;;Type 81 request received from Scheduler@node2.supernodexp.hpc, sock=16
02/14/2018 07:52:37;0100;Server@node2;Req;;Type 71 request received from Scheduler@node2.supernodexp.hpc, sock=16
02/14/2018 07:52:37;0100;Server@node2;Req;;Type 58 request received from Scheduler@node2.supernodexp.hpc, sock=16
02/14/2018 07:52:37;0100;Server@node2;Req;;Type 20 request received from Scheduler@node2.supernodexp.hpc, sock=16
02/14/2018 07:52:37;0100;Server@node2;Req;;Type 51 request received from Scheduler@node2.supernodexp.hpc, sock=16
02/14/2018 07:52:37;0100;Server@node2;Req;;Type 23 request received from Scheduler@node2.supernodexp.hpc, sock=16
02/14/2018 07:52:37;0008;Server@node2;Job;1119.node2.supernodexp.hpc;Job Run at request of Scheduler@node2.supernodexp.hpc on exec_vnode (node13:ncpus=16:mem=8388608kb)
02/14/2018 07:52:37;0001;Server@node2;Svr;Server@node2;Success (0) in req_runjob2, return value of svr_startjob is 0
02/14/2018 07:52:37;0100;Server@node2;Req;;Type 11 request received from Scheduler@node2.supernodexp.hpc, sock=16
02/14/2018 07:52:37;0008;Server@node2;Job;1147.node2.supernodexp.hpc;Job Modified at request of Scheduler@node2.supernodexp.hpc
02/14/2018 07:53:39;0080;Server@node2;Job;1196.node2.supernodexp.hpc;Obit received momhop:1 serverhop:1 state:4 substate:42
02/14/2018 07:54:00;0010;Server@node2;Job;1196.node2.supernodexp.hpc;Exit_status=0 resources_used.cpupercent=4730 resources_used.cput=11:35:16 resources_used.mem=8055460kb resources_used.ncpus=48 resources_used.vmem=47424820kb resources_used.walltime=00:14:38
02/14/2018 07:54:00;0100;Server@node2;Job;1196.node2.supernodexp.hpc;dequeuing from workq, state 5
02/14/2018 07:54:00;0040;Server@node2;Svr;node2.supernodexp.hpc;Scheduler sent command 2
02/14/2018 07:54:00;0040;Server@node2;Svr;node2.supernodexp.hpc;Scheduler sent command 0
02/14/2018 07:54:00;0100;Server@node2;Req;;Type 21 request received from Scheduler@node2.supernodexp.hpc, sock=16
02/14/2018 07:54:00;0100;Server@node2;Req;;Type 81 request received from Scheduler@node2.supernodexp.hpc, sock=16
02/14/2018 07:54:00;0100;Server@node2;Req;;Type 71 request received from Scheduler@node2.supernodexp.hpc, sock=16
02/14/2018 07:54:00;0100;Server@node2;Req;;Type 58 request received from Scheduler@node2.supernodexp.hpc, sock=16
02/14/2018 07:54:00;0100;Server@node2;Req;;Type 20 request received from Scheduler@node2.supernodexp.hpc, sock=16
02/14/2018 07:54:00;0100;Server@node2;Req;;Type 51 request received from Scheduler@node2.supernodexp.hpc, sock=16
02/14/2018 07:54:00;0100;Server@node2;Req;;Type 23 request received from Scheduler@node2.supernodexp.hpc, sock=16
02/14/2018 07:54:00;0008;Server@node2;Job;1147.node2.supernodexp.hpc;Job Run at request of Scheduler@node2.supernodexp.hpc on exec_vnode (node14:ncpus=16:mem=8388608kb)
02/14/2018 07:54:00;0001;Server@node2;Svr;Server@node2;Success (0) in req_runjob2, return value of svr_startjob is 0
02/14/2018 07:54:00;0100;Server@node2;Req;;Type 23 request received from Scheduler@node2.supernodexp.hpc, sock=16
02/14/2018 07:54:00;0008;Server@node2;Job;1181.node2.supernodexp.hpc;Job Run at request of Scheduler@node2.supernodexp.hpc on exec_vnode (node14:ncpus=16:mem=8388608kb)
02/14/2018 07:54:00;0001;Server@node2;Svr;Server@node2;Success (0) in req_runjob2, return value of svr_startjob is 0
02/14/2018 07:54:00;0100;Server@node2;Req;;Type 23 request received from Scheduler@node2.supernodexp.hpc, sock=16
02/14/2018 07:54:00;0008;Server@node2;Job;1192.node2.supernodexp.hpc;Job Run at request of Scheduler@node2.supernodexp.hpc on exec_vnode (node14:ncpus=16:mem=8388608kb)
02/14/2018 07:54:00;0001;Server@node2;Svr;Server@node2;Success (0) in req_runjob2, return value of svr_startjob is 0
02/14/2018 07:54:00;0100;Server@node2;Req;;Type 11 request received from Scheduler@node2.supernodexp.hpc, sock=16
02/14/2018 07:54:00;0008;Server@node2;Job;1011.node2.supernodexp.hpc;Job Modified at request of Scheduler@node2.supernodexp.hpc
02/14/2018 07:54:05;0080;Server@node2;Job;1147.node2.supernodexp.hpc;Obit received momhop:1 serverhop:1 state:4 substate:42
02/14/2018 07:54:08;0080;Server@node2;Job;1192.node2.supernodexp.hpc;Obit received momhop:1 serverhop:1 state:4 substate:42
02/14/2018 07:54:12;0010;Server@node2;Job;1147.node2.supernodexp.hpc;Exit_status=1 resources_used.cpupercent=50 resources_used.cput=00:00:02 resources_used.mem=0kb resources_used.ncpus=16 resources_used.vmem=0kb resources_used.walltime=00:00:06
02/14/2018 07:54:12;0100;Server@node2;Job;1147.node2.supernodexp.hpc;dequeuing from workq, state 5
02/14/2018 07:54:12;0040;Server@node2;Svr;node2.supernodexp.hpc;Scheduler sent command 2
02/14/2018 07:54:12;0040;Server@node2;Svr;node2.supernodexp.hpc;Scheduler sent command 0
02/14/2018 07:54:12;0100;Server@node2;Req;;Type 21 request received from Scheduler@node2.supernodexp.hpc, sock=16
02/14/2018 07:54:12;0100;Server@node2;Req;;Type 81 request received from Scheduler@node2.supernodexp.hpc, sock=16
02/14/2018 07:54:12;0100;Server@node2;Req;;Type 71 request received from Scheduler@node2.supernodexp.hpc, sock=16
02/14/2018 07:54:12;0100;Server@node2;Req;;Type 58 request received from Scheduler@node2.supernodexp.hpc, sock=16
02/14/2018 07:54:12;0100;Server@node2;Req;;Type 20 request received from Scheduler@node2.supernodexp.hpc, sock=16
02/14/2018 07:54:12;0100;Server@node2;Req;;Type 51 request received from Scheduler@node2.supernodexp.hpc, sock=16
02/14/2018 07:54:12;0100;Server@node2;Req;;Type 11 request received from Scheduler@node2.supernodexp.hpc, sock=16
02/14/2018 07:54:12;0008;Server@node2;Job;1011.node2.supernodexp.hpc;Job Modified at request of Scheduler@node2.supernodexp.hpc
02/14/2018 07:54:17;0010;Server@node2;Job;1192.node2.supernodexp.hpc;Exit_status=1 resources_used.cpupercent=50 resources_used.cput=00:00:03 resources_used.mem=37024kb resources_used.ncpus=16 resources_used.vmem=651680kb resources_used.walltime=00:00:08
02/14/2018 07:54:17;0100;Server@node2;Job;1192.node2.supernodexp.hpc;dequeuing from workq, state 5
02/14/2018 07:54:17;0040;Server@node2;Svr;node2.supernodexp.hpc;Scheduler sent command 2
02/14/2018 07:54:17;0040;Server@node2;Svr;node2.supernodexp.hpc;Scheduler sent command 0
02/14/2018 07:54:17;0100;Server@node2;Req;;Type 21 request received from Scheduler@node2.supernodexp.hpc, sock=16
02/14/2018 07:54:17;0100;Server@node2;Req;;Type 81 request received from Scheduler@node2.supernodexp.hpc, sock=16
02/14/2018 07:54:17;0100;Server@node2;Req;;Type 71 request received from Scheduler@node2.supernodexp.hpc, sock=16
02/14/2018 07:54:17;0100;Server@node2;Req;;Type 58 request received from Scheduler@node2.supernodexp.hpc, sock=16
02/14/2018 07:54:17;0100;Server@node2;Req;;Type 20 request received from Scheduler@node2.supernodexp.hpc, sock=16
02/14/2018 07:54:17;0100;Server@node2;Req;;Type 51 request received from Scheduler@node2.supernodexp.hpc, sock=16
02/14/2018 07:54:17;0100;Server@node2;Req;;Type 23 request received from Scheduler@node2.supernodexp.hpc, sock=16
02/14/2018 07:54:17;0008;Server@node2;Job;1011.node2.supernodexp.hpc;Job Run at request of Scheduler@node2.supernodexp.hpc on exec_vnode (node14:ncpus=24:mem=2097152kb)
02/14/2018 07:54:17;0001;Server@node2;Svr;Server@node2;Success (0) in req_runjob2, return value of svr_startjob is 0
02/14/2018 07:54:17;0100;Server@node2;Req;;Type 11 request received from Scheduler@node2.supernodexp.hpc, sock=16
02/14/2018 07:54:17;0008;Server@node2;Job;1014.node2.supernodexp.hpc;Job Modified at request of Scheduler@node2.supernodexp.hpc
02/14/2018 07:56:06;0080;Server@node2;Job;1070.node2.supernodexp.hpc;Obit received momhop:1 serverhop:1 state:4 substate:42
02/14/2018 07:56:08;0010;Server@node2;Job;1070.node2.supernodexp.hpc;Exit_status=0 resources_used.cpupercent=850 resources_used.cput=00:55:49 resources_used.mem=1114836kb resources_used.ncpus=16 resources_used.vmem=9776672kb resources_used.walltime=00:03:46
02/14/2018 07:56:08;0100;Server@node2;Job;1070.node2.supernodexp.hpc;dequeuing from workq, state 5
02/14/2018 07:56:08;0040;Server@node2;Svr;node2.supernodexp.hpc;Scheduler sent command 2
02/14/2018 07:56:08;0040;Server@node2;Svr;node2.supernodexp.hpc;Scheduler sent command 0
02/14/2018 07:56:08;0100;Server@node2;Req;;Type 21 request received from Scheduler@node2.supernodexp.hpc, sock=16
02/14/2018 07:56:08;0100;Server@node2;Req;;Type 81 request received from Scheduler@node2.supernodexp.hpc, sock=16
02/14/2018 07:56:08;0100;Server@node2;Req;;Type 71 request received from Scheduler@node2.supernodexp.hpc, sock=16
02/14/2018 07:56:08;0100;Server@node2;Req;;Type 58 request received from Scheduler@node2.supernodexp.hpc, sock=16
02/14/2018 07:56:08;0100;Server@node2;Req;;Type 20 request received from Scheduler@node2.supernodexp.hpc, sock=16
02/14/2018 07:56:08;0100;Server@node2;Req;;Type 51 request received from Scheduler@node2.supernodexp.hpc, sock=16
02/14/2018 07:56:08;0100;Server@node2;Req;;Type 11 request received from Scheduler@node2.supernodexp.hpc, sock=16
02/14/2018 07:56:08;0008;Server@node2;Job;1014.node2.supernodexp.hpc;Job Modified at request of Scheduler@node2.supernodexp.hpc
02/14/2018 07:56:15;0080;Server@node2;Job;1117.node2.supernodexp.hpc;Obit received momhop:1 serverhop:1 state:4 substate:42
02/14/2018 07:56:15;0080;Server@node2;Job;1119.node2.supernodexp.hpc;Obit received momhop:1 serverhop:1 state:4 substate:42
02/14/2018 07:56:16;0010;Server@node2;Job;1117.node2.supernodexp.hpc;Exit_status=0 resources_used.cpupercent=876 resources_used.cput=00:56:15 resources_used.mem=1116288kb resources_used.ncpus=16 resources_used.vmem=9777664kb resources_used.walltime=00:03:40
02/14/2018 07:56:16;0100;Server@node2;Job;1117.node2.supernodexp.hpc;dequeuing from workq, state 5
02/14/2018 07:56:16;0010;Server@node2;Job;1119.node2.supernodexp.hpc;Exit_status=0 resources_used.cpupercent=994 resources_used.cput=00:55:21 resources_used.mem=1114948kb resources_used.ncpus=16 resources_used.vmem=9776604kb resources_used.walltime=00:03:38
02/14/2018 07:56:16;0100;Server@node2;Job;1119.node2.supernodexp.hpc;dequeuing from workq, state 5
02/14/2018 07:56:16;0040;Server@node2;Svr;node2.supernodexp.hpc;Scheduler sent command 2
02/14/2018 07:56:16;0040;Server@node2;Svr;node2.supernodexp.hpc;Scheduler sent command 0
02/14/2018 07:56:16;0100;Server@node2;Req;;Type 21 request received from Scheduler@node2.supernodexp.hpc, sock=16
02/14/2018 07:56:16;0100;Server@node2;Req;;Type 81 request received from Scheduler@node2.supernodexp.hpc, sock=16
02/14/2018 07:56:16;0100;Server@node2;Req;;Type 71 request received from Scheduler@node2.supernodexp.hpc, sock=16
02/14/2018 07:56:16;0100;Server@node2;Req;;Type 58 request received from Scheduler@node2.supernodexp.hpc, sock=16
02/14/2018 07:56:16;0100;Server@node2;Req;;Type 20 request received from Scheduler@node2.supernodexp.hpc, sock=16
02/14/2018 07:56:16;0100;Server@node2;Req;;Type 51 request received from Scheduler@node2.supernodexp.hpc, sock=16
02/14/2018 07:56:17;0100;Server@node2;Req;;Type 23 request received from Scheduler@node2.supernodexp.hpc, sock=16
02/14/2018 07:56:17;0008;Server@node2;Job;1014.node2.supernodexp.hpc;Job Run at request of Scheduler@node2.supernodexp.hpc on exec_vnode (node13:ncpus=24:mem=2097152kb)
02/14/2018 07:56:17;0001;Server@node2;Svr;Server@node2;Success (0) in req_runjob2, return value of svr_startjob is 0
02/14/2018 07:56:17;0100;Server@node2;Req;;Type 23 request received from Scheduler@node2.supernodexp.hpc, sock=16
02/14/2018 07:56:17;0008;Server@node2;Job;1039.node2.supernodexp.hpc;Job Run at request of Scheduler@node2.supernodexp.hpc on exec_vnode (node13:ncpus=24:mem=2097152kb)
02/14/2018 07:56:17;0001;Server@node2;Svr;Server@node2;Success (0) in req_runjob2, return value of svr_startjob is 0
02/14/2018 07:56:17;0100;Server@node2;Req;;Type 11 request received from Scheduler@node2.supernodexp.hpc, sock=16
02/14/2018 07:56:17;0008;Server@node2;Job;1049.node2.supernodexp.hpc;Job Modified at request of Scheduler@node2.supernodexp.hpc
02/14/2018 07:56:42;0080;Server@node2;Job;1014.node2.supernodexp.hpc;Obit received momhop:1 serverhop:1 state:4 substate:42
02/14/2018 07:56:43;0010;Server@node2;Job;1014.node2.supernodexp.hpc;Exit_status=1 resources_used.cpupercent=20 resources_used.cput=00:00:03 resources_used.mem=38664kb resources_used.ncpus=24 resources_used.vmem=651664kb resources_used.walltime=00:00:26
02/14/2018 07:56:43;0100;Server@node2;Job;1014.node2.supernodexp.hpc;dequeuing from workq, state 5
02/14/2018 07:56:43;0040;Server@node2;Svr;node2.supernodexp.hpc;Scheduler sent command 2
02/14/2018 07:56:43;0040;Server@node2;Svr;node2.supernodexp.hpc;Scheduler sent command 0
02/14/2018 07:56:43;0100;Server@node2;Req;;Type 21 request received from Scheduler@node2.supernodexp.hpc, sock=16
02/14/2018 07:56:43;0100;Server@node2;Req;;Type 81 request received from Scheduler@node2.supernodexp.hpc, sock=16
02/14/2018 07:56:43;0100;Server@node2;Req;;Type 71 request received from Scheduler@node2.supernodexp.hpc, sock=16
02/14/2018 07:56:43;0100;Server@node2;Req;;Type 58 request received from Scheduler@node2.supernodexp.hpc, sock=16
02/14/2018 07:56:44;0100;Server@node2;Req;;Type 20 request received from Scheduler@node2.supernodexp.hpc, sock=16
02/14/2018 07:56:44;0100;Server@node2;Req;;Type 51 request received from Scheduler@node2.supernodexp.hpc, sock=16
02/14/2018 07:56:44;0100;Server@node2;Req;;Type 23 request received from Scheduler@node2.supernodexp.hpc, sock=16
02/14/2018 07:56:44;0008;Server@node2;Job;1049.node2.supernodexp.hpc;Job Run at request of Scheduler@node2.supernodexp.hpc on exec_vnode (node13:ncpus=24:mem=2097152kb)
02/14/2018 07:56:44;0001;Server@node2;Svr;Server@node2;Success (0) in req_runjob2, return value of svr_startjob is 0
02/14/2018 07:56:44;0100;Server@node2;Req;;Type 11 request received from Scheduler@node2.supernodexp.hpc, sock=16
02/14/2018 07:56:44;0008;Server@node2;Job;1071.node2.supernodexp.hpc;Job Modified at request of Scheduler@node2.supernodexp.hpc
02/14/2018 07:57:14;0080;Server@node2;Job;1011.node2.supernodexp.hpc;Obit received momhop:1 serverhop:1 state:4 substate:42
02/14/2018 07:57:15;0080;Server@node2;Job;1181.node2.supernodexp.hpc;Obit received momhop:1 serverhop:1 state:4 substate:42
02/14/2018 07:57:16;0010;Server@node2;Job;1011.node2.supernodexp.hpc;Exit_status=0 resources_used.cpupercent=1342 resources_used.cput=01:06:43 resources_used.mem=1642080kb resources_used.ncpus=24 resources_used.vmem=15000220kb resources_used.walltime=00:02:58
02/14/2018 07:57:16;0100;Server@node2;Job;1011.node2.supernodexp.hpc;dequeuing from workq, state 5
02/14/2018 07:57:16;0010;Server@node2;Job;1181.node2.supernodexp.hpc;Exit_status=0 resources_used.cpupercent=781 resources_used.cput=00:48:59 resources_used.mem=1115004kb resources_used.ncpus=16 resources_used.vmem=9811912kb resources_used.walltime=00:03:15
02/14/2018 07:57:16;0100;Server@node2;Job;1181.node2.supernodexp.hpc;dequeuing from workq, state 5
02/14/2018 07:57:16;0040;Server@node2;Svr;node2.supernodexp.hpc;Scheduler sent command 2
02/14/2018 07:57:16;0040;Server@node2;Svr;node2.supernodexp.hpc;Scheduler sent command 0
02/14/2018 07:57:16;0100;Server@node2;Req;;Type 21 request received from Scheduler@node2.supernodexp.hpc, sock=16
02/14/2018 07:57:16;0100;Server@node2;Req;;Type 81 request received from Scheduler@node2.supernodexp.hpc, sock=16
02/14/2018 07:57:16;0100;Server@node2;Req;;Type 71 request received from Scheduler@node2.supernodexp.hpc, sock=16
02/14/2018 07:57:16;0100;Server@node2;Req;;Type 58 request received from Scheduler@node2.supernodexp.hpc, sock=16
02/14/2018 07:57:16;0100;Server@node2;Req;;Type 20 request received from Scheduler@node2.supernodexp.hpc, sock=16
02/14/2018 07:57:16;0100;Server@node2;Req;;Type 51 request received from Scheduler@node2.supernodexp.hpc, sock=16
02/14/2018 07:57:16;0100;Server@node2;Req;;Type 23 request received from Scheduler@node2.supernodexp.hpc, sock=16
02/14/2018 07:57:16;0008;Server@node2;Job;1071.node2.supernodexp.hpc;Job Run at request of Scheduler@node2.supernodexp.hpc on exec_vnode (node14:ncpus=24:mem=2097152kb)
02/14/2018 07:57:16;0001;Server@node2;Svr;Server@node2;Success (0) in req_runjob2, return value of svr_startjob is 0
02/14/2018 07:57:16;0100;Server@node2;Req;;Type 23 request received from Scheduler@node2.supernodexp.hpc, sock=16
02/14/2018 07:57:16;0008;Server@node2;Job;1091.node2.supernodexp.hpc;Job Run at request of Scheduler@node2.supernodexp.hpc on exec_vnode (node14:ncpus=24:mem=2097152kb)
02/14/2018 07:57:16;0001;Server@node2;Svr;Server@node2;Success (0) in req_runjob2, return value of svr_startjob is 0
02/14/2018 07:57:16;0100;Server@node2;Req;;Type 11 request received from Scheduler@node2.supernodexp.hpc, sock=16
02/14/2018 07:57:16;0008;Server@node2;Job;1121.node2.supernodexp.hpc;Job Modified at request of Scheduler@node2.supernodexp.hpc
02/14/2018 07:57:24;0080;Server@node2;Job;1071.node2.supernodexp.hpc;Obit received momhop:1 serverhop:1 state:4 substate:42
02/14/2018 07:57:25;0010;Server@node2;Job;1071.node2.supernodexp.hpc;Exit_status=1 resources_used.cpupercent=28 resources_used.cput=00:00:02 resources_used.mem=0kb resources_used.ncpus=24 resources_used.vmem=0kb resources_used.walltime=00:00:07
02/14/2018 07:57:25;0100;Server@node2;Job;1071.node2.supernodexp.hpc;dequeuing from workq, state 5
02/14/2018 07:57:25;0040;Server@node2;Svr;node2.supernodexp.hpc;Scheduler sent command 2
02/14/2018 07:57:25;0040;Server@node2;Svr;node2.supernodexp.hpc;Scheduler sent command 0
02/14/2018 07:57:25;0100;Server@node2;Req;;Type 21 request received from Scheduler@node2.supernodexp.hpc, sock=16
02/14/2018 07:57:25;0100;Server@node2;Req;;Type 81 request received from Scheduler@node2.supernodexp.hpc, sock=16
02/14/2018 07:57:25;0100;Server@node2;Req;;Type 71 request received from Scheduler@node2.supernodexp.hpc, sock=16
02/14/2018 07:57:25;0100;Server@node2;Req;;Type 58 request received from Scheduler@node2.supernodexp.hpc, sock=16
02/14/2018 07:57:25;0100;Server@node2;Req;;Type 20 request received from Scheduler@node2.supernodexp.hpc, sock=16
02/14/2018 07:57:25;0100;Server@node2;Req;;Type 51 request received from Scheduler@node2.supernodexp.hpc, sock=16
02/14/2018 07:57:25;0100;Server@node2;Req;;Type 23 request received from Scheduler@node2.supernodexp.hpc, sock=16
02/14/2018 07:57:25;0008;Server@node2;Job;1121.node2.supernodexp.hpc;Job Run at request of Scheduler@node2.supernodexp.hpc on exec_vnode (node14:ncpus=24:mem=2097152kb)
02/14/2018 07:57:25;0001;Server@node2;Svr;Server@node2;Success (0) in req_runjob2, return value of svr_startjob is 0
02/14/2018 07:57:25;0100;Server@node2;Req;;Type 11 request received from Scheduler@node2.supernodexp.hpc, sock=16
02/14/2018 07:57:25;0008;Server@node2;Job;1126.node2.supernodexp.hpc;Job Modified at request of Scheduler@node2.supernodexp.hpc
02/14/2018 07:59:38;0080;Server@node2;Job;1039.node2.supernodexp.hpc;Obit received momhop:1 serverhop:1 state:4 substate:42
02/14/2018 07:59:40;0010;Server@node2;Job;1039.node2.supernodexp.hpc;Exit_status=0 resources_used.cpupercent=1069 resources_used.cput=01:07:30 resources_used.mem=1642712kb resources_used.ncpus=24 resources_used.vmem=14948508kb resources_used.walltime=00:03:21
02/14/2018 07:59:40;0100;Server@node2;Job;1039.node2.supernodexp.hpc;dequeuing from workq, state 5
02/14/2018 07:59:40;0040;Server@node2;Svr;node2.supernodexp.hpc;Scheduler sent command 2
02/14/2018 07:59:40;0040;Server@node2;Svr;node2.supernodexp.hpc;Scheduler sent command 0
02/14/2018 07:59:40;0100;Server@node2;Req;;Type 21 request received from Scheduler@node2.supernodexp.hpc, sock=16
02/14/2018 07:59:40;0100;Server@node2;Req;;Type 81 request received from Scheduler@node2.supernodexp.hpc, sock=16
02/14/2018 07:59:40;0100;Server@node2;Req;;Type 71 request received from Scheduler@node2.supernodexp.hpc, sock=16
02/14/2018 07:59:40;0100;Server@node2;Req;;Type 58 request received from Scheduler@node2.supernodexp.hpc, sock=16
02/14/2018 07:59:40;0100;Server@node2;Req;;Type 20 request received from Scheduler@node2.supernodexp.hpc, sock=16
02/14/2018 07:59:40;0100;Server@node2;Req;;Type 51 request received from Scheduler@node2.supernodexp.hpc, sock=16
02/14/2018 07:59:40;0100;Server@node2;Req;;Type 23 request received from Scheduler@node2.supernodexp.hpc, sock=16
02/14/2018 07:59:40;0008;Server@node2;Job;1126.node2.supernodexp.hpc;Job Run at request of Scheduler@node2.supernodexp.hpc on exec_vnode (node13:ncpus=24:mem=2097152kb)
02/14/2018 07:59:40;0001;Server@node2;Svr;Server@node2;Success (0) in req_runjob2, return value of svr_startjob is 0
02/14/2018 07:59:40;0100;Server@node2;Req;;Type 11 request received from Scheduler@node2.supernodexp.hpc, sock=16
02/14/2018 07:59:40;0008;Server@node2;Job;1130.node2.supernodexp.hpc;Job Modified at request of Scheduler@node2.supernodexp.hpc
02/14/2018 07:59:45;0080;Server@node2;Job;1049.node2.supernodexp.hpc;Obit received momhop:1 serverhop:1 state:4 substate:42
02/14/2018 07:59:47;0010;Server@node2;Job;1049.node2.supernodexp.hpc;Exit_status=0 resources_used.cpupercent=1226 resources_used.cput=01:08:22 resources_used.mem=1642388kb resources_used.ncpus=24 resources_used.vmem=14948260kb resources_used.walltime=00:03:02
02/14/2018 07:59:47;0100;Server@node2;Job;1049.node2.supernodexp.hpc;dequeuing from workq, state 5
02/14/2018 07:59:47;0040;Server@node2;Svr;node2.supernodexp.hpc;Scheduler sent command 2
02/14/2018 07:59:47;0040;Server@node2;Svr;node2.supernodexp.hpc;Scheduler sent command 0
02/14/2018 07:59:47;0100;Server@node2;Req;;Type 21 request received from Scheduler@node2.supernodexp.hpc, sock=16
02/14/2018 07:59:47;0100;Server@node2;Req;;Type 81 request received from Scheduler@node2.supernodexp.hpc, sock=16
02/14/2018 07:59:47;0100;Server@node2;Req;;Type 71 request received from Scheduler@node2.supernodexp.hpc, sock=16
02/14/2018 07:59:47;0100;Server@node2;Req;;Type 58 request received from Scheduler@node2.supernodexp.hpc, sock=16
02/14/2018 07:59:47;0100;Server@node2;Req;;Type 20 request received from Scheduler@node2.supernodexp.hpc, sock=16
02/14/2018 07:59:47;0100;Server@node2;Req;;Type 51 request received from Scheduler@node2.supernodexp.hpc, sock=16
02/14/2018 07:59:47;0100;Server@node2;Req;;Type 23 request received from Scheduler@node2.supernodexp.hpc, sock=16
02/14/2018 07:59:47;0008;Server@node2;Job;1130.node2.supernodexp.hpc;Job Run at request of Scheduler@node2.supernodexp.hpc on exec_vnode (node13:ncpus=24:mem=2097152kb)
02/14/2018 07:59:47;0001;Server@node2;Svr;Server@node2;Success (0) in req_runjob2, return value of svr_startjob is 0
02/14/2018 07:59:47;0100;Server@node2;Req;;Type 11 request received from Scheduler@node2.supernodexp.hpc, sock=16
02/14/2018 07:59:47;0008;Server@node2;Job;1143.node2.supernodexp.hpc;Job Modified at request of Scheduler@node2.supernodexp.hpc
02/14/2018 08:00:20;0080;Server@node2;Job;1091.node2.supernodexp.hpc;Obit received momhop:1 serverhop:1 state:4 substate:42
02/14/2018 08:00:21;0010;Server@node2;Job;1091.node2.supernodexp.hpc;Exit_status=0 resources_used.cpupercent=1087 resources_used.cput=01:07:54 resources_used.mem=1642760kb resources_used.ncpus=24 resources_used.vmem=15000464kb resources_used.walltime=00:03:04
02/14/2018 08:00:21;0100;Server@node2;Job;1091.node2.supernodexp.hpc;dequeuing from workq, state 5
02/14/2018 08:00:21;0040;Server@node2;Svr;node2.supernodexp.hpc;Scheduler sent command 2
02/14/2018 08:00:21;0040;Server@node2;Svr;node2.supernodexp.hpc;Scheduler sent command 0
02/14/2018 08:00:21;0100;Server@node2;Req;;Type 21 request received from Scheduler@node2.supernodexp.hpc, sock=16
02/14/2018 08:00:21;0100;Server@node2;Req;;Type 81 request received from Scheduler@node2.supernodexp.hpc, sock=16
02/14/2018 08:00:21;0100;Server@node2;Req;;Type 71 request received from Scheduler@node2.supernodexp.hpc, sock=16
02/14/2018 08:00:21;0100;Server@node2;Req;;Type 58 request received from Scheduler@node2.supernodexp.hpc, sock=16
02/14/2018 08:00:21;0100;Server@node2;Req;;Type 20 request received from Scheduler@node2.supernodexp.hpc, sock=16
02/14/2018 08:00:21;0100;Server@node2;Req;;Type 51 request received from Scheduler@node2.supernodexp.hpc, sock=16
02/14/2018 08:00:21;0100;Server@node2;Req;;Type 23 request received from Scheduler@node2.supernodexp.hpc, sock=16
02/14/2018 08:00:21;0008;Server@node2;Job;1143.node2.supernodexp.hpc;Job Run at request of Scheduler@node2.supernodexp.hpc on exec_vnode (node14:ncpus=24:mem=2097152kb)
02/14/2018 08:00:21;0001;Server@node2;Svr;Server@node2;Success (0) in req_runjob2, return value of svr_startjob is 0
02/14/2018 08:00:21;0100;Server@node2;Req;;Type 11 request received from Scheduler@node2.supernodexp.hpc, sock=16
02/14/2018 08:00:21;0008;Server@node2;Job;1144.node2.supernodexp.hpc;Job Modified at request of Scheduler@node2.supernodexp.hpc
02/14/2018 08:00:24;0080;Server@node2;Job;1121.node2.supernodexp.hpc;Obit received momhop:1 serverhop:1 state:4 substate:42
02/14/2018 08:00:25;0010;Server@node2;Job;1121.node2.supernodexp.hpc;Exit_status=0 resources_used.cpupercent=1347 resources_used.cput=01:07:55 resources_used.mem=1642176kb resources_used.ncpus=24 resources_used.vmem=15000280kb resources_used.walltime=00:02:59
02/14/2018 08:00:25;0100;Server@node2;Job;1121.node2.supernodexp.hpc;dequeuing from workq, state 5
02/14/2018 08:00:26;0040;Server@node2;Svr;node2.supernodexp.hpc;Scheduler sent command 2
02/14/2018 08:00:26;0040;Server@node2;Svr;node2.supernodexp.hpc;Scheduler sent command 0
02/14/2018 08:00:26;0100;Server@node2;Req;;Type 21 request received from Scheduler@node2.supernodexp.hpc, sock=16
02/14/2018 08:00:26;0100;Server@node2;Req;;Type 81 request received from Scheduler@node2.supernodexp.hpc, sock=16
02/14/2018 08:00:26;0100;Server@node2;Req;;Type 71 request received from Scheduler@node2.supernodexp.hpc, sock=16
02/14/2018 08:00:26;0100;Server@node2;Req;;Type 58 request received from Scheduler@node2.supernodexp.hpc, sock=16
02/14/2018 08:00:26;0100;Server@node2;Req;;Type 20 request received from Scheduler@node2.supernodexp.hpc, sock=16
02/14/2018 08:00:26;0100;Server@node2;Req;;Type 51 request received from Scheduler@node2.supernodexp.hpc, sock=16
02/14/2018 08:00:26;0100;Server@node2;Req;;Type 23 request received from Scheduler@node2.supernodexp.hpc, sock=16
02/14/2018 08:00:26;0008;Server@node2;Job;1144.node2.supernodexp.hpc;Job Run at request of Scheduler@node2.supernodexp.hpc on exec_vnode (node14:ncpus=24:mem=2097152kb)
02/14/2018 08:00:26;0001;Server@node2;Svr;Server@node2;Success (0) in req_runjob2, return value of svr_startjob is 0
02/14/2018 08:00:26;0100;Server@node2;Req;;Type 11 request received from Scheduler@node2.supernodexp.hpc, sock=16
02/14/2018 08:00:26;0008;Server@node2;Job;1153.node2.supernodexp.hpc;Job Modified at request of Scheduler@node2.supernodexp.hpc
02/14/2018 08:00:29;0080;Server@node2;Job;1144.node2.supernodexp.hpc;Obit received momhop:1 serverhop:1 state:4 substate:42
02/14/2018 08:00:30;0010;Server@node2;Job;1144.node2.supernodexp.hpc;Exit_status=1 resources_used.cpupercent=66 resources_used.cput=00:00:02 resources_used.mem=0kb resources_used.ncpus=24 resources_used.vmem=0kb resources_used.walltime=00:00:03
02/14/2018 08:00:30;0100;Server@node2;Job;1144.node2.supernodexp.hpc;dequeuing from workq, state 5
02/14/2018 08:00:30;0040;Server@node2;Svr;node2.supernodexp.hpc;Scheduler sent command 2
02/14/2018 08:00:30;0040;Server@node2;Svr;node2.supernodexp.hpc;Scheduler sent command 0
02/14/2018 08:00:30;0100;Server@node2;Req;;Type 21 request received from Scheduler@node2.supernodexp.hpc, sock=16
02/14/2018 08:00:30;0100;Server@node2;Req;;Type 81 request received from Scheduler@node2.supernodexp.hpc, sock=16
02/14/2018 08:00:30;0100;Server@node2;Req;;Type 71 request received from Scheduler@node2.supernodexp.hpc, sock=16
02/14/2018 08:00:30;0100;Server@node2;Req;;Type 58 request received from Scheduler@node2.supernodexp.hpc, sock=16
02/14/2018 08:00:30;0100;Server@node2;Req;;Type 20 request received from Scheduler@node2.supernodexp.hpc, sock=16
02/14/2018 08:00:30;0100;Server@node2;Req;;Type 51 request received from Scheduler@node2.supernodexp.hpc, sock=16
02/14/2018 08:00:30;0100;Server@node2;Req;;Type 23 request received from Scheduler@node2.supernodexp.hpc, sock=16
02/14/2018 08:00:30;0008;Server@node2;Job;1153.node2.supernodexp.hpc;Job Run at request of Scheduler@node2.supernodexp.hpc on exec_vnode (node14:ncpus=24:mem=2097152kb)
02/14/2018 08:00:30;0001;Server@node2;Svr;Server@node2;Success (0) in req_runjob2, return value of svr_startjob is 0
02/14/2018 08:00:30;0100;Server@node2;Req;;Type 11 request received from Scheduler@node2.supernodexp.hpc, sock=16
02/14/2018 08:00:30;0008;Server@node2;Job;1158.node2.supernodexp.hpc;Job Modified at request of Scheduler@node2.supernodexp.hpc
02/14/2018 08:00:32;0080;Server@node2;Job;1143.node2.supernodexp.hpc;Obit received momhop:1 serverhop:1 state:4 substate:42
02/14/2018 08:00:33;0010;Server@node2;Job;1143.node2.supernodexp.hpc;Exit_status=1 resources_used.cpupercent=66 resources_used.cput=00:00:06 resources_used.mem=41872kb resources_used.ncpus=24 resources_used.vmem=816200kb resources_used.walltime=00:00:11
02/14/2018 08:00:33;0100;Server@node2;Job;1143.node2.supernodexp.hpc;dequeuing from workq, state 5
02/14/2018 08:00:33;0040;Server@node2;Svr;node2.supernodexp.hpc;Scheduler sent command 2
02/14/2018 08:00:33;0040;Server@node2;Svr;node2.supernodexp.hpc;Scheduler sent command 0
02/14/2018 08:00:33;0100;Server@node2;Req;;Type 21 request received from Scheduler@node2.supernodexp.hpc, sock=16
02/14/2018 08:00:33;0100;Server@node2;Req;;Type 81 request received from Scheduler@node2.supernodexp.hpc, sock=16
02/14/2018 08:00:33;0100;Server@node2;Req;;Type 71 request received from Scheduler@node2.supernodexp.hpc, sock=16
02/14/2018 08:00:33;0100;Server@node2;Req;;Type 58 request received from Scheduler@node2.supernodexp.hpc, sock=16
02/14/2018 08:00:33;0100;Server@node2;Req;;Type 20 request received from Scheduler@node2.supernodexp.hpc, sock=16
02/14/2018 08:00:33;0100;Server@node2;Req;;Type 51 request received from Scheduler@node2.supernodexp.hpc, sock=16
02/14/2018 08:00:33;0100;Server@node2;Req;;Type 23 request received from Scheduler@node2.supernodexp.hpc, sock=16
02/14/2018 08:00:33;0008;Server@node2;Job;1158.node2.supernodexp.hpc;Job Run at request of Scheduler@node2.supernodexp.hpc on exec_vnode (node14:ncpus=24:mem=2097152kb)
02/14/2018 08:00:33;0001;Server@node2;Svr;Server@node2;Success (0) in req_runjob2, return value of svr_startjob is 0
02/14/2018 08:00:33;0100;Server@node2;Req;;Type 11 request received from Scheduler@node2.supernodexp.hpc, sock=16
02/14/2018 08:00:33;0008;Server@node2;Job;1165.node2.supernodexp.hpc;Job Modified at request of Scheduler@node2.supernodexp.hpc
02/14/2018 08:02:49;0080;Server@node2;Job;1126.node2.supernodexp.hpc;Obit received momhop:1 serverhop:1 state:4 substate:42
02/14/2018 08:02:51;0010;Server@node2;Job;1126.node2.supernodexp.hpc;Exit_status=0 resources_used.cpupercent=1101 resources_used.cput=01:09:28 resources_used.mem=1642496kb resources_used.ncpus=24 resources_used.vmem=14948244kb resources_used.walltime=00:03:09
02/14/2018 08:02:51;0100;Server@node2;Job;1126.node2.supernodexp.hpc;dequeuing from workq, state 5
02/14/2018 08:02:51;0040;Server@node2;Svr;node2.supernodexp.hpc;Scheduler sent command 2
02/14/2018 08:02:51;0040;Server@node2;Svr;node2.supernodexp.hpc;Scheduler sent command 0
02/14/2018 08:02:51;0100;Server@node2;Req;;Type 21 request received from Scheduler@node2.supernodexp.hpc, sock=16
02/14/2018 08:02:51;0100;Server@node2;Req;;Type 81 request received from Scheduler@node2.supernodexp.hpc, sock=16
02/14/2018 08:02:51;0100;Server@node2;Req;;Type 71 request received from Scheduler@node2.supernodexp.hpc, sock=16
02/14/2018 08:02:51;0100;Server@node2;Req;;Type 58 request received from Scheduler@node2.supernodexp.hpc, sock=16
02/14/2018 08:02:51;0100;Server@node2;Req;;Type 20 request received from Scheduler@node2.supernodexp.hpc, sock=16
02/14/2018 08:02:51;0100;Server@node2;Req;;Type 51 request received from Scheduler@node2.supernodexp.hpc, sock=16
02/14/2018 08:02:51;0100;Server@node2;Req;;Type 23 request received from Scheduler@node2.supernodexp.hpc, sock=16
02/14/2018 08:02:51;0008;Server@node2;Job;1165.node2.supernodexp.hpc;Job Run at request of Scheduler@node2.supernodexp.hpc on exec_vnode (node13:ncpus=24:mem=2097152kb)
02/14/2018 08:02:51;0001;Server@node2;Svr;Server@node2;Success (0) in req_runjob2, return value of svr_startjob is 0
02/14/2018 08:02:51;0100;Server@node2;Req;;Type 11 request received from Scheduler@node2.supernodexp.hpc, sock=16
02/14/2018 08:02:51;0008;Server@node2;Job;1166.node2.supernodexp.hpc;Job Modified at request of Scheduler@node2.supernodexp.hpc
02/14/2018 08:02:52;0080;Server@node2;Job;1130.node2.supernodexp.hpc;Obit received momhop:1 serverhop:1 state:4 substate:42
02/14/2018 08:02:55;0010;Server@node2;Job;1130.node2.supernodexp.hpc;Exit_status=0 resources_used.cpupercent=1117 resources_used.cput=01:08:57 resources_used.mem=1642676kb resources_used.ncpus=24 resources_used.vmem=14948404kb resources_used.walltime=00:03:05
02/14/2018 08:02:55;0100;Server@node2;Job;1130.node2.supernodexp.hpc;dequeuing from workq, state 5
02/14/2018 08:02:55;0040;Server@node2;Svr;node2.supernodexp.hpc;Scheduler sent command 2
02/14/2018 08:02:55;0040;Server@node2;Svr;node2.supernodexp.hpc;Scheduler sent command 0
02/14/2018 08:02:55;0100;Server@node2;Req;;Type 21 request received from Scheduler@node2.supernodexp.hpc, sock=16
02/14/2018 08:02:55;0100;Server@node2;Req;;Type 81 request received from Scheduler@node2.supernodexp.hpc, sock=16
02/14/2018 08:02:55;0100;Server@node2;Req;;Type 71 request received from Scheduler@node2.supernodexp.hpc, sock=16
02/14/2018 08:02:55;0100;Server@node2;Req;;Type 58 request received from Scheduler@node2.supernodexp.hpc, sock=16
02/14/2018 08:02:55;0100;Server@node2;Req;;Type 20 request received from Scheduler@node2.supernodexp.hpc, sock=16
02/14/2018 08:02:55;0100;Server@node2;Req;;Type 51 request received from Scheduler@node2.supernodexp.hpc, sock=16
02/14/2018 08:02:55;0100;Server@node2;Req;;Type 23 request received from Scheduler@node2.supernodexp.hpc, sock=16
02/14/2018 08:02:55;0008;Server@node2;Job;1166.node2.supernodexp.hpc;Job Run at request of Scheduler@node2.supernodexp.hpc on exec_vnode (node13:ncpus=24:mem=2097152kb)
02/14/2018 08:02:56;0001;Server@node2;Svr;Server@node2;Success (0) in req_runjob2, return value of svr_startjob is 0
02/14/2018 08:02:56;0100;Server@node2;Req;;Type 11 request received from Scheduler@node2.supernodexp.hpc, sock=16
02/14/2018 08:02:56;0008;Server@node2;Job;1171.node2.supernodexp.hpc;Job Modified at request of Scheduler@node2.supernodexp.hpc
02/14/2018 08:03:29;0080;Server@node2;Job;1153.node2.supernodexp.hpc;Obit received momhop:1 serverhop:1 state:4 substate:42
02/14/2018 08:03:30;0010;Server@node2;Job;1153.node2.supernodexp.hpc;Exit_status=0 resources_used.cpupercent=1119 resources_used.cput=01:07:50 resources_used.mem=1642148kb resources_used.ncpus=24 resources_used.vmem=15000516kb resources_used.walltime=00:02:59
02/14/2018 08:03:30;0100;Server@node2;Job;1153.node2.supernodexp.hpc;dequeuing from workq, state 5
02/14/2018 08:03:31;0040;Server@node2;Svr;node2.supernodexp.hpc;Scheduler sent command 2
02/14/2018 08:03:31;0040;Server@node2;Svr;node2.supernodexp.hpc;Scheduler sent command 0
02/14/2018 08:03:31;0100;Server@node2;Req;;Type 21 request received from Scheduler@node2.supernodexp.hpc, sock=16
02/14/2018 08:03:31;0100;Server@node2;Req;;Type 81 request received from Scheduler@node2.supernodexp.hpc, sock=16
02/14/2018 08:03:31;0100;Server@node2;Req;;Type 71 request received from Scheduler@node2.supernodexp.hpc, sock=16
02/14/2018 08:03:31;0100;Server@node2;Req;;Type 58 request received from Scheduler@node2.supernodexp.hpc, sock=16
02/14/2018 08:03:31;0100;Server@node2;Req;;Type 20 request received from Scheduler@node2.supernodexp.hpc, sock=16
02/14/2018 08:03:31;0100;Server@node2;Req;;Type 51 request received from Scheduler@node2.supernodexp.hpc, sock=16
02/14/2018 08:03:31;0100;Server@node2;Req;;Type 23 request received from Scheduler@node2.supernodexp.hpc, sock=16
02/14/2018 08:03:31;0008;Server@node2;Job;1171.node2.supernodexp.hpc;Job Run at request of Scheduler@node2.supernodexp.hpc on exec_vnode (node14:ncpus=24:mem=2097152kb)
02/14/2018 08:03:31;0001;Server@node2;Svr;Server@node2;Success (0) in req_runjob2, return value of svr_startjob is 0
02/14/2018 08:03:31;0100;Server@node2;Req;;Type 11 request received from Scheduler@node2.supernodexp.hpc, sock=16
02/14/2018 08:03:31;0008;Server@node2;Job;1172.node2.supernodexp.hpc;Job Modified at request of Scheduler@node2.supernodexp.hpc
02/14/2018 08:03:34;0080;Server@node2;Job;1158.node2.supernodexp.hpc;Obit received momhop:1 serverhop:1 state:4 substate:42
02/14/2018 08:03:35;0010;Server@node2;Job;1158.node2.supernodexp.hpc;Exit_status=0 resources_used.cpupercent=1223 resources_used.cput=01:07:50 resources_used.mem=1641560kb resources_used.ncpus=24 resources_used.vmem=15000340kb resources_used.walltime=00:03:01
02/14/2018 08:03:35;0100;Server@node2;Job;1158.node2.supernodexp.hpc;dequeuing from workq, state 5
02/14/2018 08:03:35;0040;Server@node2;Svr;node2.supernodexp.hpc;Scheduler sent command 2
02/14/2018 08:03:35;0040;Server@node2;Svr;node2.supernodexp.hpc;Scheduler sent command 0
02/14/2018 08:03:35;0100;Server@node2;Req;;Type 21 request received from Scheduler@node2.supernodexp.hpc, sock=16
02/14/2018 08:03:35;0100;Server@node2;Req;;Type 81 request received from Scheduler@node2.supernodexp.hpc, sock=16
02/14/2018 08:03:35;0100;Server@node2;Req;;Type 71 request received from Scheduler@node2.supernodexp.hpc, sock=16
02/14/2018 08:03:35;0100;Server@node2;Req;;Type 58 request received from Scheduler@node2.supernodexp.hpc, sock=16
02/14/2018 08:03:35;0100;Server@node2;Req;;Type 20 request received from Scheduler@node2.supernodexp.hpc, sock=16
02/14/2018 08:03:35;0100;Server@node2;Req;;Type 51 request received from Scheduler@node2.supernodexp.hpc, sock=16
02/14/2018 08:03:35;0100;Server@node2;Req;;Type 23 request received from Scheduler@node2.supernodexp.hpc, sock=16
02/14/2018 08:03:35;0008;Server@node2;Job;1172.node2.supernodexp.hpc;Job Run at request of Scheduler@node2.supernodexp.hpc on exec_vnode (node14:ncpus=24:mem=2097152kb)
02/14/2018 08:03:35;0001;Server@node2;Svr;Server@node2;Success (0) in req_runjob2, return value of svr_startjob is 0
02/14/2018 08:03:35;0100;Server@node2;Req;;Type 11 request received from Scheduler@node2.supernodexp.hpc, sock=16
02/14/2018 08:03:35;0008;Server@node2;Job;1183.node2.supernodexp.hpc;Job Modified at request of Scheduler@node2.supernodexp.hpc
02/14/2018 08:05:58;0080;Server@node2;Job;1165.node2.supernodexp.hpc;Obit received momhop:1 serverhop:1 state:4 substate:42
02/14/2018 08:05:59;0010;Server@node2;Job;1165.node2.supernodexp.hpc;Exit_status=0 resources_used.cpupercent=1107 resources_used.cput=01:09:07 resources_used.mem=1642448kb resources_used.ncpus=24 resources_used.vmem=14948388kb resources_used.walltime=00:03:07
02/14/2018 08:05:59;0100;Server@node2;Job;1165.node2.supernodexp.hpc;dequeuing from workq, state 5
02/14/2018 08:05:59;0040;Server@node2;Svr;node2.supernodexp.hpc;Scheduler sent command 2
02/14/2018 08:05:59;0040;Server@node2;Svr;node2.supernodexp.hpc;Scheduler sent command 0
02/14/2018 08:05:59;0100;Server@node2;Req;;Type 21 request received from Scheduler@node2.supernodexp.hpc, sock=16
02/14/2018 08:05:59;0100;Server@node2;Req;;Type 81 request received from Scheduler@node2.supernodexp.hpc, sock=16
02/14/2018 08:05:59;0100;Server@node2;Req;;Type 71 request received from Scheduler@node2.supernodexp.hpc, sock=16
02/14/2018 08:05:59;0100;Server@node2;Req;;Type 58 request received from Scheduler@node2.supernodexp.hpc, sock=16
02/14/2018 08:05:59;0100;Server@node2;Req;;Type 20 request received from Scheduler@node2.supernodexp.hpc, sock=16
02/14/2018 08:05:59;0100;Server@node2;Req;;Type 51 request received from Scheduler@node2.supernodexp.hpc, sock=16
02/14/2018 08:05:59;0100;Server@node2;Req;;Type 23 request received from Scheduler@node2.supernodexp.hpc, sock=16
02/14/2018 08:05:59;0008;Server@node2;Job;1183.node2.supernodexp.hpc;Job Run at request of Scheduler@node2.supernodexp.hpc on exec_vnode (node13:ncpus=24:mem=2097152kb)
02/14/2018 08:05:59;0001;Server@node2;Svr;Server@node2;Success (0) in req_runjob2, return value of svr_startjob is 0
02/14/2018 08:05:59;0100;Server@node2;Req;;Type 11 request received from Scheduler@node2.supernodexp.hpc, sock=16
02/14/2018 08:05:59;0008;Server@node2;Job;1187.node2.supernodexp.hpc;Job Modified at request of Scheduler@node2.supernodexp.hpc
02/14/2018 08:06:01;0080;Server@node2;Job;1166.node2.supernodexp.hpc;Obit received momhop:1 serverhop:1 state:4 substate:42
02/14/2018 08:06:02;0010;Server@node2;Job;1166.node2.supernodexp.hpc;Exit_status=0 resources_used.cpupercent=1227 resources_used.cput=01:08:28 resources_used.mem=1642248kb resources_used.ncpus=24 resources_used.vmem=14948140kb resources_used.walltime=00:03:06
02/14/2018 08:06:02;0100;Server@node2;Job;1166.node2.supernodexp.hpc;dequeuing from workq, state 5
02/14/2018 08:06:02;0040;Server@node2;Svr;node2.supernodexp.hpc;Scheduler sent command 2
02/14/2018 08:06:02;0040;Server@node2;Svr;node2.supernodexp.hpc;Scheduler sent command 0
02/14/2018 08:06:02;0100;Server@node2;Req;;Type 21 request received from Scheduler@node2.supernodexp.hpc, sock=16
02/14/2018 08:06:02;0100;Server@node2;Req;;Type 81 request received from Scheduler@node2.supernodexp.hpc, sock=16
02/14/2018 08:06:02;0100;Server@node2;Req;;Type 71 request received from Scheduler@node2.supernodexp.hpc, sock=16
02/14/2018 08:06:02;0100;Server@node2;Req;;Type 58 request received from Scheduler@node2.supernodexp.hpc, sock=16
02/14/2018 08:06:02;0100;Server@node2;Req;;Type 20 request received from Scheduler@node2.supernodexp.hpc, sock=16
02/14/2018 08:06:02;0100;Server@node2;Req;;Type 51 request received from Scheduler@node2.supernodexp.hpc, sock=16
02/14/2018 08:06:02;0100;Server@node2;Req;;Type 23 request received from Scheduler@node2.supernodexp.hpc, sock=16
02/14/2018 08:06:02;0008;Server@node2;Job;1187.node2.supernodexp.hpc;Job Run at request of Scheduler@node2.supernodexp.hpc on exec_vnode (node13:ncpus=24:mem=2097152kb)
02/14/2018 08:06:02;0001;Server@node2;Svr;Server@node2;Success (0) in req_runjob2, return value of svr_startjob is 0
02/14/2018 08:06:02;0100;Server@node2;Req;;Type 11 request received from Scheduler@node2.supernodexp.hpc, sock=16
02/14/2018 08:06:02;0008;Server@node2;Job;1006.node2.supernodexp.hpc;Job Modified at request of Scheduler@node2.supernodexp.hpc
02/14/2018 08:06:35;0080;Server@node2;Job;1172.node2.supernodexp.hpc;Obit received momhop:1 serverhop:1 state:4 substate:42
02/14/2018 08:06:35;0080;Server@node2;Job;1171.node2.supernodexp.hpc;Obit received momhop:1 serverhop:1 state:4 substate:42
02/14/2018 08:06:36;0010;Server@node2;Job;1172.node2.supernodexp.hpc;Exit_status=0 resources_used.cpupercent=1609 resources_used.cput=01:08:29 resources_used.mem=1642828kb resources_used.ncpus=24 resources_used.vmem=15000408kb resources_used.walltime=00:02:59
02/14/2018 08:06:36;0100;Server@node2;Job;1172.node2.supernodexp.hpc;dequeuing from workq, state 5
02/14/2018 08:06:36;0010;Server@node2;Job;1171.node2.supernodexp.hpc;Exit_status=0 resources_used.cpupercent=1130 resources_used.cput=01:08:46 resources_used.mem=1644124kb resources_used.ncpus=24 resources_used.vmem=15000488kb resources_used.walltime=00:03:04
02/14/2018 08:06:36;0100;Server@node2;Job;1171.node2.supernodexp.hpc;dequeuing from workq, state 5
02/14/2018 08:06:36;0040;Server@node2;Svr;node2.supernodexp.hpc;Scheduler sent command 2
02/14/2018 08:06:36;0040;Server@node2;Svr;node2.supernodexp.hpc;Scheduler sent command 0
02/14/2018 08:06:36;0100;Server@node2;Req;;Type 21 request received from Scheduler@node2.supernodexp.hpc, sock=16
02/14/2018 08:06:36;0100;Server@node2;Req;;Type 81 request received from Scheduler@node2.supernodexp.hpc, sock=16
02/14/2018 08:06:36;0100;Server@node2;Req;;Type 71 request received from Scheduler@node2.supernodexp.hpc, sock=16
02/14/2018 08:06:36;0100;Server@node2;Req;;Type 58 request received from Scheduler@node2.supernodexp.hpc, sock=16
02/14/2018 08:06:36;0100;Server@node2;Req;;Type 20 request received from Scheduler@node2.supernodexp.hpc, sock=16
02/14/2018 08:06:36;0100;Server@node2;Req;;Type 51 request received from Scheduler@node2.supernodexp.hpc, sock=16
02/14/2018 08:06:36;0100;Server@node2;Req;;Type 23 request received from Scheduler@node2.supernodexp.hpc, sock=16
02/14/2018 08:06:36;0008;Server@node2;Job;1006.node2.supernodexp.hpc;Job Run at request of Scheduler@node2.supernodexp.hpc on exec_vnode (node14:ncpus=24:mem=4194304kb)+(node14:ncpus=24:mem=4194304kb)
02/14/2018 08:06:36;0001;Server@node2;Svr;Server@node2;Success (0) in req_runjob2, return value of svr_startjob is 0
02/14/2018 08:06:36;0100;Server@node2;Req;;Type 11 request received from Scheduler@node2.supernodexp.hpc, sock=16
02/14/2018 08:06:36;0008;Server@node2;Job;1008.node2.supernodexp.hpc;Job Modified at request of Scheduler@node2.supernodexp.hpc
02/14/2018 08:09:08;0080;Server@node2;Job;1187.node2.supernodexp.hpc;Obit received momhop:1 serverhop:1 state:4 substate:42
02/14/2018 08:09:08;0080;Server@node2;Job;1183.node2.supernodexp.hpc;Obit received momhop:1 serverhop:1 state:4 substate:42
02/14/2018 08:09:10;0010;Server@node2;Job;1187.node2.supernodexp.hpc;Exit_status=0 resources_used.cpupercent=1228 resources_used.cput=01:09:12 resources_used.mem=1642280kb resources_used.ncpus=24 resources_used.vmem=14948348kb resources_used.walltime=00:03:05
02/14/2018 08:09:10;0100;Server@node2;Job;1187.node2.supernodexp.hpc;dequeuing from workq, state 5
02/14/2018 08:09:10;0040;Server@node2;Svr;node2.supernodexp.hpc;Scheduler sent command 2
02/14/2018 08:09:10;0040;Server@node2;Svr;node2.supernodexp.hpc;Scheduler sent command 0
02/14/2018 08:09:10;0100;Server@node2;Req;;Type 21 request received from Scheduler@node2.supernodexp.hpc, sock=16
02/14/2018 08:09:10;0100;Server@node2;Req;;Type 81 request received from Scheduler@node2.supernodexp.hpc, sock=16
02/14/2018 08:09:10;0100;Server@node2;Req;;Type 71 request received from Scheduler@node2.supernodexp.hpc, sock=16
02/14/2018 08:09:10;0100;Server@node2;Req;;Type 58 request received from Scheduler@node2.supernodexp.hpc, sock=16
02/14/2018 08:09:10;0100;Server@node2;Req;;Type 20 request received from Scheduler@node2.supernodexp.hpc, sock=16
02/14/2018 08:09:10;0100;Server@node2;Req;;Type 51 request received from Scheduler@node2.supernodexp.hpc, sock=16
02/14/2018 08:09:10;0100;Server@node2;Req;;Type 11 request received from Scheduler@node2.supernodexp.hpc, sock=16
02/14/2018 08:09:10;0008;Server@node2;Job;1008.node2.supernodexp.hpc;Job Modified at request of Scheduler@node2.supernodexp.hpc
02/14/2018 08:09:15;0010;Server@node2;Job;1183.node2.supernodexp.hpc;Exit_status=0 resources_used.cpupercent=1125 resources_used.cput=01:10:33 resources_used.mem=1642728kb resources_used.ncpus=24 resources_used.vmem=14949604kb resources_used.walltime=00:03:09
02/14/2018 08:09:15;0100;Server@node2;Job;1183.node2.supernodexp.hpc;dequeuing from workq, state 5
02/14/2018 08:09:15;0040;Server@node2;Svr;node2.supernodexp.hpc;Scheduler sent command 2
02/14/2018 08:09:15;0040;Server@node2;Svr;node2.supernodexp.hpc;Scheduler sent command 0
02/14/2018 08:09:15;0100;Server@node2;Req;;Type 21 request received from Scheduler@node2.supernodexp.hpc, sock=16
02/14/2018 08:09:15;0100;Server@node2;Req;;Type 81 request received from Scheduler@node2.supernodexp.hpc, sock=16
02/14/2018 08:09:15;0100;Server@node2;Req;;Type 71 request received from Scheduler@node2.supernodexp.hpc, sock=16
02/14/2018 08:09:15;0100;Server@node2;Req;;Type 58 request received from Scheduler@node2.supernodexp.hpc, sock=16
02/14/2018 08:09:15;0100;Server@node2;Req;;Type 20 request received from Scheduler@node2.supernodexp.hpc, sock=16
02/14/2018 08:09:15;0100;Server@node2;Req;;Type 51 request received from Scheduler@node2.supernodexp.hpc, sock=16
02/14/2018 08:09:15;0100;Server@node2;Req;;Type 23 request received from Scheduler@node2.supernodexp.hpc, sock=16
02/14/2018 08:09:15;0008;Server@node2;Job;1008.node2.supernodexp.hpc;Job Run at request of Scheduler@node2.supernodexp.hpc on exec_vnode (node13:ncpus=24:mem=4194304kb)+(node13:ncpus=24:mem=4194304kb)
02/14/2018 08:09:15;0001;Server@node2;Svr;Server@node2;Success (0) in req_runjob2, return value of svr_startjob is 0
02/14/2018 08:09:15;0100;Server@node2;Req;;Type 11 request received from Scheduler@node2.supernodexp.hpc, sock=16
