02/13/2018 17:55:26;0100;Server@node2;Job;801.node2.supernodexp.hpc;enqueuing into workq, state 1 hop 1
02/13/2018 17:55:26;0008;Server@node2;Job;801.node2.supernodexp.hpc;Job Queued at request of ctminh@node2.supernodexp.hpc, owner = ctminh@node2.supernodexp.hpc, job name = vectorization, queue = workq
02/13/2018 17:55:26;0040;Server@node2;Svr;node2.supernodexp.hpc;Scheduler sent command 1
02/13/2018 17:55:26;0040;Server@node2;Svr;node2.supernodexp.hpc;Scheduler sent command 0
02/13/2018 17:55:26;0100;Server@node2;Req;;Type 21 request received from Scheduler@node2.supernodexp.hpc, sock=20
02/13/2018 17:55:26;0100;Server@node2;Req;;Type 81 request received from Scheduler@node2.supernodexp.hpc, sock=20
02/13/2018 17:55:26;0100;Server@node2;Req;;Type 71 request received from Scheduler@node2.supernodexp.hpc, sock=20
02/13/2018 17:55:26;0100;Server@node2;Req;;Type 58 request received from Scheduler@node2.supernodexp.hpc, sock=20
02/13/2018 17:55:26;0100;Server@node2;Req;;Type 20 request received from Scheduler@node2.supernodexp.hpc, sock=20
02/13/2018 17:55:26;0100;Server@node2;Req;;Type 51 request received from Scheduler@node2.supernodexp.hpc, sock=20
02/13/2018 17:55:26;0100;Server@node2;Req;;Type 1 request received from ctminh@node2.supernodexp.hpc, sock=16
02/13/2018 17:55:26;0100;Server@node2;Req;;Type 3 request received from ctminh@node2.supernodexp.hpc, sock=16
02/13/2018 17:55:26;0100;Server@node2;Req;;Type 5 request received from ctminh@node2.supernodexp.hpc, sock=16
02/13/2018 17:55:26;0100;Server@node2;Job;802.node2.supernodexp.hpc;enqueuing into workq, state 1 hop 1
02/13/2018 17:55:26;0008;Server@node2;Job;802.node2.supernodexp.hpc;Job Queued at request of ctminh@node2.supernodexp.hpc, owner = ctminh@node2.supernodexp.hpc, job name = vast1, queue = workq
02/13/2018 17:55:26;0100;Server@node2;Req;;Type 23 request received from Scheduler@node2.supernodexp.hpc, sock=20
02/13/2018 17:55:26;0008;Server@node2;Job;801.node2.supernodexp.hpc;Job Run at request of Scheduler@node2.supernodexp.hpc on exec_vnode (node13:ncpus=12:mem=1048576kb)
02/13/2018 17:55:26;0001;Server@node2;Svr;Server@node2;Success (0) in req_runjob2, return value of svr_startjob is 0
02/13/2018 17:55:26;0040;Server@node2;Svr;node2.supernodexp.hpc;Scheduler sent command 1
02/13/2018 17:55:26;0040;Server@node2;Svr;node2.supernodexp.hpc;Scheduler sent command 0
02/13/2018 17:55:26;0100;Server@node2;Req;;Type 21 request received from Scheduler@node2.supernodexp.hpc, sock=20
02/13/2018 17:55:26;0100;Server@node2;Req;;Type 81 request received from Scheduler@node2.supernodexp.hpc, sock=20
02/13/2018 17:55:26;0100;Server@node2;Req;;Type 71 request received from Scheduler@node2.supernodexp.hpc, sock=20
02/13/2018 17:55:26;0100;Server@node2;Req;;Type 58 request received from Scheduler@node2.supernodexp.hpc, sock=20
02/13/2018 17:55:26;0100;Server@node2;Req;;Type 20 request received from Scheduler@node2.supernodexp.hpc, sock=20
02/13/2018 17:55:26;0100;Server@node2;Req;;Type 51 request received from Scheduler@node2.supernodexp.hpc, sock=20
02/13/2018 17:55:26;0100;Server@node2;Req;;Type 23 request received from Scheduler@node2.supernodexp.hpc, sock=20
02/13/2018 17:55:26;0008;Server@node2;Job;802.node2.supernodexp.hpc;Job Run at request of Scheduler@node2.supernodexp.hpc on exec_vnode (node14:ncpus=48:mem=5242880kb)
02/13/2018 17:55:26;0001;Server@node2;Svr;Server@node2;Success (0) in req_runjob2, return value of svr_startjob is 0
02/13/2018 17:55:32;0080;Server@node2;Job;801.node2.supernodexp.hpc;Obit received momhop:1 serverhop:1 state:4 substate:42
02/13/2018 17:55:34;0010;Server@node2;Job;801.node2.supernodexp.hpc;Exit_status=0 resources_used.cpupercent=1200 resources_used.cput=00:01:12 resources_used.mem=0kb resources_used.ncpus=12 resources_used.vmem=0kb resources_used.walltime=00:00:07
02/13/2018 17:55:34;0100;Server@node2;Job;801.node2.supernodexp.hpc;dequeuing from workq, state 5
02/13/2018 17:55:34;0040;Server@node2;Svr;node2.supernodexp.hpc;Scheduler sent command 2
02/13/2018 17:55:34;0040;Server@node2;Svr;node2.supernodexp.hpc;Scheduler sent command 0
02/13/2018 17:55:34;0100;Server@node2;Req;;Type 21 request received from Scheduler@node2.supernodexp.hpc, sock=20
02/13/2018 17:55:34;0100;Server@node2;Req;;Type 81 request received from Scheduler@node2.supernodexp.hpc, sock=20
02/13/2018 17:55:34;0100;Server@node2;Req;;Type 71 request received from Scheduler@node2.supernodexp.hpc, sock=20
02/13/2018 17:55:34;0100;Server@node2;Req;;Type 58 request received from Scheduler@node2.supernodexp.hpc, sock=20
02/13/2018 17:55:34;0100;Server@node2;Req;;Type 20 request received from Scheduler@node2.supernodexp.hpc, sock=20
02/13/2018 17:55:34;0100;Server@node2;Req;;Type 51 request received from Scheduler@node2.supernodexp.hpc, sock=20
02/13/2018 17:56:10;0100;Server@node2;Req;;Type 1 request received from ctminh@node2.supernodexp.hpc, sock=16
02/13/2018 17:56:10;0100;Server@node2;Req;;Type 3 request received from ctminh@node2.supernodexp.hpc, sock=16
02/13/2018 17:56:10;0100;Server@node2;Req;;Type 5 request received from ctminh@node2.supernodexp.hpc, sock=16
02/13/2018 17:56:10;0100;Server@node2;Job;803.node2.supernodexp.hpc;enqueuing into workq, state 1 hop 1
02/13/2018 17:56:10;0008;Server@node2;Job;803.node2.supernodexp.hpc;Job Queued at request of ctminh@node2.supernodexp.hpc, owner = ctminh@node2.supernodexp.hpc, job name = qe_mic_test, queue = workq
02/13/2018 17:56:10;0040;Server@node2;Svr;node2.supernodexp.hpc;Scheduler sent command 1
02/13/2018 17:56:10;0040;Server@node2;Svr;node2.supernodexp.hpc;Scheduler sent command 0
02/13/2018 17:56:10;0100;Server@node2;Req;;Type 21 request received from Scheduler@node2.supernodexp.hpc, sock=20
02/13/2018 17:56:10;0100;Server@node2;Req;;Type 81 request received from Scheduler@node2.supernodexp.hpc, sock=20
02/13/2018 17:56:10;0100;Server@node2;Req;;Type 71 request received from Scheduler@node2.supernodexp.hpc, sock=20
02/13/2018 17:56:10;0100;Server@node2;Req;;Type 58 request received from Scheduler@node2.supernodexp.hpc, sock=20
02/13/2018 17:56:10;0100;Server@node2;Req;;Type 1 request received from ctminh@node2.supernodexp.hpc, sock=16
02/13/2018 17:56:10;0100;Server@node2;Req;;Type 3 request received from ctminh@node2.supernodexp.hpc, sock=16
02/13/2018 17:56:10;0100;Server@node2;Req;;Type 5 request received from ctminh@node2.supernodexp.hpc, sock=16
02/13/2018 17:56:10;0100;Server@node2;Job;804.node2.supernodexp.hpc;enqueuing into workq, state 1 hop 1
02/13/2018 17:56:10;0008;Server@node2;Job;804.node2.supernodexp.hpc;Job Queued at request of ctminh@node2.supernodexp.hpc, owner = ctminh@node2.supernodexp.hpc, job name = thread-affinity, queue = workq
02/13/2018 17:56:10;0100;Server@node2;Req;;Type 20 request received from Scheduler@node2.supernodexp.hpc, sock=20
02/13/2018 17:56:10;0100;Server@node2;Req;;Type 51 request received from Scheduler@node2.supernodexp.hpc, sock=20
02/13/2018 17:56:10;0100;Server@node2;Req;;Type 1 request received from ctminh@node2.supernodexp.hpc, sock=16
02/13/2018 17:56:10;0100;Server@node2;Req;;Type 3 request received from ctminh@node2.supernodexp.hpc, sock=16
02/13/2018 17:56:10;0100;Server@node2;Req;;Type 5 request received from ctminh@node2.supernodexp.hpc, sock=16
02/13/2018 17:56:10;0100;Server@node2;Job;805.node2.supernodexp.hpc;enqueuing into workq, state 1 hop 1
02/13/2018 17:56:10;0008;Server@node2;Job;805.node2.supernodexp.hpc;Job Queued at request of ctminh@node2.supernodexp.hpc, owner = ctminh@node2.supernodexp.hpc, job name = sweep, queue = workq
02/13/2018 17:56:10;0100;Server@node2;Req;;Type 23 request received from Scheduler@node2.supernodexp.hpc, sock=20
02/13/2018 17:56:10;0008;Server@node2;Job;804.node2.supernodexp.hpc;Job Run at request of Scheduler@node2.supernodexp.hpc on exec_vnode (node13:ncpus=24:mem=2097152kb)
02/13/2018 17:56:10;0001;Server@node2;Svr;Server@node2;Success (0) in req_runjob2, return value of svr_startjob is 0
02/13/2018 17:56:10;0100;Server@node2;Req;;Type 11 request received from Scheduler@node2.supernodexp.hpc, sock=20
02/13/2018 17:56:10;0008;Server@node2;Job;803.node2.supernodexp.hpc;Job Modified at request of Scheduler@node2.supernodexp.hpc
02/13/2018 17:56:10;0040;Server@node2;Svr;node2.supernodexp.hpc;Scheduler sent command 1
02/13/2018 17:56:10;0040;Server@node2;Svr;node2.supernodexp.hpc;Scheduler sent command 0
02/13/2018 17:56:10;0100;Server@node2;Req;;Type 21 request received from Scheduler@node2.supernodexp.hpc, sock=20
02/13/2018 17:56:10;0100;Server@node2;Req;;Type 81 request received from Scheduler@node2.supernodexp.hpc, sock=20
02/13/2018 17:56:10;0100;Server@node2;Req;;Type 71 request received from Scheduler@node2.supernodexp.hpc, sock=20
02/13/2018 17:56:10;0100;Server@node2;Req;;Type 58 request received from Scheduler@node2.supernodexp.hpc, sock=20
02/13/2018 17:56:10;0100;Server@node2;Req;;Type 1 request received from ctminh@node2.supernodexp.hpc, sock=16
02/13/2018 17:56:10;0100;Server@node2;Req;;Type 3 request received from ctminh@node2.supernodexp.hpc, sock=16
02/13/2018 17:56:10;0100;Server@node2;Req;;Type 5 request received from ctminh@node2.supernodexp.hpc, sock=16
02/13/2018 17:56:10;0100;Server@node2;Job;806.node2.supernodexp.hpc;enqueuing into workq, state 1 hop 1
02/13/2018 17:56:10;0008;Server@node2;Job;806.node2.supernodexp.hpc;Job Queued at request of ctminh@node2.supernodexp.hpc, owner = ctminh@node2.supernodexp.hpc, job name = jacobi, queue = workq
02/13/2018 17:56:10;0100;Server@node2;Req;;Type 1 request received from ctminh@node2.supernodexp.hpc, sock=16
02/13/2018 17:56:10;0100;Server@node2;Req;;Type 20 request received from Scheduler@node2.supernodexp.hpc, sock=20
02/13/2018 17:56:10;0100;Server@node2;Req;;Type 3 request received from ctminh@node2.supernodexp.hpc, sock=16
02/13/2018 17:56:10;0100;Server@node2;Req;;Type 51 request received from Scheduler@node2.supernodexp.hpc, sock=20
02/13/2018 17:56:10;0100;Server@node2;Req;;Type 5 request received from ctminh@node2.supernodexp.hpc, sock=16
02/13/2018 17:56:10;0100;Server@node2;Job;807.node2.supernodexp.hpc;enqueuing into workq, state 1 hop 1
02/13/2018 17:56:10;0008;Server@node2;Job;807.node2.supernodexp.hpc;Job Queued at request of ctminh@node2.supernodexp.hpc, owner = ctminh@node2.supernodexp.hpc, job name = nbody, queue = workq
02/13/2018 17:56:10;0100;Server@node2;Req;;Type 1 request received from ctminh@node2.supernodexp.hpc, sock=16
02/13/2018 17:56:10;0100;Server@node2;Req;;Type 3 request received from ctminh@node2.supernodexp.hpc, sock=16
02/13/2018 17:56:10;0100;Server@node2;Req;;Type 5 request received from ctminh@node2.supernodexp.hpc, sock=16
02/13/2018 17:56:10;0100;Server@node2;Job;808.node2.supernodexp.hpc;enqueuing into workq, state 1 hop 1
02/13/2018 17:56:10;0008;Server@node2;Job;808.node2.supernodexp.hpc;Job Queued at request of ctminh@node2.supernodexp.hpc, owner = ctminh@node2.supernodexp.hpc, job name = histogram, queue = workq
02/13/2018 17:56:10;0100;Server@node2;Req;;Type 23 request received from Scheduler@node2.supernodexp.hpc, sock=20
02/13/2018 17:56:10;0008;Server@node2;Job;805.node2.supernodexp.hpc;Job Run at request of Scheduler@node2.supernodexp.hpc on exec_vnode (node13:ncpus=8:mem=3145728kb)
02/13/2018 17:56:10;0001;Server@node2;Svr;Server@node2;Success (0) in req_runjob2, return value of svr_startjob is 0
02/13/2018 17:56:10;0100;Server@node2;Req;;Type 23 request received from Scheduler@node2.supernodexp.hpc, sock=20
02/13/2018 17:56:10;0008;Server@node2;Job;806.node2.supernodexp.hpc;Job Run at request of Scheduler@node2.supernodexp.hpc on exec_vnode (node13:ncpus=16:mem=2097152kb)
02/13/2018 17:56:10;0001;Server@node2;Svr;Server@node2;Success (0) in req_runjob2, return value of svr_startjob is 0
02/13/2018 17:56:10;0100;Server@node2;Req;;Type 1 request received from ctminh@node2.supernodexp.hpc, sock=16
02/13/2018 17:56:10;0100;Server@node2;Req;;Type 11 request received from Scheduler@node2.supernodexp.hpc, sock=20
02/13/2018 17:56:10;0008;Server@node2;Job;803.node2.supernodexp.hpc;Job Modified at request of Scheduler@node2.supernodexp.hpc
02/13/2018 17:56:10;0100;Server@node2;Req;;Type 3 request received from ctminh@node2.supernodexp.hpc, sock=16
02/13/2018 17:56:10;0100;Server@node2;Req;;Type 5 request received from ctminh@node2.supernodexp.hpc, sock=16
02/13/2018 17:56:10;0100;Server@node2;Job;809.node2.supernodexp.hpc;enqueuing into workq, state 1 hop 1
02/13/2018 17:56:10;0008;Server@node2;Job;809.node2.supernodexp.hpc;Job Queued at request of ctminh@node2.supernodexp.hpc, owner = ctminh@node2.supernodexp.hpc, job name = histogram, queue = workq
02/13/2018 17:56:10;0040;Server@node2;Svr;node2.supernodexp.hpc;Scheduler sent command 1
02/13/2018 17:56:10;0040;Server@node2;Svr;node2.supernodexp.hpc;Scheduler sent command 0
02/13/2018 17:56:10;0100;Server@node2;Req;;Type 21 request received from Scheduler@node2.supernodexp.hpc, sock=20
02/13/2018 17:56:10;0100;Server@node2;Req;;Type 81 request received from Scheduler@node2.supernodexp.hpc, sock=20
02/13/2018 17:56:10;0100;Server@node2;Req;;Type 71 request received from Scheduler@node2.supernodexp.hpc, sock=20
02/13/2018 17:56:10;0100;Server@node2;Req;;Type 58 request received from Scheduler@node2.supernodexp.hpc, sock=20
02/13/2018 17:56:10;0100;Server@node2;Req;;Type 1 request received from ctminh@node2.supernodexp.hpc, sock=16
02/13/2018 17:56:10;0100;Server@node2;Req;;Type 3 request received from ctminh@node2.supernodexp.hpc, sock=16
02/13/2018 17:56:10;0100;Server@node2;Req;;Type 5 request received from ctminh@node2.supernodexp.hpc, sock=16
02/13/2018 17:56:10;0100;Server@node2;Job;810.node2.supernodexp.hpc;enqueuing into workq, state 1 hop 1
02/13/2018 17:56:10;0008;Server@node2;Job;810.node2.supernodexp.hpc;Job Queued at request of ctminh@node2.supernodexp.hpc, owner = ctminh@node2.supernodexp.hpc, job name = matrix-x-vector, queue = workq
02/13/2018 17:56:10;0100;Server@node2;Req;;Type 20 request received from Scheduler@node2.supernodexp.hpc, sock=20
02/13/2018 17:56:10;0100;Server@node2;Req;;Type 51 request received from Scheduler@node2.supernodexp.hpc, sock=20
02/13/2018 17:56:10;0100;Server@node2;Req;;Type 1 request received from ctminh@node2.supernodexp.hpc, sock=16
02/13/2018 17:56:10;0100;Server@node2;Req;;Type 3 request received from ctminh@node2.supernodexp.hpc, sock=16
02/13/2018 17:56:10;0100;Server@node2;Req;;Type 5 request received from ctminh@node2.supernodexp.hpc, sock=16
02/13/2018 17:56:10;0100;Server@node2;Job;811.node2.supernodexp.hpc;enqueuing into workq, state 1 hop 1
02/13/2018 17:56:10;0008;Server@node2;Job;811.node2.supernodexp.hpc;Job Queued at request of ctminh@node2.supernodexp.hpc, owner = ctminh@node2.supernodexp.hpc, job name = histogram, queue = workq
02/13/2018 17:56:10;0100;Server@node2;Req;;Type 11 request received from Scheduler@node2.supernodexp.hpc, sock=20
02/13/2018 17:56:10;0008;Server@node2;Job;808.node2.supernodexp.hpc;Job Modified at request of Scheduler@node2.supernodexp.hpc
02/13/2018 17:56:10;0100;Server@node2;Req;;Type 11 request received from Scheduler@node2.supernodexp.hpc, sock=20
02/13/2018 17:56:10;0008;Server@node2;Job;809.node2.supernodexp.hpc;Job Modified at request of Scheduler@node2.supernodexp.hpc
02/13/2018 17:56:10;0100;Server@node2;Req;;Type 11 request received from Scheduler@node2.supernodexp.hpc, sock=20
02/13/2018 17:56:10;0008;Server@node2;Job;807.node2.supernodexp.hpc;Job Modified at request of Scheduler@node2.supernodexp.hpc
02/13/2018 17:56:10;0100;Server@node2;Req;;Type 11 request received from Scheduler@node2.supernodexp.hpc, sock=20
02/13/2018 17:56:10;0008;Server@node2;Job;803.node2.supernodexp.hpc;Job Modified at request of Scheduler@node2.supernodexp.hpc
02/13/2018 17:56:10;0100;Server@node2;Req;;Type 1 request received from ctminh@node2.supernodexp.hpc, sock=16
02/13/2018 17:56:10;0100;Server@node2;Req;;Type 11 request received from Scheduler@node2.supernodexp.hpc, sock=20
02/13/2018 17:56:10;0008;Server@node2;Job;810.node2.supernodexp.hpc;Job Modified at request of Scheduler@node2.supernodexp.hpc
02/13/2018 17:56:10;0100;Server@node2;Req;;Type 3 request received from ctminh@node2.supernodexp.hpc, sock=16
02/13/2018 17:56:10;0100;Server@node2;Req;;Type 5 request received from ctminh@node2.supernodexp.hpc, sock=16
02/13/2018 17:56:10;0100;Server@node2;Job;812.node2.supernodexp.hpc;enqueuing into workq, state 1 hop 1
02/13/2018 17:56:10;0008;Server@node2;Job;812.node2.supernodexp.hpc;Job Queued at request of ctminh@node2.supernodexp.hpc, owner = ctminh@node2.supernodexp.hpc, job name = lu-decomp, queue = workq
02/13/2018 17:56:10;0040;Server@node2;Svr;node2.supernodexp.hpc;Scheduler sent command 1
02/13/2018 17:56:10;0040;Server@node2;Svr;node2.supernodexp.hpc;Scheduler sent command 0
02/13/2018 17:56:10;0100;Server@node2;Req;;Type 21 request received from Scheduler@node2.supernodexp.hpc, sock=20
02/13/2018 17:56:10;0100;Server@node2;Req;;Type 81 request received from Scheduler@node2.supernodexp.hpc, sock=20
02/13/2018 17:56:10;0100;Server@node2;Req;;Type 71 request received from Scheduler@node2.supernodexp.hpc, sock=20
02/13/2018 17:56:10;0100;Server@node2;Req;;Type 58 request received from Scheduler@node2.supernodexp.hpc, sock=20
02/13/2018 17:56:10;0100;Server@node2;Req;;Type 1 request received from ctminh@node2.supernodexp.hpc, sock=16
02/13/2018 17:56:10;0100;Server@node2;Req;;Type 3 request received from ctminh@node2.supernodexp.hpc, sock=16
02/13/2018 17:56:10;0100;Server@node2;Req;;Type 5 request received from ctminh@node2.supernodexp.hpc, sock=16
02/13/2018 17:56:10;0100;Server@node2;Job;813.node2.supernodexp.hpc;enqueuing into workq, state 1 hop 1
02/13/2018 17:56:10;0008;Server@node2;Job;813.node2.supernodexp.hpc;Job Queued at request of ctminh@node2.supernodexp.hpc, owner = ctminh@node2.supernodexp.hpc, job name = vectorization, queue = workq
02/13/2018 17:56:10;0100;Server@node2;Req;;Type 1 request received from ctminh@node2.supernodexp.hpc, sock=16
02/13/2018 17:56:10;0100;Server@node2;Req;;Type 20 request received from Scheduler@node2.supernodexp.hpc, sock=20
02/13/2018 17:56:10;0100;Server@node2;Req;;Type 3 request received from ctminh@node2.supernodexp.hpc, sock=16
02/13/2018 17:56:10;0100;Server@node2;Req;;Type 51 request received from Scheduler@node2.supernodexp.hpc, sock=20
02/13/2018 17:56:10;0100;Server@node2;Req;;Type 5 request received from ctminh@node2.supernodexp.hpc, sock=16
02/13/2018 17:56:10;0100;Server@node2;Job;814.node2.supernodexp.hpc;enqueuing into workq, state 1 hop 1
02/13/2018 17:56:10;0008;Server@node2;Job;814.node2.supernodexp.hpc;Job Queued at request of ctminh@node2.supernodexp.hpc, owner = ctminh@node2.supernodexp.hpc, job name = vast1, queue = workq
02/13/2018 17:56:10;0100;Server@node2;Req;;Type 1 request received from ctminh@node2.supernodexp.hpc, sock=16
02/13/2018 17:56:10;0100;Server@node2;Req;;Type 3 request received from ctminh@node2.supernodexp.hpc, sock=16
02/13/2018 17:56:10;0100;Server@node2;Req;;Type 5 request received from ctminh@node2.supernodexp.hpc, sock=16
02/13/2018 17:56:10;0100;Server@node2;Job;815.node2.supernodexp.hpc;enqueuing into workq, state 1 hop 1
02/13/2018 17:56:10;0008;Server@node2;Job;815.node2.supernodexp.hpc;Job Queued at request of ctminh@node2.supernodexp.hpc, owner = ctminh@node2.supernodexp.hpc, job name = nbody, queue = workq
02/13/2018 17:56:10;0100;Server@node2;Req;;Type 11 request received from Scheduler@node2.supernodexp.hpc, sock=20
02/13/2018 17:56:10;0008;Server@node2;Job;812.node2.supernodexp.hpc;Job Modified at request of Scheduler@node2.supernodexp.hpc
02/13/2018 17:56:10;0100;Server@node2;Req;;Type 11 request received from Scheduler@node2.supernodexp.hpc, sock=20
02/13/2018 17:56:10;0008;Server@node2;Job;811.node2.supernodexp.hpc;Job Modified at request of Scheduler@node2.supernodexp.hpc
02/13/2018 17:56:10;0100;Server@node2;Req;;Type 11 request received from Scheduler@node2.supernodexp.hpc, sock=20
02/13/2018 17:56:10;0008;Server@node2;Job;813.node2.supernodexp.hpc;Job Modified at request of Scheduler@node2.supernodexp.hpc
02/13/2018 17:56:10;0040;Server@node2;Svr;node2.supernodexp.hpc;Scheduler sent command 1
02/13/2018 17:56:10;0040;Server@node2;Svr;node2.supernodexp.hpc;Scheduler sent command 0
02/13/2018 17:56:10;0100;Server@node2;Req;;Type 21 request received from Scheduler@node2.supernodexp.hpc, sock=20
02/13/2018 17:56:10;0100;Server@node2;Req;;Type 81 request received from Scheduler@node2.supernodexp.hpc, sock=20
02/13/2018 17:56:10;0100;Server@node2;Req;;Type 71 request received from Scheduler@node2.supernodexp.hpc, sock=20
02/13/2018 17:56:10;0100;Server@node2;Req;;Type 58 request received from Scheduler@node2.supernodexp.hpc, sock=20
02/13/2018 17:56:10;0100;Server@node2;Req;;Type 1 request received from ctminh@node2.supernodexp.hpc, sock=16
02/13/2018 17:56:10;0100;Server@node2;Req;;Type 3 request received from ctminh@node2.supernodexp.hpc, sock=16
02/13/2018 17:56:10;0100;Server@node2;Req;;Type 5 request received from ctminh@node2.supernodexp.hpc, sock=16
02/13/2018 17:56:10;0100;Server@node2;Job;816.node2.supernodexp.hpc;enqueuing into workq, state 1 hop 1
02/13/2018 17:56:10;0008;Server@node2;Job;816.node2.supernodexp.hpc;Job Queued at request of ctminh@node2.supernodexp.hpc, owner = ctminh@node2.supernodexp.hpc, job name = vast1, queue = workq
02/13/2018 17:56:10;0100;Server@node2;Req;;Type 20 request received from Scheduler@node2.supernodexp.hpc, sock=20
02/13/2018 17:56:10;0100;Server@node2;Req;;Type 51 request received from Scheduler@node2.supernodexp.hpc, sock=20
02/13/2018 17:56:10;0100;Server@node2;Req;;Type 11 request received from Scheduler@node2.supernodexp.hpc, sock=20
02/13/2018 17:56:10;0008;Server@node2;Job;815.node2.supernodexp.hpc;Job Modified at request of Scheduler@node2.supernodexp.hpc
02/13/2018 17:56:10;0100;Server@node2;Req;;Type 11 request received from Scheduler@node2.supernodexp.hpc, sock=20
02/13/2018 17:56:10;0008;Server@node2;Job;814.node2.supernodexp.hpc;Job Modified at request of Scheduler@node2.supernodexp.hpc
02/13/2018 17:56:10;0100;Server@node2;Req;;Type 11 request received from Scheduler@node2.supernodexp.hpc, sock=20
02/13/2018 17:56:10;0008;Server@node2;Job;816.node2.supernodexp.hpc;Job Modified at request of Scheduler@node2.supernodexp.hpc
02/13/2018 17:56:10;0040;Server@node2;Svr;node2.supernodexp.hpc;Scheduler sent command 1
02/13/2018 17:56:10;0040;Server@node2;Svr;node2.supernodexp.hpc;Scheduler sent command 0
02/13/2018 17:56:10;0100;Server@node2;Req;;Type 21 request received from Scheduler@node2.supernodexp.hpc, sock=20
02/13/2018 17:56:10;0100;Server@node2;Req;;Type 81 request received from Scheduler@node2.supernodexp.hpc, sock=20
02/13/2018 17:56:10;0100;Server@node2;Req;;Type 71 request received from Scheduler@node2.supernodexp.hpc, sock=20
02/13/2018 17:56:10;0100;Server@node2;Req;;Type 58 request received from Scheduler@node2.supernodexp.hpc, sock=20
02/13/2018 17:56:10;0100;Server@node2;Req;;Type 20 request received from Scheduler@node2.supernodexp.hpc, sock=20
02/13/2018 17:56:10;0100;Server@node2;Req;;Type 51 request received from Scheduler@node2.supernodexp.hpc, sock=20
02/13/2018 17:56:12;0080;Server@node2;Job;805.node2.supernodexp.hpc;Obit received momhop:1 serverhop:1 state:4 substate:42
02/13/2018 17:56:13;0010;Server@node2;Job;805.node2.supernodexp.hpc;Exit_status=0 resources_used.cpupercent=800 resources_used.cput=00:00:10 resources_used.mem=0kb resources_used.ncpus=8 resources_used.vmem=0kb resources_used.walltime=00:00:01
02/13/2018 17:56:13;0100;Server@node2;Job;805.node2.supernodexp.hpc;dequeuing from workq, state 5
02/13/2018 17:56:13;0040;Server@node2;Svr;node2.supernodexp.hpc;Scheduler sent command 2
02/13/2018 17:56:13;0040;Server@node2;Svr;node2.supernodexp.hpc;Scheduler sent command 0
02/13/2018 17:56:13;0100;Server@node2;Req;;Type 21 request received from Scheduler@node2.supernodexp.hpc, sock=20
02/13/2018 17:56:13;0100;Server@node2;Req;;Type 81 request received from Scheduler@node2.supernodexp.hpc, sock=20
02/13/2018 17:56:13;0100;Server@node2;Req;;Type 71 request received from Scheduler@node2.supernodexp.hpc, sock=20
02/13/2018 17:56:13;0100;Server@node2;Req;;Type 58 request received from Scheduler@node2.supernodexp.hpc, sock=20
02/13/2018 17:56:13;0100;Server@node2;Req;;Type 20 request received from Scheduler@node2.supernodexp.hpc, sock=20
02/13/2018 17:56:13;0100;Server@node2;Req;;Type 51 request received from Scheduler@node2.supernodexp.hpc, sock=20
02/13/2018 17:56:13;0100;Server@node2;Req;;Type 11 request received from Scheduler@node2.supernodexp.hpc, sock=20
02/13/2018 17:56:13;0008;Server@node2;Job;810.node2.supernodexp.hpc;Job Modified at request of Scheduler@node2.supernodexp.hpc
02/13/2018 17:56:36;0080;Server@node2;Job;804.node2.supernodexp.hpc;Obit received momhop:1 serverhop:1 state:4 substate:42
02/13/2018 17:56:37;0010;Server@node2;Job;804.node2.supernodexp.hpc;Exit_status=0 resources_used.cpupercent=2400 resources_used.cput=00:10:06 resources_used.mem=1549544kb resources_used.ncpus=24 resources_used.vmem=3509008kb resources_used.walltime=00:00:28
02/13/2018 17:56:37;0100;Server@node2;Job;804.node2.supernodexp.hpc;dequeuing from workq, state 5
02/13/2018 17:56:37;0040;Server@node2;Svr;node2.supernodexp.hpc;Scheduler sent command 2
02/13/2018 17:56:37;0040;Server@node2;Svr;node2.supernodexp.hpc;Scheduler sent command 0
02/13/2018 17:56:37;0100;Server@node2;Req;;Type 21 request received from Scheduler@node2.supernodexp.hpc, sock=20
02/13/2018 17:56:37;0100;Server@node2;Req;;Type 81 request received from Scheduler@node2.supernodexp.hpc, sock=20
02/13/2018 17:56:37;0100;Server@node2;Req;;Type 71 request received from Scheduler@node2.supernodexp.hpc, sock=20
02/13/2018 17:56:37;0100;Server@node2;Req;;Type 58 request received from Scheduler@node2.supernodexp.hpc, sock=20
02/13/2018 17:56:37;0100;Server@node2;Req;;Type 20 request received from Scheduler@node2.supernodexp.hpc, sock=20
02/13/2018 17:56:37;0100;Server@node2;Req;;Type 51 request received from Scheduler@node2.supernodexp.hpc, sock=20
02/13/2018 17:56:37;0100;Server@node2;Req;;Type 23 request received from Scheduler@node2.supernodexp.hpc, sock=20
02/13/2018 17:56:37;0008;Server@node2;Job;810.node2.supernodexp.hpc;Job Run at request of Scheduler@node2.supernodexp.hpc on exec_vnode (node13:ncpus=16:mem=5242880kb)
02/13/2018 17:56:37;0001;Server@node2;Svr;Server@node2;Success (0) in req_runjob2, return value of svr_startjob is 0
02/13/2018 17:56:37;0100;Server@node2;Req;;Type 11 request received from Scheduler@node2.supernodexp.hpc, sock=20
02/13/2018 17:56:37;0008;Server@node2;Job;812.node2.supernodexp.hpc;Job Modified at request of Scheduler@node2.supernodexp.hpc
02/13/2018 17:56:39;0080;Server@node2;Job;810.node2.supernodexp.hpc;Obit received momhop:1 serverhop:1 state:4 substate:42
02/13/2018 17:56:40;0010;Server@node2;Job;810.node2.supernodexp.hpc;Exit_status=0 resources_used.cpupercent=1300 resources_used.cput=00:00:13 resources_used.mem=0kb resources_used.ncpus=16 resources_used.vmem=0kb resources_used.walltime=00:00:01
02/13/2018 17:56:40;0100;Server@node2;Job;810.node2.supernodexp.hpc;dequeuing from workq, state 5
02/13/2018 17:56:40;0040;Server@node2;Svr;node2.supernodexp.hpc;Scheduler sent command 2
02/13/2018 17:56:40;0040;Server@node2;Svr;node2.supernodexp.hpc;Scheduler sent command 0
02/13/2018 17:56:40;0100;Server@node2;Req;;Type 21 request received from Scheduler@node2.supernodexp.hpc, sock=20
02/13/2018 17:56:40;0100;Server@node2;Req;;Type 81 request received from Scheduler@node2.supernodexp.hpc, sock=20
02/13/2018 17:56:40;0100;Server@node2;Req;;Type 71 request received from Scheduler@node2.supernodexp.hpc, sock=20
02/13/2018 17:56:40;0100;Server@node2;Req;;Type 58 request received from Scheduler@node2.supernodexp.hpc, sock=20
02/13/2018 17:56:40;0100;Server@node2;Req;;Type 20 request received from Scheduler@node2.supernodexp.hpc, sock=20
02/13/2018 17:56:40;0100;Server@node2;Req;;Type 51 request received from Scheduler@node2.supernodexp.hpc, sock=20
02/13/2018 17:56:40;0100;Server@node2;Req;;Type 23 request received from Scheduler@node2.supernodexp.hpc, sock=20
02/13/2018 17:56:40;0008;Server@node2;Job;812.node2.supernodexp.hpc;Job Run at request of Scheduler@node2.supernodexp.hpc on exec_vnode (node13:ncpus=24:mem=1048576kb)
02/13/2018 17:56:40;0001;Server@node2;Svr;Server@node2;Success (0) in req_runjob2, return value of svr_startjob is 0
02/13/2018 17:56:40;0100;Server@node2;Req;;Type 11 request received from Scheduler@node2.supernodexp.hpc, sock=20
02/13/2018 17:56:40;0008;Server@node2;Job;808.node2.supernodexp.hpc;Job Modified at request of Scheduler@node2.supernodexp.hpc
02/13/2018 17:56:42;0080;Server@node2;Job;812.node2.supernodexp.hpc;Obit received momhop:1 serverhop:1 state:4 substate:42
02/13/2018 17:56:43;0010;Server@node2;Job;812.node2.supernodexp.hpc;Exit_status=0 resources_used.cpupercent=2050 resources_used.cput=00:00:41 resources_used.mem=0kb resources_used.ncpus=24 resources_used.vmem=0kb resources_used.walltime=00:00:02
02/13/2018 17:56:43;0100;Server@node2;Job;812.node2.supernodexp.hpc;dequeuing from workq, state 5
02/13/2018 17:56:43;0040;Server@node2;Svr;node2.supernodexp.hpc;Scheduler sent command 2
02/13/2018 17:56:43;0040;Server@node2;Svr;node2.supernodexp.hpc;Scheduler sent command 0
02/13/2018 17:56:43;0100;Server@node2;Req;;Type 21 request received from Scheduler@node2.supernodexp.hpc, sock=20
02/13/2018 17:56:43;0100;Server@node2;Req;;Type 81 request received from Scheduler@node2.supernodexp.hpc, sock=20
02/13/2018 17:56:43;0100;Server@node2;Req;;Type 71 request received from Scheduler@node2.supernodexp.hpc, sock=20
02/13/2018 17:56:43;0100;Server@node2;Req;;Type 58 request received from Scheduler@node2.supernodexp.hpc, sock=20
02/13/2018 17:56:43;0100;Server@node2;Req;;Type 20 request received from Scheduler@node2.supernodexp.hpc, sock=20
02/13/2018 17:56:43;0100;Server@node2;Req;;Type 51 request received from Scheduler@node2.supernodexp.hpc, sock=20
02/13/2018 17:56:43;0100;Server@node2;Req;;Type 23 request received from Scheduler@node2.supernodexp.hpc, sock=20
02/13/2018 17:56:43;0008;Server@node2;Job;808.node2.supernodexp.hpc;Job Run at request of Scheduler@node2.supernodexp.hpc on exec_vnode (node13:ncpus=32:mem=2097152kb)
02/13/2018 17:56:43;0001;Server@node2;Svr;Server@node2;Success (0) in req_runjob2, return value of svr_startjob is 0
02/13/2018 17:56:43;0100;Server@node2;Req;;Type 11 request received from Scheduler@node2.supernodexp.hpc, sock=20
02/13/2018 17:56:43;0008;Server@node2;Job;809.node2.supernodexp.hpc;Job Modified at request of Scheduler@node2.supernodexp.hpc
02/13/2018 17:56:47;0080;Server@node2;Job;808.node2.supernodexp.hpc;Obit received momhop:1 serverhop:1 state:4 substate:42
02/13/2018 17:56:49;0010;Server@node2;Job;808.node2.supernodexp.hpc;Exit_status=0 resources_used.cpupercent=100 resources_used.cput=00:00:04 resources_used.mem=0kb resources_used.ncpus=32 resources_used.vmem=0kb resources_used.walltime=00:00:05
02/13/2018 17:56:49;0100;Server@node2;Job;808.node2.supernodexp.hpc;dequeuing from workq, state 5
02/13/2018 17:56:49;0040;Server@node2;Svr;node2.supernodexp.hpc;Scheduler sent command 2
02/13/2018 17:56:49;0040;Server@node2;Svr;node2.supernodexp.hpc;Scheduler sent command 0
02/13/2018 17:56:49;0100;Server@node2;Req;;Type 21 request received from Scheduler@node2.supernodexp.hpc, sock=20
02/13/2018 17:56:49;0100;Server@node2;Req;;Type 81 request received from Scheduler@node2.supernodexp.hpc, sock=20
02/13/2018 17:56:49;0100;Server@node2;Req;;Type 71 request received from Scheduler@node2.supernodexp.hpc, sock=20
02/13/2018 17:56:49;0100;Server@node2;Req;;Type 58 request received from Scheduler@node2.supernodexp.hpc, sock=20
02/13/2018 17:56:49;0100;Server@node2;Req;;Type 20 request received from Scheduler@node2.supernodexp.hpc, sock=20
02/13/2018 17:56:49;0100;Server@node2;Req;;Type 51 request received from Scheduler@node2.supernodexp.hpc, sock=20
02/13/2018 17:56:49;0100;Server@node2;Req;;Type 23 request received from Scheduler@node2.supernodexp.hpc, sock=20
02/13/2018 17:56:49;0008;Server@node2;Job;809.node2.supernodexp.hpc;Job Run at request of Scheduler@node2.supernodexp.hpc on exec_vnode (node13:ncpus=32:mem=2097152kb)
02/13/2018 17:56:49;0001;Server@node2;Svr;Server@node2;Success (0) in req_runjob2, return value of svr_startjob is 0
02/13/2018 17:56:49;0100;Server@node2;Req;;Type 11 request received from Scheduler@node2.supernodexp.hpc, sock=20
02/13/2018 17:56:49;0008;Server@node2;Job;811.node2.supernodexp.hpc;Job Modified at request of Scheduler@node2.supernodexp.hpc
02/13/2018 17:56:53;0080;Server@node2;Job;809.node2.supernodexp.hpc;Obit received momhop:1 serverhop:1 state:4 substate:42
02/13/2018 17:56:54;0010;Server@node2;Job;809.node2.supernodexp.hpc;Exit_status=0 resources_used.cpupercent=79 resources_used.cput=00:00:04 resources_used.mem=0kb resources_used.ncpus=32 resources_used.vmem=0kb resources_used.walltime=00:00:05
02/13/2018 17:56:54;0100;Server@node2;Job;809.node2.supernodexp.hpc;dequeuing from workq, state 5
02/13/2018 17:56:54;0040;Server@node2;Svr;node2.supernodexp.hpc;Scheduler sent command 2
02/13/2018 17:56:54;0040;Server@node2;Svr;node2.supernodexp.hpc;Scheduler sent command 0
02/13/2018 17:56:54;0100;Server@node2;Req;;Type 21 request received from Scheduler@node2.supernodexp.hpc, sock=20
02/13/2018 17:56:54;0100;Server@node2;Req;;Type 81 request received from Scheduler@node2.supernodexp.hpc, sock=20
02/13/2018 17:56:54;0100;Server@node2;Req;;Type 71 request received from Scheduler@node2.supernodexp.hpc, sock=20
02/13/2018 17:56:54;0100;Server@node2;Req;;Type 58 request received from Scheduler@node2.supernodexp.hpc, sock=20
02/13/2018 17:56:54;0100;Server@node2;Req;;Type 20 request received from Scheduler@node2.supernodexp.hpc, sock=20
02/13/2018 17:56:54;0100;Server@node2;Req;;Type 51 request received from Scheduler@node2.supernodexp.hpc, sock=20
02/13/2018 17:56:54;0100;Server@node2;Req;;Type 23 request received from Scheduler@node2.supernodexp.hpc, sock=20
02/13/2018 17:56:54;0008;Server@node2;Job;811.node2.supernodexp.hpc;Job Run at request of Scheduler@node2.supernodexp.hpc on exec_vnode (node13:ncpus=32:mem=2097152kb)
02/13/2018 17:56:54;0001;Server@node2;Svr;Server@node2;Success (0) in req_runjob2, return value of svr_startjob is 0
02/13/2018 17:56:54;0100;Server@node2;Req;;Type 11 request received from Scheduler@node2.supernodexp.hpc, sock=20
02/13/2018 17:56:54;0008;Server@node2;Job;813.node2.supernodexp.hpc;Job Modified at request of Scheduler@node2.supernodexp.hpc
02/13/2018 17:56:55;0100;Server@node2;Req;;Type 1 request received from ctminh@node2.supernodexp.hpc, sock=16
02/13/2018 17:56:55;0100;Server@node2;Req;;Type 3 request received from ctminh@node2.supernodexp.hpc, sock=16
02/13/2018 17:56:55;0100;Server@node2;Req;;Type 5 request received from ctminh@node2.supernodexp.hpc, sock=16
02/13/2018 17:56:55;0100;Server@node2;Job;817.node2.supernodexp.hpc;enqueuing into workq, state 1 hop 1
02/13/2018 17:56:55;0008;Server@node2;Job;817.node2.supernodexp.hpc;Job Queued at request of ctminh@node2.supernodexp.hpc, owner = ctminh@node2.supernodexp.hpc, job name = telemac2, queue = workq
02/13/2018 17:56:55;0040;Server@node2;Svr;node2.supernodexp.hpc;Scheduler sent command 1
02/13/2018 17:56:55;0040;Server@node2;Svr;node2.supernodexp.hpc;Scheduler sent command 0
02/13/2018 17:56:55;0100;Server@node2;Req;;Type 21 request received from Scheduler@node2.supernodexp.hpc, sock=20
02/13/2018 17:56:55;0100;Server@node2;Req;;Type 81 request received from Scheduler@node2.supernodexp.hpc, sock=20
02/13/2018 17:56:55;0100;Server@node2;Req;;Type 71 request received from Scheduler@node2.supernodexp.hpc, sock=20
02/13/2018 17:56:55;0100;Server@node2;Req;;Type 58 request received from Scheduler@node2.supernodexp.hpc, sock=20
02/13/2018 17:56:55;0100;Server@node2;Req;;Type 1 request received from ctminh@node2.supernodexp.hpc, sock=16
02/13/2018 17:56:55;0100;Server@node2;Req;;Type 3 request received from ctminh@node2.supernodexp.hpc, sock=16
02/13/2018 17:56:55;0100;Server@node2;Req;;Type 5 request received from ctminh@node2.supernodexp.hpc, sock=16
02/13/2018 17:56:55;0100;Server@node2;Job;818.node2.supernodexp.hpc;enqueuing into workq, state 1 hop 1
02/13/2018 17:56:55;0008;Server@node2;Job;818.node2.supernodexp.hpc;Job Queued at request of ctminh@node2.supernodexp.hpc, owner = ctminh@node2.supernodexp.hpc, job name = telemac2, queue = workq
02/13/2018 17:56:55;0100;Server@node2;Req;;Type 20 request received from Scheduler@node2.supernodexp.hpc, sock=20
02/13/2018 17:56:55;0100;Server@node2;Req;;Type 51 request received from Scheduler@node2.supernodexp.hpc, sock=20
02/13/2018 17:56:55;0100;Server@node2;Req;;Type 1 request received from ctminh@node2.supernodexp.hpc, sock=16
02/13/2018 17:56:55;0100;Server@node2;Req;;Type 3 request received from ctminh@node2.supernodexp.hpc, sock=16
02/13/2018 17:56:55;0100;Server@node2;Req;;Type 5 request received from ctminh@node2.supernodexp.hpc, sock=16
02/13/2018 17:56:55;0100;Server@node2;Job;819.node2.supernodexp.hpc;enqueuing into workq, state 1 hop 1
02/13/2018 17:56:55;0008;Server@node2;Job;819.node2.supernodexp.hpc;Job Queued at request of ctminh@node2.supernodexp.hpc, owner = ctminh@node2.supernodexp.hpc, job name = telemac3, queue = workq
02/13/2018 17:56:55;0100;Server@node2;Req;;Type 1 request received from ctminh@node2.supernodexp.hpc, sock=16
02/13/2018 17:56:55;0100;Server@node2;Req;;Type 3 request received from ctminh@node2.supernodexp.hpc, sock=16
02/13/2018 17:56:55;0100;Server@node2;Req;;Type 5 request received from ctminh@node2.supernodexp.hpc, sock=16
02/13/2018 17:56:55;0100;Server@node2;Job;820.node2.supernodexp.hpc;enqueuing into workq, state 1 hop 1
02/13/2018 17:56:55;0008;Server@node2;Job;820.node2.supernodexp.hpc;Job Queued at request of ctminh@node2.supernodexp.hpc, owner = ctminh@node2.supernodexp.hpc, job name = telemac1, queue = workq
02/13/2018 17:56:55;0100;Server@node2;Req;;Type 11 request received from Scheduler@node2.supernodexp.hpc, sock=20
02/13/2018 17:56:55;0008;Server@node2;Job;817.node2.supernodexp.hpc;Job Modified at request of Scheduler@node2.supernodexp.hpc
02/13/2018 17:56:55;0100;Server@node2;Req;;Type 11 request received from Scheduler@node2.supernodexp.hpc, sock=20
02/13/2018 17:56:55;0008;Server@node2;Job;818.node2.supernodexp.hpc;Job Modified at request of Scheduler@node2.supernodexp.hpc
02/13/2018 17:56:55;0040;Server@node2;Svr;node2.supernodexp.hpc;Scheduler sent command 1
02/13/2018 17:56:55;0040;Server@node2;Svr;node2.supernodexp.hpc;Scheduler sent command 0
02/13/2018 17:56:55;0100;Server@node2;Req;;Type 21 request received from Scheduler@node2.supernodexp.hpc, sock=20
02/13/2018 17:56:55;0100;Server@node2;Req;;Type 81 request received from Scheduler@node2.supernodexp.hpc, sock=20
02/13/2018 17:56:55;0100;Server@node2;Req;;Type 71 request received from Scheduler@node2.supernodexp.hpc, sock=20
02/13/2018 17:56:55;0100;Server@node2;Req;;Type 58 request received from Scheduler@node2.supernodexp.hpc, sock=20
02/13/2018 17:56:55;0100;Server@node2;Req;;Type 1 request received from ctminh@node2.supernodexp.hpc, sock=16
02/13/2018 17:56:55;0100;Server@node2;Req;;Type 3 request received from ctminh@node2.supernodexp.hpc, sock=16
02/13/2018 17:56:55;0100;Server@node2;Req;;Type 5 request received from ctminh@node2.supernodexp.hpc, sock=16
02/13/2018 17:56:55;0100;Server@node2;Job;821.node2.supernodexp.hpc;enqueuing into workq, state 1 hop 1
02/13/2018 17:56:55;0008;Server@node2;Job;821.node2.supernodexp.hpc;Job Queued at request of ctminh@node2.supernodexp.hpc, owner = ctminh@node2.supernodexp.hpc, job name = vectorization, queue = workq
02/13/2018 17:56:55;0100;Server@node2;Req;;Type 1 request received from ctminh@node2.supernodexp.hpc, sock=16
02/13/2018 17:56:55;0100;Server@node2;Req;;Type 20 request received from Scheduler@node2.supernodexp.hpc, sock=20
02/13/2018 17:56:55;0100;Server@node2;Req;;Type 3 request received from ctminh@node2.supernodexp.hpc, sock=16
02/13/2018 17:56:55;0100;Server@node2;Req;;Type 51 request received from Scheduler@node2.supernodexp.hpc, sock=20
02/13/2018 17:56:55;0100;Server@node2;Req;;Type 5 request received from ctminh@node2.supernodexp.hpc, sock=16
02/13/2018 17:56:55;0100;Server@node2;Job;822.node2.supernodexp.hpc;enqueuing into workq, state 1 hop 1
02/13/2018 17:56:55;0008;Server@node2;Job;822.node2.supernodexp.hpc;Job Queued at request of ctminh@node2.supernodexp.hpc, owner = ctminh@node2.supernodexp.hpc, job name = telemac1, queue = workq
02/13/2018 17:56:55;0100;Server@node2;Req;;Type 1 request received from ctminh@node2.supernodexp.hpc, sock=16
02/13/2018 17:56:55;0100;Server@node2;Req;;Type 3 request received from ctminh@node2.supernodexp.hpc, sock=16
02/13/2018 17:56:55;0100;Server@node2;Req;;Type 5 request received from ctminh@node2.supernodexp.hpc, sock=16
02/13/2018 17:56:55;0100;Server@node2;Job;823.node2.supernodexp.hpc;enqueuing into workq, state 1 hop 1
02/13/2018 17:56:55;0008;Server@node2;Job;823.node2.supernodexp.hpc;Job Queued at request of ctminh@node2.supernodexp.hpc, owner = ctminh@node2.supernodexp.hpc, job name = telemac2, queue = workq
02/13/2018 17:56:55;0100;Server@node2;Req;;Type 11 request received from Scheduler@node2.supernodexp.hpc, sock=20
02/13/2018 17:56:55;0008;Server@node2;Job;821.node2.supernodexp.hpc;Job Modified at request of Scheduler@node2.supernodexp.hpc
02/13/2018 17:56:55;0100;Server@node2;Req;;Type 11 request received from Scheduler@node2.supernodexp.hpc, sock=20
02/13/2018 17:56:55;0008;Server@node2;Job;819.node2.supernodexp.hpc;Job Modified at request of Scheduler@node2.supernodexp.hpc
02/13/2018 17:56:55;0100;Server@node2;Req;;Type 11 request received from Scheduler@node2.supernodexp.hpc, sock=20
02/13/2018 17:56:55;0008;Server@node2;Job;820.node2.supernodexp.hpc;Job Modified at request of Scheduler@node2.supernodexp.hpc
02/13/2018 17:56:55;0040;Server@node2;Svr;node2.supernodexp.hpc;Scheduler sent command 1
02/13/2018 17:56:55;0040;Server@node2;Svr;node2.supernodexp.hpc;Scheduler sent command 0
02/13/2018 17:56:55;0100;Server@node2;Req;;Type 21 request received from Scheduler@node2.supernodexp.hpc, sock=20
02/13/2018 17:56:55;0100;Server@node2;Req;;Type 81 request received from Scheduler@node2.supernodexp.hpc, sock=20
02/13/2018 17:56:55;0100;Server@node2;Req;;Type 71 request received from Scheduler@node2.supernodexp.hpc, sock=20
02/13/2018 17:56:55;0100;Server@node2;Req;;Type 58 request received from Scheduler@node2.supernodexp.hpc, sock=20
02/13/2018 17:56:55;0100;Server@node2;Req;;Type 1 request received from ctminh@node2.supernodexp.hpc, sock=16
02/13/2018 17:56:55;0100;Server@node2;Req;;Type 3 request received from ctminh@node2.supernodexp.hpc, sock=16
02/13/2018 17:56:55;0100;Server@node2;Req;;Type 5 request received from ctminh@node2.supernodexp.hpc, sock=16
02/13/2018 17:56:55;0100;Server@node2;Job;824.node2.supernodexp.hpc;enqueuing into workq, state 1 hop 1
02/13/2018 17:56:55;0008;Server@node2;Job;824.node2.supernodexp.hpc;Job Queued at request of ctminh@node2.supernodexp.hpc, owner = ctminh@node2.supernodexp.hpc, job name = qe_mic_test, queue = workq
02/13/2018 17:56:55;0100;Server@node2;Req;;Type 1 request received from ctminh@node2.supernodexp.hpc, sock=16
02/13/2018 17:56:56;0100;Server@node2;Req;;Type 3 request received from ctminh@node2.supernodexp.hpc, sock=16
02/13/2018 17:56:56;0100;Server@node2;Req;;Type 5 request received from ctminh@node2.supernodexp.hpc, sock=16
02/13/2018 17:56:56;0100;Server@node2;Job;825.node2.supernodexp.hpc;enqueuing into workq, state 1 hop 1
02/13/2018 17:56:56;0008;Server@node2;Job;825.node2.supernodexp.hpc;Job Queued at request of ctminh@node2.supernodexp.hpc, owner = ctminh@node2.supernodexp.hpc, job name = matrix-x-vector, queue = workq
02/13/2018 17:56:56;0100;Server@node2;Req;;Type 20 request received from Scheduler@node2.supernodexp.hpc, sock=20
02/13/2018 17:56:56;0100;Server@node2;Req;;Type 51 request received from Scheduler@node2.supernodexp.hpc, sock=20
02/13/2018 17:56:56;0100;Server@node2;Req;;Type 1 request received from ctminh@node2.supernodexp.hpc, sock=16
02/13/2018 17:56:56;0100;Server@node2;Req;;Type 3 request received from ctminh@node2.supernodexp.hpc, sock=16
02/13/2018 17:56:56;0100;Server@node2;Req;;Type 5 request received from ctminh@node2.supernodexp.hpc, sock=16
02/13/2018 17:56:56;0100;Server@node2;Job;826.node2.supernodexp.hpc;enqueuing into workq, state 1 hop 1
02/13/2018 17:56:56;0008;Server@node2;Job;826.node2.supernodexp.hpc;Job Queued at request of ctminh@node2.supernodexp.hpc, owner = ctminh@node2.supernodexp.hpc, job name = thread-affinity, queue = workq
02/13/2018 17:56:56;0100;Server@node2;Req;;Type 1 request received from ctminh@node2.supernodexp.hpc, sock=16
02/13/2018 17:56:56;0100;Server@node2;Req;;Type 3 request received from ctminh@node2.supernodexp.hpc, sock=16
02/13/2018 17:56:56;0100;Server@node2;Req;;Type 5 request received from ctminh@node2.supernodexp.hpc, sock=16
02/13/2018 17:56:56;0100;Server@node2;Job;827.node2.supernodexp.hpc;enqueuing into workq, state 1 hop 1
02/13/2018 17:56:56;0008;Server@node2;Job;827.node2.supernodexp.hpc;Job Queued at request of ctminh@node2.supernodexp.hpc, owner = ctminh@node2.supernodexp.hpc, job name = vectorization, queue = workq
02/13/2018 17:56:56;0100;Server@node2;Req;;Type 11 request received from Scheduler@node2.supernodexp.hpc, sock=20
02/13/2018 17:56:56;0008;Server@node2;Job;813.node2.supernodexp.hpc;Job Modified at request of Scheduler@node2.supernodexp.hpc
02/13/2018 17:56:56;0100;Server@node2;Req;;Type 11 request received from Scheduler@node2.supernodexp.hpc, sock=20
02/13/2018 17:56:56;0008;Server@node2;Job;822.node2.supernodexp.hpc;Job Modified at request of Scheduler@node2.supernodexp.hpc
02/13/2018 17:56:56;0100;Server@node2;Req;;Type 11 request received from Scheduler@node2.supernodexp.hpc, sock=20
02/13/2018 17:56:56;0008;Server@node2;Job;823.node2.supernodexp.hpc;Job Modified at request of Scheduler@node2.supernodexp.hpc
02/13/2018 17:56:56;0100;Server@node2;Req;;Type 11 request received from Scheduler@node2.supernodexp.hpc, sock=20
02/13/2018 17:56:56;0008;Server@node2;Job;824.node2.supernodexp.hpc;Job Modified at request of Scheduler@node2.supernodexp.hpc
02/13/2018 17:56:56;0100;Server@node2;Req;;Type 11 request received from Scheduler@node2.supernodexp.hpc, sock=20
02/13/2018 17:56:56;0008;Server@node2;Job;825.node2.supernodexp.hpc;Job Modified at request of Scheduler@node2.supernodexp.hpc
02/13/2018 17:56:56;0040;Server@node2;Svr;node2.supernodexp.hpc;Scheduler sent command 1
02/13/2018 17:56:56;0040;Server@node2;Svr;node2.supernodexp.hpc;Scheduler sent command 0
02/13/2018 17:56:56;0100;Server@node2;Req;;Type 21 request received from Scheduler@node2.supernodexp.hpc, sock=20
02/13/2018 17:56:56;0100;Server@node2;Req;;Type 81 request received from Scheduler@node2.supernodexp.hpc, sock=20
02/13/2018 17:56:56;0100;Server@node2;Req;;Type 71 request received from Scheduler@node2.supernodexp.hpc, sock=20
02/13/2018 17:56:56;0100;Server@node2;Req;;Type 58 request received from Scheduler@node2.supernodexp.hpc, sock=20
02/13/2018 17:56:56;0100;Server@node2;Req;;Type 1 request received from ctminh@node2.supernodexp.hpc, sock=16
02/13/2018 17:56:56;0100;Server@node2;Req;;Type 3 request received from ctminh@node2.supernodexp.hpc, sock=16
02/13/2018 17:56:56;0100;Server@node2;Req;;Type 5 request received from ctminh@node2.supernodexp.hpc, sock=16
02/13/2018 17:56:56;0100;Server@node2;Job;828.node2.supernodexp.hpc;enqueuing into workq, state 1 hop 1
02/13/2018 17:56:56;0008;Server@node2;Job;828.node2.supernodexp.hpc;Job Queued at request of ctminh@node2.supernodexp.hpc, owner = ctminh@node2.supernodexp.hpc, job name = lu-decomp, queue = workq
02/13/2018 17:56:56;0100;Server@node2;Req;;Type 1 request received from ctminh@node2.supernodexp.hpc, sock=16
02/13/2018 17:56:56;0100;Server@node2;Req;;Type 3 request received from ctminh@node2.supernodexp.hpc, sock=16
02/13/2018 17:56:56;0100;Server@node2;Req;;Type 5 request received from ctminh@node2.supernodexp.hpc, sock=16
02/13/2018 17:56:56;0100;Server@node2;Job;829.node2.supernodexp.hpc;enqueuing into workq, state 1 hop 1
02/13/2018 17:56:56;0008;Server@node2;Job;829.node2.supernodexp.hpc;Job Queued at request of ctminh@node2.supernodexp.hpc, owner = ctminh@node2.supernodexp.hpc, job name = telemac1, queue = workq
02/13/2018 17:56:56;0100;Server@node2;Req;;Type 20 request received from Scheduler@node2.supernodexp.hpc, sock=20
02/13/2018 17:56:56;0100;Server@node2;Req;;Type 51 request received from Scheduler@node2.supernodexp.hpc, sock=20
02/13/2018 17:56:56;0100;Server@node2;Req;;Type 1 request received from ctminh@node2.supernodexp.hpc, sock=16
02/13/2018 17:56:56;0100;Server@node2;Req;;Type 3 request received from ctminh@node2.supernodexp.hpc, sock=16
02/13/2018 17:56:56;0100;Server@node2;Req;;Type 5 request received from ctminh@node2.supernodexp.hpc, sock=16
02/13/2018 17:56:56;0100;Server@node2;Job;830.node2.supernodexp.hpc;enqueuing into workq, state 1 hop 1
02/13/2018 17:56:56;0008;Server@node2;Job;830.node2.supernodexp.hpc;Job Queued at request of ctminh@node2.supernodexp.hpc, owner = ctminh@node2.supernodexp.hpc, job name = telemac1, queue = workq
02/13/2018 17:56:56;0100;Server@node2;Req;;Type 1 request received from ctminh@node2.supernodexp.hpc, sock=16
02/13/2018 17:56:56;0100;Server@node2;Req;;Type 3 request received from ctminh@node2.supernodexp.hpc, sock=16
02/13/2018 17:56:56;0100;Server@node2;Req;;Type 5 request received from ctminh@node2.supernodexp.hpc, sock=16
02/13/2018 17:56:56;0100;Server@node2;Job;831.node2.supernodexp.hpc;enqueuing into workq, state 1 hop 1
02/13/2018 17:56:56;0008;Server@node2;Job;831.node2.supernodexp.hpc;Job Queued at request of ctminh@node2.supernodexp.hpc, owner = ctminh@node2.supernodexp.hpc, job name = telemac1, queue = workq
02/13/2018 17:56:56;0100;Server@node2;Req;;Type 11 request received from Scheduler@node2.supernodexp.hpc, sock=20
02/13/2018 17:56:56;0008;Server@node2;Job;828.node2.supernodexp.hpc;Job Modified at request of Scheduler@node2.supernodexp.hpc
02/13/2018 17:56:56;0100;Server@node2;Req;;Type 11 request received from Scheduler@node2.supernodexp.hpc, sock=20
02/13/2018 17:56:56;0008;Server@node2;Job;827.node2.supernodexp.hpc;Job Modified at request of Scheduler@node2.supernodexp.hpc
02/13/2018 17:56:56;0100;Server@node2;Req;;Type 11 request received from Scheduler@node2.supernodexp.hpc, sock=20
02/13/2018 17:56:56;0008;Server@node2;Job;826.node2.supernodexp.hpc;Job Modified at request of Scheduler@node2.supernodexp.hpc
02/13/2018 17:56:56;0100;Server@node2;Req;;Type 11 request received from Scheduler@node2.supernodexp.hpc, sock=20
02/13/2018 17:56:56;0008;Server@node2;Job;829.node2.supernodexp.hpc;Job Modified at request of Scheduler@node2.supernodexp.hpc
02/13/2018 17:56:56;0040;Server@node2;Svr;node2.supernodexp.hpc;Scheduler sent command 1
02/13/2018 17:56:56;0040;Server@node2;Svr;node2.supernodexp.hpc;Scheduler sent command 0
02/13/2018 17:56:56;0100;Server@node2;Req;;Type 21 request received from Scheduler@node2.supernodexp.hpc, sock=20
02/13/2018 17:56:56;0100;Server@node2;Req;;Type 81 request received from Scheduler@node2.supernodexp.hpc, sock=20
02/13/2018 17:56:56;0100;Server@node2;Req;;Type 71 request received from Scheduler@node2.supernodexp.hpc, sock=20
02/13/2018 17:56:56;0100;Server@node2;Req;;Type 58 request received from Scheduler@node2.supernodexp.hpc, sock=20
02/13/2018 17:56:56;0100;Server@node2;Req;;Type 1 request received from ctminh@node2.supernodexp.hpc, sock=16
02/13/2018 17:56:56;0100;Server@node2;Req;;Type 3 request received from ctminh@node2.supernodexp.hpc, sock=16
02/13/2018 17:56:56;0100;Server@node2;Req;;Type 5 request received from ctminh@node2.supernodexp.hpc, sock=16
02/13/2018 17:56:56;0100;Server@node2;Job;832.node2.supernodexp.hpc;enqueuing into workq, state 1 hop 1
02/13/2018 17:56:56;0008;Server@node2;Job;832.node2.supernodexp.hpc;Job Queued at request of ctminh@node2.supernodexp.hpc, owner = ctminh@node2.supernodexp.hpc, job name = nbody, queue = workq
02/13/2018 17:56:56;0100;Server@node2;Req;;Type 1 request received from ctminh@node2.supernodexp.hpc, sock=16
02/13/2018 17:56:56;0100;Server@node2;Req;;Type 20 request received from Scheduler@node2.supernodexp.hpc, sock=20
02/13/2018 17:56:56;0100;Server@node2;Req;;Type 3 request received from ctminh@node2.supernodexp.hpc, sock=16
02/13/2018 17:56:56;0100;Server@node2;Req;;Type 51 request received from Scheduler@node2.supernodexp.hpc, sock=20
02/13/2018 17:56:56;0100;Server@node2;Req;;Type 5 request received from ctminh@node2.supernodexp.hpc, sock=16
02/13/2018 17:56:56;0100;Server@node2;Job;833.node2.supernodexp.hpc;enqueuing into workq, state 1 hop 1
02/13/2018 17:56:56;0008;Server@node2;Job;833.node2.supernodexp.hpc;Job Queued at request of ctminh@node2.supernodexp.hpc, owner = ctminh@node2.supernodexp.hpc, job name = telemac1, queue = workq
02/13/2018 17:56:56;0100;Server@node2;Req;;Type 1 request received from ctminh@node2.supernodexp.hpc, sock=16
02/13/2018 17:56:56;0100;Server@node2;Req;;Type 3 request received from ctminh@node2.supernodexp.hpc, sock=16
02/13/2018 17:56:56;0100;Server@node2;Req;;Type 5 request received from ctminh@node2.supernodexp.hpc, sock=16
02/13/2018 17:56:56;0100;Server@node2;Job;834.node2.supernodexp.hpc;enqueuing into workq, state 1 hop 1
02/13/2018 17:56:56;0008;Server@node2;Job;834.node2.supernodexp.hpc;Job Queued at request of ctminh@node2.supernodexp.hpc, owner = ctminh@node2.supernodexp.hpc, job name = jacobi, queue = workq
02/13/2018 17:56:56;0100;Server@node2;Req;;Type 11 request received from Scheduler@node2.supernodexp.hpc, sock=20
02/13/2018 17:56:56;0008;Server@node2;Job;832.node2.supernodexp.hpc;Job Modified at request of Scheduler@node2.supernodexp.hpc
02/13/2018 17:56:56;0100;Server@node2;Req;;Type 11 request received from Scheduler@node2.supernodexp.hpc, sock=20
02/13/2018 17:56:56;0008;Server@node2;Job;830.node2.supernodexp.hpc;Job Modified at request of Scheduler@node2.supernodexp.hpc
02/13/2018 17:56:56;0100;Server@node2;Req;;Type 11 request received from Scheduler@node2.supernodexp.hpc, sock=20
02/13/2018 17:56:56;0008;Server@node2;Job;831.node2.supernodexp.hpc;Job Modified at request of Scheduler@node2.supernodexp.hpc
02/13/2018 17:56:56;0040;Server@node2;Svr;node2.supernodexp.hpc;Scheduler sent command 1
02/13/2018 17:56:56;0040;Server@node2;Svr;node2.supernodexp.hpc;Scheduler sent command 0
02/13/2018 17:56:56;0100;Server@node2;Req;;Type 21 request received from Scheduler@node2.supernodexp.hpc, sock=20
02/13/2018 17:56:56;0100;Server@node2;Req;;Type 81 request received from Scheduler@node2.supernodexp.hpc, sock=20
02/13/2018 17:56:56;0100;Server@node2;Req;;Type 71 request received from Scheduler@node2.supernodexp.hpc, sock=20
02/13/2018 17:56:56;0100;Server@node2;Req;;Type 58 request received from Scheduler@node2.supernodexp.hpc, sock=20
02/13/2018 17:56:56;0100;Server@node2;Req;;Type 1 request received from ctminh@node2.supernodexp.hpc, sock=16
02/13/2018 17:56:56;0100;Server@node2;Req;;Type 3 request received from ctminh@node2.supernodexp.hpc, sock=16
02/13/2018 17:56:56;0100;Server@node2;Req;;Type 5 request received from ctminh@node2.supernodexp.hpc, sock=16
02/13/2018 17:56:56;0100;Server@node2;Job;835.node2.supernodexp.hpc;enqueuing into workq, state 1 hop 1
02/13/2018 17:56:56;0008;Server@node2;Job;835.node2.supernodexp.hpc;Job Queued at request of ctminh@node2.supernodexp.hpc, owner = ctminh@node2.supernodexp.hpc, job name = vast1, queue = workq
02/13/2018 17:56:56;0100;Server@node2;Req;;Type 1 request received from ctminh@node2.supernodexp.hpc, sock=16
02/13/2018 17:56:56;0100;Server@node2;Req;;Type 3 request received from ctminh@node2.supernodexp.hpc, sock=16
02/13/2018 17:56:56;0100;Server@node2;Req;;Type 5 request received from ctminh@node2.supernodexp.hpc, sock=16
02/13/2018 17:56:56;0100;Server@node2;Job;836.node2.supernodexp.hpc;enqueuing into workq, state 1 hop 1
02/13/2018 17:56:56;0008;Server@node2;Job;836.node2.supernodexp.hpc;Job Queued at request of ctminh@node2.supernodexp.hpc, owner = ctminh@node2.supernodexp.hpc, job name = histogram, queue = workq
02/13/2018 17:56:56;0100;Server@node2;Req;;Type 20 request received from Scheduler@node2.supernodexp.hpc, sock=20
02/13/2018 17:56:56;0100;Server@node2;Req;;Type 51 request received from Scheduler@node2.supernodexp.hpc, sock=20
02/13/2018 17:56:56;0100;Server@node2;Req;;Type 1 request received from ctminh@node2.supernodexp.hpc, sock=16
02/13/2018 17:56:56;0100;Server@node2;Req;;Type 3 request received from ctminh@node2.supernodexp.hpc, sock=16
02/13/2018 17:56:56;0100;Server@node2;Req;;Type 5 request received from ctminh@node2.supernodexp.hpc, sock=16
02/13/2018 17:56:56;0100;Server@node2;Job;837.node2.supernodexp.hpc;enqueuing into workq, state 1 hop 1
02/13/2018 17:56:56;0008;Server@node2;Job;837.node2.supernodexp.hpc;Job Queued at request of ctminh@node2.supernodexp.hpc, owner = ctminh@node2.supernodexp.hpc, job name = sweep, queue = workq
02/13/2018 17:56:56;0100;Server@node2;Req;;Type 1 request received from ctminh@node2.supernodexp.hpc, sock=16
02/13/2018 17:56:56;0100;Server@node2;Req;;Type 3 request received from ctminh@node2.supernodexp.hpc, sock=16
02/13/2018 17:56:56;0100;Server@node2;Req;;Type 5 request received from ctminh@node2.supernodexp.hpc, sock=16
02/13/2018 17:56:56;0100;Server@node2;Job;838.node2.supernodexp.hpc;enqueuing into workq, state 1 hop 1
02/13/2018 17:56:56;0008;Server@node2;Job;838.node2.supernodexp.hpc;Job Queued at request of ctminh@node2.supernodexp.hpc, owner = ctminh@node2.supernodexp.hpc, job name = qe_mic_test, queue = workq
02/13/2018 17:56:56;0100;Server@node2;Req;;Type 11 request received from Scheduler@node2.supernodexp.hpc, sock=20
02/13/2018 17:56:56;0008;Server@node2;Job;836.node2.supernodexp.hpc;Job Modified at request of Scheduler@node2.supernodexp.hpc
02/13/2018 17:56:56;0100;Server@node2;Req;;Type 11 request received from Scheduler@node2.supernodexp.hpc, sock=20
02/13/2018 17:56:56;0008;Server@node2;Job;834.node2.supernodexp.hpc;Job Modified at request of Scheduler@node2.supernodexp.hpc
02/13/2018 17:56:56;0100;Server@node2;Req;;Type 11 request received from Scheduler@node2.supernodexp.hpc, sock=20
02/13/2018 17:56:56;0008;Server@node2;Job;833.node2.supernodexp.hpc;Job Modified at request of Scheduler@node2.supernodexp.hpc
02/13/2018 17:56:56;0100;Server@node2;Req;;Type 11 request received from Scheduler@node2.supernodexp.hpc, sock=20
02/13/2018 17:56:56;0008;Server@node2;Job;835.node2.supernodexp.hpc;Job Modified at request of Scheduler@node2.supernodexp.hpc
02/13/2018 17:56:56;0040;Server@node2;Svr;node2.supernodexp.hpc;Scheduler sent command 1
02/13/2018 17:56:56;0040;Server@node2;Svr;node2.supernodexp.hpc;Scheduler sent command 0
02/13/2018 17:56:56;0100;Server@node2;Req;;Type 21 request received from Scheduler@node2.supernodexp.hpc, sock=20
02/13/2018 17:56:56;0100;Server@node2;Req;;Type 81 request received from Scheduler@node2.supernodexp.hpc, sock=20
02/13/2018 17:56:56;0100;Server@node2;Req;;Type 71 request received from Scheduler@node2.supernodexp.hpc, sock=20
02/13/2018 17:56:56;0100;Server@node2;Req;;Type 58 request received from Scheduler@node2.supernodexp.hpc, sock=20
02/13/2018 17:56:56;0100;Server@node2;Req;;Type 1 request received from ctminh@node2.supernodexp.hpc, sock=16
02/13/2018 17:56:56;0100;Server@node2;Req;;Type 3 request received from ctminh@node2.supernodexp.hpc, sock=16
02/13/2018 17:56:56;0100;Server@node2;Req;;Type 5 request received from ctminh@node2.supernodexp.hpc, sock=16
02/13/2018 17:56:56;0100;Server@node2;Job;839.node2.supernodexp.hpc;enqueuing into workq, state 1 hop 1
02/13/2018 17:56:56;0008;Server@node2;Job;839.node2.supernodexp.hpc;Job Queued at request of ctminh@node2.supernodexp.hpc, owner = ctminh@node2.supernodexp.hpc, job name = jacobi, queue = workq
02/13/2018 17:56:56;0100;Server@node2;Req;;Type 1 request received from ctminh@node2.supernodexp.hpc, sock=16
02/13/2018 17:56:56;0100;Server@node2;Req;;Type 3 request received from ctminh@node2.supernodexp.hpc, sock=16
02/13/2018 17:56:56;0100;Server@node2;Req;;Type 5 request received from ctminh@node2.supernodexp.hpc, sock=16
02/13/2018 17:56:56;0100;Server@node2;Job;840.node2.supernodexp.hpc;enqueuing into workq, state 1 hop 1
02/13/2018 17:56:56;0008;Server@node2;Job;840.node2.supernodexp.hpc;Job Queued at request of ctminh@node2.supernodexp.hpc, owner = ctminh@node2.supernodexp.hpc, job name = jacobi, queue = workq
02/13/2018 17:56:56;0100;Server@node2;Req;;Type 20 request received from Scheduler@node2.supernodexp.hpc, sock=20
02/13/2018 17:56:56;0100;Server@node2;Req;;Type 51 request received from Scheduler@node2.supernodexp.hpc, sock=20
02/13/2018 17:56:56;0100;Server@node2;Req;;Type 1 request received from ctminh@node2.supernodexp.hpc, sock=16
02/13/2018 17:56:56;0100;Server@node2;Req;;Type 3 request received from ctminh@node2.supernodexp.hpc, sock=16
02/13/2018 17:56:56;0100;Server@node2;Req;;Type 5 request received from ctminh@node2.supernodexp.hpc, sock=16
02/13/2018 17:56:56;0100;Server@node2;Job;841.node2.supernodexp.hpc;enqueuing into workq, state 1 hop 1
02/13/2018 17:56:56;0008;Server@node2;Job;841.node2.supernodexp.hpc;Job Queued at request of ctminh@node2.supernodexp.hpc, owner = ctminh@node2.supernodexp.hpc, job name = telemac1, queue = workq
02/13/2018 17:56:56;0100;Server@node2;Req;;Type 1 request received from ctminh@node2.supernodexp.hpc, sock=16
02/13/2018 17:56:56;0100;Server@node2;Req;;Type 3 request received from ctminh@node2.supernodexp.hpc, sock=16
02/13/2018 17:56:56;0100;Server@node2;Req;;Type 5 request received from ctminh@node2.supernodexp.hpc, sock=16
02/13/2018 17:56:56;0100;Server@node2;Job;842.node2.supernodexp.hpc;enqueuing into workq, state 1 hop 1
02/13/2018 17:56:56;0008;Server@node2;Job;842.node2.supernodexp.hpc;Job Queued at request of ctminh@node2.supernodexp.hpc, owner = ctminh@node2.supernodexp.hpc, job name = jacobi, queue = workq
02/13/2018 17:56:56;0100;Server@node2;Req;;Type 11 request received from Scheduler@node2.supernodexp.hpc, sock=20
02/13/2018 17:56:56;0008;Server@node2;Job;837.node2.supernodexp.hpc;Job Modified at request of Scheduler@node2.supernodexp.hpc
02/13/2018 17:56:56;0100;Server@node2;Req;;Type 11 request received from Scheduler@node2.supernodexp.hpc, sock=20
02/13/2018 17:56:56;0008;Server@node2;Job;839.node2.supernodexp.hpc;Job Modified at request of Scheduler@node2.supernodexp.hpc
02/13/2018 17:56:56;0100;Server@node2;Req;;Type 11 request received from Scheduler@node2.supernodexp.hpc, sock=20
02/13/2018 17:56:56;0008;Server@node2;Job;840.node2.supernodexp.hpc;Job Modified at request of Scheduler@node2.supernodexp.hpc
02/13/2018 17:56:56;0100;Server@node2;Req;;Type 11 request received from Scheduler@node2.supernodexp.hpc, sock=20
02/13/2018 17:56:56;0008;Server@node2;Job;838.node2.supernodexp.hpc;Job Modified at request of Scheduler@node2.supernodexp.hpc
02/13/2018 17:56:56;0040;Server@node2;Svr;node2.supernodexp.hpc;Scheduler sent command 1
02/13/2018 17:56:56;0040;Server@node2;Svr;node2.supernodexp.hpc;Scheduler sent command 0
02/13/2018 17:56:56;0100;Server@node2;Req;;Type 21 request received from Scheduler@node2.supernodexp.hpc, sock=20
02/13/2018 17:56:56;0100;Server@node2;Req;;Type 81 request received from Scheduler@node2.supernodexp.hpc, sock=20
02/13/2018 17:56:56;0100;Server@node2;Req;;Type 71 request received from Scheduler@node2.supernodexp.hpc, sock=20
02/13/2018 17:56:56;0100;Server@node2;Req;;Type 58 request received from Scheduler@node2.supernodexp.hpc, sock=20
02/13/2018 17:56:56;0100;Server@node2;Req;;Type 1 request received from ctminh@node2.supernodexp.hpc, sock=16
02/13/2018 17:56:56;0100;Server@node2;Req;;Type 3 request received from ctminh@node2.supernodexp.hpc, sock=16
02/13/2018 17:56:56;0100;Server@node2;Req;;Type 5 request received from ctminh@node2.supernodexp.hpc, sock=16
02/13/2018 17:56:56;0100;Server@node2;Job;843.node2.supernodexp.hpc;enqueuing into workq, state 1 hop 1
02/13/2018 17:56:56;0008;Server@node2;Job;843.node2.supernodexp.hpc;Job Queued at request of ctminh@node2.supernodexp.hpc, owner = ctminh@node2.supernodexp.hpc, job name = qe_mic_test, queue = workq
02/13/2018 17:56:56;0100;Server@node2;Req;;Type 1 request received from ctminh@node2.supernodexp.hpc, sock=16
02/13/2018 17:56:56;0100;Server@node2;Req;;Type 20 request received from Scheduler@node2.supernodexp.hpc, sock=20
02/13/2018 17:56:56;0100;Server@node2;Req;;Type 3 request received from ctminh@node2.supernodexp.hpc, sock=16
02/13/2018 17:56:56;0100;Server@node2;Req;;Type 51 request received from Scheduler@node2.supernodexp.hpc, sock=20
02/13/2018 17:56:56;0100;Server@node2;Req;;Type 5 request received from ctminh@node2.supernodexp.hpc, sock=16
02/13/2018 17:56:56;0100;Server@node2;Job;844.node2.supernodexp.hpc;enqueuing into workq, state 1 hop 1
02/13/2018 17:56:56;0008;Server@node2;Job;844.node2.supernodexp.hpc;Job Queued at request of ctminh@node2.supernodexp.hpc, owner = ctminh@node2.supernodexp.hpc, job name = matrix-x-vector, queue = workq
02/13/2018 17:56:56;0100;Server@node2;Req;;Type 11 request received from Scheduler@node2.supernodexp.hpc, sock=20
02/13/2018 17:56:56;0008;Server@node2;Job;842.node2.supernodexp.hpc;Job Modified at request of Scheduler@node2.supernodexp.hpc
02/13/2018 17:56:56;0100;Server@node2;Req;;Type 11 request received from Scheduler@node2.supernodexp.hpc, sock=20
02/13/2018 17:56:56;0008;Server@node2;Job;841.node2.supernodexp.hpc;Job Modified at request of Scheduler@node2.supernodexp.hpc
02/13/2018 17:56:56;0100;Server@node2;Req;;Type 11 request received from Scheduler@node2.supernodexp.hpc, sock=20
02/13/2018 17:56:56;0008;Server@node2;Job;843.node2.supernodexp.hpc;Job Modified at request of Scheduler@node2.supernodexp.hpc
02/13/2018 17:56:56;0040;Server@node2;Svr;node2.supernodexp.hpc;Scheduler sent command 1
02/13/2018 17:56:56;0040;Server@node2;Svr;node2.supernodexp.hpc;Scheduler sent command 0
02/13/2018 17:56:56;0100;Server@node2;Req;;Type 21 request received from Scheduler@node2.supernodexp.hpc, sock=20
02/13/2018 17:56:56;0100;Server@node2;Req;;Type 81 request received from Scheduler@node2.supernodexp.hpc, sock=20
02/13/2018 17:56:56;0100;Server@node2;Req;;Type 71 request received from Scheduler@node2.supernodexp.hpc, sock=20
02/13/2018 17:56:56;0100;Server@node2;Req;;Type 58 request received from Scheduler@node2.supernodexp.hpc, sock=20
02/13/2018 17:56:56;0100;Server@node2;Req;;Type 20 request received from Scheduler@node2.supernodexp.hpc, sock=20
02/13/2018 17:56:56;0100;Server@node2;Req;;Type 51 request received from Scheduler@node2.supernodexp.hpc, sock=20
02/13/2018 17:56:56;0100;Server@node2;Req;;Type 11 request received from Scheduler@node2.supernodexp.hpc, sock=20
02/13/2018 17:56:56;0008;Server@node2;Job;844.node2.supernodexp.hpc;Job Modified at request of Scheduler@node2.supernodexp.hpc
02/13/2018 17:56:59;0080;Server@node2;Job;811.node2.supernodexp.hpc;Obit received momhop:1 serverhop:1 state:4 substate:42
02/13/2018 17:57:00;0010;Server@node2;Job;811.node2.supernodexp.hpc;Exit_status=0 resources_used.cpupercent=100 resources_used.cput=00:00:04 resources_used.mem=0kb resources_used.ncpus=32 resources_used.vmem=0kb resources_used.walltime=00:00:04
02/13/2018 17:57:00;0100;Server@node2;Job;811.node2.supernodexp.hpc;dequeuing from workq, state 5
02/13/2018 17:57:00;0040;Server@node2;Svr;node2.supernodexp.hpc;Scheduler sent command 2
02/13/2018 17:57:00;0040;Server@node2;Svr;node2.supernodexp.hpc;Scheduler sent command 0
02/13/2018 17:57:00;0100;Server@node2;Req;;Type 21 request received from Scheduler@node2.supernodexp.hpc, sock=20
02/13/2018 17:57:00;0100;Server@node2;Req;;Type 81 request received from Scheduler@node2.supernodexp.hpc, sock=20
02/13/2018 17:57:00;0100;Server@node2;Req;;Type 71 request received from Scheduler@node2.supernodexp.hpc, sock=20
02/13/2018 17:57:00;0100;Server@node2;Req;;Type 58 request received from Scheduler@node2.supernodexp.hpc, sock=20
02/13/2018 17:57:00;0080;Server@node2;Job;806.node2.supernodexp.hpc;Obit received momhop:1 serverhop:1 state:4 substate:42
02/13/2018 17:57:00;0100;Server@node2;Req;;Type 20 request received from Scheduler@node2.supernodexp.hpc, sock=20
02/13/2018 17:57:00;0100;Server@node2;Req;;Type 51 request received from Scheduler@node2.supernodexp.hpc, sock=20
02/13/2018 17:57:00;0100;Server@node2;Req;;Type 23 request received from Scheduler@node2.supernodexp.hpc, sock=20
02/13/2018 17:57:00;0008;Server@node2;Job;825.node2.supernodexp.hpc;Job Run at request of Scheduler@node2.supernodexp.hpc on exec_vnode (node13:ncpus=16:mem=5242880kb)
02/13/2018 17:57:00;0001;Server@node2;Svr;Server@node2;Success (0) in req_runjob2, return value of svr_startjob is 0
02/13/2018 17:57:00;0100;Server@node2;Req;;Type 11 request received from Scheduler@node2.supernodexp.hpc, sock=20
02/13/2018 17:57:00;0008;Server@node2;Job;828.node2.supernodexp.hpc;Job Modified at request of Scheduler@node2.supernodexp.hpc
02/13/2018 17:57:01;0080;Server@node2;Job;825.node2.supernodexp.hpc;Obit received momhop:1 serverhop:1 state:4 substate:42
02/13/2018 17:57:01;0010;Server@node2;Job;806.node2.supernodexp.hpc;Exit_status=0 resources_used.cpupercent=1510 resources_used.cput=00:12:47 resources_used.mem=96868kb resources_used.ncpus=16 resources_used.vmem=1472432kb resources_used.walltime=00:00:50
02/13/2018 17:57:01;0100;Server@node2;Job;806.node2.supernodexp.hpc;dequeuing from workq, state 5
02/13/2018 17:57:01;0040;Server@node2;Svr;node2.supernodexp.hpc;Scheduler sent command 2
02/13/2018 17:57:01;0040;Server@node2;Svr;node2.supernodexp.hpc;Scheduler sent command 0
02/13/2018 17:57:01;0100;Server@node2;Req;;Type 21 request received from Scheduler@node2.supernodexp.hpc, sock=20
02/13/2018 17:57:01;0100;Server@node2;Req;;Type 81 request received from Scheduler@node2.supernodexp.hpc, sock=20
02/13/2018 17:57:01;0100;Server@node2;Req;;Type 71 request received from Scheduler@node2.supernodexp.hpc, sock=20
02/13/2018 17:57:01;0100;Server@node2;Req;;Type 58 request received from Scheduler@node2.supernodexp.hpc, sock=20
02/13/2018 17:57:01;0100;Server@node2;Req;;Type 20 request received from Scheduler@node2.supernodexp.hpc, sock=20
02/13/2018 17:57:01;0100;Server@node2;Req;;Type 51 request received from Scheduler@node2.supernodexp.hpc, sock=20
02/13/2018 17:57:01;0100;Server@node2;Req;;Type 23 request received from Scheduler@node2.supernodexp.hpc, sock=20
02/13/2018 17:57:01;0008;Server@node2;Job;828.node2.supernodexp.hpc;Job Run at request of Scheduler@node2.supernodexp.hpc on exec_vnode (node13:ncpus=24:mem=1048576kb)
02/13/2018 17:57:01;0001;Server@node2;Svr;Server@node2;Success (0) in req_runjob2, return value of svr_startjob is 0
02/13/2018 17:57:01;0100;Server@node2;Req;;Type 11 request received from Scheduler@node2.supernodexp.hpc, sock=20
02/13/2018 17:57:01;0008;Server@node2;Job;844.node2.supernodexp.hpc;Job Modified at request of Scheduler@node2.supernodexp.hpc
02/13/2018 17:57:02;0010;Server@node2;Job;825.node2.supernodexp.hpc;Exit_status=0 resources_used.cpupercent=800 resources_used.cput=00:00:08 resources_used.mem=0kb resources_used.ncpus=16 resources_used.vmem=0kb resources_used.walltime=00:00:00
02/13/2018 17:57:02;0100;Server@node2;Job;825.node2.supernodexp.hpc;dequeuing from workq, state 5
02/13/2018 17:57:02;0040;Server@node2;Svr;node2.supernodexp.hpc;Scheduler sent command 2
02/13/2018 17:57:02;0040;Server@node2;Svr;node2.supernodexp.hpc;Scheduler sent command 0
02/13/2018 17:57:02;0100;Server@node2;Req;;Type 21 request received from Scheduler@node2.supernodexp.hpc, sock=20
02/13/2018 17:57:02;0100;Server@node2;Req;;Type 81 request received from Scheduler@node2.supernodexp.hpc, sock=20
02/13/2018 17:57:02;0100;Server@node2;Req;;Type 71 request received from Scheduler@node2.supernodexp.hpc, sock=20
02/13/2018 17:57:02;0100;Server@node2;Req;;Type 58 request received from Scheduler@node2.supernodexp.hpc, sock=20
02/13/2018 17:57:02;0100;Server@node2;Req;;Type 20 request received from Scheduler@node2.supernodexp.hpc, sock=20
02/13/2018 17:57:02;0100;Server@node2;Req;;Type 51 request received from Scheduler@node2.supernodexp.hpc, sock=20
02/13/2018 17:57:02;0100;Server@node2;Req;;Type 23 request received from Scheduler@node2.supernodexp.hpc, sock=20
02/13/2018 17:57:02;0008;Server@node2;Job;844.node2.supernodexp.hpc;Job Run at request of Scheduler@node2.supernodexp.hpc on exec_vnode (node13:ncpus=16:mem=5242880kb)
02/13/2018 17:57:02;0001;Server@node2;Svr;Server@node2;Success (0) in req_runjob2, return value of svr_startjob is 0
02/13/2018 17:57:02;0100;Server@node2;Req;;Type 11 request received from Scheduler@node2.supernodexp.hpc, sock=20
02/13/2018 17:57:02;0008;Server@node2;Job;813.node2.supernodexp.hpc;Job Modified at request of Scheduler@node2.supernodexp.hpc
02/13/2018 17:57:03;0080;Server@node2;Job;828.node2.supernodexp.hpc;Obit received momhop:1 serverhop:1 state:4 substate:42
02/13/2018 17:57:03;0080;Server@node2;Job;844.node2.supernodexp.hpc;Obit received momhop:1 serverhop:1 state:4 substate:42
02/13/2018 17:57:04;0010;Server@node2;Job;828.node2.supernodexp.hpc;Exit_status=0 resources_used.cpupercent=703 resources_used.cput=00:00:38 resources_used.mem=1295532kb resources_used.ncpus=24 resources_used.vmem=3151056kb resources_used.walltime=00:00:02
02/13/2018 17:57:04;0100;Server@node2;Job;828.node2.supernodexp.hpc;dequeuing from workq, state 5
02/13/2018 17:57:04;0040;Server@node2;Svr;node2.supernodexp.hpc;Scheduler sent command 2
02/13/2018 17:57:04;0040;Server@node2;Svr;node2.supernodexp.hpc;Scheduler sent command 0
02/13/2018 17:57:04;0100;Server@node2;Req;;Type 21 request received from Scheduler@node2.supernodexp.hpc, sock=20
02/13/2018 17:57:04;0100;Server@node2;Req;;Type 81 request received from Scheduler@node2.supernodexp.hpc, sock=20
02/13/2018 17:57:04;0100;Server@node2;Req;;Type 71 request received from Scheduler@node2.supernodexp.hpc, sock=20
02/13/2018 17:57:04;0100;Server@node2;Req;;Type 58 request received from Scheduler@node2.supernodexp.hpc, sock=20
02/13/2018 17:57:04;0100;Server@node2;Req;;Type 20 request received from Scheduler@node2.supernodexp.hpc, sock=20
02/13/2018 17:57:04;0100;Server@node2;Req;;Type 51 request received from Scheduler@node2.supernodexp.hpc, sock=20
02/13/2018 17:57:04;0010;Server@node2;Job;844.node2.supernodexp.hpc;Exit_status=0 resources_used.cpupercent=1399 resources_used.cput=00:00:16 resources_used.mem=4208912kb resources_used.ncpus=16 resources_used.vmem=5511124kb resources_used.walltime=00:00:02
02/13/2018 17:57:04;0100;Server@node2;Job;844.node2.supernodexp.hpc;dequeuing from workq, state 5
02/13/2018 17:57:04;0100;Server@node2;Req;;Type 23 request received from Scheduler@node2.supernodexp.hpc, sock=20
02/13/2018 17:57:04;0008;Server@node2;Job;813.node2.supernodexp.hpc;Job Run at request of Scheduler@node2.supernodexp.hpc on exec_vnode (node13:ncpus=12:mem=1048576kb)
02/13/2018 17:57:04;0001;Server@node2;Svr;Server@node2;Success (0) in req_runjob2, return value of svr_startjob is 0
02/13/2018 17:57:04;0100;Server@node2;Req;;Type 23 request received from Scheduler@node2.supernodexp.hpc, sock=20
02/13/2018 17:57:04;0008;Server@node2;Job;821.node2.supernodexp.hpc;Job Run at request of Scheduler@node2.supernodexp.hpc on exec_vnode (node13:ncpus=12:mem=1048576kb)
02/13/2018 17:57:04;0001;Server@node2;Svr;Server@node2;Success (0) in req_runjob2, return value of svr_startjob is 0
02/13/2018 17:57:04;0100;Server@node2;Req;;Type 11 request received from Scheduler@node2.supernodexp.hpc, sock=20
02/13/2018 17:57:04;0008;Server@node2;Job;827.node2.supernodexp.hpc;Job Modified at request of Scheduler@node2.supernodexp.hpc
02/13/2018 17:57:04;0040;Server@node2;Svr;node2.supernodexp.hpc;Scheduler sent command 2
02/13/2018 17:57:04;0040;Server@node2;Svr;node2.supernodexp.hpc;Scheduler sent command 0
02/13/2018 17:57:04;0100;Server@node2;Req;;Type 21 request received from Scheduler@node2.supernodexp.hpc, sock=20
02/13/2018 17:57:04;0100;Server@node2;Req;;Type 81 request received from Scheduler@node2.supernodexp.hpc, sock=20
02/13/2018 17:57:04;0100;Server@node2;Req;;Type 71 request received from Scheduler@node2.supernodexp.hpc, sock=20
02/13/2018 17:57:04;0100;Server@node2;Req;;Type 58 request received from Scheduler@node2.supernodexp.hpc, sock=20
02/13/2018 17:57:04;0100;Server@node2;Req;;Type 20 request received from Scheduler@node2.supernodexp.hpc, sock=20
02/13/2018 17:57:04;0100;Server@node2;Req;;Type 51 request received from Scheduler@node2.supernodexp.hpc, sock=20
02/13/2018 17:57:04;0100;Server@node2;Req;;Type 23 request received from Scheduler@node2.supernodexp.hpc, sock=20
02/13/2018 17:57:04;0008;Server@node2;Job;827.node2.supernodexp.hpc;Job Run at request of Scheduler@node2.supernodexp.hpc on exec_vnode (node13:ncpus=12:mem=1048576kb)
02/13/2018 17:57:04;0001;Server@node2;Svr;Server@node2;Success (0) in req_runjob2, return value of svr_startjob is 0
02/13/2018 17:57:04;0100;Server@node2;Req;;Type 11 request received from Scheduler@node2.supernodexp.hpc, sock=20
02/13/2018 17:57:04;0008;Server@node2;Job;836.node2.supernodexp.hpc;Job Modified at request of Scheduler@node2.supernodexp.hpc
02/13/2018 17:57:12;0080;Server@node2;Job;813.node2.supernodexp.hpc;Obit received momhop:1 serverhop:1 state:4 substate:42
02/13/2018 17:57:13;0080;Server@node2;Job;821.node2.supernodexp.hpc;Obit received momhop:1 serverhop:1 state:4 substate:42
02/13/2018 17:57:13;0010;Server@node2;Job;813.node2.supernodexp.hpc;Exit_status=0 resources_used.cpupercent=1200 resources_used.cput=00:01:27 resources_used.mem=0kb resources_used.ncpus=12 resources_used.vmem=0kb resources_used.walltime=00:00:07
02/13/2018 17:57:13;0100;Server@node2;Job;813.node2.supernodexp.hpc;dequeuing from workq, state 5
02/13/2018 17:57:13;0040;Server@node2;Svr;node2.supernodexp.hpc;Scheduler sent command 2
02/13/2018 17:57:13;0040;Server@node2;Svr;node2.supernodexp.hpc;Scheduler sent command 0
02/13/2018 17:57:13;0100;Server@node2;Req;;Type 21 request received from Scheduler@node2.supernodexp.hpc, sock=20
02/13/2018 17:57:13;0100;Server@node2;Req;;Type 81 request received from Scheduler@node2.supernodexp.hpc, sock=20
02/13/2018 17:57:13;0100;Server@node2;Req;;Type 71 request received from Scheduler@node2.supernodexp.hpc, sock=20
02/13/2018 17:57:13;0100;Server@node2;Req;;Type 58 request received from Scheduler@node2.supernodexp.hpc, sock=20
02/13/2018 17:57:13;0100;Server@node2;Req;;Type 20 request received from Scheduler@node2.supernodexp.hpc, sock=20
02/13/2018 17:57:13;0100;Server@node2;Req;;Type 51 request received from Scheduler@node2.supernodexp.hpc, sock=20
02/13/2018 17:57:13;0100;Server@node2;Req;;Type 11 request received from Scheduler@node2.supernodexp.hpc, sock=20
02/13/2018 17:57:13;0008;Server@node2;Job;836.node2.supernodexp.hpc;Job Modified at request of Scheduler@node2.supernodexp.hpc
02/13/2018 17:57:13;0080;Server@node2;Job;827.node2.supernodexp.hpc;Obit received momhop:1 serverhop:1 state:4 substate:42
02/13/2018 17:57:14;0010;Server@node2;Job;821.node2.supernodexp.hpc;Exit_status=0 resources_used.cpupercent=1200 resources_used.cput=00:01:35 resources_used.mem=36436kb resources_used.ncpus=12 resources_used.vmem=1125532kb resources_used.walltime=00:00:08
02/13/2018 17:57:14;0100;Server@node2;Job;821.node2.supernodexp.hpc;dequeuing from workq, state 5
02/13/2018 17:57:14;0040;Server@node2;Svr;node2.supernodexp.hpc;Scheduler sent command 2
02/13/2018 17:57:14;0040;Server@node2;Svr;node2.supernodexp.hpc;Scheduler sent command 0
02/13/2018 17:57:14;0100;Server@node2;Req;;Type 21 request received from Scheduler@node2.supernodexp.hpc, sock=20
02/13/2018 17:57:14;0100;Server@node2;Req;;Type 81 request received from Scheduler@node2.supernodexp.hpc, sock=20
02/13/2018 17:57:14;0100;Server@node2;Req;;Type 71 request received from Scheduler@node2.supernodexp.hpc, sock=20
02/13/2018 17:57:14;0100;Server@node2;Req;;Type 58 request received from Scheduler@node2.supernodexp.hpc, sock=20
02/13/2018 17:57:14;0100;Server@node2;Req;;Type 20 request received from Scheduler@node2.supernodexp.hpc, sock=20
02/13/2018 17:57:14;0100;Server@node2;Req;;Type 51 request received from Scheduler@node2.supernodexp.hpc, sock=20
02/13/2018 17:57:14;0100;Server@node2;Req;;Type 23 request received from Scheduler@node2.supernodexp.hpc, sock=20
02/13/2018 17:57:14;0008;Server@node2;Job;836.node2.supernodexp.hpc;Job Run at request of Scheduler@node2.supernodexp.hpc on exec_vnode (node13:ncpus=32:mem=2097152kb)
02/13/2018 17:57:14;0001;Server@node2;Svr;Server@node2;Success (0) in req_runjob2, return value of svr_startjob is 0
02/13/2018 17:57:14;0100;Server@node2;Req;;Type 11 request received from Scheduler@node2.supernodexp.hpc, sock=20
02/13/2018 17:57:14;0008;Server@node2;Job;837.node2.supernodexp.hpc;Job Modified at request of Scheduler@node2.supernodexp.hpc
02/13/2018 17:57:14;0010;Server@node2;Job;827.node2.supernodexp.hpc;Exit_status=0 resources_used.cpupercent=1200 resources_used.cput=00:01:46 resources_used.mem=37844kb resources_used.ncpus=12 resources_used.vmem=1125532kb resources_used.walltime=00:00:09
02/13/2018 17:57:14;0100;Server@node2;Job;827.node2.supernodexp.hpc;dequeuing from workq, state 5
02/13/2018 17:57:14;0040;Server@node2;Svr;node2.supernodexp.hpc;Scheduler sent command 2
02/13/2018 17:57:14;0040;Server@node2;Svr;node2.supernodexp.hpc;Scheduler sent command 0
02/13/2018 17:57:14;0100;Server@node2;Req;;Type 21 request received from Scheduler@node2.supernodexp.hpc, sock=20
02/13/2018 17:57:14;0100;Server@node2;Req;;Type 81 request received from Scheduler@node2.supernodexp.hpc, sock=20
02/13/2018 17:57:14;0100;Server@node2;Req;;Type 71 request received from Scheduler@node2.supernodexp.hpc, sock=20
02/13/2018 17:57:14;0100;Server@node2;Req;;Type 58 request received from Scheduler@node2.supernodexp.hpc, sock=20
02/13/2018 17:57:15;0100;Server@node2;Req;;Type 20 request received from Scheduler@node2.supernodexp.hpc, sock=20
02/13/2018 17:57:15;0100;Server@node2;Req;;Type 51 request received from Scheduler@node2.supernodexp.hpc, sock=20
02/13/2018 17:57:15;0100;Server@node2;Req;;Type 23 request received from Scheduler@node2.supernodexp.hpc, sock=20
02/13/2018 17:57:15;0008;Server@node2;Job;837.node2.supernodexp.hpc;Job Run at request of Scheduler@node2.supernodexp.hpc on exec_vnode (node13:ncpus=8:mem=3145728kb)
02/13/2018 17:57:15;0001;Server@node2;Svr;Server@node2;Success (0) in req_runjob2, return value of svr_startjob is 0
02/13/2018 17:57:15;0100;Server@node2;Req;;Type 11 request received from Scheduler@node2.supernodexp.hpc, sock=20
02/13/2018 17:57:15;0008;Server@node2;Job;807.node2.supernodexp.hpc;Job Modified at request of Scheduler@node2.supernodexp.hpc
02/13/2018 17:57:16;0080;Server@node2;Job;837.node2.supernodexp.hpc;Obit received momhop:1 serverhop:1 state:4 substate:42
02/13/2018 17:57:17;0010;Server@node2;Job;837.node2.supernodexp.hpc;Exit_status=0 resources_used.cpupercent=450 resources_used.cput=00:00:09 resources_used.mem=0kb resources_used.ncpus=8 resources_used.vmem=0kb resources_used.walltime=00:00:02
02/13/2018 17:57:17;0100;Server@node2;Job;837.node2.supernodexp.hpc;dequeuing from workq, state 5
02/13/2018 17:57:17;0040;Server@node2;Svr;node2.supernodexp.hpc;Scheduler sent command 2
02/13/2018 17:57:17;0040;Server@node2;Svr;node2.supernodexp.hpc;Scheduler sent command 0
02/13/2018 17:57:17;0100;Server@node2;Req;;Type 21 request received from Scheduler@node2.supernodexp.hpc, sock=20
02/13/2018 17:57:17;0100;Server@node2;Req;;Type 81 request received from Scheduler@node2.supernodexp.hpc, sock=20
02/13/2018 17:57:17;0100;Server@node2;Req;;Type 71 request received from Scheduler@node2.supernodexp.hpc, sock=20
02/13/2018 17:57:17;0100;Server@node2;Req;;Type 58 request received from Scheduler@node2.supernodexp.hpc, sock=20
02/13/2018 17:57:17;0100;Server@node2;Req;;Type 20 request received from Scheduler@node2.supernodexp.hpc, sock=20
02/13/2018 17:57:17;0100;Server@node2;Req;;Type 51 request received from Scheduler@node2.supernodexp.hpc, sock=20
02/13/2018 17:57:17;0100;Server@node2;Req;;Type 23 request received from Scheduler@node2.supernodexp.hpc, sock=20
02/13/2018 17:57:17;0008;Server@node2;Job;807.node2.supernodexp.hpc;Job Run at request of Scheduler@node2.supernodexp.hpc on exec_vnode (node13:ncpus=12:mem=1048576kb)
02/13/2018 17:57:17;0001;Server@node2;Svr;Server@node2;Success (0) in req_runjob2, return value of svr_startjob is 0
02/13/2018 17:57:17;0100;Server@node2;Req;;Type 11 request received from Scheduler@node2.supernodexp.hpc, sock=20
02/13/2018 17:57:17;0008;Server@node2;Job;815.node2.supernodexp.hpc;Job Modified at request of Scheduler@node2.supernodexp.hpc
02/13/2018 17:57:18;0080;Server@node2;Job;836.node2.supernodexp.hpc;Obit received momhop:1 serverhop:1 state:4 substate:42
02/13/2018 17:57:19;0010;Server@node2;Job;836.node2.supernodexp.hpc;Exit_status=0 resources_used.cpupercent=100 resources_used.cput=00:00:04 resources_used.mem=536380kb resources_used.ncpus=32 resources_used.vmem=867312kb resources_used.walltime=00:00:04
02/13/2018 17:57:19;0100;Server@node2;Job;836.node2.supernodexp.hpc;dequeuing from workq, state 5
02/13/2018 17:57:19;0040;Server@node2;Svr;node2.supernodexp.hpc;Scheduler sent command 2
02/13/2018 17:57:19;0040;Server@node2;Svr;node2.supernodexp.hpc;Scheduler sent command 0
02/13/2018 17:57:19;0100;Server@node2;Req;;Type 21 request received from Scheduler@node2.supernodexp.hpc, sock=20
02/13/2018 17:57:19;0100;Server@node2;Req;;Type 81 request received from Scheduler@node2.supernodexp.hpc, sock=20
02/13/2018 17:57:19;0100;Server@node2;Req;;Type 71 request received from Scheduler@node2.supernodexp.hpc, sock=20
02/13/2018 17:57:19;0100;Server@node2;Req;;Type 58 request received from Scheduler@node2.supernodexp.hpc, sock=20
02/13/2018 17:57:19;0100;Server@node2;Req;;Type 20 request received from Scheduler@node2.supernodexp.hpc, sock=20
02/13/2018 17:57:19;0100;Server@node2;Req;;Type 51 request received from Scheduler@node2.supernodexp.hpc, sock=20
02/13/2018 17:57:19;0100;Server@node2;Req;;Type 23 request received from Scheduler@node2.supernodexp.hpc, sock=20
02/13/2018 17:57:19;0008;Server@node2;Job;815.node2.supernodexp.hpc;Job Run at request of Scheduler@node2.supernodexp.hpc on exec_vnode (node13:ncpus=12:mem=1048576kb)
02/13/2018 17:57:19;0001;Server@node2;Svr;Server@node2;Success (0) in req_runjob2, return value of svr_startjob is 0
02/13/2018 17:57:19;0100;Server@node2;Req;;Type 23 request received from Scheduler@node2.supernodexp.hpc, sock=20
02/13/2018 17:57:19;0008;Server@node2;Job;832.node2.supernodexp.hpc;Job Run at request of Scheduler@node2.supernodexp.hpc on exec_vnode (node13:ncpus=12:mem=1048576kb)
02/13/2018 17:57:19;0001;Server@node2;Svr;Server@node2;Success (0) in req_runjob2, return value of svr_startjob is 0
02/13/2018 17:57:19;0100;Server@node2;Req;;Type 11 request received from Scheduler@node2.supernodexp.hpc, sock=20
02/13/2018 17:57:19;0008;Server@node2;Job;826.node2.supernodexp.hpc;Job Modified at request of Scheduler@node2.supernodexp.hpc
02/13/2018 17:57:26;0080;Server@node2;Job;807.node2.supernodexp.hpc;Obit received momhop:1 serverhop:1 state:4 substate:42
02/13/2018 17:57:27;0010;Server@node2;Job;807.node2.supernodexp.hpc;Exit_status=0 resources_used.cpupercent=100 resources_used.cput=00:00:08 resources_used.mem=11408kb resources_used.ncpus=12 resources_used.vmem=343400kb resources_used.walltime=00:00:08
02/13/2018 17:57:27;0100;Server@node2;Job;807.node2.supernodexp.hpc;dequeuing from workq, state 5
02/13/2018 17:57:27;0040;Server@node2;Svr;node2.supernodexp.hpc;Scheduler sent command 2
02/13/2018 17:57:27;0040;Server@node2;Svr;node2.supernodexp.hpc;Scheduler sent command 0
02/13/2018 17:57:27;0100;Server@node2;Req;;Type 21 request received from Scheduler@node2.supernodexp.hpc, sock=20
02/13/2018 17:57:27;0100;Server@node2;Req;;Type 81 request received from Scheduler@node2.supernodexp.hpc, sock=20
02/13/2018 17:57:27;0100;Server@node2;Req;;Type 71 request received from Scheduler@node2.supernodexp.hpc, sock=20
02/13/2018 17:57:27;0100;Server@node2;Req;;Type 58 request received from Scheduler@node2.supernodexp.hpc, sock=20
02/13/2018 17:57:27;0100;Server@node2;Req;;Type 20 request received from Scheduler@node2.supernodexp.hpc, sock=20
02/13/2018 17:57:27;0100;Server@node2;Req;;Type 51 request received from Scheduler@node2.supernodexp.hpc, sock=20
02/13/2018 17:57:27;0100;Server@node2;Req;;Type 23 request received from Scheduler@node2.supernodexp.hpc, sock=20
02/13/2018 17:57:27;0008;Server@node2;Job;826.node2.supernodexp.hpc;Job Run at request of Scheduler@node2.supernodexp.hpc on exec_vnode (node13:ncpus=24:mem=2097152kb)
02/13/2018 17:57:27;0001;Server@node2;Svr;Server@node2;Success (0) in req_runjob2, return value of svr_startjob is 0
02/13/2018 17:57:27;0100;Server@node2;Req;;Type 11 request received from Scheduler@node2.supernodexp.hpc, sock=20
02/13/2018 17:57:27;0008;Server@node2;Job;834.node2.supernodexp.hpc;Job Modified at request of Scheduler@node2.supernodexp.hpc
02/13/2018 17:57:27;0080;Server@node2;Job;815.node2.supernodexp.hpc;Obit received momhop:1 serverhop:1 state:4 substate:42
02/13/2018 17:57:27;0080;Server@node2;Job;832.node2.supernodexp.hpc;Obit received momhop:1 serverhop:1 state:4 substate:42
02/13/2018 17:57:33;0010;Server@node2;Job;815.node2.supernodexp.hpc;Exit_status=0 resources_used.cpupercent=100 resources_used.cput=00:00:08 resources_used.mem=11628kb resources_used.ncpus=12 resources_used.vmem=343400kb resources_used.walltime=00:00:09
02/13/2018 17:57:33;0100;Server@node2;Job;815.node2.supernodexp.hpc;dequeuing from workq, state 5
02/13/2018 17:57:33;0040;Server@node2;Svr;node2.supernodexp.hpc;Scheduler sent command 2
02/13/2018 17:57:33;0040;Server@node2;Svr;node2.supernodexp.hpc;Scheduler sent command 0
02/13/2018 17:57:33;0100;Server@node2;Req;;Type 21 request received from Scheduler@node2.supernodexp.hpc, sock=20
02/13/2018 17:57:33;0100;Server@node2;Req;;Type 81 request received from Scheduler@node2.supernodexp.hpc, sock=20
02/13/2018 17:57:33;0100;Server@node2;Req;;Type 71 request received from Scheduler@node2.supernodexp.hpc, sock=20
02/13/2018 17:57:33;0100;Server@node2;Req;;Type 58 request received from Scheduler@node2.supernodexp.hpc, sock=20
02/13/2018 17:57:33;0100;Server@node2;Req;;Type 20 request received from Scheduler@node2.supernodexp.hpc, sock=20
02/13/2018 17:57:33;0100;Server@node2;Req;;Type 51 request received from Scheduler@node2.supernodexp.hpc, sock=20
02/13/2018 17:57:33;0100;Server@node2;Req;;Type 11 request received from Scheduler@node2.supernodexp.hpc, sock=20
02/13/2018 17:57:33;0008;Server@node2;Job;834.node2.supernodexp.hpc;Job Modified at request of Scheduler@node2.supernodexp.hpc
02/13/2018 17:57:33;0010;Server@node2;Job;832.node2.supernodexp.hpc;Exit_status=0 resources_used.cpupercent=100 resources_used.cput=00:00:08 resources_used.mem=11624kb resources_used.ncpus=12 resources_used.vmem=343400kb resources_used.walltime=00:00:08
02/13/2018 17:57:33;0100;Server@node2;Job;832.node2.supernodexp.hpc;dequeuing from workq, state 5
02/13/2018 17:57:33;0040;Server@node2;Svr;node2.supernodexp.hpc;Scheduler sent command 2
02/13/2018 17:57:33;0040;Server@node2;Svr;node2.supernodexp.hpc;Scheduler sent command 0
02/13/2018 17:57:33;0100;Server@node2;Req;;Type 21 request received from Scheduler@node2.supernodexp.hpc, sock=20
02/13/2018 17:57:33;0100;Server@node2;Req;;Type 81 request received from Scheduler@node2.supernodexp.hpc, sock=20
02/13/2018 17:57:33;0100;Server@node2;Req;;Type 71 request received from Scheduler@node2.supernodexp.hpc, sock=20
02/13/2018 17:57:33;0100;Server@node2;Req;;Type 58 request received from Scheduler@node2.supernodexp.hpc, sock=20
02/13/2018 17:57:34;0100;Server@node2;Req;;Type 20 request received from Scheduler@node2.supernodexp.hpc, sock=20
02/13/2018 17:57:34;0100;Server@node2;Req;;Type 51 request received from Scheduler@node2.supernodexp.hpc, sock=20
02/13/2018 17:57:34;0100;Server@node2;Req;;Type 23 request received from Scheduler@node2.supernodexp.hpc, sock=20
02/13/2018 17:57:34;0008;Server@node2;Job;834.node2.supernodexp.hpc;Job Run at request of Scheduler@node2.supernodexp.hpc on exec_vnode (node13:ncpus=16:mem=2097152kb)
02/13/2018 17:57:34;0001;Server@node2;Svr;Server@node2;Success (0) in req_runjob2, return value of svr_startjob is 0
02/13/2018 17:57:34;0100;Server@node2;Req;;Type 11 request received from Scheduler@node2.supernodexp.hpc, sock=20
02/13/2018 17:57:34;0008;Server@node2;Job;839.node2.supernodexp.hpc;Job Modified at request of Scheduler@node2.supernodexp.hpc
02/13/2018 17:57:46;0100;Server@node2;Req;;Type 1 request received from ctminh@node2.supernodexp.hpc, sock=16
02/13/2018 17:57:46;0100;Server@node2;Req;;Type 3 request received from ctminh@node2.supernodexp.hpc, sock=16
02/13/2018 17:57:46;0100;Server@node2;Req;;Type 5 request received from ctminh@node2.supernodexp.hpc, sock=16
02/13/2018 17:57:46;0100;Server@node2;Job;845.node2.supernodexp.hpc;enqueuing into workq, state 1 hop 1
02/13/2018 17:57:46;0008;Server@node2;Job;845.node2.supernodexp.hpc;Job Queued at request of ctminh@node2.supernodexp.hpc, owner = ctminh@node2.supernodexp.hpc, job name = qe_mic_test, queue = workq
02/13/2018 17:57:46;0040;Server@node2;Svr;node2.supernodexp.hpc;Scheduler sent command 1
02/13/2018 17:57:46;0040;Server@node2;Svr;node2.supernodexp.hpc;Scheduler sent command 0
02/13/2018 17:57:46;0100;Server@node2;Req;;Type 21 request received from Scheduler@node2.supernodexp.hpc, sock=20
02/13/2018 17:57:46;0100;Server@node2;Req;;Type 81 request received from Scheduler@node2.supernodexp.hpc, sock=20
02/13/2018 17:57:46;0100;Server@node2;Req;;Type 71 request received from Scheduler@node2.supernodexp.hpc, sock=20
02/13/2018 17:57:46;0100;Server@node2;Req;;Type 58 request received from Scheduler@node2.supernodexp.hpc, sock=20
02/13/2018 17:57:46;0100;Server@node2;Req;;Type 1 request received from ctminh@node2.supernodexp.hpc, sock=16
02/13/2018 17:57:46;0100;Server@node2;Req;;Type 3 request received from ctminh@node2.supernodexp.hpc, sock=16
02/13/2018 17:57:46;0100;Server@node2;Req;;Type 5 request received from ctminh@node2.supernodexp.hpc, sock=16
02/13/2018 17:57:46;0100;Server@node2;Job;846.node2.supernodexp.hpc;enqueuing into workq, state 1 hop 1
02/13/2018 17:57:46;0008;Server@node2;Job;846.node2.supernodexp.hpc;Job Queued at request of ctminh@node2.supernodexp.hpc, owner = ctminh@node2.supernodexp.hpc, job name = vast1, queue = workq
02/13/2018 17:57:46;0100;Server@node2;Req;;Type 1 request received from ctminh@node2.supernodexp.hpc, sock=16
02/13/2018 17:57:46;0100;Server@node2;Req;;Type 20 request received from Scheduler@node2.supernodexp.hpc, sock=20
02/13/2018 17:57:46;0100;Server@node2;Req;;Type 3 request received from ctminh@node2.supernodexp.hpc, sock=16
02/13/2018 17:57:46;0100;Server@node2;Req;;Type 51 request received from Scheduler@node2.supernodexp.hpc, sock=20
02/13/2018 17:57:46;0100;Server@node2;Req;;Type 5 request received from ctminh@node2.supernodexp.hpc, sock=16
02/13/2018 17:57:46;0100;Server@node2;Job;847.node2.supernodexp.hpc;enqueuing into workq, state 1 hop 1
02/13/2018 17:57:46;0008;Server@node2;Job;847.node2.supernodexp.hpc;Job Queued at request of ctminh@node2.supernodexp.hpc, owner = ctminh@node2.supernodexp.hpc, job name = sweep, queue = workq
02/13/2018 17:57:46;0100;Server@node2;Req;;Type 1 request received from ctminh@node2.supernodexp.hpc, sock=16
02/13/2018 17:57:46;0100;Server@node2;Req;;Type 3 request received from ctminh@node2.supernodexp.hpc, sock=16
02/13/2018 17:57:46;0100;Server@node2;Req;;Type 5 request received from ctminh@node2.supernodexp.hpc, sock=16
02/13/2018 17:57:46;0100;Server@node2;Job;848.node2.supernodexp.hpc;enqueuing into workq, state 1 hop 1
02/13/2018 17:57:46;0008;Server@node2;Job;848.node2.supernodexp.hpc;Job Queued at request of ctminh@node2.supernodexp.hpc, owner = ctminh@node2.supernodexp.hpc, job name = qe_mic_test, queue = workq
02/13/2018 17:57:46;0100;Server@node2;Req;;Type 1 request received from ctminh@node2.supernodexp.hpc, sock=16
02/13/2018 17:57:46;0100;Server@node2;Req;;Type 3 request received from ctminh@node2.supernodexp.hpc, sock=16
02/13/2018 17:57:46;0100;Server@node2;Req;;Type 5 request received from ctminh@node2.supernodexp.hpc, sock=16
02/13/2018 17:57:46;0100;Server@node2;Job;849.node2.supernodexp.hpc;enqueuing into workq, state 1 hop 1
02/13/2018 17:57:46;0008;Server@node2;Job;849.node2.supernodexp.hpc;Job Queued at request of ctminh@node2.supernodexp.hpc, owner = ctminh@node2.supernodexp.hpc, job name = qe_mic_test, queue = workq
02/13/2018 17:57:46;0100;Server@node2;Req;;Type 11 request received from Scheduler@node2.supernodexp.hpc, sock=20
02/13/2018 17:57:46;0008;Server@node2;Job;846.node2.supernodexp.hpc;Job Modified at request of Scheduler@node2.supernodexp.hpc
02/13/2018 17:57:46;0100;Server@node2;Req;;Type 11 request received from Scheduler@node2.supernodexp.hpc, sock=20
02/13/2018 17:57:46;0008;Server@node2;Job;845.node2.supernodexp.hpc;Job Modified at request of Scheduler@node2.supernodexp.hpc
02/13/2018 17:57:46;0040;Server@node2;Svr;node2.supernodexp.hpc;Scheduler sent command 1
02/13/2018 17:57:46;0040;Server@node2;Svr;node2.supernodexp.hpc;Scheduler sent command 0
02/13/2018 17:57:46;0100;Server@node2;Req;;Type 21 request received from Scheduler@node2.supernodexp.hpc, sock=20
02/13/2018 17:57:46;0100;Server@node2;Req;;Type 81 request received from Scheduler@node2.supernodexp.hpc, sock=20
02/13/2018 17:57:46;0100;Server@node2;Req;;Type 71 request received from Scheduler@node2.supernodexp.hpc, sock=20
02/13/2018 17:57:46;0100;Server@node2;Req;;Type 58 request received from Scheduler@node2.supernodexp.hpc, sock=20
02/13/2018 17:57:46;0100;Server@node2;Req;;Type 1 request received from ctminh@node2.supernodexp.hpc, sock=16
02/13/2018 17:57:46;0100;Server@node2;Req;;Type 3 request received from ctminh@node2.supernodexp.hpc, sock=16
02/13/2018 17:57:46;0100;Server@node2;Req;;Type 5 request received from ctminh@node2.supernodexp.hpc, sock=16
02/13/2018 17:57:46;0100;Server@node2;Job;850.node2.supernodexp.hpc;enqueuing into workq, state 1 hop 1
02/13/2018 17:57:46;0008;Server@node2;Job;850.node2.supernodexp.hpc;Job Queued at request of ctminh@node2.supernodexp.hpc, owner = ctminh@node2.supernodexp.hpc, job name = vectorization, queue = workq
02/13/2018 17:57:46;0100;Server@node2;Req;;Type 1 request received from ctminh@node2.supernodexp.hpc, sock=16
02/13/2018 17:57:46;0100;Server@node2;Req;;Type 20 request received from Scheduler@node2.supernodexp.hpc, sock=20
02/13/2018 17:57:46;0100;Server@node2;Req;;Type 3 request received from ctminh@node2.supernodexp.hpc, sock=16
02/13/2018 17:57:46;0100;Server@node2;Req;;Type 51 request received from Scheduler@node2.supernodexp.hpc, sock=20
02/13/2018 17:57:46;0100;Server@node2;Req;;Type 5 request received from ctminh@node2.supernodexp.hpc, sock=16
02/13/2018 17:57:46;0100;Server@node2;Job;851.node2.supernodexp.hpc;enqueuing into workq, state 1 hop 1
02/13/2018 17:57:46;0008;Server@node2;Job;851.node2.supernodexp.hpc;Job Queued at request of ctminh@node2.supernodexp.hpc, owner = ctminh@node2.supernodexp.hpc, job name = nbody, queue = workq
02/13/2018 17:57:46;0100;Server@node2;Req;;Type 1 request received from ctminh@node2.supernodexp.hpc, sock=16
02/13/2018 17:57:46;0100;Server@node2;Req;;Type 3 request received from ctminh@node2.supernodexp.hpc, sock=16
02/13/2018 17:57:46;0100;Server@node2;Req;;Type 5 request received from ctminh@node2.supernodexp.hpc, sock=16
02/13/2018 17:57:46;0100;Server@node2;Job;852.node2.supernodexp.hpc;enqueuing into workq, state 1 hop 1
02/13/2018 17:57:46;0008;Server@node2;Job;852.node2.supernodexp.hpc;Job Queued at request of ctminh@node2.supernodexp.hpc, owner = ctminh@node2.supernodexp.hpc, job name = sweep, queue = workq
02/13/2018 17:57:46;0100;Server@node2;Req;;Type 1 request received from ctminh@node2.supernodexp.hpc, sock=16
02/13/2018 17:57:46;0100;Server@node2;Req;;Type 3 request received from ctminh@node2.supernodexp.hpc, sock=16
02/13/2018 17:57:46;0100;Server@node2;Req;;Type 5 request received from ctminh@node2.supernodexp.hpc, sock=16
02/13/2018 17:57:46;0100;Server@node2;Job;853.node2.supernodexp.hpc;enqueuing into workq, state 1 hop 1
02/13/2018 17:57:46;0008;Server@node2;Job;853.node2.supernodexp.hpc;Job Queued at request of ctminh@node2.supernodexp.hpc, owner = ctminh@node2.supernodexp.hpc, job name = sweep, queue = workq
02/13/2018 17:57:46;0100;Server@node2;Req;;Type 23 request received from Scheduler@node2.supernodexp.hpc, sock=20
02/13/2018 17:57:46;0008;Server@node2;Job;847.node2.supernodexp.hpc;Job Run at request of Scheduler@node2.supernodexp.hpc on exec_vnode (node13:ncpus=8:mem=3145728kb)
02/13/2018 17:57:46;0001;Server@node2;Svr;Server@node2;Success (0) in req_runjob2, return value of svr_startjob is 0
02/13/2018 17:57:46;0100;Server@node2;Req;;Type 11 request received from Scheduler@node2.supernodexp.hpc, sock=20
02/13/2018 17:57:46;0008;Server@node2;Job;839.node2.supernodexp.hpc;Job Modified at request of Scheduler@node2.supernodexp.hpc
02/13/2018 17:57:46;0100;Server@node2;Req;;Type 11 request received from Scheduler@node2.supernodexp.hpc, sock=20
02/13/2018 17:57:46;0008;Server@node2;Job;848.node2.supernodexp.hpc;Job Modified at request of Scheduler@node2.supernodexp.hpc
02/13/2018 17:57:46;0100;Server@node2;Req;;Type 11 request received from Scheduler@node2.supernodexp.hpc, sock=20
02/13/2018 17:57:46;0008;Server@node2;Job;849.node2.supernodexp.hpc;Job Modified at request of Scheduler@node2.supernodexp.hpc
02/13/2018 17:57:46;0100;Server@node2;Req;;Type 11 request received from Scheduler@node2.supernodexp.hpc, sock=20
02/13/2018 17:57:46;0008;Server@node2;Job;850.node2.supernodexp.hpc;Job Modified at request of Scheduler@node2.supernodexp.hpc
02/13/2018 17:57:46;0040;Server@node2;Svr;node2.supernodexp.hpc;Scheduler sent command 1
02/13/2018 17:57:46;0040;Server@node2;Svr;node2.supernodexp.hpc;Scheduler sent command 0
02/13/2018 17:57:46;0100;Server@node2;Req;;Type 21 request received from Scheduler@node2.supernodexp.hpc, sock=20
02/13/2018 17:57:46;0100;Server@node2;Req;;Type 81 request received from Scheduler@node2.supernodexp.hpc, sock=20
02/13/2018 17:57:46;0100;Server@node2;Req;;Type 71 request received from Scheduler@node2.supernodexp.hpc, sock=20
02/13/2018 17:57:46;0100;Server@node2;Req;;Type 58 request received from Scheduler@node2.supernodexp.hpc, sock=20
02/13/2018 17:57:46;0100;Server@node2;Req;;Type 1 request received from ctminh@node2.supernodexp.hpc, sock=16
02/13/2018 17:57:46;0100;Server@node2;Req;;Type 3 request received from ctminh@node2.supernodexp.hpc, sock=16
02/13/2018 17:57:46;0100;Server@node2;Req;;Type 5 request received from ctminh@node2.supernodexp.hpc, sock=16
02/13/2018 17:57:46;0100;Server@node2;Job;854.node2.supernodexp.hpc;enqueuing into workq, state 1 hop 1
02/13/2018 17:57:46;0008;Server@node2;Job;854.node2.supernodexp.hpc;Job Queued at request of ctminh@node2.supernodexp.hpc, owner = ctminh@node2.supernodexp.hpc, job name = jacobi, queue = workq
02/13/2018 17:57:46;0100;Server@node2;Req;;Type 1 request received from ctminh@node2.supernodexp.hpc, sock=16
02/13/2018 17:57:46;0100;Server@node2;Req;;Type 3 request received from ctminh@node2.supernodexp.hpc, sock=16
02/13/2018 17:57:46;0100;Server@node2;Req;;Type 5 request received from ctminh@node2.supernodexp.hpc, sock=16
02/13/2018 17:57:46;0100;Server@node2;Job;855.node2.supernodexp.hpc;enqueuing into workq, state 1 hop 1
02/13/2018 17:57:46;0008;Server@node2;Job;855.node2.supernodexp.hpc;Job Queued at request of ctminh@node2.supernodexp.hpc, owner = ctminh@node2.supernodexp.hpc, job name = thread-affinity, queue = workq
02/13/2018 17:57:46;0100;Server@node2;Req;;Type 20 request received from Scheduler@node2.supernodexp.hpc, sock=20
02/13/2018 17:57:46;0100;Server@node2;Req;;Type 51 request received from Scheduler@node2.supernodexp.hpc, sock=20
02/13/2018 17:57:46;0100;Server@node2;Req;;Type 1 request received from ctminh@node2.supernodexp.hpc, sock=16
02/13/2018 17:57:46;0100;Server@node2;Req;;Type 3 request received from ctminh@node2.supernodexp.hpc, sock=16
02/13/2018 17:57:46;0100;Server@node2;Req;;Type 5 request received from ctminh@node2.supernodexp.hpc, sock=16
02/13/2018 17:57:46;0100;Server@node2;Job;856.node2.supernodexp.hpc;enqueuing into workq, state 1 hop 1
02/13/2018 17:57:46;0008;Server@node2;Job;856.node2.supernodexp.hpc;Job Queued at request of ctminh@node2.supernodexp.hpc, owner = ctminh@node2.supernodexp.hpc, job name = vectorization, queue = workq
02/13/2018 17:57:46;0100;Server@node2;Req;;Type 1 request received from ctminh@node2.supernodexp.hpc, sock=16
02/13/2018 17:57:46;0100;Server@node2;Req;;Type 3 request received from ctminh@node2.supernodexp.hpc, sock=16
02/13/2018 17:57:46;0100;Server@node2;Req;;Type 5 request received from ctminh@node2.supernodexp.hpc, sock=16
02/13/2018 17:57:46;0100;Server@node2;Job;857.node2.supernodexp.hpc;enqueuing into workq, state 1 hop 1
02/13/2018 17:57:46;0008;Server@node2;Job;857.node2.supernodexp.hpc;Job Queued at request of ctminh@node2.supernodexp.hpc, owner = ctminh@node2.supernodexp.hpc, job name = qe_mic_test, queue = workq
02/13/2018 17:57:46;0100;Server@node2;Req;;Type 11 request received from Scheduler@node2.supernodexp.hpc, sock=20
02/13/2018 17:57:46;0008;Server@node2;Job;852.node2.supernodexp.hpc;Job Modified at request of Scheduler@node2.supernodexp.hpc
02/13/2018 17:57:46;0100;Server@node2;Req;;Type 11 request received from Scheduler@node2.supernodexp.hpc, sock=20
02/13/2018 17:57:46;0008;Server@node2;Job;853.node2.supernodexp.hpc;Job Modified at request of Scheduler@node2.supernodexp.hpc
02/13/2018 17:57:46;0100;Server@node2;Req;;Type 11 request received from Scheduler@node2.supernodexp.hpc, sock=20
02/13/2018 17:57:46;0008;Server@node2;Job;851.node2.supernodexp.hpc;Job Modified at request of Scheduler@node2.supernodexp.hpc
02/13/2018 17:57:46;0100;Server@node2;Req;;Type 11 request received from Scheduler@node2.supernodexp.hpc, sock=20
02/13/2018 17:57:46;0008;Server@node2;Job;855.node2.supernodexp.hpc;Job Modified at request of Scheduler@node2.supernodexp.hpc
02/13/2018 17:57:46;0100;Server@node2;Req;;Type 11 request received from Scheduler@node2.supernodexp.hpc, sock=20
02/13/2018 17:57:46;0008;Server@node2;Job;854.node2.supernodexp.hpc;Job Modified at request of Scheduler@node2.supernodexp.hpc
02/13/2018 17:57:46;0040;Server@node2;Svr;node2.supernodexp.hpc;Scheduler sent command 1
02/13/2018 17:57:46;0040;Server@node2;Svr;node2.supernodexp.hpc;Scheduler sent command 0
02/13/2018 17:57:46;0100;Server@node2;Req;;Type 21 request received from Scheduler@node2.supernodexp.hpc, sock=20
02/13/2018 17:57:46;0100;Server@node2;Req;;Type 81 request received from Scheduler@node2.supernodexp.hpc, sock=20
02/13/2018 17:57:46;0100;Server@node2;Req;;Type 71 request received from Scheduler@node2.supernodexp.hpc, sock=20
02/13/2018 17:57:46;0100;Server@node2;Req;;Type 58 request received from Scheduler@node2.supernodexp.hpc, sock=20
02/13/2018 17:57:46;0100;Server@node2;Req;;Type 1 request received from ctminh@node2.supernodexp.hpc, sock=16
02/13/2018 17:57:46;0100;Server@node2;Req;;Type 3 request received from ctminh@node2.supernodexp.hpc, sock=16
02/13/2018 17:57:46;0100;Server@node2;Req;;Type 5 request received from ctminh@node2.supernodexp.hpc, sock=16
02/13/2018 17:57:46;0100;Server@node2;Job;858.node2.supernodexp.hpc;enqueuing into workq, state 1 hop 1
02/13/2018 17:57:46;0008;Server@node2;Job;858.node2.supernodexp.hpc;Job Queued at request of ctminh@node2.supernodexp.hpc, owner = ctminh@node2.supernodexp.hpc, job name = vast1, queue = workq
02/13/2018 17:57:46;0100;Server@node2;Req;;Type 1 request received from ctminh@node2.supernodexp.hpc, sock=16
02/13/2018 17:57:46;0100;Server@node2;Req;;Type 20 request received from Scheduler@node2.supernodexp.hpc, sock=20
02/13/2018 17:57:46;0100;Server@node2;Req;;Type 3 request received from ctminh@node2.supernodexp.hpc, sock=16
02/13/2018 17:57:46;0100;Server@node2;Req;;Type 51 request received from Scheduler@node2.supernodexp.hpc, sock=20
02/13/2018 17:57:46;0100;Server@node2;Req;;Type 5 request received from ctminh@node2.supernodexp.hpc, sock=16
02/13/2018 17:57:46;0100;Server@node2;Job;859.node2.supernodexp.hpc;enqueuing into workq, state 1 hop 1
02/13/2018 17:57:46;0008;Server@node2;Job;859.node2.supernodexp.hpc;Job Queued at request of ctminh@node2.supernodexp.hpc, owner = ctminh@node2.supernodexp.hpc, job name = telemac3, queue = workq
02/13/2018 17:57:46;0100;Server@node2;Req;;Type 1 request received from ctminh@node2.supernodexp.hpc, sock=16
02/13/2018 17:57:46;0100;Server@node2;Req;;Type 3 request received from ctminh@node2.supernodexp.hpc, sock=16
02/13/2018 17:57:46;0100;Server@node2;Req;;Type 5 request received from ctminh@node2.supernodexp.hpc, sock=16
02/13/2018 17:57:46;0100;Server@node2;Job;860.node2.supernodexp.hpc;enqueuing into workq, state 1 hop 1
02/13/2018 17:57:46;0008;Server@node2;Job;860.node2.supernodexp.hpc;Job Queued at request of ctminh@node2.supernodexp.hpc, owner = ctminh@node2.supernodexp.hpc, job name = qe_mic_test, queue = workq
02/13/2018 17:57:46;0100;Server@node2;Req;;Type 1 request received from ctminh@node2.supernodexp.hpc, sock=16
02/13/2018 17:57:46;0100;Server@node2;Req;;Type 3 request received from ctminh@node2.supernodexp.hpc, sock=16
02/13/2018 17:57:46;0100;Server@node2;Req;;Type 5 request received from ctminh@node2.supernodexp.hpc, sock=16
02/13/2018 17:57:46;0100;Server@node2;Job;861.node2.supernodexp.hpc;enqueuing into workq, state 1 hop 1
02/13/2018 17:57:46;0008;Server@node2;Job;861.node2.supernodexp.hpc;Job Queued at request of ctminh@node2.supernodexp.hpc, owner = ctminh@node2.supernodexp.hpc, job name = nbody, queue = workq
02/13/2018 17:57:46;0100;Server@node2;Req;;Type 11 request received from Scheduler@node2.supernodexp.hpc, sock=20
02/13/2018 17:57:46;0008;Server@node2;Job;856.node2.supernodexp.hpc;Job Modified at request of Scheduler@node2.supernodexp.hpc
02/13/2018 17:57:46;0100;Server@node2;Req;;Type 11 request received from Scheduler@node2.supernodexp.hpc, sock=20
02/13/2018 17:57:46;0008;Server@node2;Job;858.node2.supernodexp.hpc;Job Modified at request of Scheduler@node2.supernodexp.hpc
02/13/2018 17:57:46;0100;Server@node2;Req;;Type 11 request received from Scheduler@node2.supernodexp.hpc, sock=20
02/13/2018 17:57:46;0008;Server@node2;Job;857.node2.supernodexp.hpc;Job Modified at request of Scheduler@node2.supernodexp.hpc
02/13/2018 17:57:46;0040;Server@node2;Svr;node2.supernodexp.hpc;Scheduler sent command 1
02/13/2018 17:57:46;0040;Server@node2;Svr;node2.supernodexp.hpc;Scheduler sent command 0
02/13/2018 17:57:46;0100;Server@node2;Req;;Type 21 request received from Scheduler@node2.supernodexp.hpc, sock=20
02/13/2018 17:57:46;0100;Server@node2;Req;;Type 81 request received from Scheduler@node2.supernodexp.hpc, sock=20
02/13/2018 17:57:46;0100;Server@node2;Req;;Type 71 request received from Scheduler@node2.supernodexp.hpc, sock=20
02/13/2018 17:57:46;0100;Server@node2;Req;;Type 58 request received from Scheduler@node2.supernodexp.hpc, sock=20
02/13/2018 17:57:47;0100;Server@node2;Req;;Type 1 request received from ctminh@node2.supernodexp.hpc, sock=16
02/13/2018 17:57:47;0100;Server@node2;Req;;Type 3 request received from ctminh@node2.supernodexp.hpc, sock=16
02/13/2018 17:57:47;0100;Server@node2;Req;;Type 5 request received from ctminh@node2.supernodexp.hpc, sock=16
02/13/2018 17:57:47;0100;Server@node2;Job;862.node2.supernodexp.hpc;enqueuing into workq, state 1 hop 1
02/13/2018 17:57:47;0008;Server@node2;Job;862.node2.supernodexp.hpc;Job Queued at request of ctminh@node2.supernodexp.hpc, owner = ctminh@node2.supernodexp.hpc, job name = jacobi, queue = workq
02/13/2018 17:57:47;0100;Server@node2;Req;;Type 1 request received from ctminh@node2.supernodexp.hpc, sock=16
02/13/2018 17:57:47;0100;Server@node2;Req;;Type 3 request received from ctminh@node2.supernodexp.hpc, sock=16
02/13/2018 17:57:47;0100;Server@node2;Req;;Type 5 request received from ctminh@node2.supernodexp.hpc, sock=16
02/13/2018 17:57:47;0100;Server@node2;Job;863.node2.supernodexp.hpc;enqueuing into workq, state 1 hop 1
02/13/2018 17:57:47;0008;Server@node2;Job;863.node2.supernodexp.hpc;Job Queued at request of ctminh@node2.supernodexp.hpc, owner = ctminh@node2.supernodexp.hpc, job name = telemac3, queue = workq
02/13/2018 17:57:47;0100;Server@node2;Req;;Type 20 request received from Scheduler@node2.supernodexp.hpc, sock=20
02/13/2018 17:57:47;0100;Server@node2;Req;;Type 51 request received from Scheduler@node2.supernodexp.hpc, sock=20
02/13/2018 17:57:47;0100;Server@node2;Req;;Type 1 request received from ctminh@node2.supernodexp.hpc, sock=16
02/13/2018 17:57:47;0100;Server@node2;Req;;Type 3 request received from ctminh@node2.supernodexp.hpc, sock=16
02/13/2018 17:57:47;0100;Server@node2;Req;;Type 5 request received from ctminh@node2.supernodexp.hpc, sock=16
02/13/2018 17:57:47;0100;Server@node2;Job;864.node2.supernodexp.hpc;enqueuing into workq, state 1 hop 1
02/13/2018 17:57:47;0008;Server@node2;Job;864.node2.supernodexp.hpc;Job Queued at request of ctminh@node2.supernodexp.hpc, owner = ctminh@node2.supernodexp.hpc, job name = sweep, queue = workq
02/13/2018 17:57:47;0100;Server@node2;Req;;Type 1 request received from ctminh@node2.supernodexp.hpc, sock=16
02/13/2018 17:57:47;0100;Server@node2;Req;;Type 3 request received from ctminh@node2.supernodexp.hpc, sock=16
02/13/2018 17:57:47;0100;Server@node2;Req;;Type 5 request received from ctminh@node2.supernodexp.hpc, sock=16
02/13/2018 17:57:47;0100;Server@node2;Job;865.node2.supernodexp.hpc;enqueuing into workq, state 1 hop 1
02/13/2018 17:57:47;0008;Server@node2;Job;865.node2.supernodexp.hpc;Job Queued at request of ctminh@node2.supernodexp.hpc, owner = ctminh@node2.supernodexp.hpc, job name = vast1, queue = workq
02/13/2018 17:57:47;0100;Server@node2;Req;;Type 11 request received from Scheduler@node2.supernodexp.hpc, sock=20
02/13/2018 17:57:47;0008;Server@node2;Job;861.node2.supernodexp.hpc;Job Modified at request of Scheduler@node2.supernodexp.hpc
02/13/2018 17:57:47;0100;Server@node2;Req;;Type 11 request received from Scheduler@node2.supernodexp.hpc, sock=20
02/13/2018 17:57:47;0008;Server@node2;Job;862.node2.supernodexp.hpc;Job Modified at request of Scheduler@node2.supernodexp.hpc
02/13/2018 17:57:47;0100;Server@node2;Req;;Type 11 request received from Scheduler@node2.supernodexp.hpc, sock=20
02/13/2018 17:57:47;0008;Server@node2;Job;859.node2.supernodexp.hpc;Job Modified at request of Scheduler@node2.supernodexp.hpc
02/13/2018 17:57:47;0100;Server@node2;Req;;Type 11 request received from Scheduler@node2.supernodexp.hpc, sock=20
02/13/2018 17:57:47;0008;Server@node2;Job;863.node2.supernodexp.hpc;Job Modified at request of Scheduler@node2.supernodexp.hpc
02/13/2018 17:57:47;0100;Server@node2;Req;;Type 11 request received from Scheduler@node2.supernodexp.hpc, sock=20
02/13/2018 17:57:47;0008;Server@node2;Job;860.node2.supernodexp.hpc;Job Modified at request of Scheduler@node2.supernodexp.hpc
02/13/2018 17:57:47;0040;Server@node2;Svr;node2.supernodexp.hpc;Scheduler sent command 1
02/13/2018 17:57:47;0040;Server@node2;Svr;node2.supernodexp.hpc;Scheduler sent command 0
02/13/2018 17:57:47;0100;Server@node2;Req;;Type 21 request received from Scheduler@node2.supernodexp.hpc, sock=20
02/13/2018 17:57:47;0100;Server@node2;Req;;Type 81 request received from Scheduler@node2.supernodexp.hpc, sock=20
02/13/2018 17:57:47;0100;Server@node2;Req;;Type 71 request received from Scheduler@node2.supernodexp.hpc, sock=20
02/13/2018 17:57:47;0100;Server@node2;Req;;Type 58 request received from Scheduler@node2.supernodexp.hpc, sock=20
02/13/2018 17:57:47;0100;Server@node2;Req;;Type 1 request received from ctminh@node2.supernodexp.hpc, sock=16
02/13/2018 17:57:47;0100;Server@node2;Req;;Type 3 request received from ctminh@node2.supernodexp.hpc, sock=16
02/13/2018 17:57:47;0100;Server@node2;Req;;Type 5 request received from ctminh@node2.supernodexp.hpc, sock=16
02/13/2018 17:57:47;0100;Server@node2;Job;866.node2.supernodexp.hpc;enqueuing into workq, state 1 hop 1
02/13/2018 17:57:47;0008;Server@node2;Job;866.node2.supernodexp.hpc;Job Queued at request of ctminh@node2.supernodexp.hpc, owner = ctminh@node2.supernodexp.hpc, job name = jacobi, queue = workq
02/13/2018 17:57:47;0100;Server@node2;Req;;Type 1 request received from ctminh@node2.supernodexp.hpc, sock=16
02/13/2018 17:57:47;0100;Server@node2;Req;;Type 20 request received from Scheduler@node2.supernodexp.hpc, sock=20
02/13/2018 17:57:47;0100;Server@node2;Req;;Type 3 request received from ctminh@node2.supernodexp.hpc, sock=16
02/13/2018 17:57:47;0100;Server@node2;Req;;Type 5 request received from ctminh@node2.supernodexp.hpc, sock=16
02/13/2018 17:57:47;0100;Server@node2;Job;867.node2.supernodexp.hpc;enqueuing into workq, state 1 hop 1
02/13/2018 17:57:47;0008;Server@node2;Job;867.node2.supernodexp.hpc;Job Queued at request of ctminh@node2.supernodexp.hpc, owner = ctminh@node2.supernodexp.hpc, job name = histogram, queue = workq
02/13/2018 17:57:47;0100;Server@node2;Req;;Type 51 request received from Scheduler@node2.supernodexp.hpc, sock=20
02/13/2018 17:57:47;0100;Server@node2;Req;;Type 1 request received from ctminh@node2.supernodexp.hpc, sock=16
02/13/2018 17:57:47;0100;Server@node2;Req;;Type 3 request received from ctminh@node2.supernodexp.hpc, sock=16
02/13/2018 17:57:47;0100;Server@node2;Req;;Type 5 request received from ctminh@node2.supernodexp.hpc, sock=16
02/13/2018 17:57:47;0100;Server@node2;Job;868.node2.supernodexp.hpc;enqueuing into workq, state 1 hop 1
02/13/2018 17:57:47;0008;Server@node2;Job;868.node2.supernodexp.hpc;Job Queued at request of ctminh@node2.supernodexp.hpc, owner = ctminh@node2.supernodexp.hpc, job name = telemac3, queue = workq
02/13/2018 17:57:47;0100;Server@node2;Req;;Type 1 request received from ctminh@node2.supernodexp.hpc, sock=16
02/13/2018 17:57:47;0100;Server@node2;Req;;Type 3 request received from ctminh@node2.supernodexp.hpc, sock=16
02/13/2018 17:57:47;0100;Server@node2;Req;;Type 5 request received from ctminh@node2.supernodexp.hpc, sock=16
02/13/2018 17:57:47;0100;Server@node2;Job;869.node2.supernodexp.hpc;enqueuing into workq, state 1 hop 1
02/13/2018 17:57:47;0008;Server@node2;Job;869.node2.supernodexp.hpc;Job Queued at request of ctminh@node2.supernodexp.hpc, owner = ctminh@node2.supernodexp.hpc, job name = histogram, queue = workq
02/13/2018 17:57:47;0100;Server@node2;Req;;Type 11 request received from Scheduler@node2.supernodexp.hpc, sock=20
02/13/2018 17:57:47;0008;Server@node2;Job;864.node2.supernodexp.hpc;Job Modified at request of Scheduler@node2.supernodexp.hpc
02/13/2018 17:57:47;0100;Server@node2;Req;;Type 11 request received from Scheduler@node2.supernodexp.hpc, sock=20
02/13/2018 17:57:47;0008;Server@node2;Job;867.node2.supernodexp.hpc;Job Modified at request of Scheduler@node2.supernodexp.hpc
02/13/2018 17:57:47;0100;Server@node2;Req;;Type 11 request received from Scheduler@node2.supernodexp.hpc, sock=20
02/13/2018 17:57:47;0008;Server@node2;Job;866.node2.supernodexp.hpc;Job Modified at request of Scheduler@node2.supernodexp.hpc
02/13/2018 17:57:47;0100;Server@node2;Req;;Type 11 request received from Scheduler@node2.supernodexp.hpc, sock=20
02/13/2018 17:57:47;0008;Server@node2;Job;865.node2.supernodexp.hpc;Job Modified at request of Scheduler@node2.supernodexp.hpc
02/13/2018 17:57:47;0040;Server@node2;Svr;node2.supernodexp.hpc;Scheduler sent command 1
02/13/2018 17:57:47;0040;Server@node2;Svr;node2.supernodexp.hpc;Scheduler sent command 0
02/13/2018 17:57:47;0100;Server@node2;Req;;Type 21 request received from Scheduler@node2.supernodexp.hpc, sock=20
02/13/2018 17:57:47;0100;Server@node2;Req;;Type 81 request received from Scheduler@node2.supernodexp.hpc, sock=20
02/13/2018 17:57:47;0100;Server@node2;Req;;Type 71 request received from Scheduler@node2.supernodexp.hpc, sock=20
02/13/2018 17:57:47;0100;Server@node2;Req;;Type 58 request received from Scheduler@node2.supernodexp.hpc, sock=20
02/13/2018 17:57:47;0100;Server@node2;Req;;Type 1 request received from ctminh@node2.supernodexp.hpc, sock=16
02/13/2018 17:57:47;0100;Server@node2;Req;;Type 3 request received from ctminh@node2.supernodexp.hpc, sock=16
02/13/2018 17:57:47;0100;Server@node2;Req;;Type 5 request received from ctminh@node2.supernodexp.hpc, sock=16
02/13/2018 17:57:47;0100;Server@node2;Job;870.node2.supernodexp.hpc;enqueuing into workq, state 1 hop 1
02/13/2018 17:57:47;0008;Server@node2;Job;870.node2.supernodexp.hpc;Job Queued at request of ctminh@node2.supernodexp.hpc, owner = ctminh@node2.supernodexp.hpc, job name = jacobi, queue = workq
02/13/2018 17:57:47;0100;Server@node2;Req;;Type 1 request received from ctminh@node2.supernodexp.hpc, sock=16
02/13/2018 17:57:47;0100;Server@node2;Req;;Type 3 request received from ctminh@node2.supernodexp.hpc, sock=16
02/13/2018 17:57:47;0100;Server@node2;Req;;Type 5 request received from ctminh@node2.supernodexp.hpc, sock=16
02/13/2018 17:57:47;0100;Server@node2;Job;871.node2.supernodexp.hpc;enqueuing into workq, state 1 hop 1
02/13/2018 17:57:47;0008;Server@node2;Job;871.node2.supernodexp.hpc;Job Queued at request of ctminh@node2.supernodexp.hpc, owner = ctminh@node2.supernodexp.hpc, job name = histogram, queue = workq
02/13/2018 17:57:47;0100;Server@node2;Req;;Type 20 request received from Scheduler@node2.supernodexp.hpc, sock=20
02/13/2018 17:57:47;0100;Server@node2;Req;;Type 51 request received from Scheduler@node2.supernodexp.hpc, sock=20
02/13/2018 17:57:47;0100;Server@node2;Req;;Type 1 request received from ctminh@node2.supernodexp.hpc, sock=16
02/13/2018 17:57:47;0100;Server@node2;Req;;Type 3 request received from ctminh@node2.supernodexp.hpc, sock=16
02/13/2018 17:57:47;0100;Server@node2;Req;;Type 5 request received from ctminh@node2.supernodexp.hpc, sock=16
02/13/2018 17:57:47;0100;Server@node2;Job;872.node2.supernodexp.hpc;enqueuing into workq, state 1 hop 1
02/13/2018 17:57:47;0008;Server@node2;Job;872.node2.supernodexp.hpc;Job Queued at request of ctminh@node2.supernodexp.hpc, owner = ctminh@node2.supernodexp.hpc, job name = telemac3, queue = workq
02/13/2018 17:57:47;0100;Server@node2;Req;;Type 1 request received from ctminh@node2.supernodexp.hpc, sock=16
02/13/2018 17:57:47;0100;Server@node2;Req;;Type 3 request received from ctminh@node2.supernodexp.hpc, sock=16
02/13/2018 17:57:47;0100;Server@node2;Req;;Type 5 request received from ctminh@node2.supernodexp.hpc, sock=16
02/13/2018 17:57:47;0100;Server@node2;Job;873.node2.supernodexp.hpc;enqueuing into workq, state 1 hop 1
02/13/2018 17:57:47;0008;Server@node2;Job;873.node2.supernodexp.hpc;Job Queued at request of ctminh@node2.supernodexp.hpc, owner = ctminh@node2.supernodexp.hpc, job name = histogram, queue = workq
02/13/2018 17:57:47;0100;Server@node2;Req;;Type 11 request received from Scheduler@node2.supernodexp.hpc, sock=20
02/13/2018 17:57:47;0008;Server@node2;Job;869.node2.supernodexp.hpc;Job Modified at request of Scheduler@node2.supernodexp.hpc
02/13/2018 17:57:47;0100;Server@node2;Req;;Type 11 request received from Scheduler@node2.supernodexp.hpc, sock=20
02/13/2018 17:57:47;0008;Server@node2;Job;871.node2.supernodexp.hpc;Job Modified at request of Scheduler@node2.supernodexp.hpc
02/13/2018 17:57:47;0100;Server@node2;Req;;Type 11 request received from Scheduler@node2.supernodexp.hpc, sock=20
02/13/2018 17:57:47;0008;Server@node2;Job;870.node2.supernodexp.hpc;Job Modified at request of Scheduler@node2.supernodexp.hpc
02/13/2018 17:57:47;0100;Server@node2;Req;;Type 11 request received from Scheduler@node2.supernodexp.hpc, sock=20
02/13/2018 17:57:47;0008;Server@node2;Job;868.node2.supernodexp.hpc;Job Modified at request of Scheduler@node2.supernodexp.hpc
02/13/2018 17:57:47;0040;Server@node2;Svr;node2.supernodexp.hpc;Scheduler sent command 1
02/13/2018 17:57:47;0040;Server@node2;Svr;node2.supernodexp.hpc;Scheduler sent command 0
02/13/2018 17:57:47;0100;Server@node2;Req;;Type 21 request received from Scheduler@node2.supernodexp.hpc, sock=20
02/13/2018 17:57:47;0100;Server@node2;Req;;Type 81 request received from Scheduler@node2.supernodexp.hpc, sock=20
02/13/2018 17:57:47;0100;Server@node2;Req;;Type 71 request received from Scheduler@node2.supernodexp.hpc, sock=20
02/13/2018 17:57:47;0100;Server@node2;Req;;Type 58 request received from Scheduler@node2.supernodexp.hpc, sock=20
02/13/2018 17:57:47;0100;Server@node2;Req;;Type 1 request received from ctminh@node2.supernodexp.hpc, sock=16
02/13/2018 17:57:47;0100;Server@node2;Req;;Type 3 request received from ctminh@node2.supernodexp.hpc, sock=16
02/13/2018 17:57:47;0100;Server@node2;Req;;Type 5 request received from ctminh@node2.supernodexp.hpc, sock=16
02/13/2018 17:57:47;0100;Server@node2;Job;874.node2.supernodexp.hpc;enqueuing into workq, state 1 hop 1
02/13/2018 17:57:47;0008;Server@node2;Job;874.node2.supernodexp.hpc;Job Queued at request of ctminh@node2.supernodexp.hpc, owner = ctminh@node2.supernodexp.hpc, job name = vectorization, queue = workq
02/13/2018 17:57:47;0100;Server@node2;Req;;Type 1 request received from ctminh@node2.supernodexp.hpc, sock=16
02/13/2018 17:57:47;0100;Server@node2;Req;;Type 3 request received from ctminh@node2.supernodexp.hpc, sock=16
02/13/2018 17:57:47;0100;Server@node2;Req;;Type 5 request received from ctminh@node2.supernodexp.hpc, sock=16
02/13/2018 17:57:47;0100;Server@node2;Job;875.node2.supernodexp.hpc;enqueuing into workq, state 1 hop 1
02/13/2018 17:57:47;0008;Server@node2;Job;875.node2.supernodexp.hpc;Job Queued at request of ctminh@node2.supernodexp.hpc, owner = ctminh@node2.supernodexp.hpc, job name = lu-decomp, queue = workq
02/13/2018 17:57:47;0100;Server@node2;Req;;Type 20 request received from Scheduler@node2.supernodexp.hpc, sock=20
02/13/2018 17:57:47;0100;Server@node2;Req;;Type 51 request received from Scheduler@node2.supernodexp.hpc, sock=20
02/13/2018 17:57:47;0100;Server@node2;Req;;Type 1 request received from ctminh@node2.supernodexp.hpc, sock=16
02/13/2018 17:57:47;0100;Server@node2;Req;;Type 3 request received from ctminh@node2.supernodexp.hpc, sock=16
02/13/2018 17:57:47;0100;Server@node2;Req;;Type 5 request received from ctminh@node2.supernodexp.hpc, sock=16
02/13/2018 17:57:47;0100;Server@node2;Job;876.node2.supernodexp.hpc;enqueuing into workq, state 1 hop 1
02/13/2018 17:57:47;0008;Server@node2;Job;876.node2.supernodexp.hpc;Job Queued at request of ctminh@node2.supernodexp.hpc, owner = ctminh@node2.supernodexp.hpc, job name = jacobi, queue = workq
02/13/2018 17:57:47;0100;Server@node2;Req;;Type 1 request received from ctminh@node2.supernodexp.hpc, sock=16
02/13/2018 17:57:47;0100;Server@node2;Req;;Type 3 request received from ctminh@node2.supernodexp.hpc, sock=16
02/13/2018 17:57:47;0100;Server@node2;Req;;Type 5 request received from ctminh@node2.supernodexp.hpc, sock=16
02/13/2018 17:57:47;0100;Server@node2;Job;877.node2.supernodexp.hpc;enqueuing into workq, state 1 hop 1
02/13/2018 17:57:47;0008;Server@node2;Job;877.node2.supernodexp.hpc;Job Queued at request of ctminh@node2.supernodexp.hpc, owner = ctminh@node2.supernodexp.hpc, job name = telemac2, queue = workq
02/13/2018 17:57:47;0100;Server@node2;Req;;Type 11 request received from Scheduler@node2.supernodexp.hpc, sock=20
02/13/2018 17:57:47;0008;Server@node2;Job;850.node2.supernodexp.hpc;Job Modified at request of Scheduler@node2.supernodexp.hpc
02/13/2018 17:57:47;0100;Server@node2;Req;;Type 11 request received from Scheduler@node2.supernodexp.hpc, sock=20
02/13/2018 17:57:47;0008;Server@node2;Job;873.node2.supernodexp.hpc;Job Modified at request of Scheduler@node2.supernodexp.hpc
02/13/2018 17:57:47;0100;Server@node2;Req;;Type 11 request received from Scheduler@node2.supernodexp.hpc, sock=20
02/13/2018 17:57:47;0008;Server@node2;Job;874.node2.supernodexp.hpc;Job Modified at request of Scheduler@node2.supernodexp.hpc
02/13/2018 17:57:47;0100;Server@node2;Req;;Type 11 request received from Scheduler@node2.supernodexp.hpc, sock=20
02/13/2018 17:57:47;0008;Server@node2;Job;872.node2.supernodexp.hpc;Job Modified at request of Scheduler@node2.supernodexp.hpc
02/13/2018 17:57:47;0100;Server@node2;Req;;Type 11 request received from Scheduler@node2.supernodexp.hpc, sock=20
02/13/2018 17:57:47;0008;Server@node2;Job;875.node2.supernodexp.hpc;Job Modified at request of Scheduler@node2.supernodexp.hpc
02/13/2018 17:57:47;0040;Server@node2;Svr;node2.supernodexp.hpc;Scheduler sent command 1
02/13/2018 17:57:47;0040;Server@node2;Svr;node2.supernodexp.hpc;Scheduler sent command 0
02/13/2018 17:57:47;0100;Server@node2;Req;;Type 21 request received from Scheduler@node2.supernodexp.hpc, sock=20
02/13/2018 17:57:47;0100;Server@node2;Req;;Type 81 request received from Scheduler@node2.supernodexp.hpc, sock=20
02/13/2018 17:57:47;0100;Server@node2;Req;;Type 71 request received from Scheduler@node2.supernodexp.hpc, sock=20
02/13/2018 17:57:47;0100;Server@node2;Req;;Type 58 request received from Scheduler@node2.supernodexp.hpc, sock=20
02/13/2018 17:57:47;0100;Server@node2;Req;;Type 1 request received from ctminh@node2.supernodexp.hpc, sock=16
02/13/2018 17:57:47;0100;Server@node2;Req;;Type 3 request received from ctminh@node2.supernodexp.hpc, sock=16
02/13/2018 17:57:47;0100;Server@node2;Req;;Type 5 request received from ctminh@node2.supernodexp.hpc, sock=16
02/13/2018 17:57:47;0100;Server@node2;Job;878.node2.supernodexp.hpc;enqueuing into workq, state 1 hop 1
02/13/2018 17:57:47;0008;Server@node2;Job;878.node2.supernodexp.hpc;Job Queued at request of ctminh@node2.supernodexp.hpc, owner = ctminh@node2.supernodexp.hpc, job name = nbody, queue = workq
02/13/2018 17:57:47;0100;Server@node2;Req;;Type 1 request received from ctminh@node2.supernodexp.hpc, sock=16
02/13/2018 17:57:47;0100;Server@node2;Req;;Type 3 request received from ctminh@node2.supernodexp.hpc, sock=16
02/13/2018 17:57:47;0100;Server@node2;Req;;Type 5 request received from ctminh@node2.supernodexp.hpc, sock=16
02/13/2018 17:57:47;0100;Server@node2;Job;879.node2.supernodexp.hpc;enqueuing into workq, state 1 hop 1
02/13/2018 17:57:47;0008;Server@node2;Job;879.node2.supernodexp.hpc;Job Queued at request of ctminh@node2.supernodexp.hpc, owner = ctminh@node2.supernodexp.hpc, job name = vectorization, queue = workq
02/13/2018 17:57:47;0100;Server@node2;Req;;Type 20 request received from Scheduler@node2.supernodexp.hpc, sock=20
02/13/2018 17:57:47;0100;Server@node2;Req;;Type 51 request received from Scheduler@node2.supernodexp.hpc, sock=20
02/13/2018 17:57:47;0100;Server@node2;Req;;Type 1 request received from ctminh@node2.supernodexp.hpc, sock=16
02/13/2018 17:57:47;0100;Server@node2;Req;;Type 3 request received from ctminh@node2.supernodexp.hpc, sock=16
02/13/2018 17:57:47;0100;Server@node2;Req;;Type 5 request received from ctminh@node2.supernodexp.hpc, sock=16
02/13/2018 17:57:47;0100;Server@node2;Job;880.node2.supernodexp.hpc;enqueuing into workq, state 1 hop 1
02/13/2018 17:57:47;0008;Server@node2;Job;880.node2.supernodexp.hpc;Job Queued at request of ctminh@node2.supernodexp.hpc, owner = ctminh@node2.supernodexp.hpc, job name = histogram, queue = workq
02/13/2018 17:57:47;0100;Server@node2;Req;;Type 1 request received from ctminh@node2.supernodexp.hpc, sock=16
02/13/2018 17:57:47;0100;Server@node2;Req;;Type 3 request received from ctminh@node2.supernodexp.hpc, sock=16
02/13/2018 17:57:47;0100;Server@node2;Req;;Type 5 request received from ctminh@node2.supernodexp.hpc, sock=16
02/13/2018 17:57:47;0100;Server@node2;Job;881.node2.supernodexp.hpc;enqueuing into workq, state 1 hop 1
02/13/2018 17:57:47;0008;Server@node2;Job;881.node2.supernodexp.hpc;Job Queued at request of ctminh@node2.supernodexp.hpc, owner = ctminh@node2.supernodexp.hpc, job name = telemac3, queue = workq
02/13/2018 17:57:47;0100;Server@node2;Req;;Type 11 request received from Scheduler@node2.supernodexp.hpc, sock=20
02/13/2018 17:57:47;0008;Server@node2;Job;879.node2.supernodexp.hpc;Job Modified at request of Scheduler@node2.supernodexp.hpc
02/13/2018 17:57:47;0100;Server@node2;Req;;Type 11 request received from Scheduler@node2.supernodexp.hpc, sock=20
02/13/2018 17:57:47;0008;Server@node2;Job;878.node2.supernodexp.hpc;Job Modified at request of Scheduler@node2.supernodexp.hpc
02/13/2018 17:57:47;0100;Server@node2;Req;;Type 11 request received from Scheduler@node2.supernodexp.hpc, sock=20
02/13/2018 17:57:47;0008;Server@node2;Job;876.node2.supernodexp.hpc;Job Modified at request of Scheduler@node2.supernodexp.hpc
02/13/2018 17:57:47;0100;Server@node2;Req;;Type 11 request received from Scheduler@node2.supernodexp.hpc, sock=20
02/13/2018 17:57:47;0008;Server@node2;Job;877.node2.supernodexp.hpc;Job Modified at request of Scheduler@node2.supernodexp.hpc
02/13/2018 17:57:47;0040;Server@node2;Svr;node2.supernodexp.hpc;Scheduler sent command 1
02/13/2018 17:57:47;0040;Server@node2;Svr;node2.supernodexp.hpc;Scheduler sent command 0
02/13/2018 17:57:47;0100;Server@node2;Req;;Type 21 request received from Scheduler@node2.supernodexp.hpc, sock=20
02/13/2018 17:57:47;0100;Server@node2;Req;;Type 81 request received from Scheduler@node2.supernodexp.hpc, sock=20
02/13/2018 17:57:47;0100;Server@node2;Req;;Type 71 request received from Scheduler@node2.supernodexp.hpc, sock=20
02/13/2018 17:57:47;0100;Server@node2;Req;;Type 58 request received from Scheduler@node2.supernodexp.hpc, sock=20
02/13/2018 17:57:47;0100;Server@node2;Req;;Type 1 request received from ctminh@node2.supernodexp.hpc, sock=16
02/13/2018 17:57:47;0100;Server@node2;Hook;_pbs_python_event_set;Restarting Python interpreter to reduce mem usage
02/13/2018 17:57:47;0100;Server@node2;Svr;Server@node2;--> Stopping Python interpreter <--
02/13/2018 17:57:47;0100;Server@node2;Svr;Server@node2;--> Python Interpreter started, compiled with version:'2.7.5' <--
02/13/2018 17:57:47;0100;Server@node2;Svr;Server@node2;sys.modules= {'pbs.v1._svr_types': <module 'pbs.v1._svr_types' from '/opt/pbs/lib/python/altair/pbs/v1/_svr_types.pyo'>, 'copy_reg': <module 'copy_reg' from '/usr/lib64/python2.7/copy_reg.pyo'>, 'pbs.v1._pbs_v1': None, '__main__': <module '__main__' (built-in)>, '__builtin__': <module '__builtin__' (built-in)>, '_pbs_v1.svr_types': <module '_pbs_v1.svr_types' (built-in)>, 'encodings': <module 'encodings' from '/usr/lib64/python2.7/encodings/__init__.pyo'>, 'encodings.encodings': None, 'abc': <module 'abc' from '/usr/lib64/python2.7/abc.pyo'>, 'pbs._pbs_v1': None, 'posixpath': <module 'posixpath' from '/usr/lib64/python2.7/posixpath.pyo'>, '_weakrefset': <module '_weakrefset' from '/usr/lib64/python2.7/_weakrefset.pyo'>, 'pbs.v1': <module 'pbs.v1' from '/opt/pbs/lib/python/altair/pbs/v1/__init__.pyo'>, 'errno': <module 'errno' (built-in)>, 'encodings.codecs': None, 'pbs.v1._export_types': <module 'pbs.v1._export_types' from '/opt/pbs/lib/python/altair/pbs/v1/_export_types.pyo'>, 'pbs.v1.os': None, '_abcoll': <module '_abcoll' from '/usr/lib64/python2.7/_abcoll.pyo'>, 'os.path': <module 'posixpath' from '/usr/lib64/python2.7/posixpath.pyo'>, 'UserDict': <module 'UserDict' from '/usr/lib64/python2.7/UserDict.pyo'>, '_warnings': <module '_warnings' (built-in)>, 'genericpath': <module 'genericpath' from '/usr/lib64/python2.7/genericpath.pyo'>, 'stat': <module 'stat' from '/usr/lib64/python2.7/stat.pyo'>, 'zipimport': <module 'zipimport' (built-in)>, 'encodings.__builtin__': None, 'pbs.pbs': None, 'warnings': <module 'warnings' from '/usr/lib64/python2.7/warnings.pyo'>, '_codecs': <module '_codecs' (built-in)>, 'encodings.ascii': <module 'encodings.ascii' from '/usr/lib64/python2.7/encodings/ascii.pyo'>, 'sys': <module 'sys' (built-in)>, 'pbs.v1._base_types': <module 'pbs.v1._base_types' from '/opt/pbs/lib/python/altair/pbs/v1/_base_types.pyo'>, 'pbs.v1.sys': None, 'codecs': <module 'codecs' from '/usr/lib64/python2.7/codecs.pyo'>, 'types': <module 'types' from '/usr/lib64/python2.7/types.pyo'>, 'pbs': <module 'pbs' from '/opt/pbs/lib/python/altair/pbs/__init__.pyo'>, 'os': <module 'os' from '/usr/lib64/python2.7/os.pyo'>, 'signal': <module 'signal' (built-in)>, 'linecache': <module 'linecache' from '/usr/lib64/python2.7/linecache.pyo'>, '_pbs_v1': <module '_pbs_v1' (built-in)>, 'posix': <module 'posix' (built-in)>, 'encodings.aliases': <module 'encodings.aliases' from '/usr/lib64/python2.7/encodings/aliases.pyo'>, 'exceptions': <module 'exceptions' (built-in)>, 'pbs.v1._exc_types': <module 'pbs.v1._exc_types' from '/opt/pbs/lib/python/altair/pbs/v1/_exc_types.pyo'>, '_weakref': <module '_weakref' (built-in)>}
02/13/2018 17:57:47;0106;Server@node2;Svr;Server@node2;BEGIN setting up all resource attributes 
02/13/2018 17:57:47;0106;Server@node2;Svr;Server@node2;DONE setting up all resource attributes, number set <51>
02/13/2018 17:57:47;0106;Server@node2;Svr;Server@node2;BEGIN setting up all queue attributes 
02/13/2018 17:57:47;0106;Server@node2;Svr;Server@node2;DONE setting up all queue attributes, number set <55>
02/13/2018 17:57:47;0106;Server@node2;Svr;Server@node2;BEGIN setting up all job attributes 
02/13/2018 17:57:47;0106;Server@node2;Svr;Server@node2;DONE setting up all job attributes, number set <94>
02/13/2018 17:57:47;0106;Server@node2;Svr;Server@node2;BEGIN setting up all server attributes 
02/13/2018 17:57:47;0106;Server@node2;Svr;Server@node2;DONE setting up all server attributes, number set <88>
02/13/2018 17:57:47;0106;Server@node2;Svr;Server@node2;BEGIN setting up all reservation attributes 
02/13/2018 17:57:47;0106;Server@node2;Svr;Server@node2;DONE setting up all reservation attributes, number set <43>
02/13/2018 17:57:47;0106;Server@node2;Svr;Server@node2;BEGIN setting up all vnode attributes 
02/13/2018 17:57:47;0106;Server@node2;Svr;Server@node2;DONE setting up all vnode attributes, number set <28>
02/13/2018 17:57:47;0100;Server@node2;Hook;_pbs_python_event_set;Current memory usage: VmSize=321400kB, VmRSS=12776kB
02/13/2018 17:57:47;0100;Server@node2;Req;;Type 3 request received from ctminh@node2.supernodexp.hpc, sock=16
02/13/2018 17:57:47;0100;Server@node2;Req;;Type 5 request received from ctminh@node2.supernodexp.hpc, sock=16
02/13/2018 17:57:47;0100;Server@node2;Job;882.node2.supernodexp.hpc;enqueuing into workq, state 1 hop 1
02/13/2018 17:57:47;0008;Server@node2;Job;882.node2.supernodexp.hpc;Job Queued at request of ctminh@node2.supernodexp.hpc, owner = ctminh@node2.supernodexp.hpc, job name = jacobi, queue = workq
02/13/2018 17:57:47;0100;Server@node2;Req;;Type 20 request received from Scheduler@node2.supernodexp.hpc, sock=20
02/13/2018 17:57:47;0100;Server@node2;Req;;Type 51 request received from Scheduler@node2.supernodexp.hpc, sock=20
02/13/2018 17:57:47;0100;Server@node2;Req;;Type 11 request received from Scheduler@node2.supernodexp.hpc, sock=20
02/13/2018 17:57:47;0008;Server@node2;Job;880.node2.supernodexp.hpc;Job Modified at request of Scheduler@node2.supernodexp.hpc
02/13/2018 17:57:47;0100;Server@node2;Req;;Type 11 request received from Scheduler@node2.supernodexp.hpc, sock=20
02/13/2018 17:57:47;0008;Server@node2;Job;882.node2.supernodexp.hpc;Job Modified at request of Scheduler@node2.supernodexp.hpc
02/13/2018 17:57:47;0100;Server@node2;Req;;Type 11 request received from Scheduler@node2.supernodexp.hpc, sock=20
02/13/2018 17:57:47;0008;Server@node2;Job;881.node2.supernodexp.hpc;Job Modified at request of Scheduler@node2.supernodexp.hpc
02/13/2018 17:57:47;0040;Server@node2;Svr;node2.supernodexp.hpc;Scheduler sent command 1
02/13/2018 17:57:47;0040;Server@node2;Svr;node2.supernodexp.hpc;Scheduler sent command 0
02/13/2018 17:57:47;0100;Server@node2;Req;;Type 21 request received from Scheduler@node2.supernodexp.hpc, sock=20
02/13/2018 17:57:47;0100;Server@node2;Req;;Type 81 request received from Scheduler@node2.supernodexp.hpc, sock=20
02/13/2018 17:57:47;0100;Server@node2;Req;;Type 71 request received from Scheduler@node2.supernodexp.hpc, sock=20
02/13/2018 17:57:47;0100;Server@node2;Req;;Type 58 request received from Scheduler@node2.supernodexp.hpc, sock=20
02/13/2018 17:57:47;0100;Server@node2;Req;;Type 20 request received from Scheduler@node2.supernodexp.hpc, sock=20
02/13/2018 17:57:47;0100;Server@node2;Req;;Type 51 request received from Scheduler@node2.supernodexp.hpc, sock=20
02/13/2018 17:57:48;0080;Server@node2;Job;847.node2.supernodexp.hpc;Obit received momhop:1 serverhop:1 state:4 substate:42
02/13/2018 17:57:50;0010;Server@node2;Job;847.node2.supernodexp.hpc;Exit_status=0 resources_used.cpupercent=549 resources_used.cput=00:00:11 resources_used.mem=0kb resources_used.ncpus=8 resources_used.vmem=0kb resources_used.walltime=00:00:03
02/13/2018 17:57:50;0100;Server@node2;Job;847.node2.supernodexp.hpc;dequeuing from workq, state 5
02/13/2018 17:57:50;0040;Server@node2;Svr;node2.supernodexp.hpc;Scheduler sent command 2
02/13/2018 17:57:50;0040;Server@node2;Svr;node2.supernodexp.hpc;Scheduler sent command 0
02/13/2018 17:57:50;0100;Server@node2;Req;;Type 21 request received from Scheduler@node2.supernodexp.hpc, sock=20
02/13/2018 17:57:50;0100;Server@node2;Req;;Type 81 request received from Scheduler@node2.supernodexp.hpc, sock=20
02/13/2018 17:57:50;0100;Server@node2;Req;;Type 71 request received from Scheduler@node2.supernodexp.hpc, sock=20
02/13/2018 17:57:50;0100;Server@node2;Req;;Type 58 request received from Scheduler@node2.supernodexp.hpc, sock=20
02/13/2018 17:57:50;0100;Server@node2;Req;;Type 20 request received from Scheduler@node2.supernodexp.hpc, sock=20
02/13/2018 17:57:50;0100;Server@node2;Req;;Type 51 request received from Scheduler@node2.supernodexp.hpc, sock=20
02/13/2018 17:57:50;0100;Server@node2;Req;;Type 11 request received from Scheduler@node2.supernodexp.hpc, sock=20
02/13/2018 17:57:50;0008;Server@node2;Job;875.node2.supernodexp.hpc;Job Modified at request of Scheduler@node2.supernodexp.hpc
02/13/2018 17:57:52;0080;Server@node2;Job;826.node2.supernodexp.hpc;Obit received momhop:1 serverhop:1 state:4 substate:42
02/13/2018 17:57:53;0010;Server@node2;Job;826.node2.supernodexp.hpc;Exit_status=0 resources_used.cpupercent=733 resources_used.cput=00:09:35 resources_used.mem=1550292kb resources_used.ncpus=24 resources_used.vmem=3509008kb resources_used.walltime=00:00:25
02/13/2018 17:57:53;0100;Server@node2;Job;826.node2.supernodexp.hpc;dequeuing from workq, state 5
02/13/2018 17:57:53;0040;Server@node2;Svr;node2.supernodexp.hpc;Scheduler sent command 2
02/13/2018 17:57:53;0040;Server@node2;Svr;node2.supernodexp.hpc;Scheduler sent command 0
02/13/2018 17:57:53;0100;Server@node2;Req;;Type 21 request received from Scheduler@node2.supernodexp.hpc, sock=20
02/13/2018 17:57:53;0100;Server@node2;Req;;Type 81 request received from Scheduler@node2.supernodexp.hpc, sock=20
02/13/2018 17:57:53;0100;Server@node2;Req;;Type 71 request received from Scheduler@node2.supernodexp.hpc, sock=20
02/13/2018 17:57:53;0100;Server@node2;Req;;Type 58 request received from Scheduler@node2.supernodexp.hpc, sock=20
02/13/2018 17:57:53;0100;Server@node2;Req;;Type 20 request received from Scheduler@node2.supernodexp.hpc, sock=20
02/13/2018 17:57:53;0100;Server@node2;Req;;Type 51 request received from Scheduler@node2.supernodexp.hpc, sock=20
02/13/2018 17:57:53;0100;Server@node2;Req;;Type 23 request received from Scheduler@node2.supernodexp.hpc, sock=20
02/13/2018 17:57:53;0008;Server@node2;Job;875.node2.supernodexp.hpc;Job Run at request of Scheduler@node2.supernodexp.hpc on exec_vnode (node13:ncpus=24:mem=1048576kb)
02/13/2018 17:57:53;0001;Server@node2;Svr;Server@node2;Success (0) in req_runjob2, return value of svr_startjob is 0
02/13/2018 17:57:53;0100;Server@node2;Req;;Type 11 request received from Scheduler@node2.supernodexp.hpc, sock=20
02/13/2018 17:57:53;0008;Server@node2;Job;850.node2.supernodexp.hpc;Job Modified at request of Scheduler@node2.supernodexp.hpc
02/13/2018 17:57:55;0080;Server@node2;Job;875.node2.supernodexp.hpc;Obit received momhop:1 serverhop:1 state:4 substate:42
02/13/2018 17:57:56;0010;Server@node2;Job;875.node2.supernodexp.hpc;Exit_status=0 resources_used.cpupercent=2404 resources_used.cput=00:00:41 resources_used.mem=0kb resources_used.ncpus=24 resources_used.vmem=0kb resources_used.walltime=00:00:02
02/13/2018 17:57:56;0100;Server@node2;Job;875.node2.supernodexp.hpc;dequeuing from workq, state 5
02/13/2018 17:57:56;0040;Server@node2;Svr;node2.supernodexp.hpc;Scheduler sent command 2
02/13/2018 17:57:56;0040;Server@node2;Svr;node2.supernodexp.hpc;Scheduler sent command 0
02/13/2018 17:57:56;0100;Server@node2;Req;;Type 21 request received from Scheduler@node2.supernodexp.hpc, sock=20
02/13/2018 17:57:56;0100;Server@node2;Req;;Type 81 request received from Scheduler@node2.supernodexp.hpc, sock=20
02/13/2018 17:57:56;0100;Server@node2;Req;;Type 71 request received from Scheduler@node2.supernodexp.hpc, sock=20
02/13/2018 17:57:56;0100;Server@node2;Req;;Type 58 request received from Scheduler@node2.supernodexp.hpc, sock=20
02/13/2018 17:57:56;0100;Server@node2;Req;;Type 20 request received from Scheduler@node2.supernodexp.hpc, sock=20
02/13/2018 17:57:56;0100;Server@node2;Req;;Type 51 request received from Scheduler@node2.supernodexp.hpc, sock=20
02/13/2018 17:57:56;0100;Server@node2;Req;;Type 23 request received from Scheduler@node2.supernodexp.hpc, sock=20
02/13/2018 17:57:56;0008;Server@node2;Job;850.node2.supernodexp.hpc;Job Run at request of Scheduler@node2.supernodexp.hpc on exec_vnode (node13:ncpus=12:mem=1048576kb)
02/13/2018 17:57:56;0001;Server@node2;Svr;Server@node2;Success (0) in req_runjob2, return value of svr_startjob is 0
02/13/2018 17:57:56;0100;Server@node2;Req;;Type 23 request received from Scheduler@node2.supernodexp.hpc, sock=20
02/13/2018 17:57:56;0008;Server@node2;Job;852.node2.supernodexp.hpc;Job Run at request of Scheduler@node2.supernodexp.hpc on exec_vnode (node13:ncpus=8:mem=3145728kb)
02/13/2018 17:57:56;0001;Server@node2;Svr;Server@node2;Success (0) in req_runjob2, return value of svr_startjob is 0
02/13/2018 17:57:56;0100;Server@node2;Req;;Type 23 request received from Scheduler@node2.supernodexp.hpc, sock=20
02/13/2018 17:57:56;0008;Server@node2;Job;853.node2.supernodexp.hpc;Job Run at request of Scheduler@node2.supernodexp.hpc on exec_vnode (node13:ncpus=8:mem=3145728kb)
02/13/2018 17:57:56;0001;Server@node2;Svr;Server@node2;Success (0) in req_runjob2, return value of svr_startjob is 0
02/13/2018 17:57:56;0100;Server@node2;Req;;Type 11 request received from Scheduler@node2.supernodexp.hpc, sock=20
02/13/2018 17:57:56;0008;Server@node2;Job;856.node2.supernodexp.hpc;Job Modified at request of Scheduler@node2.supernodexp.hpc
02/13/2018 17:57:58;0080;Server@node2;Job;853.node2.supernodexp.hpc;Obit received momhop:1 serverhop:1 state:4 substate:42
02/13/2018 17:57:58;0080;Server@node2;Job;852.node2.supernodexp.hpc;Obit received momhop:1 serverhop:1 state:4 substate:42
02/13/2018 17:57:59;0010;Server@node2;Job;853.node2.supernodexp.hpc;Exit_status=0 resources_used.cpupercent=800 resources_used.cput=00:00:10 resources_used.mem=0kb resources_used.ncpus=8 resources_used.vmem=0kb resources_used.walltime=00:00:01
02/13/2018 17:57:59;0100;Server@node2;Job;853.node2.supernodexp.hpc;dequeuing from workq, state 5
02/13/2018 17:57:59;0010;Server@node2;Job;852.node2.supernodexp.hpc;Exit_status=0 resources_used.cpupercent=800 resources_used.cput=00:00:10 resources_used.mem=3136608kb resources_used.ncpus=8 resources_used.vmem=3942464kb resources_used.walltime=00:00:01
02/13/2018 17:57:59;0100;Server@node2;Job;852.node2.supernodexp.hpc;dequeuing from workq, state 5
02/13/2018 17:57:59;0040;Server@node2;Svr;node2.supernodexp.hpc;Scheduler sent command 2
02/13/2018 17:57:59;0040;Server@node2;Svr;node2.supernodexp.hpc;Scheduler sent command 0
02/13/2018 17:57:59;0100;Server@node2;Req;;Type 21 request received from Scheduler@node2.supernodexp.hpc, sock=20
02/13/2018 17:57:59;0100;Server@node2;Req;;Type 81 request received from Scheduler@node2.supernodexp.hpc, sock=20
02/13/2018 17:57:59;0100;Server@node2;Req;;Type 71 request received from Scheduler@node2.supernodexp.hpc, sock=20
02/13/2018 17:57:59;0100;Server@node2;Req;;Type 58 request received from Scheduler@node2.supernodexp.hpc, sock=20
02/13/2018 17:57:59;0100;Server@node2;Req;;Type 20 request received from Scheduler@node2.supernodexp.hpc, sock=20
02/13/2018 17:57:59;0100;Server@node2;Req;;Type 51 request received from Scheduler@node2.supernodexp.hpc, sock=20
02/13/2018 17:57:59;0100;Server@node2;Req;;Type 23 request received from Scheduler@node2.supernodexp.hpc, sock=20
02/13/2018 17:57:59;0008;Server@node2;Job;856.node2.supernodexp.hpc;Job Run at request of Scheduler@node2.supernodexp.hpc on exec_vnode (node13:ncpus=12:mem=1048576kb)
02/13/2018 17:57:59;0001;Server@node2;Svr;Server@node2;Success (0) in req_runjob2, return value of svr_startjob is 0
02/13/2018 17:57:59;0100;Server@node2;Req;;Type 23 request received from Scheduler@node2.supernodexp.hpc, sock=20
02/13/2018 17:57:59;0008;Server@node2;Job;864.node2.supernodexp.hpc;Job Run at request of Scheduler@node2.supernodexp.hpc on exec_vnode (node13:ncpus=8:mem=3145728kb)
02/13/2018 17:57:59;0001;Server@node2;Svr;Server@node2;Success (0) in req_runjob2, return value of svr_startjob is 0
02/13/2018 17:57:59;0100;Server@node2;Req;;Type 11 request received from Scheduler@node2.supernodexp.hpc, sock=20
02/13/2018 17:57:59;0008;Server@node2;Job;867.node2.supernodexp.hpc;Job Modified at request of Scheduler@node2.supernodexp.hpc
02/13/2018 17:58:01;0080;Server@node2;Job;864.node2.supernodexp.hpc;Obit received momhop:1 serverhop:1 state:4 substate:42
02/13/2018 17:58:02;0010;Server@node2;Job;864.node2.supernodexp.hpc;Exit_status=0 resources_used.cpupercent=548 resources_used.cput=00:00:11 resources_used.mem=1824kb resources_used.ncpus=8 resources_used.vmem=127704kb resources_used.walltime=00:00:02
02/13/2018 17:58:02;0100;Server@node2;Job;864.node2.supernodexp.hpc;dequeuing from workq, state 5
02/13/2018 17:58:02;0040;Server@node2;Svr;node2.supernodexp.hpc;Scheduler sent command 2
02/13/2018 17:58:02;0040;Server@node2;Svr;node2.supernodexp.hpc;Scheduler sent command 0
02/13/2018 17:58:02;0100;Server@node2;Req;;Type 21 request received from Scheduler@node2.supernodexp.hpc, sock=20
02/13/2018 17:58:02;0100;Server@node2;Req;;Type 81 request received from Scheduler@node2.supernodexp.hpc, sock=20
02/13/2018 17:58:02;0100;Server@node2;Req;;Type 71 request received from Scheduler@node2.supernodexp.hpc, sock=20
02/13/2018 17:58:02;0100;Server@node2;Req;;Type 58 request received from Scheduler@node2.supernodexp.hpc, sock=20
02/13/2018 17:58:02;0100;Server@node2;Req;;Type 20 request received from Scheduler@node2.supernodexp.hpc, sock=20
02/13/2018 17:58:02;0100;Server@node2;Req;;Type 51 request received from Scheduler@node2.supernodexp.hpc, sock=20
02/13/2018 17:58:02;0100;Server@node2;Req;;Type 11 request received from Scheduler@node2.supernodexp.hpc, sock=20
02/13/2018 17:58:02;0008;Server@node2;Job;867.node2.supernodexp.hpc;Job Modified at request of Scheduler@node2.supernodexp.hpc
02/13/2018 17:58:05;0080;Server@node2;Job;850.node2.supernodexp.hpc;Obit received momhop:1 serverhop:1 state:4 substate:42
02/13/2018 17:58:06;0010;Server@node2;Job;850.node2.supernodexp.hpc;Exit_status=0 resources_used.cpupercent=1201 resources_used.cput=00:01:41 resources_used.mem=28516kb resources_used.ncpus=12 resources_used.vmem=1125532kb resources_used.walltime=00:00:08
02/13/2018 17:58:06;0100;Server@node2;Job;850.node2.supernodexp.hpc;dequeuing from workq, state 5
02/13/2018 17:58:06;0040;Server@node2;Svr;node2.supernodexp.hpc;Scheduler sent command 2
02/13/2018 17:58:06;0040;Server@node2;Svr;node2.supernodexp.hpc;Scheduler sent command 0
02/13/2018 17:58:06;0100;Server@node2;Req;;Type 21 request received from Scheduler@node2.supernodexp.hpc, sock=20
02/13/2018 17:58:06;0100;Server@node2;Req;;Type 81 request received from Scheduler@node2.supernodexp.hpc, sock=20
02/13/2018 17:58:06;0100;Server@node2;Req;;Type 71 request received from Scheduler@node2.supernodexp.hpc, sock=20
02/13/2018 17:58:06;0100;Server@node2;Req;;Type 58 request received from Scheduler@node2.supernodexp.hpc, sock=20
02/13/2018 17:58:06;0100;Server@node2;Req;;Type 20 request received from Scheduler@node2.supernodexp.hpc, sock=20
02/13/2018 17:58:06;0100;Server@node2;Req;;Type 51 request received from Scheduler@node2.supernodexp.hpc, sock=20
02/13/2018 17:58:06;0100;Server@node2;Req;;Type 11 request received from Scheduler@node2.supernodexp.hpc, sock=20
02/13/2018 17:58:06;0008;Server@node2;Job;867.node2.supernodexp.hpc;Job Modified at request of Scheduler@node2.supernodexp.hpc
02/13/2018 17:58:09;0080;Server@node2;Job;856.node2.supernodexp.hpc;Obit received momhop:1 serverhop:1 state:4 substate:42
02/13/2018 17:58:10;0010;Server@node2;Job;856.node2.supernodexp.hpc;Exit_status=0 resources_used.cpupercent=910 resources_used.cput=00:01:47 resources_used.mem=33868kb resources_used.ncpus=12 resources_used.vmem=1125532kb resources_used.walltime=00:00:09
02/13/2018 17:58:10;0100;Server@node2;Job;856.node2.supernodexp.hpc;dequeuing from workq, state 5
02/13/2018 17:58:10;0040;Server@node2;Svr;node2.supernodexp.hpc;Scheduler sent command 2
02/13/2018 17:58:10;0040;Server@node2;Svr;node2.supernodexp.hpc;Scheduler sent command 0
02/13/2018 17:58:10;0100;Server@node2;Req;;Type 21 request received from Scheduler@node2.supernodexp.hpc, sock=20
02/13/2018 17:58:10;0100;Server@node2;Req;;Type 81 request received from Scheduler@node2.supernodexp.hpc, sock=20
02/13/2018 17:58:10;0100;Server@node2;Req;;Type 71 request received from Scheduler@node2.supernodexp.hpc, sock=20
02/13/2018 17:58:10;0100;Server@node2;Req;;Type 58 request received from Scheduler@node2.supernodexp.hpc, sock=20
02/13/2018 17:58:10;0100;Server@node2;Req;;Type 20 request received from Scheduler@node2.supernodexp.hpc, sock=20
02/13/2018 17:58:10;0100;Server@node2;Req;;Type 51 request received from Scheduler@node2.supernodexp.hpc, sock=20
02/13/2018 17:58:10;0100;Server@node2;Req;;Type 23 request received from Scheduler@node2.supernodexp.hpc, sock=20
02/13/2018 17:58:10;0008;Server@node2;Job;867.node2.supernodexp.hpc;Job Run at request of Scheduler@node2.supernodexp.hpc on exec_vnode (node13:ncpus=32:mem=2097152kb)
02/13/2018 17:58:10;0001;Server@node2;Svr;Server@node2;Success (0) in req_runjob2, return value of svr_startjob is 0
02/13/2018 17:58:10;0100;Server@node2;Req;;Type 11 request received from Scheduler@node2.supernodexp.hpc, sock=20
02/13/2018 17:58:10;0008;Server@node2;Job;869.node2.supernodexp.hpc;Job Modified at request of Scheduler@node2.supernodexp.hpc
02/13/2018 17:58:14;0080;Server@node2;Job;867.node2.supernodexp.hpc;Obit received momhop:1 serverhop:1 state:4 substate:42
02/13/2018 17:58:15;0010;Server@node2;Job;867.node2.supernodexp.hpc;Exit_status=0 resources_used.cpupercent=100 resources_used.cput=00:00:04 resources_used.mem=0kb resources_used.ncpus=32 resources_used.vmem=0kb resources_used.walltime=00:00:05
02/13/2018 17:58:15;0100;Server@node2;Job;867.node2.supernodexp.hpc;dequeuing from workq, state 5
02/13/2018 17:58:15;0040;Server@node2;Svr;node2.supernodexp.hpc;Scheduler sent command 2
02/13/2018 17:58:15;0040;Server@node2;Svr;node2.supernodexp.hpc;Scheduler sent command 0
02/13/2018 17:58:15;0100;Server@node2;Req;;Type 21 request received from Scheduler@node2.supernodexp.hpc, sock=20
02/13/2018 17:58:15;0100;Server@node2;Req;;Type 81 request received from Scheduler@node2.supernodexp.hpc, sock=20
02/13/2018 17:58:15;0100;Server@node2;Req;;Type 71 request received from Scheduler@node2.supernodexp.hpc, sock=20
02/13/2018 17:58:15;0100;Server@node2;Req;;Type 58 request received from Scheduler@node2.supernodexp.hpc, sock=20
02/13/2018 17:58:16;0100;Server@node2;Req;;Type 20 request received from Scheduler@node2.supernodexp.hpc, sock=20
02/13/2018 17:58:16;0100;Server@node2;Req;;Type 51 request received from Scheduler@node2.supernodexp.hpc, sock=20
02/13/2018 17:58:16;0100;Server@node2;Req;;Type 23 request received from Scheduler@node2.supernodexp.hpc, sock=20
02/13/2018 17:58:16;0008;Server@node2;Job;869.node2.supernodexp.hpc;Job Run at request of Scheduler@node2.supernodexp.hpc on exec_vnode (node13:ncpus=32:mem=2097152kb)
02/13/2018 17:58:16;0001;Server@node2;Svr;Server@node2;Success (0) in req_runjob2, return value of svr_startjob is 0
02/13/2018 17:58:16;0100;Server@node2;Req;;Type 11 request received from Scheduler@node2.supernodexp.hpc, sock=20
02/13/2018 17:58:16;0008;Server@node2;Job;871.node2.supernodexp.hpc;Job Modified at request of Scheduler@node2.supernodexp.hpc
02/13/2018 17:58:20;0080;Server@node2;Job;869.node2.supernodexp.hpc;Obit received momhop:1 serverhop:1 state:4 substate:42
02/13/2018 17:58:20;0100;Server@node2;Req;;Type 1 request received from ctminh@node2.supernodexp.hpc, sock=16
02/13/2018 17:58:20;0100;Server@node2;Req;;Type 3 request received from ctminh@node2.supernodexp.hpc, sock=16
02/13/2018 17:58:20;0100;Server@node2;Req;;Type 5 request received from ctminh@node2.supernodexp.hpc, sock=16
02/13/2018 17:58:20;0100;Server@node2;Job;883.node2.supernodexp.hpc;enqueuing into workq, state 1 hop 1
02/13/2018 17:58:20;0008;Server@node2;Job;883.node2.supernodexp.hpc;Job Queued at request of ctminh@node2.supernodexp.hpc, owner = ctminh@node2.supernodexp.hpc, job name = qe_mic_test, queue = workq
02/13/2018 17:58:20;0040;Server@node2;Svr;node2.supernodexp.hpc;Scheduler sent command 1
02/13/2018 17:58:20;0040;Server@node2;Svr;node2.supernodexp.hpc;Scheduler sent command 0
02/13/2018 17:58:20;0100;Server@node2;Req;;Type 21 request received from Scheduler@node2.supernodexp.hpc, sock=20
02/13/2018 17:58:20;0100;Server@node2;Req;;Type 81 request received from Scheduler@node2.supernodexp.hpc, sock=20
02/13/2018 17:58:20;0100;Server@node2;Req;;Type 71 request received from Scheduler@node2.supernodexp.hpc, sock=20
02/13/2018 17:58:20;0100;Server@node2;Req;;Type 58 request received from Scheduler@node2.supernodexp.hpc, sock=20
02/13/2018 17:58:20;0100;Server@node2;Req;;Type 1 request received from ctminh@node2.supernodexp.hpc, sock=16
02/13/2018 17:58:20;0100;Server@node2;Req;;Type 3 request received from ctminh@node2.supernodexp.hpc, sock=16
02/13/2018 17:58:20;0100;Server@node2;Req;;Type 5 request received from ctminh@node2.supernodexp.hpc, sock=16
02/13/2018 17:58:20;0100;Server@node2;Job;884.node2.supernodexp.hpc;enqueuing into workq, state 1 hop 1
02/13/2018 17:58:20;0008;Server@node2;Job;884.node2.supernodexp.hpc;Job Queued at request of ctminh@node2.supernodexp.hpc, owner = ctminh@node2.supernodexp.hpc, job name = qe_mic_test, queue = workq
02/13/2018 17:58:20;0100;Server@node2;Req;;Type 1 request received from ctminh@node2.supernodexp.hpc, sock=16
02/13/2018 17:58:20;0100;Server@node2;Req;;Type 20 request received from Scheduler@node2.supernodexp.hpc, sock=20
02/13/2018 17:58:20;0100;Server@node2;Req;;Type 3 request received from ctminh@node2.supernodexp.hpc, sock=16
02/13/2018 17:58:20;0100;Server@node2;Req;;Type 51 request received from Scheduler@node2.supernodexp.hpc, sock=20
02/13/2018 17:58:20;0100;Server@node2;Req;;Type 5 request received from ctminh@node2.supernodexp.hpc, sock=16
02/13/2018 17:58:20;0100;Server@node2;Job;885.node2.supernodexp.hpc;enqueuing into workq, state 1 hop 1
02/13/2018 17:58:20;0008;Server@node2;Job;885.node2.supernodexp.hpc;Job Queued at request of ctminh@node2.supernodexp.hpc, owner = ctminh@node2.supernodexp.hpc, job name = histogram, queue = workq
02/13/2018 17:58:20;0100;Server@node2;Req;;Type 1 request received from ctminh@node2.supernodexp.hpc, sock=16
02/13/2018 17:58:20;0100;Server@node2;Req;;Type 3 request received from ctminh@node2.supernodexp.hpc, sock=16
02/13/2018 17:58:20;0100;Server@node2;Req;;Type 5 request received from ctminh@node2.supernodexp.hpc, sock=16
02/13/2018 17:58:20;0100;Server@node2;Job;886.node2.supernodexp.hpc;enqueuing into workq, state 1 hop 1
02/13/2018 17:58:20;0008;Server@node2;Job;886.node2.supernodexp.hpc;Job Queued at request of ctminh@node2.supernodexp.hpc, owner = ctminh@node2.supernodexp.hpc, job name = telemac1, queue = workq
02/13/2018 17:58:20;0100;Server@node2;Req;;Type 1 request received from ctminh@node2.supernodexp.hpc, sock=16
02/13/2018 17:58:20;0100;Server@node2;Req;;Type 3 request received from ctminh@node2.supernodexp.hpc, sock=16
02/13/2018 17:58:20;0100;Server@node2;Req;;Type 5 request received from ctminh@node2.supernodexp.hpc, sock=16
02/13/2018 17:58:20;0100;Server@node2;Job;887.node2.supernodexp.hpc;enqueuing into workq, state 1 hop 1
02/13/2018 17:58:20;0008;Server@node2;Job;887.node2.supernodexp.hpc;Job Queued at request of ctminh@node2.supernodexp.hpc, owner = ctminh@node2.supernodexp.hpc, job name = nbody, queue = workq
02/13/2018 17:58:20;0100;Server@node2;Req;;Type 11 request received from Scheduler@node2.supernodexp.hpc, sock=20
02/13/2018 17:58:20;0008;Server@node2;Job;883.node2.supernodexp.hpc;Job Modified at request of Scheduler@node2.supernodexp.hpc
02/13/2018 17:58:20;0100;Server@node2;Req;;Type 11 request received from Scheduler@node2.supernodexp.hpc, sock=20
02/13/2018 17:58:20;0008;Server@node2;Job;884.node2.supernodexp.hpc;Job Modified at request of Scheduler@node2.supernodexp.hpc
02/13/2018 17:58:20;0040;Server@node2;Svr;node2.supernodexp.hpc;Scheduler sent command 1
02/13/2018 17:58:20;0040;Server@node2;Svr;node2.supernodexp.hpc;Scheduler sent command 0
02/13/2018 17:58:20;0100;Server@node2;Req;;Type 21 request received from Scheduler@node2.supernodexp.hpc, sock=20
02/13/2018 17:58:20;0100;Server@node2;Req;;Type 81 request received from Scheduler@node2.supernodexp.hpc, sock=20
02/13/2018 17:58:20;0100;Server@node2;Req;;Type 71 request received from Scheduler@node2.supernodexp.hpc, sock=20
02/13/2018 17:58:20;0100;Server@node2;Req;;Type 58 request received from Scheduler@node2.supernodexp.hpc, sock=20
02/13/2018 17:58:20;0100;Server@node2;Req;;Type 1 request received from ctminh@node2.supernodexp.hpc, sock=16
02/13/2018 17:58:20;0100;Server@node2;Req;;Type 3 request received from ctminh@node2.supernodexp.hpc, sock=16
02/13/2018 17:58:20;0100;Server@node2;Req;;Type 5 request received from ctminh@node2.supernodexp.hpc, sock=16
02/13/2018 17:58:20;0100;Server@node2;Job;888.node2.supernodexp.hpc;enqueuing into workq, state 1 hop 1
02/13/2018 17:58:20;0008;Server@node2;Job;888.node2.supernodexp.hpc;Job Queued at request of ctminh@node2.supernodexp.hpc, owner = ctminh@node2.supernodexp.hpc, job name = lu-decomp, queue = workq
02/13/2018 17:58:20;0100;Server@node2;Req;;Type 1 request received from ctminh@node2.supernodexp.hpc, sock=16
02/13/2018 17:58:20;0100;Server@node2;Req;;Type 20 request received from Scheduler@node2.supernodexp.hpc, sock=20
02/13/2018 17:58:20;0100;Server@node2;Req;;Type 3 request received from ctminh@node2.supernodexp.hpc, sock=16
02/13/2018 17:58:20;0100;Server@node2;Req;;Type 51 request received from Scheduler@node2.supernodexp.hpc, sock=20
02/13/2018 17:58:20;0100;Server@node2;Req;;Type 5 request received from ctminh@node2.supernodexp.hpc, sock=16
02/13/2018 17:58:20;0100;Server@node2;Job;889.node2.supernodexp.hpc;enqueuing into workq, state 1 hop 1
02/13/2018 17:58:20;0008;Server@node2;Job;889.node2.supernodexp.hpc;Job Queued at request of ctminh@node2.supernodexp.hpc, owner = ctminh@node2.supernodexp.hpc, job name = telemac3, queue = workq
02/13/2018 17:58:20;0100;Server@node2;Req;;Type 1 request received from ctminh@node2.supernodexp.hpc, sock=16
02/13/2018 17:58:20;0100;Server@node2;Req;;Type 3 request received from ctminh@node2.supernodexp.hpc, sock=16
02/13/2018 17:58:20;0100;Server@node2;Req;;Type 5 request received from ctminh@node2.supernodexp.hpc, sock=16
02/13/2018 17:58:20;0100;Server@node2;Job;890.node2.supernodexp.hpc;enqueuing into workq, state 1 hop 1
02/13/2018 17:58:20;0008;Server@node2;Job;890.node2.supernodexp.hpc;Job Queued at request of ctminh@node2.supernodexp.hpc, owner = ctminh@node2.supernodexp.hpc, job name = vast1, queue = workq
02/13/2018 17:58:20;0100;Server@node2;Req;;Type 11 request received from Scheduler@node2.supernodexp.hpc, sock=20
02/13/2018 17:58:20;0008;Server@node2;Job;871.node2.supernodexp.hpc;Job Modified at request of Scheduler@node2.supernodexp.hpc
02/13/2018 17:58:20;0100;Server@node2;Req;;Type 11 request received from Scheduler@node2.supernodexp.hpc, sock=20
02/13/2018 17:58:20;0008;Server@node2;Job;885.node2.supernodexp.hpc;Job Modified at request of Scheduler@node2.supernodexp.hpc
02/13/2018 17:58:20;0100;Server@node2;Req;;Type 11 request received from Scheduler@node2.supernodexp.hpc, sock=20
02/13/2018 17:58:20;0008;Server@node2;Job;887.node2.supernodexp.hpc;Job Modified at request of Scheduler@node2.supernodexp.hpc
02/13/2018 17:58:20;0100;Server@node2;Req;;Type 11 request received from Scheduler@node2.supernodexp.hpc, sock=20
02/13/2018 17:58:20;0008;Server@node2;Job;886.node2.supernodexp.hpc;Job Modified at request of Scheduler@node2.supernodexp.hpc
02/13/2018 17:58:20;0100;Server@node2;Req;;Type 11 request received from Scheduler@node2.supernodexp.hpc, sock=20
02/13/2018 17:58:20;0008;Server@node2;Job;888.node2.supernodexp.hpc;Job Modified at request of Scheduler@node2.supernodexp.hpc
02/13/2018 17:58:20;0040;Server@node2;Svr;node2.supernodexp.hpc;Scheduler sent command 1
02/13/2018 17:58:20;0040;Server@node2;Svr;node2.supernodexp.hpc;Scheduler sent command 0
02/13/2018 17:58:20;0100;Server@node2;Req;;Type 21 request received from Scheduler@node2.supernodexp.hpc, sock=20
02/13/2018 17:58:20;0100;Server@node2;Req;;Type 81 request received from Scheduler@node2.supernodexp.hpc, sock=20
02/13/2018 17:58:20;0100;Server@node2;Req;;Type 71 request received from Scheduler@node2.supernodexp.hpc, sock=20
02/13/2018 17:58:20;0100;Server@node2;Req;;Type 58 request received from Scheduler@node2.supernodexp.hpc, sock=20
02/13/2018 17:58:20;0100;Server@node2;Req;;Type 1 request received from ctminh@node2.supernodexp.hpc, sock=16
02/13/2018 17:58:20;0100;Server@node2;Req;;Type 3 request received from ctminh@node2.supernodexp.hpc, sock=16
02/13/2018 17:58:20;0100;Server@node2;Req;;Type 5 request received from ctminh@node2.supernodexp.hpc, sock=16
02/13/2018 17:58:20;0100;Server@node2;Job;891.node2.supernodexp.hpc;enqueuing into workq, state 1 hop 1
02/13/2018 17:58:20;0008;Server@node2;Job;891.node2.supernodexp.hpc;Job Queued at request of ctminh@node2.supernodexp.hpc, owner = ctminh@node2.supernodexp.hpc, job name = sweep, queue = workq
02/13/2018 17:58:20;0100;Server@node2;Req;;Type 20 request received from Scheduler@node2.supernodexp.hpc, sock=20
02/13/2018 17:58:20;0100;Server@node2;Req;;Type 51 request received from Scheduler@node2.supernodexp.hpc, sock=20
02/13/2018 17:58:20;0100;Server@node2;Req;;Type 1 request received from ctminh@node2.supernodexp.hpc, sock=16
02/13/2018 17:58:20;0100;Server@node2;Req;;Type 3 request received from ctminh@node2.supernodexp.hpc, sock=16
02/13/2018 17:58:20;0100;Server@node2;Req;;Type 5 request received from ctminh@node2.supernodexp.hpc, sock=16
02/13/2018 17:58:20;0100;Server@node2;Job;892.node2.supernodexp.hpc;enqueuing into workq, state 1 hop 1
02/13/2018 17:58:20;0008;Server@node2;Job;892.node2.supernodexp.hpc;Job Queued at request of ctminh@node2.supernodexp.hpc, owner = ctminh@node2.supernodexp.hpc, job name = vectorization, queue = workq
02/13/2018 17:58:20;0100;Server@node2;Req;;Type 1 request received from ctminh@node2.supernodexp.hpc, sock=16
02/13/2018 17:58:20;0100;Server@node2;Req;;Type 11 request received from Scheduler@node2.supernodexp.hpc, sock=20
02/13/2018 17:58:20;0008;Server@node2;Job;891.node2.supernodexp.hpc;Job Modified at request of Scheduler@node2.supernodexp.hpc
02/13/2018 17:58:20;0100;Server@node2;Req;;Type 3 request received from ctminh@node2.supernodexp.hpc, sock=16
02/13/2018 17:58:20;0100;Server@node2;Req;;Type 5 request received from ctminh@node2.supernodexp.hpc, sock=16
02/13/2018 17:58:20;0100;Server@node2;Job;893.node2.supernodexp.hpc;enqueuing into workq, state 1 hop 1
02/13/2018 17:58:20;0008;Server@node2;Job;893.node2.supernodexp.hpc;Job Queued at request of ctminh@node2.supernodexp.hpc, owner = ctminh@node2.supernodexp.hpc, job name = telemac3, queue = workq
02/13/2018 17:58:20;0100;Server@node2;Req;;Type 11 request received from Scheduler@node2.supernodexp.hpc, sock=20
02/13/2018 17:58:20;0008;Server@node2;Job;889.node2.supernodexp.hpc;Job Modified at request of Scheduler@node2.supernodexp.hpc
02/13/2018 17:58:20;0100;Server@node2;Req;;Type 11 request received from Scheduler@node2.supernodexp.hpc, sock=20
02/13/2018 17:58:20;0008;Server@node2;Job;890.node2.supernodexp.hpc;Job Modified at request of Scheduler@node2.supernodexp.hpc
02/13/2018 17:58:20;0040;Server@node2;Svr;node2.supernodexp.hpc;Scheduler sent command 1
02/13/2018 17:58:20;0040;Server@node2;Svr;node2.supernodexp.hpc;Scheduler sent command 0
02/13/2018 17:58:20;0100;Server@node2;Req;;Type 21 request received from Scheduler@node2.supernodexp.hpc, sock=20
02/13/2018 17:58:20;0100;Server@node2;Req;;Type 81 request received from Scheduler@node2.supernodexp.hpc, sock=20
02/13/2018 17:58:20;0100;Server@node2;Req;;Type 71 request received from Scheduler@node2.supernodexp.hpc, sock=20
02/13/2018 17:58:20;0100;Server@node2;Req;;Type 58 request received from Scheduler@node2.supernodexp.hpc, sock=20
02/13/2018 17:58:20;0100;Server@node2;Req;;Type 1 request received from ctminh@node2.supernodexp.hpc, sock=16
02/13/2018 17:58:20;0100;Server@node2;Req;;Type 3 request received from ctminh@node2.supernodexp.hpc, sock=16
02/13/2018 17:58:20;0100;Server@node2;Req;;Type 5 request received from ctminh@node2.supernodexp.hpc, sock=16
02/13/2018 17:58:20;0100;Server@node2;Job;894.node2.supernodexp.hpc;enqueuing into workq, state 1 hop 1
02/13/2018 17:58:20;0008;Server@node2;Job;894.node2.supernodexp.hpc;Job Queued at request of ctminh@node2.supernodexp.hpc, owner = ctminh@node2.supernodexp.hpc, job name = jacobi, queue = workq
02/13/2018 17:58:20;0100;Server@node2;Req;;Type 1 request received from ctminh@node2.supernodexp.hpc, sock=16
02/13/2018 17:58:20;0100;Server@node2;Req;;Type 20 request received from Scheduler@node2.supernodexp.hpc, sock=20
02/13/2018 17:58:20;0100;Server@node2;Req;;Type 3 request received from ctminh@node2.supernodexp.hpc, sock=16
02/13/2018 17:58:20;0100;Server@node2;Req;;Type 51 request received from Scheduler@node2.supernodexp.hpc, sock=20
02/13/2018 17:58:21;0100;Server@node2;Req;;Type 5 request received from ctminh@node2.supernodexp.hpc, sock=16
02/13/2018 17:58:21;0100;Server@node2;Job;895.node2.supernodexp.hpc;enqueuing into workq, state 1 hop 1
02/13/2018 17:58:21;0008;Server@node2;Job;895.node2.supernodexp.hpc;Job Queued at request of ctminh@node2.supernodexp.hpc, owner = ctminh@node2.supernodexp.hpc, job name = vectorization, queue = workq
02/13/2018 17:58:21;0100;Server@node2;Req;;Type 11 request received from Scheduler@node2.supernodexp.hpc, sock=20
02/13/2018 17:58:21;0008;Server@node2;Job;892.node2.supernodexp.hpc;Job Modified at request of Scheduler@node2.supernodexp.hpc
02/13/2018 17:58:21;0100;Server@node2;Req;;Type 11 request received from Scheduler@node2.supernodexp.hpc, sock=20
02/13/2018 17:58:21;0008;Server@node2;Job;894.node2.supernodexp.hpc;Job Modified at request of Scheduler@node2.supernodexp.hpc
02/13/2018 17:58:21;0100;Server@node2;Req;;Type 11 request received from Scheduler@node2.supernodexp.hpc, sock=20
02/13/2018 17:58:21;0008;Server@node2;Job;893.node2.supernodexp.hpc;Job Modified at request of Scheduler@node2.supernodexp.hpc
02/13/2018 17:58:21;0040;Server@node2;Svr;node2.supernodexp.hpc;Scheduler sent command 1
02/13/2018 17:58:21;0040;Server@node2;Svr;node2.supernodexp.hpc;Scheduler sent command 0
02/13/2018 17:58:21;0100;Server@node2;Req;;Type 21 request received from Scheduler@node2.supernodexp.hpc, sock=20
02/13/2018 17:58:21;0100;Server@node2;Req;;Type 81 request received from Scheduler@node2.supernodexp.hpc, sock=20
02/13/2018 17:58:21;0100;Server@node2;Req;;Type 71 request received from Scheduler@node2.supernodexp.hpc, sock=20
02/13/2018 17:58:21;0100;Server@node2;Req;;Type 58 request received from Scheduler@node2.supernodexp.hpc, sock=20
02/13/2018 17:58:21;0100;Server@node2;Req;;Type 1 request received from ctminh@node2.supernodexp.hpc, sock=16
02/13/2018 17:58:21;0100;Server@node2;Req;;Type 3 request received from ctminh@node2.supernodexp.hpc, sock=16
02/13/2018 17:58:21;0100;Server@node2;Req;;Type 5 request received from ctminh@node2.supernodexp.hpc, sock=16
02/13/2018 17:58:21;0100;Server@node2;Job;896.node2.supernodexp.hpc;enqueuing into workq, state 1 hop 1
02/13/2018 17:58:21;0008;Server@node2;Job;896.node2.supernodexp.hpc;Job Queued at request of ctminh@node2.supernodexp.hpc, owner = ctminh@node2.supernodexp.hpc, job name = matrix-x-vector, queue = workq
02/13/2018 17:58:21;0100;Server@node2;Req;;Type 1 request received from ctminh@node2.supernodexp.hpc, sock=16
02/13/2018 17:58:21;0100;Server@node2;Req;;Type 3 request received from ctminh@node2.supernodexp.hpc, sock=16
02/13/2018 17:58:21;0100;Server@node2;Req;;Type 5 request received from ctminh@node2.supernodexp.hpc, sock=16
02/13/2018 17:58:21;0100;Server@node2;Job;897.node2.supernodexp.hpc;enqueuing into workq, state 1 hop 1
02/13/2018 17:58:21;0008;Server@node2;Job;897.node2.supernodexp.hpc;Job Queued at request of ctminh@node2.supernodexp.hpc, owner = ctminh@node2.supernodexp.hpc, job name = telemac2, queue = workq
02/13/2018 17:58:21;0100;Server@node2;Req;;Type 20 request received from Scheduler@node2.supernodexp.hpc, sock=20
02/13/2018 17:58:21;0100;Server@node2;Req;;Type 51 request received from Scheduler@node2.supernodexp.hpc, sock=20
02/13/2018 17:58:21;0100;Server@node2;Req;;Type 1 request received from ctminh@node2.supernodexp.hpc, sock=16
02/13/2018 17:58:21;0100;Server@node2;Req;;Type 3 request received from ctminh@node2.supernodexp.hpc, sock=16
02/13/2018 17:58:21;0100;Server@node2;Req;;Type 5 request received from ctminh@node2.supernodexp.hpc, sock=16
02/13/2018 17:58:21;0100;Server@node2;Job;898.node2.supernodexp.hpc;enqueuing into workq, state 1 hop 1
02/13/2018 17:58:21;0008;Server@node2;Job;898.node2.supernodexp.hpc;Job Queued at request of ctminh@node2.supernodexp.hpc, owner = ctminh@node2.supernodexp.hpc, job name = telemac2, queue = workq
02/13/2018 17:58:21;0100;Server@node2;Req;;Type 1 request received from ctminh@node2.supernodexp.hpc, sock=16
02/13/2018 17:58:21;0100;Server@node2;Req;;Type 3 request received from ctminh@node2.supernodexp.hpc, sock=16
02/13/2018 17:58:21;0100;Server@node2;Req;;Type 5 request received from ctminh@node2.supernodexp.hpc, sock=16
02/13/2018 17:58:21;0100;Server@node2;Job;899.node2.supernodexp.hpc;enqueuing into workq, state 1 hop 1
02/13/2018 17:58:21;0008;Server@node2;Job;899.node2.supernodexp.hpc;Job Queued at request of ctminh@node2.supernodexp.hpc, owner = ctminh@node2.supernodexp.hpc, job name = telemac2, queue = workq
02/13/2018 17:58:21;0100;Server@node2;Req;;Type 11 request received from Scheduler@node2.supernodexp.hpc, sock=20
02/13/2018 17:58:21;0008;Server@node2;Job;896.node2.supernodexp.hpc;Job Modified at request of Scheduler@node2.supernodexp.hpc
02/13/2018 17:58:21;0100;Server@node2;Req;;Type 11 request received from Scheduler@node2.supernodexp.hpc, sock=20
02/13/2018 17:58:21;0008;Server@node2;Job;895.node2.supernodexp.hpc;Job Modified at request of Scheduler@node2.supernodexp.hpc
02/13/2018 17:58:21;0100;Server@node2;Req;;Type 11 request received from Scheduler@node2.supernodexp.hpc, sock=20
02/13/2018 17:58:21;0008;Server@node2;Job;897.node2.supernodexp.hpc;Job Modified at request of Scheduler@node2.supernodexp.hpc
02/13/2018 17:58:21;0040;Server@node2;Svr;node2.supernodexp.hpc;Scheduler sent command 1
02/13/2018 17:58:21;0040;Server@node2;Svr;node2.supernodexp.hpc;Scheduler sent command 0
02/13/2018 17:58:21;0100;Server@node2;Req;;Type 21 request received from Scheduler@node2.supernodexp.hpc, sock=20
02/13/2018 17:58:21;0100;Server@node2;Req;;Type 81 request received from Scheduler@node2.supernodexp.hpc, sock=20
02/13/2018 17:58:21;0100;Server@node2;Req;;Type 71 request received from Scheduler@node2.supernodexp.hpc, sock=20
02/13/2018 17:58:21;0100;Server@node2;Req;;Type 58 request received from Scheduler@node2.supernodexp.hpc, sock=20
02/13/2018 17:58:21;0100;Server@node2;Req;;Type 1 request received from ctminh@node2.supernodexp.hpc, sock=16
02/13/2018 17:58:21;0100;Server@node2;Req;;Type 3 request received from ctminh@node2.supernodexp.hpc, sock=16
02/13/2018 17:58:21;0100;Server@node2;Req;;Type 5 request received from ctminh@node2.supernodexp.hpc, sock=16
02/13/2018 17:58:21;0100;Server@node2;Job;900.node2.supernodexp.hpc;enqueuing into workq, state 1 hop 1
02/13/2018 17:58:21;0008;Server@node2;Job;900.node2.supernodexp.hpc;Job Queued at request of ctminh@node2.supernodexp.hpc, owner = ctminh@node2.supernodexp.hpc, job name = histogram, queue = workq
02/13/2018 17:58:21;0100;Server@node2;Req;;Type 1 request received from ctminh@node2.supernodexp.hpc, sock=16
02/13/2018 17:58:21;0100;Server@node2;Req;;Type 3 request received from ctminh@node2.supernodexp.hpc, sock=16
02/13/2018 17:58:21;0100;Server@node2;Req;;Type 5 request received from ctminh@node2.supernodexp.hpc, sock=16
02/13/2018 17:58:21;0100;Server@node2;Job;901.node2.supernodexp.hpc;enqueuing into workq, state 1 hop 1
02/13/2018 17:58:21;0008;Server@node2;Job;901.node2.supernodexp.hpc;Job Queued at request of ctminh@node2.supernodexp.hpc, owner = ctminh@node2.supernodexp.hpc, job name = nbody, queue = workq
02/13/2018 17:58:21;0100;Server@node2;Req;;Type 20 request received from Scheduler@node2.supernodexp.hpc, sock=20
02/13/2018 17:58:21;0100;Server@node2;Req;;Type 51 request received from Scheduler@node2.supernodexp.hpc, sock=20
02/13/2018 17:58:21;0100;Server@node2;Req;;Type 1 request received from ctminh@node2.supernodexp.hpc, sock=16
02/13/2018 17:58:21;0100;Server@node2;Req;;Type 3 request received from ctminh@node2.supernodexp.hpc, sock=16
02/13/2018 17:58:21;0100;Server@node2;Req;;Type 5 request received from ctminh@node2.supernodexp.hpc, sock=16
02/13/2018 17:58:21;0100;Server@node2;Job;902.node2.supernodexp.hpc;enqueuing into workq, state 1 hop 1
02/13/2018 17:58:21;0008;Server@node2;Job;902.node2.supernodexp.hpc;Job Queued at request of ctminh@node2.supernodexp.hpc, owner = ctminh@node2.supernodexp.hpc, job name = vectorization, queue = workq
02/13/2018 17:58:21;0100;Server@node2;Req;;Type 1 request received from ctminh@node2.supernodexp.hpc, sock=16
02/13/2018 17:58:21;0100;Server@node2;Req;;Type 3 request received from ctminh@node2.supernodexp.hpc, sock=16
02/13/2018 17:58:21;0100;Server@node2;Req;;Type 5 request received from ctminh@node2.supernodexp.hpc, sock=16
02/13/2018 17:58:21;0100;Server@node2;Job;903.node2.supernodexp.hpc;enqueuing into workq, state 1 hop 1
02/13/2018 17:58:21;0008;Server@node2;Job;903.node2.supernodexp.hpc;Job Queued at request of ctminh@node2.supernodexp.hpc, owner = ctminh@node2.supernodexp.hpc, job name = telemac2, queue = workq
02/13/2018 17:58:21;0100;Server@node2;Req;;Type 11 request received from Scheduler@node2.supernodexp.hpc, sock=20
02/13/2018 17:58:21;0008;Server@node2;Job;900.node2.supernodexp.hpc;Job Modified at request of Scheduler@node2.supernodexp.hpc
02/13/2018 17:58:21;0100;Server@node2;Req;;Type 11 request received from Scheduler@node2.supernodexp.hpc, sock=20
02/13/2018 17:58:21;0008;Server@node2;Job;901.node2.supernodexp.hpc;Job Modified at request of Scheduler@node2.supernodexp.hpc
02/13/2018 17:58:21;0100;Server@node2;Req;;Type 11 request received from Scheduler@node2.supernodexp.hpc, sock=20
02/13/2018 17:58:21;0008;Server@node2;Job;898.node2.supernodexp.hpc;Job Modified at request of Scheduler@node2.supernodexp.hpc
02/13/2018 17:58:21;0100;Server@node2;Req;;Type 11 request received from Scheduler@node2.supernodexp.hpc, sock=20
02/13/2018 17:58:21;0008;Server@node2;Job;899.node2.supernodexp.hpc;Job Modified at request of Scheduler@node2.supernodexp.hpc
02/13/2018 17:58:21;0040;Server@node2;Svr;node2.supernodexp.hpc;Scheduler sent command 1
02/13/2018 17:58:21;0040;Server@node2;Svr;node2.supernodexp.hpc;Scheduler sent command 0
02/13/2018 17:58:21;0100;Server@node2;Req;;Type 21 request received from Scheduler@node2.supernodexp.hpc, sock=20
02/13/2018 17:58:21;0100;Server@node2;Req;;Type 81 request received from Scheduler@node2.supernodexp.hpc, sock=20
02/13/2018 17:58:21;0100;Server@node2;Req;;Type 71 request received from Scheduler@node2.supernodexp.hpc, sock=20
02/13/2018 17:58:21;0100;Server@node2;Req;;Type 58 request received from Scheduler@node2.supernodexp.hpc, sock=20
02/13/2018 17:58:21;0100;Server@node2;Req;;Type 1 request received from ctminh@node2.supernodexp.hpc, sock=16
02/13/2018 17:58:21;0100;Server@node2;Req;;Type 3 request received from ctminh@node2.supernodexp.hpc, sock=16
02/13/2018 17:58:21;0100;Server@node2;Req;;Type 5 request received from ctminh@node2.supernodexp.hpc, sock=16
02/13/2018 17:58:21;0100;Server@node2;Job;904.node2.supernodexp.hpc;enqueuing into workq, state 1 hop 1
02/13/2018 17:58:21;0008;Server@node2;Job;904.node2.supernodexp.hpc;Job Queued at request of ctminh@node2.supernodexp.hpc, owner = ctminh@node2.supernodexp.hpc, job name = qe_mic_test, queue = workq
02/13/2018 17:58:21;0100;Server@node2;Req;;Type 1 request received from ctminh@node2.supernodexp.hpc, sock=16
02/13/2018 17:58:21;0100;Server@node2;Req;;Type 3 request received from ctminh@node2.supernodexp.hpc, sock=16
02/13/2018 17:58:21;0100;Server@node2;Req;;Type 5 request received from ctminh@node2.supernodexp.hpc, sock=16
02/13/2018 17:58:21;0100;Server@node2;Job;905.node2.supernodexp.hpc;enqueuing into workq, state 1 hop 1
02/13/2018 17:58:21;0008;Server@node2;Job;905.node2.supernodexp.hpc;Job Queued at request of ctminh@node2.supernodexp.hpc, owner = ctminh@node2.supernodexp.hpc, job name = matrix-x-vector, queue = workq
02/13/2018 17:58:21;0100;Server@node2;Req;;Type 20 request received from Scheduler@node2.supernodexp.hpc, sock=20
02/13/2018 17:58:21;0100;Server@node2;Req;;Type 51 request received from Scheduler@node2.supernodexp.hpc, sock=20
02/13/2018 17:58:21;0100;Server@node2;Req;;Type 1 request received from ctminh@node2.supernodexp.hpc, sock=16
02/13/2018 17:58:21;0100;Server@node2;Req;;Type 3 request received from ctminh@node2.supernodexp.hpc, sock=16
02/13/2018 17:58:21;0100;Server@node2;Req;;Type 5 request received from ctminh@node2.supernodexp.hpc, sock=16
02/13/2018 17:58:21;0100;Server@node2;Job;906.node2.supernodexp.hpc;enqueuing into workq, state 1 hop 1
02/13/2018 17:58:21;0008;Server@node2;Job;906.node2.supernodexp.hpc;Job Queued at request of ctminh@node2.supernodexp.hpc, owner = ctminh@node2.supernodexp.hpc, job name = sweep, queue = workq
02/13/2018 17:58:21;0100;Server@node2;Req;;Type 1 request received from ctminh@node2.supernodexp.hpc, sock=16
02/13/2018 17:58:21;0100;Server@node2;Req;;Type 3 request received from ctminh@node2.supernodexp.hpc, sock=16
02/13/2018 17:58:21;0100;Server@node2;Req;;Type 5 request received from ctminh@node2.supernodexp.hpc, sock=16
02/13/2018 17:58:21;0100;Server@node2;Job;907.node2.supernodexp.hpc;enqueuing into workq, state 1 hop 1
02/13/2018 17:58:21;0008;Server@node2;Job;907.node2.supernodexp.hpc;Job Queued at request of ctminh@node2.supernodexp.hpc, owner = ctminh@node2.supernodexp.hpc, job name = nbody, queue = workq
02/13/2018 17:58:21;0100;Server@node2;Req;;Type 11 request received from Scheduler@node2.supernodexp.hpc, sock=20
02/13/2018 17:58:21;0008;Server@node2;Job;905.node2.supernodexp.hpc;Job Modified at request of Scheduler@node2.supernodexp.hpc
02/13/2018 17:58:21;0100;Server@node2;Req;;Type 11 request received from Scheduler@node2.supernodexp.hpc, sock=20
02/13/2018 17:58:21;0008;Server@node2;Job;902.node2.supernodexp.hpc;Job Modified at request of Scheduler@node2.supernodexp.hpc
02/13/2018 17:58:21;0100;Server@node2;Req;;Type 11 request received from Scheduler@node2.supernodexp.hpc, sock=20
02/13/2018 17:58:21;0008;Server@node2;Job;903.node2.supernodexp.hpc;Job Modified at request of Scheduler@node2.supernodexp.hpc
02/13/2018 17:58:21;0100;Server@node2;Req;;Type 11 request received from Scheduler@node2.supernodexp.hpc, sock=20
02/13/2018 17:58:21;0008;Server@node2;Job;904.node2.supernodexp.hpc;Job Modified at request of Scheduler@node2.supernodexp.hpc
02/13/2018 17:58:21;0040;Server@node2;Svr;node2.supernodexp.hpc;Scheduler sent command 1
02/13/2018 17:58:21;0040;Server@node2;Svr;node2.supernodexp.hpc;Scheduler sent command 0
02/13/2018 17:58:21;0100;Server@node2;Req;;Type 1 request received from ctminh@node2.supernodexp.hpc, sock=16
02/13/2018 17:58:21;0100;Server@node2;Req;;Type 21 request received from Scheduler@node2.supernodexp.hpc, sock=20
02/13/2018 17:58:21;0100;Server@node2;Req;;Type 3 request received from ctminh@node2.supernodexp.hpc, sock=16
02/13/2018 17:58:21;0100;Server@node2;Req;;Type 5 request received from ctminh@node2.supernodexp.hpc, sock=16
02/13/2018 17:58:21;0100;Server@node2;Job;908.node2.supernodexp.hpc;enqueuing into workq, state 1 hop 1
02/13/2018 17:58:21;0008;Server@node2;Job;908.node2.supernodexp.hpc;Job Queued at request of ctminh@node2.supernodexp.hpc, owner = ctminh@node2.supernodexp.hpc, job name = jacobi, queue = workq
02/13/2018 17:58:21;0100;Server@node2;Req;;Type 81 request received from Scheduler@node2.supernodexp.hpc, sock=20
02/13/2018 17:58:21;0100;Server@node2;Req;;Type 71 request received from Scheduler@node2.supernodexp.hpc, sock=20
02/13/2018 17:58:21;0100;Server@node2;Req;;Type 58 request received from Scheduler@node2.supernodexp.hpc, sock=20
02/13/2018 17:58:21;0100;Server@node2;Req;;Type 1 request received from ctminh@node2.supernodexp.hpc, sock=16
02/13/2018 17:58:21;0100;Server@node2;Req;;Type 3 request received from ctminh@node2.supernodexp.hpc, sock=16
02/13/2018 17:58:21;0100;Server@node2;Req;;Type 5 request received from ctminh@node2.supernodexp.hpc, sock=16
02/13/2018 17:58:21;0100;Server@node2;Job;909.node2.supernodexp.hpc;enqueuing into workq, state 1 hop 1
02/13/2018 17:58:21;0008;Server@node2;Job;909.node2.supernodexp.hpc;Job Queued at request of ctminh@node2.supernodexp.hpc, owner = ctminh@node2.supernodexp.hpc, job name = matrix-x-vector, queue = workq
02/13/2018 17:58:21;0100;Server@node2;Req;;Type 1 request received from ctminh@node2.supernodexp.hpc, sock=16
02/13/2018 17:58:21;0100;Server@node2;Req;;Type 20 request received from Scheduler@node2.supernodexp.hpc, sock=20
02/13/2018 17:58:21;0100;Server@node2;Req;;Type 3 request received from ctminh@node2.supernodexp.hpc, sock=16
02/13/2018 17:58:21;0100;Server@node2;Req;;Type 51 request received from Scheduler@node2.supernodexp.hpc, sock=20
02/13/2018 17:58:21;0100;Server@node2;Req;;Type 5 request received from ctminh@node2.supernodexp.hpc, sock=16
02/13/2018 17:58:21;0100;Server@node2;Job;910.node2.supernodexp.hpc;enqueuing into workq, state 1 hop 1
02/13/2018 17:58:21;0008;Server@node2;Job;910.node2.supernodexp.hpc;Job Queued at request of ctminh@node2.supernodexp.hpc, owner = ctminh@node2.supernodexp.hpc, job name = vectorization, queue = workq
02/13/2018 17:58:21;0100;Server@node2;Req;;Type 11 request received from Scheduler@node2.supernodexp.hpc, sock=20
02/13/2018 17:58:21;0008;Server@node2;Job;909.node2.supernodexp.hpc;Job Modified at request of Scheduler@node2.supernodexp.hpc
02/13/2018 17:58:21;0100;Server@node2;Req;;Type 11 request received from Scheduler@node2.supernodexp.hpc, sock=20
02/13/2018 17:58:21;0008;Server@node2;Job;906.node2.supernodexp.hpc;Job Modified at request of Scheduler@node2.supernodexp.hpc
02/13/2018 17:58:21;0100;Server@node2;Req;;Type 11 request received from Scheduler@node2.supernodexp.hpc, sock=20
02/13/2018 17:58:21;0008;Server@node2;Job;907.node2.supernodexp.hpc;Job Modified at request of Scheduler@node2.supernodexp.hpc
02/13/2018 17:58:21;0100;Server@node2;Req;;Type 11 request received from Scheduler@node2.supernodexp.hpc, sock=20
02/13/2018 17:58:21;0008;Server@node2;Job;908.node2.supernodexp.hpc;Job Modified at request of Scheduler@node2.supernodexp.hpc
02/13/2018 17:58:21;0100;Server@node2;Req;;Type 1 request received from ctminh@node2.supernodexp.hpc, sock=16
02/13/2018 17:58:21;0040;Server@node2;Svr;node2.supernodexp.hpc;Scheduler sent command 1
02/13/2018 17:58:21;0040;Server@node2;Svr;node2.supernodexp.hpc;Scheduler sent command 0
02/13/2018 17:58:21;0100;Server@node2;Req;;Type 3 request received from ctminh@node2.supernodexp.hpc, sock=16
02/13/2018 17:58:21;0100;Server@node2;Req;;Type 21 request received from Scheduler@node2.supernodexp.hpc, sock=20
02/13/2018 17:58:21;0100;Server@node2;Req;;Type 5 request received from ctminh@node2.supernodexp.hpc, sock=16
02/13/2018 17:58:21;0100;Server@node2;Job;911.node2.supernodexp.hpc;enqueuing into workq, state 1 hop 1
02/13/2018 17:58:21;0008;Server@node2;Job;911.node2.supernodexp.hpc;Job Queued at request of ctminh@node2.supernodexp.hpc, owner = ctminh@node2.supernodexp.hpc, job name = qe_mic_test, queue = workq
02/13/2018 17:58:21;0100;Server@node2;Req;;Type 81 request received from Scheduler@node2.supernodexp.hpc, sock=20
02/13/2018 17:58:21;0100;Server@node2;Req;;Type 71 request received from Scheduler@node2.supernodexp.hpc, sock=20
02/13/2018 17:58:21;0100;Server@node2;Req;;Type 58 request received from Scheduler@node2.supernodexp.hpc, sock=20
02/13/2018 17:58:21;0100;Server@node2;Req;;Type 1 request received from ctminh@node2.supernodexp.hpc, sock=16
02/13/2018 17:58:21;0100;Server@node2;Req;;Type 3 request received from ctminh@node2.supernodexp.hpc, sock=16
02/13/2018 17:58:21;0100;Server@node2;Req;;Type 5 request received from ctminh@node2.supernodexp.hpc, sock=16
02/13/2018 17:58:21;0100;Server@node2;Job;912.node2.supernodexp.hpc;enqueuing into workq, state 1 hop 1
02/13/2018 17:58:21;0008;Server@node2;Job;912.node2.supernodexp.hpc;Job Queued at request of ctminh@node2.supernodexp.hpc, owner = ctminh@node2.supernodexp.hpc, job name = thread-affinity, queue = workq
02/13/2018 17:58:21;0100;Server@node2;Req;;Type 1 request received from ctminh@node2.supernodexp.hpc, sock=16
02/13/2018 17:58:21;0100;Server@node2;Req;;Type 20 request received from Scheduler@node2.supernodexp.hpc, sock=20
02/13/2018 17:58:21;0100;Server@node2;Req;;Type 3 request received from ctminh@node2.supernodexp.hpc, sock=16
02/13/2018 17:58:21;0100;Server@node2;Req;;Type 51 request received from Scheduler@node2.supernodexp.hpc, sock=20
02/13/2018 17:58:21;0100;Server@node2;Req;;Type 5 request received from ctminh@node2.supernodexp.hpc, sock=16
02/13/2018 17:58:21;0100;Server@node2;Job;913.node2.supernodexp.hpc;enqueuing into workq, state 1 hop 1
02/13/2018 17:58:21;0008;Server@node2;Job;913.node2.supernodexp.hpc;Job Queued at request of ctminh@node2.supernodexp.hpc, owner = ctminh@node2.supernodexp.hpc, job name = histogram, queue = workq
02/13/2018 17:58:21;0100;Server@node2;Req;;Type 1 request received from ctminh@node2.supernodexp.hpc, sock=16
02/13/2018 17:58:21;0100;Server@node2;Req;;Type 3 request received from ctminh@node2.supernodexp.hpc, sock=16
02/13/2018 17:58:21;0100;Server@node2;Req;;Type 5 request received from ctminh@node2.supernodexp.hpc, sock=16
02/13/2018 17:58:21;0100;Server@node2;Job;914.node2.supernodexp.hpc;enqueuing into workq, state 1 hop 1
02/13/2018 17:58:21;0008;Server@node2;Job;914.node2.supernodexp.hpc;Job Queued at request of ctminh@node2.supernodexp.hpc, owner = ctminh@node2.supernodexp.hpc, job name = histogram, queue = workq
02/13/2018 17:58:21;0100;Server@node2;Req;;Type 1 request received from ctminh@node2.supernodexp.hpc, sock=16
02/13/2018 17:58:21;0100;Server@node2;Req;;Type 3 request received from ctminh@node2.supernodexp.hpc, sock=16
02/13/2018 17:58:21;0100;Server@node2;Req;;Type 5 request received from ctminh@node2.supernodexp.hpc, sock=16
02/13/2018 17:58:21;0100;Server@node2;Job;915.node2.supernodexp.hpc;enqueuing into workq, state 1 hop 1
02/13/2018 17:58:21;0008;Server@node2;Job;915.node2.supernodexp.hpc;Job Queued at request of ctminh@node2.supernodexp.hpc, owner = ctminh@node2.supernodexp.hpc, job name = telemac2, queue = workq
02/13/2018 17:58:21;0100;Server@node2;Req;;Type 11 request received from Scheduler@node2.supernodexp.hpc, sock=20
02/13/2018 17:58:21;0008;Server@node2;Job;910.node2.supernodexp.hpc;Job Modified at request of Scheduler@node2.supernodexp.hpc
02/13/2018 17:58:21;0100;Server@node2;Req;;Type 11 request received from Scheduler@node2.supernodexp.hpc, sock=20
02/13/2018 17:58:21;0008;Server@node2;Job;912.node2.supernodexp.hpc;Job Modified at request of Scheduler@node2.supernodexp.hpc
02/13/2018 17:58:21;0100;Server@node2;Req;;Type 11 request received from Scheduler@node2.supernodexp.hpc, sock=20
02/13/2018 17:58:21;0008;Server@node2;Job;911.node2.supernodexp.hpc;Job Modified at request of Scheduler@node2.supernodexp.hpc
02/13/2018 17:58:21;0040;Server@node2;Svr;node2.supernodexp.hpc;Scheduler sent command 1
02/13/2018 17:58:21;0040;Server@node2;Svr;node2.supernodexp.hpc;Scheduler sent command 0
02/13/2018 17:58:21;0100;Server@node2;Req;;Type 21 request received from Scheduler@node2.supernodexp.hpc, sock=20
02/13/2018 17:58:21;0100;Server@node2;Req;;Type 81 request received from Scheduler@node2.supernodexp.hpc, sock=20
02/13/2018 17:58:21;0100;Server@node2;Req;;Type 71 request received from Scheduler@node2.supernodexp.hpc, sock=20
02/13/2018 17:58:21;0100;Server@node2;Req;;Type 58 request received from Scheduler@node2.supernodexp.hpc, sock=20
02/13/2018 17:58:21;0100;Server@node2;Req;;Type 1 request received from ctminh@node2.supernodexp.hpc, sock=16
02/13/2018 17:58:21;0100;Server@node2;Req;;Type 3 request received from ctminh@node2.supernodexp.hpc, sock=16
02/13/2018 17:58:21;0100;Server@node2;Req;;Type 5 request received from ctminh@node2.supernodexp.hpc, sock=16
02/13/2018 17:58:21;0100;Server@node2;Job;916.node2.supernodexp.hpc;enqueuing into workq, state 1 hop 1
02/13/2018 17:58:21;0008;Server@node2;Job;916.node2.supernodexp.hpc;Job Queued at request of ctminh@node2.supernodexp.hpc, owner = ctminh@node2.supernodexp.hpc, job name = telemac1, queue = workq
02/13/2018 17:58:21;0100;Server@node2;Req;;Type 1 request received from ctminh@node2.supernodexp.hpc, sock=16
02/13/2018 17:58:21;0100;Server@node2;Req;;Type 3 request received from ctminh@node2.supernodexp.hpc, sock=16
02/13/2018 17:58:21;0100;Server@node2;Req;;Type 5 request received from ctminh@node2.supernodexp.hpc, sock=16
02/13/2018 17:58:21;0100;Server@node2;Job;917.node2.supernodexp.hpc;enqueuing into workq, state 1 hop 1
02/13/2018 17:58:21;0008;Server@node2;Job;917.node2.supernodexp.hpc;Job Queued at request of ctminh@node2.supernodexp.hpc, owner = ctminh@node2.supernodexp.hpc, job name = vast1, queue = workq
02/13/2018 17:58:21;0100;Server@node2;Req;;Type 20 request received from Scheduler@node2.supernodexp.hpc, sock=20
02/13/2018 17:58:21;0100;Server@node2;Req;;Type 51 request received from Scheduler@node2.supernodexp.hpc, sock=20
02/13/2018 17:58:21;0100;Server@node2;Req;;Type 1 request received from ctminh@node2.supernodexp.hpc, sock=16
02/13/2018 17:58:21;0100;Server@node2;Req;;Type 3 request received from ctminh@node2.supernodexp.hpc, sock=16
02/13/2018 17:58:21;0100;Server@node2;Req;;Type 5 request received from ctminh@node2.supernodexp.hpc, sock=16
02/13/2018 17:58:21;0100;Server@node2;Job;918.node2.supernodexp.hpc;enqueuing into workq, state 1 hop 1
02/13/2018 17:58:21;0008;Server@node2;Job;918.node2.supernodexp.hpc;Job Queued at request of ctminh@node2.supernodexp.hpc, owner = ctminh@node2.supernodexp.hpc, job name = sweep, queue = workq
02/13/2018 17:58:21;0100;Server@node2;Req;;Type 1 request received from ctminh@node2.supernodexp.hpc, sock=16
02/13/2018 17:58:21;0100;Server@node2;Req;;Type 3 request received from ctminh@node2.supernodexp.hpc, sock=16
02/13/2018 17:58:21;0100;Server@node2;Req;;Type 5 request received from ctminh@node2.supernodexp.hpc, sock=16
02/13/2018 17:58:21;0100;Server@node2;Job;919.node2.supernodexp.hpc;enqueuing into workq, state 1 hop 1
02/13/2018 17:58:21;0008;Server@node2;Job;919.node2.supernodexp.hpc;Job Queued at request of ctminh@node2.supernodexp.hpc, owner = ctminh@node2.supernodexp.hpc, job name = vectorization, queue = workq
02/13/2018 17:58:21;0100;Server@node2;Req;;Type 11 request received from Scheduler@node2.supernodexp.hpc, sock=20
02/13/2018 17:58:21;0008;Server@node2;Job;913.node2.supernodexp.hpc;Job Modified at request of Scheduler@node2.supernodexp.hpc
02/13/2018 17:58:21;0100;Server@node2;Req;;Type 11 request received from Scheduler@node2.supernodexp.hpc, sock=20
02/13/2018 17:58:21;0008;Server@node2;Job;914.node2.supernodexp.hpc;Job Modified at request of Scheduler@node2.supernodexp.hpc
02/13/2018 17:58:21;0100;Server@node2;Req;;Type 11 request received from Scheduler@node2.supernodexp.hpc, sock=20
02/13/2018 17:58:21;0008;Server@node2;Job;916.node2.supernodexp.hpc;Job Modified at request of Scheduler@node2.supernodexp.hpc
02/13/2018 17:58:21;0100;Server@node2;Req;;Type 11 request received from Scheduler@node2.supernodexp.hpc, sock=20
02/13/2018 17:58:21;0008;Server@node2;Job;915.node2.supernodexp.hpc;Job Modified at request of Scheduler@node2.supernodexp.hpc
02/13/2018 17:58:21;0100;Server@node2;Req;;Type 11 request received from Scheduler@node2.supernodexp.hpc, sock=20
02/13/2018 17:58:21;0008;Server@node2;Job;917.node2.supernodexp.hpc;Job Modified at request of Scheduler@node2.supernodexp.hpc
02/13/2018 17:58:21;0040;Server@node2;Svr;node2.supernodexp.hpc;Scheduler sent command 1
02/13/2018 17:58:21;0040;Server@node2;Svr;node2.supernodexp.hpc;Scheduler sent command 0
02/13/2018 17:58:21;0100;Server@node2;Req;;Type 21 request received from Scheduler@node2.supernodexp.hpc, sock=20
02/13/2018 17:58:21;0100;Server@node2;Req;;Type 81 request received from Scheduler@node2.supernodexp.hpc, sock=20
02/13/2018 17:58:21;0100;Server@node2;Req;;Type 71 request received from Scheduler@node2.supernodexp.hpc, sock=20
02/13/2018 17:58:21;0100;Server@node2;Req;;Type 58 request received from Scheduler@node2.supernodexp.hpc, sock=20
02/13/2018 17:58:21;0100;Server@node2;Req;;Type 1 request received from ctminh@node2.supernodexp.hpc, sock=16
02/13/2018 17:58:21;0100;Server@node2;Req;;Type 3 request received from ctminh@node2.supernodexp.hpc, sock=16
02/13/2018 17:58:21;0100;Server@node2;Req;;Type 5 request received from ctminh@node2.supernodexp.hpc, sock=16
02/13/2018 17:58:21;0100;Server@node2;Job;920.node2.supernodexp.hpc;enqueuing into workq, state 1 hop 1
02/13/2018 17:58:21;0008;Server@node2;Job;920.node2.supernodexp.hpc;Job Queued at request of ctminh@node2.supernodexp.hpc, owner = ctminh@node2.supernodexp.hpc, job name = nbody, queue = workq
02/13/2018 17:58:21;0100;Server@node2;Req;;Type 20 request received from Scheduler@node2.supernodexp.hpc, sock=20
02/13/2018 17:58:21;0100;Server@node2;Req;;Type 51 request received from Scheduler@node2.supernodexp.hpc, sock=20
02/13/2018 17:58:21;0010;Server@node2;Job;869.node2.supernodexp.hpc;Exit_status=0 resources_used.cpupercent=79 resources_used.cput=00:00:04 resources_used.mem=0kb resources_used.ncpus=32 resources_used.vmem=0kb resources_used.walltime=00:00:05
02/13/2018 17:58:21;0100;Server@node2;Job;869.node2.supernodexp.hpc;dequeuing from workq, state 5
02/13/2018 17:58:21;0100;Server@node2;Req;;Type 11 request received from Scheduler@node2.supernodexp.hpc, sock=20
02/13/2018 17:58:21;0008;Server@node2;Job;918.node2.supernodexp.hpc;Job Modified at request of Scheduler@node2.supernodexp.hpc
02/13/2018 17:58:21;0100;Server@node2;Req;;Type 11 request received from Scheduler@node2.supernodexp.hpc, sock=20
02/13/2018 17:58:21;0008;Server@node2;Job;919.node2.supernodexp.hpc;Job Modified at request of Scheduler@node2.supernodexp.hpc
02/13/2018 17:58:21;0100;Server@node2;Req;;Type 11 request received from Scheduler@node2.supernodexp.hpc, sock=20
02/13/2018 17:58:21;0008;Server@node2;Job;920.node2.supernodexp.hpc;Job Modified at request of Scheduler@node2.supernodexp.hpc
02/13/2018 17:58:21;0040;Server@node2;Svr;node2.supernodexp.hpc;Scheduler sent command 2
02/13/2018 17:58:21;0040;Server@node2;Svr;node2.supernodexp.hpc;Scheduler sent command 0
02/13/2018 17:58:21;0100;Server@node2;Req;;Type 21 request received from Scheduler@node2.supernodexp.hpc, sock=20
02/13/2018 17:58:21;0100;Server@node2;Req;;Type 81 request received from Scheduler@node2.supernodexp.hpc, sock=20
02/13/2018 17:58:21;0100;Server@node2;Req;;Type 71 request received from Scheduler@node2.supernodexp.hpc, sock=20
02/13/2018 17:58:21;0100;Server@node2;Req;;Type 58 request received from Scheduler@node2.supernodexp.hpc, sock=20
02/13/2018 17:58:21;0100;Server@node2;Req;;Type 20 request received from Scheduler@node2.supernodexp.hpc, sock=20
02/13/2018 17:58:21;0100;Server@node2;Req;;Type 51 request received from Scheduler@node2.supernodexp.hpc, sock=20
02/13/2018 17:58:21;0100;Server@node2;Req;;Type 23 request received from Scheduler@node2.supernodexp.hpc, sock=20
02/13/2018 17:58:21;0008;Server@node2;Job;888.node2.supernodexp.hpc;Job Run at request of Scheduler@node2.supernodexp.hpc on exec_vnode (node13:ncpus=24:mem=1048576kb)
02/13/2018 17:58:21;0001;Server@node2;Svr;Server@node2;Success (0) in req_runjob2, return value of svr_startjob is 0
02/13/2018 17:58:21;0100;Server@node2;Req;;Type 11 request received from Scheduler@node2.supernodexp.hpc, sock=20
02/13/2018 17:58:21;0008;Server@node2;Job;896.node2.supernodexp.hpc;Job Modified at request of Scheduler@node2.supernodexp.hpc
02/13/2018 17:58:23;0080;Server@node2;Job;888.node2.supernodexp.hpc;Obit received momhop:1 serverhop:1 state:4 substate:42
02/13/2018 17:58:25;0010;Server@node2;Job;888.node2.supernodexp.hpc;Exit_status=0 resources_used.cpupercent=2100 resources_used.cput=00:00:42 resources_used.mem=0kb resources_used.ncpus=24 resources_used.vmem=0kb resources_used.walltime=00:00:02
02/13/2018 17:58:25;0100;Server@node2;Job;888.node2.supernodexp.hpc;dequeuing from workq, state 5
02/13/2018 17:58:25;0040;Server@node2;Svr;node2.supernodexp.hpc;Scheduler sent command 2
02/13/2018 17:58:25;0040;Server@node2;Svr;node2.supernodexp.hpc;Scheduler sent command 0
02/13/2018 17:58:25;0100;Server@node2;Req;;Type 21 request received from Scheduler@node2.supernodexp.hpc, sock=20
02/13/2018 17:58:25;0100;Server@node2;Req;;Type 81 request received from Scheduler@node2.supernodexp.hpc, sock=20
02/13/2018 17:58:25;0100;Server@node2;Req;;Type 71 request received from Scheduler@node2.supernodexp.hpc, sock=20
02/13/2018 17:58:25;0100;Server@node2;Req;;Type 58 request received from Scheduler@node2.supernodexp.hpc, sock=20
02/13/2018 17:58:25;0100;Server@node2;Req;;Type 20 request received from Scheduler@node2.supernodexp.hpc, sock=20
02/13/2018 17:58:25;0100;Server@node2;Req;;Type 51 request received from Scheduler@node2.supernodexp.hpc, sock=20
02/13/2018 17:58:25;0100;Server@node2;Req;;Type 23 request received from Scheduler@node2.supernodexp.hpc, sock=20
02/13/2018 17:58:25;0008;Server@node2;Job;896.node2.supernodexp.hpc;Job Run at request of Scheduler@node2.supernodexp.hpc on exec_vnode (node13:ncpus=16:mem=5242880kb)
02/13/2018 17:58:25;0001;Server@node2;Svr;Server@node2;Success (0) in req_runjob2, return value of svr_startjob is 0
02/13/2018 17:58:25;0100;Server@node2;Req;;Type 23 request received from Scheduler@node2.supernodexp.hpc, sock=20
02/13/2018 17:58:25;0008;Server@node2;Job;905.node2.supernodexp.hpc;Job Run at request of Scheduler@node2.supernodexp.hpc on exec_vnode (node13:ncpus=16:mem=5242880kb)
02/13/2018 17:58:25;0001;Server@node2;Svr;Server@node2;Success (0) in req_runjob2, return value of svr_startjob is 0
02/13/2018 17:58:25;0100;Server@node2;Req;;Type 11 request received from Scheduler@node2.supernodexp.hpc, sock=20
02/13/2018 17:58:25;0008;Server@node2;Job;909.node2.supernodexp.hpc;Job Modified at request of Scheduler@node2.supernodexp.hpc
02/13/2018 17:58:26;0080;Server@node2;Job;896.node2.supernodexp.hpc;Obit received momhop:1 serverhop:1 state:4 substate:42
02/13/2018 17:58:26;0080;Server@node2;Job;905.node2.supernodexp.hpc;Obit received momhop:1 serverhop:1 state:4 substate:42
02/13/2018 17:58:27;0080;Server@node2;Job;834.node2.supernodexp.hpc;Obit received momhop:1 serverhop:1 state:4 substate:42
02/13/2018 17:58:28;0010;Server@node2;Job;896.node2.supernodexp.hpc;Exit_status=0 resources_used.cpupercent=1600 resources_used.cput=00:00:19 resources_used.mem=0kb resources_used.ncpus=16 resources_used.vmem=0kb resources_used.walltime=00:00:02
02/13/2018 17:58:28;0100;Server@node2;Job;896.node2.supernodexp.hpc;dequeuing from workq, state 5
02/13/2018 17:58:28;0010;Server@node2;Job;905.node2.supernodexp.hpc;Exit_status=0 resources_used.cpupercent=1600 resources_used.cput=00:00:19 resources_used.mem=4205596kb resources_used.ncpus=16 resources_used.vmem=5507028kb resources_used.walltime=00:00:02
02/13/2018 17:58:28;0100;Server@node2;Job;905.node2.supernodexp.hpc;dequeuing from workq, state 5
02/13/2018 17:58:28;0040;Server@node2;Svr;node2.supernodexp.hpc;Scheduler sent command 2
02/13/2018 17:58:28;0040;Server@node2;Svr;node2.supernodexp.hpc;Scheduler sent command 0
02/13/2018 17:58:28;0100;Server@node2;Req;;Type 21 request received from Scheduler@node2.supernodexp.hpc, sock=20
02/13/2018 17:58:28;0100;Server@node2;Req;;Type 81 request received from Scheduler@node2.supernodexp.hpc, sock=20
02/13/2018 17:58:28;0100;Server@node2;Req;;Type 71 request received from Scheduler@node2.supernodexp.hpc, sock=20
02/13/2018 17:58:28;0100;Server@node2;Req;;Type 58 request received from Scheduler@node2.supernodexp.hpc, sock=20
02/13/2018 17:58:28;0100;Server@node2;Req;;Type 20 request received from Scheduler@node2.supernodexp.hpc, sock=20
02/13/2018 17:58:28;0100;Server@node2;Req;;Type 51 request received from Scheduler@node2.supernodexp.hpc, sock=20
02/13/2018 17:58:28;0100;Server@node2;Req;;Type 23 request received from Scheduler@node2.supernodexp.hpc, sock=20
02/13/2018 17:58:28;0008;Server@node2;Job;909.node2.supernodexp.hpc;Job Run at request of Scheduler@node2.supernodexp.hpc on exec_vnode (node13:ncpus=16:mem=5242880kb)
02/13/2018 17:58:28;0001;Server@node2;Svr;Server@node2;Success (0) in req_runjob2, return value of svr_startjob is 0
02/13/2018 17:58:28;0100;Server@node2;Req;;Type 11 request received from Scheduler@node2.supernodexp.hpc, sock=20
02/13/2018 17:58:28;0008;Server@node2;Job;871.node2.supernodexp.hpc;Job Modified at request of Scheduler@node2.supernodexp.hpc
02/13/2018 17:58:28;0010;Server@node2;Job;834.node2.supernodexp.hpc;Exit_status=0 resources_used.cpupercent=1207 resources_used.cput=00:13:14 resources_used.mem=94832kb resources_used.ncpus=16 resources_used.vmem=1472432kb resources_used.walltime=00:00:54
02/13/2018 17:58:28;0100;Server@node2;Job;834.node2.supernodexp.hpc;dequeuing from workq, state 5
02/13/2018 17:58:28;0040;Server@node2;Svr;node2.supernodexp.hpc;Scheduler sent command 2
02/13/2018 17:58:28;0040;Server@node2;Svr;node2.supernodexp.hpc;Scheduler sent command 0
02/13/2018 17:58:28;0100;Server@node2;Req;;Type 21 request received from Scheduler@node2.supernodexp.hpc, sock=20
02/13/2018 17:58:28;0100;Server@node2;Req;;Type 81 request received from Scheduler@node2.supernodexp.hpc, sock=20
02/13/2018 17:58:28;0100;Server@node2;Req;;Type 71 request received from Scheduler@node2.supernodexp.hpc, sock=20
02/13/2018 17:58:28;0100;Server@node2;Req;;Type 58 request received from Scheduler@node2.supernodexp.hpc, sock=20
02/13/2018 17:58:28;0100;Server@node2;Req;;Type 20 request received from Scheduler@node2.supernodexp.hpc, sock=20
02/13/2018 17:58:28;0100;Server@node2;Req;;Type 51 request received from Scheduler@node2.supernodexp.hpc, sock=20
02/13/2018 17:58:28;0100;Server@node2;Req;;Type 23 request received from Scheduler@node2.supernodexp.hpc, sock=20
02/13/2018 17:58:28;0008;Server@node2;Job;871.node2.supernodexp.hpc;Job Run at request of Scheduler@node2.supernodexp.hpc on exec_vnode (node13:ncpus=32:mem=2097152kb)
02/13/2018 17:58:28;0001;Server@node2;Svr;Server@node2;Success (0) in req_runjob2, return value of svr_startjob is 0
02/13/2018 17:58:28;0100;Server@node2;Req;;Type 11 request received from Scheduler@node2.supernodexp.hpc, sock=20
02/13/2018 17:58:28;0008;Server@node2;Job;873.node2.supernodexp.hpc;Job Modified at request of Scheduler@node2.supernodexp.hpc
02/13/2018 17:58:29;0080;Server@node2;Job;909.node2.supernodexp.hpc;Obit received momhop:1 serverhop:1 state:4 substate:42
02/13/2018 17:58:30;0010;Server@node2;Job;909.node2.supernodexp.hpc;Exit_status=0 resources_used.cpupercent=201 resources_used.cput=00:00:09 resources_used.mem=4115832kb resources_used.ncpus=16 resources_used.vmem=5511120kb resources_used.walltime=00:00:00
02/13/2018 17:58:30;0100;Server@node2;Job;909.node2.supernodexp.hpc;dequeuing from workq, state 5
02/13/2018 17:58:30;0040;Server@node2;Svr;node2.supernodexp.hpc;Scheduler sent command 2
02/13/2018 17:58:30;0040;Server@node2;Svr;node2.supernodexp.hpc;Scheduler sent command 0
02/13/2018 17:58:30;0100;Server@node2;Req;;Type 21 request received from Scheduler@node2.supernodexp.hpc, sock=20
02/13/2018 17:58:30;0100;Server@node2;Req;;Type 81 request received from Scheduler@node2.supernodexp.hpc, sock=20
02/13/2018 17:58:30;0100;Server@node2;Req;;Type 71 request received from Scheduler@node2.supernodexp.hpc, sock=20
02/13/2018 17:58:30;0100;Server@node2;Req;;Type 58 request received from Scheduler@node2.supernodexp.hpc, sock=20
02/13/2018 17:58:30;0100;Server@node2;Req;;Type 20 request received from Scheduler@node2.supernodexp.hpc, sock=20
02/13/2018 17:58:30;0100;Server@node2;Req;;Type 51 request received from Scheduler@node2.supernodexp.hpc, sock=20
02/13/2018 17:58:30;0100;Server@node2;Req;;Type 11 request received from Scheduler@node2.supernodexp.hpc, sock=20
02/13/2018 17:58:30;0008;Server@node2;Job;873.node2.supernodexp.hpc;Job Modified at request of Scheduler@node2.supernodexp.hpc
02/13/2018 17:58:32;0080;Server@node2;Job;871.node2.supernodexp.hpc;Obit received momhop:1 serverhop:1 state:4 substate:42
02/13/2018 17:58:33;0010;Server@node2;Job;871.node2.supernodexp.hpc;Exit_status=0 resources_used.cpupercent=100 resources_used.cput=00:00:03 resources_used.mem=537268kb resources_used.ncpus=32 resources_used.vmem=867312kb resources_used.walltime=00:00:04
02/13/2018 17:58:33;0100;Server@node2;Job;871.node2.supernodexp.hpc;dequeuing from workq, state 5
02/13/2018 17:58:33;0040;Server@node2;Svr;node2.supernodexp.hpc;Scheduler sent command 2
02/13/2018 17:58:33;0040;Server@node2;Svr;node2.supernodexp.hpc;Scheduler sent command 0
02/13/2018 17:58:33;0100;Server@node2;Req;;Type 21 request received from Scheduler@node2.supernodexp.hpc, sock=20
02/13/2018 17:58:33;0100;Server@node2;Req;;Type 81 request received from Scheduler@node2.supernodexp.hpc, sock=20
02/13/2018 17:58:33;0100;Server@node2;Req;;Type 71 request received from Scheduler@node2.supernodexp.hpc, sock=20
02/13/2018 17:58:33;0100;Server@node2;Req;;Type 58 request received from Scheduler@node2.supernodexp.hpc, sock=20
02/13/2018 17:58:33;0100;Server@node2;Req;;Type 20 request received from Scheduler@node2.supernodexp.hpc, sock=20
02/13/2018 17:58:33;0100;Server@node2;Req;;Type 51 request received from Scheduler@node2.supernodexp.hpc, sock=20
02/13/2018 17:58:33;0100;Server@node2;Req;;Type 23 request received from Scheduler@node2.supernodexp.hpc, sock=20
02/13/2018 17:58:33;0008;Server@node2;Job;873.node2.supernodexp.hpc;Job Run at request of Scheduler@node2.supernodexp.hpc on exec_vnode (node13:ncpus=32:mem=2097152kb)
02/13/2018 17:58:33;0001;Server@node2;Svr;Server@node2;Success (0) in req_runjob2, return value of svr_startjob is 0
02/13/2018 17:58:33;0100;Server@node2;Req;;Type 23 request received from Scheduler@node2.supernodexp.hpc, sock=20
02/13/2018 17:58:33;0008;Server@node2;Job;874.node2.supernodexp.hpc;Job Run at request of Scheduler@node2.supernodexp.hpc on exec_vnode (node13:ncpus=12:mem=1048576kb)
02/13/2018 17:58:33;0001;Server@node2;Svr;Server@node2;Success (0) in req_runjob2, return value of svr_startjob is 0
02/13/2018 17:58:33;0100;Server@node2;Req;;Type 11 request received from Scheduler@node2.supernodexp.hpc, sock=20
02/13/2018 17:58:33;0008;Server@node2;Job;879.node2.supernodexp.hpc;Job Modified at request of Scheduler@node2.supernodexp.hpc
02/13/2018 17:58:37;0080;Server@node2;Job;873.node2.supernodexp.hpc;Obit received momhop:1 serverhop:1 state:4 substate:42
02/13/2018 17:58:39;0010;Server@node2;Job;873.node2.supernodexp.hpc;Exit_status=0 resources_used.cpupercent=100 resources_used.cput=00:00:04 resources_used.mem=0kb resources_used.ncpus=32 resources_used.vmem=0kb resources_used.walltime=00:00:04
02/13/2018 17:58:39;0100;Server@node2;Job;873.node2.supernodexp.hpc;dequeuing from workq, state 5
02/13/2018 17:58:39;0040;Server@node2;Svr;node2.supernodexp.hpc;Scheduler sent command 2
02/13/2018 17:58:39;0040;Server@node2;Svr;node2.supernodexp.hpc;Scheduler sent command 0
02/13/2018 17:58:39;0100;Server@node2;Req;;Type 21 request received from Scheduler@node2.supernodexp.hpc, sock=20
02/13/2018 17:58:39;0100;Server@node2;Req;;Type 81 request received from Scheduler@node2.supernodexp.hpc, sock=20
02/13/2018 17:58:39;0100;Server@node2;Req;;Type 71 request received from Scheduler@node2.supernodexp.hpc, sock=20
02/13/2018 17:58:39;0100;Server@node2;Req;;Type 58 request received from Scheduler@node2.supernodexp.hpc, sock=20
02/13/2018 17:58:39;0100;Server@node2;Req;;Type 20 request received from Scheduler@node2.supernodexp.hpc, sock=20
02/13/2018 17:58:39;0100;Server@node2;Req;;Type 51 request received from Scheduler@node2.supernodexp.hpc, sock=20
02/13/2018 17:58:39;0100;Server@node2;Req;;Type 23 request received from Scheduler@node2.supernodexp.hpc, sock=20
02/13/2018 17:58:39;0008;Server@node2;Job;879.node2.supernodexp.hpc;Job Run at request of Scheduler@node2.supernodexp.hpc on exec_vnode (node13:ncpus=12:mem=1048576kb)
02/13/2018 17:58:39;0001;Server@node2;Svr;Server@node2;Success (0) in req_runjob2, return value of svr_startjob is 0
02/13/2018 17:58:39;0100;Server@node2;Req;;Type 11 request received from Scheduler@node2.supernodexp.hpc, sock=20
02/13/2018 17:58:39;0008;Server@node2;Job;880.node2.supernodexp.hpc;Job Modified at request of Scheduler@node2.supernodexp.hpc
02/13/2018 17:58:40;0080;Server@node2;Job;874.node2.supernodexp.hpc;Obit received momhop:1 serverhop:1 state:4 substate:42
02/13/2018 17:58:41;0010;Server@node2;Job;874.node2.supernodexp.hpc;Exit_status=0 resources_used.cpupercent=1125 resources_used.cput=00:01:11 resources_used.mem=28460kb resources_used.ncpus=12 resources_used.vmem=1125532kb resources_used.walltime=00:00:06
02/13/2018 17:58:41;0100;Server@node2;Job;874.node2.supernodexp.hpc;dequeuing from workq, state 5
02/13/2018 17:58:41;0040;Server@node2;Svr;node2.supernodexp.hpc;Scheduler sent command 2
02/13/2018 17:58:41;0040;Server@node2;Svr;node2.supernodexp.hpc;Scheduler sent command 0
02/13/2018 17:58:41;0100;Server@node2;Req;;Type 21 request received from Scheduler@node2.supernodexp.hpc, sock=20
02/13/2018 17:58:41;0100;Server@node2;Req;;Type 81 request received from Scheduler@node2.supernodexp.hpc, sock=20
02/13/2018 17:58:41;0100;Server@node2;Req;;Type 71 request received from Scheduler@node2.supernodexp.hpc, sock=20
02/13/2018 17:58:41;0100;Server@node2;Req;;Type 58 request received from Scheduler@node2.supernodexp.hpc, sock=20
02/13/2018 17:58:41;0100;Server@node2;Req;;Type 20 request received from Scheduler@node2.supernodexp.hpc, sock=20
02/13/2018 17:58:41;0100;Server@node2;Req;;Type 51 request received from Scheduler@node2.supernodexp.hpc, sock=20
02/13/2018 17:58:41;0100;Server@node2;Req;;Type 23 request received from Scheduler@node2.supernodexp.hpc, sock=20
02/13/2018 17:58:41;0008;Server@node2;Job;880.node2.supernodexp.hpc;Job Run at request of Scheduler@node2.supernodexp.hpc on exec_vnode (node13:ncpus=32:mem=2097152kb)
02/13/2018 17:58:41;0001;Server@node2;Svr;Server@node2;Success (0) in req_runjob2, return value of svr_startjob is 0
02/13/2018 17:58:41;0100;Server@node2;Req;;Type 11 request received from Scheduler@node2.supernodexp.hpc, sock=20
02/13/2018 17:58:41;0008;Server@node2;Job;885.node2.supernodexp.hpc;Job Modified at request of Scheduler@node2.supernodexp.hpc
02/13/2018 17:58:45;0080;Server@node2;Job;879.node2.supernodexp.hpc;Obit received momhop:1 serverhop:1 state:4 substate:42
02/13/2018 17:58:45;0080;Server@node2;Job;880.node2.supernodexp.hpc;Obit received momhop:1 serverhop:1 state:4 substate:42
02/13/2018 17:58:46;0010;Server@node2;Job;879.node2.supernodexp.hpc;Exit_status=0 resources_used.cpupercent=807 resources_used.cput=00:01:12 resources_used.mem=29660kb resources_used.ncpus=12 resources_used.vmem=1125532kb resources_used.walltime=00:00:06
02/13/2018 17:58:46;0100;Server@node2;Job;879.node2.supernodexp.hpc;dequeuing from workq, state 5
02/13/2018 17:58:46;0040;Server@node2;Svr;node2.supernodexp.hpc;Scheduler sent command 2
02/13/2018 17:58:46;0040;Server@node2;Svr;node2.supernodexp.hpc;Scheduler sent command 0
02/13/2018 17:58:46;0100;Server@node2;Req;;Type 21 request received from Scheduler@node2.supernodexp.hpc, sock=20
02/13/2018 17:58:46;0100;Server@node2;Req;;Type 81 request received from Scheduler@node2.supernodexp.hpc, sock=20
02/13/2018 17:58:46;0100;Server@node2;Req;;Type 71 request received from Scheduler@node2.supernodexp.hpc, sock=20
02/13/2018 17:58:46;0100;Server@node2;Req;;Type 58 request received from Scheduler@node2.supernodexp.hpc, sock=20
02/13/2018 17:58:46;0100;Server@node2;Req;;Type 20 request received from Scheduler@node2.supernodexp.hpc, sock=20
02/13/2018 17:58:46;0100;Server@node2;Req;;Type 51 request received from Scheduler@node2.supernodexp.hpc, sock=20
02/13/2018 17:58:46;0100;Server@node2;Req;;Type 11 request received from Scheduler@node2.supernodexp.hpc, sock=20
02/13/2018 17:58:46;0008;Server@node2;Job;885.node2.supernodexp.hpc;Job Modified at request of Scheduler@node2.supernodexp.hpc
02/13/2018 17:58:46;0010;Server@node2;Job;880.node2.supernodexp.hpc;Exit_status=0 resources_used.cpupercent=100 resources_used.cput=00:00:04 resources_used.mem=537280kb resources_used.ncpus=32 resources_used.vmem=867312kb resources_used.walltime=00:00:05
02/13/2018 17:58:46;0100;Server@node2;Job;880.node2.supernodexp.hpc;dequeuing from workq, state 5
02/13/2018 17:58:46;0040;Server@node2;Svr;node2.supernodexp.hpc;Scheduler sent command 2
02/13/2018 17:58:46;0040;Server@node2;Svr;node2.supernodexp.hpc;Scheduler sent command 0
02/13/2018 17:58:46;0100;Server@node2;Req;;Type 21 request received from Scheduler@node2.supernodexp.hpc, sock=20
02/13/2018 17:58:46;0100;Server@node2;Req;;Type 81 request received from Scheduler@node2.supernodexp.hpc, sock=20
02/13/2018 17:58:46;0100;Server@node2;Req;;Type 71 request received from Scheduler@node2.supernodexp.hpc, sock=20
02/13/2018 17:58:46;0100;Server@node2;Req;;Type 58 request received from Scheduler@node2.supernodexp.hpc, sock=20
02/13/2018 17:58:46;0100;Server@node2;Req;;Type 20 request received from Scheduler@node2.supernodexp.hpc, sock=20
02/13/2018 17:58:46;0100;Server@node2;Req;;Type 51 request received from Scheduler@node2.supernodexp.hpc, sock=20
02/13/2018 17:58:46;0100;Server@node2;Req;;Type 23 request received from Scheduler@node2.supernodexp.hpc, sock=20
02/13/2018 17:58:46;0008;Server@node2;Job;885.node2.supernodexp.hpc;Job Run at request of Scheduler@node2.supernodexp.hpc on exec_vnode (node13:ncpus=32:mem=2097152kb)
02/13/2018 17:58:46;0001;Server@node2;Svr;Server@node2;Success (0) in req_runjob2, return value of svr_startjob is 0
02/13/2018 17:58:46;0100;Server@node2;Req;;Type 23 request received from Scheduler@node2.supernodexp.hpc, sock=20
02/13/2018 17:58:46;0008;Server@node2;Job;891.node2.supernodexp.hpc;Job Run at request of Scheduler@node2.supernodexp.hpc on exec_vnode (node13:ncpus=8:mem=3145728kb)
02/13/2018 17:58:46;0001;Server@node2;Svr;Server@node2;Success (0) in req_runjob2, return value of svr_startjob is 0
02/13/2018 17:58:46;0100;Server@node2;Req;;Type 11 request received from Scheduler@node2.supernodexp.hpc, sock=20
02/13/2018 17:58:46;0008;Server@node2;Job;892.node2.supernodexp.hpc;Job Modified at request of Scheduler@node2.supernodexp.hpc
02/13/2018 17:58:48;0080;Server@node2;Job;891.node2.supernodexp.hpc;Obit received momhop:1 serverhop:1 state:4 substate:42
02/13/2018 17:58:49;0010;Server@node2;Job;891.node2.supernodexp.hpc;Exit_status=0 resources_used.cpupercent=800 resources_used.cput=00:00:09 resources_used.mem=0kb resources_used.ncpus=8 resources_used.vmem=0kb resources_used.walltime=00:00:01
02/13/2018 17:58:49;0100;Server@node2;Job;891.node2.supernodexp.hpc;dequeuing from workq, state 5
02/13/2018 17:58:49;0040;Server@node2;Svr;node2.supernodexp.hpc;Scheduler sent command 2
02/13/2018 17:58:49;0040;Server@node2;Svr;node2.supernodexp.hpc;Scheduler sent command 0
02/13/2018 17:58:49;0100;Server@node2;Req;;Type 21 request received from Scheduler@node2.supernodexp.hpc, sock=20
02/13/2018 17:58:49;0100;Server@node2;Req;;Type 81 request received from Scheduler@node2.supernodexp.hpc, sock=20
02/13/2018 17:58:49;0100;Server@node2;Req;;Type 71 request received from Scheduler@node2.supernodexp.hpc, sock=20
02/13/2018 17:58:49;0100;Server@node2;Req;;Type 58 request received from Scheduler@node2.supernodexp.hpc, sock=20
02/13/2018 17:58:49;0100;Server@node2;Req;;Type 20 request received from Scheduler@node2.supernodexp.hpc, sock=20
02/13/2018 17:58:49;0100;Server@node2;Req;;Type 51 request received from Scheduler@node2.supernodexp.hpc, sock=20
02/13/2018 17:58:49;0100;Server@node2;Req;;Type 23 request received from Scheduler@node2.supernodexp.hpc, sock=20
02/13/2018 17:58:49;0008;Server@node2;Job;892.node2.supernodexp.hpc;Job Run at request of Scheduler@node2.supernodexp.hpc on exec_vnode (node13:ncpus=12:mem=1048576kb)
02/13/2018 17:58:49;0001;Server@node2;Svr;Server@node2;Success (0) in req_runjob2, return value of svr_startjob is 0
02/13/2018 17:58:49;0100;Server@node2;Req;;Type 11 request received from Scheduler@node2.supernodexp.hpc, sock=20
02/13/2018 17:58:49;0008;Server@node2;Job;895.node2.supernodexp.hpc;Job Modified at request of Scheduler@node2.supernodexp.hpc
02/13/2018 17:58:50;0080;Server@node2;Job;885.node2.supernodexp.hpc;Obit received momhop:1 serverhop:1 state:4 substate:42
02/13/2018 17:58:51;0010;Server@node2;Job;885.node2.supernodexp.hpc;Exit_status=0 resources_used.cpupercent=100 resources_used.cput=00:00:04 resources_used.mem=536784kb resources_used.ncpus=32 resources_used.vmem=867312kb resources_used.walltime=00:00:04
02/13/2018 17:58:51;0100;Server@node2;Job;885.node2.supernodexp.hpc;dequeuing from workq, state 5
02/13/2018 17:58:51;0040;Server@node2;Svr;node2.supernodexp.hpc;Scheduler sent command 2
02/13/2018 17:58:51;0040;Server@node2;Svr;node2.supernodexp.hpc;Scheduler sent command 0
02/13/2018 17:58:51;0100;Server@node2;Req;;Type 21 request received from Scheduler@node2.supernodexp.hpc, sock=20
02/13/2018 17:58:51;0100;Server@node2;Req;;Type 81 request received from Scheduler@node2.supernodexp.hpc, sock=20
02/13/2018 17:58:51;0100;Server@node2;Req;;Type 71 request received from Scheduler@node2.supernodexp.hpc, sock=20
02/13/2018 17:58:51;0100;Server@node2;Req;;Type 58 request received from Scheduler@node2.supernodexp.hpc, sock=20
02/13/2018 17:58:52;0100;Server@node2;Req;;Type 20 request received from Scheduler@node2.supernodexp.hpc, sock=20
02/13/2018 17:58:52;0100;Server@node2;Req;;Type 51 request received from Scheduler@node2.supernodexp.hpc, sock=20
02/13/2018 17:58:52;0100;Server@node2;Req;;Type 23 request received from Scheduler@node2.supernodexp.hpc, sock=20
02/13/2018 17:58:52;0008;Server@node2;Job;895.node2.supernodexp.hpc;Job Run at request of Scheduler@node2.supernodexp.hpc on exec_vnode (node13:ncpus=12:mem=1048576kb)
02/13/2018 17:58:52;0001;Server@node2;Svr;Server@node2;Success (0) in req_runjob2, return value of svr_startjob is 0
02/13/2018 17:58:52;0100;Server@node2;Req;;Type 11 request received from Scheduler@node2.supernodexp.hpc, sock=20
02/13/2018 17:58:52;0008;Server@node2;Job;900.node2.supernodexp.hpc;Job Modified at request of Scheduler@node2.supernodexp.hpc
02/13/2018 17:58:55;0080;Server@node2;Job;892.node2.supernodexp.hpc;Obit received momhop:1 serverhop:1 state:4 substate:42
02/13/2018 17:58:56;0010;Server@node2;Job;892.node2.supernodexp.hpc;Exit_status=0 resources_used.cpupercent=708 resources_used.cput=00:01:11 resources_used.mem=28852kb resources_used.ncpus=12 resources_used.vmem=1125532kb resources_used.walltime=00:00:07
02/13/2018 17:58:56;0100;Server@node2;Job;892.node2.supernodexp.hpc;dequeuing from workq, state 5
02/13/2018 17:58:56;0040;Server@node2;Svr;node2.supernodexp.hpc;Scheduler sent command 2
02/13/2018 17:58:56;0040;Server@node2;Svr;node2.supernodexp.hpc;Scheduler sent command 0
02/13/2018 17:58:56;0100;Server@node2;Req;;Type 21 request received from Scheduler@node2.supernodexp.hpc, sock=20
02/13/2018 17:58:56;0100;Server@node2;Req;;Type 81 request received from Scheduler@node2.supernodexp.hpc, sock=20
02/13/2018 17:58:56;0100;Server@node2;Req;;Type 71 request received from Scheduler@node2.supernodexp.hpc, sock=20
02/13/2018 17:58:56;0100;Server@node2;Req;;Type 58 request received from Scheduler@node2.supernodexp.hpc, sock=20
02/13/2018 17:58:56;0100;Server@node2;Req;;Type 20 request received from Scheduler@node2.supernodexp.hpc, sock=20
02/13/2018 17:58:56;0100;Server@node2;Req;;Type 51 request received from Scheduler@node2.supernodexp.hpc, sock=20
02/13/2018 17:58:56;0100;Server@node2;Req;;Type 23 request received from Scheduler@node2.supernodexp.hpc, sock=20
02/13/2018 17:58:56;0008;Server@node2;Job;900.node2.supernodexp.hpc;Job Run at request of Scheduler@node2.supernodexp.hpc on exec_vnode (node13:ncpus=32:mem=2097152kb)
02/13/2018 17:58:56;0001;Server@node2;Svr;Server@node2;Success (0) in req_runjob2, return value of svr_startjob is 0
02/13/2018 17:58:56;0100;Server@node2;Req;;Type 11 request received from Scheduler@node2.supernodexp.hpc, sock=20
02/13/2018 17:58:56;0008;Server@node2;Job;902.node2.supernodexp.hpc;Job Modified at request of Scheduler@node2.supernodexp.hpc
02/13/2018 17:58:58;0080;Server@node2;Job;895.node2.supernodexp.hpc;Obit received momhop:1 serverhop:1 state:4 substate:42
02/13/2018 17:58:59;0010;Server@node2;Job;895.node2.supernodexp.hpc;Exit_status=0 resources_used.cpupercent=1202 resources_used.cput=00:01:12 resources_used.mem=28240kb resources_used.ncpus=12 resources_used.vmem=1125532kb resources_used.walltime=00:00:06
02/13/2018 17:58:59;0100;Server@node2;Job;895.node2.supernodexp.hpc;dequeuing from workq, state 5
02/13/2018 17:58:59;0040;Server@node2;Svr;node2.supernodexp.hpc;Scheduler sent command 2
02/13/2018 17:58:59;0040;Server@node2;Svr;node2.supernodexp.hpc;Scheduler sent command 0
02/13/2018 17:58:59;0100;Server@node2;Req;;Type 21 request received from Scheduler@node2.supernodexp.hpc, sock=20
02/13/2018 17:58:59;0100;Server@node2;Req;;Type 81 request received from Scheduler@node2.supernodexp.hpc, sock=20
02/13/2018 17:58:59;0100;Server@node2;Req;;Type 71 request received from Scheduler@node2.supernodexp.hpc, sock=20
02/13/2018 17:58:59;0100;Server@node2;Req;;Type 58 request received from Scheduler@node2.supernodexp.hpc, sock=20
02/13/2018 17:58:59;0100;Server@node2;Req;;Type 20 request received from Scheduler@node2.supernodexp.hpc, sock=20
02/13/2018 17:58:59;0100;Server@node2;Req;;Type 51 request received from Scheduler@node2.supernodexp.hpc, sock=20
02/13/2018 17:58:59;0100;Server@node2;Req;;Type 23 request received from Scheduler@node2.supernodexp.hpc, sock=20
02/13/2018 17:58:59;0008;Server@node2;Job;902.node2.supernodexp.hpc;Job Run at request of Scheduler@node2.supernodexp.hpc on exec_vnode (node13:ncpus=12:mem=1048576kb)
02/13/2018 17:58:59;0001;Server@node2;Svr;Server@node2;Success (0) in req_runjob2, return value of svr_startjob is 0
02/13/2018 17:58:59;0100;Server@node2;Req;;Type 11 request received from Scheduler@node2.supernodexp.hpc, sock=20
02/13/2018 17:58:59;0008;Server@node2;Job;906.node2.supernodexp.hpc;Job Modified at request of Scheduler@node2.supernodexp.hpc
02/13/2018 17:59:00;0080;Server@node2;Job;900.node2.supernodexp.hpc;Obit received momhop:1 serverhop:1 state:4 substate:42
02/13/2018 17:59:01;0010;Server@node2;Job;900.node2.supernodexp.hpc;Exit_status=0 resources_used.cpupercent=100 resources_used.cput=00:00:04 resources_used.mem=535712kb resources_used.ncpus=32 resources_used.vmem=867312kb resources_used.walltime=00:00:04
02/13/2018 17:59:01;0100;Server@node2;Job;900.node2.supernodexp.hpc;dequeuing from workq, state 5
02/13/2018 17:59:01;0040;Server@node2;Svr;node2.supernodexp.hpc;Scheduler sent command 2
02/13/2018 17:59:01;0040;Server@node2;Svr;node2.supernodexp.hpc;Scheduler sent command 0
02/13/2018 17:59:01;0100;Server@node2;Req;;Type 21 request received from Scheduler@node2.supernodexp.hpc, sock=20
02/13/2018 17:59:01;0100;Server@node2;Req;;Type 81 request received from Scheduler@node2.supernodexp.hpc, sock=20
02/13/2018 17:59:01;0100;Server@node2;Req;;Type 71 request received from Scheduler@node2.supernodexp.hpc, sock=20
02/13/2018 17:59:01;0100;Server@node2;Req;;Type 58 request received from Scheduler@node2.supernodexp.hpc, sock=20
02/13/2018 17:59:02;0100;Server@node2;Req;;Type 20 request received from Scheduler@node2.supernodexp.hpc, sock=20
02/13/2018 17:59:02;0100;Server@node2;Req;;Type 51 request received from Scheduler@node2.supernodexp.hpc, sock=20
02/13/2018 17:59:02;0100;Server@node2;Req;;Type 23 request received from Scheduler@node2.supernodexp.hpc, sock=20
02/13/2018 17:59:02;0008;Server@node2;Job;906.node2.supernodexp.hpc;Job Run at request of Scheduler@node2.supernodexp.hpc on exec_vnode (node13:ncpus=8:mem=3145728kb)
02/13/2018 17:59:02;0001;Server@node2;Svr;Server@node2;Success (0) in req_runjob2, return value of svr_startjob is 0
02/13/2018 17:59:02;0100;Server@node2;Req;;Type 23 request received from Scheduler@node2.supernodexp.hpc, sock=20
02/13/2018 17:59:02;0008;Server@node2;Job;910.node2.supernodexp.hpc;Job Run at request of Scheduler@node2.supernodexp.hpc on exec_vnode (node13:ncpus=12:mem=1048576kb)
02/13/2018 17:59:02;0001;Server@node2;Svr;Server@node2;Success (0) in req_runjob2, return value of svr_startjob is 0
02/13/2018 17:59:02;0100;Server@node2;Req;;Type 11 request received from Scheduler@node2.supernodexp.hpc, sock=20
02/13/2018 17:59:02;0008;Server@node2;Job;913.node2.supernodexp.hpc;Job Modified at request of Scheduler@node2.supernodexp.hpc
02/13/2018 17:59:03;0080;Server@node2;Job;906.node2.supernodexp.hpc;Obit received momhop:1 serverhop:1 state:4 substate:42
02/13/2018 17:59:04;0010;Server@node2;Job;906.node2.supernodexp.hpc;Exit_status=0 resources_used.cpupercent=450 resources_used.cput=00:00:09 resources_used.mem=0kb resources_used.ncpus=8 resources_used.vmem=0kb resources_used.walltime=00:00:02
02/13/2018 17:59:04;0100;Server@node2;Job;906.node2.supernodexp.hpc;dequeuing from workq, state 5
02/13/2018 17:59:04;0040;Server@node2;Svr;node2.supernodexp.hpc;Scheduler sent command 2
02/13/2018 17:59:04;0040;Server@node2;Svr;node2.supernodexp.hpc;Scheduler sent command 0
02/13/2018 17:59:04;0100;Server@node2;Req;;Type 21 request received from Scheduler@node2.supernodexp.hpc, sock=20
02/13/2018 17:59:04;0100;Server@node2;Req;;Type 81 request received from Scheduler@node2.supernodexp.hpc, sock=20
02/13/2018 17:59:04;0100;Server@node2;Req;;Type 71 request received from Scheduler@node2.supernodexp.hpc, sock=20
02/13/2018 17:59:04;0100;Server@node2;Req;;Type 58 request received from Scheduler@node2.supernodexp.hpc, sock=20
02/13/2018 17:59:04;0100;Server@node2;Req;;Type 20 request received from Scheduler@node2.supernodexp.hpc, sock=20
02/13/2018 17:59:04;0100;Server@node2;Req;;Type 51 request received from Scheduler@node2.supernodexp.hpc, sock=20
02/13/2018 17:59:04;0100;Server@node2;Req;;Type 11 request received from Scheduler@node2.supernodexp.hpc, sock=20
02/13/2018 17:59:04;0008;Server@node2;Job;913.node2.supernodexp.hpc;Job Modified at request of Scheduler@node2.supernodexp.hpc
02/13/2018 17:59:05;0080;Server@node2;Job;902.node2.supernodexp.hpc;Obit received momhop:1 serverhop:1 state:4 substate:42
02/13/2018 17:59:06;0100;Server@node2;Req;;Type 0 request received from root@node2.supernodexp.hpc, sock=20
02/13/2018 17:59:06;0100;Server@node2;Req;;Type 49 request received from root@node2.supernodexp.hpc, sock=21
02/13/2018 17:59:06;0100;Server@node2;Req;;Type 21 request received from root@node2.supernodexp.hpc, sock=20
02/13/2018 17:59:06;0100;Server@node2;Req;;Type 19 request received from root@node2.supernodexp.hpc, sock=20
02/13/2018 17:59:06;0010;Server@node2;Job;902.node2.supernodexp.hpc;Exit_status=0 resources_used.cpupercent=1200 resources_used.cput=00:01:12 resources_used.mem=42968kb resources_used.ncpus=12 resources_used.vmem=1125532kb resources_used.walltime=00:00:07
02/13/2018 17:59:06;0100;Server@node2;Job;902.node2.supernodexp.hpc;dequeuing from workq, state 5
02/13/2018 17:59:06;0040;Server@node2;Svr;node2.supernodexp.hpc;Scheduler sent command 2
02/13/2018 17:59:06;0040;Server@node2;Svr;node2.supernodexp.hpc;Scheduler sent command 0
02/13/2018 17:59:06;0100;Server@node2;Req;;Type 21 request received from Scheduler@node2.supernodexp.hpc, sock=20
02/13/2018 17:59:06;0100;Server@node2;Req;;Type 81 request received from Scheduler@node2.supernodexp.hpc, sock=20
02/13/2018 17:59:06;0100;Server@node2;Req;;Type 71 request received from Scheduler@node2.supernodexp.hpc, sock=20
02/13/2018 17:59:06;0100;Server@node2;Req;;Type 58 request received from Scheduler@node2.supernodexp.hpc, sock=20
02/13/2018 17:59:06;0100;Server@node2;Req;;Type 20 request received from Scheduler@node2.supernodexp.hpc, sock=20
02/13/2018 17:59:06;0100;Server@node2;Req;;Type 51 request received from Scheduler@node2.supernodexp.hpc, sock=20
02/13/2018 17:59:06;0100;Server@node2;Req;;Type 23 request received from Scheduler@node2.supernodexp.hpc, sock=20
02/13/2018 17:59:06;0008;Server@node2;Job;913.node2.supernodexp.hpc;Job Run at request of Scheduler@node2.supernodexp.hpc on exec_vnode (node13:ncpus=32:mem=2097152kb)
02/13/2018 17:59:06;0001;Server@node2;Svr;Server@node2;Success (0) in req_runjob2, return value of svr_startjob is 0
02/13/2018 17:59:06;0100;Server@node2;Req;;Type 11 request received from Scheduler@node2.supernodexp.hpc, sock=20
02/13/2018 17:59:06;0008;Server@node2;Job;914.node2.supernodexp.hpc;Job Modified at request of Scheduler@node2.supernodexp.hpc
02/13/2018 17:59:08;0080;Server@node2;Job;910.node2.supernodexp.hpc;Obit received momhop:1 serverhop:1 state:4 substate:42
02/13/2018 17:59:09;0010;Server@node2;Job;910.node2.supernodexp.hpc;Exit_status=0 resources_used.cpupercent=609 resources_used.cput=00:01:16 resources_used.mem=29880kb resources_used.ncpus=12 resources_used.vmem=1125532kb resources_used.walltime=00:00:07
02/13/2018 17:59:09;0100;Server@node2;Job;910.node2.supernodexp.hpc;dequeuing from workq, state 5
02/13/2018 17:59:09;0040;Server@node2;Svr;node2.supernodexp.hpc;Scheduler sent command 2
02/13/2018 17:59:09;0040;Server@node2;Svr;node2.supernodexp.hpc;Scheduler sent command 0
02/13/2018 17:59:09;0100;Server@node2;Req;;Type 21 request received from Scheduler@node2.supernodexp.hpc, sock=20
02/13/2018 17:59:09;0100;Server@node2;Req;;Type 81 request received from Scheduler@node2.supernodexp.hpc, sock=20
02/13/2018 17:59:09;0100;Server@node2;Req;;Type 71 request received from Scheduler@node2.supernodexp.hpc, sock=20
02/13/2018 17:59:09;0100;Server@node2;Req;;Type 58 request received from Scheduler@node2.supernodexp.hpc, sock=20
02/13/2018 17:59:09;0100;Server@node2;Req;;Type 20 request received from Scheduler@node2.supernodexp.hpc, sock=20
02/13/2018 17:59:09;0100;Server@node2;Req;;Type 51 request received from Scheduler@node2.supernodexp.hpc, sock=20
02/13/2018 17:59:09;0100;Server@node2;Req;;Type 11 request received from Scheduler@node2.supernodexp.hpc, sock=20
02/13/2018 17:59:09;0008;Server@node2;Job;914.node2.supernodexp.hpc;Job Modified at request of Scheduler@node2.supernodexp.hpc
02/13/2018 17:59:10;0080;Server@node2;Job;913.node2.supernodexp.hpc;Obit received momhop:1 serverhop:1 state:4 substate:42
02/13/2018 17:59:11;0010;Server@node2;Job;913.node2.supernodexp.hpc;Exit_status=0 resources_used.cpupercent=50 resources_used.cput=00:00:04 resources_used.mem=536560kb resources_used.ncpus=32 resources_used.vmem=867312kb resources_used.walltime=00:00:04
02/13/2018 17:59:11;0100;Server@node2;Job;913.node2.supernodexp.hpc;dequeuing from workq, state 5
02/13/2018 17:59:11;0040;Server@node2;Svr;node2.supernodexp.hpc;Scheduler sent command 2
02/13/2018 17:59:11;0040;Server@node2;Svr;node2.supernodexp.hpc;Scheduler sent command 0
02/13/2018 17:59:11;0100;Server@node2;Req;;Type 21 request received from Scheduler@node2.supernodexp.hpc, sock=20
02/13/2018 17:59:11;0100;Server@node2;Req;;Type 81 request received from Scheduler@node2.supernodexp.hpc, sock=20
02/13/2018 17:59:11;0100;Server@node2;Req;;Type 71 request received from Scheduler@node2.supernodexp.hpc, sock=20
02/13/2018 17:59:11;0100;Server@node2;Req;;Type 58 request received from Scheduler@node2.supernodexp.hpc, sock=20
02/13/2018 17:59:12;0100;Server@node2;Req;;Type 20 request received from Scheduler@node2.supernodexp.hpc, sock=20
02/13/2018 17:59:12;0100;Server@node2;Req;;Type 51 request received from Scheduler@node2.supernodexp.hpc, sock=20
02/13/2018 17:59:12;0100;Server@node2;Req;;Type 23 request received from Scheduler@node2.supernodexp.hpc, sock=20
02/13/2018 17:59:12;0008;Server@node2;Job;914.node2.supernodexp.hpc;Job Run at request of Scheduler@node2.supernodexp.hpc on exec_vnode (node13:ncpus=32:mem=2097152kb)
02/13/2018 17:59:12;0001;Server@node2;Svr;Server@node2;Success (0) in req_runjob2, return value of svr_startjob is 0
02/13/2018 17:59:12;0100;Server@node2;Req;;Type 23 request received from Scheduler@node2.supernodexp.hpc, sock=20
02/13/2018 17:59:12;0008;Server@node2;Job;918.node2.supernodexp.hpc;Job Run at request of Scheduler@node2.supernodexp.hpc on exec_vnode (node13:ncpus=8:mem=3145728kb)
02/13/2018 17:59:12;0001;Server@node2;Svr;Server@node2;Success (0) in req_runjob2, return value of svr_startjob is 0
02/13/2018 17:59:12;0100;Server@node2;Req;;Type 11 request received from Scheduler@node2.supernodexp.hpc, sock=20
02/13/2018 17:59:12;0008;Server@node2;Job;919.node2.supernodexp.hpc;Job Modified at request of Scheduler@node2.supernodexp.hpc
02/13/2018 17:59:12;0100;Server@node2;Req;;Type 1 request received from ctminh@node2.supernodexp.hpc, sock=16
02/13/2018 17:59:12;0100;Server@node2;Req;;Type 3 request received from ctminh@node2.supernodexp.hpc, sock=16
02/13/2018 17:59:12;0100;Server@node2;Req;;Type 5 request received from ctminh@node2.supernodexp.hpc, sock=16
02/13/2018 17:59:12;0100;Server@node2;Job;921.node2.supernodexp.hpc;enqueuing into workq, state 1 hop 1
02/13/2018 17:59:12;0008;Server@node2;Job;921.node2.supernodexp.hpc;Job Queued at request of ctminh@node2.supernodexp.hpc, owner = ctminh@node2.supernodexp.hpc, job name = telemac3, queue = workq
02/13/2018 17:59:12;0040;Server@node2;Svr;node2.supernodexp.hpc;Scheduler sent command 1
02/13/2018 17:59:12;0040;Server@node2;Svr;node2.supernodexp.hpc;Scheduler sent command 0
02/13/2018 17:59:12;0100;Server@node2;Req;;Type 21 request received from Scheduler@node2.supernodexp.hpc, sock=20
02/13/2018 17:59:12;0100;Server@node2;Req;;Type 81 request received from Scheduler@node2.supernodexp.hpc, sock=20
02/13/2018 17:59:12;0100;Server@node2;Req;;Type 71 request received from Scheduler@node2.supernodexp.hpc, sock=20
02/13/2018 17:59:12;0100;Server@node2;Req;;Type 58 request received from Scheduler@node2.supernodexp.hpc, sock=20
02/13/2018 17:59:12;0100;Server@node2;Req;;Type 1 request received from ctminh@node2.supernodexp.hpc, sock=16
02/13/2018 17:59:12;0100;Server@node2;Req;;Type 3 request received from ctminh@node2.supernodexp.hpc, sock=16
02/13/2018 17:59:12;0100;Server@node2;Req;;Type 5 request received from ctminh@node2.supernodexp.hpc, sock=16
02/13/2018 17:59:12;0100;Server@node2;Job;922.node2.supernodexp.hpc;enqueuing into workq, state 1 hop 1
02/13/2018 17:59:12;0008;Server@node2;Job;922.node2.supernodexp.hpc;Job Queued at request of ctminh@node2.supernodexp.hpc, owner = ctminh@node2.supernodexp.hpc, job name = nbody, queue = workq
02/13/2018 17:59:12;0100;Server@node2;Req;;Type 1 request received from ctminh@node2.supernodexp.hpc, sock=16
02/13/2018 17:59:12;0100;Server@node2;Req;;Type 20 request received from Scheduler@node2.supernodexp.hpc, sock=20
02/13/2018 17:59:12;0100;Server@node2;Req;;Type 3 request received from ctminh@node2.supernodexp.hpc, sock=16
02/13/2018 17:59:12;0100;Server@node2;Req;;Type 51 request received from Scheduler@node2.supernodexp.hpc, sock=20
02/13/2018 17:59:12;0100;Server@node2;Req;;Type 5 request received from ctminh@node2.supernodexp.hpc, sock=16
02/13/2018 17:59:12;0100;Server@node2;Job;923.node2.supernodexp.hpc;enqueuing into workq, state 1 hop 1
02/13/2018 17:59:12;0008;Server@node2;Job;923.node2.supernodexp.hpc;Job Queued at request of ctminh@node2.supernodexp.hpc, owner = ctminh@node2.supernodexp.hpc, job name = telemac3, queue = workq
02/13/2018 17:59:12;0100;Server@node2;Req;;Type 1 request received from ctminh@node2.supernodexp.hpc, sock=16
02/13/2018 17:59:12;0100;Server@node2;Req;;Type 3 request received from ctminh@node2.supernodexp.hpc, sock=16
02/13/2018 17:59:12;0100;Server@node2;Req;;Type 5 request received from ctminh@node2.supernodexp.hpc, sock=16
02/13/2018 17:59:12;0100;Server@node2;Job;924.node2.supernodexp.hpc;enqueuing into workq, state 1 hop 1
02/13/2018 17:59:12;0008;Server@node2;Job;924.node2.supernodexp.hpc;Job Queued at request of ctminh@node2.supernodexp.hpc, owner = ctminh@node2.supernodexp.hpc, job name = telemac1, queue = workq
02/13/2018 17:59:12;0100;Server@node2;Req;;Type 1 request received from ctminh@node2.supernodexp.hpc, sock=16
02/13/2018 17:59:12;0100;Server@node2;Req;;Type 3 request received from ctminh@node2.supernodexp.hpc, sock=16
02/13/2018 17:59:12;0100;Server@node2;Req;;Type 5 request received from ctminh@node2.supernodexp.hpc, sock=16
02/13/2018 17:59:12;0100;Server@node2;Job;925.node2.supernodexp.hpc;enqueuing into workq, state 1 hop 1
02/13/2018 17:59:12;0008;Server@node2;Job;925.node2.supernodexp.hpc;Job Queued at request of ctminh@node2.supernodexp.hpc, owner = ctminh@node2.supernodexp.hpc, job name = thread-affinity, queue = workq
02/13/2018 17:59:12;0100;Server@node2;Req;;Type 11 request received from Scheduler@node2.supernodexp.hpc, sock=20
02/13/2018 17:59:12;0008;Server@node2;Job;922.node2.supernodexp.hpc;Job Modified at request of Scheduler@node2.supernodexp.hpc
02/13/2018 17:59:12;0100;Server@node2;Req;;Type 11 request received from Scheduler@node2.supernodexp.hpc, sock=20
02/13/2018 17:59:12;0008;Server@node2;Job;921.node2.supernodexp.hpc;Job Modified at request of Scheduler@node2.supernodexp.hpc
02/13/2018 17:59:12;0040;Server@node2;Svr;node2.supernodexp.hpc;Scheduler sent command 1
02/13/2018 17:59:12;0040;Server@node2;Svr;node2.supernodexp.hpc;Scheduler sent command 0
02/13/2018 17:59:12;0100;Server@node2;Req;;Type 21 request received from Scheduler@node2.supernodexp.hpc, sock=20
02/13/2018 17:59:12;0100;Server@node2;Req;;Type 81 request received from Scheduler@node2.supernodexp.hpc, sock=20
02/13/2018 17:59:12;0100;Server@node2;Req;;Type 71 request received from Scheduler@node2.supernodexp.hpc, sock=20
02/13/2018 17:59:12;0100;Server@node2;Req;;Type 58 request received from Scheduler@node2.supernodexp.hpc, sock=20
02/13/2018 17:59:12;0100;Server@node2;Req;;Type 1 request received from ctminh@node2.supernodexp.hpc, sock=16
02/13/2018 17:59:12;0100;Server@node2;Req;;Type 3 request received from ctminh@node2.supernodexp.hpc, sock=16
02/13/2018 17:59:12;0100;Server@node2;Req;;Type 5 request received from ctminh@node2.supernodexp.hpc, sock=16
02/13/2018 17:59:12;0100;Server@node2;Job;926.node2.supernodexp.hpc;enqueuing into workq, state 1 hop 1
02/13/2018 17:59:12;0008;Server@node2;Job;926.node2.supernodexp.hpc;Job Queued at request of ctminh@node2.supernodexp.hpc, owner = ctminh@node2.supernodexp.hpc, job name = matrix-x-vector, queue = workq
02/13/2018 17:59:12;0100;Server@node2;Req;;Type 1 request received from ctminh@node2.supernodexp.hpc, sock=16
02/13/2018 17:59:12;0100;Server@node2;Req;;Type 3 request received from ctminh@node2.supernodexp.hpc, sock=16
02/13/2018 17:59:12;0100;Server@node2;Req;;Type 5 request received from ctminh@node2.supernodexp.hpc, sock=16
02/13/2018 17:59:12;0100;Server@node2;Job;927.node2.supernodexp.hpc;enqueuing into workq, state 1 hop 1
02/13/2018 17:59:12;0008;Server@node2;Job;927.node2.supernodexp.hpc;Job Queued at request of ctminh@node2.supernodexp.hpc, owner = ctminh@node2.supernodexp.hpc, job name = telemac2, queue = workq
02/13/2018 17:59:12;0100;Server@node2;Req;;Type 20 request received from Scheduler@node2.supernodexp.hpc, sock=20
02/13/2018 17:59:12;0100;Server@node2;Req;;Type 51 request received from Scheduler@node2.supernodexp.hpc, sock=20
02/13/2018 17:59:12;0100;Server@node2;Req;;Type 1 request received from ctminh@node2.supernodexp.hpc, sock=16
02/13/2018 17:59:12;0100;Server@node2;Req;;Type 3 request received from ctminh@node2.supernodexp.hpc, sock=16
02/13/2018 17:59:12;0100;Server@node2;Req;;Type 5 request received from ctminh@node2.supernodexp.hpc, sock=16
02/13/2018 17:59:12;0100;Server@node2;Job;928.node2.supernodexp.hpc;enqueuing into workq, state 1 hop 1
02/13/2018 17:59:12;0008;Server@node2;Job;928.node2.supernodexp.hpc;Job Queued at request of ctminh@node2.supernodexp.hpc, owner = ctminh@node2.supernodexp.hpc, job name = vectorization, queue = workq
02/13/2018 17:59:12;0100;Server@node2;Req;;Type 1 request received from ctminh@node2.supernodexp.hpc, sock=16
02/13/2018 17:59:12;0100;Server@node2;Req;;Type 3 request received from ctminh@node2.supernodexp.hpc, sock=16
02/13/2018 17:59:12;0100;Server@node2;Req;;Type 5 request received from ctminh@node2.supernodexp.hpc, sock=16
02/13/2018 17:59:12;0100;Server@node2;Job;929.node2.supernodexp.hpc;enqueuing into workq, state 1 hop 1
02/13/2018 17:59:12;0008;Server@node2;Job;929.node2.supernodexp.hpc;Job Queued at request of ctminh@node2.supernodexp.hpc, owner = ctminh@node2.supernodexp.hpc, job name = telemac2, queue = workq
02/13/2018 17:59:12;0100;Server@node2;Req;;Type 1 request received from ctminh@node2.supernodexp.hpc, sock=16
02/13/2018 17:59:12;0100;Server@node2;Req;;Type 11 request received from Scheduler@node2.supernodexp.hpc, sock=20
02/13/2018 17:59:12;0008;Server@node2;Job;919.node2.supernodexp.hpc;Job Modified at request of Scheduler@node2.supernodexp.hpc
02/13/2018 17:59:12;0100;Server@node2;Req;;Type 3 request received from ctminh@node2.supernodexp.hpc, sock=16
02/13/2018 17:59:12;0100;Server@node2;Req;;Type 5 request received from ctminh@node2.supernodexp.hpc, sock=16
02/13/2018 17:59:12;0100;Server@node2;Job;930.node2.supernodexp.hpc;enqueuing into workq, state 1 hop 1
02/13/2018 17:59:12;0008;Server@node2;Job;930.node2.supernodexp.hpc;Job Queued at request of ctminh@node2.supernodexp.hpc, owner = ctminh@node2.supernodexp.hpc, job name = vast1, queue = workq
02/13/2018 17:59:12;0100;Server@node2;Req;;Type 11 request received from Scheduler@node2.supernodexp.hpc, sock=20
02/13/2018 17:59:12;0008;Server@node2;Job;925.node2.supernodexp.hpc;Job Modified at request of Scheduler@node2.supernodexp.hpc
02/13/2018 17:59:12;0100;Server@node2;Req;;Type 11 request received from Scheduler@node2.supernodexp.hpc, sock=20
02/13/2018 17:59:12;0008;Server@node2;Job;923.node2.supernodexp.hpc;Job Modified at request of Scheduler@node2.supernodexp.hpc
02/13/2018 17:59:12;0100;Server@node2;Req;;Type 11 request received from Scheduler@node2.supernodexp.hpc, sock=20
02/13/2018 17:59:12;0008;Server@node2;Job;924.node2.supernodexp.hpc;Job Modified at request of Scheduler@node2.supernodexp.hpc
02/13/2018 17:59:12;0100;Server@node2;Req;;Type 11 request received from Scheduler@node2.supernodexp.hpc, sock=20
02/13/2018 17:59:12;0008;Server@node2;Job;927.node2.supernodexp.hpc;Job Modified at request of Scheduler@node2.supernodexp.hpc
02/13/2018 17:59:12;0100;Server@node2;Req;;Type 11 request received from Scheduler@node2.supernodexp.hpc, sock=20
02/13/2018 17:59:12;0008;Server@node2;Job;926.node2.supernodexp.hpc;Job Modified at request of Scheduler@node2.supernodexp.hpc
02/13/2018 17:59:12;0040;Server@node2;Svr;node2.supernodexp.hpc;Scheduler sent command 1
02/13/2018 17:59:12;0040;Server@node2;Svr;node2.supernodexp.hpc;Scheduler sent command 0
02/13/2018 17:59:12;0100;Server@node2;Req;;Type 21 request received from Scheduler@node2.supernodexp.hpc, sock=20
02/13/2018 17:59:12;0100;Server@node2;Req;;Type 81 request received from Scheduler@node2.supernodexp.hpc, sock=20
02/13/2018 17:59:12;0100;Server@node2;Req;;Type 71 request received from Scheduler@node2.supernodexp.hpc, sock=20
02/13/2018 17:59:12;0100;Server@node2;Req;;Type 58 request received from Scheduler@node2.supernodexp.hpc, sock=20
02/13/2018 17:59:12;0100;Server@node2;Req;;Type 1 request received from ctminh@node2.supernodexp.hpc, sock=16
02/13/2018 17:59:12;0100;Server@node2;Req;;Type 3 request received from ctminh@node2.supernodexp.hpc, sock=16
02/13/2018 17:59:12;0100;Server@node2;Req;;Type 5 request received from ctminh@node2.supernodexp.hpc, sock=16
02/13/2018 17:59:12;0100;Server@node2;Job;931.node2.supernodexp.hpc;enqueuing into workq, state 1 hop 1
02/13/2018 17:59:12;0008;Server@node2;Job;931.node2.supernodexp.hpc;Job Queued at request of ctminh@node2.supernodexp.hpc, owner = ctminh@node2.supernodexp.hpc, job name = histogram, queue = workq
02/13/2018 17:59:12;0100;Server@node2;Req;;Type 1 request received from ctminh@node2.supernodexp.hpc, sock=16
02/13/2018 17:59:12;0100;Server@node2;Req;;Type 3 request received from ctminh@node2.supernodexp.hpc, sock=16
02/13/2018 17:59:12;0100;Server@node2;Req;;Type 5 request received from ctminh@node2.supernodexp.hpc, sock=16
02/13/2018 17:59:12;0100;Server@node2;Job;932.node2.supernodexp.hpc;enqueuing into workq, state 1 hop 1
02/13/2018 17:59:12;0008;Server@node2;Job;932.node2.supernodexp.hpc;Job Queued at request of ctminh@node2.supernodexp.hpc, owner = ctminh@node2.supernodexp.hpc, job name = telemac1, queue = workq
02/13/2018 17:59:12;0100;Server@node2;Req;;Type 20 request received from Scheduler@node2.supernodexp.hpc, sock=20
02/13/2018 17:59:12;0100;Server@node2;Req;;Type 51 request received from Scheduler@node2.supernodexp.hpc, sock=20
02/13/2018 17:59:13;0100;Server@node2;Req;;Type 1 request received from ctminh@node2.supernodexp.hpc, sock=16
02/13/2018 17:59:13;0100;Server@node2;Req;;Type 3 request received from ctminh@node2.supernodexp.hpc, sock=16
02/13/2018 17:59:13;0100;Server@node2;Req;;Type 5 request received from ctminh@node2.supernodexp.hpc, sock=16
02/13/2018 17:59:13;0100;Server@node2;Job;933.node2.supernodexp.hpc;enqueuing into workq, state 1 hop 1
02/13/2018 17:59:13;0008;Server@node2;Job;933.node2.supernodexp.hpc;Job Queued at request of ctminh@node2.supernodexp.hpc, owner = ctminh@node2.supernodexp.hpc, job name = telemac3, queue = workq
02/13/2018 17:59:13;0100;Server@node2;Req;;Type 1 request received from ctminh@node2.supernodexp.hpc, sock=16
02/13/2018 17:59:13;0100;Server@node2;Req;;Type 3 request received from ctminh@node2.supernodexp.hpc, sock=16
02/13/2018 17:59:13;0100;Server@node2;Req;;Type 5 request received from ctminh@node2.supernodexp.hpc, sock=16
02/13/2018 17:59:13;0100;Server@node2;Job;934.node2.supernodexp.hpc;enqueuing into workq, state 1 hop 1
02/13/2018 17:59:13;0008;Server@node2;Job;934.node2.supernodexp.hpc;Job Queued at request of ctminh@node2.supernodexp.hpc, owner = ctminh@node2.supernodexp.hpc, job name = lu-decomp, queue = workq
02/13/2018 17:59:13;0100;Server@node2;Req;;Type 1 request received from ctminh@node2.supernodexp.hpc, sock=16
02/13/2018 17:59:13;0100;Server@node2;Req;;Type 11 request received from Scheduler@node2.supernodexp.hpc, sock=20
02/13/2018 17:59:13;0008;Server@node2;Job;928.node2.supernodexp.hpc;Job Modified at request of Scheduler@node2.supernodexp.hpc
02/13/2018 17:59:13;0100;Server@node2;Req;;Type 3 request received from ctminh@node2.supernodexp.hpc, sock=16
02/13/2018 17:59:13;0100;Server@node2;Req;;Type 11 request received from Scheduler@node2.supernodexp.hpc, sock=20
02/13/2018 17:59:13;0008;Server@node2;Job;931.node2.supernodexp.hpc;Job Modified at request of Scheduler@node2.supernodexp.hpc
02/13/2018 17:59:13;0100;Server@node2;Req;;Type 5 request received from ctminh@node2.supernodexp.hpc, sock=16
02/13/2018 17:59:13;0100;Server@node2;Job;935.node2.supernodexp.hpc;enqueuing into workq, state 1 hop 1
02/13/2018 17:59:13;0008;Server@node2;Job;935.node2.supernodexp.hpc;Job Queued at request of ctminh@node2.supernodexp.hpc, owner = ctminh@node2.supernodexp.hpc, job name = lu-decomp, queue = workq
02/13/2018 17:59:13;0100;Server@node2;Req;;Type 11 request received from Scheduler@node2.supernodexp.hpc, sock=20
02/13/2018 17:59:13;0008;Server@node2;Job;932.node2.supernodexp.hpc;Job Modified at request of Scheduler@node2.supernodexp.hpc
02/13/2018 17:59:13;0100;Server@node2;Req;;Type 11 request received from Scheduler@node2.supernodexp.hpc, sock=20
02/13/2018 17:59:13;0008;Server@node2;Job;929.node2.supernodexp.hpc;Job Modified at request of Scheduler@node2.supernodexp.hpc
02/13/2018 17:59:13;0100;Server@node2;Req;;Type 11 request received from Scheduler@node2.supernodexp.hpc, sock=20
02/13/2018 17:59:13;0008;Server@node2;Job;930.node2.supernodexp.hpc;Job Modified at request of Scheduler@node2.supernodexp.hpc
02/13/2018 17:59:13;0040;Server@node2;Svr;node2.supernodexp.hpc;Scheduler sent command 1
02/13/2018 17:59:13;0040;Server@node2;Svr;node2.supernodexp.hpc;Scheduler sent command 0
02/13/2018 17:59:13;0100;Server@node2;Req;;Type 21 request received from Scheduler@node2.supernodexp.hpc, sock=20
02/13/2018 17:59:13;0100;Server@node2;Req;;Type 81 request received from Scheduler@node2.supernodexp.hpc, sock=20
02/13/2018 17:59:13;0100;Server@node2;Req;;Type 71 request received from Scheduler@node2.supernodexp.hpc, sock=20
02/13/2018 17:59:13;0100;Server@node2;Req;;Type 58 request received from Scheduler@node2.supernodexp.hpc, sock=20
02/13/2018 17:59:13;0100;Server@node2;Req;;Type 1 request received from ctminh@node2.supernodexp.hpc, sock=16
02/13/2018 17:59:13;0100;Server@node2;Req;;Type 3 request received from ctminh@node2.supernodexp.hpc, sock=16
02/13/2018 17:59:13;0100;Server@node2;Req;;Type 5 request received from ctminh@node2.supernodexp.hpc, sock=16
02/13/2018 17:59:13;0100;Server@node2;Job;936.node2.supernodexp.hpc;enqueuing into workq, state 1 hop 1
02/13/2018 17:59:13;0008;Server@node2;Job;936.node2.supernodexp.hpc;Job Queued at request of ctminh@node2.supernodexp.hpc, owner = ctminh@node2.supernodexp.hpc, job name = nbody, queue = workq
02/13/2018 17:59:13;0100;Server@node2;Req;;Type 1 request received from ctminh@node2.supernodexp.hpc, sock=16
02/13/2018 17:59:13;0100;Server@node2;Req;;Type 3 request received from ctminh@node2.supernodexp.hpc, sock=16
02/13/2018 17:59:13;0100;Server@node2;Req;;Type 5 request received from ctminh@node2.supernodexp.hpc, sock=16
02/13/2018 17:59:13;0100;Server@node2;Job;937.node2.supernodexp.hpc;enqueuing into workq, state 1 hop 1
02/13/2018 17:59:13;0008;Server@node2;Job;937.node2.supernodexp.hpc;Job Queued at request of ctminh@node2.supernodexp.hpc, owner = ctminh@node2.supernodexp.hpc, job name = telemac1, queue = workq
02/13/2018 17:59:13;0100;Server@node2;Req;;Type 20 request received from Scheduler@node2.supernodexp.hpc, sock=20
02/13/2018 17:59:13;0100;Server@node2;Req;;Type 51 request received from Scheduler@node2.supernodexp.hpc, sock=20
02/13/2018 17:59:13;0100;Server@node2;Req;;Type 1 request received from ctminh@node2.supernodexp.hpc, sock=16
02/13/2018 17:59:13;0100;Server@node2;Req;;Type 3 request received from ctminh@node2.supernodexp.hpc, sock=16
02/13/2018 17:59:13;0100;Server@node2;Req;;Type 5 request received from ctminh@node2.supernodexp.hpc, sock=16
02/13/2018 17:59:13;0100;Server@node2;Job;938.node2.supernodexp.hpc;enqueuing into workq, state 1 hop 1
02/13/2018 17:59:13;0008;Server@node2;Job;938.node2.supernodexp.hpc;Job Queued at request of ctminh@node2.supernodexp.hpc, owner = ctminh@node2.supernodexp.hpc, job name = lu-decomp, queue = workq
02/13/2018 17:59:13;0100;Server@node2;Req;;Type 1 request received from ctminh@node2.supernodexp.hpc, sock=16
02/13/2018 17:59:13;0100;Server@node2;Req;;Type 3 request received from ctminh@node2.supernodexp.hpc, sock=16
02/13/2018 17:59:13;0100;Server@node2;Req;;Type 5 request received from ctminh@node2.supernodexp.hpc, sock=16
02/13/2018 17:59:13;0100;Server@node2;Job;939.node2.supernodexp.hpc;enqueuing into workq, state 1 hop 1
02/13/2018 17:59:13;0008;Server@node2;Job;939.node2.supernodexp.hpc;Job Queued at request of ctminh@node2.supernodexp.hpc, owner = ctminh@node2.supernodexp.hpc, job name = qe_mic_test, queue = workq
02/13/2018 17:59:13;0100;Server@node2;Req;;Type 1 request received from ctminh@node2.supernodexp.hpc, sock=16
02/13/2018 17:59:13;0100;Server@node2;Req;;Type 11 request received from Scheduler@node2.supernodexp.hpc, sock=20
02/13/2018 17:59:13;0008;Server@node2;Job;934.node2.supernodexp.hpc;Job Modified at request of Scheduler@node2.supernodexp.hpc
02/13/2018 17:59:13;0100;Server@node2;Req;;Type 3 request received from ctminh@node2.supernodexp.hpc, sock=16
02/13/2018 17:59:13;0100;Server@node2;Req;;Type 11 request received from Scheduler@node2.supernodexp.hpc, sock=20
02/13/2018 17:59:13;0008;Server@node2;Job;935.node2.supernodexp.hpc;Job Modified at request of Scheduler@node2.supernodexp.hpc
02/13/2018 17:59:13;0100;Server@node2;Req;;Type 5 request received from ctminh@node2.supernodexp.hpc, sock=16
02/13/2018 17:59:13;0100;Server@node2;Job;940.node2.supernodexp.hpc;enqueuing into workq, state 1 hop 1
02/13/2018 17:59:13;0008;Server@node2;Job;940.node2.supernodexp.hpc;Job Queued at request of ctminh@node2.supernodexp.hpc, owner = ctminh@node2.supernodexp.hpc, job name = jacobi, queue = workq
02/13/2018 17:59:13;0100;Server@node2;Req;;Type 11 request received from Scheduler@node2.supernodexp.hpc, sock=20
02/13/2018 17:59:13;0008;Server@node2;Job;936.node2.supernodexp.hpc;Job Modified at request of Scheduler@node2.supernodexp.hpc
02/13/2018 17:59:13;0100;Server@node2;Req;;Type 11 request received from Scheduler@node2.supernodexp.hpc, sock=20
02/13/2018 17:59:13;0008;Server@node2;Job;933.node2.supernodexp.hpc;Job Modified at request of Scheduler@node2.supernodexp.hpc
02/13/2018 17:59:13;0100;Server@node2;Req;;Type 11 request received from Scheduler@node2.supernodexp.hpc, sock=20
02/13/2018 17:59:13;0008;Server@node2;Job;937.node2.supernodexp.hpc;Job Modified at request of Scheduler@node2.supernodexp.hpc
02/13/2018 17:59:13;0040;Server@node2;Svr;node2.supernodexp.hpc;Scheduler sent command 1
02/13/2018 17:59:13;0040;Server@node2;Svr;node2.supernodexp.hpc;Scheduler sent command 0
02/13/2018 17:59:13;0100;Server@node2;Req;;Type 21 request received from Scheduler@node2.supernodexp.hpc, sock=20
02/13/2018 17:59:13;0100;Server@node2;Req;;Type 81 request received from Scheduler@node2.supernodexp.hpc, sock=20
02/13/2018 17:59:13;0100;Server@node2;Req;;Type 71 request received from Scheduler@node2.supernodexp.hpc, sock=20
02/13/2018 17:59:13;0100;Server@node2;Req;;Type 58 request received from Scheduler@node2.supernodexp.hpc, sock=20
02/13/2018 17:59:13;0100;Server@node2;Req;;Type 1 request received from ctminh@node2.supernodexp.hpc, sock=16
02/13/2018 17:59:13;0100;Server@node2;Req;;Type 3 request received from ctminh@node2.supernodexp.hpc, sock=16
02/13/2018 17:59:13;0100;Server@node2;Req;;Type 5 request received from ctminh@node2.supernodexp.hpc, sock=16
02/13/2018 17:59:13;0100;Server@node2;Job;941.node2.supernodexp.hpc;enqueuing into workq, state 1 hop 1
02/13/2018 17:59:13;0008;Server@node2;Job;941.node2.supernodexp.hpc;Job Queued at request of ctminh@node2.supernodexp.hpc, owner = ctminh@node2.supernodexp.hpc, job name = sweep, queue = workq
02/13/2018 17:59:13;0100;Server@node2;Req;;Type 1 request received from ctminh@node2.supernodexp.hpc, sock=16
02/13/2018 17:59:13;0100;Server@node2;Req;;Type 3 request received from ctminh@node2.supernodexp.hpc, sock=16
02/13/2018 17:59:13;0100;Server@node2;Req;;Type 5 request received from ctminh@node2.supernodexp.hpc, sock=16
02/13/2018 17:59:13;0100;Server@node2;Job;942.node2.supernodexp.hpc;enqueuing into workq, state 1 hop 1
02/13/2018 17:59:13;0008;Server@node2;Job;942.node2.supernodexp.hpc;Job Queued at request of ctminh@node2.supernodexp.hpc, owner = ctminh@node2.supernodexp.hpc, job name = histogram, queue = workq
02/13/2018 17:59:13;0100;Server@node2;Req;;Type 20 request received from Scheduler@node2.supernodexp.hpc, sock=20
02/13/2018 17:59:13;0100;Server@node2;Req;;Type 51 request received from Scheduler@node2.supernodexp.hpc, sock=20
02/13/2018 17:59:13;0100;Server@node2;Req;;Type 1 request received from ctminh@node2.supernodexp.hpc, sock=16
02/13/2018 17:59:13;0100;Server@node2;Req;;Type 3 request received from ctminh@node2.supernodexp.hpc, sock=16
02/13/2018 17:59:13;0100;Server@node2;Req;;Type 5 request received from ctminh@node2.supernodexp.hpc, sock=16
02/13/2018 17:59:13;0100;Server@node2;Job;943.node2.supernodexp.hpc;enqueuing into workq, state 1 hop 1
02/13/2018 17:59:13;0008;Server@node2;Job;943.node2.supernodexp.hpc;Job Queued at request of ctminh@node2.supernodexp.hpc, owner = ctminh@node2.supernodexp.hpc, job name = sweep, queue = workq
02/13/2018 17:59:13;0100;Server@node2;Req;;Type 1 request received from ctminh@node2.supernodexp.hpc, sock=16
02/13/2018 17:59:13;0100;Server@node2;Req;;Type 3 request received from ctminh@node2.supernodexp.hpc, sock=16
02/13/2018 17:59:13;0100;Server@node2;Req;;Type 5 request received from ctminh@node2.supernodexp.hpc, sock=16
02/13/2018 17:59:13;0100;Server@node2;Job;944.node2.supernodexp.hpc;enqueuing into workq, state 1 hop 1
02/13/2018 17:59:13;0008;Server@node2;Job;944.node2.supernodexp.hpc;Job Queued at request of ctminh@node2.supernodexp.hpc, owner = ctminh@node2.supernodexp.hpc, job name = telemac2, queue = workq
02/13/2018 17:59:13;0100;Server@node2;Req;;Type 1 request received from ctminh@node2.supernodexp.hpc, sock=16
02/13/2018 17:59:13;0100;Server@node2;Req;;Type 11 request received from Scheduler@node2.supernodexp.hpc, sock=20
02/13/2018 17:59:13;0008;Server@node2;Job;938.node2.supernodexp.hpc;Job Modified at request of Scheduler@node2.supernodexp.hpc
02/13/2018 17:59:13;0100;Server@node2;Req;;Type 3 request received from ctminh@node2.supernodexp.hpc, sock=16
02/13/2018 17:59:13;0100;Server@node2;Req;;Type 5 request received from ctminh@node2.supernodexp.hpc, sock=16
02/13/2018 17:59:13;0100;Server@node2;Job;945.node2.supernodexp.hpc;enqueuing into workq, state 1 hop 1
02/13/2018 17:59:13;0008;Server@node2;Job;945.node2.supernodexp.hpc;Job Queued at request of ctminh@node2.supernodexp.hpc, owner = ctminh@node2.supernodexp.hpc, job name = matrix-x-vector, queue = workq
02/13/2018 17:59:13;0100;Server@node2;Req;;Type 11 request received from Scheduler@node2.supernodexp.hpc, sock=20
02/13/2018 17:59:13;0008;Server@node2;Job;941.node2.supernodexp.hpc;Job Modified at request of Scheduler@node2.supernodexp.hpc
02/13/2018 17:59:13;0100;Server@node2;Req;;Type 11 request received from Scheduler@node2.supernodexp.hpc, sock=20
02/13/2018 17:59:13;0008;Server@node2;Job;942.node2.supernodexp.hpc;Job Modified at request of Scheduler@node2.supernodexp.hpc
02/13/2018 17:59:13;0100;Server@node2;Req;;Type 11 request received from Scheduler@node2.supernodexp.hpc, sock=20
02/13/2018 17:59:13;0008;Server@node2;Job;940.node2.supernodexp.hpc;Job Modified at request of Scheduler@node2.supernodexp.hpc
02/13/2018 17:59:13;0100;Server@node2;Req;;Type 11 request received from Scheduler@node2.supernodexp.hpc, sock=20
02/13/2018 17:59:13;0008;Server@node2;Job;939.node2.supernodexp.hpc;Job Modified at request of Scheduler@node2.supernodexp.hpc
02/13/2018 17:59:13;0040;Server@node2;Svr;node2.supernodexp.hpc;Scheduler sent command 1
02/13/2018 17:59:13;0040;Server@node2;Svr;node2.supernodexp.hpc;Scheduler sent command 0
02/13/2018 17:59:13;0100;Server@node2;Req;;Type 21 request received from Scheduler@node2.supernodexp.hpc, sock=20
02/13/2018 17:59:13;0100;Server@node2;Req;;Type 81 request received from Scheduler@node2.supernodexp.hpc, sock=20
02/13/2018 17:59:13;0100;Server@node2;Req;;Type 71 request received from Scheduler@node2.supernodexp.hpc, sock=20
02/13/2018 17:59:13;0100;Server@node2;Req;;Type 58 request received from Scheduler@node2.supernodexp.hpc, sock=20
02/13/2018 17:59:13;0100;Server@node2;Req;;Type 1 request received from ctminh@node2.supernodexp.hpc, sock=16
02/13/2018 17:59:13;0100;Server@node2;Req;;Type 3 request received from ctminh@node2.supernodexp.hpc, sock=16
02/13/2018 17:59:13;0100;Server@node2;Req;;Type 5 request received from ctminh@node2.supernodexp.hpc, sock=16
02/13/2018 17:59:13;0100;Server@node2;Job;946.node2.supernodexp.hpc;enqueuing into workq, state 1 hop 1
02/13/2018 17:59:13;0008;Server@node2;Job;946.node2.supernodexp.hpc;Job Queued at request of ctminh@node2.supernodexp.hpc, owner = ctminh@node2.supernodexp.hpc, job name = vectorization, queue = workq
02/13/2018 17:59:13;0100;Server@node2;Req;;Type 1 request received from ctminh@node2.supernodexp.hpc, sock=16
02/13/2018 17:59:13;0100;Server@node2;Req;;Type 3 request received from ctminh@node2.supernodexp.hpc, sock=16
02/13/2018 17:59:13;0100;Server@node2;Req;;Type 5 request received from ctminh@node2.supernodexp.hpc, sock=16
02/13/2018 17:59:13;0100;Server@node2;Job;947.node2.supernodexp.hpc;enqueuing into workq, state 1 hop 1
02/13/2018 17:59:13;0008;Server@node2;Job;947.node2.supernodexp.hpc;Job Queued at request of ctminh@node2.supernodexp.hpc, owner = ctminh@node2.supernodexp.hpc, job name = qe_mic_test, queue = workq
02/13/2018 17:59:13;0100;Server@node2;Req;;Type 20 request received from Scheduler@node2.supernodexp.hpc, sock=20
02/13/2018 17:59:13;0100;Server@node2;Req;;Type 51 request received from Scheduler@node2.supernodexp.hpc, sock=20
02/13/2018 17:59:13;0100;Server@node2;Req;;Type 1 request received from ctminh@node2.supernodexp.hpc, sock=16
02/13/2018 17:59:13;0080;Server@node2;Job;918.node2.supernodexp.hpc;Obit received momhop:1 serverhop:1 state:4 substate:42
02/13/2018 17:59:13;0100;Server@node2;Req;;Type 3 request received from ctminh@node2.supernodexp.hpc, sock=16
02/13/2018 17:59:13;0100;Server@node2;Req;;Type 11 request received from Scheduler@node2.supernodexp.hpc, sock=20
02/13/2018 17:59:13;0008;Server@node2;Job;945.node2.supernodexp.hpc;Job Modified at request of Scheduler@node2.supernodexp.hpc
02/13/2018 17:59:13;0100;Server@node2;Req;;Type 5 request received from ctminh@node2.supernodexp.hpc, sock=16
02/13/2018 17:59:13;0100;Server@node2;Job;948.node2.supernodexp.hpc;enqueuing into workq, state 1 hop 1
02/13/2018 17:59:13;0008;Server@node2;Job;948.node2.supernodexp.hpc;Job Queued at request of ctminh@node2.supernodexp.hpc, owner = ctminh@node2.supernodexp.hpc, job name = telemac1, queue = workq
02/13/2018 17:59:13;0100;Server@node2;Req;;Type 11 request received from Scheduler@node2.supernodexp.hpc, sock=20
02/13/2018 17:59:13;0008;Server@node2;Job;943.node2.supernodexp.hpc;Job Modified at request of Scheduler@node2.supernodexp.hpc
02/13/2018 17:59:13;0100;Server@node2;Req;;Type 11 request received from Scheduler@node2.supernodexp.hpc, sock=20
02/13/2018 17:59:13;0008;Server@node2;Job;946.node2.supernodexp.hpc;Job Modified at request of Scheduler@node2.supernodexp.hpc
02/13/2018 17:59:13;0100;Server@node2;Req;;Type 11 request received from Scheduler@node2.supernodexp.hpc, sock=20
02/13/2018 17:59:13;0008;Server@node2;Job;944.node2.supernodexp.hpc;Job Modified at request of Scheduler@node2.supernodexp.hpc
02/13/2018 17:59:13;0100;Server@node2;Req;;Type 11 request received from Scheduler@node2.supernodexp.hpc, sock=20
02/13/2018 17:59:13;0008;Server@node2;Job;947.node2.supernodexp.hpc;Job Modified at request of Scheduler@node2.supernodexp.hpc
02/13/2018 17:59:13;0040;Server@node2;Svr;node2.supernodexp.hpc;Scheduler sent command 1
02/13/2018 17:59:13;0040;Server@node2;Svr;node2.supernodexp.hpc;Scheduler sent command 0
02/13/2018 17:59:13;0100;Server@node2;Req;;Type 21 request received from Scheduler@node2.supernodexp.hpc, sock=20
02/13/2018 17:59:13;0100;Server@node2;Req;;Type 81 request received from Scheduler@node2.supernodexp.hpc, sock=20
02/13/2018 17:59:13;0100;Server@node2;Req;;Type 71 request received from Scheduler@node2.supernodexp.hpc, sock=20
02/13/2018 17:59:13;0100;Server@node2;Req;;Type 58 request received from Scheduler@node2.supernodexp.hpc, sock=20
02/13/2018 17:59:13;0100;Server@node2;Req;;Type 1 request received from ctminh@node2.supernodexp.hpc, sock=16
02/13/2018 17:59:13;0100;Server@node2;Req;;Type 3 request received from ctminh@node2.supernodexp.hpc, sock=16
02/13/2018 17:59:13;0100;Server@node2;Req;;Type 5 request received from ctminh@node2.supernodexp.hpc, sock=16
02/13/2018 17:59:13;0100;Server@node2;Job;949.node2.supernodexp.hpc;enqueuing into workq, state 1 hop 1
02/13/2018 17:59:13;0008;Server@node2;Job;949.node2.supernodexp.hpc;Job Queued at request of ctminh@node2.supernodexp.hpc, owner = ctminh@node2.supernodexp.hpc, job name = vast1, queue = workq
02/13/2018 17:59:13;0100;Server@node2;Req;;Type 1 request received from ctminh@node2.supernodexp.hpc, sock=16
02/13/2018 17:59:13;0100;Server@node2;Req;;Type 3 request received from ctminh@node2.supernodexp.hpc, sock=16
02/13/2018 17:59:13;0100;Server@node2;Req;;Type 5 request received from ctminh@node2.supernodexp.hpc, sock=16
02/13/2018 17:59:13;0100;Server@node2;Job;950.node2.supernodexp.hpc;enqueuing into workq, state 1 hop 1
02/13/2018 17:59:13;0008;Server@node2;Job;950.node2.supernodexp.hpc;Job Queued at request of ctminh@node2.supernodexp.hpc, owner = ctminh@node2.supernodexp.hpc, job name = sweep, queue = workq
02/13/2018 17:59:13;0100;Server@node2;Req;;Type 20 request received from Scheduler@node2.supernodexp.hpc, sock=20
02/13/2018 17:59:13;0100;Server@node2;Req;;Type 51 request received from Scheduler@node2.supernodexp.hpc, sock=20
02/13/2018 17:59:13;0100;Server@node2;Req;;Type 11 request received from Scheduler@node2.supernodexp.hpc, sock=20
02/13/2018 17:59:13;0008;Server@node2;Job;950.node2.supernodexp.hpc;Job Modified at request of Scheduler@node2.supernodexp.hpc
02/13/2018 17:59:13;0100;Server@node2;Req;;Type 11 request received from Scheduler@node2.supernodexp.hpc, sock=20
02/13/2018 17:59:13;0008;Server@node2;Job;948.node2.supernodexp.hpc;Job Modified at request of Scheduler@node2.supernodexp.hpc
02/13/2018 17:59:13;0100;Server@node2;Req;;Type 11 request received from Scheduler@node2.supernodexp.hpc, sock=20
02/13/2018 17:59:13;0008;Server@node2;Job;949.node2.supernodexp.hpc;Job Modified at request of Scheduler@node2.supernodexp.hpc
02/13/2018 17:59:13;0040;Server@node2;Svr;node2.supernodexp.hpc;Scheduler sent command 1
02/13/2018 17:59:13;0040;Server@node2;Svr;node2.supernodexp.hpc;Scheduler sent command 0
02/13/2018 17:59:13;0100;Server@node2;Req;;Type 21 request received from Scheduler@node2.supernodexp.hpc, sock=20
02/13/2018 17:59:13;0100;Server@node2;Req;;Type 81 request received from Scheduler@node2.supernodexp.hpc, sock=20
02/13/2018 17:59:13;0100;Server@node2;Req;;Type 71 request received from Scheduler@node2.supernodexp.hpc, sock=20
02/13/2018 17:59:13;0100;Server@node2;Req;;Type 58 request received from Scheduler@node2.supernodexp.hpc, sock=20
02/13/2018 17:59:13;0100;Server@node2;Req;;Type 20 request received from Scheduler@node2.supernodexp.hpc, sock=20
02/13/2018 17:59:13;0100;Server@node2;Req;;Type 51 request received from Scheduler@node2.supernodexp.hpc, sock=20
02/13/2018 17:59:14;0010;Server@node2;Job;918.node2.supernodexp.hpc;Exit_status=0 resources_used.cpupercent=800 resources_used.cput=00:00:08 resources_used.mem=0kb resources_used.ncpus=8 resources_used.vmem=0kb resources_used.walltime=00:00:02
02/13/2018 17:59:14;0100;Server@node2;Job;918.node2.supernodexp.hpc;dequeuing from workq, state 5
02/13/2018 17:59:14;0040;Server@node2;Svr;node2.supernodexp.hpc;Scheduler sent command 2
02/13/2018 17:59:14;0040;Server@node2;Svr;node2.supernodexp.hpc;Scheduler sent command 0
02/13/2018 17:59:14;0100;Server@node2;Req;;Type 21 request received from Scheduler@node2.supernodexp.hpc, sock=20
02/13/2018 17:59:14;0100;Server@node2;Req;;Type 81 request received from Scheduler@node2.supernodexp.hpc, sock=20
02/13/2018 17:59:14;0100;Server@node2;Req;;Type 71 request received from Scheduler@node2.supernodexp.hpc, sock=20
02/13/2018 17:59:14;0100;Server@node2;Req;;Type 58 request received from Scheduler@node2.supernodexp.hpc, sock=20
02/13/2018 17:59:14;0100;Server@node2;Req;;Type 20 request received from Scheduler@node2.supernodexp.hpc, sock=20
02/13/2018 17:59:14;0100;Server@node2;Req;;Type 51 request received from Scheduler@node2.supernodexp.hpc, sock=20
02/13/2018 17:59:14;0100;Server@node2;Req;;Type 23 request received from Scheduler@node2.supernodexp.hpc, sock=20
02/13/2018 17:59:14;0008;Server@node2;Job;926.node2.supernodexp.hpc;Job Run at request of Scheduler@node2.supernodexp.hpc on exec_vnode (node13:ncpus=16:mem=5242880kb)
02/13/2018 17:59:14;0001;Server@node2;Svr;Server@node2;Success (0) in req_runjob2, return value of svr_startjob is 0
02/13/2018 17:59:14;0100;Server@node2;Req;;Type 11 request received from Scheduler@node2.supernodexp.hpc, sock=20
02/13/2018 17:59:14;0008;Server@node2;Job;934.node2.supernodexp.hpc;Job Modified at request of Scheduler@node2.supernodexp.hpc
02/13/2018 17:59:15;0080;Server@node2;Job;926.node2.supernodexp.hpc;Obit received momhop:1 serverhop:1 state:4 substate:42
02/13/2018 17:59:15;0080;Server@node2;Job;914.node2.supernodexp.hpc;Obit received momhop:1 serverhop:1 state:4 substate:42
02/13/2018 17:59:16;0010;Server@node2;Job;926.node2.supernodexp.hpc;Exit_status=0 resources_used.cpupercent=1600 resources_used.cput=00:00:16 resources_used.mem=0kb resources_used.ncpus=16 resources_used.vmem=0kb resources_used.walltime=00:00:01
02/13/2018 17:59:16;0100;Server@node2;Job;926.node2.supernodexp.hpc;dequeuing from workq, state 5
02/13/2018 17:59:16;0040;Server@node2;Svr;node2.supernodexp.hpc;Scheduler sent command 2
02/13/2018 17:59:16;0040;Server@node2;Svr;node2.supernodexp.hpc;Scheduler sent command 0
02/13/2018 17:59:16;0100;Server@node2;Req;;Type 21 request received from Scheduler@node2.supernodexp.hpc, sock=20
02/13/2018 17:59:16;0100;Server@node2;Req;;Type 81 request received from Scheduler@node2.supernodexp.hpc, sock=20
02/13/2018 17:59:16;0100;Server@node2;Req;;Type 71 request received from Scheduler@node2.supernodexp.hpc, sock=20
02/13/2018 17:59:16;0100;Server@node2;Req;;Type 58 request received from Scheduler@node2.supernodexp.hpc, sock=20
02/13/2018 17:59:16;0100;Server@node2;Req;;Type 20 request received from Scheduler@node2.supernodexp.hpc, sock=20
02/13/2018 17:59:16;0100;Server@node2;Req;;Type 51 request received from Scheduler@node2.supernodexp.hpc, sock=20
02/13/2018 17:59:16;0100;Server@node2;Req;;Type 11 request received from Scheduler@node2.supernodexp.hpc, sock=20
02/13/2018 17:59:16;0008;Server@node2;Job;934.node2.supernodexp.hpc;Job Modified at request of Scheduler@node2.supernodexp.hpc
02/13/2018 17:59:17;0010;Server@node2;Job;914.node2.supernodexp.hpc;Exit_status=0 resources_used.cpupercent=100 resources_used.cput=00:00:04 resources_used.mem=535668kb resources_used.ncpus=32 resources_used.vmem=867312kb resources_used.walltime=00:00:04
02/13/2018 17:59:17;0100;Server@node2;Job;914.node2.supernodexp.hpc;dequeuing from workq, state 5
02/13/2018 17:59:17;0040;Server@node2;Svr;node2.supernodexp.hpc;Scheduler sent command 2
02/13/2018 17:59:17;0040;Server@node2;Svr;node2.supernodexp.hpc;Scheduler sent command 0
02/13/2018 17:59:17;0100;Server@node2;Req;;Type 21 request received from Scheduler@node2.supernodexp.hpc, sock=20
02/13/2018 17:59:17;0100;Server@node2;Req;;Type 81 request received from Scheduler@node2.supernodexp.hpc, sock=20
02/13/2018 17:59:17;0100;Server@node2;Req;;Type 71 request received from Scheduler@node2.supernodexp.hpc, sock=20
02/13/2018 17:59:17;0100;Server@node2;Req;;Type 58 request received from Scheduler@node2.supernodexp.hpc, sock=20
02/13/2018 17:59:17;0100;Server@node2;Req;;Type 20 request received from Scheduler@node2.supernodexp.hpc, sock=20
02/13/2018 17:59:17;0100;Server@node2;Req;;Type 51 request received from Scheduler@node2.supernodexp.hpc, sock=20
02/13/2018 17:59:17;0100;Server@node2;Req;;Type 23 request received from Scheduler@node2.supernodexp.hpc, sock=20
02/13/2018 17:59:17;0008;Server@node2;Job;934.node2.supernodexp.hpc;Job Run at request of Scheduler@node2.supernodexp.hpc on exec_vnode (node13:ncpus=24:mem=1048576kb)
02/13/2018 17:59:17;0001;Server@node2;Svr;Server@node2;Success (0) in req_runjob2, return value of svr_startjob is 0
02/13/2018 17:59:17;0100;Server@node2;Req;;Type 23 request received from Scheduler@node2.supernodexp.hpc, sock=20
02/13/2018 17:59:17;0008;Server@node2;Job;935.node2.supernodexp.hpc;Job Run at request of Scheduler@node2.supernodexp.hpc on exec_vnode (node13:ncpus=24:mem=1048576kb)
02/13/2018 17:59:17;0001;Server@node2;Svr;Server@node2;Success (0) in req_runjob2, return value of svr_startjob is 0
02/13/2018 17:59:17;0100;Server@node2;Req;;Type 11 request received from Scheduler@node2.supernodexp.hpc, sock=20
02/13/2018 17:59:17;0008;Server@node2;Job;938.node2.supernodexp.hpc;Job Modified at request of Scheduler@node2.supernodexp.hpc
02/13/2018 17:59:19;0080;Server@node2;Job;934.node2.supernodexp.hpc;Obit received momhop:1 serverhop:1 state:4 substate:42
02/13/2018 17:59:19;0080;Server@node2;Job;935.node2.supernodexp.hpc;Obit received momhop:1 serverhop:1 state:4 substate:42
02/13/2018 17:59:20;0010;Server@node2;Job;934.node2.supernodexp.hpc;Exit_status=0 resources_used.cpupercent=2403 resources_used.cput=00:00:38 resources_used.mem=0kb resources_used.ncpus=24 resources_used.vmem=0kb resources_used.walltime=00:00:02
02/13/2018 17:59:20;0100;Server@node2;Job;934.node2.supernodexp.hpc;dequeuing from workq, state 5
02/13/2018 17:59:20;0040;Server@node2;Svr;node2.supernodexp.hpc;Scheduler sent command 2
02/13/2018 17:59:20;0040;Server@node2;Svr;node2.supernodexp.hpc;Scheduler sent command 0
02/13/2018 17:59:20;0100;Server@node2;Req;;Type 21 request received from Scheduler@node2.supernodexp.hpc, sock=20
02/13/2018 17:59:20;0100;Server@node2;Req;;Type 81 request received from Scheduler@node2.supernodexp.hpc, sock=20
02/13/2018 17:59:20;0100;Server@node2;Req;;Type 71 request received from Scheduler@node2.supernodexp.hpc, sock=20
02/13/2018 17:59:20;0100;Server@node2;Req;;Type 58 request received from Scheduler@node2.supernodexp.hpc, sock=20
02/13/2018 17:59:20;0100;Server@node2;Req;;Type 20 request received from Scheduler@node2.supernodexp.hpc, sock=20
02/13/2018 17:59:20;0100;Server@node2;Req;;Type 51 request received from Scheduler@node2.supernodexp.hpc, sock=20
02/13/2018 17:59:20;0100;Server@node2;Req;;Type 23 request received from Scheduler@node2.supernodexp.hpc, sock=20
02/13/2018 17:59:20;0008;Server@node2;Job;938.node2.supernodexp.hpc;Job Run at request of Scheduler@node2.supernodexp.hpc on exec_vnode (node13:ncpus=24:mem=1048576kb)
02/13/2018 17:59:20;0001;Server@node2;Svr;Server@node2;Success (0) in req_runjob2, return value of svr_startjob is 0
02/13/2018 17:59:20;0100;Server@node2;Req;;Type 11 request received from Scheduler@node2.supernodexp.hpc, sock=20
02/13/2018 17:59:20;0008;Server@node2;Job;945.node2.supernodexp.hpc;Job Modified at request of Scheduler@node2.supernodexp.hpc
02/13/2018 17:59:20;0010;Server@node2;Job;935.node2.supernodexp.hpc;Exit_status=0 resources_used.cpupercent=2402 resources_used.cput=00:00:41 resources_used.mem=1292252kb resources_used.ncpus=24 resources_used.vmem=3151056kb resources_used.walltime=00:00:02
02/13/2018 17:59:20;0100;Server@node2;Job;935.node2.supernodexp.hpc;dequeuing from workq, state 5
02/13/2018 17:59:20;0040;Server@node2;Svr;node2.supernodexp.hpc;Scheduler sent command 2
02/13/2018 17:59:20;0040;Server@node2;Svr;node2.supernodexp.hpc;Scheduler sent command 0
02/13/2018 17:59:20;0100;Server@node2;Req;;Type 21 request received from Scheduler@node2.supernodexp.hpc, sock=20
02/13/2018 17:59:20;0100;Server@node2;Req;;Type 81 request received from Scheduler@node2.supernodexp.hpc, sock=20
02/13/2018 17:59:20;0100;Server@node2;Req;;Type 71 request received from Scheduler@node2.supernodexp.hpc, sock=20
02/13/2018 17:59:20;0100;Server@node2;Req;;Type 58 request received from Scheduler@node2.supernodexp.hpc, sock=20
02/13/2018 17:59:20;0100;Server@node2;Req;;Type 20 request received from Scheduler@node2.supernodexp.hpc, sock=20
02/13/2018 17:59:20;0100;Server@node2;Req;;Type 51 request received from Scheduler@node2.supernodexp.hpc, sock=20
02/13/2018 17:59:20;0100;Server@node2;Req;;Type 23 request received from Scheduler@node2.supernodexp.hpc, sock=20
02/13/2018 17:59:20;0008;Server@node2;Job;945.node2.supernodexp.hpc;Job Run at request of Scheduler@node2.supernodexp.hpc on exec_vnode (node13:ncpus=16:mem=5242880kb)
02/13/2018 17:59:20;0001;Server@node2;Svr;Server@node2;Success (0) in req_runjob2, return value of svr_startjob is 0
02/13/2018 17:59:20;0100;Server@node2;Req;;Type 11 request received from Scheduler@node2.supernodexp.hpc, sock=20
02/13/2018 17:59:20;0008;Server@node2;Job;919.node2.supernodexp.hpc;Job Modified at request of Scheduler@node2.supernodexp.hpc
02/13/2018 17:59:22;0080;Server@node2;Job;945.node2.supernodexp.hpc;Obit received momhop:1 serverhop:1 state:4 substate:42
02/13/2018 17:59:22;0080;Server@node2;Job;938.node2.supernodexp.hpc;Obit received momhop:1 serverhop:1 state:4 substate:42
02/13/2018 17:59:23;0010;Server@node2;Job;945.node2.supernodexp.hpc;Exit_status=0 resources_used.cpupercent=1600 resources_used.cput=00:00:18 resources_used.mem=0kb resources_used.ncpus=16 resources_used.vmem=0kb resources_used.walltime=00:00:01
02/13/2018 17:59:23;0100;Server@node2;Job;945.node2.supernodexp.hpc;dequeuing from workq, state 5
02/13/2018 17:59:23;0010;Server@node2;Job;938.node2.supernodexp.hpc;Exit_status=0 resources_used.cpupercent=110 resources_used.cput=00:00:38 resources_used.mem=1296184kb resources_used.ncpus=24 resources_used.vmem=3151052kb resources_used.walltime=00:00:01
02/13/2018 17:59:23;0100;Server@node2;Job;938.node2.supernodexp.hpc;dequeuing from workq, state 5
02/13/2018 17:59:23;0040;Server@node2;Svr;node2.supernodexp.hpc;Scheduler sent command 2
02/13/2018 17:59:23;0040;Server@node2;Svr;node2.supernodexp.hpc;Scheduler sent command 0
02/13/2018 17:59:23;0100;Server@node2;Req;;Type 21 request received from Scheduler@node2.supernodexp.hpc, sock=20
02/13/2018 17:59:23;0100;Server@node2;Req;;Type 81 request received from Scheduler@node2.supernodexp.hpc, sock=20
02/13/2018 17:59:23;0100;Server@node2;Req;;Type 71 request received from Scheduler@node2.supernodexp.hpc, sock=20
02/13/2018 17:59:23;0100;Server@node2;Req;;Type 58 request received from Scheduler@node2.supernodexp.hpc, sock=20
02/13/2018 17:59:23;0100;Server@node2;Req;;Type 20 request received from Scheduler@node2.supernodexp.hpc, sock=20
02/13/2018 17:59:23;0100;Server@node2;Req;;Type 51 request received from Scheduler@node2.supernodexp.hpc, sock=20
02/13/2018 17:59:23;0100;Server@node2;Req;;Type 23 request received from Scheduler@node2.supernodexp.hpc, sock=20
02/13/2018 17:59:23;0008;Server@node2;Job;919.node2.supernodexp.hpc;Job Run at request of Scheduler@node2.supernodexp.hpc on exec_vnode (node13:ncpus=12:mem=1048576kb)
02/13/2018 17:59:23;0001;Server@node2;Svr;Server@node2;Success (0) in req_runjob2, return value of svr_startjob is 0
02/13/2018 17:59:23;0100;Server@node2;Req;;Type 23 request received from Scheduler@node2.supernodexp.hpc, sock=20
02/13/2018 17:59:23;0008;Server@node2;Job;928.node2.supernodexp.hpc;Job Run at request of Scheduler@node2.supernodexp.hpc on exec_vnode (node13:ncpus=12:mem=1048576kb)
02/13/2018 17:59:23;0001;Server@node2;Svr;Server@node2;Success (0) in req_runjob2, return value of svr_startjob is 0
02/13/2018 17:59:23;0100;Server@node2;Req;;Type 11 request received from Scheduler@node2.supernodexp.hpc, sock=20
02/13/2018 17:59:23;0008;Server@node2;Job;931.node2.supernodexp.hpc;Job Modified at request of Scheduler@node2.supernodexp.hpc
02/13/2018 17:59:23;0100;Server@node2;Req;;Type 0 request received from root@node2.supernodexp.hpc, sock=20
02/13/2018 17:59:23;0100;Server@node2;Req;;Type 49 request received from root@node2.supernodexp.hpc, sock=21
02/13/2018 17:59:23;0100;Server@node2;Req;;Type 21 request received from root@node2.supernodexp.hpc, sock=20
02/13/2018 17:59:23;0100;Server@node2;Req;;Type 19 request received from root@node2.supernodexp.hpc, sock=20
02/13/2018 17:59:29;0080;Server@node2;Job;919.node2.supernodexp.hpc;Obit received momhop:1 serverhop:1 state:4 substate:42
02/13/2018 17:59:29;0080;Server@node2;Job;928.node2.supernodexp.hpc;Obit received momhop:1 serverhop:1 state:4 substate:42
02/13/2018 17:59:31;0010;Server@node2;Job;919.node2.supernodexp.hpc;Exit_status=0 resources_used.cpupercent=1200 resources_used.cput=00:01:12 resources_used.mem=1820kb resources_used.ncpus=12 resources_used.vmem=127704kb resources_used.walltime=00:00:06
02/13/2018 17:59:31;0100;Server@node2;Job;919.node2.supernodexp.hpc;dequeuing from workq, state 5
02/13/2018 17:59:31;0040;Server@node2;Svr;node2.supernodexp.hpc;Scheduler sent command 2
02/13/2018 17:59:31;0040;Server@node2;Svr;node2.supernodexp.hpc;Scheduler sent command 0
02/13/2018 17:59:31;0100;Server@node2;Req;;Type 21 request received from Scheduler@node2.supernodexp.hpc, sock=20
02/13/2018 17:59:31;0100;Server@node2;Req;;Type 81 request received from Scheduler@node2.supernodexp.hpc, sock=20
02/13/2018 17:59:31;0100;Server@node2;Req;;Type 71 request received from Scheduler@node2.supernodexp.hpc, sock=20
02/13/2018 17:59:31;0100;Server@node2;Req;;Type 58 request received from Scheduler@node2.supernodexp.hpc, sock=20
02/13/2018 17:59:31;0100;Server@node2;Req;;Type 20 request received from Scheduler@node2.supernodexp.hpc, sock=20
02/13/2018 17:59:31;0100;Server@node2;Req;;Type 51 request received from Scheduler@node2.supernodexp.hpc, sock=20
02/13/2018 17:59:31;0100;Server@node2;Req;;Type 23 request received from Scheduler@node2.supernodexp.hpc, sock=20
02/13/2018 17:59:31;0008;Server@node2;Job;931.node2.supernodexp.hpc;Job Run at request of Scheduler@node2.supernodexp.hpc on exec_vnode (node13:ncpus=32:mem=2097152kb)
02/13/2018 17:59:31;0001;Server@node2;Svr;Server@node2;Success (0) in req_runjob2, return value of svr_startjob is 0
02/13/2018 17:59:31;0100;Server@node2;Req;;Type 11 request received from Scheduler@node2.supernodexp.hpc, sock=20
02/13/2018 17:59:31;0008;Server@node2;Job;941.node2.supernodexp.hpc;Job Modified at request of Scheduler@node2.supernodexp.hpc
02/13/2018 17:59:31;0010;Server@node2;Job;928.node2.supernodexp.hpc;Exit_status=0 resources_used.cpupercent=1200 resources_used.cput=00:01:12 resources_used.mem=45500kb resources_used.ncpus=12 resources_used.vmem=1125532kb resources_used.walltime=00:00:06
02/13/2018 17:59:31;0100;Server@node2;Job;928.node2.supernodexp.hpc;dequeuing from workq, state 5
02/13/2018 17:59:31;0040;Server@node2;Svr;node2.supernodexp.hpc;Scheduler sent command 2
02/13/2018 17:59:31;0040;Server@node2;Svr;node2.supernodexp.hpc;Scheduler sent command 0
02/13/2018 17:59:31;0100;Server@node2;Req;;Type 21 request received from Scheduler@node2.supernodexp.hpc, sock=20
02/13/2018 17:59:31;0100;Server@node2;Req;;Type 81 request received from Scheduler@node2.supernodexp.hpc, sock=20
02/13/2018 17:59:31;0100;Server@node2;Req;;Type 71 request received from Scheduler@node2.supernodexp.hpc, sock=20
02/13/2018 17:59:31;0100;Server@node2;Req;;Type 58 request received from Scheduler@node2.supernodexp.hpc, sock=20
02/13/2018 17:59:31;0100;Server@node2;Req;;Type 20 request received from Scheduler@node2.supernodexp.hpc, sock=20
02/13/2018 17:59:31;0100;Server@node2;Req;;Type 51 request received from Scheduler@node2.supernodexp.hpc, sock=20
02/13/2018 17:59:31;0100;Server@node2;Req;;Type 23 request received from Scheduler@node2.supernodexp.hpc, sock=20
02/13/2018 17:59:31;0008;Server@node2;Job;941.node2.supernodexp.hpc;Job Run at request of Scheduler@node2.supernodexp.hpc on exec_vnode (node13:ncpus=8:mem=3145728kb)
02/13/2018 17:59:31;0001;Server@node2;Svr;Server@node2;Success (0) in req_runjob2, return value of svr_startjob is 0
02/13/2018 17:59:31;0100;Server@node2;Req;;Type 11 request received from Scheduler@node2.supernodexp.hpc, sock=20
02/13/2018 17:59:31;0008;Server@node2;Job;942.node2.supernodexp.hpc;Job Modified at request of Scheduler@node2.supernodexp.hpc
02/13/2018 17:59:32;0080;Server@node2;Job;941.node2.supernodexp.hpc;Obit received momhop:1 serverhop:1 state:4 substate:42
02/13/2018 17:59:33;0010;Server@node2;Job;941.node2.supernodexp.hpc;Exit_status=0 resources_used.cpupercent=800 resources_used.cput=00:00:08 resources_used.mem=0kb resources_used.ncpus=8 resources_used.vmem=0kb resources_used.walltime=00:00:01
02/13/2018 17:59:33;0100;Server@node2;Job;941.node2.supernodexp.hpc;dequeuing from workq, state 5
02/13/2018 17:59:33;0040;Server@node2;Svr;node2.supernodexp.hpc;Scheduler sent command 2
02/13/2018 17:59:33;0040;Server@node2;Svr;node2.supernodexp.hpc;Scheduler sent command 0
02/13/2018 17:59:33;0100;Server@node2;Req;;Type 21 request received from Scheduler@node2.supernodexp.hpc, sock=20
02/13/2018 17:59:33;0100;Server@node2;Req;;Type 81 request received from Scheduler@node2.supernodexp.hpc, sock=20
02/13/2018 17:59:33;0100;Server@node2;Req;;Type 71 request received from Scheduler@node2.supernodexp.hpc, sock=20
02/13/2018 17:59:33;0100;Server@node2;Req;;Type 58 request received from Scheduler@node2.supernodexp.hpc, sock=20
02/13/2018 17:59:33;0100;Server@node2;Req;;Type 20 request received from Scheduler@node2.supernodexp.hpc, sock=20
02/13/2018 17:59:33;0100;Server@node2;Req;;Type 51 request received from Scheduler@node2.supernodexp.hpc, sock=20
02/13/2018 17:59:33;0100;Server@node2;Req;;Type 11 request received from Scheduler@node2.supernodexp.hpc, sock=20
02/13/2018 17:59:33;0008;Server@node2;Job;942.node2.supernodexp.hpc;Job Modified at request of Scheduler@node2.supernodexp.hpc
02/13/2018 17:59:35;0080;Server@node2;Job;931.node2.supernodexp.hpc;Obit received momhop:1 serverhop:1 state:4 substate:42
02/13/2018 17:59:36;0010;Server@node2;Job;931.node2.supernodexp.hpc;Exit_status=0 resources_used.cpupercent=50 resources_used.cput=00:00:03 resources_used.mem=536744kb resources_used.ncpus=32 resources_used.vmem=867312kb resources_used.walltime=00:00:04
02/13/2018 17:59:36;0100;Server@node2;Job;931.node2.supernodexp.hpc;dequeuing from workq, state 5
02/13/2018 17:59:36;0040;Server@node2;Svr;node2.supernodexp.hpc;Scheduler sent command 2
02/13/2018 17:59:36;0040;Server@node2;Svr;node2.supernodexp.hpc;Scheduler sent command 0
02/13/2018 17:59:36;0100;Server@node2;Req;;Type 21 request received from Scheduler@node2.supernodexp.hpc, sock=20
02/13/2018 17:59:36;0100;Server@node2;Req;;Type 81 request received from Scheduler@node2.supernodexp.hpc, sock=20
02/13/2018 17:59:36;0100;Server@node2;Req;;Type 71 request received from Scheduler@node2.supernodexp.hpc, sock=20
02/13/2018 17:59:36;0100;Server@node2;Req;;Type 58 request received from Scheduler@node2.supernodexp.hpc, sock=20
02/13/2018 17:59:36;0100;Server@node2;Req;;Type 20 request received from Scheduler@node2.supernodexp.hpc, sock=20
02/13/2018 17:59:36;0100;Server@node2;Req;;Type 51 request received from Scheduler@node2.supernodexp.hpc, sock=20
02/13/2018 17:59:36;0100;Server@node2;Req;;Type 23 request received from Scheduler@node2.supernodexp.hpc, sock=20
02/13/2018 17:59:36;0008;Server@node2;Job;942.node2.supernodexp.hpc;Job Run at request of Scheduler@node2.supernodexp.hpc on exec_vnode (node13:ncpus=32:mem=2097152kb)
02/13/2018 17:59:36;0001;Server@node2;Svr;Server@node2;Success (0) in req_runjob2, return value of svr_startjob is 0
02/13/2018 17:59:36;0100;Server@node2;Req;;Type 23 request received from Scheduler@node2.supernodexp.hpc, sock=20
02/13/2018 17:59:36;0008;Server@node2;Job;943.node2.supernodexp.hpc;Job Run at request of Scheduler@node2.supernodexp.hpc on exec_vnode (node13:ncpus=8:mem=3145728kb)
02/13/2018 17:59:36;0001;Server@node2;Svr;Server@node2;Success (0) in req_runjob2, return value of svr_startjob is 0
02/13/2018 17:59:36;0100;Server@node2;Req;;Type 11 request received from Scheduler@node2.supernodexp.hpc, sock=20
02/13/2018 17:59:36;0008;Server@node2;Job;946.node2.supernodexp.hpc;Job Modified at request of Scheduler@node2.supernodexp.hpc
02/13/2018 17:59:37;0080;Server@node2;Job;943.node2.supernodexp.hpc;Obit received momhop:1 serverhop:1 state:4 substate:42
02/13/2018 17:59:38;0010;Server@node2;Job;943.node2.supernodexp.hpc;Exit_status=0 resources_used.cpupercent=800 resources_used.cput=00:00:08 resources_used.mem=0kb resources_used.ncpus=8 resources_used.vmem=0kb resources_used.walltime=00:00:02
02/13/2018 17:59:38;0100;Server@node2;Job;943.node2.supernodexp.hpc;dequeuing from workq, state 5
02/13/2018 17:59:38;0040;Server@node2;Svr;node2.supernodexp.hpc;Scheduler sent command 2
02/13/2018 17:59:38;0040;Server@node2;Svr;node2.supernodexp.hpc;Scheduler sent command 0
02/13/2018 17:59:38;0100;Server@node2;Req;;Type 21 request received from Scheduler@node2.supernodexp.hpc, sock=20
02/13/2018 17:59:38;0100;Server@node2;Req;;Type 81 request received from Scheduler@node2.supernodexp.hpc, sock=20
02/13/2018 17:59:38;0100;Server@node2;Req;;Type 71 request received from Scheduler@node2.supernodexp.hpc, sock=20
02/13/2018 17:59:38;0100;Server@node2;Req;;Type 58 request received from Scheduler@node2.supernodexp.hpc, sock=20
02/13/2018 17:59:38;0100;Server@node2;Req;;Type 20 request received from Scheduler@node2.supernodexp.hpc, sock=20
02/13/2018 17:59:38;0100;Server@node2;Req;;Type 51 request received from Scheduler@node2.supernodexp.hpc, sock=20
02/13/2018 17:59:38;0100;Server@node2;Req;;Type 23 request received from Scheduler@node2.supernodexp.hpc, sock=20
02/13/2018 17:59:38;0008;Server@node2;Job;946.node2.supernodexp.hpc;Job Run at request of Scheduler@node2.supernodexp.hpc on exec_vnode (node13:ncpus=12:mem=1048576kb)
02/13/2018 17:59:38;0001;Server@node2;Svr;Server@node2;Success (0) in req_runjob2, return value of svr_startjob is 0
02/13/2018 17:59:38;0100;Server@node2;Req;;Type 11 request received from Scheduler@node2.supernodexp.hpc, sock=20
02/13/2018 17:59:38;0008;Server@node2;Job;950.node2.supernodexp.hpc;Job Modified at request of Scheduler@node2.supernodexp.hpc
02/13/2018 17:59:40;0080;Server@node2;Job;942.node2.supernodexp.hpc;Obit received momhop:1 serverhop:1 state:4 substate:42
02/13/2018 17:59:41;0010;Server@node2;Job;942.node2.supernodexp.hpc;Exit_status=0 resources_used.cpupercent=100 resources_used.cput=00:00:04 resources_used.mem=537260kb resources_used.ncpus=32 resources_used.vmem=867312kb resources_used.walltime=00:00:04
02/13/2018 17:59:41;0100;Server@node2;Job;942.node2.supernodexp.hpc;dequeuing from workq, state 5
02/13/2018 17:59:41;0040;Server@node2;Svr;node2.supernodexp.hpc;Scheduler sent command 2
02/13/2018 17:59:41;0040;Server@node2;Svr;node2.supernodexp.hpc;Scheduler sent command 0
02/13/2018 17:59:41;0100;Server@node2;Req;;Type 21 request received from Scheduler@node2.supernodexp.hpc, sock=20
02/13/2018 17:59:41;0100;Server@node2;Req;;Type 81 request received from Scheduler@node2.supernodexp.hpc, sock=20
02/13/2018 17:59:41;0100;Server@node2;Req;;Type 71 request received from Scheduler@node2.supernodexp.hpc, sock=20
02/13/2018 17:59:41;0100;Server@node2;Req;;Type 58 request received from Scheduler@node2.supernodexp.hpc, sock=20
02/13/2018 17:59:41;0100;Server@node2;Req;;Type 20 request received from Scheduler@node2.supernodexp.hpc, sock=20
02/13/2018 17:59:41;0100;Server@node2;Req;;Type 51 request received from Scheduler@node2.supernodexp.hpc, sock=20
02/13/2018 17:59:41;0100;Server@node2;Req;;Type 23 request received from Scheduler@node2.supernodexp.hpc, sock=20
02/13/2018 17:59:41;0008;Server@node2;Job;950.node2.supernodexp.hpc;Job Run at request of Scheduler@node2.supernodexp.hpc on exec_vnode (node13:ncpus=8:mem=3145728kb)
02/13/2018 17:59:41;0001;Server@node2;Svr;Server@node2;Success (0) in req_runjob2, return value of svr_startjob is 0
02/13/2018 17:59:41;0100;Server@node2;Req;;Type 23 request received from Scheduler@node2.supernodexp.hpc, sock=20
02/13/2018 17:59:41;0008;Server@node2;Job;851.node2.supernodexp.hpc;Job Run at request of Scheduler@node2.supernodexp.hpc on exec_vnode (node13:ncpus=12:mem=1048576kb)
02/13/2018 17:59:41;0001;Server@node2;Svr;Server@node2;Success (0) in req_runjob2, return value of svr_startjob is 0
02/13/2018 17:59:41;0100;Server@node2;Req;;Type 23 request received from Scheduler@node2.supernodexp.hpc, sock=20
02/13/2018 17:59:41;0008;Server@node2;Job;861.node2.supernodexp.hpc;Job Run at request of Scheduler@node2.supernodexp.hpc on exec_vnode (node13:ncpus=12:mem=1048576kb)
02/13/2018 17:59:41;0001;Server@node2;Svr;Server@node2;Success (0) in req_runjob2, return value of svr_startjob is 0
02/13/2018 17:59:41;0100;Server@node2;Req;;Type 11 request received from Scheduler@node2.supernodexp.hpc, sock=20
02/13/2018 17:59:41;0008;Server@node2;Job;878.node2.supernodexp.hpc;Job Modified at request of Scheduler@node2.supernodexp.hpc
02/13/2018 17:59:43;0080;Server@node2;Job;950.node2.supernodexp.hpc;Obit received momhop:1 serverhop:1 state:4 substate:42
02/13/2018 17:59:44;0010;Server@node2;Job;950.node2.supernodexp.hpc;Exit_status=0 resources_used.cpupercent=800 resources_used.cput=00:00:09 resources_used.mem=0kb resources_used.ncpus=8 resources_used.vmem=0kb resources_used.walltime=00:00:01
02/13/2018 17:59:44;0100;Server@node2;Job;950.node2.supernodexp.hpc;dequeuing from workq, state 5
02/13/2018 17:59:44;0040;Server@node2;Svr;node2.supernodexp.hpc;Scheduler sent command 2
02/13/2018 17:59:44;0040;Server@node2;Svr;node2.supernodexp.hpc;Scheduler sent command 0
02/13/2018 17:59:44;0100;Server@node2;Req;;Type 21 request received from Scheduler@node2.supernodexp.hpc, sock=20
02/13/2018 17:59:44;0100;Server@node2;Req;;Type 81 request received from Scheduler@node2.supernodexp.hpc, sock=20
02/13/2018 17:59:44;0100;Server@node2;Req;;Type 71 request received from Scheduler@node2.supernodexp.hpc, sock=20
02/13/2018 17:59:44;0100;Server@node2;Req;;Type 58 request received from Scheduler@node2.supernodexp.hpc, sock=20
02/13/2018 17:59:44;0100;Server@node2;Req;;Type 20 request received from Scheduler@node2.supernodexp.hpc, sock=20
02/13/2018 17:59:44;0100;Server@node2;Req;;Type 51 request received from Scheduler@node2.supernodexp.hpc, sock=20
02/13/2018 17:59:44;0100;Server@node2;Req;;Type 23 request received from Scheduler@node2.supernodexp.hpc, sock=20
02/13/2018 17:59:44;0008;Server@node2;Job;878.node2.supernodexp.hpc;Job Run at request of Scheduler@node2.supernodexp.hpc on exec_vnode (node13:ncpus=12:mem=1048576kb)
02/13/2018 17:59:44;0001;Server@node2;Svr;Server@node2;Success (0) in req_runjob2, return value of svr_startjob is 0
02/13/2018 17:59:44;0100;Server@node2;Req;;Type 11 request received from Scheduler@node2.supernodexp.hpc, sock=20
02/13/2018 17:59:44;0008;Server@node2;Job;887.node2.supernodexp.hpc;Job Modified at request of Scheduler@node2.supernodexp.hpc
02/13/2018 17:59:44;0080;Server@node2;Job;946.node2.supernodexp.hpc;Obit received momhop:1 serverhop:1 state:4 substate:42
02/13/2018 17:59:46;0010;Server@node2;Job;946.node2.supernodexp.hpc;Exit_status=0 resources_used.cpupercent=1201 resources_used.cput=00:01:12 resources_used.mem=39992kb resources_used.ncpus=12 resources_used.vmem=1125532kb resources_used.walltime=00:00:06
02/13/2018 17:59:46;0100;Server@node2;Job;946.node2.supernodexp.hpc;dequeuing from workq, state 5
02/13/2018 17:59:46;0040;Server@node2;Svr;node2.supernodexp.hpc;Scheduler sent command 2
02/13/2018 17:59:46;0040;Server@node2;Svr;node2.supernodexp.hpc;Scheduler sent command 0
02/13/2018 17:59:46;0100;Server@node2;Req;;Type 21 request received from Scheduler@node2.supernodexp.hpc, sock=20
02/13/2018 17:59:46;0100;Server@node2;Req;;Type 81 request received from Scheduler@node2.supernodexp.hpc, sock=20
02/13/2018 17:59:46;0100;Server@node2;Req;;Type 71 request received from Scheduler@node2.supernodexp.hpc, sock=20
02/13/2018 17:59:46;0100;Server@node2;Req;;Type 58 request received from Scheduler@node2.supernodexp.hpc, sock=20
02/13/2018 17:59:46;0100;Server@node2;Req;;Type 20 request received from Scheduler@node2.supernodexp.hpc, sock=20
02/13/2018 17:59:46;0100;Server@node2;Req;;Type 51 request received from Scheduler@node2.supernodexp.hpc, sock=20
02/13/2018 17:59:46;0100;Server@node2;Req;;Type 23 request received from Scheduler@node2.supernodexp.hpc, sock=20
02/13/2018 17:59:46;0008;Server@node2;Job;887.node2.supernodexp.hpc;Job Run at request of Scheduler@node2.supernodexp.hpc on exec_vnode (node13:ncpus=12:mem=1048576kb)
02/13/2018 17:59:46;0001;Server@node2;Svr;Server@node2;Success (0) in req_runjob2, return value of svr_startjob is 0
02/13/2018 17:59:46;0100;Server@node2;Req;;Type 11 request received from Scheduler@node2.supernodexp.hpc, sock=20
02/13/2018 17:59:46;0008;Server@node2;Job;901.node2.supernodexp.hpc;Job Modified at request of Scheduler@node2.supernodexp.hpc
02/13/2018 17:59:50;0080;Server@node2;Job;851.node2.supernodexp.hpc;Obit received momhop:1 serverhop:1 state:4 substate:42
02/13/2018 17:59:50;0080;Server@node2;Job;861.node2.supernodexp.hpc;Obit received momhop:1 serverhop:1 state:4 substate:42
02/13/2018 17:59:51;0010;Server@node2;Job;851.node2.supernodexp.hpc;Exit_status=0 resources_used.cpupercent=100 resources_used.cput=00:00:08 resources_used.mem=11620kb resources_used.ncpus=12 resources_used.vmem=343400kb resources_used.walltime=00:00:08
02/13/2018 17:59:51;0100;Server@node2;Job;851.node2.supernodexp.hpc;dequeuing from workq, state 5
02/13/2018 17:59:51;0010;Server@node2;Job;861.node2.supernodexp.hpc;Exit_status=0 resources_used.cpupercent=100 resources_used.cput=00:00:08 resources_used.mem=11624kb resources_used.ncpus=12 resources_used.vmem=343400kb resources_used.walltime=00:00:08
02/13/2018 17:59:51;0100;Server@node2;Job;861.node2.supernodexp.hpc;dequeuing from workq, state 5
02/13/2018 17:59:51;0040;Server@node2;Svr;node2.supernodexp.hpc;Scheduler sent command 2
02/13/2018 17:59:51;0040;Server@node2;Svr;node2.supernodexp.hpc;Scheduler sent command 0
02/13/2018 17:59:51;0100;Server@node2;Req;;Type 21 request received from Scheduler@node2.supernodexp.hpc, sock=20
02/13/2018 17:59:51;0100;Server@node2;Req;;Type 81 request received from Scheduler@node2.supernodexp.hpc, sock=20
02/13/2018 17:59:51;0100;Server@node2;Req;;Type 71 request received from Scheduler@node2.supernodexp.hpc, sock=20
02/13/2018 17:59:51;0100;Server@node2;Req;;Type 58 request received from Scheduler@node2.supernodexp.hpc, sock=20
02/13/2018 17:59:51;0100;Server@node2;Req;;Type 20 request received from Scheduler@node2.supernodexp.hpc, sock=20
02/13/2018 17:59:51;0100;Server@node2;Req;;Type 51 request received from Scheduler@node2.supernodexp.hpc, sock=20
02/13/2018 17:59:51;0100;Server@node2;Req;;Type 23 request received from Scheduler@node2.supernodexp.hpc, sock=20
02/13/2018 17:59:51;0008;Server@node2;Job;901.node2.supernodexp.hpc;Job Run at request of Scheduler@node2.supernodexp.hpc on exec_vnode (node13:ncpus=12:mem=1048576kb)
02/13/2018 17:59:51;0001;Server@node2;Svr;Server@node2;Success (0) in req_runjob2, return value of svr_startjob is 0
02/13/2018 17:59:51;0100;Server@node2;Req;;Type 23 request received from Scheduler@node2.supernodexp.hpc, sock=20
02/13/2018 17:59:51;0008;Server@node2;Job;907.node2.supernodexp.hpc;Job Run at request of Scheduler@node2.supernodexp.hpc on exec_vnode (node13:ncpus=12:mem=1048576kb)
02/13/2018 17:59:51;0001;Server@node2;Svr;Server@node2;Success (0) in req_runjob2, return value of svr_startjob is 0
02/13/2018 17:59:51;0100;Server@node2;Req;;Type 11 request received from Scheduler@node2.supernodexp.hpc, sock=20
02/13/2018 17:59:51;0008;Server@node2;Job;920.node2.supernodexp.hpc;Job Modified at request of Scheduler@node2.supernodexp.hpc
02/13/2018 17:59:52;0080;Server@node2;Job;878.node2.supernodexp.hpc;Obit received momhop:1 serverhop:1 state:4 substate:42
02/13/2018 17:59:53;0010;Server@node2;Job;878.node2.supernodexp.hpc;Exit_status=0 resources_used.cpupercent=100 resources_used.cput=00:00:08 resources_used.mem=11620kb resources_used.ncpus=12 resources_used.vmem=343400kb resources_used.walltime=00:00:09
02/13/2018 17:59:53;0100;Server@node2;Job;878.node2.supernodexp.hpc;dequeuing from workq, state 5
02/13/2018 17:59:53;0040;Server@node2;Svr;node2.supernodexp.hpc;Scheduler sent command 2
02/13/2018 17:59:53;0040;Server@node2;Svr;node2.supernodexp.hpc;Scheduler sent command 0
02/13/2018 17:59:53;0100;Server@node2;Req;;Type 21 request received from Scheduler@node2.supernodexp.hpc, sock=20
02/13/2018 17:59:53;0100;Server@node2;Req;;Type 81 request received from Scheduler@node2.supernodexp.hpc, sock=20
02/13/2018 17:59:53;0100;Server@node2;Req;;Type 71 request received from Scheduler@node2.supernodexp.hpc, sock=20
02/13/2018 17:59:53;0100;Server@node2;Req;;Type 58 request received from Scheduler@node2.supernodexp.hpc, sock=20
02/13/2018 17:59:53;0100;Server@node2;Req;;Type 20 request received from Scheduler@node2.supernodexp.hpc, sock=20
02/13/2018 17:59:53;0100;Server@node2;Req;;Type 51 request received from Scheduler@node2.supernodexp.hpc, sock=20
02/13/2018 17:59:53;0100;Server@node2;Req;;Type 23 request received from Scheduler@node2.supernodexp.hpc, sock=20
02/13/2018 17:59:53;0008;Server@node2;Job;920.node2.supernodexp.hpc;Job Run at request of Scheduler@node2.supernodexp.hpc on exec_vnode (node13:ncpus=12:mem=1048576kb)
02/13/2018 17:59:53;0001;Server@node2;Svr;Server@node2;Success (0) in req_runjob2, return value of svr_startjob is 0
02/13/2018 17:59:53;0100;Server@node2;Req;;Type 11 request received from Scheduler@node2.supernodexp.hpc, sock=20
02/13/2018 17:59:53;0008;Server@node2;Job;922.node2.supernodexp.hpc;Job Modified at request of Scheduler@node2.supernodexp.hpc
02/13/2018 17:59:54;0080;Server@node2;Job;887.node2.supernodexp.hpc;Obit received momhop:1 serverhop:1 state:4 substate:42
02/13/2018 17:59:55;0010;Server@node2;Job;887.node2.supernodexp.hpc;Exit_status=0 resources_used.cpupercent=100 resources_used.cput=00:00:08 resources_used.mem=11624kb resources_used.ncpus=12 resources_used.vmem=343400kb resources_used.walltime=00:00:08
02/13/2018 17:59:55;0100;Server@node2;Job;887.node2.supernodexp.hpc;dequeuing from workq, state 5
02/13/2018 17:59:55;0040;Server@node2;Svr;node2.supernodexp.hpc;Scheduler sent command 2
02/13/2018 17:59:55;0040;Server@node2;Svr;node2.supernodexp.hpc;Scheduler sent command 0
02/13/2018 17:59:55;0100;Server@node2;Req;;Type 21 request received from Scheduler@node2.supernodexp.hpc, sock=20
02/13/2018 17:59:55;0100;Server@node2;Req;;Type 81 request received from Scheduler@node2.supernodexp.hpc, sock=20
02/13/2018 17:59:55;0100;Server@node2;Req;;Type 71 request received from Scheduler@node2.supernodexp.hpc, sock=20
02/13/2018 17:59:55;0100;Server@node2;Req;;Type 58 request received from Scheduler@node2.supernodexp.hpc, sock=20
02/13/2018 17:59:55;0100;Server@node2;Req;;Type 20 request received from Scheduler@node2.supernodexp.hpc, sock=20
02/13/2018 17:59:55;0100;Server@node2;Req;;Type 51 request received from Scheduler@node2.supernodexp.hpc, sock=20
02/13/2018 17:59:55;0100;Server@node2;Req;;Type 23 request received from Scheduler@node2.supernodexp.hpc, sock=20
02/13/2018 17:59:55;0008;Server@node2;Job;922.node2.supernodexp.hpc;Job Run at request of Scheduler@node2.supernodexp.hpc on exec_vnode (node13:ncpus=12:mem=1048576kb)
02/13/2018 17:59:55;0001;Server@node2;Svr;Server@node2;Success (0) in req_runjob2, return value of svr_startjob is 0
02/13/2018 17:59:55;0100;Server@node2;Req;;Type 11 request received from Scheduler@node2.supernodexp.hpc, sock=20
02/13/2018 17:59:55;0008;Server@node2;Job;936.node2.supernodexp.hpc;Job Modified at request of Scheduler@node2.supernodexp.hpc
02/13/2018 17:59:59;0100;Server@node2;Req;;Type 1 request received from ctminh@node2.supernodexp.hpc, sock=16
02/13/2018 17:59:59;0100;Server@node2;Req;;Type 3 request received from ctminh@node2.supernodexp.hpc, sock=16
02/13/2018 17:59:59;0100;Server@node2;Req;;Type 5 request received from ctminh@node2.supernodexp.hpc, sock=16
02/13/2018 17:59:59;0100;Server@node2;Job;951.node2.supernodexp.hpc;enqueuing into workq, state 1 hop 1
02/13/2018 17:59:59;0008;Server@node2;Job;951.node2.supernodexp.hpc;Job Queued at request of ctminh@node2.supernodexp.hpc, owner = ctminh@node2.supernodexp.hpc, job name = histogram, queue = workq
02/13/2018 17:59:59;0040;Server@node2;Svr;node2.supernodexp.hpc;Scheduler sent command 1
02/13/2018 17:59:59;0040;Server@node2;Svr;node2.supernodexp.hpc;Scheduler sent command 0
02/13/2018 17:59:59;0100;Server@node2;Req;;Type 21 request received from Scheduler@node2.supernodexp.hpc, sock=20
02/13/2018 17:59:59;0100;Server@node2;Req;;Type 81 request received from Scheduler@node2.supernodexp.hpc, sock=20
02/13/2018 17:59:59;0100;Server@node2;Req;;Type 71 request received from Scheduler@node2.supernodexp.hpc, sock=20
02/13/2018 17:59:59;0100;Server@node2;Req;;Type 58 request received from Scheduler@node2.supernodexp.hpc, sock=20
02/13/2018 17:59:59;0100;Server@node2;Req;;Type 1 request received from ctminh@node2.supernodexp.hpc, sock=16
02/13/2018 17:59:59;0100;Server@node2;Req;;Type 3 request received from ctminh@node2.supernodexp.hpc, sock=16
02/13/2018 17:59:59;0100;Server@node2;Req;;Type 5 request received from ctminh@node2.supernodexp.hpc, sock=16
02/13/2018 17:59:59;0100;Server@node2;Job;952.node2.supernodexp.hpc;enqueuing into workq, state 1 hop 1
02/13/2018 17:59:59;0008;Server@node2;Job;952.node2.supernodexp.hpc;Job Queued at request of ctminh@node2.supernodexp.hpc, owner = ctminh@node2.supernodexp.hpc, job name = thread-affinity, queue = workq
02/13/2018 17:59:59;0100;Server@node2;Req;;Type 1 request received from ctminh@node2.supernodexp.hpc, sock=16
02/13/2018 17:59:59;0100;Server@node2;Req;;Type 20 request received from Scheduler@node2.supernodexp.hpc, sock=20
02/13/2018 17:59:59;0100;Server@node2;Req;;Type 3 request received from ctminh@node2.supernodexp.hpc, sock=16
02/13/2018 17:59:59;0100;Server@node2;Req;;Type 51 request received from Scheduler@node2.supernodexp.hpc, sock=20
02/13/2018 17:59:59;0100;Server@node2;Req;;Type 5 request received from ctminh@node2.supernodexp.hpc, sock=16
02/13/2018 17:59:59;0100;Server@node2;Job;953.node2.supernodexp.hpc;enqueuing into workq, state 1 hop 1
02/13/2018 17:59:59;0008;Server@node2;Job;953.node2.supernodexp.hpc;Job Queued at request of ctminh@node2.supernodexp.hpc, owner = ctminh@node2.supernodexp.hpc, job name = matrix-x-vector, queue = workq
02/13/2018 17:59:59;0100;Server@node2;Req;;Type 1 request received from ctminh@node2.supernodexp.hpc, sock=16
02/13/2018 17:59:59;0100;Server@node2;Req;;Type 3 request received from ctminh@node2.supernodexp.hpc, sock=16
02/13/2018 17:59:59;0100;Server@node2;Req;;Type 5 request received from ctminh@node2.supernodexp.hpc, sock=16
02/13/2018 17:59:59;0100;Server@node2;Job;954.node2.supernodexp.hpc;enqueuing into workq, state 1 hop 1
02/13/2018 17:59:59;0008;Server@node2;Job;954.node2.supernodexp.hpc;Job Queued at request of ctminh@node2.supernodexp.hpc, owner = ctminh@node2.supernodexp.hpc, job name = jacobi, queue = workq
02/13/2018 17:59:59;0100;Server@node2;Req;;Type 1 request received from ctminh@node2.supernodexp.hpc, sock=16
02/13/2018 17:59:59;0100;Server@node2;Req;;Type 3 request received from ctminh@node2.supernodexp.hpc, sock=16
02/13/2018 17:59:59;0100;Server@node2;Req;;Type 5 request received from ctminh@node2.supernodexp.hpc, sock=16
02/13/2018 17:59:59;0100;Server@node2;Job;955.node2.supernodexp.hpc;enqueuing into workq, state 1 hop 1
02/13/2018 17:59:59;0008;Server@node2;Job;955.node2.supernodexp.hpc;Job Queued at request of ctminh@node2.supernodexp.hpc, owner = ctminh@node2.supernodexp.hpc, job name = telemac2, queue = workq
02/13/2018 17:59:59;0100;Server@node2;Req;;Type 11 request received from Scheduler@node2.supernodexp.hpc, sock=20
02/13/2018 17:59:59;0008;Server@node2;Job;936.node2.supernodexp.hpc;Job Modified at request of Scheduler@node2.supernodexp.hpc
02/13/2018 17:59:59;0100;Server@node2;Req;;Type 11 request received from Scheduler@node2.supernodexp.hpc, sock=20
02/13/2018 17:59:59;0008;Server@node2;Job;952.node2.supernodexp.hpc;Job Modified at request of Scheduler@node2.supernodexp.hpc
02/13/2018 17:59:59;0100;Server@node2;Req;;Type 11 request received from Scheduler@node2.supernodexp.hpc, sock=20
02/13/2018 17:59:59;0008;Server@node2;Job;951.node2.supernodexp.hpc;Job Modified at request of Scheduler@node2.supernodexp.hpc
02/13/2018 17:59:59;0040;Server@node2;Svr;node2.supernodexp.hpc;Scheduler sent command 1
02/13/2018 17:59:59;0040;Server@node2;Svr;node2.supernodexp.hpc;Scheduler sent command 0
02/13/2018 17:59:59;0100;Server@node2;Req;;Type 21 request received from Scheduler@node2.supernodexp.hpc, sock=20
02/13/2018 17:59:59;0100;Server@node2;Req;;Type 81 request received from Scheduler@node2.supernodexp.hpc, sock=20
02/13/2018 17:59:59;0100;Server@node2;Req;;Type 71 request received from Scheduler@node2.supernodexp.hpc, sock=20
02/13/2018 17:59:59;0100;Server@node2;Req;;Type 58 request received from Scheduler@node2.supernodexp.hpc, sock=20
02/13/2018 17:59:59;0100;Server@node2;Req;;Type 1 request received from ctminh@node2.supernodexp.hpc, sock=16
02/13/2018 17:59:59;0100;Server@node2;Req;;Type 3 request received from ctminh@node2.supernodexp.hpc, sock=16
02/13/2018 17:59:59;0100;Server@node2;Req;;Type 5 request received from ctminh@node2.supernodexp.hpc, sock=16
02/13/2018 17:59:59;0100;Server@node2;Job;956.node2.supernodexp.hpc;enqueuing into workq, state 1 hop 1
02/13/2018 17:59:59;0008;Server@node2;Job;956.node2.supernodexp.hpc;Job Queued at request of ctminh@node2.supernodexp.hpc, owner = ctminh@node2.supernodexp.hpc, job name = qe_mic_test, queue = workq
02/13/2018 17:59:59;0100;Server@node2;Req;;Type 1 request received from ctminh@node2.supernodexp.hpc, sock=16
02/13/2018 17:59:59;0100;Server@node2;Req;;Type 3 request received from ctminh@node2.supernodexp.hpc, sock=16
02/13/2018 17:59:59;0100;Server@node2;Req;;Type 5 request received from ctminh@node2.supernodexp.hpc, sock=16
02/13/2018 17:59:59;0100;Server@node2;Job;957.node2.supernodexp.hpc;enqueuing into workq, state 1 hop 1
02/13/2018 17:59:59;0008;Server@node2;Job;957.node2.supernodexp.hpc;Job Queued at request of ctminh@node2.supernodexp.hpc, owner = ctminh@node2.supernodexp.hpc, job name = nbody, queue = workq
02/13/2018 17:59:59;0100;Server@node2;Req;;Type 20 request received from Scheduler@node2.supernodexp.hpc, sock=20
02/13/2018 17:59:59;0100;Server@node2;Req;;Type 51 request received from Scheduler@node2.supernodexp.hpc, sock=20
02/13/2018 17:59:59;0100;Server@node2;Req;;Type 1 request received from ctminh@node2.supernodexp.hpc, sock=16
02/13/2018 17:59:59;0100;Server@node2;Req;;Type 3 request received from ctminh@node2.supernodexp.hpc, sock=16
02/13/2018 17:59:59;0100;Server@node2;Req;;Type 5 request received from ctminh@node2.supernodexp.hpc, sock=16
02/13/2018 17:59:59;0100;Server@node2;Job;958.node2.supernodexp.hpc;enqueuing into workq, state 1 hop 1
02/13/2018 17:59:59;0008;Server@node2;Job;958.node2.supernodexp.hpc;Job Queued at request of ctminh@node2.supernodexp.hpc, owner = ctminh@node2.supernodexp.hpc, job name = telemac1, queue = workq
02/13/2018 17:59:59;0100;Server@node2;Req;;Type 1 request received from ctminh@node2.supernodexp.hpc, sock=16
02/13/2018 17:59:59;0100;Server@node2;Req;;Type 3 request received from ctminh@node2.supernodexp.hpc, sock=16
02/13/2018 17:59:59;0100;Server@node2;Req;;Type 5 request received from ctminh@node2.supernodexp.hpc, sock=16
02/13/2018 17:59:59;0100;Server@node2;Job;959.node2.supernodexp.hpc;enqueuing into workq, state 1 hop 1
02/13/2018 17:59:59;0008;Server@node2;Job;959.node2.supernodexp.hpc;Job Queued at request of ctminh@node2.supernodexp.hpc, owner = ctminh@node2.supernodexp.hpc, job name = jacobi, queue = workq
02/13/2018 17:59:59;0100;Server@node2;Req;;Type 11 request received from Scheduler@node2.supernodexp.hpc, sock=20
02/13/2018 17:59:59;0008;Server@node2;Job;951.node2.supernodexp.hpc;Job Modified at request of Scheduler@node2.supernodexp.hpc
02/13/2018 17:59:59;0100;Server@node2;Req;;Type 1 request received from ctminh@node2.supernodexp.hpc, sock=16
02/13/2018 17:59:59;0100;Server@node2;Req;;Type 11 request received from Scheduler@node2.supernodexp.hpc, sock=20
02/13/2018 17:59:59;0008;Server@node2;Job;957.node2.supernodexp.hpc;Job Modified at request of Scheduler@node2.supernodexp.hpc
02/13/2018 17:59:59;0100;Server@node2;Req;;Type 3 request received from ctminh@node2.supernodexp.hpc, sock=16
02/13/2018 17:59:59;0100;Server@node2;Req;;Type 5 request received from ctminh@node2.supernodexp.hpc, sock=16
02/13/2018 17:59:59;0100;Server@node2;Job;960.node2.supernodexp.hpc;enqueuing into workq, state 1 hop 1
02/13/2018 17:59:59;0008;Server@node2;Job;960.node2.supernodexp.hpc;Job Queued at request of ctminh@node2.supernodexp.hpc, owner = ctminh@node2.supernodexp.hpc, job name = vast1, queue = workq
02/13/2018 17:59:59;0100;Server@node2;Req;;Type 11 request received from Scheduler@node2.supernodexp.hpc, sock=20
02/13/2018 17:59:59;0008;Server@node2;Job;954.node2.supernodexp.hpc;Job Modified at request of Scheduler@node2.supernodexp.hpc
02/13/2018 17:59:59;0100;Server@node2;Req;;Type 11 request received from Scheduler@node2.supernodexp.hpc, sock=20
02/13/2018 17:59:59;0008;Server@node2;Job;955.node2.supernodexp.hpc;Job Modified at request of Scheduler@node2.supernodexp.hpc
02/13/2018 17:59:59;0100;Server@node2;Req;;Type 11 request received from Scheduler@node2.supernodexp.hpc, sock=20
02/13/2018 17:59:59;0008;Server@node2;Job;956.node2.supernodexp.hpc;Job Modified at request of Scheduler@node2.supernodexp.hpc
02/13/2018 17:59:59;0100;Server@node2;Req;;Type 11 request received from Scheduler@node2.supernodexp.hpc, sock=20
02/13/2018 17:59:59;0008;Server@node2;Job;953.node2.supernodexp.hpc;Job Modified at request of Scheduler@node2.supernodexp.hpc
02/13/2018 17:59:59;0040;Server@node2;Svr;node2.supernodexp.hpc;Scheduler sent command 1
02/13/2018 17:59:59;0040;Server@node2;Svr;node2.supernodexp.hpc;Scheduler sent command 0
02/13/2018 17:59:59;0100;Server@node2;Req;;Type 21 request received from Scheduler@node2.supernodexp.hpc, sock=20
02/13/2018 17:59:59;0100;Server@node2;Req;;Type 81 request received from Scheduler@node2.supernodexp.hpc, sock=20
02/13/2018 17:59:59;0100;Server@node2;Req;;Type 71 request received from Scheduler@node2.supernodexp.hpc, sock=20
02/13/2018 17:59:59;0100;Server@node2;Req;;Type 58 request received from Scheduler@node2.supernodexp.hpc, sock=20
02/13/2018 17:59:59;0100;Server@node2;Req;;Type 1 request received from ctminh@node2.supernodexp.hpc, sock=16
02/13/2018 17:59:59;0100;Server@node2;Req;;Type 3 request received from ctminh@node2.supernodexp.hpc, sock=16
02/13/2018 17:59:59;0100;Server@node2;Req;;Type 5 request received from ctminh@node2.supernodexp.hpc, sock=16
02/13/2018 17:59:59;0100;Server@node2;Job;961.node2.supernodexp.hpc;enqueuing into workq, state 1 hop 1
02/13/2018 17:59:59;0008;Server@node2;Job;961.node2.supernodexp.hpc;Job Queued at request of ctminh@node2.supernodexp.hpc, owner = ctminh@node2.supernodexp.hpc, job name = vectorization, queue = workq
02/13/2018 17:59:59;0100;Server@node2;Req;;Type 1 request received from ctminh@node2.supernodexp.hpc, sock=16
02/13/2018 17:59:59;0100;Server@node2;Req;;Type 20 request received from Scheduler@node2.supernodexp.hpc, sock=20
02/13/2018 17:59:59;0100;Server@node2;Req;;Type 3 request received from ctminh@node2.supernodexp.hpc, sock=16
02/13/2018 17:59:59;0100;Server@node2;Req;;Type 51 request received from Scheduler@node2.supernodexp.hpc, sock=20
02/13/2018 17:59:59;0100;Server@node2;Req;;Type 5 request received from ctminh@node2.supernodexp.hpc, sock=16
02/13/2018 17:59:59;0100;Server@node2;Job;962.node2.supernodexp.hpc;enqueuing into workq, state 1 hop 1
02/13/2018 17:59:59;0008;Server@node2;Job;962.node2.supernodexp.hpc;Job Queued at request of ctminh@node2.supernodexp.hpc, owner = ctminh@node2.supernodexp.hpc, job name = lu-decomp, queue = workq
02/13/2018 17:59:59;0100;Server@node2;Req;;Type 1 request received from ctminh@node2.supernodexp.hpc, sock=16
02/13/2018 17:59:59;0100;Server@node2;Req;;Type 3 request received from ctminh@node2.supernodexp.hpc, sock=16
02/13/2018 17:59:59;0100;Server@node2;Req;;Type 5 request received from ctminh@node2.supernodexp.hpc, sock=16
02/13/2018 17:59:59;0100;Server@node2;Job;963.node2.supernodexp.hpc;enqueuing into workq, state 1 hop 1
02/13/2018 17:59:59;0008;Server@node2;Job;963.node2.supernodexp.hpc;Job Queued at request of ctminh@node2.supernodexp.hpc, owner = ctminh@node2.supernodexp.hpc, job name = telemac2, queue = workq
02/13/2018 17:59:59;0100;Server@node2;Req;;Type 1 request received from ctminh@node2.supernodexp.hpc, sock=16
02/13/2018 17:59:59;0100;Server@node2;Req;;Type 3 request received from ctminh@node2.supernodexp.hpc, sock=16
02/13/2018 17:59:59;0100;Server@node2;Req;;Type 5 request received from ctminh@node2.supernodexp.hpc, sock=16
02/13/2018 17:59:59;0100;Server@node2;Job;964.node2.supernodexp.hpc;enqueuing into workq, state 1 hop 1
02/13/2018 17:59:59;0008;Server@node2;Job;964.node2.supernodexp.hpc;Job Queued at request of ctminh@node2.supernodexp.hpc, owner = ctminh@node2.supernodexp.hpc, job name = vast1, queue = workq
02/13/2018 17:59:59;0100;Server@node2;Req;;Type 11 request received from Scheduler@node2.supernodexp.hpc, sock=20
02/13/2018 17:59:59;0008;Server@node2;Job;961.node2.supernodexp.hpc;Job Modified at request of Scheduler@node2.supernodexp.hpc
02/13/2018 17:59:59;0100;Server@node2;Req;;Type 11 request received from Scheduler@node2.supernodexp.hpc, sock=20
02/13/2018 17:59:59;0008;Server@node2;Job;959.node2.supernodexp.hpc;Job Modified at request of Scheduler@node2.supernodexp.hpc
02/13/2018 17:59:59;0100;Server@node2;Req;;Type 11 request received from Scheduler@node2.supernodexp.hpc, sock=20
02/13/2018 17:59:59;0008;Server@node2;Job;958.node2.supernodexp.hpc;Job Modified at request of Scheduler@node2.supernodexp.hpc
02/13/2018 17:59:59;0100;Server@node2;Req;;Type 11 request received from Scheduler@node2.supernodexp.hpc, sock=20
02/13/2018 17:59:59;0008;Server@node2;Job;960.node2.supernodexp.hpc;Job Modified at request of Scheduler@node2.supernodexp.hpc
02/13/2018 17:59:59;0040;Server@node2;Svr;node2.supernodexp.hpc;Scheduler sent command 1
02/13/2018 17:59:59;0040;Server@node2;Svr;node2.supernodexp.hpc;Scheduler sent command 0
02/13/2018 17:59:59;0100;Server@node2;Req;;Type 21 request received from Scheduler@node2.supernodexp.hpc, sock=20
02/13/2018 17:59:59;0100;Server@node2;Req;;Type 81 request received from Scheduler@node2.supernodexp.hpc, sock=20
02/13/2018 17:59:59;0100;Server@node2;Req;;Type 71 request received from Scheduler@node2.supernodexp.hpc, sock=20
02/13/2018 17:59:59;0100;Server@node2;Req;;Type 58 request received from Scheduler@node2.supernodexp.hpc, sock=20
02/13/2018 17:59:59;0100;Server@node2;Req;;Type 1 request received from ctminh@node2.supernodexp.hpc, sock=16
02/13/2018 17:59:59;0100;Server@node2;Req;;Type 3 request received from ctminh@node2.supernodexp.hpc, sock=16
02/13/2018 17:59:59;0100;Server@node2;Req;;Type 5 request received from ctminh@node2.supernodexp.hpc, sock=16
02/13/2018 17:59:59;0100;Server@node2;Job;965.node2.supernodexp.hpc;enqueuing into workq, state 1 hop 1
02/13/2018 17:59:59;0008;Server@node2;Job;965.node2.supernodexp.hpc;Job Queued at request of ctminh@node2.supernodexp.hpc, owner = ctminh@node2.supernodexp.hpc, job name = sweep, queue = workq
02/13/2018 17:59:59;0100;Server@node2;Req;;Type 1 request received from ctminh@node2.supernodexp.hpc, sock=16
02/13/2018 17:59:59;0100;Server@node2;Req;;Type 3 request received from ctminh@node2.supernodexp.hpc, sock=16
02/13/2018 17:59:59;0100;Server@node2;Req;;Type 5 request received from ctminh@node2.supernodexp.hpc, sock=16
02/13/2018 17:59:59;0100;Server@node2;Job;966.node2.supernodexp.hpc;enqueuing into workq, state 1 hop 1
02/13/2018 17:59:59;0008;Server@node2;Job;966.node2.supernodexp.hpc;Job Queued at request of ctminh@node2.supernodexp.hpc, owner = ctminh@node2.supernodexp.hpc, job name = vast1, queue = workq
02/13/2018 17:59:59;0100;Server@node2;Req;;Type 20 request received from Scheduler@node2.supernodexp.hpc, sock=20
02/13/2018 17:59:59;0100;Server@node2;Req;;Type 51 request received from Scheduler@node2.supernodexp.hpc, sock=20
02/13/2018 17:59:59;0100;Server@node2;Req;;Type 1 request received from ctminh@node2.supernodexp.hpc, sock=16
02/13/2018 17:59:59;0100;Server@node2;Req;;Type 3 request received from ctminh@node2.supernodexp.hpc, sock=16
02/13/2018 17:59:59;0100;Server@node2;Req;;Type 5 request received from ctminh@node2.supernodexp.hpc, sock=16
02/13/2018 17:59:59;0100;Server@node2;Job;967.node2.supernodexp.hpc;enqueuing into workq, state 1 hop 1
02/13/2018 17:59:59;0008;Server@node2;Job;967.node2.supernodexp.hpc;Job Queued at request of ctminh@node2.supernodexp.hpc, owner = ctminh@node2.supernodexp.hpc, job name = matrix-x-vector, queue = workq
02/13/2018 17:59:59;0100;Server@node2;Req;;Type 11 request received from Scheduler@node2.supernodexp.hpc, sock=20
02/13/2018 17:59:59;0008;Server@node2;Job;962.node2.supernodexp.hpc;Job Modified at request of Scheduler@node2.supernodexp.hpc
02/13/2018 17:59:59;0100;Server@node2;Req;;Type 11 request received from Scheduler@node2.supernodexp.hpc, sock=20
02/13/2018 17:59:59;0008;Server@node2;Job;965.node2.supernodexp.hpc;Job Modified at request of Scheduler@node2.supernodexp.hpc
02/13/2018 17:59:59;0100;Server@node2;Req;;Type 11 request received from Scheduler@node2.supernodexp.hpc, sock=20
02/13/2018 17:59:59;0008;Server@node2;Job;963.node2.supernodexp.hpc;Job Modified at request of Scheduler@node2.supernodexp.hpc
02/13/2018 17:59:59;0100;Server@node2;Req;;Type 11 request received from Scheduler@node2.supernodexp.hpc, sock=20
02/13/2018 17:59:59;0008;Server@node2;Job;964.node2.supernodexp.hpc;Job Modified at request of Scheduler@node2.supernodexp.hpc
02/13/2018 17:59:59;0100;Server@node2;Req;;Type 11 request received from Scheduler@node2.supernodexp.hpc, sock=20
02/13/2018 17:59:59;0008;Server@node2;Job;966.node2.supernodexp.hpc;Job Modified at request of Scheduler@node2.supernodexp.hpc
02/13/2018 17:59:59;0040;Server@node2;Svr;node2.supernodexp.hpc;Scheduler sent command 1
02/13/2018 17:59:59;0040;Server@node2;Svr;node2.supernodexp.hpc;Scheduler sent command 0
02/13/2018 17:59:59;0100;Server@node2;Req;;Type 21 request received from Scheduler@node2.supernodexp.hpc, sock=20
02/13/2018 17:59:59;0100;Server@node2;Req;;Type 81 request received from Scheduler@node2.supernodexp.hpc, sock=20
02/13/2018 17:59:59;0100;Server@node2;Req;;Type 71 request received from Scheduler@node2.supernodexp.hpc, sock=20
02/13/2018 17:59:59;0100;Server@node2;Req;;Type 58 request received from Scheduler@node2.supernodexp.hpc, sock=20
02/13/2018 17:59:59;0100;Server@node2;Req;;Type 1 request received from ctminh@node2.supernodexp.hpc, sock=16
02/13/2018 17:59:59;0100;Server@node2;Req;;Type 3 request received from ctminh@node2.supernodexp.hpc, sock=16
02/13/2018 17:59:59;0100;Server@node2;Req;;Type 5 request received from ctminh@node2.supernodexp.hpc, sock=16
02/13/2018 17:59:59;0100;Server@node2;Job;968.node2.supernodexp.hpc;enqueuing into workq, state 1 hop 1
02/13/2018 17:59:59;0008;Server@node2;Job;968.node2.supernodexp.hpc;Job Queued at request of ctminh@node2.supernodexp.hpc, owner = ctminh@node2.supernodexp.hpc, job name = nbody, queue = workq
02/13/2018 17:59:59;0100;Server@node2;Req;;Type 1 request received from ctminh@node2.supernodexp.hpc, sock=16
02/13/2018 17:59:59;0100;Server@node2;Req;;Type 3 request received from ctminh@node2.supernodexp.hpc, sock=16
02/13/2018 17:59:59;0100;Server@node2;Req;;Type 5 request received from ctminh@node2.supernodexp.hpc, sock=16
02/13/2018 17:59:59;0100;Server@node2;Job;969.node2.supernodexp.hpc;enqueuing into workq, state 1 hop 1
02/13/2018 17:59:59;0008;Server@node2;Job;969.node2.supernodexp.hpc;Job Queued at request of ctminh@node2.supernodexp.hpc, owner = ctminh@node2.supernodexp.hpc, job name = vast1, queue = workq
02/13/2018 17:59:59;0100;Server@node2;Req;;Type 20 request received from Scheduler@node2.supernodexp.hpc, sock=20
02/13/2018 17:59:59;0100;Server@node2;Req;;Type 51 request received from Scheduler@node2.supernodexp.hpc, sock=20
02/13/2018 17:59:59;0100;Server@node2;Req;;Type 1 request received from ctminh@node2.supernodexp.hpc, sock=16
02/13/2018 17:59:59;0100;Server@node2;Req;;Type 3 request received from ctminh@node2.supernodexp.hpc, sock=16
02/13/2018 17:59:59;0100;Server@node2;Req;;Type 5 request received from ctminh@node2.supernodexp.hpc, sock=16
02/13/2018 17:59:59;0100;Server@node2;Job;970.node2.supernodexp.hpc;enqueuing into workq, state 1 hop 1
02/13/2018 17:59:59;0008;Server@node2;Job;970.node2.supernodexp.hpc;Job Queued at request of ctminh@node2.supernodexp.hpc, owner = ctminh@node2.supernodexp.hpc, job name = telemac3, queue = workq
02/13/2018 18:00:00;0100;Server@node2;Req;;Type 11 request received from Scheduler@node2.supernodexp.hpc, sock=20
02/13/2018 18:00:00;0008;Server@node2;Job;967.node2.supernodexp.hpc;Job Modified at request of Scheduler@node2.supernodexp.hpc
02/13/2018 18:00:00;0100;Server@node2;Req;;Type 11 request received from Scheduler@node2.supernodexp.hpc, sock=20
02/13/2018 18:00:00;0008;Server@node2;Job;968.node2.supernodexp.hpc;Job Modified at request of Scheduler@node2.supernodexp.hpc
02/13/2018 18:00:00;0100;Server@node2;Req;;Type 11 request received from Scheduler@node2.supernodexp.hpc, sock=20
02/13/2018 18:00:00;0008;Server@node2;Job;969.node2.supernodexp.hpc;Job Modified at request of Scheduler@node2.supernodexp.hpc
02/13/2018 18:00:00;0040;Server@node2;Svr;node2.supernodexp.hpc;Scheduler sent command 1
02/13/2018 18:00:00;0040;Server@node2;Svr;node2.supernodexp.hpc;Scheduler sent command 0
02/13/2018 18:00:00;0100;Server@node2;Req;;Type 21 request received from Scheduler@node2.supernodexp.hpc, sock=20
02/13/2018 18:00:00;0100;Server@node2;Req;;Type 81 request received from Scheduler@node2.supernodexp.hpc, sock=20
02/13/2018 18:00:00;0100;Server@node2;Req;;Type 71 request received from Scheduler@node2.supernodexp.hpc, sock=20
02/13/2018 18:00:00;0100;Server@node2;Req;;Type 58 request received from Scheduler@node2.supernodexp.hpc, sock=20
02/13/2018 18:00:00;0100;Server@node2;Req;;Type 20 request received from Scheduler@node2.supernodexp.hpc, sock=20
02/13/2018 18:00:00;0100;Server@node2;Req;;Type 51 request received from Scheduler@node2.supernodexp.hpc, sock=20
02/13/2018 18:00:00;0100;Server@node2;Req;;Type 11 request received from Scheduler@node2.supernodexp.hpc, sock=20
02/13/2018 18:00:00;0008;Server@node2;Job;970.node2.supernodexp.hpc;Job Modified at request of Scheduler@node2.supernodexp.hpc
02/13/2018 18:00:00;0080;Server@node2;Job;901.node2.supernodexp.hpc;Obit received momhop:1 serverhop:1 state:4 substate:42
02/13/2018 18:00:00;0080;Server@node2;Job;907.node2.supernodexp.hpc;Obit received momhop:1 serverhop:1 state:4 substate:42
02/13/2018 18:00:01;0010;Server@node2;Job;901.node2.supernodexp.hpc;Exit_status=0 resources_used.cpupercent=100 resources_used.cput=00:00:08 resources_used.mem=11624kb resources_used.ncpus=12 resources_used.vmem=343400kb resources_used.walltime=00:00:08
02/13/2018 18:00:01;0100;Server@node2;Job;901.node2.supernodexp.hpc;dequeuing from workq, state 5
02/13/2018 18:00:01;0010;Server@node2;Job;907.node2.supernodexp.hpc;Exit_status=0 resources_used.cpupercent=100 resources_used.cput=00:00:08 resources_used.mem=11624kb resources_used.ncpus=12 resources_used.vmem=343400kb resources_used.walltime=00:00:08
02/13/2018 18:00:01;0100;Server@node2;Job;907.node2.supernodexp.hpc;dequeuing from workq, state 5
02/13/2018 18:00:01;0040;Server@node2;Svr;node2.supernodexp.hpc;Scheduler sent command 2
02/13/2018 18:00:01;0040;Server@node2;Svr;node2.supernodexp.hpc;Scheduler sent command 0
02/13/2018 18:00:01;0100;Server@node2;Req;;Type 21 request received from Scheduler@node2.supernodexp.hpc, sock=20
02/13/2018 18:00:01;0100;Server@node2;Req;;Type 81 request received from Scheduler@node2.supernodexp.hpc, sock=20
02/13/2018 18:00:01;0100;Server@node2;Req;;Type 71 request received from Scheduler@node2.supernodexp.hpc, sock=20
02/13/2018 18:00:01;0100;Server@node2;Req;;Type 58 request received from Scheduler@node2.supernodexp.hpc, sock=20
02/13/2018 18:00:01;0100;Server@node2;Req;;Type 20 request received from Scheduler@node2.supernodexp.hpc, sock=20
02/13/2018 18:00:01;0100;Server@node2;Req;;Type 51 request received from Scheduler@node2.supernodexp.hpc, sock=20
02/13/2018 18:00:01;0100;Server@node2;Req;;Type 23 request received from Scheduler@node2.supernodexp.hpc, sock=20
02/13/2018 18:00:01;0008;Server@node2;Job;953.node2.supernodexp.hpc;Job Run at request of Scheduler@node2.supernodexp.hpc on exec_vnode (node13:ncpus=16:mem=5242880kb)
02/13/2018 18:00:01;0001;Server@node2;Svr;Server@node2;Success (0) in req_runjob2, return value of svr_startjob is 0
02/13/2018 18:00:01;0100;Server@node2;Req;;Type 11 request received from Scheduler@node2.supernodexp.hpc, sock=20
02/13/2018 18:00:01;0008;Server@node2;Job;962.node2.supernodexp.hpc;Job Modified at request of Scheduler@node2.supernodexp.hpc
02/13/2018 18:00:02;0080;Server@node2;Job;920.node2.supernodexp.hpc;Obit received momhop:1 serverhop:1 state:4 substate:42
02/13/2018 18:00:02;0080;Server@node2;Job;953.node2.supernodexp.hpc;Obit received momhop:1 serverhop:1 state:4 substate:42
02/13/2018 18:00:03;0010;Server@node2;Job;920.node2.supernodexp.hpc;Exit_status=0 resources_used.cpupercent=100 resources_used.cput=00:00:08 resources_used.mem=11624kb resources_used.ncpus=12 resources_used.vmem=343400kb resources_used.walltime=00:00:08
02/13/2018 18:00:03;0100;Server@node2;Job;920.node2.supernodexp.hpc;dequeuing from workq, state 5
02/13/2018 18:00:03;0040;Server@node2;Svr;node2.supernodexp.hpc;Scheduler sent command 2
02/13/2018 18:00:03;0040;Server@node2;Svr;node2.supernodexp.hpc;Scheduler sent command 0
02/13/2018 18:00:03;0100;Server@node2;Req;;Type 21 request received from Scheduler@node2.supernodexp.hpc, sock=20
02/13/2018 18:00:03;0100;Server@node2;Req;;Type 81 request received from Scheduler@node2.supernodexp.hpc, sock=20
02/13/2018 18:00:03;0100;Server@node2;Req;;Type 71 request received from Scheduler@node2.supernodexp.hpc, sock=20
02/13/2018 18:00:03;0100;Server@node2;Req;;Type 58 request received from Scheduler@node2.supernodexp.hpc, sock=20
02/13/2018 18:00:03;0100;Server@node2;Req;;Type 20 request received from Scheduler@node2.supernodexp.hpc, sock=20
02/13/2018 18:00:03;0100;Server@node2;Req;;Type 51 request received from Scheduler@node2.supernodexp.hpc, sock=20
02/13/2018 18:00:03;0080;Server@node2;Job;922.node2.supernodexp.hpc;Obit received momhop:1 serverhop:1 state:4 substate:42
02/13/2018 18:00:03;0100;Server@node2;Req;;Type 11 request received from Scheduler@node2.supernodexp.hpc, sock=20
02/13/2018 18:00:03;0008;Server@node2;Job;962.node2.supernodexp.hpc;Job Modified at request of Scheduler@node2.supernodexp.hpc
02/13/2018 18:00:03;0010;Server@node2;Job;953.node2.supernodexp.hpc;Exit_status=0 resources_used.cpupercent=700 resources_used.cput=00:00:15 resources_used.mem=4205732kb resources_used.ncpus=16 resources_used.vmem=5511124kb resources_used.walltime=00:00:01
02/13/2018 18:00:03;0100;Server@node2;Job;953.node2.supernodexp.hpc;dequeuing from workq, state 5
02/13/2018 18:00:03;0040;Server@node2;Svr;node2.supernodexp.hpc;Scheduler sent command 2
02/13/2018 18:00:03;0040;Server@node2;Svr;node2.supernodexp.hpc;Scheduler sent command 0
02/13/2018 18:00:03;0100;Server@node2;Req;;Type 21 request received from Scheduler@node2.supernodexp.hpc, sock=20
02/13/2018 18:00:03;0100;Server@node2;Req;;Type 81 request received from Scheduler@node2.supernodexp.hpc, sock=20
02/13/2018 18:00:03;0100;Server@node2;Req;;Type 71 request received from Scheduler@node2.supernodexp.hpc, sock=20
02/13/2018 18:00:03;0100;Server@node2;Req;;Type 58 request received from Scheduler@node2.supernodexp.hpc, sock=20
02/13/2018 18:00:04;0100;Server@node2;Req;;Type 20 request received from Scheduler@node2.supernodexp.hpc, sock=20
02/13/2018 18:00:04;0100;Server@node2;Req;;Type 51 request received from Scheduler@node2.supernodexp.hpc, sock=20
02/13/2018 18:00:04;0100;Server@node2;Req;;Type 23 request received from Scheduler@node2.supernodexp.hpc, sock=20
02/13/2018 18:00:04;0008;Server@node2;Job;962.node2.supernodexp.hpc;Job Run at request of Scheduler@node2.supernodexp.hpc on exec_vnode (node13:ncpus=24:mem=1048576kb)
02/13/2018 18:00:04;0001;Server@node2;Svr;Server@node2;Success (0) in req_runjob2, return value of svr_startjob is 0
02/13/2018 18:00:04;0100;Server@node2;Req;;Type 11 request received from Scheduler@node2.supernodexp.hpc, sock=20
02/13/2018 18:00:04;0008;Server@node2;Job;967.node2.supernodexp.hpc;Job Modified at request of Scheduler@node2.supernodexp.hpc
02/13/2018 18:00:04;0010;Server@node2;Job;922.node2.supernodexp.hpc;Exit_status=0 resources_used.cpupercent=124 resources_used.cput=00:00:08 resources_used.mem=11624kb resources_used.ncpus=12 resources_used.vmem=343400kb resources_used.walltime=00:00:09
02/13/2018 18:00:04;0100;Server@node2;Job;922.node2.supernodexp.hpc;dequeuing from workq, state 5
02/13/2018 18:00:04;0040;Server@node2;Svr;node2.supernodexp.hpc;Scheduler sent command 2
02/13/2018 18:00:04;0040;Server@node2;Svr;node2.supernodexp.hpc;Scheduler sent command 0
02/13/2018 18:00:04;0100;Server@node2;Req;;Type 21 request received from Scheduler@node2.supernodexp.hpc, sock=20
02/13/2018 18:00:04;0100;Server@node2;Req;;Type 81 request received from Scheduler@node2.supernodexp.hpc, sock=20
02/13/2018 18:00:04;0100;Server@node2;Req;;Type 71 request received from Scheduler@node2.supernodexp.hpc, sock=20
02/13/2018 18:00:04;0100;Server@node2;Req;;Type 58 request received from Scheduler@node2.supernodexp.hpc, sock=20
02/13/2018 18:00:04;0100;Server@node2;Req;;Type 20 request received from Scheduler@node2.supernodexp.hpc, sock=20
02/13/2018 18:00:04;0100;Server@node2;Req;;Type 51 request received from Scheduler@node2.supernodexp.hpc, sock=20
02/13/2018 18:00:04;0100;Server@node2;Req;;Type 23 request received from Scheduler@node2.supernodexp.hpc, sock=20
02/13/2018 18:00:04;0008;Server@node2;Job;967.node2.supernodexp.hpc;Job Run at request of Scheduler@node2.supernodexp.hpc on exec_vnode (node13:ncpus=16:mem=5242880kb)
02/13/2018 18:00:04;0001;Server@node2;Svr;Server@node2;Success (0) in req_runjob2, return value of svr_startjob is 0
02/13/2018 18:00:04;0100;Server@node2;Req;;Type 11 request received from Scheduler@node2.supernodexp.hpc, sock=20
02/13/2018 18:00:04;0008;Server@node2;Job;951.node2.supernodexp.hpc;Job Modified at request of Scheduler@node2.supernodexp.hpc
02/13/2018 18:00:05;0080;Server@node2;Job;962.node2.supernodexp.hpc;Obit received momhop:1 serverhop:1 state:4 substate:42
02/13/2018 18:00:05;0080;Server@node2;Job;967.node2.supernodexp.hpc;Obit received momhop:1 serverhop:1 state:4 substate:42
02/13/2018 18:00:07;0010;Server@node2;Job;962.node2.supernodexp.hpc;Exit_status=0 resources_used.cpupercent=505 resources_used.cput=00:00:30 resources_used.mem=1292260kb resources_used.ncpus=24 resources_used.vmem=3151052kb resources_used.walltime=00:00:02
02/13/2018 18:00:07;0100;Server@node2;Job;962.node2.supernodexp.hpc;dequeuing from workq, state 5
02/13/2018 18:00:07;0010;Server@node2;Job;967.node2.supernodexp.hpc;Exit_status=0 resources_used.cpupercent=900 resources_used.cput=00:00:11 resources_used.mem=4209396kb resources_used.ncpus=16 resources_used.vmem=5511124kb resources_used.walltime=00:00:01
02/13/2018 18:00:07;0100;Server@node2;Job;967.node2.supernodexp.hpc;dequeuing from workq, state 5
02/13/2018 18:00:07;0040;Server@node2;Svr;node2.supernodexp.hpc;Scheduler sent command 2
02/13/2018 18:00:07;0040;Server@node2;Svr;node2.supernodexp.hpc;Scheduler sent command 0
02/13/2018 18:00:07;0100;Server@node2;Req;;Type 21 request received from Scheduler@node2.supernodexp.hpc, sock=20
02/13/2018 18:00:07;0100;Server@node2;Req;;Type 81 request received from Scheduler@node2.supernodexp.hpc, sock=20
02/13/2018 18:00:07;0100;Server@node2;Req;;Type 71 request received from Scheduler@node2.supernodexp.hpc, sock=20
02/13/2018 18:00:07;0100;Server@node2;Req;;Type 58 request received from Scheduler@node2.supernodexp.hpc, sock=20
02/13/2018 18:00:07;0100;Server@node2;Req;;Type 20 request received from Scheduler@node2.supernodexp.hpc, sock=20
02/13/2018 18:00:07;0100;Server@node2;Req;;Type 51 request received from Scheduler@node2.supernodexp.hpc, sock=20
02/13/2018 18:00:07;0100;Server@node2;Req;;Type 23 request received from Scheduler@node2.supernodexp.hpc, sock=20
02/13/2018 18:00:07;0008;Server@node2;Job;951.node2.supernodexp.hpc;Job Run at request of Scheduler@node2.supernodexp.hpc on exec_vnode (node13:ncpus=32:mem=2097152kb)
02/13/2018 18:00:07;0001;Server@node2;Svr;Server@node2;Success (0) in req_runjob2, return value of svr_startjob is 0
02/13/2018 18:00:07;0100;Server@node2;Req;;Type 23 request received from Scheduler@node2.supernodexp.hpc, sock=20
02/13/2018 18:00:07;0008;Server@node2;Job;961.node2.supernodexp.hpc;Job Run at request of Scheduler@node2.supernodexp.hpc on exec_vnode (node13:ncpus=12:mem=1048576kb)
02/13/2018 18:00:07;0001;Server@node2;Svr;Server@node2;Success (0) in req_runjob2, return value of svr_startjob is 0
02/13/2018 18:00:07;0100;Server@node2;Req;;Type 11 request received from Scheduler@node2.supernodexp.hpc, sock=20
02/13/2018 18:00:07;0008;Server@node2;Job;965.node2.supernodexp.hpc;Job Modified at request of Scheduler@node2.supernodexp.hpc
02/13/2018 18:00:11;0080;Server@node2;Job;951.node2.supernodexp.hpc;Obit received momhop:1 serverhop:1 state:4 substate:42
02/13/2018 18:00:12;0010;Server@node2;Job;951.node2.supernodexp.hpc;Exit_status=0 resources_used.cpupercent=100 resources_used.cput=00:00:04 resources_used.mem=1820kb resources_used.ncpus=32 resources_used.vmem=127704kb resources_used.walltime=00:00:05
02/13/2018 18:00:12;0100;Server@node2;Job;951.node2.supernodexp.hpc;dequeuing from workq, state 5
02/13/2018 18:00:12;0040;Server@node2;Svr;node2.supernodexp.hpc;Scheduler sent command 2
02/13/2018 18:00:12;0040;Server@node2;Svr;node2.supernodexp.hpc;Scheduler sent command 0
02/13/2018 18:00:12;0100;Server@node2;Req;;Type 21 request received from Scheduler@node2.supernodexp.hpc, sock=20
02/13/2018 18:00:12;0100;Server@node2;Req;;Type 81 request received from Scheduler@node2.supernodexp.hpc, sock=20
02/13/2018 18:00:12;0100;Server@node2;Req;;Type 71 request received from Scheduler@node2.supernodexp.hpc, sock=20
02/13/2018 18:00:12;0100;Server@node2;Req;;Type 58 request received from Scheduler@node2.supernodexp.hpc, sock=20
02/13/2018 18:00:12;0100;Server@node2;Req;;Type 20 request received from Scheduler@node2.supernodexp.hpc, sock=20
02/13/2018 18:00:12;0100;Server@node2;Req;;Type 51 request received from Scheduler@node2.supernodexp.hpc, sock=20
02/13/2018 18:00:12;0100;Server@node2;Req;;Type 23 request received from Scheduler@node2.supernodexp.hpc, sock=20
02/13/2018 18:00:12;0008;Server@node2;Job;965.node2.supernodexp.hpc;Job Run at request of Scheduler@node2.supernodexp.hpc on exec_vnode (node13:ncpus=8:mem=3145728kb)
02/13/2018 18:00:12;0001;Server@node2;Svr;Server@node2;Success (0) in req_runjob2, return value of svr_startjob is 0
02/13/2018 18:00:12;0100;Server@node2;Req;;Type 23 request received from Scheduler@node2.supernodexp.hpc, sock=20
02/13/2018 18:00:12;0008;Server@node2;Job;936.node2.supernodexp.hpc;Job Run at request of Scheduler@node2.supernodexp.hpc on exec_vnode (node13:ncpus=12:mem=1048576kb)
02/13/2018 18:00:12;0001;Server@node2;Svr;Server@node2;Success (0) in req_runjob2, return value of svr_startjob is 0
02/13/2018 18:00:12;0100;Server@node2;Req;;Type 23 request received from Scheduler@node2.supernodexp.hpc, sock=20
02/13/2018 18:00:12;0008;Server@node2;Job;957.node2.supernodexp.hpc;Job Run at request of Scheduler@node2.supernodexp.hpc on exec_vnode (node13:ncpus=12:mem=1048576kb)
02/13/2018 18:00:12;0001;Server@node2;Svr;Server@node2;Success (0) in req_runjob2, return value of svr_startjob is 0
02/13/2018 18:00:12;0100;Server@node2;Req;;Type 11 request received from Scheduler@node2.supernodexp.hpc, sock=20
02/13/2018 18:00:12;0008;Server@node2;Job;968.node2.supernodexp.hpc;Job Modified at request of Scheduler@node2.supernodexp.hpc
02/13/2018 18:00:13;0080;Server@node2;Job;961.node2.supernodexp.hpc;Obit received momhop:1 serverhop:1 state:4 substate:42
02/13/2018 18:00:14;0080;Server@node2;Job;965.node2.supernodexp.hpc;Obit received momhop:1 serverhop:1 state:4 substate:42
02/13/2018 18:00:14;0010;Server@node2;Job;961.node2.supernodexp.hpc;Exit_status=0 resources_used.cpupercent=1175 resources_used.cput=00:01:11 resources_used.mem=29692kb resources_used.ncpus=12 resources_used.vmem=1125532kb resources_used.walltime=00:00:06
02/13/2018 18:00:14;0100;Server@node2;Job;961.node2.supernodexp.hpc;dequeuing from workq, state 5
02/13/2018 18:00:14;0040;Server@node2;Svr;node2.supernodexp.hpc;Scheduler sent command 2
02/13/2018 18:00:14;0040;Server@node2;Svr;node2.supernodexp.hpc;Scheduler sent command 0
02/13/2018 18:00:14;0100;Server@node2;Req;;Type 21 request received from Scheduler@node2.supernodexp.hpc, sock=20
02/13/2018 18:00:14;0100;Server@node2;Req;;Type 81 request received from Scheduler@node2.supernodexp.hpc, sock=20
02/13/2018 18:00:14;0100;Server@node2;Req;;Type 71 request received from Scheduler@node2.supernodexp.hpc, sock=20
02/13/2018 18:00:14;0100;Server@node2;Req;;Type 58 request received from Scheduler@node2.supernodexp.hpc, sock=20
02/13/2018 18:00:14;0100;Server@node2;Req;;Type 20 request received from Scheduler@node2.supernodexp.hpc, sock=20
02/13/2018 18:00:14;0100;Server@node2;Req;;Type 51 request received from Scheduler@node2.supernodexp.hpc, sock=20
02/13/2018 18:00:14;0100;Server@node2;Req;;Type 23 request received from Scheduler@node2.supernodexp.hpc, sock=20
02/13/2018 18:00:14;0008;Server@node2;Job;968.node2.supernodexp.hpc;Job Run at request of Scheduler@node2.supernodexp.hpc on exec_vnode (node13:ncpus=12:mem=1048576kb)
02/13/2018 18:00:14;0001;Server@node2;Svr;Server@node2;Success (0) in req_runjob2, return value of svr_startjob is 0
02/13/2018 18:00:14;0100;Server@node2;Req;;Type 11 request received from Scheduler@node2.supernodexp.hpc, sock=20
02/13/2018 18:00:14;0008;Server@node2;Job;855.node2.supernodexp.hpc;Job Modified at request of Scheduler@node2.supernodexp.hpc
02/13/2018 18:00:15;0010;Server@node2;Job;965.node2.supernodexp.hpc;Exit_status=0 resources_used.cpupercent=301 resources_used.cput=00:00:09 resources_used.mem=3137060kb resources_used.ncpus=8 resources_used.vmem=3942464kb resources_used.walltime=00:00:02
02/13/2018 18:00:15;0100;Server@node2;Job;965.node2.supernodexp.hpc;dequeuing from workq, state 5
02/13/2018 18:00:15;0040;Server@node2;Svr;node2.supernodexp.hpc;Scheduler sent command 2
02/13/2018 18:00:15;0040;Server@node2;Svr;node2.supernodexp.hpc;Scheduler sent command 0
02/13/2018 18:00:15;0100;Server@node2;Req;;Type 21 request received from Scheduler@node2.supernodexp.hpc, sock=20
02/13/2018 18:00:15;0100;Server@node2;Req;;Type 81 request received from Scheduler@node2.supernodexp.hpc, sock=20
02/13/2018 18:00:15;0100;Server@node2;Req;;Type 71 request received from Scheduler@node2.supernodexp.hpc, sock=20
02/13/2018 18:00:15;0100;Server@node2;Req;;Type 58 request received from Scheduler@node2.supernodexp.hpc, sock=20
02/13/2018 18:00:15;0100;Server@node2;Req;;Type 20 request received from Scheduler@node2.supernodexp.hpc, sock=20
02/13/2018 18:00:15;0100;Server@node2;Req;;Type 51 request received from Scheduler@node2.supernodexp.hpc, sock=20
02/13/2018 18:00:15;0100;Server@node2;Req;;Type 11 request received from Scheduler@node2.supernodexp.hpc, sock=20
02/13/2018 18:00:15;0008;Server@node2;Job;855.node2.supernodexp.hpc;Job Modified at request of Scheduler@node2.supernodexp.hpc
02/13/2018 18:00:21;0080;Server@node2;Job;936.node2.supernodexp.hpc;Obit received momhop:1 serverhop:1 state:4 substate:42
02/13/2018 18:00:21;0080;Server@node2;Job;957.node2.supernodexp.hpc;Obit received momhop:1 serverhop:1 state:4 substate:42
02/13/2018 18:00:22;0010;Server@node2;Job;936.node2.supernodexp.hpc;Exit_status=0 resources_used.cpupercent=100 resources_used.cput=00:00:08 resources_used.mem=11616kb resources_used.ncpus=12 resources_used.vmem=343400kb resources_used.walltime=00:00:09
02/13/2018 18:00:22;0100;Server@node2;Job;936.node2.supernodexp.hpc;dequeuing from workq, state 5
02/13/2018 18:00:22;0010;Server@node2;Job;957.node2.supernodexp.hpc;Exit_status=0 resources_used.cpupercent=100 resources_used.cput=00:00:08 resources_used.mem=11628kb resources_used.ncpus=12 resources_used.vmem=343400kb resources_used.walltime=00:00:09
02/13/2018 18:00:22;0100;Server@node2;Job;957.node2.supernodexp.hpc;dequeuing from workq, state 5
02/13/2018 18:00:22;0040;Server@node2;Svr;node2.supernodexp.hpc;Scheduler sent command 2
02/13/2018 18:00:22;0040;Server@node2;Svr;node2.supernodexp.hpc;Scheduler sent command 0
02/13/2018 18:00:22;0100;Server@node2;Req;;Type 21 request received from Scheduler@node2.supernodexp.hpc, sock=20
02/13/2018 18:00:22;0100;Server@node2;Req;;Type 81 request received from Scheduler@node2.supernodexp.hpc, sock=20
02/13/2018 18:00:22;0100;Server@node2;Req;;Type 71 request received from Scheduler@node2.supernodexp.hpc, sock=20
02/13/2018 18:00:22;0100;Server@node2;Req;;Type 58 request received from Scheduler@node2.supernodexp.hpc, sock=20
02/13/2018 18:00:23;0100;Server@node2;Req;;Type 20 request received from Scheduler@node2.supernodexp.hpc, sock=20
02/13/2018 18:00:23;0100;Server@node2;Req;;Type 51 request received from Scheduler@node2.supernodexp.hpc, sock=20
02/13/2018 18:00:23;0100;Server@node2;Req;;Type 23 request received from Scheduler@node2.supernodexp.hpc, sock=20
02/13/2018 18:00:23;0008;Server@node2;Job;855.node2.supernodexp.hpc;Job Run at request of Scheduler@node2.supernodexp.hpc on exec_vnode (node13:ncpus=24:mem=2097152kb)
02/13/2018 18:00:23;0001;Server@node2;Svr;Server@node2;Success (0) in req_runjob2, return value of svr_startjob is 0
02/13/2018 18:00:23;0080;Server@node2;Job;968.node2.supernodexp.hpc;Obit received momhop:1 serverhop:1 state:4 substate:42
02/13/2018 18:00:23;0100;Server@node2;Req;;Type 11 request received from Scheduler@node2.supernodexp.hpc, sock=20
02/13/2018 18:00:23;0008;Server@node2;Job;912.node2.supernodexp.hpc;Job Modified at request of Scheduler@node2.supernodexp.hpc
02/13/2018 18:00:24;0010;Server@node2;Job;968.node2.supernodexp.hpc;Exit_status=0 resources_used.cpupercent=116 resources_used.cput=00:00:08 resources_used.mem=11624kb resources_used.ncpus=12 resources_used.vmem=343400kb resources_used.walltime=00:00:08
02/13/2018 18:00:24;0100;Server@node2;Job;968.node2.supernodexp.hpc;dequeuing from workq, state 5
02/13/2018 18:00:24;0040;Server@node2;Svr;node2.supernodexp.hpc;Scheduler sent command 2
02/13/2018 18:00:24;0040;Server@node2;Svr;node2.supernodexp.hpc;Scheduler sent command 0
02/13/2018 18:00:24;0100;Server@node2;Req;;Type 21 request received from Scheduler@node2.supernodexp.hpc, sock=20
02/13/2018 18:00:24;0100;Server@node2;Req;;Type 81 request received from Scheduler@node2.supernodexp.hpc, sock=20
02/13/2018 18:00:24;0100;Server@node2;Req;;Type 71 request received from Scheduler@node2.supernodexp.hpc, sock=20
02/13/2018 18:00:24;0100;Server@node2;Req;;Type 58 request received from Scheduler@node2.supernodexp.hpc, sock=20
02/13/2018 18:00:24;0100;Server@node2;Req;;Type 20 request received from Scheduler@node2.supernodexp.hpc, sock=20
02/13/2018 18:00:24;0100;Server@node2;Req;;Type 51 request received from Scheduler@node2.supernodexp.hpc, sock=20
02/13/2018 18:00:24;0100;Server@node2;Req;;Type 23 request received from Scheduler@node2.supernodexp.hpc, sock=20
02/13/2018 18:00:24;0008;Server@node2;Job;912.node2.supernodexp.hpc;Job Run at request of Scheduler@node2.supernodexp.hpc on exec_vnode (node13:ncpus=24:mem=2097152kb)
02/13/2018 18:00:24;0001;Server@node2;Svr;Server@node2;Success (0) in req_runjob2, return value of svr_startjob is 0
02/13/2018 18:00:24;0100;Server@node2;Req;;Type 11 request received from Scheduler@node2.supernodexp.hpc, sock=20
02/13/2018 18:00:24;0008;Server@node2;Job;925.node2.supernodexp.hpc;Job Modified at request of Scheduler@node2.supernodexp.hpc
02/13/2018 18:00:44;0100;Server@node2;Req;;Type 1 request received from ctminh@node2.supernodexp.hpc, sock=16
02/13/2018 18:00:44;0100;Server@node2;Req;;Type 3 request received from ctminh@node2.supernodexp.hpc, sock=16
02/13/2018 18:00:44;0100;Server@node2;Req;;Type 5 request received from ctminh@node2.supernodexp.hpc, sock=16
02/13/2018 18:00:44;0100;Server@node2;Job;971.node2.supernodexp.hpc;enqueuing into workq, state 1 hop 1
02/13/2018 18:00:44;0008;Server@node2;Job;971.node2.supernodexp.hpc;Job Queued at request of ctminh@node2.supernodexp.hpc, owner = ctminh@node2.supernodexp.hpc, job name = histogram, queue = workq
02/13/2018 18:00:44;0040;Server@node2;Svr;node2.supernodexp.hpc;Scheduler sent command 1
02/13/2018 18:00:44;0040;Server@node2;Svr;node2.supernodexp.hpc;Scheduler sent command 0
02/13/2018 18:00:44;0100;Server@node2;Req;;Type 21 request received from Scheduler@node2.supernodexp.hpc, sock=20
02/13/2018 18:00:44;0100;Server@node2;Req;;Type 81 request received from Scheduler@node2.supernodexp.hpc, sock=20
02/13/2018 18:00:44;0100;Server@node2;Req;;Type 71 request received from Scheduler@node2.supernodexp.hpc, sock=20
02/13/2018 18:00:44;0100;Server@node2;Req;;Type 58 request received from Scheduler@node2.supernodexp.hpc, sock=20
02/13/2018 18:00:44;0100;Server@node2;Req;;Type 1 request received from ctminh@node2.supernodexp.hpc, sock=16
02/13/2018 18:00:44;0100;Server@node2;Req;;Type 3 request received from ctminh@node2.supernodexp.hpc, sock=16
02/13/2018 18:00:44;0100;Server@node2;Req;;Type 5 request received from ctminh@node2.supernodexp.hpc, sock=16
02/13/2018 18:00:44;0100;Server@node2;Job;972.node2.supernodexp.hpc;enqueuing into workq, state 1 hop 1
02/13/2018 18:00:44;0008;Server@node2;Job;972.node2.supernodexp.hpc;Job Queued at request of ctminh@node2.supernodexp.hpc, owner = ctminh@node2.supernodexp.hpc, job name = telemac2, queue = workq
02/13/2018 18:00:44;0100;Server@node2;Req;;Type 1 request received from ctminh@node2.supernodexp.hpc, sock=16
02/13/2018 18:00:44;0100;Server@node2;Req;;Type 20 request received from Scheduler@node2.supernodexp.hpc, sock=20
02/13/2018 18:00:44;0100;Server@node2;Req;;Type 3 request received from ctminh@node2.supernodexp.hpc, sock=16
02/13/2018 18:00:44;0100;Server@node2;Req;;Type 51 request received from Scheduler@node2.supernodexp.hpc, sock=20
02/13/2018 18:00:44;0100;Server@node2;Req;;Type 5 request received from ctminh@node2.supernodexp.hpc, sock=16
02/13/2018 18:00:44;0100;Server@node2;Job;973.node2.supernodexp.hpc;enqueuing into workq, state 1 hop 1
02/13/2018 18:00:44;0008;Server@node2;Job;973.node2.supernodexp.hpc;Job Queued at request of ctminh@node2.supernodexp.hpc, owner = ctminh@node2.supernodexp.hpc, job name = telemac3, queue = workq
02/13/2018 18:00:44;0100;Server@node2;Req;;Type 1 request received from ctminh@node2.supernodexp.hpc, sock=16
02/13/2018 18:00:44;0100;Server@node2;Req;;Type 3 request received from ctminh@node2.supernodexp.hpc, sock=16
02/13/2018 18:00:44;0100;Server@node2;Req;;Type 5 request received from ctminh@node2.supernodexp.hpc, sock=16
02/13/2018 18:00:44;0100;Server@node2;Job;974.node2.supernodexp.hpc;enqueuing into workq, state 1 hop 1
02/13/2018 18:00:44;0008;Server@node2;Job;974.node2.supernodexp.hpc;Job Queued at request of ctminh@node2.supernodexp.hpc, owner = ctminh@node2.supernodexp.hpc, job name = sweep, queue = workq
02/13/2018 18:00:44;0100;Server@node2;Req;;Type 1 request received from ctminh@node2.supernodexp.hpc, sock=16
02/13/2018 18:00:44;0100;Server@node2;Req;;Type 3 request received from ctminh@node2.supernodexp.hpc, sock=16
02/13/2018 18:00:44;0100;Server@node2;Req;;Type 5 request received from ctminh@node2.supernodexp.hpc, sock=16
02/13/2018 18:00:44;0100;Server@node2;Job;975.node2.supernodexp.hpc;enqueuing into workq, state 1 hop 1
02/13/2018 18:00:44;0008;Server@node2;Job;975.node2.supernodexp.hpc;Job Queued at request of ctminh@node2.supernodexp.hpc, owner = ctminh@node2.supernodexp.hpc, job name = sweep, queue = workq
02/13/2018 18:00:44;0100;Server@node2;Req;;Type 11 request received from Scheduler@node2.supernodexp.hpc, sock=20
02/13/2018 18:00:44;0008;Server@node2;Job;925.node2.supernodexp.hpc;Job Modified at request of Scheduler@node2.supernodexp.hpc
02/13/2018 18:00:44;0100;Server@node2;Req;;Type 11 request received from Scheduler@node2.supernodexp.hpc, sock=20
02/13/2018 18:00:44;0008;Server@node2;Job;972.node2.supernodexp.hpc;Job Modified at request of Scheduler@node2.supernodexp.hpc
02/13/2018 18:00:44;0100;Server@node2;Req;;Type 11 request received from Scheduler@node2.supernodexp.hpc, sock=20
02/13/2018 18:00:44;0008;Server@node2;Job;971.node2.supernodexp.hpc;Job Modified at request of Scheduler@node2.supernodexp.hpc
02/13/2018 18:00:44;0040;Server@node2;Svr;node2.supernodexp.hpc;Scheduler sent command 1
02/13/2018 18:00:44;0040;Server@node2;Svr;node2.supernodexp.hpc;Scheduler sent command 0
02/13/2018 18:00:44;0100;Server@node2;Req;;Type 21 request received from Scheduler@node2.supernodexp.hpc, sock=20
02/13/2018 18:00:44;0100;Server@node2;Req;;Type 81 request received from Scheduler@node2.supernodexp.hpc, sock=20
02/13/2018 18:00:44;0100;Server@node2;Req;;Type 71 request received from Scheduler@node2.supernodexp.hpc, sock=20
02/13/2018 18:00:44;0100;Server@node2;Req;;Type 58 request received from Scheduler@node2.supernodexp.hpc, sock=20
02/13/2018 18:00:44;0100;Server@node2;Req;;Type 1 request received from ctminh@node2.supernodexp.hpc, sock=16
02/13/2018 18:00:44;0100;Server@node2;Req;;Type 3 request received from ctminh@node2.supernodexp.hpc, sock=16
02/13/2018 18:00:44;0100;Server@node2;Req;;Type 5 request received from ctminh@node2.supernodexp.hpc, sock=16
02/13/2018 18:00:44;0100;Server@node2;Job;976.node2.supernodexp.hpc;enqueuing into workq, state 1 hop 1
02/13/2018 18:00:44;0008;Server@node2;Job;976.node2.supernodexp.hpc;Job Queued at request of ctminh@node2.supernodexp.hpc, owner = ctminh@node2.supernodexp.hpc, job name = nbody, queue = workq
02/13/2018 18:00:44;0100;Server@node2;Req;;Type 1 request received from ctminh@node2.supernodexp.hpc, sock=16
02/13/2018 18:00:44;0100;Server@node2;Req;;Type 3 request received from ctminh@node2.supernodexp.hpc, sock=16
02/13/2018 18:00:44;0100;Server@node2;Req;;Type 5 request received from ctminh@node2.supernodexp.hpc, sock=16
02/13/2018 18:00:44;0100;Server@node2;Job;977.node2.supernodexp.hpc;enqueuing into workq, state 1 hop 1
02/13/2018 18:00:44;0008;Server@node2;Job;977.node2.supernodexp.hpc;Job Queued at request of ctminh@node2.supernodexp.hpc, owner = ctminh@node2.supernodexp.hpc, job name = nbody, queue = workq
02/13/2018 18:00:44;0100;Server@node2;Req;;Type 20 request received from Scheduler@node2.supernodexp.hpc, sock=20
02/13/2018 18:00:44;0100;Server@node2;Req;;Type 51 request received from Scheduler@node2.supernodexp.hpc, sock=20
02/13/2018 18:00:44;0100;Server@node2;Req;;Type 1 request received from ctminh@node2.supernodexp.hpc, sock=16
02/13/2018 18:00:44;0100;Server@node2;Req;;Type 3 request received from ctminh@node2.supernodexp.hpc, sock=16
02/13/2018 18:00:44;0100;Server@node2;Req;;Type 5 request received from ctminh@node2.supernodexp.hpc, sock=16
02/13/2018 18:00:44;0100;Server@node2;Job;978.node2.supernodexp.hpc;enqueuing into workq, state 1 hop 1
02/13/2018 18:00:44;0008;Server@node2;Job;978.node2.supernodexp.hpc;Job Queued at request of ctminh@node2.supernodexp.hpc, owner = ctminh@node2.supernodexp.hpc, job name = lu-decomp, queue = workq
02/13/2018 18:00:44;0100;Server@node2;Req;;Type 1 request received from ctminh@node2.supernodexp.hpc, sock=16
02/13/2018 18:00:44;0100;Server@node2;Req;;Type 3 request received from ctminh@node2.supernodexp.hpc, sock=16
02/13/2018 18:00:44;0100;Server@node2;Req;;Type 5 request received from ctminh@node2.supernodexp.hpc, sock=16
02/13/2018 18:00:44;0100;Server@node2;Job;979.node2.supernodexp.hpc;enqueuing into workq, state 1 hop 1
02/13/2018 18:00:44;0008;Server@node2;Job;979.node2.supernodexp.hpc;Job Queued at request of ctminh@node2.supernodexp.hpc, owner = ctminh@node2.supernodexp.hpc, job name = jacobi, queue = workq
02/13/2018 18:00:44;0100;Server@node2;Req;;Type 1 request received from ctminh@node2.supernodexp.hpc, sock=16
02/13/2018 18:00:44;0100;Server@node2;Req;;Type 11 request received from Scheduler@node2.supernodexp.hpc, sock=20
02/13/2018 18:00:44;0008;Server@node2;Job;974.node2.supernodexp.hpc;Job Modified at request of Scheduler@node2.supernodexp.hpc
02/13/2018 18:00:44;0100;Server@node2;Req;;Type 3 request received from ctminh@node2.supernodexp.hpc, sock=16
02/13/2018 18:00:44;0100;Server@node2;Req;;Type 11 request received from Scheduler@node2.supernodexp.hpc, sock=20
02/13/2018 18:00:44;0008;Server@node2;Job;975.node2.supernodexp.hpc;Job Modified at request of Scheduler@node2.supernodexp.hpc
02/13/2018 18:00:44;0100;Server@node2;Req;;Type 5 request received from ctminh@node2.supernodexp.hpc, sock=16
02/13/2018 18:00:44;0100;Server@node2;Job;980.node2.supernodexp.hpc;enqueuing into workq, state 1 hop 1
02/13/2018 18:00:44;0008;Server@node2;Job;980.node2.supernodexp.hpc;Job Queued at request of ctminh@node2.supernodexp.hpc, owner = ctminh@node2.supernodexp.hpc, job name = vectorization, queue = workq
02/13/2018 18:00:44;0100;Server@node2;Req;;Type 11 request received from Scheduler@node2.supernodexp.hpc, sock=20
02/13/2018 18:00:44;0008;Server@node2;Job;976.node2.supernodexp.hpc;Job Modified at request of Scheduler@node2.supernodexp.hpc
02/13/2018 18:00:44;0100;Server@node2;Req;;Type 11 request received from Scheduler@node2.supernodexp.hpc, sock=20
02/13/2018 18:00:44;0008;Server@node2;Job;977.node2.supernodexp.hpc;Job Modified at request of Scheduler@node2.supernodexp.hpc
02/13/2018 18:00:44;0100;Server@node2;Req;;Type 11 request received from Scheduler@node2.supernodexp.hpc, sock=20
02/13/2018 18:00:44;0008;Server@node2;Job;973.node2.supernodexp.hpc;Job Modified at request of Scheduler@node2.supernodexp.hpc
02/13/2018 18:00:44;0040;Server@node2;Svr;node2.supernodexp.hpc;Scheduler sent command 1
02/13/2018 18:00:44;0040;Server@node2;Svr;node2.supernodexp.hpc;Scheduler sent command 0
02/13/2018 18:00:44;0100;Server@node2;Req;;Type 21 request received from Scheduler@node2.supernodexp.hpc, sock=20
02/13/2018 18:00:44;0100;Server@node2;Req;;Type 81 request received from Scheduler@node2.supernodexp.hpc, sock=20
02/13/2018 18:00:44;0100;Server@node2;Req;;Type 71 request received from Scheduler@node2.supernodexp.hpc, sock=20
02/13/2018 18:00:44;0100;Server@node2;Req;;Type 58 request received from Scheduler@node2.supernodexp.hpc, sock=20
02/13/2018 18:00:44;0100;Server@node2;Req;;Type 20 request received from Scheduler@node2.supernodexp.hpc, sock=20
02/13/2018 18:00:44;0100;Server@node2;Req;;Type 51 request received from Scheduler@node2.supernodexp.hpc, sock=20
02/13/2018 18:00:44;0100;Server@node2;Req;;Type 11 request received from Scheduler@node2.supernodexp.hpc, sock=20
02/13/2018 18:00:44;0008;Server@node2;Job;971.node2.supernodexp.hpc;Job Modified at request of Scheduler@node2.supernodexp.hpc
02/13/2018 18:00:44;0100;Server@node2;Req;;Type 11 request received from Scheduler@node2.supernodexp.hpc, sock=20
02/13/2018 18:00:44;0008;Server@node2;Job;980.node2.supernodexp.hpc;Job Modified at request of Scheduler@node2.supernodexp.hpc
02/13/2018 18:00:44;0100;Server@node2;Req;;Type 11 request received from Scheduler@node2.supernodexp.hpc, sock=20
02/13/2018 18:00:44;0008;Server@node2;Job;979.node2.supernodexp.hpc;Job Modified at request of Scheduler@node2.supernodexp.hpc
02/13/2018 18:00:44;0100;Server@node2;Req;;Type 11 request received from Scheduler@node2.supernodexp.hpc, sock=20
02/13/2018 18:00:44;0008;Server@node2;Job;978.node2.supernodexp.hpc;Job Modified at request of Scheduler@node2.supernodexp.hpc
02/13/2018 18:00:49;0080;Server@node2;Job;855.node2.supernodexp.hpc;Obit received momhop:1 serverhop:1 state:4 substate:42
02/13/2018 18:00:50;0010;Server@node2;Job;855.node2.supernodexp.hpc;Exit_status=0 resources_used.cpupercent=2404 resources_used.cput=00:10:22 resources_used.mem=1557276kb resources_used.ncpus=24 resources_used.vmem=3509008kb resources_used.walltime=00:00:26
02/13/2018 18:00:50;0100;Server@node2;Job;855.node2.supernodexp.hpc;dequeuing from workq, state 5
02/13/2018 18:00:50;0040;Server@node2;Svr;node2.supernodexp.hpc;Scheduler sent command 2
02/13/2018 18:00:50;0040;Server@node2;Svr;node2.supernodexp.hpc;Scheduler sent command 0
02/13/2018 18:00:50;0100;Server@node2;Req;;Type 21 request received from Scheduler@node2.supernodexp.hpc, sock=20
02/13/2018 18:00:50;0100;Server@node2;Req;;Type 81 request received from Scheduler@node2.supernodexp.hpc, sock=20
02/13/2018 18:00:50;0100;Server@node2;Req;;Type 71 request received from Scheduler@node2.supernodexp.hpc, sock=20
02/13/2018 18:00:50;0100;Server@node2;Req;;Type 58 request received from Scheduler@node2.supernodexp.hpc, sock=20
02/13/2018 18:00:50;0100;Server@node2;Req;;Type 20 request received from Scheduler@node2.supernodexp.hpc, sock=20
02/13/2018 18:00:50;0100;Server@node2;Req;;Type 51 request received from Scheduler@node2.supernodexp.hpc, sock=20
02/13/2018 18:00:50;0100;Server@node2;Req;;Type 23 request received from Scheduler@node2.supernodexp.hpc, sock=20
02/13/2018 18:00:50;0008;Server@node2;Job;978.node2.supernodexp.hpc;Job Run at request of Scheduler@node2.supernodexp.hpc on exec_vnode (node13:ncpus=24:mem=1048576kb)
02/13/2018 18:00:50;0001;Server@node2;Svr;Server@node2;Success (0) in req_runjob2, return value of svr_startjob is 0
02/13/2018 18:00:50;0100;Server@node2;Req;;Type 11 request received from Scheduler@node2.supernodexp.hpc, sock=20
02/13/2018 18:00:50;0008;Server@node2;Job;971.node2.supernodexp.hpc;Job Modified at request of Scheduler@node2.supernodexp.hpc
02/13/2018 18:00:51;0080;Server@node2;Job;912.node2.supernodexp.hpc;Obit received momhop:1 serverhop:1 state:4 substate:42
02/13/2018 18:00:52;0010;Server@node2;Job;912.node2.supernodexp.hpc;Exit_status=0 resources_used.cpupercent=2290 resources_used.cput=00:10:22 resources_used.mem=1552388kb resources_used.ncpus=24 resources_used.vmem=3509008kb resources_used.walltime=00:00:26
02/13/2018 18:00:52;0100;Server@node2;Job;912.node2.supernodexp.hpc;dequeuing from workq, state 5
02/13/2018 18:00:52;0040;Server@node2;Svr;node2.supernodexp.hpc;Scheduler sent command 2
02/13/2018 18:00:52;0040;Server@node2;Svr;node2.supernodexp.hpc;Scheduler sent command 0
02/13/2018 18:00:52;0100;Server@node2;Req;;Type 21 request received from Scheduler@node2.supernodexp.hpc, sock=20
02/13/2018 18:00:52;0100;Server@node2;Req;;Type 81 request received from Scheduler@node2.supernodexp.hpc, sock=20
02/13/2018 18:00:52;0100;Server@node2;Req;;Type 71 request received from Scheduler@node2.supernodexp.hpc, sock=20
02/13/2018 18:00:52;0100;Server@node2;Req;;Type 58 request received from Scheduler@node2.supernodexp.hpc, sock=20
02/13/2018 18:00:52;0100;Server@node2;Req;;Type 20 request received from Scheduler@node2.supernodexp.hpc, sock=20
02/13/2018 18:00:52;0100;Server@node2;Req;;Type 51 request received from Scheduler@node2.supernodexp.hpc, sock=20
02/13/2018 18:00:52;0100;Server@node2;Req;;Type 11 request received from Scheduler@node2.supernodexp.hpc, sock=20
02/13/2018 18:00:52;0008;Server@node2;Job;971.node2.supernodexp.hpc;Job Modified at request of Scheduler@node2.supernodexp.hpc
02/13/2018 18:00:52;0080;Server@node2;Job;978.node2.supernodexp.hpc;Obit received momhop:1 serverhop:1 state:4 substate:42
02/13/2018 18:00:53;0010;Server@node2;Job;978.node2.supernodexp.hpc;Exit_status=0 resources_used.cpupercent=109 resources_used.cput=00:00:35 resources_used.mem=1296796kb resources_used.ncpus=24 resources_used.vmem=3151052kb resources_used.walltime=00:00:02
02/13/2018 18:00:53;0100;Server@node2;Job;978.node2.supernodexp.hpc;dequeuing from workq, state 5
02/13/2018 18:00:53;0040;Server@node2;Svr;node2.supernodexp.hpc;Scheduler sent command 2
02/13/2018 18:00:53;0040;Server@node2;Svr;node2.supernodexp.hpc;Scheduler sent command 0
02/13/2018 18:00:53;0100;Server@node2;Req;;Type 21 request received from Scheduler@node2.supernodexp.hpc, sock=20
02/13/2018 18:00:53;0100;Server@node2;Req;;Type 81 request received from Scheduler@node2.supernodexp.hpc, sock=20
02/13/2018 18:00:53;0100;Server@node2;Req;;Type 71 request received from Scheduler@node2.supernodexp.hpc, sock=20
02/13/2018 18:00:53;0100;Server@node2;Req;;Type 58 request received from Scheduler@node2.supernodexp.hpc, sock=20
02/13/2018 18:00:53;0100;Server@node2;Req;;Type 20 request received from Scheduler@node2.supernodexp.hpc, sock=20
02/13/2018 18:00:53;0100;Server@node2;Req;;Type 51 request received from Scheduler@node2.supernodexp.hpc, sock=20
02/13/2018 18:00:53;0100;Server@node2;Req;;Type 23 request received from Scheduler@node2.supernodexp.hpc, sock=20
02/13/2018 18:00:53;0008;Server@node2;Job;971.node2.supernodexp.hpc;Job Run at request of Scheduler@node2.supernodexp.hpc on exec_vnode (node13:ncpus=32:mem=2097152kb)
02/13/2018 18:00:53;0001;Server@node2;Svr;Server@node2;Success (0) in req_runjob2, return value of svr_startjob is 0
02/13/2018 18:00:53;0100;Server@node2;Req;;Type 23 request received from Scheduler@node2.supernodexp.hpc, sock=20
02/13/2018 18:00:53;0008;Server@node2;Job;974.node2.supernodexp.hpc;Job Run at request of Scheduler@node2.supernodexp.hpc on exec_vnode (node13:ncpus=8:mem=3145728kb)
02/13/2018 18:00:53;0001;Server@node2;Svr;Server@node2;Success (0) in req_runjob2, return value of svr_startjob is 0
02/13/2018 18:00:53;0100;Server@node2;Req;;Type 23 request received from Scheduler@node2.supernodexp.hpc, sock=20
02/13/2018 18:00:53;0008;Server@node2;Job;975.node2.supernodexp.hpc;Job Run at request of Scheduler@node2.supernodexp.hpc on exec_vnode (node13:ncpus=8:mem=3145728kb)
02/13/2018 18:00:53;0001;Server@node2;Svr;Server@node2;Success (0) in req_runjob2, return value of svr_startjob is 0
02/13/2018 18:00:53;0100;Server@node2;Req;;Type 11 request received from Scheduler@node2.supernodexp.hpc, sock=20
02/13/2018 18:00:53;0008;Server@node2;Job;980.node2.supernodexp.hpc;Job Modified at request of Scheduler@node2.supernodexp.hpc
02/13/2018 18:00:55;0080;Server@node2;Job;974.node2.supernodexp.hpc;Obit received momhop:1 serverhop:1 state:4 substate:42
02/13/2018 18:00:55;0080;Server@node2;Job;975.node2.supernodexp.hpc;Obit received momhop:1 serverhop:1 state:4 substate:42
02/13/2018 18:00:57;0010;Server@node2;Job;974.node2.supernodexp.hpc;Exit_status=0 resources_used.cpupercent=498 resources_used.cput=00:00:10 resources_used.mem=0kb resources_used.ncpus=8 resources_used.vmem=0kb resources_used.walltime=00:00:02
02/13/2018 18:00:57;0100;Server@node2;Job;974.node2.supernodexp.hpc;dequeuing from workq, state 5
02/13/2018 18:00:57;0010;Server@node2;Job;975.node2.supernodexp.hpc;Exit_status=0 resources_used.cpupercent=498 resources_used.cput=00:00:10 resources_used.mem=0kb resources_used.ncpus=8 resources_used.vmem=0kb resources_used.walltime=00:00:02
02/13/2018 18:00:57;0100;Server@node2;Job;975.node2.supernodexp.hpc;dequeuing from workq, state 5
02/13/2018 18:00:57;0040;Server@node2;Svr;node2.supernodexp.hpc;Scheduler sent command 2
02/13/2018 18:00:57;0040;Server@node2;Svr;node2.supernodexp.hpc;Scheduler sent command 0
02/13/2018 18:00:57;0100;Server@node2;Req;;Type 21 request received from Scheduler@node2.supernodexp.hpc, sock=20
02/13/2018 18:00:57;0100;Server@node2;Req;;Type 81 request received from Scheduler@node2.supernodexp.hpc, sock=20
02/13/2018 18:00:57;0100;Server@node2;Req;;Type 71 request received from Scheduler@node2.supernodexp.hpc, sock=20
02/13/2018 18:00:57;0100;Server@node2;Req;;Type 58 request received from Scheduler@node2.supernodexp.hpc, sock=20
02/13/2018 18:00:57;0100;Server@node2;Req;;Type 20 request received from Scheduler@node2.supernodexp.hpc, sock=20
02/13/2018 18:00:57;0100;Server@node2;Req;;Type 51 request received from Scheduler@node2.supernodexp.hpc, sock=20
02/13/2018 18:00:57;0100;Server@node2;Req;;Type 23 request received from Scheduler@node2.supernodexp.hpc, sock=20
02/13/2018 18:00:57;0008;Server@node2;Job;980.node2.supernodexp.hpc;Job Run at request of Scheduler@node2.supernodexp.hpc on exec_vnode (node13:ncpus=12:mem=1048576kb)
02/13/2018 18:00:57;0001;Server@node2;Svr;Server@node2;Success (0) in req_runjob2, return value of svr_startjob is 0
02/13/2018 18:00:57;0100;Server@node2;Req;;Type 11 request received from Scheduler@node2.supernodexp.hpc, sock=20
02/13/2018 18:00:57;0008;Server@node2;Job;976.node2.supernodexp.hpc;Job Modified at request of Scheduler@node2.supernodexp.hpc
02/13/2018 18:00:57;0080;Server@node2;Job;971.node2.supernodexp.hpc;Obit received momhop:1 serverhop:1 state:4 substate:42
02/13/2018 18:00:59;0010;Server@node2;Job;971.node2.supernodexp.hpc;Exit_status=0 resources_used.cpupercent=50 resources_used.cput=00:00:04 resources_used.mem=537024kb resources_used.ncpus=32 resources_used.vmem=867312kb resources_used.walltime=00:00:04
02/13/2018 18:00:59;0100;Server@node2;Job;971.node2.supernodexp.hpc;dequeuing from workq, state 5
02/13/2018 18:00:59;0040;Server@node2;Svr;node2.supernodexp.hpc;Scheduler sent command 2
02/13/2018 18:00:59;0040;Server@node2;Svr;node2.supernodexp.hpc;Scheduler sent command 0
02/13/2018 18:00:59;0100;Server@node2;Req;;Type 21 request received from Scheduler@node2.supernodexp.hpc, sock=20
02/13/2018 18:00:59;0100;Server@node2;Req;;Type 81 request received from Scheduler@node2.supernodexp.hpc, sock=20
02/13/2018 18:00:59;0100;Server@node2;Req;;Type 71 request received from Scheduler@node2.supernodexp.hpc, sock=20
02/13/2018 18:00:59;0100;Server@node2;Req;;Type 58 request received from Scheduler@node2.supernodexp.hpc, sock=20
02/13/2018 18:00:59;0100;Server@node2;Req;;Type 20 request received from Scheduler@node2.supernodexp.hpc, sock=20
02/13/2018 18:00:59;0100;Server@node2;Req;;Type 51 request received from Scheduler@node2.supernodexp.hpc, sock=20
02/13/2018 18:00:59;0100;Server@node2;Req;;Type 23 request received from Scheduler@node2.supernodexp.hpc, sock=20
02/13/2018 18:00:59;0008;Server@node2;Job;976.node2.supernodexp.hpc;Job Run at request of Scheduler@node2.supernodexp.hpc on exec_vnode (node13:ncpus=12:mem=1048576kb)
02/13/2018 18:00:59;0001;Server@node2;Svr;Server@node2;Success (0) in req_runjob2, return value of svr_startjob is 0
02/13/2018 18:00:59;0100;Server@node2;Req;;Type 23 request received from Scheduler@node2.supernodexp.hpc, sock=20
02/13/2018 18:00:59;0008;Server@node2;Job;977.node2.supernodexp.hpc;Job Run at request of Scheduler@node2.supernodexp.hpc on exec_vnode (node13:ncpus=12:mem=1048576kb)
02/13/2018 18:00:59;0001;Server@node2;Svr;Server@node2;Success (0) in req_runjob2, return value of svr_startjob is 0
02/13/2018 18:00:59;0100;Server@node2;Req;;Type 11 request received from Scheduler@node2.supernodexp.hpc, sock=20
02/13/2018 18:00:59;0008;Server@node2;Job;925.node2.supernodexp.hpc;Job Modified at request of Scheduler@node2.supernodexp.hpc
02/13/2018 18:01:03;0080;Server@node2;Job;980.node2.supernodexp.hpc;Obit received momhop:1 serverhop:1 state:4 substate:42
02/13/2018 18:01:04;0010;Server@node2;Job;980.node2.supernodexp.hpc;Exit_status=0 resources_used.cpupercent=511 resources_used.cput=00:01:11 resources_used.mem=29548kb resources_used.ncpus=12 resources_used.vmem=1125532kb resources_used.walltime=00:00:07
02/13/2018 18:01:04;0100;Server@node2;Job;980.node2.supernodexp.hpc;dequeuing from workq, state 5
02/13/2018 18:01:04;0040;Server@node2;Svr;node2.supernodexp.hpc;Scheduler sent command 2
02/13/2018 18:01:04;0040;Server@node2;Svr;node2.supernodexp.hpc;Scheduler sent command 0
02/13/2018 18:01:04;0100;Server@node2;Req;;Type 21 request received from Scheduler@node2.supernodexp.hpc, sock=20
02/13/2018 18:01:04;0100;Server@node2;Req;;Type 81 request received from Scheduler@node2.supernodexp.hpc, sock=20
02/13/2018 18:01:04;0100;Server@node2;Req;;Type 71 request received from Scheduler@node2.supernodexp.hpc, sock=20
02/13/2018 18:01:04;0100;Server@node2;Req;;Type 58 request received from Scheduler@node2.supernodexp.hpc, sock=20
02/13/2018 18:01:04;0100;Server@node2;Req;;Type 20 request received from Scheduler@node2.supernodexp.hpc, sock=20
02/13/2018 18:01:04;0100;Server@node2;Req;;Type 51 request received from Scheduler@node2.supernodexp.hpc, sock=20
02/13/2018 18:01:04;0100;Server@node2;Req;;Type 23 request received from Scheduler@node2.supernodexp.hpc, sock=20
02/13/2018 18:01:04;0008;Server@node2;Job;925.node2.supernodexp.hpc;Job Run at request of Scheduler@node2.supernodexp.hpc on exec_vnode (node13:ncpus=24:mem=2097152kb)
02/13/2018 18:01:04;0001;Server@node2;Svr;Server@node2;Success (0) in req_runjob2, return value of svr_startjob is 0
02/13/2018 18:01:04;0100;Server@node2;Req;;Type 11 request received from Scheduler@node2.supernodexp.hpc, sock=20
02/13/2018 18:01:04;0008;Server@node2;Job;952.node2.supernodexp.hpc;Job Modified at request of Scheduler@node2.supernodexp.hpc
02/13/2018 18:01:07;0080;Server@node2;Job;976.node2.supernodexp.hpc;Obit received momhop:1 serverhop:1 state:4 substate:42
02/13/2018 18:01:07;0080;Server@node2;Job;977.node2.supernodexp.hpc;Obit received momhop:1 serverhop:1 state:4 substate:42
02/13/2018 18:01:09;0010;Server@node2;Job;976.node2.supernodexp.hpc;Exit_status=0 resources_used.cpupercent=79 resources_used.cput=00:00:08 resources_used.mem=11624kb resources_used.ncpus=12 resources_used.vmem=343400kb resources_used.walltime=00:00:09
02/13/2018 18:01:09;0100;Server@node2;Job;976.node2.supernodexp.hpc;dequeuing from workq, state 5
02/13/2018 18:01:09;0040;Server@node2;Svr;node2.supernodexp.hpc;Scheduler sent command 2
02/13/2018 18:01:09;0040;Server@node2;Svr;node2.supernodexp.hpc;Scheduler sent command 0
02/13/2018 18:01:09;0100;Server@node2;Req;;Type 21 request received from Scheduler@node2.supernodexp.hpc, sock=20
02/13/2018 18:01:09;0100;Server@node2;Req;;Type 81 request received from Scheduler@node2.supernodexp.hpc, sock=20
02/13/2018 18:01:09;0100;Server@node2;Req;;Type 71 request received from Scheduler@node2.supernodexp.hpc, sock=20
02/13/2018 18:01:09;0100;Server@node2;Req;;Type 58 request received from Scheduler@node2.supernodexp.hpc, sock=20
02/13/2018 18:01:09;0100;Server@node2;Req;;Type 20 request received from Scheduler@node2.supernodexp.hpc, sock=20
02/13/2018 18:01:09;0100;Server@node2;Req;;Type 51 request received from Scheduler@node2.supernodexp.hpc, sock=20
02/13/2018 18:01:09;0100;Server@node2;Req;;Type 11 request received from Scheduler@node2.supernodexp.hpc, sock=20
02/13/2018 18:01:09;0008;Server@node2;Job;952.node2.supernodexp.hpc;Job Modified at request of Scheduler@node2.supernodexp.hpc
02/13/2018 18:01:09;0010;Server@node2;Job;977.node2.supernodexp.hpc;Exit_status=0 resources_used.cpupercent=79 resources_used.cput=00:00:08 resources_used.mem=11620kb resources_used.ncpus=12 resources_used.vmem=343400kb resources_used.walltime=00:00:09
02/13/2018 18:01:09;0100;Server@node2;Job;977.node2.supernodexp.hpc;dequeuing from workq, state 5
02/13/2018 18:01:09;0040;Server@node2;Svr;node2.supernodexp.hpc;Scheduler sent command 2
02/13/2018 18:01:09;0040;Server@node2;Svr;node2.supernodexp.hpc;Scheduler sent command 0
02/13/2018 18:01:09;0100;Server@node2;Req;;Type 21 request received from Scheduler@node2.supernodexp.hpc, sock=20
02/13/2018 18:01:09;0100;Server@node2;Req;;Type 81 request received from Scheduler@node2.supernodexp.hpc, sock=20
02/13/2018 18:01:09;0100;Server@node2;Req;;Type 71 request received from Scheduler@node2.supernodexp.hpc, sock=20
02/13/2018 18:01:09;0100;Server@node2;Req;;Type 58 request received from Scheduler@node2.supernodexp.hpc, sock=20
02/13/2018 18:01:09;0100;Server@node2;Req;;Type 20 request received from Scheduler@node2.supernodexp.hpc, sock=20
02/13/2018 18:01:09;0100;Server@node2;Req;;Type 51 request received from Scheduler@node2.supernodexp.hpc, sock=20
02/13/2018 18:01:09;0100;Server@node2;Req;;Type 23 request received from Scheduler@node2.supernodexp.hpc, sock=20
02/13/2018 18:01:09;0008;Server@node2;Job;952.node2.supernodexp.hpc;Job Run at request of Scheduler@node2.supernodexp.hpc on exec_vnode (node13:ncpus=24:mem=2097152kb)
02/13/2018 18:01:09;0001;Server@node2;Svr;Server@node2;Success (0) in req_runjob2, return value of svr_startjob is 0
02/13/2018 18:01:09;0100;Server@node2;Req;;Type 11 request received from Scheduler@node2.supernodexp.hpc, sock=20
02/13/2018 18:01:09;0008;Server@node2;Job;839.node2.supernodexp.hpc;Job Modified at request of Scheduler@node2.supernodexp.hpc
02/13/2018 18:01:32;0080;Server@node2;Job;925.node2.supernodexp.hpc;Obit received momhop:1 serverhop:1 state:4 substate:42
02/13/2018 18:01:33;0100;Server@node2;Req;;Type 1 request received from ctminh@node2.supernodexp.hpc, sock=16
02/13/2018 18:01:33;0100;Server@node2;Req;;Type 3 request received from ctminh@node2.supernodexp.hpc, sock=16
02/13/2018 18:01:33;0100;Server@node2;Req;;Type 5 request received from ctminh@node2.supernodexp.hpc, sock=16
02/13/2018 18:01:33;0100;Server@node2;Job;981.node2.supernodexp.hpc;enqueuing into workq, state 1 hop 1
02/13/2018 18:01:33;0008;Server@node2;Job;981.node2.supernodexp.hpc;Job Queued at request of ctminh@node2.supernodexp.hpc, owner = ctminh@node2.supernodexp.hpc, job name = histogram, queue = workq
02/13/2018 18:01:33;0040;Server@node2;Svr;node2.supernodexp.hpc;Scheduler sent command 1
02/13/2018 18:01:33;0040;Server@node2;Svr;node2.supernodexp.hpc;Scheduler sent command 0
02/13/2018 18:01:33;0100;Server@node2;Req;;Type 21 request received from Scheduler@node2.supernodexp.hpc, sock=20
02/13/2018 18:01:33;0100;Server@node2;Req;;Type 81 request received from Scheduler@node2.supernodexp.hpc, sock=20
02/13/2018 18:01:33;0100;Server@node2;Req;;Type 71 request received from Scheduler@node2.supernodexp.hpc, sock=20
02/13/2018 18:01:33;0100;Server@node2;Req;;Type 58 request received from Scheduler@node2.supernodexp.hpc, sock=20
02/13/2018 18:01:33;0100;Server@node2;Req;;Type 1 request received from ctminh@node2.supernodexp.hpc, sock=16
02/13/2018 18:01:33;0100;Server@node2;Hook;_pbs_python_event_set;Restarting Python interpreter to reduce mem usage
02/13/2018 18:01:33;0100;Server@node2;Svr;Server@node2;--> Stopping Python interpreter <--
02/13/2018 18:01:33;0100;Server@node2;Svr;Server@node2;--> Python Interpreter started, compiled with version:'2.7.5' <--
02/13/2018 18:01:33;0100;Server@node2;Svr;Server@node2;sys.modules= {'pbs.v1._svr_types': <module 'pbs.v1._svr_types' from '/opt/pbs/lib/python/altair/pbs/v1/_svr_types.pyo'>, 'copy_reg': <module 'copy_reg' from '/usr/lib64/python2.7/copy_reg.pyo'>, 'pbs.v1._pbs_v1': None, '__main__': <module '__main__' (built-in)>, '__builtin__': <module '__builtin__' (built-in)>, '_pbs_v1.svr_types': <module '_pbs_v1.svr_types' (built-in)>, 'encodings': <module 'encodings' from '/usr/lib64/python2.7/encodings/__init__.pyo'>, 'encodings.encodings': None, 'abc': <module 'abc' from '/usr/lib64/python2.7/abc.pyo'>, 'pbs._pbs_v1': None, 'posixpath': <module 'posixpath' from '/usr/lib64/python2.7/posixpath.pyo'>, '_weakrefset': <module '_weakrefset' from '/usr/lib64/python2.7/_weakrefset.pyo'>, 'pbs.v1': <module 'pbs.v1' from '/opt/pbs/lib/python/altair/pbs/v1/__init__.pyo'>, 'errno': <module 'errno' (built-in)>, 'encodings.codecs': None, 'pbs.v1._export_types': <module 'pbs.v1._export_types' from '/opt/pbs/lib/python/altair/pbs/v1/_export_types.pyo'>, 'pbs.v1.os': None, '_abcoll': <module '_abcoll' from '/usr/lib64/python2.7/_abcoll.pyo'>, 'os.path': <module 'posixpath' from '/usr/lib64/python2.7/posixpath.pyo'>, 'UserDict': <module 'UserDict' from '/usr/lib64/python2.7/UserDict.pyo'>, '_warnings': <module '_warnings' (built-in)>, 'genericpath': <module 'genericpath' from '/usr/lib64/python2.7/genericpath.pyo'>, 'stat': <module 'stat' from '/usr/lib64/python2.7/stat.pyo'>, 'zipimport': <module 'zipimport' (built-in)>, 'encodings.__builtin__': None, 'pbs.pbs': None, 'warnings': <module 'warnings' from '/usr/lib64/python2.7/warnings.pyo'>, '_codecs': <module '_codecs' (built-in)>, 'encodings.ascii': <module 'encodings.ascii' from '/usr/lib64/python2.7/encodings/ascii.pyo'>, 'sys': <module 'sys' (built-in)>, 'pbs.v1._base_types': <module 'pbs.v1._base_types' from '/opt/pbs/lib/python/altair/pbs/v1/_base_types.pyo'>, 'pbs.v1.sys': None, 'codecs': <module 'codecs' from '/usr/lib64/python2.7/codecs.pyo'>, 'types': <module 'types' from '/usr/lib64/python2.7/types.pyo'>, 'pbs': <module 'pbs' from '/opt/pbs/lib/python/altair/pbs/__init__.pyo'>, 'os': <module 'os' from '/usr/lib64/python2.7/os.pyo'>, 'signal': <module 'signal' (built-in)>, 'linecache': <module 'linecache' from '/usr/lib64/python2.7/linecache.pyo'>, '_pbs_v1': <module '_pbs_v1' (built-in)>, 'posix': <module 'posix' (built-in)>, 'encodings.aliases': <module 'encodings.aliases' from '/usr/lib64/python2.7/encodings/aliases.pyo'>, 'exceptions': <module 'exceptions' (built-in)>, 'pbs.v1._exc_types': <module 'pbs.v1._exc_types' from '/opt/pbs/lib/python/altair/pbs/v1/_exc_types.pyo'>, '_weakref': <module '_weakref' (built-in)>}
02/13/2018 18:01:33;0106;Server@node2;Svr;Server@node2;BEGIN setting up all resource attributes 
02/13/2018 18:01:33;0106;Server@node2;Svr;Server@node2;DONE setting up all resource attributes, number set <51>
02/13/2018 18:01:33;0106;Server@node2;Svr;Server@node2;BEGIN setting up all queue attributes 
02/13/2018 18:01:33;0106;Server@node2;Svr;Server@node2;DONE setting up all queue attributes, number set <55>
02/13/2018 18:01:33;0106;Server@node2;Svr;Server@node2;BEGIN setting up all job attributes 
02/13/2018 18:01:33;0106;Server@node2;Svr;Server@node2;DONE setting up all job attributes, number set <94>
02/13/2018 18:01:33;0106;Server@node2;Svr;Server@node2;BEGIN setting up all server attributes 
02/13/2018 18:01:33;0106;Server@node2;Svr;Server@node2;DONE setting up all server attributes, number set <88>
02/13/2018 18:01:33;0106;Server@node2;Svr;Server@node2;BEGIN setting up all reservation attributes 
02/13/2018 18:01:33;0106;Server@node2;Svr;Server@node2;DONE setting up all reservation attributes, number set <43>
02/13/2018 18:01:33;0106;Server@node2;Svr;Server@node2;BEGIN setting up all vnode attributes 
02/13/2018 18:01:33;0106;Server@node2;Svr;Server@node2;DONE setting up all vnode attributes, number set <28>
02/13/2018 18:01:33;0100;Server@node2;Hook;_pbs_python_event_set;Current memory usage: VmSize=324728kB, VmRSS=16264kB
02/13/2018 18:01:33;0100;Server@node2;Req;;Type 3 request received from ctminh@node2.supernodexp.hpc, sock=16
02/13/2018 18:01:33;0100;Server@node2;Req;;Type 5 request received from ctminh@node2.supernodexp.hpc, sock=16
02/13/2018 18:01:33;0100;Server@node2;Job;982.node2.supernodexp.hpc;enqueuing into workq, state 1 hop 1
02/13/2018 18:01:33;0008;Server@node2;Job;982.node2.supernodexp.hpc;Job Queued at request of ctminh@node2.supernodexp.hpc, owner = ctminh@node2.supernodexp.hpc, job name = matrix-x-vector, queue = workq
02/13/2018 18:01:33;0100;Server@node2;Req;;Type 20 request received from Scheduler@node2.supernodexp.hpc, sock=20
02/13/2018 18:01:33;0100;Server@node2;Req;;Type 51 request received from Scheduler@node2.supernodexp.hpc, sock=20
02/13/2018 18:01:33;0100;Server@node2;Req;;Type 1 request received from ctminh@node2.supernodexp.hpc, sock=16
02/13/2018 18:01:33;0100;Server@node2;Req;;Type 3 request received from ctminh@node2.supernodexp.hpc, sock=16
02/13/2018 18:01:33;0100;Server@node2;Req;;Type 5 request received from ctminh@node2.supernodexp.hpc, sock=16
02/13/2018 18:01:33;0100;Server@node2;Job;983.node2.supernodexp.hpc;enqueuing into workq, state 1 hop 1
02/13/2018 18:01:33;0008;Server@node2;Job;983.node2.supernodexp.hpc;Job Queued at request of ctminh@node2.supernodexp.hpc, owner = ctminh@node2.supernodexp.hpc, job name = histogram, queue = workq
02/13/2018 18:01:33;0100;Server@node2;Req;;Type 1 request received from ctminh@node2.supernodexp.hpc, sock=16
02/13/2018 18:01:33;0100;Server@node2;Req;;Type 3 request received from ctminh@node2.supernodexp.hpc, sock=16
02/13/2018 18:01:33;0100;Server@node2;Req;;Type 5 request received from ctminh@node2.supernodexp.hpc, sock=16
02/13/2018 18:01:33;0100;Server@node2;Job;984.node2.supernodexp.hpc;enqueuing into workq, state 1 hop 1
02/13/2018 18:01:33;0008;Server@node2;Job;984.node2.supernodexp.hpc;Job Queued at request of ctminh@node2.supernodexp.hpc, owner = ctminh@node2.supernodexp.hpc, job name = telemac3, queue = workq
02/13/2018 18:01:33;0100;Server@node2;Req;;Type 11 request received from Scheduler@node2.supernodexp.hpc, sock=20
02/13/2018 18:01:33;0008;Server@node2;Job;981.node2.supernodexp.hpc;Job Modified at request of Scheduler@node2.supernodexp.hpc
02/13/2018 18:01:33;0100;Server@node2;Req;;Type 11 request received from Scheduler@node2.supernodexp.hpc, sock=20
02/13/2018 18:01:33;0008;Server@node2;Job;839.node2.supernodexp.hpc;Job Modified at request of Scheduler@node2.supernodexp.hpc
02/13/2018 18:01:33;0100;Server@node2;Req;;Type 11 request received from Scheduler@node2.supernodexp.hpc, sock=20
02/13/2018 18:01:33;0008;Server@node2;Job;982.node2.supernodexp.hpc;Job Modified at request of Scheduler@node2.supernodexp.hpc
02/13/2018 18:01:33;0040;Server@node2;Svr;node2.supernodexp.hpc;Scheduler sent command 1
02/13/2018 18:01:33;0040;Server@node2;Svr;node2.supernodexp.hpc;Scheduler sent command 0
02/13/2018 18:01:33;0100;Server@node2;Req;;Type 21 request received from Scheduler@node2.supernodexp.hpc, sock=20
02/13/2018 18:01:33;0100;Server@node2;Req;;Type 81 request received from Scheduler@node2.supernodexp.hpc, sock=20
02/13/2018 18:01:33;0100;Server@node2;Req;;Type 71 request received from Scheduler@node2.supernodexp.hpc, sock=20
02/13/2018 18:01:33;0100;Server@node2;Req;;Type 58 request received from Scheduler@node2.supernodexp.hpc, sock=20
02/13/2018 18:01:33;0100;Server@node2;Req;;Type 20 request received from Scheduler@node2.supernodexp.hpc, sock=20
02/13/2018 18:01:33;0100;Server@node2;Req;;Type 51 request received from Scheduler@node2.supernodexp.hpc, sock=20
02/13/2018 18:01:33;0100;Server@node2;Req;;Type 11 request received from Scheduler@node2.supernodexp.hpc, sock=20
02/13/2018 18:01:33;0008;Server@node2;Job;983.node2.supernodexp.hpc;Job Modified at request of Scheduler@node2.supernodexp.hpc
02/13/2018 18:01:33;0100;Server@node2;Req;;Type 11 request received from Scheduler@node2.supernodexp.hpc, sock=20
02/13/2018 18:01:33;0008;Server@node2;Job;984.node2.supernodexp.hpc;Job Modified at request of Scheduler@node2.supernodexp.hpc
02/13/2018 18:01:33;0010;Server@node2;Job;925.node2.supernodexp.hpc;Exit_status=0 resources_used.cpupercent=2091 resources_used.cput=00:10:50 resources_used.mem=1554200kb resources_used.ncpus=24 resources_used.vmem=3513104kb resources_used.walltime=00:00:27
02/13/2018 18:01:33;0100;Server@node2;Job;925.node2.supernodexp.hpc;dequeuing from workq, state 5
02/13/2018 18:01:33;0040;Server@node2;Svr;node2.supernodexp.hpc;Scheduler sent command 2
02/13/2018 18:01:33;0040;Server@node2;Svr;node2.supernodexp.hpc;Scheduler sent command 0
02/13/2018 18:01:33;0100;Server@node2;Req;;Type 21 request received from Scheduler@node2.supernodexp.hpc, sock=20
02/13/2018 18:01:33;0100;Server@node2;Req;;Type 81 request received from Scheduler@node2.supernodexp.hpc, sock=20
02/13/2018 18:01:33;0100;Server@node2;Req;;Type 71 request received from Scheduler@node2.supernodexp.hpc, sock=20
02/13/2018 18:01:33;0100;Server@node2;Req;;Type 58 request received from Scheduler@node2.supernodexp.hpc, sock=20
02/13/2018 18:01:33;0100;Server@node2;Req;;Type 20 request received from Scheduler@node2.supernodexp.hpc, sock=20
02/13/2018 18:01:33;0100;Server@node2;Req;;Type 51 request received from Scheduler@node2.supernodexp.hpc, sock=20
02/13/2018 18:01:33;0100;Server@node2;Req;;Type 23 request received from Scheduler@node2.supernodexp.hpc, sock=20
02/13/2018 18:01:33;0008;Server@node2;Job;982.node2.supernodexp.hpc;Job Run at request of Scheduler@node2.supernodexp.hpc on exec_vnode (node13:ncpus=16:mem=5242880kb)
02/13/2018 18:01:33;0001;Server@node2;Svr;Server@node2;Success (0) in req_runjob2, return value of svr_startjob is 0
02/13/2018 18:01:33;0100;Server@node2;Req;;Type 11 request received from Scheduler@node2.supernodexp.hpc, sock=20
02/13/2018 18:01:33;0008;Server@node2;Job;981.node2.supernodexp.hpc;Job Modified at request of Scheduler@node2.supernodexp.hpc
02/13/2018 18:01:35;0080;Server@node2;Job;982.node2.supernodexp.hpc;Obit received momhop:1 serverhop:1 state:4 substate:42
02/13/2018 18:01:35;0080;Server@node2;Job;952.node2.supernodexp.hpc;Obit received momhop:1 serverhop:1 state:4 substate:42
02/13/2018 18:01:36;0010;Server@node2;Job;982.node2.supernodexp.hpc;Exit_status=0 resources_used.cpupercent=1200 resources_used.cput=00:00:12 resources_used.mem=0kb resources_used.ncpus=16 resources_used.vmem=0kb resources_used.walltime=00:00:01
02/13/2018 18:01:36;0100;Server@node2;Job;982.node2.supernodexp.hpc;dequeuing from workq, state 5
02/13/2018 18:01:36;0040;Server@node2;Svr;node2.supernodexp.hpc;Scheduler sent command 2
02/13/2018 18:01:36;0040;Server@node2;Svr;node2.supernodexp.hpc;Scheduler sent command 0
02/13/2018 18:01:36;0100;Server@node2;Req;;Type 21 request received from Scheduler@node2.supernodexp.hpc, sock=20
02/13/2018 18:01:36;0100;Server@node2;Req;;Type 81 request received from Scheduler@node2.supernodexp.hpc, sock=20
02/13/2018 18:01:36;0100;Server@node2;Req;;Type 71 request received from Scheduler@node2.supernodexp.hpc, sock=20
02/13/2018 18:01:36;0100;Server@node2;Req;;Type 58 request received from Scheduler@node2.supernodexp.hpc, sock=20
02/13/2018 18:01:36;0100;Server@node2;Req;;Type 20 request received from Scheduler@node2.supernodexp.hpc, sock=20
02/13/2018 18:01:36;0100;Server@node2;Req;;Type 51 request received from Scheduler@node2.supernodexp.hpc, sock=20
02/13/2018 18:01:36;0100;Server@node2;Req;;Type 11 request received from Scheduler@node2.supernodexp.hpc, sock=20
02/13/2018 18:01:36;0008;Server@node2;Job;981.node2.supernodexp.hpc;Job Modified at request of Scheduler@node2.supernodexp.hpc
02/13/2018 18:01:36;0010;Server@node2;Job;952.node2.supernodexp.hpc;Exit_status=0 resources_used.cpupercent=2225 resources_used.cput=00:10:14 resources_used.mem=1557984kb resources_used.ncpus=24 resources_used.vmem=3509008kb resources_used.walltime=00:00:27
02/13/2018 18:01:36;0100;Server@node2;Job;952.node2.supernodexp.hpc;dequeuing from workq, state 5
02/13/2018 18:01:36;0040;Server@node2;Svr;node2.supernodexp.hpc;Scheduler sent command 2
02/13/2018 18:01:36;0040;Server@node2;Svr;node2.supernodexp.hpc;Scheduler sent command 0
02/13/2018 18:01:36;0100;Server@node2;Req;;Type 21 request received from Scheduler@node2.supernodexp.hpc, sock=20
02/13/2018 18:01:36;0100;Server@node2;Req;;Type 81 request received from Scheduler@node2.supernodexp.hpc, sock=20
02/13/2018 18:01:36;0100;Server@node2;Req;;Type 71 request received from Scheduler@node2.supernodexp.hpc, sock=20
02/13/2018 18:01:36;0100;Server@node2;Req;;Type 58 request received from Scheduler@node2.supernodexp.hpc, sock=20
02/13/2018 18:01:36;0100;Server@node2;Req;;Type 20 request received from Scheduler@node2.supernodexp.hpc, sock=20
02/13/2018 18:01:36;0100;Server@node2;Req;;Type 51 request received from Scheduler@node2.supernodexp.hpc, sock=20
02/13/2018 18:01:36;0100;Server@node2;Req;;Type 23 request received from Scheduler@node2.supernodexp.hpc, sock=20
02/13/2018 18:01:36;0008;Server@node2;Job;981.node2.supernodexp.hpc;Job Run at request of Scheduler@node2.supernodexp.hpc on exec_vnode (node13:ncpus=32:mem=2097152kb)
02/13/2018 18:01:36;0001;Server@node2;Svr;Server@node2;Success (0) in req_runjob2, return value of svr_startjob is 0
02/13/2018 18:01:36;0100;Server@node2;Req;;Type 11 request received from Scheduler@node2.supernodexp.hpc, sock=20
02/13/2018 18:01:36;0008;Server@node2;Job;983.node2.supernodexp.hpc;Job Modified at request of Scheduler@node2.supernodexp.hpc
02/13/2018 18:01:40;0080;Server@node2;Job;981.node2.supernodexp.hpc;Obit received momhop:1 serverhop:1 state:4 substate:42
02/13/2018 18:01:41;0010;Server@node2;Job;981.node2.supernodexp.hpc;Exit_status=0 resources_used.cpupercent=75 resources_used.cput=00:00:03 resources_used.mem=0kb resources_used.ncpus=32 resources_used.vmem=0kb resources_used.walltime=00:00:04
02/13/2018 18:01:41;0100;Server@node2;Job;981.node2.supernodexp.hpc;dequeuing from workq, state 5
02/13/2018 18:01:41;0040;Server@node2;Svr;node2.supernodexp.hpc;Scheduler sent command 2
02/13/2018 18:01:41;0040;Server@node2;Svr;node2.supernodexp.hpc;Scheduler sent command 0
02/13/2018 18:01:41;0100;Server@node2;Req;;Type 21 request received from Scheduler@node2.supernodexp.hpc, sock=20
02/13/2018 18:01:41;0100;Server@node2;Req;;Type 81 request received from Scheduler@node2.supernodexp.hpc, sock=20
02/13/2018 18:01:41;0100;Server@node2;Req;;Type 71 request received from Scheduler@node2.supernodexp.hpc, sock=20
02/13/2018 18:01:41;0100;Server@node2;Req;;Type 58 request received from Scheduler@node2.supernodexp.hpc, sock=20
02/13/2018 18:01:41;0100;Server@node2;Req;;Type 20 request received from Scheduler@node2.supernodexp.hpc, sock=20
02/13/2018 18:01:41;0100;Server@node2;Req;;Type 51 request received from Scheduler@node2.supernodexp.hpc, sock=20
02/13/2018 18:01:42;0100;Server@node2;Req;;Type 23 request received from Scheduler@node2.supernodexp.hpc, sock=20
02/13/2018 18:01:42;0008;Server@node2;Job;983.node2.supernodexp.hpc;Job Run at request of Scheduler@node2.supernodexp.hpc on exec_vnode (node13:ncpus=32:mem=2097152kb)
02/13/2018 18:01:42;0001;Server@node2;Svr;Server@node2;Success (0) in req_runjob2, return value of svr_startjob is 0
02/13/2018 18:01:42;0100;Server@node2;Req;;Type 23 request received from Scheduler@node2.supernodexp.hpc, sock=20
02/13/2018 18:01:42;0008;Server@node2;Job;839.node2.supernodexp.hpc;Job Run at request of Scheduler@node2.supernodexp.hpc on exec_vnode (node13:ncpus=16:mem=2097152kb)
02/13/2018 18:01:42;0001;Server@node2;Svr;Server@node2;Success (0) in req_runjob2, return value of svr_startjob is 0
02/13/2018 18:01:42;0100;Server@node2;Req;;Type 11 request received from Scheduler@node2.supernodexp.hpc, sock=20
02/13/2018 18:01:42;0008;Server@node2;Job;840.node2.supernodexp.hpc;Job Modified at request of Scheduler@node2.supernodexp.hpc
02/13/2018 18:01:46;0080;Server@node2;Job;983.node2.supernodexp.hpc;Obit received momhop:1 serverhop:1 state:4 substate:42
02/13/2018 18:01:47;0010;Server@node2;Job;983.node2.supernodexp.hpc;Exit_status=0 resources_used.cpupercent=100 resources_used.cput=00:00:04 resources_used.mem=0kb resources_used.ncpus=32 resources_used.vmem=0kb resources_used.walltime=00:00:04
02/13/2018 18:01:47;0100;Server@node2;Job;983.node2.supernodexp.hpc;dequeuing from workq, state 5
02/13/2018 18:01:47;0040;Server@node2;Svr;node2.supernodexp.hpc;Scheduler sent command 2
02/13/2018 18:01:47;0040;Server@node2;Svr;node2.supernodexp.hpc;Scheduler sent command 0
02/13/2018 18:01:47;0100;Server@node2;Req;;Type 21 request received from Scheduler@node2.supernodexp.hpc, sock=20
02/13/2018 18:01:47;0100;Server@node2;Req;;Type 81 request received from Scheduler@node2.supernodexp.hpc, sock=20
02/13/2018 18:01:47;0100;Server@node2;Req;;Type 71 request received from Scheduler@node2.supernodexp.hpc, sock=20
02/13/2018 18:01:47;0100;Server@node2;Req;;Type 58 request received from Scheduler@node2.supernodexp.hpc, sock=20
